5:return {{["x"] = 0, ["meta"] = {["fields"] = {}, ["inventory"] = {}}, ["y"] = 0, ["param1"] = 45, ["z"] = 0, ["name"] = "default:water_source"}, {["x"] = 0, ["meta"] = {["fields"] = {}, ["inventory"] = {}}, ["y"] = 0, ["param1"] = 29, ["z"] = 1, ["name"] = "default:water_source"}, {["x"] = 0, ["meta"] = {["fields"] = {}, ["inventory"] = {}}, ["y"] = 0, ["param1"] = 13, ["z"] = 2, ["name"] = "default:water_source"}, {["x"] = 0, ["meta"] = {["fields"] = {}, ["inventory"] = {}}, ["y"] = 0, ["param1"] = 13, ["z"] = 3, ["name"] = "default:water_source"}, {["x"] = 0, ["meta"] = {["fields"] = {}, ["inventory"] = {}}, ["y"] = 0, ["param1"] = 13, ["z"] = 4, ["name"] = "default:water_source"}, {["x"] = 0, ["meta"] = {["fields"] = {}, ["inventory"] = {}}, ["y"] = 0, ["param1"] = 13, ["z"] = 5, ["name"] = "default:water_source"}, {["x"] = 0, ["meta"] = {["fields"] = {}, ["inventory"] = {}}, ["y"] = 0, ["param1"] = 13, ["z"] = 6, ["name"] = "default:water_source"}, {["x"] = 0, ["meta"] = {["fields"] = {}, ["inventory"] = {}}, ["y"] = 0, ["param1"] = 13, ["z"] = 7, ["name"] = "default:water_source"}, {["x"] = 0, ["meta"] = {["fields"] = {}, ["inventory"] = {}}, ["y"] = 0, ["param1"] = 13, ["z"] = 8, ["name"] = "default:water_source"}, {["x"] = 0, ["meta"] = {["fields"] = {}, ["inventory"] = {}}, ["y"] = 0, ["param1"] = 13, ["z"] = 9, ["name"] = "default:water_source"}, {["x"] = 0, ["meta"] = {["fields"] = {}, ["inventory"] = {}}, ["y"] = 0, ["param1"] = 13, ["z"] = 10, ["name"] = "default:water_source"}, {["x"] = 0, ["meta"] = {["fields"] = {}, ["inventory"] = {}}, ["y"] = 0, ["param1"] = 13, ["z"] = 11, ["name"] = "default:water_source"}, {["x"] = 0, ["meta"] = {["fields"] = {}, ["inventory"] = {}}, ["y"] = 0, ["param1"] = 13, ["z"] = 12, ["name"] = "default:water_source"}, {["x"] = 0, ["meta"] = {["fields"] = {}, ["inventory"] = {}}, ["y"] = 0, ["param1"] = 13, ["z"] = 13, ["name"] = "default:water_source"}, {["x"] = 0, ["meta"] = {["fields"] = {}, ["inventory"] = {}}, ["y"] = 0, ["param1"] = 13, ["z"] = 14, ["name"] = "default:water_source"}, {["x"] = 0, ["meta"] = {["fields"] = {}, ["inventory"] = {}}, ["y"] = 0, ["param1"] = 13, ["z"] = 15, ["name"] = "default:water_source"}, {["x"] = 0, ["meta"] = {["fields"] = {}, ["inventory"] = {}}, ["y"] = 0, ["param1"] = 13, ["z"] = 16, ["name"] = "default:water_source"}, {["x"] = 0, ["meta"] = {["fields"] = {}, ["inventory"] = {}}, ["y"] = 0, ["param1"] = 13, ["z"] = 17, ["name"] = "default:water_source"}, {["x"] = 0, ["meta"] = {["fields"] = {}, ["inventory"] = {}}, ["y"] = 0, ["param1"] = 13, ["z"] = 18, ["name"] = "default:water_source"}, {["x"] = 0, ["meta"] = {["fields"] = {}, ["inventory"] = {}}, ["y"] = 0, ["param1"] = 13, ["z"] = 19, ["name"] = "default:water_source"}, {["x"] = 0, ["meta"] = {["fields"] = {}, ["inventory"] = {}}, ["y"] = 0, ["param1"] = 13, ["z"] = 20, ["name"] = "default:water_source"}, {["x"] = 0, ["meta"] = {["fields"] = {}, ["inventory"] = {}}, ["y"] = 0, ["param1"] = 13, ["z"] = 21, ["name"] = "default:water_source"}, {["x"] = 0, ["meta"] = {["fields"] = {}, ["inventory"] = {}}, ["y"] = 0, ["param1"] = 13, ["z"] = 22, ["name"] = "default:water_source"}, {["x"] = 0, ["meta"] = {["fields"] = {}, ["inventory"] = {}}, ["y"] = 0, ["param1"] = 13, ["z"] = 23, ["name"] = "default:water_source"}, {["x"] = 0, ["meta"] = {["fields"] = {}, ["inventory"] = {}}, ["y"] = 0, ["param1"] = 13, ["z"] = 24, ["name"] = "default:water_source"}, {["x"] = 0, ["meta"] = {["fields"] = {}, ["inventory"] = {}}, ["y"] = 0, ["param1"] = 13, ["z"] = 25, ["name"] = "default:water_source"}, {["x"] = 0, ["meta"] = {["fields"] = {}, ["inventory"] = {}}, ["y"] = 0, ["param1"] = 13, ["z"] = 26, ["name"] = "default:water_source"}, {["x"] = 0, ["meta"] = {["fields"] = {}, ["inventory"] = {}}, ["y"] = 0, ["param1"] = 13, ["z"] = 27, ["name"] = "default:water_source"}, {["x"] = 0, ["meta"] = {["fields"] = {}, ["inventory"] = {}}, ["y"] = 0, ["param1"] = 13, ["z"] = 28, ["name"] = "default:water_source"}, {["x"] = 0, ["meta"] = {["fields"] = {}, ["inventory"] = {}}, ["y"] = 0, ["param1"] = 13, ["z"] = 29, ["name"] = "default:water_source"}, {["x"] = 0, ["meta"] = {["fields"] = {}, ["inventory"] = {}}, ["y"] = 0, ["param1"] = 13, ["z"] = 30, ["name"] = "default:water_source"}, {["x"] = 0, ["meta"] = {["fields"] = {}, ["inventory"] = {}}, ["y"] = 0, ["param1"] = 13, ["z"] = 31, ["name"] = "default:water_source"}, {["x"] = 0, ["meta"] = {["fields"] = {}, ["inventory"] = {}}, ["y"] = 0, ["param1"] = 13, ["z"] = 32, ["name"] = "default:water_source"}, {["x"] = 0, ["meta"] = {["fields"] = {}, ["inventory"] = {}}, ["y"] = 0, ["param1"] = 13, ["z"] = 33, ["name"] = "default:water_source"}, {["x"] = 0, ["meta"] = {["fields"] = {}, ["inventory"] = {}}, ["y"] = 0, ["param1"] = 13, ["z"] = 34, ["name"] = "default:water_source"}, {["x"] = 0, ["meta"] = {["fields"] = {}, ["inventory"] = {}}, ["y"] = 0, ["param1"] = 13, ["z"] = 35, ["name"] = "default:water_source"}, {["x"] = 0, ["meta"] = {["fields"] = {}, ["inventory"] = {}}, ["y"] = 0, ["param1"] = 13, ["z"] = 36, ["name"] = "default:water_source"}, {["x"] = 0, ["meta"] = {["fields"] = {}, ["inventory"] = {}}, ["y"] = 0, ["param1"] = 13, ["z"] = 37, ["name"] = "default:water_source"}, {["x"] = 0, ["meta"] = {["fields"] = {}, ["inventory"] = {}}, ["y"] = 0, ["param1"] = 13, ["z"] = 38, ["name"] = "default:water_source"}, {["x"] = 0, ["meta"] = {["fields"] = {}, ["inventory"] = {}}, ["y"] = 0, ["param1"] = 13, ["z"] = 39, ["name"] = "default:water_source"}, {["x"] = 0, ["meta"] = {["fields"] = {}, ["inventory"] = {}}, ["y"] = 0, ["param1"] = 13, ["z"] = 40, ["name"] = "default:water_source"}, {["x"] = 0, ["meta"] = {["fields"] = {}, ["inventory"] = {}}, ["y"] = 0, ["param1"] = 13, ["z"] = 41, ["name"] = "default:water_source"}, {["x"] = 0, ["meta"] = {["fields"] = {}, ["inventory"] = {}}, ["y"] = 0, ["param1"] = 13, ["z"] = 42, ["name"] = "default:water_source"}, {["x"] = 0, ["meta"] = {["fields"] = {}, ["inventory"] = {}}, ["y"] = 0, ["param1"] = 13, ["z"] = 43, ["name"] = "default:water_source"}, {["x"] = 0, ["meta"] = {["fields"] = {}, ["inventory"] = {}}, ["y"] = 0, ["param1"] = 13, ["z"] = 44, ["name"] = "default:water_source"}, {["x"] = 0, ["meta"] = {["fields"] = {}, ["inventory"] = {}}, ["y"] = 0, ["param1"] = 13, ["z"] = 45, ["name"] = "default:water_source"}, {["x"] = 0, ["meta"] = {["fields"] = {}, ["inventory"] = {}}, ["y"] = 0, ["param1"] = 13, ["z"] = 46, ["name"] = "default:water_source"}, {["x"] = 0, ["meta"] = {["fields"] = {}, ["inventory"] = {}}, ["y"] = 0, ["param1"] = 13, ["z"] = 47, ["name"] = "default:water_source"}, {["x"] = 0, ["meta"] = {["fields"] = {}, ["inventory"] = {}}, ["y"] = 0, ["param1"] = 13, ["z"] = 48, ["name"] = "default:water_source"}, {["x"] = 0, ["meta"] = {["fields"] = {}, ["inventory"] = {}}, ["y"] = 0, ["param1"] = 13, ["z"] = 49, ["name"] = "default:water_source"}, {["x"] = 0, ["meta"] = {["fields"] = {}, ["inventory"] = {}}, ["y"] = 0, ["param1"] = 13, ["z"] = 50, ["name"] = "default:water_source"}, {["x"] = 0, ["meta"] = {["fields"] = {}, ["inventory"] = {}}, ["y"] = 0, ["param1"] = 13, ["z"] = 51, ["name"] = "default:water_source"}, {["x"] = 0, ["meta"] = {["fields"] = {}, ["inventory"] = {}}, ["y"] = 0, ["param1"] = 13, ["z"] = 52, ["name"] = "default:water_source"}, {["x"] = 0, ["meta"] = {["fields"] = {}, ["inventory"] = {}}, ["y"] = 0, ["param1"] = 13, ["z"] = 53, ["name"] = "default:water_source"}, {["x"] = 0, ["meta"] = {["fields"] = {}, ["inventory"] = {}}, ["y"] = 0, ["param1"] = 13, ["z"] = 54, ["name"] = "default:water_source"}, {["x"] = 0, ["meta"] = {["fields"] = {}, ["inventory"] = {}}, ["y"] = 0, ["param1"] = 13, ["z"] = 55, ["name"] = "default:water_source"}, {["x"] = 0, ["meta"] = {["fields"] = {}, ["inventory"] = {}}, ["y"] = 0, ["param1"] = 13, ["z"] = 56, ["name"] = "default:water_source"}, {["x"] = 0, ["meta"] = {["fields"] = {}, ["inventory"] = {}}, ["y"] = 0, ["param1"] = 13, ["z"] = 57, ["name"] = "default:water_source"}, {["x"] = 0, ["meta"] = {["fields"] = {}, ["inventory"] = {}}, ["y"] = 0, ["param1"] = 13, ["z"] = 58, ["name"] = "default:water_source"}, {["x"] = 0, ["meta"] = {["fields"] = {}, ["inventory"] = {}}, ["y"] = 0, ["param1"] = 13, ["z"] = 59, ["name"] = "default:water_source"}, {["x"] = 0, ["meta"] = {["fields"] = {}, ["inventory"] = {}}, ["y"] = 0, ["param1"] = 13, ["z"] = 60, ["name"] = "default:water_source"}, {["x"] = 0, ["meta"] = {["fields"] = {}, ["inventory"] = {}}, ["y"] = 0, ["param1"] = 13, ["z"] = 61, ["name"] = "default:water_source"}, {["x"] = 0, ["meta"] = {["fields"] = {}, ["inventory"] = {}}, ["y"] = 0, ["param1"] = 13, ["z"] = 62, ["name"] = "default:water_source"}, {["x"] = 0, ["meta"] = {["fields"] = {}, ["inventory"] = {}}, ["y"] = 0, ["param1"] = 13, ["z"] = 63, ["name"] = "default:water_source"}, {["x"] = 0, ["meta"] = {["fields"] = {}, ["inventory"] = {}}, ["y"] = 0, ["param1"] = 13, ["z"] = 64, ["name"] = "default:water_source"}, {["x"] = 0, ["meta"] = {["fields"] = {}, ["inventory"] = {}}, ["y"] = 0, ["param1"] = 29, ["z"] = 65, ["name"] = "default:water_source"}, {["x"] = 0, ["meta"] = {["fields"] = {}, ["inventory"] = {}}, ["y"] = 0, ["param1"] = 45, ["z"] = 66, ["name"] = "default:water_source"}, {["x"] = 0, ["meta"] = {["fields"] = {}, ["inventory"] = {}}, ["y"] = 0, ["param1"] = 61, ["z"] = 67, ["name"] = "default:water_source"}, {["x"] = 0, ["meta"] = {["fields"] = {}, ["inventory"] = {}}, ["y"] = 0, ["param1"] = 77, ["z"] = 68, ["name"] = "default:water_source"}, {["x"] = 0, ["meta"] = {["fields"] = {}, ["inventory"] = {}}, ["y"] = 0, ["param1"] = 93, ["z"] = 69, ["name"] = "default:water_source"}, {["x"] = 0, ["meta"] = {["fields"] = {}, ["inventory"] = {}}, ["y"] = 0, ["param1"] = 109, ["z"] = 70, ["name"] = "default:water_source"}, {["x"] = 0, ["meta"] = {["fields"] = {}, ["inventory"] = {}}, ["y"] = 0, ["param1"] = 125, ["z"] = 71, ["name"] = "default:water_source"}, {["x"] = 0, ["meta"] = {["fields"] = {}, ["inventory"] = {}}, ["y"] = 0, ["param1"] = 141, ["z"] = 72, ["name"] = "default:water_source"}, {["x"] = 0, ["meta"] = {["fields"] = {}, ["inventory"] = {}}, ["y"] = 0, ["param1"] = 157, ["z"] = 73, ["name"] = "default:water_source"}, {["x"] = 0, ["meta"] = {["fields"] = {}, ["inventory"] = {}}, ["y"] = 0, ["param1"] = 173, ["z"] = 74, ["name"] = "default:water_source"}, {["x"] = 0, ["meta"] = {["fields"] = {}, ["inventory"] = {}}, ["y"] = 0, ["param1"] = 189, ["z"] = 75, ["name"] = "default:water_source"}, {["x"] = 0, ["meta"] = {["fields"] = {}, ["inventory"] = {}}, ["y"] = 0, ["param1"] = 205, ["z"] = 76, ["name"] = "default:water_source"}, {["x"] = 0, ["meta"] = {["fields"] = {}, ["inventory"] = {}}, ["y"] = 0, ["param1"] = 221, ["z"] = 77, ["name"] = "default:water_source"}, {["x"] = 0, ["meta"] = {["fields"] = {}, ["inventory"] = {}}, ["y"] = 0, ["param1"] = 15, ["z"] = 78, ["name"] = "stained_glass:6_5_7"}, {["x"] = 1, ["meta"] = {["fields"] = {}, ["inventory"] = {}}, ["y"] = 0, ["param1"] = 29, ["z"] = 0, ["name"] = "default:water_source"}, {["x"] = 1, ["meta"] = {["fields"] = {}, ["inventory"] = {}}, ["y"] = 0, ["param1"] = 13, ["z"] = 1, ["name"] = "default:water_source"}, {["x"] = 1, ["meta"] = {["fields"] = {}, ["inventory"] = {}}, ["y"] = 0, ["param1"] = 13, ["z"] = 2, ["name"] = "default:water_source"}, {["x"] = 1, ["meta"] = {["fields"] = {}, ["inventory"] = {}}, ["y"] = 0, ["param1"] = 13, ["z"] = 3, ["name"] = "default:water_source"}, {["x"] = 1, ["meta"] = {["fields"] = {}, ["inventory"] = {}}, ["y"] = 0, ["param1"] = 13, ["z"] = 4, ["name"] = "default:water_source"}, {["x"] = 1, ["meta"] = {["fields"] = {}, ["inventory"] = {}}, ["y"] = 0, ["param1"] = 13, ["z"] = 5, ["name"] = "default:water_source"}, {["x"] = 1, ["meta"] = {["fields"] = {}, ["inventory"] = {}}, ["y"] = 0, ["param1"] = 13, ["z"] = 6, ["name"] = "default:water_source"}, {["x"] = 1, ["meta"] = {["fields"] = {}, ["inventory"] = {}}, ["y"] = 0, ["param1"] = 13, ["z"] = 7, ["name"] = "default:water_source"}, {["x"] = 1, ["meta"] = {["fields"] = {}, ["inventory"] = {}}, ["y"] = 0, ["param1"] = 13, ["z"] = 8, ["name"] = "default:water_source"}, {["x"] = 1, ["meta"] = {["fields"] = {}, ["inventory"] = {}}, ["y"] = 0, ["param1"] = 13, ["z"] = 9, ["name"] = "default:water_source"}, {["x"] = 1, ["meta"] = {["fields"] = {}, ["inventory"] = {}}, ["y"] = 0, ["param1"] = 13, ["z"] = 10, ["name"] = "default:water_source"}, {["x"] = 1, ["meta"] = {["fields"] = {}, ["inventory"] = {}}, ["y"] = 0, ["param1"] = 13, ["z"] = 11, ["name"] = "default:water_source"}, {["x"] = 1, ["meta"] = {["fields"] = {}, ["inventory"] = {}}, ["y"] = 0, ["param1"] = 13, ["z"] = 12, ["name"] = "default:water_source"}, {["x"] = 1, ["meta"] = {["fields"] = {}, ["inventory"] = {}}, ["y"] = 0, ["param1"] = 13, ["z"] = 13, ["name"] = "default:water_source"}, {["x"] = 1, ["meta"] = {["fields"] = {}, ["inventory"] = {}}, ["y"] = 0, ["param1"] = 13, ["z"] = 14, ["name"] = "default:water_source"}, {["x"] = 1, ["meta"] = {["fields"] = {}, ["inventory"] = {}}, ["y"] = 0, ["param1"] = 13, ["z"] = 15, ["name"] = "default:water_source"}, {["x"] = 1, ["meta"] = {["fields"] = {}, ["inventory"] = {}}, ["y"] = 0, ["param1"] = 13, ["z"] = 16, ["name"] = "default:water_source"}, {["x"] = 1, ["meta"] = {["fields"] = {}, ["inventory"] = {}}, ["y"] = 0, ["param1"] = 13, ["z"] = 17, ["name"] = "default:water_source"}, {["x"] = 1, ["meta"] = {["fields"] = {}, ["inventory"] = {}}, ["y"] = 0, ["param1"] = 13, ["z"] = 18, ["name"] = "default:water_source"}, {["x"] = 1, ["meta"] = {["fields"] = {}, ["inventory"] = {}}, ["y"] = 0, ["param1"] = 13, ["z"] = 19, ["name"] = "default:water_source"}, {["x"] = 1, ["meta"] = {["fields"] = {}, ["inventory"] = {}}, ["y"] = 0, ["param1"] = 13, ["z"] = 20, ["name"] = "default:water_source"}, {["x"] = 1, ["meta"] = {["fields"] = {}, ["inventory"] = {}}, ["y"] = 0, ["param1"] = 13, ["z"] = 21, ["name"] = "default:water_source"}, {["x"] = 1, ["meta"] = {["fields"] = {}, ["inventory"] = {}}, ["y"] = 0, ["param1"] = 13, ["z"] = 22, ["name"] = "default:water_source"}, {["x"] = 1, ["meta"] = {["fields"] = {}, ["inventory"] = {}}, ["y"] = 0, ["param1"] = 13, ["z"] = 23, ["name"] = "default:water_source"}, {["x"] = 1, ["meta"] = {["fields"] = {}, ["inventory"] = {}}, ["y"] = 0, ["param1"] = 13, ["z"] = 24, ["name"] = "default:water_source"}, {["x"] = 1, ["meta"] = {["fields"] = {}, ["inventory"] = {}}, ["y"] = 0, ["param1"] = 13, ["z"] = 25, ["name"] = "default:water_source"}, {["x"] = 1, ["meta"] = {["fields"] = {}, ["inventory"] = {}}, ["y"] = 0, ["param1"] = 13, ["z"] = 26, ["name"] = "default:water_source"}, {["x"] = 1, ["meta"] = {["fields"] = {}, ["inventory"] = {}}, ["y"] = 0, ["param1"] = 13, ["z"] = 27, ["name"] = "default:water_source"}, {["x"] = 1, ["meta"] = {["fields"] = {}, ["inventory"] = {}}, ["y"] = 0, ["param1"] = 13, ["z"] = 28, ["name"] = "default:water_source"}, {["x"] = 1, ["meta"] = {["fields"] = {}, ["inventory"] = {}}, ["y"] = 0, ["param1"] = 13, ["z"] = 29, ["name"] = "default:water_source"}, {["x"] = 1, ["meta"] = {["fields"] = {}, ["inventory"] = {}}, ["y"] = 0, ["param1"] = 13, ["z"] = 30, ["name"] = "default:water_source"}, {["x"] = 1, ["meta"] = {["fields"] = {}, ["inventory"] = {}}, ["y"] = 0, ["param1"] = 13, ["z"] = 31, ["name"] = "default:water_source"}, {["x"] = 1, ["meta"] = {["fields"] = {}, ["inventory"] = {}}, ["y"] = 0, ["param1"] = 13, ["z"] = 32, ["name"] = "default:water_source"}, {["x"] = 1, ["meta"] = {["fields"] = {}, ["inventory"] = {}}, ["y"] = 0, ["param1"] = 13, ["z"] = 33, ["name"] = "default:water_source"}, {["x"] = 1, ["meta"] = {["fields"] = {}, ["inventory"] = {}}, ["y"] = 0, ["param1"] = 13, ["z"] = 34, ["name"] = "default:water_source"}, {["x"] = 1, ["meta"] = {["fields"] = {}, ["inventory"] = {}}, ["y"] = 0, ["param1"] = 13, ["z"] = 35, ["name"] = "default:water_source"}, {["x"] = 1, ["meta"] = {["fields"] = {}, ["inventory"] = {}}, ["y"] = 0, ["param1"] = 13, ["z"] = 36, ["name"] = "default:water_source"}, {["x"] = 1, ["meta"] = {["fields"] = {}, ["inventory"] = {}}, ["y"] = 0, ["param1"] = 13, ["z"] = 37, ["name"] = "default:water_source"}, {["x"] = 1, ["meta"] = {["fields"] = {}, ["inventory"] = {}}, ["y"] = 0, ["param1"] = 13, ["z"] = 38, ["name"] = "default:water_source"}, {["x"] = 1, ["meta"] = {["fields"] = {}, ["inventory"] = {}}, ["y"] = 0, ["param1"] = 13, ["z"] = 39, ["name"] = "default:water_source"}, {["x"] = 1, ["meta"] = {["fields"] = {}, ["inventory"] = {}}, ["y"] = 0, ["param1"] = 13, ["z"] = 40, ["name"] = "default:water_source"}, {["x"] = 1, ["meta"] = {["fields"] = {}, ["inventory"] = {}}, ["y"] = 0, ["param1"] = 13, ["z"] = 41, ["name"] = "default:water_source"}, {["x"] = 1, ["meta"] = {["fields"] = {}, ["inventory"] = {}}, ["y"] = 0, ["param1"] = 13, ["z"] = 42, ["name"] = "default:water_source"}, {["x"] = 1, ["meta"] = {["fields"] = {}, ["inventory"] = {}}, ["y"] = 0, ["param1"] = 13, ["z"] = 43, ["name"] = "default:water_source"}, {["x"] = 1, ["meta"] = {["fields"] = {}, ["inventory"] = {}}, ["y"] = 0, ["param1"] = 13, ["z"] = 44, ["name"] = "default:water_source"}, {["x"] = 1, ["meta"] = {["fields"] = {}, ["inventory"] = {}}, ["y"] = 0, ["param1"] = 13, ["z"] = 45, ["name"] = "default:water_source"}, {["x"] = 1, ["meta"] = {["fields"] = {}, ["inventory"] = {}}, ["y"] = 0, ["param1"] = 13, ["z"] = 46, ["name"] = "default:water_source"}, {["x"] = 1, ["meta"] = {["fields"] = {}, ["inventory"] = {}}, ["y"] = 0, ["param1"] = 13, ["z"] = 47, ["name"] = "default:water_source"}, {["x"] = 1, ["meta"] = {["fields"] = {}, ["inventory"] = {}}, ["y"] = 0, ["param1"] = 13, ["z"] = 48, ["name"] = "default:water_source"}, {["x"] = 1, ["meta"] = {["fields"] = {}, ["inventory"] = {}}, ["y"] = 0, ["param1"] = 13, ["z"] = 49, ["name"] = "default:water_source"}, {["x"] = 1, ["meta"] = {["fields"] = {}, ["inventory"] = {}}, ["y"] = 0, ["param1"] = 13, ["z"] = 50, ["name"] = "default:water_source"}, {["x"] = 1, ["meta"] = {["fields"] = {}, ["inventory"] = {}}, ["y"] = 0, ["param1"] = 13, ["z"] = 51, ["name"] = "default:water_source"}, {["x"] = 1, ["meta"] = {["fields"] = {}, ["inventory"] = {}}, ["y"] = 0, ["param1"] = 13, ["z"] = 52, ["name"] = "default:water_source"}, {["x"] = 1, ["meta"] = {["fields"] = {}, ["inventory"] = {}}, ["y"] = 0, ["param1"] = 13, ["z"] = 53, ["name"] = "default:water_source"}, {["x"] = 1, ["meta"] = {["fields"] = {}, ["inventory"] = {}}, ["y"] = 0, ["param1"] = 13, ["z"] = 54, ["name"] = "default:water_source"}, {["x"] = 1, ["meta"] = {["fields"] = {}, ["inventory"] = {}}, ["y"] = 0, ["param1"] = 13, ["z"] = 55, ["name"] = "default:water_source"}, {["x"] = 1, ["meta"] = {["fields"] = {}, ["inventory"] = {}}, ["y"] = 0, ["param1"] = 13, ["z"] = 56, ["name"] = "default:water_source"}, {["x"] = 1, ["meta"] = {["fields"] = {}, ["inventory"] = {}}, ["y"] = 0, ["param1"] = 13, ["z"] = 57, ["name"] = "default:water_source"}, {["x"] = 1, ["meta"] = {["fields"] = {}, ["inventory"] = {}}, ["y"] = 0, ["param1"] = 13, ["z"] = 58, ["name"] = "default:water_source"}, {["x"] = 1, ["meta"] = {["fields"] = {}, ["inventory"] = {}}, ["y"] = 0, ["param1"] = 13, ["z"] = 59, ["name"] = "default:water_source"}, {["x"] = 1, ["meta"] = {["fields"] = {}, ["inventory"] = {}}, ["y"] = 0, ["param1"] = 13, ["z"] = 60, ["name"] = "default:water_source"}, {["x"] = 1, ["meta"] = {["fields"] = {}, ["inventory"] = {}}, ["y"] = 0, ["param1"] = 13, ["z"] = 61, ["name"] = "default:water_source"}, {["x"] = 1, ["meta"] = {["fields"] = {}, ["inventory"] = {}}, ["y"] = 0, ["param1"] = 13, ["z"] = 62, ["name"] = "default:water_source"}, {["x"] = 1, ["meta"] = {["fields"] = {}, ["inventory"] = {}}, ["y"] = 0, ["param1"] = 13, ["z"] = 63, ["name"] = "default:water_source"}, {["x"] = 1, ["meta"] = {["fields"] = {}, ["inventory"] = {}}, ["y"] = 0, ["param1"] = 13, ["z"] = 64, ["name"] = "default:water_source"}, {["x"] = 1, ["meta"] = {["fields"] = {}, ["inventory"] = {}}, ["y"] = 0, ["param1"] = 29, ["z"] = 65, ["name"] = "default:water_source"}, {["x"] = 1, ["meta"] = {["fields"] = {}, ["inventory"] = {}}, ["y"] = 0, ["param1"] = 45, ["z"] = 66, ["name"] = "default:water_source"}, {["x"] = 1, ["meta"] = {["fields"] = {}, ["inventory"] = {}}, ["y"] = 0, ["param1"] = 61, ["z"] = 67, ["name"] = "default:water_source"}, {["x"] = 1, ["meta"] = {["fields"] = {}, ["inventory"] = {}}, ["y"] = 0, ["param1"] = 77, ["z"] = 68, ["name"] = "default:water_source"}, {["x"] = 1, ["meta"] = {["fields"] = {}, ["inventory"] = {}}, ["y"] = 0, ["param1"] = 93, ["z"] = 69, ["name"] = "default:water_source"}, {["x"] = 1, ["meta"] = {["fields"] = {}, ["inventory"] = {}}, ["y"] = 0, ["param1"] = 109, ["z"] = 70, ["name"] = "default:water_source"}, {["x"] = 1, ["meta"] = {["fields"] = {}, ["inventory"] = {}}, ["y"] = 0, ["param1"] = 125, ["z"] = 71, ["name"] = "default:water_source"}, {["x"] = 1, ["meta"] = {["fields"] = {}, ["inventory"] = {}}, ["y"] = 0, ["param1"] = 141, ["z"] = 72, ["name"] = "default:water_source"}, {["x"] = 1, ["meta"] = {["fields"] = {}, ["inventory"] = {}}, ["y"] = 0, ["param1"] = 157, ["z"] = 73, ["name"] = "default:water_source"}, {["x"] = 1, ["meta"] = {["fields"] = {}, ["inventory"] = {}}, ["y"] = 0, ["param1"] = 173, ["z"] = 74, ["name"] = "default:water_source"}, {["x"] = 1, ["meta"] = {["fields"] = {}, ["inventory"] = {}}, ["y"] = 0, ["param1"] = 189, ["z"] = 75, ["name"] = "default:water_source"}, {["x"] = 1, ["meta"] = {["fields"] = {}, ["inventory"] = {}}, ["y"] = 0, ["param1"] = 205, ["z"] = 76, ["name"] = "default:water_source"}, {["x"] = 1, ["meta"] = {["fields"] = {}, ["inventory"] = {}}, ["y"] = 0, ["param1"] = 221, ["z"] = 77, ["name"] = "default:water_source"}, {["x"] = 1, ["meta"] = {["fields"] = {}, ["inventory"] = {}}, ["y"] = 0, ["param1"] = 15, ["z"] = 78, ["name"] = "stained_glass:6_5_7"}, {["x"] = 2, ["meta"] = {["fields"] = {}, ["inventory"] = {}}, ["y"] = 0, ["param1"] = 13, ["z"] = 0, ["name"] = "default:water_source"}, {["x"] = 2, ["meta"] = {["fields"] = {}, ["inventory"] = {}}, ["y"] = 0, ["param1"] = 13, ["z"] = 1, ["name"] = "default:water_source"}, {["x"] = 2, ["meta"] = {["fields"] = {}, ["inventory"] = {}}, ["y"] = 0, ["param1"] = 13, ["z"] = 2, ["name"] = "default:water_source"}, {["x"] = 2, ["meta"] = {["fields"] = {}, ["inventory"] = {}}, ["y"] = 0, ["param1"] = 13, ["z"] = 3, ["name"] = "default:water_source"}, {["x"] = 2, ["meta"] = {["fields"] = {}, ["inventory"] = {}}, ["y"] = 0, ["param1"] = 13, ["z"] = 4, ["name"] = "default:water_source"}, {["x"] = 2, ["meta"] = {["fields"] = {}, ["inventory"] = {}}, ["y"] = 0, ["param1"] = 13, ["z"] = 5, ["name"] = "default:water_source"}, {["x"] = 2, ["meta"] = {["fields"] = {}, ["inventory"] = {}}, ["y"] = 0, ["param1"] = 13, ["z"] = 6, ["name"] = "default:water_source"}, {["x"] = 2, ["meta"] = {["fields"] = {}, ["inventory"] = {}}, ["y"] = 0, ["param1"] = 13, ["z"] = 7, ["name"] = "default:water_source"}, {["x"] = 2, ["meta"] = {["fields"] = {}, ["inventory"] = {}}, ["y"] = 0, ["param1"] = 13, ["z"] = 8, ["name"] = "default:water_source"}, {["x"] = 2, ["meta"] = {["fields"] = {}, ["inventory"] = {}}, ["y"] = 0, ["param1"] = 13, ["z"] = 9, ["name"] = "default:water_source"}, {["x"] = 2, ["meta"] = {["fields"] = {}, ["inventory"] = {}}, ["y"] = 0, ["param1"] = 13, ["z"] = 10, ["name"] = "default:water_source"}, {["x"] = 2, ["meta"] = {["fields"] = {}, ["inventory"] = {}}, ["y"] = 0, ["param1"] = 13, ["z"] = 11, ["name"] = "default:water_source"}, {["x"] = 2, ["meta"] = {["fields"] = {}, ["inventory"] = {}}, ["y"] = 0, ["param1"] = 13, ["z"] = 12, ["name"] = "default:water_source"}, {["x"] = 2, ["meta"] = {["fields"] = {}, ["inventory"] = {}}, ["y"] = 0, ["param1"] = 13, ["z"] = 13, ["name"] = "default:water_source"}, {["x"] = 2, ["meta"] = {["fields"] = {}, ["inventory"] = {}}, ["y"] = 0, ["param1"] = 13, ["z"] = 14, ["name"] = "default:water_source"}, {["x"] = 2, ["meta"] = {["fields"] = {}, ["inventory"] = {}}, ["y"] = 0, ["param1"] = 13, ["z"] = 15, ["name"] = "default:water_source"}, {["x"] = 2, ["meta"] = {["fields"] = {}, ["inventory"] = {}}, ["y"] = 0, ["param1"] = 13, ["z"] = 16, ["name"] = "default:water_source"}, {["x"] = 2, ["meta"] = {["fields"] = {}, ["inventory"] = {}}, ["y"] = 0, ["param1"] = 13, ["z"] = 17, ["name"] = "default:water_source"}, {["x"] = 2, ["meta"] = {["fields"] = {}, ["inventory"] = {}}, ["y"] = 0, ["param1"] = 13, ["z"] = 18, ["name"] = "default:water_source"}, {["x"] = 2, ["meta"] = {["fields"] = {}, ["inventory"] = {}}, ["y"] = 0, ["param1"] = 13, ["z"] = 19, ["name"] = "default:water_source"}, {["x"] = 2, ["meta"] = {["fields"] = {}, ["inventory"] = {}}, ["y"] = 0, ["param1"] = 13, ["z"] = 20, ["name"] = "default:water_source"}, {["x"] = 2, ["meta"] = {["fields"] = {}, ["inventory"] = {}}, ["y"] = 0, ["param1"] = 13, ["z"] = 21, ["name"] = "default:water_source"}, {["x"] = 2, ["meta"] = {["fields"] = {}, ["inventory"] = {}}, ["y"] = 0, ["param1"] = 13, ["z"] = 22, ["name"] = "default:water_source"}, {["x"] = 2, ["meta"] = {["fields"] = {}, ["inventory"] = {}}, ["y"] = 0, ["param1"] = 13, ["z"] = 23, ["name"] = "default:water_source"}, {["x"] = 2, ["meta"] = {["fields"] = {}, ["inventory"] = {}}, ["y"] = 0, ["param1"] = 13, ["z"] = 24, ["name"] = "default:water_source"}, {["x"] = 2, ["meta"] = {["fields"] = {}, ["inventory"] = {}}, ["y"] = 0, ["param1"] = 13, ["z"] = 25, ["name"] = "default:water_source"}, {["x"] = 2, ["meta"] = {["fields"] = {}, ["inventory"] = {}}, ["y"] = 0, ["param1"] = 13, ["z"] = 26, ["name"] = "default:water_source"}, {["x"] = 2, ["meta"] = {["fields"] = {}, ["inventory"] = {}}, ["y"] = 0, ["param1"] = 13, ["z"] = 27, ["name"] = "default:water_source"}, {["x"] = 2, ["meta"] = {["fields"] = {}, ["inventory"] = {}}, ["y"] = 0, ["param1"] = 13, ["z"] = 28, ["name"] = "default:water_source"}, {["x"] = 2, ["meta"] = {["fields"] = {}, ["inventory"] = {}}, ["y"] = 0, ["param1"] = 13, ["z"] = 29, ["name"] = "default:water_source"}, {["x"] = 2, ["meta"] = {["fields"] = {}, ["inventory"] = {}}, ["y"] = 0, ["param1"] = 13, ["z"] = 30, ["name"] = "default:water_source"}, {["x"] = 2, ["meta"] = {["fields"] = {}, ["inventory"] = {}}, ["y"] = 0, ["param1"] = 13, ["z"] = 31, ["name"] = "default:water_source"}, {["x"] = 2, ["meta"] = {["fields"] = {}, ["inventory"] = {}}, ["y"] = 0, ["param1"] = 13, ["z"] = 32, ["name"] = "default:water_source"}, {["x"] = 2, ["meta"] = {["fields"] = {}, ["inventory"] = {}}, ["y"] = 0, ["param1"] = 13, ["z"] = 33, ["name"] = "default:water_source"}, {["x"] = 2, ["meta"] = {["fields"] = {}, ["inventory"] = {}}, ["y"] = 0, ["param1"] = 13, ["z"] = 34, ["name"] = "default:water_source"}, {["x"] = 2, ["meta"] = {["fields"] = {}, ["inventory"] = {}}, ["y"] = 0, ["param1"] = 13, ["z"] = 35, ["name"] = "default:water_source"}, {["x"] = 2, ["meta"] = {["fields"] = {}, ["inventory"] = {}}, ["y"] = 0, ["param1"] = 13, ["z"] = 36, ["name"] = "default:water_source"}, {["x"] = 2, ["meta"] = {["fields"] = {}, ["inventory"] = {}}, ["y"] = 0, ["param1"] = 13, ["z"] = 37, ["name"] = "default:water_source"}, {["x"] = 2, ["meta"] = {["fields"] = {}, ["inventory"] = {}}, ["y"] = 0, ["param1"] = 13, ["z"] = 38, ["name"] = "default:water_source"}, {["x"] = 2, ["meta"] = {["fields"] = {}, ["inventory"] = {}}, ["y"] = 0, ["param1"] = 13, ["z"] = 39, ["name"] = "default:water_source"}, {["x"] = 2, ["meta"] = {["fields"] = {}, ["inventory"] = {}}, ["y"] = 0, ["param1"] = 13, ["z"] = 40, ["name"] = "default:water_source"}, {["x"] = 2, ["meta"] = {["fields"] = {}, ["inventory"] = {}}, ["y"] = 0, ["param1"] = 13, ["z"] = 41, ["name"] = "default:water_source"}, {["x"] = 2, ["meta"] = {["fields"] = {}, ["inventory"] = {}}, ["y"] = 0, ["param1"] = 13, ["z"] = 42, ["name"] = "default:water_source"}, {["x"] = 2, ["meta"] = {["fields"] = {}, ["inventory"] = {}}, ["y"] = 0, ["param1"] = 13, ["z"] = 43, ["name"] = "default:water_source"}, {["x"] = 2, ["meta"] = {["fields"] = {}, ["inventory"] = {}}, ["y"] = 0, ["param1"] = 13, ["z"] = 44, ["name"] = "default:water_source"}, {["x"] = 2, ["meta"] = {["fields"] = {}, ["inventory"] = {}}, ["y"] = 0, ["param1"] = 13, ["z"] = 45, ["name"] = "default:water_source"}, {["x"] = 2, ["meta"] = {["fields"] = {}, ["inventory"] = {}}, ["y"] = 0, ["param1"] = 13, ["z"] = 46, ["name"] = "default:water_source"}, {["x"] = 2, ["meta"] = {["fields"] = {}, ["inventory"] = {}}, ["y"] = 0, ["param1"] = 13, ["z"] = 47, ["name"] = "default:water_source"}, {["x"] = 2, ["meta"] = {["fields"] = {}, ["inventory"] = {}}, ["y"] = 0, ["param1"] = 13, ["z"] = 48, ["name"] = "default:water_source"}, {["x"] = 2, ["meta"] = {["fields"] = {}, ["inventory"] = {}}, ["y"] = 0, ["param1"] = 13, ["z"] = 49, ["name"] = "default:water_source"}, {["x"] = 2, ["meta"] = {["fields"] = {}, ["inventory"] = {}}, ["y"] = 0, ["param1"] = 13, ["z"] = 50, ["name"] = "default:water_source"}, {["x"] = 2, ["meta"] = {["fields"] = {}, ["inventory"] = {}}, ["y"] = 0, ["param1"] = 13, ["z"] = 51, ["name"] = "default:water_source"}, {["x"] = 2, ["meta"] = {["fields"] = {}, ["inventory"] = {}}, ["y"] = 0, ["param1"] = 13, ["z"] = 52, ["name"] = "default:water_source"}, {["x"] = 2, ["meta"] = {["fields"] = {}, ["inventory"] = {}}, ["y"] = 0, ["param1"] = 13, ["z"] = 53, ["name"] = "default:water_source"}, {["x"] = 2, ["meta"] = {["fields"] = {}, ["inventory"] = {}}, ["y"] = 0, ["param1"] = 13, ["z"] = 54, ["name"] = "default:water_source"}, {["x"] = 2, ["meta"] = {["fields"] = {}, ["inventory"] = {}}, ["y"] = 0, ["param1"] = 13, ["z"] = 55, ["name"] = "default:water_source"}, {["x"] = 2, ["meta"] = {["fields"] = {}, ["inventory"] = {}}, ["y"] = 0, ["param1"] = 13, ["z"] = 56, ["name"] = "default:water_source"}, {["x"] = 2, ["meta"] = {["fields"] = {}, ["inventory"] = {}}, ["y"] = 0, ["param1"] = 13, ["z"] = 57, ["name"] = "default:water_source"}, {["x"] = 2, ["meta"] = {["fields"] = {}, ["inventory"] = {}}, ["y"] = 0, ["param1"] = 13, ["z"] = 58, ["name"] = "default:water_source"}, {["x"] = 2, ["meta"] = {["fields"] = {}, ["inventory"] = {}}, ["y"] = 0, ["param1"] = 13, ["z"] = 59, ["name"] = "default:water_source"}, {["x"] = 2, ["meta"] = {["fields"] = {}, ["inventory"] = {}}, ["y"] = 0, ["param1"] = 13, ["z"] = 60, ["name"] = "default:water_source"}, {["x"] = 2, ["meta"] = {["fields"] = {}, ["inventory"] = {}}, ["y"] = 0, ["param1"] = 13, ["z"] = 61, ["name"] = "default:water_source"}, {["x"] = 2, ["meta"] = {["fields"] = {}, ["inventory"] = {}}, ["y"] = 0, ["param1"] = 13, ["z"] = 62, ["name"] = "default:water_source"}, {["x"] = 2, ["meta"] = {["fields"] = {}, ["inventory"] = {}}, ["y"] = 0, ["param1"] = 13, ["z"] = 63, ["name"] = "default:water_source"}, {["x"] = 2, ["meta"] = {["fields"] = {}, ["inventory"] = {}}, ["y"] = 0, ["param1"] = 13, ["z"] = 64, ["name"] = "default:water_source"}, {["x"] = 2, ["meta"] = {["fields"] = {}, ["inventory"] = {}}, ["y"] = 0, ["param1"] = 29, ["z"] = 65, ["name"] = "default:water_source"}, {["x"] = 2, ["meta"] = {["fields"] = {}, ["inventory"] = {}}, ["y"] = 0, ["param1"] = 45, ["z"] = 66, ["name"] = "default:water_source"}, {["x"] = 2, ["meta"] = {["fields"] = {}, ["inventory"] = {}}, ["y"] = 0, ["param1"] = 61, ["z"] = 67, ["name"] = "default:water_source"}, {["x"] = 2, ["meta"] = {["fields"] = {}, ["inventory"] = {}}, ["y"] = 0, ["param1"] = 77, ["z"] = 68, ["name"] = "default:water_source"}, {["x"] = 2, ["meta"] = {["fields"] = {}, ["inventory"] = {}}, ["y"] = 0, ["param1"] = 93, ["z"] = 69, ["name"] = "default:water_source"}, {["x"] = 2, ["meta"] = {["fields"] = {}, ["inventory"] = {}}, ["y"] = 0, ["param1"] = 109, ["z"] = 70, ["name"] = "default:water_source"}, {["x"] = 2, ["meta"] = {["fields"] = {}, ["inventory"] = {}}, ["y"] = 0, ["param1"] = 125, ["z"] = 71, ["name"] = "default:water_source"}, {["x"] = 2, ["meta"] = {["fields"] = {}, ["inventory"] = {}}, ["y"] = 0, ["param1"] = 141, ["z"] = 72, ["name"] = "default:water_source"}, {["x"] = 2, ["meta"] = {["fields"] = {}, ["inventory"] = {}}, ["y"] = 0, ["param1"] = 157, ["z"] = 73, ["name"] = "default:water_source"}, {["x"] = 2, ["meta"] = {["fields"] = {}, ["inventory"] = {}}, ["y"] = 0, ["param1"] = 173, ["z"] = 74, ["name"] = "default:water_source"}, {["x"] = 2, ["meta"] = {["fields"] = {}, ["inventory"] = {}}, ["y"] = 0, ["param1"] = 189, ["z"] = 75, ["name"] = "default:water_source"}, {["x"] = 2, ["meta"] = {["fields"] = {}, ["inventory"] = {}}, ["y"] = 0, ["param1"] = 205, ["z"] = 76, ["name"] = "default:water_source"}, {["x"] = 2, ["meta"] = {["fields"] = {}, ["inventory"] = {}}, ["y"] = 0, ["param1"] = 221, ["z"] = 77, ["name"] = "default:water_source"}, {["x"] = 2, ["meta"] = {["fields"] = {}, ["inventory"] = {}}, ["y"] = 0, ["param1"] = 15, ["z"] = 78, ["name"] = "stained_glass:6_5_7"}, {["x"] = 3, ["meta"] = {["fields"] = {}, ["inventory"] = {}}, ["y"] = 0, ["param1"] = 13, ["z"] = 0, ["name"] = "default:water_source"}, {["x"] = 3, ["meta"] = {["fields"] = {}, ["inventory"] = {}}, ["y"] = 0, ["param1"] = 13, ["z"] = 1, ["name"] = "default:water_source"}, {["x"] = 3, ["meta"] = {["fields"] = {}, ["inventory"] = {}}, ["y"] = 0, ["param1"] = 13, ["z"] = 2, ["name"] = "default:water_source"}, {["x"] = 3, ["meta"] = {["fields"] = {}, ["inventory"] = {}}, ["y"] = 0, ["param1"] = 13, ["z"] = 3, ["name"] = "default:water_source"}, {["x"] = 3, ["meta"] = {["fields"] = {}, ["inventory"] = {}}, ["y"] = 0, ["param1"] = 13, ["z"] = 4, ["name"] = "default:water_source"}, {["x"] = 3, ["meta"] = {["fields"] = {}, ["inventory"] = {}}, ["y"] = 0, ["param1"] = 13, ["z"] = 5, ["name"] = "default:water_source"}, {["x"] = 3, ["meta"] = {["fields"] = {}, ["inventory"] = {}}, ["y"] = 0, ["param1"] = 13, ["z"] = 6, ["name"] = "default:water_source"}, {["x"] = 3, ["meta"] = {["fields"] = {}, ["inventory"] = {}}, ["y"] = 0, ["param1"] = 13, ["z"] = 7, ["name"] = "default:water_source"}, {["x"] = 3, ["meta"] = {["fields"] = {}, ["inventory"] = {}}, ["y"] = 0, ["param1"] = 13, ["z"] = 8, ["name"] = "default:water_source"}, {["x"] = 3, ["meta"] = {["fields"] = {}, ["inventory"] = {}}, ["y"] = 0, ["param1"] = 13, ["z"] = 9, ["name"] = "default:water_source"}, {["x"] = 3, ["meta"] = {["fields"] = {}, ["inventory"] = {}}, ["y"] = 0, ["param1"] = 13, ["z"] = 10, ["name"] = "default:water_source"}, {["x"] = 3, ["meta"] = {["fields"] = {}, ["inventory"] = {}}, ["y"] = 0, ["param1"] = 13, ["z"] = 11, ["name"] = "default:water_source"}, {["x"] = 3, ["meta"] = {["fields"] = {}, ["inventory"] = {}}, ["y"] = 0, ["param1"] = 13, ["z"] = 12, ["name"] = "default:water_source"}, {["x"] = 3, ["meta"] = {["fields"] = {}, ["inventory"] = {}}, ["y"] = 0, ["param1"] = 13, ["z"] = 13, ["name"] = "default:water_source"}, {["x"] = 3, ["meta"] = {["fields"] = {}, ["inventory"] = {}}, ["y"] = 0, ["param1"] = 13, ["z"] = 14, ["name"] = "default:water_source"}, {["x"] = 3, ["meta"] = {["fields"] = {}, ["inventory"] = {}}, ["y"] = 0, ["param1"] = 13, ["z"] = 15, ["name"] = "default:water_source"}, {["x"] = 3, ["meta"] = {["fields"] = {}, ["inventory"] = {}}, ["y"] = 0, ["param1"] = 13, ["z"] = 16, ["name"] = "default:water_source"}, {["x"] = 3, ["meta"] = {["fields"] = {}, ["inventory"] = {}}, ["y"] = 0, ["param1"] = 13, ["z"] = 17, ["name"] = "default:water_source"}, {["x"] = 3, ["meta"] = {["fields"] = {}, ["inventory"] = {}}, ["y"] = 0, ["param1"] = 13, ["z"] = 18, ["name"] = "default:water_source"}, {["x"] = 3, ["meta"] = {["fields"] = {}, ["inventory"] = {}}, ["y"] = 0, ["param1"] = 13, ["z"] = 19, ["name"] = "default:water_source"}, {["x"] = 3, ["meta"] = {["fields"] = {}, ["inventory"] = {}}, ["y"] = 0, ["param1"] = 13, ["z"] = 20, ["name"] = "default:water_source"}, {["x"] = 3, ["meta"] = {["fields"] = {}, ["inventory"] = {}}, ["y"] = 0, ["param1"] = 13, ["z"] = 21, ["name"] = "default:water_source"}, {["x"] = 3, ["meta"] = {["fields"] = {}, ["inventory"] = {}}, ["y"] = 0, ["param1"] = 13, ["z"] = 22, ["name"] = "default:water_source"}, {["x"] = 3, ["meta"] = {["fields"] = {}, ["inventory"] = {}}, ["y"] = 0, ["param1"] = 13, ["z"] = 23, ["name"] = "default:water_source"}, {["x"] = 3, ["meta"] = {["fields"] = {}, ["inventory"] = {}}, ["y"] = 0, ["param1"] = 13, ["z"] = 24, ["name"] = "default:water_source"}, {["x"] = 3, ["meta"] = {["fields"] = {}, ["inventory"] = {}}, ["y"] = 0, ["param1"] = 13, ["z"] = 25, ["name"] = "default:water_source"}, {["x"] = 3, ["meta"] = {["fields"] = {}, ["inventory"] = {}}, ["y"] = 0, ["param1"] = 13, ["z"] = 26, ["name"] = "default:water_source"}, {["x"] = 3, ["meta"] = {["fields"] = {}, ["inventory"] = {}}, ["y"] = 0, ["param1"] = 13, ["z"] = 27, ["name"] = "default:water_source"}, {["x"] = 3, ["meta"] = {["fields"] = {}, ["inventory"] = {}}, ["y"] = 0, ["param1"] = 13, ["z"] = 28, ["name"] = "default:water_source"}, {["x"] = 3, ["meta"] = {["fields"] = {}, ["inventory"] = {}}, ["y"] = 0, ["param1"] = 13, ["z"] = 29, ["name"] = "default:water_source"}, {["x"] = 3, ["meta"] = {["fields"] = {}, ["inventory"] = {}}, ["y"] = 0, ["param1"] = 13, ["z"] = 30, ["name"] = "default:water_source"}, {["x"] = 3, ["meta"] = {["fields"] = {}, ["inventory"] = {}}, ["y"] = 0, ["param1"] = 13, ["z"] = 31, ["name"] = "default:water_source"}, {["x"] = 3, ["meta"] = {["fields"] = {}, ["inventory"] = {}}, ["y"] = 0, ["param1"] = 13, ["z"] = 32, ["name"] = "default:water_source"}, {["x"] = 3, ["meta"] = {["fields"] = {}, ["inventory"] = {}}, ["y"] = 0, ["param1"] = 12, ["z"] = 33, ["name"] = "default:water_source"}, {["x"] = 3, ["meta"] = {["fields"] = {}, ["inventory"] = {}}, ["y"] = 0, ["param1"] = 12, ["z"] = 34, ["name"] = "default:water_source"}, {["x"] = 3, ["meta"] = {["fields"] = {}, ["inventory"] = {}}, ["y"] = 0, ["param1"] = 12, ["z"] = 35, ["name"] = "default:water_source"}, {["x"] = 3, ["meta"] = {["fields"] = {}, ["inventory"] = {}}, ["y"] = 0, ["param1"] = 12, ["z"] = 36, ["name"] = "default:water_source"}, {["x"] = 3, ["meta"] = {["fields"] = {}, ["inventory"] = {}}, ["y"] = 0, ["param1"] = 12, ["z"] = 37, ["name"] = "default:water_source"}, {["x"] = 3, ["meta"] = {["fields"] = {}, ["inventory"] = {}}, ["y"] = 0, ["param1"] = 12, ["z"] = 38, ["name"] = "default:water_source"}, {["x"] = 3, ["meta"] = {["fields"] = {}, ["inventory"] = {}}, ["y"] = 0, ["param1"] = 12, ["z"] = 39, ["name"] = "default:water_source"}, {["x"] = 3, ["meta"] = {["fields"] = {}, ["inventory"] = {}}, ["y"] = 0, ["param1"] = 13, ["z"] = 40, ["name"] = "default:water_source"}, {["x"] = 3, ["meta"] = {["fields"] = {}, ["inventory"] = {}}, ["y"] = 0, ["param1"] = 13, ["z"] = 41, ["name"] = "default:water_source"}, {["x"] = 3, ["meta"] = {["fields"] = {}, ["inventory"] = {}}, ["y"] = 0, ["param1"] = 13, ["z"] = 42, ["name"] = "default:water_source"}, {["x"] = 3, ["meta"] = {["fields"] = {}, ["inventory"] = {}}, ["y"] = 0, ["param1"] = 13, ["z"] = 43, ["name"] = "default:water_source"}, {["x"] = 3, ["meta"] = {["fields"] = {}, ["inventory"] = {}}, ["y"] = 0, ["param1"] = 13, ["z"] = 44, ["name"] = "default:water_source"}, {["x"] = 3, ["meta"] = {["fields"] = {}, ["inventory"] = {}}, ["y"] = 0, ["param1"] = 13, ["z"] = 45, ["name"] = "default:water_source"}, {["x"] = 3, ["meta"] = {["fields"] = {}, ["inventory"] = {}}, ["y"] = 0, ["param1"] = 13, ["z"] = 46, ["name"] = "default:water_source"}, {["x"] = 3, ["meta"] = {["fields"] = {}, ["inventory"] = {}}, ["y"] = 0, ["param1"] = 13, ["z"] = 47, ["name"] = "default:water_source"}, {["x"] = 3, ["meta"] = {["fields"] = {}, ["inventory"] = {}}, ["y"] = 0, ["param1"] = 13, ["z"] = 48, ["name"] = "default:water_source"}, {["x"] = 3, ["meta"] = {["fields"] = {}, ["inventory"] = {}}, ["y"] = 0, ["param1"] = 13, ["z"] = 49, ["name"] = "default:water_source"}, {["x"] = 3, ["meta"] = {["fields"] = {}, ["inventory"] = {}}, ["y"] = 0, ["param1"] = 13, ["z"] = 50, ["name"] = "default:water_source"}, {["x"] = 3, ["meta"] = {["fields"] = {}, ["inventory"] = {}}, ["y"] = 0, ["param1"] = 13, ["z"] = 51, ["name"] = "default:water_source"}, {["x"] = 3, ["meta"] = {["fields"] = {}, ["inventory"] = {}}, ["y"] = 0, ["param1"] = 13, ["z"] = 52, ["name"] = "default:water_source"}, {["x"] = 3, ["meta"] = {["fields"] = {}, ["inventory"] = {}}, ["y"] = 0, ["param1"] = 13, ["z"] = 53, ["name"] = "default:water_source"}, {["x"] = 3, ["meta"] = {["fields"] = {}, ["inventory"] = {}}, ["y"] = 0, ["param1"] = 13, ["z"] = 54, ["name"] = "default:water_source"}, {["x"] = 3, ["meta"] = {["fields"] = {}, ["inventory"] = {}}, ["y"] = 0, ["param1"] = 13, ["z"] = 55, ["name"] = "default:water_source"}, {["x"] = 3, ["meta"] = {["fields"] = {}, ["inventory"] = {}}, ["y"] = 0, ["param1"] = 13, ["z"] = 56, ["name"] = "default:water_source"}, {["x"] = 3, ["meta"] = {["fields"] = {}, ["inventory"] = {}}, ["y"] = 0, ["param1"] = 13, ["z"] = 57, ["name"] = "default:water_source"}, {["x"] = 3, ["meta"] = {["fields"] = {}, ["inventory"] = {}}, ["y"] = 0, ["param1"] = 13, ["z"] = 58, ["name"] = "default:water_source"}, {["x"] = 3, ["meta"] = {["fields"] = {}, ["inventory"] = {}}, ["y"] = 0, ["param1"] = 13, ["z"] = 59, ["name"] = "default:water_source"}, {["x"] = 3, ["meta"] = {["fields"] = {}, ["inventory"] = {}}, ["y"] = 0, ["param1"] = 13, ["z"] = 60, ["name"] = "default:water_source"}, {["x"] = 3, ["meta"] = {["fields"] = {}, ["inventory"] = {}}, ["y"] = 0, ["param1"] = 13, ["z"] = 61, ["name"] = "default:water_source"}, {["x"] = 3, ["meta"] = {["fields"] = {}, ["inventory"] = {}}, ["y"] = 0, ["param1"] = 13, ["z"] = 62, ["name"] = "default:water_source"}, {["x"] = 3, ["meta"] = {["fields"] = {}, ["inventory"] = {}}, ["y"] = 0, ["param1"] = 13, ["z"] = 63, ["name"] = "default:water_source"}, {["x"] = 3, ["meta"] = {["fields"] = {}, ["inventory"] = {}}, ["y"] = 0, ["param1"] = 13, ["z"] = 64, ["name"] = "default:water_source"}, {["x"] = 3, ["meta"] = {["fields"] = {}, ["inventory"] = {}}, ["y"] = 0, ["param1"] = 29, ["z"] = 65, ["name"] = "default:water_source"}, {["x"] = 3, ["meta"] = {["fields"] = {}, ["inventory"] = {}}, ["y"] = 0, ["param1"] = 45, ["z"] = 66, ["name"] = "default:water_source"}, {["x"] = 3, ["meta"] = {["fields"] = {}, ["inventory"] = {}}, ["y"] = 0, ["param1"] = 61, ["z"] = 67, ["name"] = "default:water_source"}, {["x"] = 3, ["meta"] = {["fields"] = {}, ["inventory"] = {}}, ["y"] = 0, ["param1"] = 77, ["z"] = 68, ["name"] = "default:water_source"}, {["x"] = 3, ["meta"] = {["fields"] = {}, ["inventory"] = {}}, ["y"] = 0, ["param1"] = 93, ["z"] = 69, ["name"] = "default:water_source"}, {["x"] = 3, ["meta"] = {["fields"] = {}, ["inventory"] = {}}, ["y"] = 0, ["param1"] = 109, ["z"] = 70, ["name"] = "default:water_source"}, {["x"] = 3, ["meta"] = {["fields"] = {}, ["inventory"] = {}}, ["y"] = 0, ["param1"] = 125, ["z"] = 71, ["name"] = "default:water_source"}, {["x"] = 3, ["meta"] = {["fields"] = {}, ["inventory"] = {}}, ["y"] = 0, ["param1"] = 141, ["z"] = 72, ["name"] = "default:water_source"}, {["x"] = 3, ["meta"] = {["fields"] = {}, ["inventory"] = {}}, ["y"] = 0, ["param1"] = 157, ["z"] = 73, ["name"] = "default:water_source"}, {["x"] = 3, ["meta"] = {["fields"] = {}, ["inventory"] = {}}, ["y"] = 0, ["param1"] = 173, ["z"] = 74, ["name"] = "default:water_source"}, {["x"] = 3, ["meta"] = {["fields"] = {}, ["inventory"] = {}}, ["y"] = 0, ["param1"] = 189, ["z"] = 75, ["name"] = "default:water_source"}, {["x"] = 3, ["meta"] = {["fields"] = {}, ["inventory"] = {}}, ["y"] = 0, ["param1"] = 205, ["z"] = 76, ["name"] = "default:water_source"}, {["x"] = 3, ["meta"] = {["fields"] = {}, ["inventory"] = {}}, ["y"] = 0, ["param1"] = 221, ["z"] = 77, ["name"] = "default:water_source"}, {["x"] = 3, ["meta"] = {["fields"] = {}, ["inventory"] = {}}, ["y"] = 0, ["param1"] = 15, ["z"] = 78, ["name"] = "stained_glass:6_5_7"}, {["x"] = 3, ["meta"] = {["fields"] = {}, ["inventory"] = {}}, ["y"] = 25, ["param1"] = 207, ["z"] = 33, ["name"] = "default:steelblock"}, {["x"] = 3, ["meta"] = {["fields"] = {}, ["inventory"] = {}}, ["y"] = 25, ["param1"] = 207, ["z"] = 34, ["name"] = "default:steelblock"}, {["x"] = 3, ["meta"] = {["fields"] = {}, ["inventory"] = {}}, ["y"] = 25, ["param1"] = 207, ["z"] = 35, ["name"] = "default:steelblock"}, {["x"] = 3, ["meta"] = {["fields"] = {}, ["inventory"] = {}}, ["y"] = 25, ["param1"] = 207, ["z"] = 36, ["name"] = "default:steelblock"}, {["x"] = 3, ["meta"] = {["fields"] = {}, ["inventory"] = {}}, ["y"] = 25, ["param1"] = 207, ["z"] = 37, ["name"] = "default:steelblock"}, {["x"] = 3, ["meta"] = {["fields"] = {}, ["inventory"] = {}}, ["y"] = 25, ["param1"] = 207, ["z"] = 38, ["name"] = "default:steelblock"}, {["x"] = 3, ["meta"] = {["fields"] = {}, ["inventory"] = {}}, ["y"] = 25, ["param1"] = 207, ["z"] = 39, ["name"] = "default:steelblock"}, {["x"] = 3, ["meta"] = {["fields"] = {}, ["inventory"] = {}}, ["y"] = 26, ["param1"] = 223, ["z"] = 33, ["name"] = "default:steelblock"}, {["x"] = 3, ["meta"] = {["fields"] = {}, ["inventory"] = {}}, ["y"] = 26, ["param1"] = 223, ["z"] = 34, ["name"] = "default:steelblock"}, {["x"] = 3, ["meta"] = {["fields"] = {}, ["inventory"] = {}}, ["y"] = 26, ["param1"] = 223, ["z"] = 35, ["name"] = "default:steelblock"}, {["x"] = 3, ["meta"] = {["fields"] = {}, ["inventory"] = {}}, ["y"] = 26, ["param1"] = 223, ["z"] = 36, ["name"] = "default:steelblock"}, {["x"] = 3, ["meta"] = {["fields"] = {}, ["inventory"] = {}}, ["y"] = 26, ["param1"] = 223, ["z"] = 37, ["name"] = "default:steelblock"}, {["x"] = 3, ["meta"] = {["fields"] = {}, ["inventory"] = {}}, ["y"] = 26, ["param1"] = 223, ["z"] = 38, ["name"] = "default:steelblock"}, {["x"] = 3, ["meta"] = {["fields"] = {}, ["inventory"] = {}}, ["y"] = 26, ["param1"] = 223, ["z"] = 39, ["name"] = "default:steelblock"}, {["x"] = 3, ["meta"] = {["fields"] = {}, ["inventory"] = {}}, ["y"] = 27, ["param1"] = 207, ["z"] = 33, ["name"] = "default:steelblock"}, {["x"] = 3, ["meta"] = {["fields"] = {}, ["inventory"] = {}}, ["y"] = 27, ["param1"] = 207, ["z"] = 34, ["name"] = "default:steelblock"}, {["x"] = 3, ["meta"] = {["fields"] = {}, ["inventory"] = {}}, ["y"] = 27, ["param1"] = 207, ["z"] = 35, ["name"] = "default:steelblock"}, {["x"] = 3, ["meta"] = {["fields"] = {}, ["inventory"] = {}}, ["y"] = 27, ["param1"] = 207, ["z"] = 36, ["name"] = "default:steelblock"}, {["x"] = 3, ["meta"] = {["fields"] = {}, ["inventory"] = {}}, ["y"] = 27, ["param1"] = 207, ["z"] = 37, ["name"] = "default:steelblock"}, {["x"] = 3, ["meta"] = {["fields"] = {}, ["inventory"] = {}}, ["y"] = 27, ["param1"] = 207, ["z"] = 38, ["name"] = "default:steelblock"}, {["x"] = 3, ["meta"] = {["fields"] = {}, ["inventory"] = {}}, ["y"] = 27, ["param1"] = 207, ["z"] = 39, ["name"] = "default:steelblock"}, {["x"] = 3, ["meta"] = {["fields"] = {}, ["inventory"] = {}}, ["y"] = 28, ["param1"] = 191, ["z"] = 33, ["name"] = "default:steelblock"}, {["x"] = 3, ["meta"] = {["fields"] = {}, ["inventory"] = {}}, ["y"] = 28, ["param1"] = 191, ["z"] = 34, ["name"] = "default:steelblock"}, {["x"] = 3, ["meta"] = {["fields"] = {}, ["inventory"] = {}}, ["y"] = 28, ["param1"] = 191, ["z"] = 35, ["name"] = "default:steelblock"}, {["x"] = 3, ["meta"] = {["fields"] = {}, ["inventory"] = {}}, ["y"] = 28, ["param1"] = 191, ["z"] = 36, ["name"] = "default:steelblock"}, {["x"] = 3, ["meta"] = {["fields"] = {}, ["inventory"] = {}}, ["y"] = 28, ["param1"] = 191, ["z"] = 37, ["name"] = "default:steelblock"}, {["x"] = 3, ["meta"] = {["fields"] = {}, ["inventory"] = {}}, ["y"] = 28, ["param1"] = 191, ["z"] = 38, ["name"] = "default:steelblock"}, {["x"] = 3, ["meta"] = {["fields"] = {}, ["inventory"] = {}}, ["y"] = 28, ["param1"] = 191, ["z"] = 39, ["name"] = "default:steelblock"}, {["x"] = 3, ["meta"] = {["fields"] = {}, ["inventory"] = {}}, ["y"] = 29, ["param1"] = 175, ["z"] = 33, ["name"] = "default:steelblock"}, {["x"] = 3, ["meta"] = {["fields"] = {}, ["inventory"] = {}}, ["y"] = 29, ["param1"] = 175, ["z"] = 34, ["name"] = "default:steelblock"}, {["x"] = 3, ["meta"] = {["fields"] = {}, ["inventory"] = {}}, ["y"] = 29, ["param1"] = 175, ["z"] = 35, ["name"] = "default:steelblock"}, {["x"] = 3, ["meta"] = {["fields"] = {}, ["inventory"] = {}}, ["y"] = 29, ["param1"] = 175, ["z"] = 36, ["name"] = "default:steelblock"}, {["x"] = 3, ["meta"] = {["fields"] = {}, ["inventory"] = {}}, ["y"] = 29, ["param1"] = 175, ["z"] = 37, ["name"] = "default:steelblock"}, {["x"] = 3, ["meta"] = {["fields"] = {}, ["inventory"] = {}}, ["y"] = 29, ["param1"] = 175, ["z"] = 38, ["name"] = "default:steelblock"}, {["x"] = 3, ["meta"] = {["fields"] = {}, ["inventory"] = {}}, ["y"] = 29, ["param1"] = 175, ["z"] = 39, ["name"] = "default:steelblock"}, {["x"] = 3, ["meta"] = {["fields"] = {}, ["inventory"] = {}}, ["y"] = 30, ["param1"] = 159, ["z"] = 33, ["name"] = "default:steelblock"}, {["x"] = 3, ["meta"] = {["fields"] = {}, ["inventory"] = {}}, ["y"] = 30, ["param1"] = 159, ["z"] = 34, ["name"] = "default:steelblock"}, {["x"] = 3, ["meta"] = {["fields"] = {}, ["inventory"] = {}}, ["y"] = 30, ["param1"] = 159, ["z"] = 35, ["name"] = "default:steelblock"}, {["x"] = 3, ["meta"] = {["fields"] = {}, ["inventory"] = {}}, ["y"] = 30, ["param1"] = 159, ["z"] = 36, ["name"] = "default:steelblock"}, {["x"] = 3, ["meta"] = {["fields"] = {}, ["inventory"] = {}}, ["y"] = 30, ["param1"] = 159, ["z"] = 37, ["name"] = "default:steelblock"}, {["x"] = 3, ["meta"] = {["fields"] = {}, ["inventory"] = {}}, ["y"] = 30, ["param1"] = 159, ["z"] = 38, ["name"] = "default:steelblock"}, {["x"] = 3, ["meta"] = {["fields"] = {}, ["inventory"] = {}}, ["y"] = 30, ["param1"] = 159, ["z"] = 39, ["name"] = "default:steelblock"}, {["x"] = 3, ["meta"] = {["fields"] = {}, ["inventory"] = {}}, ["y"] = 31, ["param1"] = 143, ["z"] = 33, ["name"] = "default:steelblock"}, {["x"] = 3, ["meta"] = {["fields"] = {}, ["inventory"] = {}}, ["y"] = 31, ["param1"] = 143, ["z"] = 34, ["name"] = "default:steelblock"}, {["x"] = 3, ["meta"] = {["fields"] = {}, ["inventory"] = {}}, ["y"] = 31, ["param1"] = 143, ["z"] = 35, ["name"] = "default:steelblock"}, {["x"] = 3, ["meta"] = {["fields"] = {}, ["inventory"] = {}}, ["y"] = 31, ["param1"] = 143, ["z"] = 36, ["name"] = "default:steelblock"}, {["x"] = 3, ["meta"] = {["fields"] = {}, ["inventory"] = {}}, ["y"] = 31, ["param1"] = 143, ["z"] = 37, ["name"] = "default:steelblock"}, {["x"] = 3, ["meta"] = {["fields"] = {}, ["inventory"] = {}}, ["y"] = 31, ["param1"] = 143, ["z"] = 38, ["name"] = "default:steelblock"}, {["x"] = 3, ["meta"] = {["fields"] = {}, ["inventory"] = {}}, ["y"] = 31, ["param1"] = 143, ["z"] = 39, ["name"] = "default:steelblock"}, {["x"] = 3, ["meta"] = {["fields"] = {}, ["inventory"] = {}}, ["y"] = 32, ["param1"] = 127, ["z"] = 33, ["name"] = "default:steelblock"}, {["x"] = 3, ["meta"] = {["fields"] = {}, ["inventory"] = {}}, ["y"] = 32, ["param1"] = 127, ["z"] = 34, ["name"] = "default:steelblock"}, {["x"] = 3, ["meta"] = {["fields"] = {}, ["inventory"] = {}}, ["y"] = 32, ["param1"] = 127, ["z"] = 35, ["name"] = "default:steelblock"}, {["x"] = 3, ["meta"] = {["fields"] = {}, ["inventory"] = {}}, ["y"] = 32, ["param1"] = 127, ["z"] = 36, ["name"] = "default:steelblock"}, {["x"] = 3, ["meta"] = {["fields"] = {}, ["inventory"] = {}}, ["y"] = 32, ["param1"] = 127, ["z"] = 37, ["name"] = "default:steelblock"}, {["x"] = 3, ["meta"] = {["fields"] = {}, ["inventory"] = {}}, ["y"] = 32, ["param1"] = 127, ["z"] = 38, ["name"] = "default:steelblock"}, {["x"] = 3, ["meta"] = {["fields"] = {}, ["inventory"] = {}}, ["y"] = 32, ["param1"] = 127, ["z"] = 39, ["name"] = "default:steelblock"}, {["x"] = 3, ["meta"] = {["fields"] = {}, ["inventory"] = {}}, ["y"] = 33, ["param1"] = 127, ["z"] = 33, ["name"] = "default:steelblock"}, {["x"] = 3, ["meta"] = {["fields"] = {}, ["inventory"] = {}}, ["y"] = 33, ["param1"] = 111, ["z"] = 34, ["name"] = "default:steelblock"}, {["x"] = 3, ["meta"] = {["fields"] = {}, ["inventory"] = {}}, ["y"] = 33, ["param1"] = 111, ["z"] = 35, ["name"] = "default:steelblock"}, {["x"] = 3, ["meta"] = {["fields"] = {}, ["inventory"] = {}}, ["y"] = 33, ["param1"] = 111, ["z"] = 36, ["name"] = "default:steelblock"}, {["x"] = 3, ["meta"] = {["fields"] = {}, ["inventory"] = {}}, ["y"] = 33, ["param1"] = 111, ["z"] = 37, ["name"] = "default:steelblock"}, {["x"] = 3, ["meta"] = {["fields"] = {}, ["inventory"] = {}}, ["y"] = 33, ["param1"] = 111, ["z"] = 38, ["name"] = "default:steelblock"}, {["x"] = 3, ["meta"] = {["fields"] = {}, ["inventory"] = {}}, ["y"] = 33, ["param1"] = 127, ["z"] = 39, ["name"] = "default:steelblock"}, {["x"] = 3, ["meta"] = {["fields"] = {}, ["inventory"] = {}}, ["y"] = 34, ["param1"] = 127, ["z"] = 33, ["name"] = "default:steelblock"}, {["x"] = 3, ["meta"] = {["fields"] = {}, ["inventory"] = {}}, ["y"] = 34, ["param1"] = 111, ["z"] = 34, ["name"] = "default:steelblock"}, {["x"] = 3, ["meta"] = {["fields"] = {}, ["inventory"] = {}}, ["y"] = 34, ["param1"] = 95, ["z"] = 35, ["name"] = "default:steelblock"}, {["x"] = 3, ["meta"] = {["fields"] = {}, ["inventory"] = {}}, ["y"] = 34, ["param1"] = 95, ["z"] = 36, ["name"] = "default:steelblock"}, {["x"] = 3, ["meta"] = {["fields"] = {}, ["inventory"] = {}}, ["y"] = 34, ["param1"] = 95, ["z"] = 37, ["name"] = "default:steelblock"}, {["x"] = 3, ["meta"] = {["fields"] = {}, ["inventory"] = {}}, ["y"] = 34, ["param1"] = 111, ["z"] = 38, ["name"] = "default:steelblock"}, {["x"] = 3, ["meta"] = {["fields"] = {}, ["inventory"] = {}}, ["y"] = 34, ["param1"] = 127, ["z"] = 39, ["name"] = "default:steelblock"}, {["x"] = 3, ["meta"] = {["fields"] = {}, ["inventory"] = {}}, ["y"] = 35, ["param1"] = 127, ["z"] = 33, ["name"] = "default:steelblock"}, {["x"] = 3, ["meta"] = {["fields"] = {}, ["inventory"] = {}}, ["y"] = 35, ["param1"] = 111, ["z"] = 34, ["name"] = "default:steelblock"}, {["x"] = 3, ["meta"] = {["fields"] = {}, ["inventory"] = {}}, ["y"] = 35, ["param1"] = 95, ["z"] = 35, ["name"] = "default:steelblock"}, {["x"] = 3, ["meta"] = {["fields"] = {}, ["inventory"] = {}}, ["y"] = 35, ["param1"] = 79, ["z"] = 36, ["name"] = "default:steelblock"}, {["x"] = 3, ["meta"] = {["fields"] = {}, ["inventory"] = {}}, ["y"] = 35, ["param1"] = 95, ["z"] = 37, ["name"] = "default:steelblock"}, {["x"] = 3, ["meta"] = {["fields"] = {}, ["inventory"] = {}}, ["y"] = 35, ["param1"] = 111, ["z"] = 38, ["name"] = "default:steelblock"}, {["x"] = 3, ["meta"] = {["fields"] = {}, ["inventory"] = {}}, ["y"] = 35, ["param1"] = 127, ["z"] = 39, ["name"] = "default:steelblock"}, {["x"] = 3, ["meta"] = {["fields"] = {}, ["inventory"] = {}}, ["y"] = 36, ["param1"] = 127, ["z"] = 33, ["name"] = "default:steelblock"}, {["x"] = 3, ["meta"] = {["fields"] = {}, ["inventory"] = {}}, ["y"] = 36, ["param1"] = 111, ["z"] = 34, ["name"] = "default:steelblock"}, {["x"] = 3, ["meta"] = {["fields"] = {}, ["inventory"] = {}}, ["y"] = 36, ["param1"] = 95, ["z"] = 35, ["name"] = "default:steelblock"}, {["x"] = 3, ["meta"] = {["fields"] = {}, ["inventory"] = {}}, ["y"] = 36, ["param1"] = 79, ["z"] = 36, ["name"] = "default:steelblock"}, {["x"] = 3, ["meta"] = {["fields"] = {}, ["inventory"] = {}}, ["y"] = 36, ["param1"] = 95, ["z"] = 37, ["name"] = "default:steelblock"}, {["x"] = 3, ["meta"] = {["fields"] = {}, ["inventory"] = {}}, ["y"] = 36, ["param1"] = 111, ["z"] = 38, ["name"] = "default:steelblock"}, {["x"] = 3, ["meta"] = {["fields"] = {}, ["inventory"] = {}}, ["y"] = 36, ["param1"] = 127, ["z"] = 39, ["name"] = "default:steelblock"}, {["x"] = 3, ["meta"] = {["fields"] = {}, ["inventory"] = {}}, ["y"] = 37, ["param1"] = 127, ["z"] = 33, ["name"] = "default:steelblock"}, {["x"] = 3, ["meta"] = {["fields"] = {}, ["inventory"] = {}}, ["y"] = 37, ["param1"] = 111, ["z"] = 34, ["name"] = "default:steelblock"}, {["x"] = 3, ["meta"] = {["fields"] = {}, ["inventory"] = {}}, ["y"] = 37, ["param1"] = 95, ["z"] = 35, ["name"] = "default:steelblock"}, {["x"] = 3, ["meta"] = {["fields"] = {}, ["inventory"] = {}}, ["y"] = 37, ["param1"] = 79, ["z"] = 36, ["name"] = "default:steelblock"}, {["x"] = 3, ["meta"] = {["fields"] = {}, ["inventory"] = {}}, ["y"] = 37, ["param1"] = 95, ["z"] = 37, ["name"] = "default:steelblock"}, {["x"] = 3, ["meta"] = {["fields"] = {}, ["inventory"] = {}}, ["y"] = 37, ["param1"] = 111, ["z"] = 38, ["name"] = "default:steelblock"}, {["x"] = 3, ["meta"] = {["fields"] = {}, ["inventory"] = {}}, ["y"] = 37, ["param1"] = 127, ["z"] = 39, ["name"] = "default:steelblock"}, {["x"] = 3, ["meta"] = {["fields"] = {}, ["inventory"] = {}}, ["y"] = 38, ["param1"] = 127, ["z"] = 33, ["name"] = "default:steelblock"}, {["x"] = 3, ["meta"] = {["fields"] = {}, ["inventory"] = {}}, ["y"] = 38, ["param1"] = 111, ["z"] = 34, ["name"] = "default:steelblock"}, {["x"] = 3, ["meta"] = {["fields"] = {}, ["inventory"] = {}}, ["y"] = 38, ["param1"] = 95, ["z"] = 35, ["name"] = "default:steelblock"}, {["x"] = 3, ["meta"] = {["fields"] = {}, ["inventory"] = {}}, ["y"] = 38, ["param1"] = 79, ["z"] = 36, ["name"] = "default:steelblock"}, {["x"] = 3, ["meta"] = {["fields"] = {}, ["inventory"] = {}}, ["y"] = 38, ["param1"] = 95, ["z"] = 37, ["name"] = "default:steelblock"}, {["x"] = 3, ["meta"] = {["fields"] = {}, ["inventory"] = {}}, ["y"] = 38, ["param1"] = 111, ["z"] = 38, ["name"] = "default:steelblock"}, {["x"] = 3, ["meta"] = {["fields"] = {}, ["inventory"] = {}}, ["y"] = 38, ["param1"] = 127, ["z"] = 39, ["name"] = "default:steelblock"}, {["x"] = 3, ["meta"] = {["fields"] = {}, ["inventory"] = {}}, ["y"] = 39, ["param1"] = 127, ["z"] = 33, ["name"] = "default:steelblock"}, {["x"] = 3, ["meta"] = {["fields"] = {}, ["inventory"] = {}}, ["y"] = 39, ["param1"] = 111, ["z"] = 34, ["name"] = "default:steelblock"}, {["x"] = 3, ["meta"] = {["fields"] = {}, ["inventory"] = {}}, ["y"] = 39, ["param1"] = 95, ["z"] = 35, ["name"] = "default:steelblock"}, {["x"] = 3, ["meta"] = {["fields"] = {}, ["inventory"] = {}}, ["y"] = 39, ["param1"] = 79, ["z"] = 36, ["name"] = "default:steelblock"}, {["x"] = 3, ["meta"] = {["fields"] = {}, ["inventory"] = {}}, ["y"] = 39, ["param1"] = 95, ["z"] = 37, ["name"] = "default:steelblock"}, {["x"] = 3, ["meta"] = {["fields"] = {}, ["inventory"] = {}}, ["y"] = 39, ["param1"] = 111, ["z"] = 38, ["name"] = "default:steelblock"}, {["x"] = 3, ["meta"] = {["fields"] = {}, ["inventory"] = {}}, ["y"] = 39, ["param1"] = 127, ["z"] = 39, ["name"] = "default:steelblock"}, {["x"] = 3, ["meta"] = {["fields"] = {}, ["inventory"] = {}}, ["y"] = 40, ["param1"] = 127, ["z"] = 33, ["name"] = "default:steelblock"}, {["x"] = 3, ["meta"] = {["fields"] = {}, ["inventory"] = {}}, ["y"] = 40, ["param1"] = 111, ["z"] = 34, ["name"] = "default:steelblock"}, {["x"] = 3, ["meta"] = {["fields"] = {}, ["inventory"] = {}}, ["y"] = 40, ["param1"] = 95, ["z"] = 35, ["name"] = "default:steelblock"}, {["x"] = 3, ["meta"] = {["fields"] = {}, ["inventory"] = {}}, ["y"] = 40, ["param1"] = 79, ["z"] = 36, ["name"] = "default:steelblock"}, {["x"] = 3, ["meta"] = {["fields"] = {}, ["inventory"] = {}}, ["y"] = 40, ["param1"] = 95, ["z"] = 37, ["name"] = "default:steelblock"}, {["x"] = 3, ["meta"] = {["fields"] = {}, ["inventory"] = {}}, ["y"] = 40, ["param1"] = 111, ["z"] = 38, ["name"] = "default:steelblock"}, {["x"] = 3, ["meta"] = {["fields"] = {}, ["inventory"] = {}}, ["y"] = 40, ["param1"] = 127, ["z"] = 39, ["name"] = "default:steelblock"}, {["x"] = 3, ["meta"] = {["fields"] = {}, ["inventory"] = {}}, ["y"] = 41, ["param1"] = 127, ["z"] = 33, ["name"] = "default:steelblock"}, {["x"] = 3, ["meta"] = {["fields"] = {}, ["inventory"] = {}}, ["y"] = 41, ["param1"] = 111, ["z"] = 34, ["name"] = "default:steelblock"}, {["x"] = 3, ["meta"] = {["fields"] = {}, ["inventory"] = {}}, ["y"] = 41, ["param1"] = 95, ["z"] = 35, ["name"] = "default:steelblock"}, {["x"] = 3, ["meta"] = {["fields"] = {}, ["inventory"] = {}}, ["y"] = 41, ["param1"] = 79, ["z"] = 36, ["name"] = "default:steelblock"}, {["x"] = 3, ["meta"] = {["fields"] = {}, ["inventory"] = {}}, ["y"] = 41, ["param1"] = 95, ["z"] = 37, ["name"] = "default:steelblock"}, {["x"] = 3, ["meta"] = {["fields"] = {}, ["inventory"] = {}}, ["y"] = 41, ["param1"] = 111, ["z"] = 38, ["name"] = "default:steelblock"}, {["x"] = 3, ["meta"] = {["fields"] = {}, ["inventory"] = {}}, ["y"] = 41, ["param1"] = 127, ["z"] = 39, ["name"] = "default:steelblock"}, {["x"] = 3, ["meta"] = {["fields"] = {}, ["inventory"] = {}}, ["y"] = 42, ["param1"] = 127, ["z"] = 33, ["name"] = "default:steelblock"}, {["x"] = 3, ["meta"] = {["fields"] = {}, ["inventory"] = {}}, ["y"] = 42, ["param1"] = 111, ["z"] = 34, ["name"] = "default:steelblock"}, {["x"] = 3, ["meta"] = {["fields"] = {}, ["inventory"] = {}}, ["y"] = 42, ["param1"] = 95, ["z"] = 35, ["name"] = "default:steelblock"}, {["x"] = 3, ["meta"] = {["fields"] = {}, ["inventory"] = {}}, ["y"] = 42, ["param1"] = 79, ["z"] = 36, ["name"] = "default:steelblock"}, {["x"] = 3, ["meta"] = {["fields"] = {}, ["inventory"] = {}}, ["y"] = 42, ["param1"] = 95, ["z"] = 37, ["name"] = "default:steelblock"}, {["x"] = 3, ["meta"] = {["fields"] = {}, ["inventory"] = {}}, ["y"] = 42, ["param1"] = 111, ["z"] = 38, ["name"] = "default:steelblock"}, {["x"] = 3, ["meta"] = {["fields"] = {}, ["inventory"] = {}}, ["y"] = 42, ["param1"] = 127, ["z"] = 39, ["name"] = "default:steelblock"}, {["x"] = 3, ["meta"] = {["fields"] = {}, ["inventory"] = {}}, ["y"] = 43, ["param1"] = 127, ["z"] = 33, ["name"] = "default:steelblock"}, {["x"] = 3, ["meta"] = {["fields"] = {}, ["inventory"] = {}}, ["y"] = 43, ["param1"] = 111, ["z"] = 34, ["name"] = "default:steelblock"}, {["x"] = 3, ["meta"] = {["fields"] = {}, ["inventory"] = {}}, ["y"] = 43, ["param1"] = 95, ["z"] = 35, ["name"] = "default:steelblock"}, {["x"] = 3, ["meta"] = {["fields"] = {}, ["inventory"] = {}}, ["y"] = 43, ["param1"] = 79, ["z"] = 36, ["name"] = "default:steelblock"}, {["x"] = 3, ["meta"] = {["fields"] = {}, ["inventory"] = {}}, ["y"] = 43, ["param1"] = 95, ["z"] = 37, ["name"] = "default:steelblock"}, {["x"] = 3, ["meta"] = {["fields"] = {}, ["inventory"] = {}}, ["y"] = 43, ["param1"] = 111, ["z"] = 38, ["name"] = "default:steelblock"}, {["x"] = 3, ["meta"] = {["fields"] = {}, ["inventory"] = {}}, ["y"] = 43, ["param1"] = 127, ["z"] = 39, ["name"] = "default:steelblock"}, {["x"] = 3, ["meta"] = {["fields"] = {}, ["inventory"] = {}}, ["y"] = 44, ["param1"] = 127, ["z"] = 33, ["name"] = "default:steelblock"}, {["x"] = 3, ["meta"] = {["fields"] = {}, ["inventory"] = {}}, ["y"] = 44, ["param1"] = 111, ["z"] = 34, ["name"] = "default:steelblock"}, {["x"] = 3, ["meta"] = {["fields"] = {}, ["inventory"] = {}}, ["y"] = 44, ["param1"] = 95, ["z"] = 35, ["name"] = "default:steelblock"}, {["x"] = 3, ["meta"] = {["fields"] = {}, ["inventory"] = {}}, ["y"] = 44, ["param1"] = 79, ["z"] = 36, ["name"] = "default:steelblock"}, {["x"] = 3, ["meta"] = {["fields"] = {}, ["inventory"] = {}}, ["y"] = 44, ["param1"] = 95, ["z"] = 37, ["name"] = "default:steelblock"}, {["x"] = 3, ["meta"] = {["fields"] = {}, ["inventory"] = {}}, ["y"] = 44, ["param1"] = 111, ["z"] = 38, ["name"] = "default:steelblock"}, {["x"] = 3, ["meta"] = {["fields"] = {}, ["inventory"] = {}}, ["y"] = 44, ["param1"] = 127, ["z"] = 39, ["name"] = "default:steelblock"}, {["x"] = 3, ["meta"] = {["fields"] = {}, ["inventory"] = {}}, ["y"] = 45, ["param1"] = 127, ["z"] = 33, ["name"] = "default:steelblock"}, {["x"] = 3, ["meta"] = {["fields"] = {}, ["inventory"] = {}}, ["y"] = 45, ["param1"] = 111, ["z"] = 34, ["name"] = "default:steelblock"}, {["x"] = 3, ["meta"] = {["fields"] = {}, ["inventory"] = {}}, ["y"] = 45, ["param1"] = 95, ["z"] = 35, ["name"] = "default:steelblock"}, {["x"] = 3, ["meta"] = {["fields"] = {}, ["inventory"] = {}}, ["y"] = 45, ["param1"] = 79, ["z"] = 36, ["name"] = "default:steelblock"}, {["x"] = 3, ["meta"] = {["fields"] = {}, ["inventory"] = {}}, ["y"] = 45, ["param1"] = 95, ["z"] = 37, ["name"] = "default:steelblock"}, {["x"] = 3, ["meta"] = {["fields"] = {}, ["inventory"] = {}}, ["y"] = 45, ["param1"] = 111, ["z"] = 38, ["name"] = "default:steelblock"}, {["x"] = 3, ["meta"] = {["fields"] = {}, ["inventory"] = {}}, ["y"] = 45, ["param1"] = 127, ["z"] = 39, ["name"] = "default:steelblock"}, {["x"] = 3, ["meta"] = {["fields"] = {}, ["inventory"] = {}}, ["y"] = 46, ["param1"] = 127, ["z"] = 33, ["name"] = "default:steelblock"}, {["x"] = 3, ["meta"] = {["fields"] = {}, ["inventory"] = {}}, ["y"] = 46, ["param1"] = 111, ["z"] = 34, ["name"] = "default:steelblock"}, {["x"] = 3, ["meta"] = {["fields"] = {}, ["inventory"] = {}}, ["y"] = 46, ["param1"] = 95, ["z"] = 35, ["name"] = "default:steelblock"}, {["x"] = 3, ["meta"] = {["fields"] = {}, ["inventory"] = {}}, ["y"] = 46, ["param1"] = 79, ["z"] = 36, ["name"] = "default:steelblock"}, {["x"] = 3, ["meta"] = {["fields"] = {}, ["inventory"] = {}}, ["y"] = 46, ["param1"] = 95, ["z"] = 37, ["name"] = "default:steelblock"}, {["x"] = 3, ["meta"] = {["fields"] = {}, ["inventory"] = {}}, ["y"] = 46, ["param1"] = 111, ["z"] = 38, ["name"] = "default:steelblock"}, {["x"] = 3, ["meta"] = {["fields"] = {}, ["inventory"] = {}}, ["y"] = 46, ["param1"] = 127, ["z"] = 39, ["name"] = "default:steelblock"}, {["x"] = 3, ["meta"] = {["fields"] = {}, ["inventory"] = {}}, ["y"] = 47, ["param1"] = 127, ["z"] = 33, ["name"] = "default:steelblock"}, {["x"] = 3, ["meta"] = {["fields"] = {}, ["inventory"] = {}}, ["y"] = 47, ["param1"] = 111, ["z"] = 34, ["name"] = "default:steelblock"}, {["x"] = 3, ["meta"] = {["fields"] = {}, ["inventory"] = {}}, ["y"] = 47, ["param1"] = 95, ["z"] = 35, ["name"] = "default:steelblock"}, {["x"] = 3, ["meta"] = {["fields"] = {}, ["inventory"] = {}}, ["y"] = 47, ["param1"] = 79, ["z"] = 36, ["name"] = "default:steelblock"}, {["x"] = 3, ["meta"] = {["fields"] = {}, ["inventory"] = {}}, ["y"] = 47, ["param1"] = 95, ["z"] = 37, ["name"] = "default:steelblock"}, {["x"] = 3, ["meta"] = {["fields"] = {}, ["inventory"] = {}}, ["y"] = 47, ["param1"] = 111, ["z"] = 38, ["name"] = "default:steelblock"}, {["x"] = 3, ["meta"] = {["fields"] = {}, ["inventory"] = {}}, ["y"] = 47, ["param1"] = 127, ["z"] = 39, ["name"] = "default:steelblock"}, {["x"] = 3, ["meta"] = {["fields"] = {}, ["inventory"] = {}}, ["y"] = 48, ["param1"] = 127, ["z"] = 33, ["name"] = "default:steelblock"}, {["x"] = 3, ["meta"] = {["fields"] = {}, ["inventory"] = {}}, ["y"] = 48, ["param1"] = 111, ["z"] = 34, ["name"] = "default:steelblock"}, {["x"] = 3, ["meta"] = {["fields"] = {}, ["inventory"] = {}}, ["y"] = 48, ["param1"] = 95, ["z"] = 35, ["name"] = "default:steelblock"}, {["x"] = 3, ["meta"] = {["fields"] = {}, ["inventory"] = {}}, ["y"] = 48, ["param1"] = 79, ["z"] = 36, ["name"] = "default:steelblock"}, {["x"] = 3, ["meta"] = {["fields"] = {}, ["inventory"] = {}}, ["y"] = 48, ["param1"] = 95, ["z"] = 37, ["name"] = "default:steelblock"}, {["x"] = 3, ["meta"] = {["fields"] = {}, ["inventory"] = {}}, ["y"] = 48, ["param1"] = 111, ["z"] = 38, ["name"] = "default:steelblock"}, {["x"] = 3, ["meta"] = {["fields"] = {}, ["inventory"] = {}}, ["y"] = 48, ["param1"] = 127, ["z"] = 39, ["name"] = "default:steelblock"}, {["x"] = 3, ["meta"] = {["fields"] = {}, ["inventory"] = {}}, ["y"] = 49, ["param1"] = 111, ["z"] = 33, ["name"] = "default:steelblock"}, {["x"] = 3, ["meta"] = {["fields"] = {}, ["inventory"] = {}}, ["y"] = 49, ["param1"] = 95, ["z"] = 34, ["name"] = "default:steelblock"}, {["x"] = 3, ["meta"] = {["fields"] = {}, ["inventory"] = {}}, ["y"] = 49, ["param1"] = 79, ["z"] = 35, ["name"] = "default:steelblock"}, {["x"] = 3, ["meta"] = {["fields"] = {}, ["inventory"] = {}}, ["y"] = 49, ["param1"] = 63, ["z"] = 36, ["name"] = "default:steelblock"}, {["x"] = 3, ["meta"] = {["fields"] = {}, ["inventory"] = {}}, ["y"] = 49, ["param1"] = 79, ["z"] = 37, ["name"] = "default:steelblock"}, {["x"] = 3, ["meta"] = {["fields"] = {}, ["inventory"] = {}}, ["y"] = 49, ["param1"] = 95, ["z"] = 38, ["name"] = "default:steelblock"}, {["x"] = 3, ["meta"] = {["fields"] = {}, ["inventory"] = {}}, ["y"] = 49, ["param1"] = 111, ["z"] = 39, ["name"] = "default:steelblock"}, {["x"] = 4, ["meta"] = {["fields"] = {}, ["inventory"] = {}}, ["y"] = 0, ["param1"] = 13, ["z"] = 0, ["name"] = "default:water_source"}, {["x"] = 4, ["meta"] = {["fields"] = {}, ["inventory"] = {}}, ["y"] = 0, ["param1"] = 13, ["z"] = 1, ["name"] = "default:water_source"}, {["x"] = 4, ["meta"] = {["fields"] = {}, ["inventory"] = {}}, ["y"] = 0, ["param1"] = 13, ["z"] = 2, ["name"] = "default:water_source"}, {["x"] = 4, ["meta"] = {["fields"] = {}, ["inventory"] = {}}, ["y"] = 0, ["param1"] = 13, ["z"] = 3, ["name"] = "default:water_source"}, {["x"] = 4, ["meta"] = {["fields"] = {}, ["inventory"] = {}}, ["y"] = 0, ["param1"] = 13, ["z"] = 4, ["name"] = "default:water_source"}, {["x"] = 4, ["meta"] = {["fields"] = {}, ["inventory"] = {}}, ["y"] = 0, ["param1"] = 13, ["z"] = 5, ["name"] = "default:water_source"}, {["x"] = 4, ["meta"] = {["fields"] = {}, ["inventory"] = {}}, ["y"] = 0, ["param1"] = 13, ["z"] = 6, ["name"] = "default:water_source"}, {["x"] = 4, ["meta"] = {["fields"] = {}, ["inventory"] = {}}, ["y"] = 0, ["param1"] = 13, ["z"] = 7, ["name"] = "default:water_source"}, {["x"] = 4, ["meta"] = {["fields"] = {}, ["inventory"] = {}}, ["y"] = 0, ["param1"] = 13, ["z"] = 8, ["name"] = "default:water_source"}, {["x"] = 4, ["meta"] = {["fields"] = {}, ["inventory"] = {}}, ["y"] = 0, ["param1"] = 13, ["z"] = 9, ["name"] = "default:water_source"}, {["x"] = 4, ["meta"] = {["fields"] = {}, ["inventory"] = {}}, ["y"] = 0, ["param1"] = 13, ["z"] = 10, ["name"] = "default:water_source"}, {["x"] = 4, ["meta"] = {["fields"] = {}, ["inventory"] = {}}, ["y"] = 0, ["param1"] = 13, ["z"] = 11, ["name"] = "default:water_source"}, {["x"] = 4, ["meta"] = {["fields"] = {}, ["inventory"] = {}}, ["y"] = 0, ["param1"] = 13, ["z"] = 12, ["name"] = "default:water_source"}, {["x"] = 4, ["meta"] = {["fields"] = {}, ["inventory"] = {}}, ["y"] = 0, ["param1"] = 13, ["z"] = 13, ["name"] = "default:water_source"}, {["x"] = 4, ["meta"] = {["fields"] = {}, ["inventory"] = {}}, ["y"] = 0, ["param1"] = 13, ["z"] = 14, ["name"] = "default:water_source"}, {["x"] = 4, ["meta"] = {["fields"] = {}, ["inventory"] = {}}, ["y"] = 0, ["param1"] = 13, ["z"] = 15, ["name"] = "default:water_source"}, {["x"] = 4, ["meta"] = {["fields"] = {}, ["inventory"] = {}}, ["y"] = 0, ["param1"] = 13, ["z"] = 16, ["name"] = "default:water_source"}, {["x"] = 4, ["meta"] = {["fields"] = {}, ["inventory"] = {}}, ["y"] = 0, ["param1"] = 13, ["z"] = 17, ["name"] = "default:water_source"}, {["x"] = 4, ["meta"] = {["fields"] = {}, ["inventory"] = {}}, ["y"] = 0, ["param1"] = 13, ["z"] = 18, ["name"] = "default:water_source"}, {["x"] = 4, ["meta"] = {["fields"] = {}, ["inventory"] = {}}, ["y"] = 0, ["param1"] = 13, ["z"] = 19, ["name"] = "default:water_source"}, {["x"] = 4, ["meta"] = {["fields"] = {}, ["inventory"] = {}}, ["y"] = 0, ["param1"] = 13, ["z"] = 20, ["name"] = "default:water_source"}, {["x"] = 4, ["meta"] = {["fields"] = {}, ["inventory"] = {}}, ["y"] = 0, ["param1"] = 13, ["z"] = 21, ["name"] = "default:water_source"}, {["x"] = 4, ["meta"] = {["fields"] = {}, ["inventory"] = {}}, ["y"] = 0, ["param1"] = 13, ["z"] = 22, ["name"] = "default:water_source"}, {["x"] = 4, ["meta"] = {["fields"] = {}, ["inventory"] = {}}, ["y"] = 0, ["param1"] = 13, ["z"] = 23, ["name"] = "default:water_source"}, {["x"] = 4, ["meta"] = {["fields"] = {}, ["inventory"] = {}}, ["y"] = 0, ["param1"] = 13, ["z"] = 24, ["name"] = "default:water_source"}, {["x"] = 4, ["meta"] = {["fields"] = {}, ["inventory"] = {}}, ["y"] = 0, ["param1"] = 13, ["z"] = 25, ["name"] = "default:water_source"}, {["x"] = 4, ["meta"] = {["fields"] = {}, ["inventory"] = {}}, ["y"] = 0, ["param1"] = 13, ["z"] = 26, ["name"] = "default:water_source"}, {["x"] = 4, ["meta"] = {["fields"] = {}, ["inventory"] = {}}, ["y"] = 0, ["param1"] = 13, ["z"] = 27, ["name"] = "default:water_source"}, {["x"] = 4, ["meta"] = {["fields"] = {}, ["inventory"] = {}}, ["y"] = 0, ["param1"] = 13, ["z"] = 28, ["name"] = "default:water_source"}, {["x"] = 4, ["meta"] = {["fields"] = {}, ["inventory"] = {}}, ["y"] = 0, ["param1"] = 13, ["z"] = 29, ["name"] = "default:water_source"}, {["x"] = 4, ["meta"] = {["fields"] = {}, ["inventory"] = {}}, ["y"] = 0, ["param1"] = 13, ["z"] = 30, ["name"] = "default:water_source"}, {["x"] = 4, ["meta"] = {["fields"] = {}, ["inventory"] = {}}, ["y"] = 0, ["param1"] = 12, ["z"] = 31, ["name"] = "default:water_source"}, {["x"] = 4, ["meta"] = {["fields"] = {}, ["inventory"] = {}}, ["y"] = 0, ["param1"] = 12, ["z"] = 32, ["name"] = "default:water_source"}, {["x"] = 4, ["meta"] = {["fields"] = {}, ["inventory"] = {}}, ["y"] = 0, ["param1"] = 11, ["z"] = 33, ["name"] = "default:water_source"}, {["x"] = 4, ["meta"] = {["fields"] = {}, ["inventory"] = {}}, ["y"] = 0, ["param1"] = 11, ["z"] = 34, ["name"] = "default:water_source"}, {["x"] = 4, ["meta"] = {["fields"] = {}, ["inventory"] = {}}, ["y"] = 0, ["param1"] = 11, ["z"] = 35, ["name"] = "default:water_source"}, {["x"] = 4, ["meta"] = {["fields"] = {}, ["inventory"] = {}}, ["y"] = 0, ["param1"] = 11, ["z"] = 36, ["name"] = "default:water_source"}, {["x"] = 4, ["meta"] = {["fields"] = {}, ["inventory"] = {}}, ["y"] = 0, ["param1"] = 11, ["z"] = 37, ["name"] = "default:water_source"}, {["x"] = 4, ["meta"] = {["fields"] = {}, ["inventory"] = {}}, ["y"] = 0, ["param1"] = 11, ["z"] = 38, ["name"] = "default:water_source"}, {["x"] = 4, ["meta"] = {["fields"] = {}, ["inventory"] = {}}, ["y"] = 0, ["param1"] = 11, ["z"] = 39, ["name"] = "default:water_source"}, {["x"] = 4, ["meta"] = {["fields"] = {}, ["inventory"] = {}}, ["y"] = 0, ["param1"] = 12, ["z"] = 40, ["name"] = "default:water_source"}, {["x"] = 4, ["meta"] = {["fields"] = {}, ["inventory"] = {}}, ["y"] = 0, ["param1"] = 12, ["z"] = 41, ["name"] = "default:water_source"}, {["x"] = 4, ["meta"] = {["fields"] = {}, ["inventory"] = {}}, ["y"] = 0, ["param1"] = 13, ["z"] = 42, ["name"] = "default:water_source"}, {["x"] = 4, ["meta"] = {["fields"] = {}, ["inventory"] = {}}, ["y"] = 0, ["param1"] = 13, ["z"] = 43, ["name"] = "default:water_source"}, {["x"] = 4, ["meta"] = {["fields"] = {}, ["inventory"] = {}}, ["y"] = 0, ["param1"] = 13, ["z"] = 44, ["name"] = "default:water_source"}, {["x"] = 4, ["meta"] = {["fields"] = {}, ["inventory"] = {}}, ["y"] = 0, ["param1"] = 13, ["z"] = 45, ["name"] = "default:water_source"}, {["x"] = 4, ["meta"] = {["fields"] = {}, ["inventory"] = {}}, ["y"] = 0, ["param1"] = 13, ["z"] = 46, ["name"] = "default:water_source"}, {["x"] = 4, ["meta"] = {["fields"] = {}, ["inventory"] = {}}, ["y"] = 0, ["param1"] = 13, ["z"] = 47, ["name"] = "default:water_source"}, {["x"] = 4, ["meta"] = {["fields"] = {}, ["inventory"] = {}}, ["y"] = 0, ["param1"] = 13, ["z"] = 48, ["name"] = "default:water_source"}, {["x"] = 4, ["meta"] = {["fields"] = {}, ["inventory"] = {}}, ["y"] = 0, ["param1"] = 13, ["z"] = 49, ["name"] = "default:water_source"}, {["x"] = 4, ["meta"] = {["fields"] = {}, ["inventory"] = {}}, ["y"] = 0, ["param1"] = 13, ["z"] = 50, ["name"] = "default:water_source"}, {["x"] = 4, ["meta"] = {["fields"] = {}, ["inventory"] = {}}, ["y"] = 0, ["param1"] = 13, ["z"] = 51, ["name"] = "default:water_source"}, {["x"] = 4, ["meta"] = {["fields"] = {}, ["inventory"] = {}}, ["y"] = 0, ["param1"] = 13, ["z"] = 52, ["name"] = "default:water_source"}, {["x"] = 4, ["meta"] = {["fields"] = {}, ["inventory"] = {}}, ["y"] = 0, ["param1"] = 13, ["z"] = 53, ["name"] = "default:water_source"}, {["x"] = 4, ["meta"] = {["fields"] = {}, ["inventory"] = {}}, ["y"] = 0, ["param1"] = 13, ["z"] = 54, ["name"] = "default:water_source"}, {["x"] = 4, ["meta"] = {["fields"] = {}, ["inventory"] = {}}, ["y"] = 0, ["param1"] = 13, ["z"] = 55, ["name"] = "default:water_source"}, {["x"] = 4, ["meta"] = {["fields"] = {}, ["inventory"] = {}}, ["y"] = 0, ["param1"] = 13, ["z"] = 56, ["name"] = "default:water_source"}, {["x"] = 4, ["meta"] = {["fields"] = {}, ["inventory"] = {}}, ["y"] = 0, ["param1"] = 13, ["z"] = 57, ["name"] = "default:water_source"}, {["x"] = 4, ["meta"] = {["fields"] = {}, ["inventory"] = {}}, ["y"] = 0, ["param1"] = 13, ["z"] = 58, ["name"] = "default:water_source"}, {["x"] = 4, ["meta"] = {["fields"] = {}, ["inventory"] = {}}, ["y"] = 0, ["param1"] = 13, ["z"] = 59, ["name"] = "default:water_source"}, {["x"] = 4, ["meta"] = {["fields"] = {}, ["inventory"] = {}}, ["y"] = 0, ["param1"] = 13, ["z"] = 60, ["name"] = "default:water_source"}, {["x"] = 4, ["meta"] = {["fields"] = {}, ["inventory"] = {}}, ["y"] = 0, ["param1"] = 13, ["z"] = 61, ["name"] = "default:water_source"}, {["x"] = 4, ["meta"] = {["fields"] = {}, ["inventory"] = {}}, ["y"] = 0, ["param1"] = 13, ["z"] = 62, ["name"] = "default:water_source"}, {["x"] = 4, ["meta"] = {["fields"] = {}, ["inventory"] = {}}, ["y"] = 0, ["param1"] = 13, ["z"] = 63, ["name"] = "default:water_source"}, {["x"] = 4, ["meta"] = {["fields"] = {}, ["inventory"] = {}}, ["y"] = 0, ["param1"] = 13, ["z"] = 64, ["name"] = "default:water_source"}, {["x"] = 4, ["meta"] = {["fields"] = {}, ["inventory"] = {}}, ["y"] = 0, ["param1"] = 29, ["z"] = 65, ["name"] = "default:water_source"}, {["x"] = 4, ["meta"] = {["fields"] = {}, ["inventory"] = {}}, ["y"] = 0, ["param1"] = 45, ["z"] = 66, ["name"] = "default:water_source"}, {["x"] = 4, ["meta"] = {["fields"] = {}, ["inventory"] = {}}, ["y"] = 0, ["param1"] = 61, ["z"] = 67, ["name"] = "default:water_source"}, {["x"] = 4, ["meta"] = {["fields"] = {}, ["inventory"] = {}}, ["y"] = 0, ["param1"] = 77, ["z"] = 68, ["name"] = "default:water_source"}, {["x"] = 4, ["meta"] = {["fields"] = {}, ["inventory"] = {}}, ["y"] = 0, ["param1"] = 93, ["z"] = 69, ["name"] = "default:water_source"}, {["x"] = 4, ["meta"] = {["fields"] = {}, ["inventory"] = {}}, ["y"] = 0, ["param1"] = 109, ["z"] = 70, ["name"] = "default:water_source"}, {["x"] = 4, ["meta"] = {["fields"] = {}, ["inventory"] = {}}, ["y"] = 0, ["param1"] = 125, ["z"] = 71, ["name"] = "default:water_source"}, {["x"] = 4, ["meta"] = {["fields"] = {}, ["inventory"] = {}}, ["y"] = 0, ["param1"] = 141, ["z"] = 72, ["name"] = "default:water_source"}, {["x"] = 4, ["meta"] = {["fields"] = {}, ["inventory"] = {}}, ["y"] = 0, ["param1"] = 157, ["z"] = 73, ["name"] = "default:water_source"}, {["x"] = 4, ["meta"] = {["fields"] = {}, ["inventory"] = {}}, ["y"] = 0, ["param1"] = 173, ["z"] = 74, ["name"] = "default:water_source"}, {["x"] = 4, ["meta"] = {["fields"] = {}, ["inventory"] = {}}, ["y"] = 0, ["param1"] = 189, ["z"] = 75, ["name"] = "default:water_source"}, {["x"] = 4, ["meta"] = {["fields"] = {}, ["inventory"] = {}}, ["y"] = 0, ["param1"] = 205, ["z"] = 76, ["name"] = "default:water_source"}, {["x"] = 4, ["meta"] = {["fields"] = {}, ["inventory"] = {}}, ["y"] = 0, ["param1"] = 221, ["z"] = 77, ["name"] = "default:water_source"}, {["x"] = 4, ["meta"] = {["fields"] = {}, ["inventory"] = {}}, ["y"] = 0, ["param1"] = 15, ["z"] = 78, ["name"] = "stained_glass:6_5_7"}, {["x"] = 4, ["meta"] = {["fields"] = {}, ["inventory"] = {}}, ["y"] = 25, ["param1"] = 63, ["z"] = 31, ["name"] = "default:steelblock"}, {["x"] = 4, ["meta"] = {["fields"] = {}, ["inventory"] = {}}, ["y"] = 25, ["param1"] = 79, ["z"] = 32, ["name"] = "default:steelblock"}, {["x"] = 4, ["meta"] = {["fields"] = {}, ["inventory"] = {}}, ["y"] = 25, ["param1"] = 75, ["z"] = 33, ["name"] = "default:steelblock"}, {["x"] = 4, ["meta"] = {["fields"] = {}, ["inventory"] = {}}, ["y"] = 25, ["param1"] = 75, ["z"] = 34, ["name"] = "default:steelblock"}, {["x"] = 4, ["meta"] = {["fields"] = {}, ["inventory"] = {}}, ["y"] = 25, ["param1"] = 75, ["z"] = 35, ["name"] = "default:steelblock"}, {["x"] = 4, ["meta"] = {["fields"] = {}, ["inventory"] = {}}, ["y"] = 25, ["param1"] = 75, ["z"] = 36, ["name"] = "default:steelblock"}, {["x"] = 4, ["meta"] = {["fields"] = {}, ["inventory"] = {}}, ["y"] = 25, ["param1"] = 75, ["z"] = 37, ["name"] = "default:steelblock"}, {["x"] = 4, ["meta"] = {["fields"] = {}, ["inventory"] = {}}, ["y"] = 25, ["param1"] = 75, ["z"] = 38, ["name"] = "default:steelblock"}, {["x"] = 4, ["meta"] = {["fields"] = {}, ["inventory"] = {}}, ["y"] = 25, ["param1"] = 75, ["z"] = 39, ["name"] = "default:steelblock"}, {["x"] = 4, ["meta"] = {["fields"] = {}, ["inventory"] = {}}, ["y"] = 25, ["param1"] = 63, ["z"] = 40, ["name"] = "default:steelblock"}, {["x"] = 4, ["meta"] = {["fields"] = {}, ["inventory"] = {}}, ["y"] = 25, ["param1"] = 79, ["z"] = 41, ["name"] = "default:steelblock"}, {["x"] = 4, ["meta"] = {["fields"] = {}, ["inventory"] = {}}, ["y"] = 26, ["param1"] = 47, ["z"] = 31, ["name"] = "default:steelblock"}, {["x"] = 4, ["meta"] = {["fields"] = {}, ["inventory"] = {}}, ["y"] = 26, ["param1"] = 63, ["z"] = 32, ["name"] = "default:steelblock"}, {["x"] = 4, ["meta"] = {["fields"] = {}, ["inventory"] = {}}, ["param2"] = 1, ["y"] = 26, ["z"] = 33, ["name"] = "homedecor:glowlight_half_white"}, {["x"] = 4, ["meta"] = {["fields"] = {}, ["inventory"] = {}}, ["param2"] = 1, ["y"] = 26, ["z"] = 34, ["name"] = "homedecor:glowlight_half_white"}, {["x"] = 4, ["meta"] = {["fields"] = {}, ["inventory"] = {}}, ["param2"] = 1, ["y"] = 26, ["z"] = 35, ["name"] = "homedecor:glowlight_half_white"}, {["x"] = 4, ["meta"] = {["fields"] = {}, ["inventory"] = {}}, ["param2"] = 1, ["y"] = 26, ["z"] = 36, ["name"] = "homedecor:glowlight_half_white"}, {["x"] = 4, ["meta"] = {["fields"] = {}, ["inventory"] = {}}, ["param2"] = 1, ["y"] = 26, ["z"] = 37, ["name"] = "homedecor:glowlight_half_white"}, {["x"] = 4, ["meta"] = {["fields"] = {}, ["inventory"] = {}}, ["param2"] = 1, ["y"] = 26, ["z"] = 38, ["name"] = "homedecor:glowlight_half_white"}, {["x"] = 4, ["meta"] = {["fields"] = {}, ["inventory"] = {}}, ["param2"] = 1, ["y"] = 26, ["z"] = 39, ["name"] = "homedecor:glowlight_half_white"}, {["x"] = 4, ["meta"] = {["fields"] = {}, ["inventory"] = {}}, ["y"] = 26, ["param1"] = 47, ["z"] = 40, ["name"] = "default:steelblock"}, {["x"] = 4, ["meta"] = {["fields"] = {}, ["inventory"] = {}}, ["y"] = 26, ["param1"] = 63, ["z"] = 41, ["name"] = "default:steelblock"}, {["x"] = 4, ["meta"] = {["fields"] = {}, ["inventory"] = {}}, ["y"] = 27, ["param1"] = 31, ["z"] = 31, ["name"] = "default:steelblock"}, {["x"] = 4, ["meta"] = {["fields"] = {}, ["inventory"] = {}}, ["y"] = 27, ["param1"] = 47, ["z"] = 32, ["name"] = "default:steelblock"}, {["x"] = 4, ["meta"] = {["fields"] = {}, ["inventory"] = {}}, ["y"] = 27, ["param1"] = 31, ["z"] = 40, ["name"] = "default:steelblock"}, {["x"] = 4, ["meta"] = {["fields"] = {}, ["inventory"] = {}}, ["y"] = 27, ["param1"] = 47, ["z"] = 41, ["name"] = "default:steelblock"}, {["x"] = 4, ["meta"] = {["fields"] = {}, ["inventory"] = {}}, ["y"] = 28, ["param1"] = 15, ["z"] = 31, ["name"] = "default:steelblock"}, {["x"] = 4, ["meta"] = {["fields"] = {}, ["inventory"] = {}}, ["y"] = 28, ["param1"] = 31, ["z"] = 32, ["name"] = "default:steelblock"}, {["x"] = 4, ["meta"] = {["fields"] = {}, ["inventory"] = {}}, ["y"] = 28, ["param1"] = 15, ["z"] = 40, ["name"] = "default:steelblock"}, {["x"] = 4, ["meta"] = {["fields"] = {}, ["inventory"] = {}}, ["y"] = 28, ["param1"] = 31, ["z"] = 41, ["name"] = "default:steelblock"}, {["x"] = 4, ["meta"] = {["fields"] = {}, ["inventory"] = {}}, ["y"] = 29, ["param1"] = 15, ["z"] = 31, ["name"] = "default:steelblock"}, {["x"] = 4, ["meta"] = {["fields"] = {}, ["inventory"] = {}}, ["y"] = 29, ["param1"] = 15, ["z"] = 32, ["name"] = "default:steelblock"}, {["x"] = 4, ["meta"] = {["fields"] = {}, ["inventory"] = {}}, ["y"] = 29, ["param1"] = 15, ["z"] = 40, ["name"] = "default:steelblock"}, {["x"] = 4, ["meta"] = {["fields"] = {}, ["inventory"] = {}}, ["y"] = 29, ["param1"] = 15, ["z"] = 41, ["name"] = "default:steelblock"}, {["x"] = 4, ["meta"] = {["fields"] = {}, ["inventory"] = {}}, ["y"] = 30, ["param1"] = 15, ["z"] = 31, ["name"] = "default:steelblock"}, {["x"] = 4, ["meta"] = {["fields"] = {}, ["inventory"] = {}}, ["y"] = 30, ["param1"] = 15, ["z"] = 32, ["name"] = "default:steelblock"}, {["x"] = 4, ["meta"] = {["fields"] = {}, ["inventory"] = {}}, ["y"] = 30, ["param1"] = 15, ["z"] = 40, ["name"] = "default:steelblock"}, {["x"] = 4, ["meta"] = {["fields"] = {}, ["inventory"] = {}}, ["y"] = 30, ["param1"] = 15, ["z"] = 41, ["name"] = "default:steelblock"}, {["x"] = 4, ["meta"] = {["fields"] = {}, ["inventory"] = {}}, ["y"] = 31, ["param1"] = 15, ["z"] = 31, ["name"] = "default:steelblock"}, {["x"] = 4, ["meta"] = {["fields"] = {}, ["inventory"] = {}}, ["y"] = 31, ["param1"] = 15, ["z"] = 32, ["name"] = "default:steelblock"}, {["x"] = 4, ["meta"] = {["fields"] = {}, ["inventory"] = {}}, ["y"] = 31, ["param1"] = 15, ["z"] = 40, ["name"] = "default:steelblock"}, {["x"] = 4, ["meta"] = {["fields"] = {}, ["inventory"] = {}}, ["y"] = 31, ["param1"] = 15, ["z"] = 41, ["name"] = "default:steelblock"}, {["x"] = 4, ["meta"] = {["fields"] = {}, ["inventory"] = {}}, ["y"] = 32, ["param1"] = 15, ["z"] = 31, ["name"] = "default:steelblock"}, {["x"] = 4, ["meta"] = {["fields"] = {}, ["inventory"] = {}}, ["y"] = 32, ["param1"] = 15, ["z"] = 32, ["name"] = "default:steelblock"}, {["x"] = 4, ["meta"] = {["fields"] = {}, ["inventory"] = {}}, ["y"] = 32, ["param1"] = 15, ["z"] = 40, ["name"] = "default:steelblock"}, {["x"] = 4, ["meta"] = {["fields"] = {}, ["inventory"] = {}}, ["y"] = 32, ["param1"] = 15, ["z"] = 41, ["name"] = "default:steelblock"}, {["x"] = 4, ["meta"] = {["fields"] = {}, ["inventory"] = {}}, ["y"] = 33, ["param1"] = 15, ["z"] = 31, ["name"] = "default:steelblock"}, {["x"] = 4, ["meta"] = {["fields"] = {}, ["inventory"] = {}}, ["y"] = 33, ["param1"] = 15, ["z"] = 32, ["name"] = "default:steelblock"}, {["x"] = 4, ["meta"] = {["fields"] = {}, ["inventory"] = {}}, ["y"] = 33, ["param1"] = 15, ["z"] = 40, ["name"] = "default:steelblock"}, {["x"] = 4, ["meta"] = {["fields"] = {}, ["inventory"] = {}}, ["y"] = 33, ["param1"] = 15, ["z"] = 41, ["name"] = "default:steelblock"}, {["x"] = 4, ["meta"] = {["fields"] = {}, ["inventory"] = {}}, ["y"] = 34, ["param1"] = 15, ["z"] = 31, ["name"] = "default:steelblock"}, {["x"] = 4, ["meta"] = {["fields"] = {}, ["inventory"] = {}}, ["y"] = 34, ["param1"] = 15, ["z"] = 32, ["name"] = "default:steelblock"}, {["x"] = 4, ["meta"] = {["fields"] = {}, ["inventory"] = {}}, ["y"] = 34, ["param1"] = 15, ["z"] = 40, ["name"] = "default:steelblock"}, {["x"] = 4, ["meta"] = {["fields"] = {}, ["inventory"] = {}}, ["y"] = 34, ["param1"] = 15, ["z"] = 41, ["name"] = "default:steelblock"}, {["x"] = 4, ["meta"] = {["fields"] = {}, ["inventory"] = {}}, ["y"] = 35, ["param1"] = 15, ["z"] = 31, ["name"] = "default:steelblock"}, {["x"] = 4, ["meta"] = {["fields"] = {}, ["inventory"] = {}}, ["y"] = 35, ["param1"] = 15, ["z"] = 32, ["name"] = "default:steelblock"}, {["x"] = 4, ["meta"] = {["fields"] = {}, ["inventory"] = {}}, ["y"] = 35, ["param1"] = 15, ["z"] = 40, ["name"] = "default:steelblock"}, {["x"] = 4, ["meta"] = {["fields"] = {}, ["inventory"] = {}}, ["y"] = 35, ["param1"] = 15, ["z"] = 41, ["name"] = "default:steelblock"}, {["x"] = 4, ["meta"] = {["fields"] = {}, ["inventory"] = {}}, ["y"] = 36, ["param1"] = 15, ["z"] = 31, ["name"] = "default:steelblock"}, {["x"] = 4, ["meta"] = {["fields"] = {}, ["inventory"] = {}}, ["y"] = 36, ["param1"] = 15, ["z"] = 32, ["name"] = "default:steelblock"}, {["x"] = 4, ["meta"] = {["fields"] = {}, ["inventory"] = {}}, ["y"] = 36, ["param1"] = 15, ["z"] = 40, ["name"] = "default:steelblock"}, {["x"] = 4, ["meta"] = {["fields"] = {}, ["inventory"] = {}}, ["y"] = 36, ["param1"] = 15, ["z"] = 41, ["name"] = "default:steelblock"}, {["x"] = 4, ["meta"] = {["fields"] = {}, ["inventory"] = {}}, ["y"] = 37, ["param1"] = 15, ["z"] = 31, ["name"] = "default:steelblock"}, {["x"] = 4, ["meta"] = {["fields"] = {}, ["inventory"] = {}}, ["y"] = 37, ["param1"] = 15, ["z"] = 32, ["name"] = "default:steelblock"}, {["x"] = 4, ["meta"] = {["fields"] = {}, ["inventory"] = {}}, ["y"] = 37, ["param1"] = 15, ["z"] = 40, ["name"] = "default:steelblock"}, {["x"] = 4, ["meta"] = {["fields"] = {}, ["inventory"] = {}}, ["y"] = 37, ["param1"] = 15, ["z"] = 41, ["name"] = "default:steelblock"}, {["x"] = 4, ["meta"] = {["fields"] = {}, ["inventory"] = {}}, ["y"] = 38, ["param1"] = 15, ["z"] = 31, ["name"] = "default:steelblock"}, {["x"] = 4, ["meta"] = {["fields"] = {}, ["inventory"] = {}}, ["y"] = 38, ["param1"] = 15, ["z"] = 32, ["name"] = "default:steelblock"}, {["x"] = 4, ["meta"] = {["fields"] = {}, ["inventory"] = {}}, ["y"] = 38, ["param1"] = 15, ["z"] = 40, ["name"] = "default:steelblock"}, {["x"] = 4, ["meta"] = {["fields"] = {}, ["inventory"] = {}}, ["y"] = 38, ["param1"] = 15, ["z"] = 41, ["name"] = "default:steelblock"}, {["x"] = 4, ["meta"] = {["fields"] = {}, ["inventory"] = {}}, ["y"] = 39, ["param1"] = 15, ["z"] = 31, ["name"] = "default:steelblock"}, {["x"] = 4, ["meta"] = {["fields"] = {}, ["inventory"] = {}}, ["y"] = 39, ["param1"] = 15, ["z"] = 32, ["name"] = "default:steelblock"}, {["x"] = 4, ["meta"] = {["fields"] = {}, ["inventory"] = {}}, ["y"] = 39, ["param1"] = 15, ["z"] = 40, ["name"] = "default:steelblock"}, {["x"] = 4, ["meta"] = {["fields"] = {}, ["inventory"] = {}}, ["y"] = 39, ["param1"] = 15, ["z"] = 41, ["name"] = "default:steelblock"}, {["x"] = 4, ["meta"] = {["fields"] = {}, ["inventory"] = {}}, ["y"] = 40, ["param1"] = 15, ["z"] = 31, ["name"] = "default:steelblock"}, {["x"] = 4, ["meta"] = {["fields"] = {}, ["inventory"] = {}}, ["y"] = 40, ["param1"] = 15, ["z"] = 32, ["name"] = "default:steelblock"}, {["x"] = 4, ["meta"] = {["fields"] = {}, ["inventory"] = {}}, ["y"] = 40, ["param1"] = 15, ["z"] = 40, ["name"] = "default:steelblock"}, {["x"] = 4, ["meta"] = {["fields"] = {}, ["inventory"] = {}}, ["y"] = 40, ["param1"] = 15, ["z"] = 41, ["name"] = "default:steelblock"}, {["x"] = 4, ["meta"] = {["fields"] = {}, ["inventory"] = {}}, ["y"] = 41, ["param1"] = 15, ["z"] = 31, ["name"] = "default:steelblock"}, {["x"] = 4, ["meta"] = {["fields"] = {}, ["inventory"] = {}}, ["y"] = 41, ["param1"] = 15, ["z"] = 32, ["name"] = "default:steelblock"}, {["x"] = 4, ["meta"] = {["fields"] = {}, ["inventory"] = {}}, ["y"] = 41, ["param1"] = 15, ["z"] = 40, ["name"] = "default:steelblock"}, {["x"] = 4, ["meta"] = {["fields"] = {}, ["inventory"] = {}}, ["y"] = 41, ["param1"] = 15, ["z"] = 41, ["name"] = "default:steelblock"}, {["x"] = 4, ["meta"] = {["fields"] = {}, ["inventory"] = {}}, ["y"] = 42, ["param1"] = 15, ["z"] = 31, ["name"] = "default:steelblock"}, {["x"] = 4, ["meta"] = {["fields"] = {}, ["inventory"] = {}}, ["y"] = 42, ["param1"] = 15, ["z"] = 32, ["name"] = "default:steelblock"}, {["x"] = 4, ["meta"] = {["fields"] = {}, ["inventory"] = {}}, ["y"] = 42, ["param1"] = 15, ["z"] = 40, ["name"] = "default:steelblock"}, {["x"] = 4, ["meta"] = {["fields"] = {}, ["inventory"] = {}}, ["y"] = 42, ["param1"] = 15, ["z"] = 41, ["name"] = "default:steelblock"}, {["x"] = 4, ["meta"] = {["fields"] = {}, ["inventory"] = {}}, ["y"] = 43, ["param1"] = 15, ["z"] = 31, ["name"] = "default:steelblock"}, {["x"] = 4, ["meta"] = {["fields"] = {}, ["inventory"] = {}}, ["y"] = 43, ["param1"] = 15, ["z"] = 32, ["name"] = "default:steelblock"}, {["x"] = 4, ["meta"] = {["fields"] = {}, ["inventory"] = {}}, ["y"] = 43, ["param1"] = 15, ["z"] = 40, ["name"] = "default:steelblock"}, {["x"] = 4, ["meta"] = {["fields"] = {}, ["inventory"] = {}}, ["y"] = 43, ["param1"] = 15, ["z"] = 41, ["name"] = "default:steelblock"}, {["x"] = 4, ["meta"] = {["fields"] = {}, ["inventory"] = {}}, ["y"] = 44, ["param1"] = 15, ["z"] = 31, ["name"] = "default:steelblock"}, {["x"] = 4, ["meta"] = {["fields"] = {}, ["inventory"] = {}}, ["y"] = 44, ["param1"] = 15, ["z"] = 32, ["name"] = "default:steelblock"}, {["x"] = 4, ["meta"] = {["fields"] = {}, ["inventory"] = {}}, ["y"] = 44, ["param1"] = 15, ["z"] = 40, ["name"] = "default:steelblock"}, {["x"] = 4, ["meta"] = {["fields"] = {}, ["inventory"] = {}}, ["y"] = 44, ["param1"] = 15, ["z"] = 41, ["name"] = "default:steelblock"}, {["x"] = 4, ["meta"] = {["fields"] = {}, ["inventory"] = {}}, ["y"] = 45, ["param1"] = 15, ["z"] = 31, ["name"] = "default:steelblock"}, {["x"] = 4, ["meta"] = {["fields"] = {}, ["inventory"] = {}}, ["y"] = 45, ["param1"] = 15, ["z"] = 32, ["name"] = "default:steelblock"}, {["x"] = 4, ["meta"] = {["fields"] = {}, ["inventory"] = {}}, ["y"] = 45, ["param1"] = 15, ["z"] = 40, ["name"] = "default:steelblock"}, {["x"] = 4, ["meta"] = {["fields"] = {}, ["inventory"] = {}}, ["y"] = 45, ["param1"] = 15, ["z"] = 41, ["name"] = "default:steelblock"}, {["x"] = 4, ["meta"] = {["fields"] = {}, ["inventory"] = {}}, ["y"] = 46, ["param1"] = 15, ["z"] = 31, ["name"] = "default:steelblock"}, {["x"] = 4, ["meta"] = {["fields"] = {}, ["inventory"] = {}}, ["y"] = 46, ["param1"] = 15, ["z"] = 32, ["name"] = "default:steelblock"}, {["x"] = 4, ["meta"] = {["fields"] = {}, ["inventory"] = {}}, ["y"] = 46, ["param1"] = 15, ["z"] = 40, ["name"] = "default:steelblock"}, {["x"] = 4, ["meta"] = {["fields"] = {}, ["inventory"] = {}}, ["y"] = 46, ["param1"] = 15, ["z"] = 41, ["name"] = "default:steelblock"}, {["x"] = 4, ["meta"] = {["fields"] = {}, ["inventory"] = {}}, ["y"] = 47, ["param1"] = 15, ["z"] = 31, ["name"] = "default:steelblock"}, {["x"] = 4, ["meta"] = {["fields"] = {}, ["inventory"] = {}}, ["y"] = 47, ["param1"] = 15, ["z"] = 32, ["name"] = "default:steelblock"}, {["x"] = 4, ["meta"] = {["fields"] = {}, ["inventory"] = {}}, ["y"] = 47, ["param1"] = 15, ["z"] = 40, ["name"] = "default:steelblock"}, {["x"] = 4, ["meta"] = {["fields"] = {}, ["inventory"] = {}}, ["y"] = 47, ["param1"] = 15, ["z"] = 41, ["name"] = "default:steelblock"}, {["x"] = 4, ["meta"] = {["fields"] = {}, ["inventory"] = {}}, ["y"] = 48, ["param1"] = 15, ["z"] = 31, ["name"] = "default:steelblock"}, {["x"] = 4, ["meta"] = {["fields"] = {}, ["inventory"] = {}}, ["y"] = 48, ["param1"] = 15, ["z"] = 32, ["name"] = "default:steelblock"}, {["x"] = 4, ["meta"] = {["fields"] = {}, ["inventory"] = {}}, ["y"] = 48, ["param1"] = 15, ["z"] = 40, ["name"] = "default:steelblock"}, {["x"] = 4, ["meta"] = {["fields"] = {}, ["inventory"] = {}}, ["y"] = 48, ["param1"] = 15, ["z"] = 41, ["name"] = "default:steelblock"}, {["x"] = 4, ["meta"] = {["fields"] = {}, ["inventory"] = {}}, ["y"] = 49, ["param1"] = 15, ["z"] = 31, ["name"] = "default:steelblock"}, {["x"] = 4, ["meta"] = {["fields"] = {}, ["inventory"] = {}}, ["y"] = 49, ["param1"] = 15, ["z"] = 32, ["name"] = "default:steelblock"}, {["x"] = 4, ["meta"] = {["fields"] = {}, ["inventory"] = {}}, ["y"] = 49, ["param1"] = 15, ["z"] = 40, ["name"] = "default:steelblock"}, {["x"] = 4, ["meta"] = {["fields"] = {}, ["inventory"] = {}}, ["y"] = 49, ["param1"] = 15, ["z"] = 41, ["name"] = "default:steelblock"}, {["x"] = 4, ["meta"] = {["fields"] = {}, ["inventory"] = {}}, ["y"] = 50, ["z"] = 33, ["name"] = "default:steelblock"}, {["x"] = 4, ["meta"] = {["fields"] = {}, ["inventory"] = {}}, ["y"] = 50, ["param1"] = 15, ["z"] = 34, ["name"] = "default:steelblock"}, {["x"] = 4, ["meta"] = {["fields"] = {}, ["inventory"] = {}}, ["y"] = 50, ["param1"] = 15, ["z"] = 35, ["name"] = "default:steelblock"}, {["x"] = 4, ["meta"] = {["fields"] = {}, ["inventory"] = {}}, ["y"] = 50, ["param1"] = 15, ["z"] = 36, ["name"] = "default:steelblock"}, {["x"] = 4, ["meta"] = {["fields"] = {}, ["inventory"] = {}}, ["y"] = 50, ["param1"] = 15, ["z"] = 37, ["name"] = "default:steelblock"}, {["x"] = 4, ["meta"] = {["fields"] = {}, ["inventory"] = {}}, ["y"] = 50, ["param1"] = 15, ["z"] = 38, ["name"] = "default:steelblock"}, {["x"] = 4, ["meta"] = {["fields"] = {}, ["inventory"] = {}}, ["y"] = 50, ["z"] = 39, ["name"] = "default:steelblock"}, {["x"] = 5, ["meta"] = {["fields"] = {}, ["inventory"] = {}}, ["y"] = 0, ["z"] = 0, ["name"] = "default:sandstone"}, {["x"] = 5, ["meta"] = {["fields"] = {}, ["inventory"] = {}}, ["y"] = 0, ["z"] = 1, ["name"] = "default:sandstone"}, {["x"] = 5, ["meta"] = {["fields"] = {}, ["inventory"] = {}}, ["y"] = 0, ["z"] = 2, ["name"] = "default:sandstone"}, {["x"] = 5, ["meta"] = {["fields"] = {}, ["inventory"] = {}}, ["y"] = 0, ["z"] = 3, ["name"] = "default:sandstone"}, {["x"] = 5, ["meta"] = {["fields"] = {}, ["inventory"] = {}}, ["y"] = 0, ["z"] = 4, ["name"] = "default:sandstone"}, {["x"] = 5, ["meta"] = {["fields"] = {}, ["inventory"] = {}}, ["y"] = 0, ["z"] = 5, ["name"] = "default:sandstone"}, {["x"] = 5, ["meta"] = {["fields"] = {}, ["inventory"] = {}}, ["y"] = 0, ["z"] = 6, ["name"] = "default:sandstone"}, {["x"] = 5, ["meta"] = {["fields"] = {}, ["inventory"] = {}}, ["y"] = 0, ["z"] = 7, ["name"] = "default:sandstone"}, {["x"] = 5, ["meta"] = {["fields"] = {}, ["inventory"] = {}}, ["param2"] = 7, ["y"] = 0, ["param1"] = 13, ["z"] = 8, ["name"] = "default:sandstone"}, {["x"] = 5, ["meta"] = {["fields"] = {}, ["inventory"] = {}}, ["param2"] = 7, ["y"] = 0, ["param1"] = 13, ["z"] = 9, ["name"] = "default:sandstone"}, {["x"] = 5, ["meta"] = {["fields"] = {}, ["inventory"] = {}}, ["param2"] = 7, ["y"] = 0, ["param1"] = 13, ["z"] = 10, ["name"] = "default:sandstone"}, {["x"] = 5, ["meta"] = {["fields"] = {}, ["inventory"] = {}}, ["param2"] = 7, ["y"] = 0, ["param1"] = 13, ["z"] = 11, ["name"] = "default:sandstone"}, {["x"] = 5, ["meta"] = {["fields"] = {}, ["inventory"] = {}}, ["param2"] = 7, ["y"] = 0, ["param1"] = 13, ["z"] = 12, ["name"] = "default:sandstone"}, {["x"] = 5, ["meta"] = {["fields"] = {}, ["inventory"] = {}}, ["param2"] = 7, ["y"] = 0, ["param1"] = 13, ["z"] = 13, ["name"] = "default:sandstone"}, {["x"] = 5, ["meta"] = {["fields"] = {}, ["inventory"] = {}}, ["param2"] = 7, ["y"] = 0, ["param1"] = 13, ["z"] = 14, ["name"] = "default:sandstone"}, {["x"] = 5, ["meta"] = {["fields"] = {}, ["inventory"] = {}}, ["param2"] = 7, ["y"] = 0, ["param1"] = 13, ["z"] = 15, ["name"] = "default:sandstone"}, {["x"] = 5, ["meta"] = {["fields"] = {}, ["inventory"] = {}}, ["param2"] = 7, ["y"] = 0, ["param1"] = 13, ["z"] = 16, ["name"] = "default:sandstone"}, {["x"] = 5, ["meta"] = {["fields"] = {}, ["inventory"] = {}}, ["param2"] = 7, ["y"] = 0, ["param1"] = 13, ["z"] = 17, ["name"] = "default:sandstone"}, {["x"] = 5, ["meta"] = {["fields"] = {}, ["inventory"] = {}}, ["param2"] = 7, ["y"] = 0, ["param1"] = 13, ["z"] = 18, ["name"] = "default:sandstone"}, {["x"] = 5, ["meta"] = {["fields"] = {}, ["inventory"] = {}}, ["param2"] = 7, ["y"] = 0, ["param1"] = 13, ["z"] = 19, ["name"] = "default:sandstone"}, {["x"] = 5, ["meta"] = {["fields"] = {}, ["inventory"] = {}}, ["param2"] = 7, ["y"] = 0, ["param1"] = 13, ["z"] = 20, ["name"] = "default:sandstone"}, {["x"] = 5, ["meta"] = {["fields"] = {}, ["inventory"] = {}}, ["param2"] = 7, ["y"] = 0, ["param1"] = 13, ["z"] = 21, ["name"] = "default:sandstone"}, {["x"] = 5, ["meta"] = {["fields"] = {}, ["inventory"] = {}}, ["param2"] = 7, ["y"] = 0, ["param1"] = 13, ["z"] = 22, ["name"] = "default:sandstone"}, {["x"] = 5, ["meta"] = {["fields"] = {}, ["inventory"] = {}}, ["param2"] = 7, ["y"] = 0, ["param1"] = 13, ["z"] = 23, ["name"] = "default:sandstone"}, {["x"] = 5, ["meta"] = {["fields"] = {}, ["inventory"] = {}}, ["param2"] = 7, ["y"] = 0, ["param1"] = 13, ["z"] = 24, ["name"] = "default:sandstone"}, {["x"] = 5, ["meta"] = {["fields"] = {}, ["inventory"] = {}}, ["param2"] = 7, ["y"] = 0, ["param1"] = 13, ["z"] = 25, ["name"] = "default:sandstone"}, {["x"] = 5, ["meta"] = {["fields"] = {}, ["inventory"] = {}}, ["param2"] = 7, ["y"] = 0, ["param1"] = 13, ["z"] = 26, ["name"] = "default:sandstone"}, {["x"] = 5, ["meta"] = {["fields"] = {}, ["inventory"] = {}}, ["param2"] = 7, ["y"] = 0, ["param1"] = 13, ["z"] = 27, ["name"] = "default:sandstone"}, {["x"] = 5, ["meta"] = {["fields"] = {}, ["inventory"] = {}}, ["param2"] = 7, ["y"] = 0, ["param1"] = 13, ["z"] = 28, ["name"] = "default:sandstone"}, {["x"] = 5, ["meta"] = {["fields"] = {}, ["inventory"] = {}}, ["param2"] = 7, ["y"] = 0, ["param1"] = 12, ["z"] = 29, ["name"] = "default:sandstone"}, {["x"] = 5, ["meta"] = {["fields"] = {}, ["inventory"] = {}}, ["param2"] = 7, ["y"] = 0, ["param1"] = 12, ["z"] = 30, ["name"] = "default:sandstone"}, {["x"] = 5, ["meta"] = {["fields"] = {}, ["inventory"] = {}}, ["param2"] = 7, ["y"] = 0, ["param1"] = 11, ["z"] = 31, ["name"] = "default:sandstone"}, {["x"] = 5, ["meta"] = {["fields"] = {}, ["inventory"] = {}}, ["param2"] = 7, ["y"] = 0, ["param1"] = 10, ["z"] = 32, ["name"] = "default:sandstone"}, {["x"] = 5, ["meta"] = {["fields"] = {}, ["inventory"] = {}},