5:return {{["x"] = 0, ["meta"] = {["fields"] = {}, ["inventory"] = {}}, ["y"] = 0, ["z"] = 0, ["name"] = "rainbow:stonebrick_yellow"}, {["x"] = 0, ["meta"] = {["fields"] = {}, ["inventory"] = {}}, ["y"] = 0, ["z"] = 1, ["name"] = "rainbow:stonebrick_red"}, {["x"] = 0, ["meta"] = {["fields"] = {}, ["inventory"] = {}}, ["y"] = 0, ["z"] = 2, ["name"] = "rainbow:stonebrick_orange"}, {["x"] = 0, ["meta"] = {["fields"] = {}, ["inventory"] = {}}, ["y"] = 0, ["z"] = 3, ["name"] = "rainbow:stonebrick_yellow"}, {["x"] = 0, ["meta"] = {["fields"] = {}, ["inventory"] = {}}, ["y"] = 0, ["z"] = 4, ["name"] = "rainbow:stonebrick_lightgreen"}, {["x"] = 0, ["meta"] = {["fields"] = {}, ["inventory"] = {}}, ["y"] = 0, ["z"] = 5, ["name"] = "rainbow:stonebrick_cyan"}, {["x"] = 0, ["meta"] = {["fields"] = {}, ["inventory"] = {}}, ["y"] = 0, ["z"] = 6, ["name"] = "rainbow:stonebrick_blue"}, {["x"] = 0, ["meta"] = {["fields"] = {}, ["inventory"] = {}}, ["y"] = 0, ["z"] = 7, ["name"] = "rainbow:stonebrick_violet"}, {["x"] = 0, ["meta"] = {["fields"] = {}, ["inventory"] = {}}, ["y"] = 1, ["z"] = 0, ["name"] = "rainbow:stonebrick_orange"}, {["x"] = 0, ["meta"] = {["fields"] = {}, ["inventory"] = {}}, ["y"] = 1, ["z"] = 1, ["name"] = "rainbow:stonebrick_red"}, {["x"] = 0, ["meta"] = {["fields"] = {}, ["inventory"] = {}}, ["y"] = 1, ["z"] = 2, ["name"] = "rainbow:stonebrick_orange"}, {["x"] = 0, ["meta"] = {["fields"] = {}, ["inventory"] = {}}, ["y"] = 1, ["z"] = 3, ["name"] = "rainbow:stonebrick_yellow"}, {["x"] = 0, ["meta"] = {["fields"] = {}, ["inventory"] = {}}, ["y"] = 1, ["z"] = 4, ["name"] = "rainbow:stonebrick_lightgreen"}, {["x"] = 0, ["meta"] = {["fields"] = {}, ["inventory"] = {}}, ["y"] = 1, ["z"] = 5, ["name"] = "rainbow:stonebrick_cyan"}, {["x"] = 0, ["meta"] = {["fields"] = {}, ["inventory"] = {}}, ["y"] = 1, ["z"] = 6, ["name"] = "rainbow:stonebrick_blue"}, {["x"] = 0, ["meta"] = {["fields"] = {}, ["inventory"] = {}}, ["y"] = 1, ["z"] = 7, ["name"] = "rainbow:stonebrick_violet"}, {["x"] = 0, ["meta"] = {["fields"] = {}, ["inventory"] = {}}, ["y"] = 2, ["z"] = 0, ["name"] = "rainbow:stonebrick_red"}, {["x"] = 0, ["meta"] = {["fields"] = {}, ["inventory"] = {}}, ["y"] = 2, ["z"] = 1, ["name"] = "rainbow:stonebrick_red"}, {["x"] = 0, ["meta"] = {["fields"] = {}, ["inventory"] = {}}, ["y"] = 2, ["z"] = 2, ["name"] = "rainbow:stonebrick_orange"}, {["x"] = 0, ["meta"] = {["fields"] = {}, ["inventory"] = {}}, ["y"] = 2, ["z"] = 3, ["name"] = "rainbow:stonebrick_yellow"}, {["x"] = 0, ["meta"] = {["fields"] = {}, ["inventory"] = {}}, ["y"] = 2, ["z"] = 4, ["name"] = "rainbow:stonebrick_lightgreen"}, {["x"] = 0, ["meta"] = {["fields"] = {}, ["inventory"] = {}}, ["y"] = 2, ["z"] = 5, ["name"] = "rainbow:stonebrick_cyan"}, {["x"] = 0, ["meta"] = {["fields"] = {}, ["inventory"] = {}}, ["y"] = 2, ["z"] = 6, ["name"] = "rainbow:stonebrick_blue"}, {["x"] = 0, ["meta"] = {["fields"] = {}, ["inventory"] = {}}, ["y"] = 2, ["z"] = 7, ["name"] = "rainbow:stonebrick_violet"}, {["x"] = 0, ["meta"] = {["fields"] = {}, ["inventory"] = {}}, ["y"] = 3, ["z"] = 0, ["name"] = "rainbow:stonebrick_violet"}, {["x"] = 0, ["meta"] = {["fields"] = {}, ["inventory"] = {}}, ["y"] = 3, ["z"] = 1, ["name"] = "rainbow:stonebrick_red"}, {["x"] = 0, ["meta"] = {["fields"] = {}, ["inventory"] = {}}, ["y"] = 3, ["z"] = 2, ["name"] = "rainbow:stonebrick_orange"}, {["x"] = 0, ["meta"] = {["fields"] = {}, ["inventory"] = {}}, ["y"] = 3, ["z"] = 3, ["name"] = "rainbow:stonebrick_yellow"}, {["x"] = 0, ["meta"] = {["fields"] = {}, ["inventory"] = {}}, ["y"] = 3, ["z"] = 4, ["name"] = "rainbow:stonebrick_lightgreen"}, {["x"] = 0, ["meta"] = {["fields"] = {}, ["inventory"] = {}}, ["y"] = 3, ["z"] = 5, ["name"] = "rainbow:stonebrick_cyan"}, {["x"] = 0, ["meta"] = {["fields"] = {}, ["inventory"] = {}}, ["y"] = 3, ["z"] = 6, ["name"] = "rainbow:stonebrick_blue"}, {["x"] = 0, ["meta"] = {["fields"] = {}, ["inventory"] = {}}, ["y"] = 3, ["z"] = 7, ["name"] = "rainbow:stonebrick_violet"}, {["x"] = 0, ["meta"] = {["fields"] = {}, ["inventory"] = {}}, ["y"] = 4, ["z"] = 0, ["name"] = "rainbow:stonebrick_blue"}, {["x"] = 0, ["meta"] = {["fields"] = {}, ["inventory"] = {}}, ["y"] = 4, ["z"] = 1, ["name"] = "rainbow:stonebrick_red"}, {["x"] = 0, ["meta"] = {["fields"] = {}, ["inventory"] = {}}, ["y"] = 4, ["z"] = 2, ["name"] = "rainbow:stonebrick_orange"}, {["x"] = 0, ["meta"] = {["fields"] = {}, ["inventory"] = {}}, ["y"] = 4, ["z"] = 3, ["name"] = "rainbow:stonebrick_yellow"}, {["x"] = 0, ["meta"] = {["fields"] = {}, ["inventory"] = {}}, ["y"] = 4, ["z"] = 4, ["name"] = "rainbow:stonebrick_lightgreen"}, {["x"] = 0, ["meta"] = {["fields"] = {}, ["inventory"] = {}}, ["y"] = 4, ["z"] = 5, ["name"] = "rainbow:stonebrick_cyan"}, {["x"] = 0, ["meta"] = {["fields"] = {}, ["inventory"] = {}}, ["y"] = 4, ["z"] = 6, ["name"] = "rainbow:stonebrick_blue"}, {["x"] = 0, ["meta"] = {["fields"] = {}, ["inventory"] = {}}, ["y"] = 4, ["z"] = 7, ["name"] = "rainbow:stonebrick_violet"}, {["x"] = 0, ["meta"] = {["fields"] = {}, ["inventory"] = {}}, ["y"] = 5, ["z"] = 0, ["name"] = "rainbow:stonebrick_cyan"}, {["x"] = 0, ["meta"] = {["fields"] = {}, ["inventory"] = {}}, ["y"] = 5, ["z"] = 1, ["name"] = "rainbow:stonebrick_red"}, {["x"] = 0, ["meta"] = {["fields"] = {}, ["inventory"] = {}}, ["y"] = 5, ["z"] = 2, ["name"] = "rainbow:stonebrick_orange"}, {["x"] = 0, ["meta"] = {["fields"] = {}, ["inventory"] = {}}, ["y"] = 5, ["z"] = 3, ["name"] = "rainbow:stonebrick_yellow"}, {["x"] = 0, ["meta"] = {["fields"] = {}, ["inventory"] = {}}, ["y"] = 5, ["z"] = 4, ["name"] = "rainbow:stonebrick_lightgreen"}, {["x"] = 0, ["meta"] = {["fields"] = {}, ["inventory"] = {}}, ["y"] = 5, ["z"] = 5, ["name"] = "rainbow:stonebrick_cyan"}, {["x"] = 0, ["meta"] = {["fields"] = {}, ["inventory"] = {}}, ["y"] = 5, ["z"] = 6, ["name"] = "rainbow:stonebrick_blue"}, {["x"] = 0, ["meta"] = {["fields"] = {}, ["inventory"] = {}}, ["y"] = 5, ["z"] = 7, ["name"] = "rainbow:stonebrick_violet"}, {["x"] = 0, ["meta"] = {["fields"] = {}, ["inventory"] = {}}, ["y"] = 6, ["z"] = 0, ["name"] = "rainbow:stonebrick_lightgreen"}, {["x"] = 0, ["meta"] = {["fields"] = {}, ["inventory"] = {}}, ["param2"] = 2, ["y"] = 6, ["param1"] = 62, ["z"] = 1, ["name"] = "rainbow:micro_stonebrick_red_15"}, {["x"] = 0, ["meta"] = {["fields"] = {}, ["inventory"] = {}}, ["param2"] = 2, ["y"] = 6, ["param1"] = 46, ["z"] = 2, ["name"] = "rainbow:micro_stonebrick_orange_15"}, {["x"] = 0, ["meta"] = {["fields"] = {}, ["inventory"] = {}}, ["param2"] = 2, ["y"] = 6, ["param1"] = 30, ["z"] = 3, ["name"] = "rainbow:micro_stonebrick_yellow_15"}, {["x"] = 0, ["meta"] = {["fields"] = {}, ["inventory"] = {}}, ["param2"] = 2, ["y"] = 6, ["param1"] = 14, ["z"] = 4, ["name"] = "rainbow:micro_stonebrick_lightgreen_15"}, {["x"] = 0, ["meta"] = {["fields"] = {}, ["inventory"] = {}}, ["param2"] = 2, ["y"] = 6, ["param1"] = 14, ["z"] = 5, ["name"] = "rainbow:micro_stonebrick_cyan_15"}, {["x"] = 0, ["meta"] = {["fields"] = {}, ["inventory"] = {}}, ["param2"] = 2, ["y"] = 6, ["param1"] = 14, ["z"] = 6, ["name"] = "rainbow:micro_stonebrick_blue_15"}, {["x"] = 0, ["meta"] = {["fields"] = {}, ["inventory"] = {}}, ["param2"] = 2, ["y"] = 6, ["param1"] = 14, ["z"] = 7, ["name"] = "rainbow:micro_stonebrick_violet_15"}, {["x"] = 0, ["meta"] = {["fields"] = {}, ["inventory"] = {}}, ["y"] = 7, ["z"] = 0, ["name"] = "rainbow:stonebrick_yellow"}, {["x"] = 0, ["meta"] = {["fields"] = {}, ["inventory"] = {}}, ["y"] = 8, ["z"] = 0, ["name"] = "rainbow:stonebrick_orange"}, {["x"] = 0, ["meta"] = {["fields"] = {}, ["inventory"] = {}}, ["y"] = 9, ["z"] = 0, ["name"] = "rainbow:stonebrick_red"}, {["x"] = 0, ["meta"] = {["fields"] = {}, ["inventory"] = {}}, ["y"] = 10, ["z"] = 0, ["name"] = "rainbow:stonebrick_violet"}, {["x"] = 0, ["meta"] = {["fields"] = {}, ["inventory"] = {}}, ["y"] = 11, ["z"] = 0, ["name"] = "rainbow:stonebrick_blue"}, {["x"] = 0, ["meta"] = {["fields"] = {}, ["inventory"] = {}}, ["y"] = 12, ["z"] = 0, ["name"] = "rainbow:stonebrick_cyan"}, {["x"] = 0, ["meta"] = {["fields"] = {}, ["inventory"] = {}}, ["y"] = 13, ["z"] = 0, ["name"] = "rainbow:stonebrick_lightgreen"}, {["x"] = 0, ["meta"] = {["fields"] = {}, ["inventory"] = {}}, ["y"] = 14, ["z"] = 0, ["name"] = "rainbow:stonebrick_yellow"}, {["x"] = 0, ["meta"] = {["fields"] = {}, ["inventory"] = {}}, ["y"] = 15, ["z"] = 0, ["name"] = "rainbow:stonebrick_orange"}, {["x"] = 0, ["meta"] = {["fields"] = {}, ["inventory"] = {}}, ["y"] = 16, ["z"] = 0, ["name"] = "rainbow:stonebrick_red"}, {["x"] = 0, ["meta"] = {["fields"] = {}, ["inventory"] = {}}, ["y"] = 17, ["z"] = 0, ["name"] = "rainbow:stonebrick_violet"}, {["x"] = 0, ["meta"] = {["fields"] = {}, ["inventory"] = {}}, ["y"] = 18, ["z"] = 0, ["name"] = "rainbow:stonebrick_blue"}, {["x"] = 0, ["meta"] = {["fields"] = {}, ["inventory"] = {}}, ["y"] = 19, ["z"] = 0, ["name"] = "rainbow:stonebrick_cyan"}, {["x"] = 0, ["meta"] = {["fields"] = {}, ["inventory"] = {}}, ["y"] = 20, ["z"] = 0, ["name"] = "rainbow:stonebrick_lightgreen"}, {["x"] = 0, ["meta"] = {["fields"] = {}, ["inventory"] = {}}, ["y"] = 21, ["z"] = 0, ["name"] = "rainbow:stonebrick_yellow"}, {["x"] = 0, ["meta"] = {["fields"] = {}, ["inventory"] = {}}, ["y"] = 22, ["z"] = 0, ["name"] = "rainbow:stonebrick_orange"}, {["x"] = 0, ["meta"] = {["fields"] = {}, ["inventory"] = {}}, ["y"] = 23, ["z"] = 0, ["name"] = "rainbow:stonebrick_red"}, {["x"] = 0, ["meta"] = {["fields"] = {}, ["inventory"] = {}}, ["y"] = 24, ["z"] = 0, ["name"] = "rainbow:stonebrick_violet"}, {["x"] = 0, ["meta"] = {["fields"] = {}, ["inventory"] = {}}, ["y"] = 25, ["z"] = 0, ["name"] = "rainbow:stonebrick_blue"}, {["x"] = 0, ["meta"] = {["fields"] = {}, ["inventory"] = {}}, ["y"] = 26, ["z"] = 0, ["name"] = "rainbow:stonebrick_cyan"}, {["x"] = 0, ["meta"] = {["fields"] = {}, ["inventory"] = {}}, ["y"] = 27, ["z"] = 0, ["name"] = "rainbow:stonebrick_lightgreen"}, {["x"] = 0, ["meta"] = {["fields"] = {}, ["inventory"] = {}}, ["param2"] = 22, ["y"] = 27, ["param1"] = 110, ["z"] = 1, ["name"] = "rainbow:slope_stonebrick_black"}, {["x"] = 0, ["meta"] = {["fields"] = {}, ["inventory"] = {}}, ["param2"] = 20, ["y"] = 27, ["param1"] = 110, ["z"] = 7, ["name"] = "rainbow:slope_stonebrick_black"}, {["x"] = 0, ["meta"] = {["fields"] = {}, ["inventory"] = {}}, ["y"] = 28, ["z"] = 0, ["name"] = "rainbow:stonebrick_yellow"}, {["x"] = 0, ["meta"] = {["fields"] = {}, ["inventory"] = {}}, ["y"] = 28, ["param1"] = 126, ["z"] = 1, ["name"] = "rainbow:slope_stonebrick_black"}, {["x"] = 0, ["meta"] = {["fields"] = {}, ["inventory"] = {}}, ["param2"] = 22, ["y"] = 28, ["param1"] = 110, ["z"] = 2, ["name"] = "rainbow:slope_stonebrick_black"}, {["x"] = 0, ["meta"] = {["fields"] = {}, ["inventory"] = {}}, ["param2"] = 20, ["y"] = 28, ["param1"] = 110, ["z"] = 6, ["name"] = "rainbow:slope_stonebrick_black"}, {["x"] = 0, ["meta"] = {["fields"] = {}, ["inventory"] = {}}, ["param2"] = 2, ["y"] = 28, ["param1"] = 126, ["z"] = 7, ["name"] = "rainbow:slope_stonebrick_black"}, {["x"] = 0, ["meta"] = {["fields"] = {}, ["inventory"] = {}}, ["y"] = 29, ["z"] = 0, ["name"] = "rainbow:stonebrick_orange"}, {["x"] = 0, ["meta"] = {["fields"] = {}, ["inventory"] = {}}, ["y"] = 29, ["z"] = 2, ["name"] = "rainbow:stonebrick_black"}, {["x"] = 0, ["meta"] = {["fields"] = {}, ["inventory"] = {}}, ["param2"] = 22, ["y"] = 29, ["param1"] = 142, ["z"] = 3, ["name"] = "rainbow:slope_stonebrick_black"}, {["x"] = 0, ["meta"] = {["fields"] = {}, ["inventory"] = {}}, ["param2"] = 20, ["y"] = 29, ["param1"] = 142, ["z"] = 5, ["name"] = "rainbow:slope_stonebrick_black"}, {["x"] = 0, ["meta"] = {["fields"] = {}, ["inventory"] = {}}, ["y"] = 29, ["z"] = 6, ["name"] = "rainbow:stonebrick_black"}, {["x"] = 0, ["meta"] = {["fields"] = {}, ["inventory"] = {}}, ["y"] = 30, ["z"] = 0, ["name"] = "rainbow:stonebrick_red"}, {["x"] = 0, ["meta"] = {["fields"] = {}, ["inventory"] = {}}, ["param2"] = 20, ["y"] = 30, ["param1"] = 158, ["z"] = 1, ["name"] = "rainbow:slope_stonebrick_black"}, {["x"] = 0, ["meta"] = {["fields"] = {}, ["inventory"] = {}}, ["param2"] = 2, ["y"] = 30, ["param1"] = 142, ["z"] = 2, ["name"] = "rainbow:slope_stonebrick_black"}, {["x"] = 0, ["meta"] = {["fields"] = {}, ["inventory"] = {}}, ["y"] = 30, ["param1"] = 158, ["z"] = 3, ["name"] = "rainbow:slope_stonebrick_black"}, {["x"] = 0, ["meta"] = {["fields"] = {}, ["inventory"] = {}}, ["y"] = 30, ["z"] = 4, ["name"] = "rainbow:stonebrick_black"}, {["x"] = 0, ["meta"] = {["fields"] = {}, ["inventory"] = {}}, ["param2"] = 2, ["y"] = 30, ["param1"] = 158, ["z"] = 5, ["name"] = "rainbow:slope_stonebrick_black"}, {["x"] = 0, ["meta"] = {["fields"] = {}, ["inventory"] = {}}, ["y"] = 30, ["param1"] = 142, ["z"] = 6, ["name"] = "rainbow:slope_stonebrick_black"}, {["x"] = 0, ["meta"] = {["fields"] = {}, ["inventory"] = {}}, ["param2"] = 22, ["y"] = 30, ["param1"] = 158, ["z"] = 7, ["name"] = "rainbow:slope_stonebrick_black"}, {["x"] = 0, ["meta"] = {["fields"] = {}, ["inventory"] = {}}, ["y"] = 31, ["z"] = 0, ["name"] = "rainbow:stonebrick_black"}, {["x"] = 0, ["meta"] = {["fields"] = {}, ["inventory"] = {}}, ["y"] = 31, ["z"] = 1, ["name"] = "rainbow:stonebrick_red"}, {["x"] = 0, ["meta"] = {["fields"] = {}, ["inventory"] = {}}, ["y"] = 31, ["z"] = 2, ["name"] = "rainbow:stonebrick_orange"}, {["x"] = 0, ["meta"] = {["fields"] = {}, ["inventory"] = {}}, ["y"] = 31, ["z"] = 3, ["name"] = "rainbow:stonebrick_yellow"}, {["x"] = 0, ["meta"] = {["fields"] = {}, ["inventory"] = {}}, ["y"] = 31, ["z"] = 4, ["name"] = "rainbow:stonebrick_lightgreen"}, {["x"] = 0, ["meta"] = {["fields"] = {}, ["inventory"] = {}}, ["y"] = 31, ["z"] = 5, ["name"] = "rainbow:stonebrick_cyan"}, {["x"] = 0, ["meta"] = {["fields"] = {}, ["inventory"] = {}}, ["y"] = 31, ["z"] = 6, ["name"] = "rainbow:stonebrick_blue"}, {["x"] = 0, ["meta"] = {["fields"] = {}, ["inventory"] = {}}, ["y"] = 31, ["z"] = 7, ["name"] = "rainbow:stonebrick_violet"}, {["x"] = 1, ["meta"] = {["fields"] = {}, ["inventory"] = {}}, ["y"] = 0, ["z"] = 0, ["name"] = "rainbow:stonebrick_black"}, {["x"] = 1, ["meta"] = {["fields"] = {}, ["inventory"] = {}}, ["y"] = 0, ["z"] = 1, ["name"] = "rainbow:stonebrick_red"}, {["x"] = 1, ["meta"] = {["fields"] = {}, ["inventory"] = {}}, ["y"] = 0, ["z"] = 2, ["name"] = "rainbow:stonebrick_orange"}, {["x"] = 1, ["meta"] = {["fields"] = {}, ["inventory"] = {}}, ["y"] = 0, ["z"] = 3, ["name"] = "rainbow:stonebrick_yellow"}, {["x"] = 1, ["meta"] = {["fields"] = {}, ["inventory"] = {}}, ["y"] = 0, ["z"] = 4, ["name"] = "rainbow:stonebrick_lightgreen"}, {["x"] = 1, ["meta"] = {["fields"] = {}, ["inventory"] = {}}, ["y"] = 0, ["z"] = 5, ["name"] = "rainbow:stonebrick_cyan"}, {["x"] = 1, ["meta"] = {["fields"] = {}, ["inventory"] = {}}, ["y"] = 0, ["z"] = 6, ["name"] = "rainbow:stonebrick_blue"}, {["x"] = 1, ["meta"] = {["fields"] = {}, ["inventory"] = {}}, ["y"] = 0, ["z"] = 7, ["name"] = "rainbow:stonebrick_violet"}, {["x"] = 1, ["meta"] = {["fields"] = {}, ["inventory"] = {}}, ["y"] = 1, ["param1"] = 170, ["z"] = 0, ["name"] = "default:water_source"}, {["x"] = 1, ["meta"] = {["fields"] = {}, ["inventory"] = {}}, ["y"] = 1, ["param1"] = 153, ["z"] = 1, ["name"] = "default:water_source"}, {["x"] = 1, ["meta"] = {["fields"] = {}, ["inventory"] = {}}, ["y"] = 1, ["param1"] = 136, ["z"] = 2, ["name"] = "default:water_source"}, {["x"] = 1, ["meta"] = {["fields"] = {}, ["inventory"] = {}}, ["y"] = 1, ["param1"] = 120, ["z"] = 3, ["name"] = "default:water_source"}, {["x"] = 1, ["meta"] = {["fields"] = {}, ["inventory"] = {}}, ["y"] = 1, ["param1"] = 104, ["z"] = 4, ["name"] = "default:water_source"}, {["x"] = 1, ["meta"] = {["fields"] = {}, ["inventory"] = {}}, ["param2"] = 240, ["y"] = 1, ["param1"] = 88, ["z"] = 5, ["name"] = "default:water_source"}, {["x"] = 1, ["meta"] = {["fields"] = {}, ["inventory"] = {}}, ["y"] = 1, ["param1"] = 72, ["z"] = 6, ["name"] = "default:water_source"}, {["x"] = 1, ["meta"] = {["fields"] = {}, ["inventory"] = {}}, ["y"] = 1, ["param1"] = 57, ["z"] = 7, ["name"] = "default:water_source"}, {["x"] = 1, ["meta"] = {["fields"] = {}, ["inventory"] = {}}, ["y"] = 2, ["param1"] = 153, ["z"] = 0, ["name"] = "default:water_source"}, {["x"] = 1, ["meta"] = {["fields"] = {}, ["inventory"] = {}}, ["y"] = 2, ["param1"] = 137, ["z"] = 1, ["name"] = "default:water_source"}, {["x"] = 1, ["meta"] = {["fields"] = {}, ["inventory"] = {}}, ["y"] = 2, ["param1"] = 121, ["z"] = 2, ["name"] = "default:water_source"}, {["x"] = 1, ["meta"] = {["fields"] = {}, ["inventory"] = {}}, ["y"] = 2, ["param1"] = 105, ["z"] = 3, ["name"] = "default:water_source"}, {["x"] = 1, ["meta"] = {["fields"] = {}, ["inventory"] = {}}, ["y"] = 2, ["param1"] = 89, ["z"] = 4, ["name"] = "default:water_source"}, {["x"] = 1, ["meta"] = {["fields"] = {}, ["inventory"] = {}}, ["y"] = 2, ["param1"] = 73, ["z"] = 5, ["name"] = "default:water_source"}, {["x"] = 1, ["meta"] = {["fields"] = {}, ["inventory"] = {}}, ["y"] = 2, ["param1"] = 57, ["z"] = 6, ["name"] = "default:water_source"}, {["x"] = 1, ["meta"] = {["fields"] = {}, ["inventory"] = {}}, ["y"] = 2, ["param1"] = 42, ["z"] = 7, ["name"] = "default:water_source"}, {["x"] = 1, ["meta"] = {["fields"] = {}, ["inventory"] = {}}, ["y"] = 3, ["param1"] = 137, ["z"] = 0, ["name"] = "default:water_source"}, {["x"] = 1, ["meta"] = {["fields"] = {}, ["inventory"] = {}}, ["y"] = 3, ["param1"] = 122, ["z"] = 1, ["name"] = "default:water_source"}, {["x"] = 1, ["meta"] = {["fields"] = {}, ["inventory"] = {}}, ["y"] = 3, ["param1"] = 106, ["z"] = 2, ["name"] = "default:water_source"}, {["x"] = 1, ["meta"] = {["fields"] = {}, ["inventory"] = {}}, ["y"] = 3, ["param1"] = 90, ["z"] = 3, ["name"] = "default:water_source"}, {["x"] = 1, ["meta"] = {["fields"] = {}, ["inventory"] = {}}, ["y"] = 3, ["param1"] = 74, ["z"] = 4, ["name"] = "default:water_source"}, {["x"] = 1, ["meta"] = {["fields"] = {}, ["inventory"] = {}}, ["y"] = 3, ["param1"] = 58, ["z"] = 5, ["name"] = "default:water_source"}, {["x"] = 1, ["meta"] = {["fields"] = {}, ["inventory"] = {}}, ["y"] = 3, ["param1"] = 42, ["z"] = 6, ["name"] = "default:water_source"}, {["x"] = 1, ["meta"] = {["fields"] = {}, ["inventory"] = {}}, ["y"] = 3, ["param1"] = 27, ["z"] = 7, ["name"] = "default:water_source"}, {["x"] = 1, ["meta"] = {["fields"] = {}, ["inventory"] = {}}, ["y"] = 4, ["param1"] = 122, ["z"] = 0, ["name"] = "default:water_source"}, {["x"] = 1, ["meta"] = {["fields"] = {}, ["inventory"] = {}}, ["y"] = 4, ["param1"] = 107, ["z"] = 1, ["name"] = "default:water_source"}, {["x"] = 1, ["meta"] = {["fields"] = {}, ["inventory"] = {}}, ["y"] = 4, ["param1"] = 91, ["z"] = 2, ["name"] = "default:water_source"}, {["x"] = 1, ["meta"] = {["fields"] = {}, ["inventory"] = {}}, ["y"] = 4, ["param1"] = 75, ["z"] = 3, ["name"] = "default:water_source"}, {["x"] = 1, ["meta"] = {["fields"] = {}, ["inventory"] = {}}, ["y"] = 4, ["param1"] = 59, ["z"] = 4, ["name"] = "default:water_source"}, {["x"] = 1, ["meta"] = {["fields"] = {}, ["inventory"] = {}}, ["y"] = 4, ["param1"] = 43, ["z"] = 5, ["name"] = "default:water_source"}, {["x"] = 1, ["meta"] = {["fields"] = {}, ["inventory"] = {}}, ["y"] = 4, ["param1"] = 27, ["z"] = 6, ["name"] = "default:water_source"}, {["x"] = 1, ["meta"] = {["fields"] = {}, ["inventory"] = {}}, ["y"] = 4, ["param1"] = 12, ["z"] = 7, ["name"] = "default:water_source"}, {["x"] = 1, ["meta"] = {["fields"] = {}, ["inventory"] = {}}, ["y"] = 5, ["param1"] = 107, ["z"] = 0, ["name"] = "default:water_source"}, {["x"] = 1, ["meta"] = {["fields"] = {}, ["inventory"] = {}}, ["y"] = 5, ["param1"] = 92, ["z"] = 1, ["name"] = "default:water_source"}, {["x"] = 1, ["meta"] = {["fields"] = {}, ["inventory"] = {}}, ["y"] = 5, ["param1"] = 76, ["z"] = 2, ["name"] = "default:water_source"}, {["x"] = 1, ["meta"] = {["fields"] = {}, ["inventory"] = {}}, ["y"] = 5, ["param1"] = 60, ["z"] = 3, ["name"] = "default:water_source"}, {["x"] = 1, ["meta"] = {["fields"] = {}, ["inventory"] = {}}, ["y"] = 5, ["param1"] = 44, ["z"] = 4, ["name"] = "default:water_source"}, {["x"] = 1, ["meta"] = {["fields"] = {}, ["inventory"] = {}}, ["y"] = 5, ["param1"] = 28, ["z"] = 5, ["name"] = "default:water_source"}, {["x"] = 1, ["meta"] = {["fields"] = {}, ["inventory"] = {}}, ["y"] = 5, ["param1"] = 12, ["z"] = 6, ["name"] = "default:water_source"}, {["x"] = 1, ["meta"] = {["fields"] = {}, ["inventory"] = {}}, ["y"] = 5, ["param1"] = 13, ["z"] = 7, ["name"] = "default:water_source"}, {["x"] = 1, ["meta"] = {["fields"] = {}, ["inventory"] = {}}, ["param2"] = 21, ["y"] = 26, ["param1"] = 92, ["z"] = 0, ["name"] = "rainbow:slope_stonebrick_black"}, {["x"] = 1, ["meta"] = {["fields"] = {}, ["inventory"] = {}}, ["param2"] = 1, ["y"] = 27, ["param1"] = 108, ["z"] = 0, ["name"] = "rainbow:slope_stonebrick_black"}, {["x"] = 1, ["meta"] = {["fields"] = {}, ["inventory"] = {}}, ["param2"] = 22, ["y"] = 27, ["param1"] = 125, ["z"] = 1, ["name"] = "rainbow:slab_stonebrick_black_1"}, {["x"] = 1, ["meta"] = {["fields"] = {}, ["inventory"] = {}}, ["param2"] = 3, ["y"] = 28, ["param1"] = 124, ["z"] = 0, ["name"] = "default:ladder_steel"}, {["x"] = 1, ["meta"] = {["fields"] = {}, ["inventory"] = {}}, ["param2"] = 7, ["y"] = 28, ["param1"] = 125, ["z"] = 2, ["name"] = "rainbow:slab_stonebrick_black_1"}, {["x"] = 1, ["meta"] = {["fields"] = {}, ["inventory"] = {}}, ["param2"] = 3, ["y"] = 29, ["param1"] = 140, ["z"] = 0, ["name"] = "default:ladder_steel"}, {["x"] = 1, ["meta"] = {["fields"] = {}, ["inventory"] = {}}, ["param2"] = 3, ["y"] = 30, ["param1"] = 156, ["z"] = 0, ["name"] = "default:ladder_steel"}, {["x"] = 1, ["meta"] = {["fields"] = {}, ["inventory"] = {}}, ["param2"] = 3, ["y"] = 31, ["param1"] = 141, ["z"] = 0, ["name"] = "default:ladder_steel"}, {["x"] = 1, ["meta"] = {["fields"] = {}, ["inventory"] = {}}, ["y"] = 31, ["z"] = 1, ["name"] = "rainbow:stonebrick_red"}, {["x"] = 1, ["meta"] = {["fields"] = {}, ["inventory"] = {}}, ["y"] = 31, ["z"] = 2, ["name"] = "rainbow:stonebrick_orange"}, {["x"] = 1, ["meta"] = {["fields"] = {}, ["inventory"] = {}}, ["y"] = 31, ["z"] = 3, ["name"] = "rainbow:stonebrick_yellow"}, {["x"] = 1, ["meta"] = {["fields"] = {}, ["inventory"] = {}}, ["y"] = 31, ["z"] = 4, ["name"] = "rainbow:stonebrick_lightgreen"}, {["x"] = 1, ["meta"] = {["fields"] = {}, ["inventory"] = {}}, ["y"] = 31, ["z"] = 5, ["name"] = "rainbow:stonebrick_cyan"}, {["x"] = 1, ["meta"] = {["fields"] = {}, ["inventory"] = {}}, ["y"] = 31, ["z"] = 6, ["name"] = "rainbow:stonebrick_blue"}, {["x"] = 1, ["meta"] = {["fields"] = {}, ["inventory"] = {}}, ["y"] = 31, ["z"] = 7, ["name"] = "rainbow:stonebrick_violet"}, {["x"] = 1, ["meta"] = {["fields"] = {["infotext"] = "Owned by Nigel", ["doors_owner"] = "Nigel"}, ["inventory"] = {}}, ["param2"] = 2, ["y"] = 32, ["param1"] = 158, ["z"] = 0, ["name"] = "doors:trapdoor_steel"}, {["x"] = 2, ["meta"] = {["fields"] = {}, ["inventory"] = {}}, ["y"] = 0, ["z"] = 0, ["name"] = "rainbow:stonebrick_black"}, {["x"] = 2, ["meta"] = {["fields"] = {}, ["inventory"] = {}}, ["y"] = 0, ["z"] = 1, ["name"] = "rainbow:stonebrick_red"}, {["x"] = 2, ["meta"] = {["fields"] = {}, ["inventory"] = {}}, ["y"] = 0, ["z"] = 2, ["name"] = "rainbow:stonebrick_orange"}, {["x"] = 2, ["meta"] = {["fields"] = {}, ["inventory"] = {}}, ["y"] = 0, ["z"] = 3, ["name"] = "rainbow:stonebrick_yellow"}, {["x"] = 2, ["meta"] = {["fields"] = {}, ["inventory"] = {}}, ["y"] = 0, ["z"] = 4, ["name"] = "rainbow:stonebrick_lightgreen"}, {["x"] = 2, ["meta"] = {["fields"] = {}, ["inventory"] = {}}, ["y"] = 0, ["z"] = 5, ["name"] = "rainbow:stonebrick_cyan"}, {["x"] = 2, ["meta"] = {["fields"] = {}, ["inventory"] = {}}, ["y"] = 0, ["z"] = 6, ["name"] = "rainbow:stonebrick_blue"}, {["x"] = 2, ["meta"] = {["fields"] = {}, ["inventory"] = {}}, ["y"] = 0, ["z"] = 7, ["name"] = "rainbow:stonebrick_violet"}, {["x"] = 2, ["meta"] = {["fields"] = {}, ["inventory"] = {}}, ["y"] = 1, ["param1"] = 187, ["z"] = 0, ["name"] = "default:water_source"}, {["x"] = 2, ["meta"] = {["fields"] = {}, ["inventory"] = {}}, ["y"] = 1, ["param1"] = 170, ["z"] = 1, ["name"] = "default:water_source"}, {["x"] = 2, ["meta"] = {["fields"] = {}, ["inventory"] = {}}, ["y"] = 1, ["param1"] = 153, ["z"] = 2, ["name"] = "default:water_source"}, {["x"] = 2, ["meta"] = {["fields"] = {}, ["inventory"] = {}}, ["y"] = 1, ["param1"] = 136, ["z"] = 3, ["name"] = "default:water_source"}, {["x"] = 2, ["meta"] = {["fields"] = {}, ["inventory"] = {}}, ["y"] = 1, ["param1"] = 119, ["z"] = 4, ["name"] = "default:water_source"}, {["x"] = 2, ["meta"] = {["fields"] = {}, ["inventory"] = {}}, ["y"] = 1, ["param1"] = 103, ["z"] = 5, ["name"] = "default:water_source"}, {["x"] = 2, ["meta"] = {["fields"] = {}, ["inventory"] = {}}, ["y"] = 1, ["param1"] = 88, ["z"] = 6, ["name"] = "default:water_source"}, {["x"] = 2, ["meta"] = {["fields"] = {}, ["inventory"] = {}}, ["y"] = 1, ["param1"] = 73, ["z"] = 7, ["name"] = "default:water_source"}, {["x"] = 2, ["meta"] = {["fields"] = {}, ["inventory"] = {}}, ["y"] = 2, ["param1"] = 170, ["z"] = 0, ["name"] = "default:water_source"}, {["x"] = 2, ["meta"] = {["fields"] = {}, ["inventory"] = {}}, ["y"] = 2, ["param1"] = 153, ["z"] = 1, ["name"] = "default:water_source"}, {["x"] = 2, ["meta"] = {["fields"] = {}, ["inventory"] = {}}, ["y"] = 2, ["param1"] = 136, ["z"] = 2, ["name"] = "default:water_source"}, {["x"] = 2, ["meta"] = {["fields"] = {}, ["inventory"] = {}}, ["y"] = 2, ["param1"] = 120, ["z"] = 3, ["name"] = "default:water_source"}, {["x"] = 2, ["meta"] = {["fields"] = {}, ["inventory"] = {}}, ["y"] = 2, ["param1"] = 104, ["z"] = 4, ["name"] = "default:water_source"}, {["x"] = 2, ["meta"] = {["fields"] = {}, ["inventory"] = {}}, ["y"] = 2, ["param1"] = 88, ["z"] = 5, ["name"] = "default:water_source"}, {["x"] = 2, ["meta"] = {["fields"] = {}, ["inventory"] = {}}, ["y"] = 2, ["param1"] = 73, ["z"] = 6, ["name"] = "default:water_source"}, {["x"] = 2, ["meta"] = {["fields"] = {}, ["inventory"] = {}}, ["y"] = 2, ["param1"] = 58, ["z"] = 7, ["name"] = "default:water_source"}, {["x"] = 2, ["meta"] = {["fields"] = {}, ["inventory"] = {}}, ["y"] = 3, ["param1"] = 153, ["z"] = 0, ["name"] = "default:water_source"}, {["x"] = 2, ["meta"] = {["fields"] = {}, ["inventory"] = {}}, ["y"] = 3, ["param1"] = 137, ["z"] = 1, ["name"] = "default:water_source"}, {["x"] = 2, ["meta"] = {["fields"] = {}, ["inventory"] = {}}, ["y"] = 3, ["param1"] = 121, ["z"] = 2, ["name"] = "default:water_source"}, {["x"] = 2, ["meta"] = {["fields"] = {}, ["inventory"] = {}}, ["y"] = 3, ["param1"] = 105, ["z"] = 3, ["name"] = "default:water_source"}, {["x"] = 2, ["meta"] = {["fields"] = {}, ["inventory"] = {}}, ["y"] = 3, ["param1"] = 89, ["z"] = 4, ["name"] = "default:water_source"}, {["x"] = 2, ["meta"] = {["fields"] = {}, ["inventory"] = {}}, ["y"] = 3, ["param1"] = 73, ["z"] = 5, ["name"] = "default:water_source"}, {["x"] = 2, ["meta"] = {["fields"] = {}, ["inventory"] = {}}, ["y"] = 3, ["param1"] = 58, ["z"] = 6, ["name"] = "default:water_source"}, {["x"] = 2, ["meta"] = {["fields"] = {}, ["inventory"] = {}}, ["y"] = 3, ["param1"] = 43, ["z"] = 7, ["name"] = "default:water_source"}, {["x"] = 2, ["meta"] = {["fields"] = {}, ["inventory"] = {}}, ["y"] = 4, ["param1"] = 137, ["z"] = 0, ["name"] = "default:water_source"}, {["x"] = 2, ["meta"] = {["fields"] = {}, ["inventory"] = {}}, ["y"] = 4, ["param1"] = 122, ["z"] = 1, ["name"] = "default:water_source"}, {["x"] = 2, ["meta"] = {["fields"] = {}, ["inventory"] = {}}, ["y"] = 4, ["param1"] = 106, ["z"] = 2, ["name"] = "default:water_source"}, {["x"] = 2, ["meta"] = {["fields"] = {}, ["inventory"] = {}}, ["y"] = 4, ["param1"] = 90, ["z"] = 3, ["name"] = "default:water_source"}, {["x"] = 2, ["meta"] = {["fields"] = {}, ["inventory"] = {}}, ["y"] = 4, ["param1"] = 74, ["z"] = 4, ["name"] = "default:water_source"}, {["x"] = 2, ["meta"] = {["fields"] = {}, ["inventory"] = {}}, ["y"] = 4, ["param1"] = 58, ["z"] = 5, ["name"] = "default:water_source"}, {["x"] = 2, ["meta"] = {["fields"] = {}, ["inventory"] = {}}, ["y"] = 4, ["param1"] = 43, ["z"] = 6, ["name"] = "default:water_source"}, {["x"] = 2, ["meta"] = {["fields"] = {}, ["inventory"] = {}}, ["y"] = 4, ["param1"] = 28, ["z"] = 7, ["name"] = "default:water_source"}, {["x"] = 2, ["meta"] = {["fields"] = {}, ["inventory"] = {}}, ["y"] = 5, ["param1"] = 122, ["z"] = 0, ["name"] = "default:water_source"}, {["x"] = 2, ["meta"] = {["fields"] = {}, ["inventory"] = {}}, ["y"] = 5, ["param1"] = 107, ["z"] = 1, ["name"] = "default:water_source"}, {["x"] = 2, ["meta"] = {["fields"] = {}, ["inventory"] = {}}, ["y"] = 5, ["param1"] = 91, ["z"] = 2, ["name"] = "default:water_source"}, {["x"] = 2, ["meta"] = {["fields"] = {}, ["inventory"] = {}}, ["y"] = 5, ["param1"] = 75, ["z"] = 3, ["name"] = "default:water_source"}, {["x"] = 2, ["meta"] = {["fields"] = {}, ["inventory"] = {}}, ["y"] = 5, ["param1"] = 59, ["z"] = 4, ["name"] = "default:water_source"}, {["x"] = 2, ["meta"] = {["fields"] = {}, ["inventory"] = {}}, ["y"] = 5, ["param1"] = 43, ["z"] = 5, ["name"] = "default:water_source"}, {["x"] = 2, ["meta"] = {["fields"] = {}, ["inventory"] = {}}, ["y"] = 5, ["param1"] = 28, ["z"] = 6, ["name"] = "default:water_source"}, {["x"] = 2, ["meta"] = {["fields"] = {}, ["inventory"] = {}}, ["y"] = 5, ["param1"] = 13, ["z"] = 7, ["name"] = "default:water_source"}, {["x"] = 2, ["meta"] = {["fields"] = {}, ["inventory"] = {}}, ["param2"] = 21, ["y"] = 27, ["param1"] = 123, ["z"] = 0, ["name"] = "rainbow:slope_stonebrick_black"}, {["x"] = 2, ["meta"] = {["fields"] = {}, ["inventory"] = {}}, ["param2"] = 22, ["y"] = 27, ["param1"] = 140, ["z"] = 1, ["name"] = "rainbow:slab_stonebrick_black_1"}, {["x"] = 2, ["meta"] = {["fields"] = {}, ["inventory"] = {}}, ["param2"] = 1, ["y"] = 28, ["param1"] = 140, ["z"] = 0, ["name"] = "rainbow:slope_stonebrick_black"}, {["x"] = 2, ["meta"] = {["fields"] = {}, ["inventory"] = {}}, ["param2"] = 7, ["y"] = 28, ["param1"] = 140, ["z"] = 2, ["name"] = "rainbow:slab_stonebrick_black_1"}, {["x"] = 2, ["meta"] = {["fields"] = {}, ["inventory"] = {}}, ["y"] = 31, ["z"] = 0, ["name"] = "rainbow:stonebrick_black"}, {["x"] = 2, ["meta"] = {["fields"] = {}, ["inventory"] = {}}, ["y"] = 31, ["z"] = 1, ["name"] = "rainbow:stonebrick_red"}, {["x"] = 2, ["meta"] = {["fields"] = {}, ["inventory"] = {}}, ["y"] = 31, ["z"] = 2, ["name"] = "rainbow:stonebrick_orange"}, {["x"] = 2, ["meta"] = {["fields"] = {}, ["inventory"] = {}}, ["y"] = 31, ["z"] = 3, ["name"] = "rainbow:stonebrick_yellow"}, {["x"] = 2, ["meta"] = {["fields"] = {}, ["inventory"] = {}}, ["y"] = 31, ["z"] = 4, ["name"] = "rainbow:stonebrick_lightgreen"}, {["x"] = 2, ["meta"] = {["fields"] = {}, ["inventory"] = {}}, ["y"] = 31, ["z"] = 5, ["name"] = "rainbow:stonebrick_cyan"}, {["x"] = 2, ["meta"] = {["fields"] = {}, ["inventory"] = {}}, ["y"] = 31, ["z"] = 6, ["name"] = "rainbow:stonebrick_blue"}, {["x"] = 2, ["meta"] = {["fields"] = {}, ["inventory"] = {}}, ["y"] = 31, ["z"] = 7, ["name"] = "rainbow:stonebrick_violet"}, {["x"] = 3, ["meta"] = {["fields"] = {}, ["inventory"] = {}}, ["y"] = 0, ["z"] = 0, ["name"] = "rainbow:stonebrick_black"}, {["x"] = 3, ["meta"] = {["fields"] = {}, ["inventory"] = {}}, ["y"] = 0, ["z"] = 1, ["name"] = "rainbow:stonebrick_red"}, {["x"] = 3, ["meta"] = {["fields"] = {}, ["inventory"] = {}}, ["y"] = 0, ["z"] = 2, ["name"] = "rainbow:stonebrick_orange"}, {["x"] = 3, ["meta"] = {["fields"] = {}, ["inventory"] = {}}, ["y"] = 0, ["z"] = 3, ["name"] = "rainbow:stonebrick_yellow"}, {["x"] = 3, ["meta"] = {["fields"] = {}, ["inventory"] = {}}, ["y"] = 0, ["z"] = 4, ["name"] = "rainbow:stonebrick_lightgreen"}, {["x"] = 3, ["meta"] = {["fields"] = {}, ["inventory"] = {}}, ["y"] = 0, ["z"] = 5, ["name"] = "rainbow:stonebrick_cyan"}, {["x"] = 3, ["meta"] = {["fields"] = {}, ["inventory"] = {}}, ["y"] = 0, ["z"] = 6, ["name"] = "rainbow:stonebrick_blue"}, {["x"] = 3, ["meta"] = {["fields"] = {}, ["inventory"] = {}}, ["y"] = 0, ["z"] = 7, ["name"] = "rainbow:stonebrick_violet"}, {["x"] = 3, ["meta"] = {["fields"] = {}, ["inventory"] = {}}, ["y"] = 1, ["param1"] = 204, ["z"] = 0, ["name"] = "default:water_source"}, {["x"] = 3, ["meta"] = {["fields"] = {}, ["inventory"] = {}}, ["y"] = 1, ["param1"] = 187, ["z"] = 1, ["name"] = "default:water_source"}, {["x"] = 3, ["meta"] = {["fields"] = {}, ["inventory"] = {}}, ["y"] = 1, ["param1"] = 170, ["z"] = 2, ["name"] = "default:water_source"}, {["x"] = 3, ["meta"] = {["fields"] = {}, ["inventory"] = {}}, ["y"] = 1, ["param1"] = 153, ["z"] = 3, ["name"] = "default:water_source"}, {["x"] = 3, ["meta"] = {["fields"] = {}, ["inventory"] = {}}, ["y"] = 1, ["param1"] = 136, ["z"] = 4, ["name"] = "default:water_source"}, {["x"] = 3, ["meta"] = {["fields"] = {}, ["inventory"] = {}}, ["y"] = 1, ["param1"] = 119, ["z"] = 5, ["name"] = "default:water_source"}, {["x"] = 3, ["meta"] = {["fields"] = {}, ["inventory"] = {}}, ["y"] = 1, ["param1"] = 104, ["z"] = 6, ["name"] = "default:water_source"}, {["x"] = 3, ["meta"] = {["fields"] = {}, ["inventory"] = {}}, ["y"] = 1, ["param1"] = 89, ["z"] = 7, ["name"] = "default:water_source"}, {["x"] = 3, ["meta"] = {["fields"] = {}, ["inventory"] = {}}, ["y"] = 2, ["param1"] = 187, ["z"] = 0, ["name"] = "default:water_source"}, {["x"] = 3, ["meta"] = {["fields"] = {}, ["inventory"] = {}}, ["y"] = 2, ["param1"] = 170, ["z"] = 1, ["name"] = "default:water_source"}, {["x"] = 3, ["meta"] = {["fields"] = {}, ["inventory"] = {}}, ["y"] = 2, ["param1"] = 153, ["z"] = 2, ["name"] = "default:water_source"}, {["x"] = 3, ["meta"] = {["fields"] = {}, ["inventory"] = {}}, ["y"] = 2, ["param1"] = 136, ["z"] = 3, ["name"] = "default:water_source"}, {["x"] = 3, ["meta"] = {["fields"] = {}, ["inventory"] = {}}, ["y"] = 2, ["param1"] = 119, ["z"] = 4, ["name"] = "default:water_source"}, {["x"] = 3, ["meta"] = {["fields"] = {}, ["inventory"] = {}}, ["y"] = 2, ["param1"] = 104, ["z"] = 5, ["name"] = "default:water_source"}, {["x"] = 3, ["meta"] = {["fields"] = {}, ["inventory"] = {}}, ["y"] = 2, ["param1"] = 89, ["z"] = 6, ["name"] = "default:water_source"}, {["x"] = 3, ["meta"] = {["fields"] = {}, ["inventory"] = {}}, ["y"] = 2, ["param1"] = 74, ["z"] = 7, ["name"] = "default:water_source"}, {["x"] = 3, ["meta"] = {["fields"] = {}, ["inventory"] = {}}, ["y"] = 3, ["param1"] = 170, ["z"] = 0, ["name"] = "default:water_source"}, {["x"] = 3, ["meta"] = {["fields"] = {}, ["inventory"] = {}}, ["y"] = 3, ["param1"] = 153, ["z"] = 1, ["name"] = "default:water_source"}, {["x"] = 3, ["meta"] = {["fields"] = {}, ["inventory"] = {}}, ["y"] = 3, ["param1"] = 136, ["z"] = 2, ["name"] = "default:water_source"}, {["x"] = 3, ["meta"] = {["fields"] = {}, ["inventory"] = {}}, ["y"] = 3, ["param1"] = 120, ["z"] = 3, ["name"] = "default:water_source"}, {["x"] = 3, ["meta"] = {["fields"] = {}, ["inventory"] = {}}, ["y"] = 3, ["param1"] = 104, ["z"] = 4, ["name"] = "default:water_source"}, {["x"] = 3, ["meta"] = {["fields"] = {}, ["inventory"] = {}}, ["y"] = 3, ["param1"] = 89, ["z"] = 5, ["name"] = "default:water_source"}, {["x"] = 3, ["meta"] = {["fields"] = {}, ["inventory"] = {}}, ["y"] = 3, ["param1"] = 74, ["z"] = 6, ["name"] = "default:water_source"}, {["x"] = 3, ["meta"] = {["fields"] = {}, ["inventory"] = {}}, ["y"] = 3, ["param1"] = 59, ["z"] = 7, ["name"] = "default:water_source"}, {["x"] = 3, ["meta"] = {["fields"] = {}, ["inventory"] = {}}, ["y"] = 4, ["param1"] = 153, ["z"] = 0, ["name"] = "default:water_source"}, {["x"] = 3, ["meta"] = {["fields"] = {}, ["inventory"] = {}}, ["y"] = 4, ["param1"] = 137, ["z"] = 1, ["name"] = "default:water_source"}, {["x"] = 3, ["meta"] = {["fields"] = {}, ["inventory"] = {}}, ["y"] = 4, ["param1"] = 121, ["z"] = 2, ["name"] = "default:water_source"}, {["x"] = 3, ["meta"] = {["fields"] = {}, ["inventory"] = {}}, ["y"] = 4, ["param1"] = 105, ["z"] = 3, ["name"] = "default:water_source"}, {["x"] = 3, ["meta"] = {["fields"] = {}, ["inventory"] = {}}, ["y"] = 4, ["param1"] = 89, ["z"] = 4, ["name"] = "default:water_source"}, {["x"] = 3, ["meta"] = {["fields"] = {}, ["inventory"] = {}}, ["y"] = 4, ["param1"] = 74, ["z"] = 5, ["name"] = "default:water_source"}, {["x"] = 3, ["meta"] = {["fields"] = {}, ["inventory"] = {}}, ["y"] = 4, ["param1"] = 59, ["z"] = 6, ["name"] = "default:water_source"}, {["x"] = 3, ["meta"] = {["fields"] = {}, ["inventory"] = {}}, ["y"] = 4, ["param1"] = 44, ["z"] = 7, ["name"] = "default:water_source"}, {["x"] = 3, ["meta"] = {["fields"] = {}, ["inventory"] = {}}, ["y"] = 5, ["param1"] = 137, ["z"] = 0, ["name"] = "default:water_source"}, {["x"] = 3, ["meta"] = {["fields"] = {}, ["inventory"] = {}}, ["y"] = 5, ["param1"] = 122, ["z"] = 1, ["name"] = "default:water_source"}, {["x"] = 3, ["meta"] = {["fields"] = {}, ["inventory"] = {}}, ["y"] = 5, ["param1"] = 106, ["z"] = 2, ["name"] = "default:water_source"}, {["x"] = 3, ["meta"] = {["fields"] = {}, ["inventory"] = {}}, ["y"] = 5, ["param1"] = 90, ["z"] = 3, ["name"] = "default:water_source"}, {["x"] = 3, ["meta"] = {["fields"] = {}, ["inventory"] = {}}, ["y"] = 5, ["param1"] = 74, ["z"] = 4, ["name"] = "default:water_source"}, {["x"] = 3, ["meta"] = {["fields"] = {}, ["inventory"] = {}}, ["y"] = 5, ["param1"] = 59, ["z"] = 5, ["name"] = "default:water_source"}, {["x"] = 3, ["meta"] = {["fields"] = {}, ["inventory"] = {}}, ["y"] = 5, ["param1"] = 44, ["z"] = 6, ["name"] = "default:water_source"}, {["x"] = 3, ["meta"] = {["fields"] = {}, ["inventory"] = {}}, ["y"] = 5, ["param1"] = 29, ["z"] = 7, ["name"] = "default:water_source"}, {["x"] = 3, ["meta"] = {["fields"] = {}, ["inventory"] = {}}, ["param2"] = 22, ["y"] = 27, ["param1"] = 157, ["z"] = 1, ["name"] = "rainbow:slab_stonebrick_black_1"}, {["x"] = 3, ["meta"] = {["fields"] = {}, ["inventory"] = {}}, ["param2"] = 21, ["y"] = 28, ["param1"] = 157, ["z"] = 0, ["name"] = "rainbow:slope_stonebrick_black"}, {["x"] = 3, ["meta"] = {["fields"] = {}, ["inventory"] = {}}, ["param2"] = 18, ["y"] = 28, ["param1"] = 157, ["z"] = 2, ["name"] = "rainbow:slab_stonebrick_black_1"}, {["x"] = 3, ["meta"] = {["fields"] = {}, ["inventory"] = {}}, ["param2"] = 18, ["y"] = 28, ["param1"] = 174, ["z"] = 3, ["name"] = "rainbow:slab_stonebrick_black_1"}, {["x"] = 3, ["meta"] = {["fields"] = {}, ["inventory"] = {}}, ["param2"] = 18, ["y"] = 28, ["param1"] = 157, ["z"] = 4, ["name"] = "rainbow:slab_stonebrick_black_1"}, {["x"] = 3, ["meta"] = {["fields"] = {}, ["inventory"] = {}}, ["param2"] = 18, ["y"] = 28, ["param1"] = 174, ["z"] = 5, ["name"] = "rainbow:slab_stonebrick_black_1"}, {["x"] = 3, ["meta"] = {["fields"] = {}, ["inventory"] = {}}, ["param2"] = 18, ["y"] = 28, ["param1"] = 157, ["z"] = 6, ["name"] = "rainbow:slab_stonebrick_black_1"}, {["x"] = 3, ["meta"] = {["fields"] = {}, ["inventory"] = {}}, ["param2"] = 18, ["y"] = 28, ["param1"] = 174, ["z"] = 7, ["name"] = "rainbow:slab_stonebrick_black_1"}, {["x"] = 3, ["meta"] = {["fields"] = {}, ["inventory"] = {}}, ["y"] = 29, ["z"] = 0, ["name"] = "rainbow:stonebrick_black"}, {["x"] = 3, ["meta"] = {["fields"] = {}, ["inventory"] = {}}, ["y"] = 30, ["z"] = 0, ["name"] = "rainbow:stonebrick_black"}, {["x"] = 3, ["meta"] = {["fields"] = {}, ["inventory"] = {}}, ["y"] = 31, ["z"] = 0, ["name"] = "rainbow:stonebrick_black"}, {["x"] = 3, ["meta"] = {["fields"] = {}, ["inventory"] = {}}, ["y"] = 31, ["z"] = 1, ["name"] = "rainbow:stonebrick_red"}, {["x"] = 3, ["meta"] = {["fields"] = {}, ["inventory"] = {}}, ["y"] = 31, ["z"] = 2, ["name"] = "rainbow:stonebrick_orange"}, {["x"] = 3, ["meta"] = {["fields"] = {}, ["inventory"] = {}}, ["y"] = 31, ["z"] = 3, ["name"] = "rainbow:stonebrick_yellow"}, {["x"] = 3, ["meta"] = {["fields"] = {}, ["inventory"] = {}}, ["y"] = 31, ["z"] = 4, ["name"] = "rainbow:stonebrick_lightgreen"}, {["x"] = 3, ["meta"] = {["fields"] = {}, ["inventory"] = {}}, ["y"] = 31, ["z"] = 5, ["name"] = "rainbow:stonebrick_cyan"}, {["x"] = 3, ["meta"] = {["fields"] = {}, ["inventory"] = {}}, ["y"] = 31, ["z"] = 6, ["name"] = "rainbow:stonebrick_blue"}, {["x"] = 3, ["meta"] = {["fields"] = {}, ["inventory"] = {}}, ["y"] = 31, ["z"] = 7, ["name"] = "rainbow:stonebrick_violet"}, {["x"] = 4, ["meta"] = {["fields"] = {}, ["inventory"] = {}}, ["y"] = 0, ["param1"] = 238, ["z"] = 0, ["name"] = "default:meselamp"}, {["x"] = 4, ["meta"] = {["fields"] = {}, ["inventory"] = {}}, ["y"] = 0, ["z"] = 1, ["name"] = "rainbow:stonebrick_red"}, {["x"] = 4, ["meta"] = {["fields"] = {}, ["inventory"] = {}}, ["y"] = 0, ["z"] = 2, ["name"] = "rainbow:stonebrick_orange"}, {["x"] = 4, ["meta"] = {["fields"] = {}, ["inventory"] = {}}, ["y"] = 0, ["z"] = 3, ["name"] = "rainbow:stonebrick_yellow"}, {["x"] = 4, ["meta"] = {["fields"] = {}, ["inventory"] = {}}, ["y"] = 0, ["z"] = 4, ["name"] = "rainbow:stonebrick_lightgreen"}, {["x"] = 4, ["meta"] = {["fields"] = {}, ["inventory"] = {}}, ["y"] = 0, ["z"] = 5, ["name"] = "rainbow:stonebrick_cyan"}, {["x"] = 4, ["meta"] = {["fields"] = {}, ["inventory"] = {}}, ["y"] = 0, ["z"] = 6, ["name"] = "rainbow:stonebrick_blue"}, {["x"] = 4, ["meta"] = {["fields"] = {}, ["inventory"] = {}}, ["y"] = 0, ["z"] = 7, ["name"] = "rainbow:stonebrick_violet"}, {["x"] = 4, ["meta"] = {["fields"] = {}, ["inventory"] = {}}, ["y"] = 1, ["param1"] = 221, ["z"] = 0, ["name"] = "default:water_source"}, {["x"] = 4, ["meta"] = {["fields"] = {}, ["inventory"] = {}}, ["y"] = 1, ["param1"] = 204, ["z"] = 1, ["name"] = "default:water_source"}, {["x"] = 4, ["meta"] = {["fields"] = {}, ["inventory"] = {}}, ["y"] = 1, ["param1"] = 187, ["z"] = 2, ["name"] = "default:water_source"}, {["x"] = 4, ["meta"] = {["fields"] = {}, ["inventory"] = {}}, ["y"] = 1, ["param1"] = 170, ["z"] = 3, ["name"] = "default:water_source"}, {["x"] = 4, ["meta"] = {["fields"] = {}, ["inventory"] = {}}, ["y"] = 1, ["param1"] = 153, ["z"] = 4, ["name"] = "default:water_source"}, {["x"] = 4, ["meta"] = {["fields"] = {}, ["inventory"] = {}}, ["y"] = 1, ["param1"] = 136, ["z"] = 5, ["name"] = "default:water_source"}, {["x"] = 4, ["meta"] = {["fields"] = {}, ["inventory"] = {}}, ["y"] = 1, ["param1"] = 120, ["z"] = 6, ["name"] = "default:water_source"}, {["x"] = 4, ["meta"] = {["fields"] = {}, ["inventory"] = {}}, ["y"] = 1, ["param1"] = 105, ["z"] = 7, ["name"] = "default:water_source"}, {["x"] = 4, ["meta"] = {["fields"] = {}, ["inventory"] = {}}, ["y"] = 2, ["param1"] = 204, ["z"] = 0, ["name"] = "default:water_source"}, {["x"] = 4, ["meta"] = {["fields"] = {}, ["inventory"] = {}}, ["y"] = 2, ["param1"] = 187, ["z"] = 1, ["name"] = "default:water_source"}, {["x"] = 4, ["meta"] = {["fields"] = {}, ["inventory"] = {}}, ["y"] = 2, ["param1"] = 170, ["z"] = 2, ["name"] = "default:water_source"}, {["x"] = 4, ["meta"] = {["fields"] = {}, ["inventory"] = {}}, ["y"] = 2, ["param1"] = 153, ["z"] = 3, ["name"] = "default:water_source"}, {["x"] = 4, ["meta"] = {["fields"] = {}, ["inventory"] = {}}, ["y"] = 2, ["param1"] = 136, ["z"] = 4, ["name"] = "default:water_source"}, {["x"] = 4, ["meta"] = {["fields"] = {}, ["inventory"] = {}}, ["y"] = 2, ["param1"] = 120, ["z"] = 5, ["name"] = "default:water_source"}, {["x"] = 4, ["meta"] = {["fields"] = {}, ["inventory"] = {}}, ["y"] = 2, ["param1"] = 105, ["z"] = 6, ["name"] = "default:water_source"}, {["x"] = 4, ["meta"] = {["fields"] = {}, ["inventory"] = {}}, ["y"] = 2, ["param1"] = 90, ["z"] = 7, ["name"] = "default:water_source"}, {["x"] = 4, ["meta"] = {["fields"] = {}, ["inventory"] = {}}, ["y"] = 3, ["param1"] = 187, ["z"] = 0, ["name"] = "default:water_source"}, {["x"] = 4, ["meta"] = {["fields"] = {}, ["inventory"] = {}}, ["y"] = 3, ["param1"] = 170, ["z"] = 1, ["name"] = "default:water_source"}, {["x"] = 4, ["meta"] = {["fields"] = {}, ["inventory"] = {}}, ["y"] = 3, ["param1"] = 153, ["z"] = 2, ["name"] = "default:water_source"}, {["x"] = 4, ["meta"] = {["fields"] = {}, ["inventory"] = {}}, ["y"] = 3, ["param1"] = 136, ["z"] = 3, ["name"] = "default:water_source"}, {["x"] = 4, ["meta"] = {["fields"] = {}, ["inventory"] = {}}, ["y"] = 3, ["param1"] = 120, ["z"] = 4, ["name"] = "default:water_source"}, {["x"] = 4, ["meta"] = {["fields"] = {}, ["inventory"] = {}}, ["y"] = 3, ["param1"] = 105, ["z"] = 5, ["name"] = "default:water_source"}, {["x"] = 4, ["meta"] = {["fields"] = {}, ["inventory"] = {}}, ["y"] = 3, ["param1"] = 90, ["z"] = 6, ["name"] = "default:water_source"}, {["x"] = 4, ["meta"] = {["fields"] = {}, ["inventory"] = {}}, ["y"] = 3, ["param1"] = 75, ["z"] = 7, ["name"] = "default:water_source"}, {["x"] = 4, ["meta"] = {["fields"] = {}, ["inventory"] = {}}, ["y"] = 4, ["param1"] = 170, ["z"] = 0, ["name"] = "default:water_source"}, {["x"] = 4, ["meta"] = {["fields"] = {}, ["inventory"] = {}}, ["y"] = 4, ["param1"] = 153, ["z"] = 1, ["name"] = "default:water_source"}, {["x"] = 4, ["meta"] = {["fields"] = {}, ["inventory"] = {}}, ["y"] = 4, ["param1"] = 136, ["z"] = 2, ["name"] = "default:water_source"}, {["x"] = 4, ["meta"] = {["fields"] = {}, ["inventory"] = {}}, ["y"] = 4, ["param1"] = 120, ["z"] = 3, ["name"] = "default:water_source"}, {["x"] = 4, ["meta"] = {["fields"] = {}, ["inventory"] = {}}, ["y"] = 4, ["param1"] = 105, ["z"] = 4, ["name"] = "default:water_source"}, {["x"] = 4, ["meta"] = {["fields"] = {}, ["inventory"] = {}}, ["y"] = 4, ["param1"] = 90, ["z"] = 5, ["name"] = "default:water_source"}, {["x"] = 4, ["meta"] = {["fields"] = {}, ["inventory"] = {}}, ["y"] = 4, ["param1"] = 75, ["z"] = 6, ["name"] = "default:water_source"}, {["x"] = 4, ["meta"] = {["fields"] = {}, ["inventory"] = {}}, ["y"] = 4, ["param1"] = 60, ["z"] = 7, ["name"] = "default:water_source"}, {["x"] = 4, ["meta"] = {["fields"] = {}, ["inventory"] = {}}, ["y"] = 5, ["param1"] = 153, ["z"] = 0, ["name"] = "default:water_source"}, {["x"] = 4, ["meta"] = {["fields"] = {}, ["inventory"] = {}}, ["y"] = 5, ["param1"] = 137, ["z"] = 1, ["name"] = "default:water_source"}, {["x"] = 4, ["meta"] = {["fields"] = {}, ["inventory"] = {}}, ["y"] = 5, ["param1"] = 121, ["z"] = 2, ["name"] = "default:water_source"}, {["x"] = 4, ["meta"] = {["fields"] = {}, ["inventory"] = {}}, ["y"] = 5, ["param1"] = 105, ["z"] = 3, ["name"] = "default:water_source"}, {["x"] = 4, ["meta"] = {["fields"] = {}, ["inventory"] = {}}, ["y"] = 5, ["param1"] = 90, ["z"] = 4, ["name"] = "default:water_source"}, {["x"] = 4, ["meta"] = {["fields"] = {}, ["inventory"] = {}}, ["y"] = 5, ["param1"] = 75, ["z"] = 5, ["name"] = "default:water_source"}, {["x"] = 4, ["meta"] = {["fields"] = {}, ["inventory"] = {}}, ["y"] = 5, ["param1"] = 60, ["z"] = 6, ["name"] = "default:water_source"}, {["x"] = 4, ["meta"] = {["fields"] = {}, ["inventory"] = {}}, ["y"] = 5, ["param1"] = 45, ["z"] = 7, ["name"] = "default:water_source"}, {["x"] = 4, ["meta"] = {["fields"] = {}, ["inventory"] = {}}, ["param2"] = 22, ["y"] = 27, ["param1"] = 157, ["z"] = 0, ["name"] = "rainbow:slab_stonebrick_black_1"}, {["x"] = 4, ["meta"] = {["fields"] = {}, ["inventory"] = {}}, ["param2"] = 23, ["y"] = 27, ["param1"] = 174, ["z"] = 1, ["name"] = "rainbow:slab_stonebrick_red_1"}, {["x"] = 4, ["meta"] = {["fields"] = {}, ["inventory"] = {}}, ["param2"] = 20, ["y"] = 27, ["param1"] = 157, ["z"] = 2, ["name"] = "rainbow:slab_stonebrick_orange_1"}, {["x"] = 4, ["meta"] = {["fields"] = {}, ["inventory"] = {}}, ["param2"] = 20, ["y"] = 27, ["param1"] = 174, ["z"] = 3, ["name"] = "rainbow:slab_stonebrick_yellow_1"}, {["x"] = 4, ["meta"] = {["fields"] = {}, ["inventory"] = {}}, ["param2"] = 22, ["y"] = 27, ["param1"] = 157, ["z"] = 4, ["name"] = "rainbow:slab_stonebrick_lightgreen_1"}, {["x"] = 4, ["meta"] = {["fields"] = {}, ["inventory"] = {}}, ["param2"] = 20, ["y"] = 27, ["param1"] = 174, ["z"] = 5, ["name"] = "rainbow:slab_stonebrick_cyan_1"}, {["x"] = 4, ["meta"] = {["fields"] = {}, ["inventory"] = {}}, ["param2"] = 20, ["y"] = 27, ["param1"] = 157, ["z"] = 6, ["name"] = "rainbow:slab_stonebrick_blue_1"}, {["x"] = 4, ["meta"] = {["fields"] = {}, ["inventory"] = {}}, ["param2"] = 20, ["y"] = 27, ["param1"] = 174, ["z"] = 7, ["name"] = "rainbow:slab_stonebrick_violet_1"}, {["x"] = 4, ["meta"] = {["fields"] = {}, ["inventory"] = {}}, ["y"] = 31, ["z"] = 0, ["name"] = "rainbow:stonebrick_black"}, {["x"] = 4, ["meta"] = {["fields"] = {}, ["inventory"] = {}}, ["y"] = 31, ["param1"] = 239, ["z"] = 1, ["name"] = "default:meselamp"}, {["x"] = 4, ["meta"] = {["fields"] = {}, ["inventory"] = {}}, ["y"] = 31, ["z"] = 2, ["name"] = "rainbow:stonebrick_orange"}, {["x"] = 4, ["meta"] = {["fields"] = {}, ["inventory"] = {}}, ["y"] = 31, ["param1"] = 239, ["z"] = 3, ["name"] = "default:meselamp"}, {["x"] = 4, ["meta"] = {["fields"] = {}, ["inventory"] = {}}, ["y"] = 31, ["z"] = 4, ["name"] = "rainbow:stonebrick_lightgreen"}, {["x"] = 4, ["meta"] = {["fields"] = {}, ["inventory"] = {}}, ["y"] = 31, ["param1"] = 239, ["z"] = 5, ["name"] = "default:meselamp"}, {["x"] = 4, ["meta"] = {["fields"] = {}, ["inventory"] = {}}, ["y"] = 31, ["z"] = 6, ["name"] = "rainbow:stonebrick_blue"}, {["x"] = 4, ["meta"] = {["fields"] = {}, ["inventory"] = {}}, ["y"] = 31, ["param1"] = 239, ["z"] = 7, ["name"] = "default:meselamp"}, {["x"] = 5, ["meta"] = {["fields"] = {}, ["inventory"] = {}}, ["y"] = 0, ["z"] = 0, ["name"] = "rainbow:stonebrick_black"}, {["x"] = 5, ["meta"] = {["fields"] = {}, ["inventory"] = {}}, ["y"] = 0, ["z"] = 1, ["name"] = "rainbow:stonebrick_red"}, {["x"] = 5, ["meta"] = {["fields"] = {}, ["inventory"] = {}}, ["y"] = 0, ["z"] = 2, ["name"] = "rainbow:stonebrick_orange"}, {["x"] = 5, ["meta"] = {["fields"] = {}, ["inventory"] = {}}, ["y"] = 0, ["z"] = 3, ["name"] = "rainbow:stonebrick_yellow"}, {["x"] = 5, ["meta"] = {["fields"] = {}, ["inventory"] = {}}, ["y"] = 0, ["z"] = 4, ["name"] = "rainbow:stonebrick_lightgreen"}, {["x"] = 5, ["meta"] = {["fields"] = {}, ["inventory"] = {}}, ["y"] = 0, ["z"] = 5, ["name"] = "rainbow:stonebrick_cyan"}, {["x"] = 5, ["meta"] = {["fields"] = {}, ["inventory"] = {}}, ["y"] = 0, ["z"] = 6, ["name"] = "rainbow:stonebrick_blue"}, {["x"] = 5, ["meta"] = {["fields"] = {}, ["inventory"] = {}}, ["y"] = 0, ["z"] = 7, ["name"] = "rainbow:stonebrick_violet"}, {["x"] = 5, ["meta"] = {["fields"] = {}, ["inventory"] = {}}, ["y"] = 1, ["param1"] = 204, ["z"] = 0, ["name"] = "default:water_source"}, {["x"] = 5, ["meta"] = {["fields"] = {}, ["inventory"] = {}}, ["y"] = 1, ["param1"] = 187, ["z"] = 1, ["name"] = "default:water_source"}, {["x"] = 5, ["meta"] = {["fields"] = {}, ["inventory"] = {}}, ["y"] = 1, ["param1"] = 170, ["z"] = 2, ["name"] = "default:water_source"}, {["x"] = 5, ["meta"] = {["fields"] = {}, ["inventory"] = {}}, ["y"] = 1, ["param1"] = 153, ["z"] = 3, ["name"] = "default:water_source"}, {["x"] = 5, ["meta"] = {["fields"] = {}, ["inventory"] = {}}, ["y"] = 1, ["param1"] = 136, ["z"] = 4, ["name"] = "default:water_source"}, {["x"] = 5, ["meta"] = {["fields"] = {}, ["inventory"] = {}}, ["y"] = 1, ["param1"] = 119, ["z"] = 5, ["name"] = "default:water_source"}, {["x"] = 5, ["meta"] = {["fields"] = {}, ["inventory"] = {}}, ["y"] = 1, ["param1"] = 104, ["z"] = 6, ["name"] = "default:water_source"}, {["x"] = 5, ["meta"] = {["fields"] = {}, ["inventory"] = {}}, ["y"] = 1, ["param1"] = 89, ["z"] = 7, ["name"] = "default:water_source"}, {["x"] = 5, ["meta"] = {["fields"] = {}, ["inventory"] = {}}, ["y"] = 2, ["param1"] = 187, ["z"] = 0, ["name"] = "default:water_source"}, {["x"] = 5, ["meta"] = {["fields"] = {}, ["inventory"] = {}}, ["y"] = 2, ["param1"] = 170, ["z"] = 1, ["name"] = "default:water_source"}, {["x"] = 5, ["meta"] = {["fields"] = {}, ["inventory"] = {}}, ["y"] = 2, ["param1"] = 153, ["z"] = 2, ["name"] = "default:water_source"}, {["x"] = 5, ["meta"] = {["fields"] = {}, ["inventory"] = {}}, ["y"] = 2, ["param1"] = 136, ["z"] = 3, ["name"] = "default:water_source"}, {["x"] = 5, ["meta"] = {["fields"] = {}, ["inventory"] = {}}, ["y"] = 2, ["param1"] = 119, ["z"] = 4, ["name"] = "default:water_source"}, {["x"] = 5, ["meta"] = {["fields"] = {}, ["inventory"] = {}}, ["y"] = 2, ["param1"] = 104, ["z"] = 5, ["name"] = "default:water_source"}, {["x"] = 5, ["meta"] = {["fields"] = {}, ["inventory"] = {}}, ["y"] = 2, ["param1"] = 89, ["z"] = 6, ["name"] = "default:water_source"}, {["x"] = 5, ["meta"] = {["fields"] = {}, ["inventory"] = {}}, ["y"] = 2, ["param1"] = 74, ["z"] = 7, ["name"] = "default:water_source"}, {["x"] = 5, ["meta"] = {["fields"] = {}, ["inventory"] = {}}, ["y"] = 3, ["param1"] = 170, ["z"] = 0, ["name"] = "default:water_source"}, {["x"] = 5, ["meta"] = {["fields"] = {}, ["inventory"] = {}}, ["y"] = 3, ["param1"] = 153, ["z"] = 1, ["name"] = "default:water_source"}, {["x"] = 5, ["meta"] = {["fields"] = {}, ["inventory"] = {}}, ["y"] = 3, ["param1"] = 136, ["z"] = 2, ["name"] = "default:water_source"}, {["x"] = 5, ["meta"] = {["fields"] = {}, ["inventory"] = {}}, ["y"] = 3, ["param1"] = 120, ["z"] = 3, ["name"] = "default:water_source"}, {["x"] = 5, ["meta"] = {["fields"] = {}, ["inventory"] = {}}, ["y"] = 3, ["param1"] = 104, ["z"] = 4, ["name"] = "default:water_source"}, {["x"] = 5, ["meta"] = {["fields"] = {}, ["inventory"] = {}}, ["y"] = 3, ["param1"] = 89, ["z"] = 5, ["name"] = "default:water_source"}, {["x"] = 5, ["meta"] = {["fields"] = {}, ["inventory"] = {}}, ["y"] = 3, ["param1"] = 74, ["z"] = 6, ["name"] = "default:water_source"}, {["x"] = 5, ["meta"] = {["fields"] = {}, ["inventory"] = {}}, ["y"] = 3, ["param1"] = 59, ["z"] = 7, ["name"] = "default:water_source"}, {["x"] = 5, ["meta"] = {["fields"] = {}, ["inventory"] = {}}, ["y"] = 4, ["param1"] = 153, ["z"] = 0, ["name"] = "default:water_source"}, {["x"] = 5, ["meta"] = {["fields"] = {}, ["inventory"] = {}}, ["y"] = 4, ["param1"] = 136, ["z"] = 1, ["name"] = "default:water_source"}, {["x"] = 5, ["meta"] = {["fields"] = {}, ["inventory"] = {}}, ["y"] = 4, ["param1"] = 121, ["z"] = 2, ["name"] = "default:water_source"}, {["x"] = 5, ["meta"] = {["fields"] = {}, ["inventory"] = {}}, ["y"] = 4, ["param1"] = 105, ["z"] = 3, ["name"] = "default:water_source"}, {["x"] = 5, ["meta"] = {["fields"] = {}, ["inventory"] = {}}, ["y"] = 4, ["param1"] = 89, ["z"] = 4, ["name"] = "default:water_source"}, {["x"] = 5, ["meta"] = {["fields"] = {}, ["inventory"] = {}}, ["y"] = 4, ["param1"] = 74, ["z"] = 5, ["name"] = "default:water_source"}, {["x"] = 5, ["meta"] = {["fields"] = {}, ["inventory"] = {}}, ["y"] = 4, ["param1"] = 59, ["z"] = 6, ["name"] = "default:water_source"}, {["x"] = 5, ["meta"] = {["fields"] = {}, ["inventory"] = {}}, ["y"] = 4, ["param1"] = 44, ["z"] = 7, ["name"] = "default:water_source"}, {["x"] = 5, ["meta"] = {["fields"] = {}, ["inventory"] = {}}, ["y"] = 5, ["param1"] = 136, ["z"] = 0, ["name"] = "default:water_source"}, {["x"] = 5, ["meta"] = {["fields"] = {}, ["inventory"] = {}}, ["y"] = 5, ["param1"] = 121, ["z"] = 1, ["name"] = "default:water_source"}, {["x"] = 5, ["meta"] = {["fields"] = {}, ["inventory"] = {}}, ["y"] = 5, ["param1"] = 106, ["z"] = 2, ["name"] = "default:water_source"}, {["x"] = 5, ["meta"] = {["fields"] = {}, ["inventory"] = {}}, ["y"] = 5, ["param1"] = 90, ["z"] = 3, ["name"] = "default:water_source"}, {["x"] = 5, ["meta"] = {["fields"] = {}, ["inventory"] = {}}, ["y"] = 5, ["param1"] = 74, ["z"] = 4, ["name"] = "default:water_source"}, {["x"] = 5, ["meta"] = {["fields"] = {}, ["inventory"] = {}}, ["y"] = 5, ["param1"] = 59, ["z"] = 5, ["name"] = "default:water_source"}, {["x"] = 5, ["meta"] = {["fields"] = {}, ["inventory"] = {}}, ["y"] = 5, ["param1"] = 44, ["z"] = 6, ["name"] = "default:water_source"}, {["x"] = 5, ["meta"] = {["fields"] = {}, ["inventory"] = {}}, ["param2"] = 240, ["y"] = 5, ["param1"] = 29, ["z"] = 7, ["name"] = "default:water_source"}, {["x"] = 5, ["meta"] = {["fields"] = {}, ["inventory"] = {}}, ["param2"] = 23, ["y"] = 28, ["param1"] = 157, ["z"] = 0, ["name"] = "rainbow:slope_stonebrick_black"}, {["x"] = 5, ["meta"] = {["fields"] = {}, ["inventory"] = {}}, ["param2"] = 12, ["y"] = 28, ["param1"] = 174, ["z"] = 1, ["name"] = "rainbow:slab_stonebrick_black_1"}, {["x"] = 5, ["meta"] = {["fields"] = {}, ["inventory"] = {}}, ["param2"] = 12, ["y"] = 28, ["param1"] = 157, ["z"] = 2, ["name"] = "rainbow:slab_stonebrick_black_1"}, {["x"] = 5, ["meta"] = {["fields"] = {}, ["inventory"] = {}}, ["param2"] = 12, ["y"] = 28, ["param1"] = 174, ["z"] = 3, ["name"] = "rainbow:slab_stonebrick_black_1"}, {["x"] = 5, ["meta"] = {["fields"] = {}, ["inventory"] = {}}, ["param2"] = 12, ["y"] = 28, ["param1"] = 157, ["z"] = 4, ["name"] = "rainbow:slab_stonebrick_black_1"}, {["x"] = 5, ["meta"] = {["fields"] = {}, ["inventory"] = {}}, ["param2"] = 12, ["y"] = 28, ["param1"] = 174, ["z"] = 5, ["name"] = "rainbow:slab_stonebrick_black_1"}, {["x"] = 5, ["meta"] = {["fields"] = {}, ["inventory"] = {}}, ["param2"] = 12, ["y"] = 28, ["param1"] = 157, ["z"] = 6, ["name"] = "rainbow:slab_stonebrick_black_1"}, {["x"] = 5, ["meta"] = {["fields"] = {}, ["inventory"] = {}}, ["param2"] = 12, ["y"] = 28, ["param1"] = 174, ["z"] = 7, ["name"] = "rainbow:slab_stonebrick_black_1"}, {["x"] = 5, ["meta"] = {["fields"] = {}, ["inventory"] = {}}, ["y"] = 29, ["z"] = 0, ["name"] = "rainbow:stonebrick_black"}, {["x"] = 5, ["meta"] = {["fields"] = {}, ["inventory"] = {}}, ["y"] = 30, ["z"] = 0, ["name"] = "rainbow:stonebrick_black"}, {["x"] = 5, ["meta"] = {["fields"] = {}, ["inventory"] = {}}, ["y"] = 31, ["z"] = 0, ["name"] = "rainbow:stonebrick_black"}, {["x"] = 5, ["meta"] = {["fields"] = {}, ["inventory"] = {}}, ["y"] = 31, ["z"] = 1, ["name"] = "rainbow:stonebrick_red"}, {["x"] = 5, ["meta"] = {["fields"] = {}, ["inventory"] = {}}, ["y"] = 31, ["z"] = 2, ["name"] = "rainbow:stonebrick_orange"}, {["x"] = 5, ["meta"] = {["fields"] = {}, ["inventory"] = {}}, ["y"] = 31, ["z"] = 3, ["name"] = "rainbow:stonebrick_yellow"}, {["x"] = 5, ["meta"] = {["fields"] = {}, ["inventory"] = {}}, ["y"] = 31, ["z"] = 4, ["name"] = "rainbow:stonebrick_lightgreen"}, {["x"] = 5, ["meta"] = {["fields"] = {}, ["inventory"] = {}}, ["y"] = 31, ["z"] = 5, ["name"] = "rainbow:stonebrick_cyan"}, {["x"] = 5, ["meta"] = {["fields"] = {}, ["inventory"] = {}}, ["y"] = 31, ["z"] = 6, ["name"] = "rainbow:stonebrick_blue"}, {["x"] = 5, ["meta"] = {["fields"] = {}, ["inventory"] = {}}, ["y"] = 31, ["z"] = 7, ["name"] = "rainbow:stonebrick_violet"}, {["x"] = 6, ["meta"] = {["fields"] = {}, ["inventory"] = {}}, ["y"] = 0, ["z"] = 0, ["name"] = "rainbow:stonebrick_black"}, {["x"] = 6, ["meta"] = {["fields"] = {}, ["inventory"] = {}}, ["y"] = 0, ["z"] = 1, ["name"] = "rainbow:stonebrick_red"}, {["x"] = 6, ["meta"] = {["fields"] = {}, ["inventory"] = {}}, ["y"] = 0, ["z"] = 2, ["name"] = "rainbow:stonebrick_orange"}, {["x"] = 6, ["meta"] = {["fields"] = {}, ["inventory"] = {}}, ["y"] = 0, ["z"] = 3, ["name"] = "rainbow:stonebrick_yellow"}, {["x"] = 6, ["meta"] = {["fields"] = {}, ["inventory"] = {}}, ["y"] = 0, ["z"] = 4, ["name"] = "rainbow:stonebrick_lightgreen"}, {["x"] = 6, ["meta"] = {["fields"] = {}, ["inventory"] = {}}, ["y"] = 0, ["z"] = 5, ["name"] = "rainbow:stonebrick_cyan"}, {["x"] = 6, ["meta"] = {["fields"] = {}, ["inventory"] = {}}, ["y"] = 0, ["z"] = 6, ["name"] = "rainbow:stonebrick_blue"}, {["x"] = 6, ["meta"] = {["fields"] = {}, ["inventory"] = {}}, ["y"] = 0, ["z"] = 7, ["name"] = "rainbow:stonebrick_violet"}, {["x"] = 6, ["meta"] = {["fields"] = {}, ["inventory"] = {}}, ["y"] = 1, ["param1"] = 187, ["z"] = 0, ["name"] = "default:water_source"}, {["x"] = 6, ["meta"] = {["fields"] = {}, ["inventory"] = {}}, ["y"] = 1, ["param1"] = 170, ["z"] = 1, ["name"] = "default:water_source"}, {["x"] = 6, ["meta"] = {["fields"] = {}, ["inventory"] = {}}, ["y"] = 1, ["param1"] = 153, ["z"] = 2, ["name"] = "default:water_source"}, {["x"] = 6, ["meta"] = {["fields"] = {}, ["inventory"] = {}}, ["y"] = 1, ["param1"] = 136, ["z"] = 3, ["name"] = "default:water_source"}, {["x"] = 6, ["meta"] = {["fields"] = {}, ["inventory"] = {}}, ["y"] = 1, ["param1"] = 119, ["z"] = 4, ["name"] = "default:water_source"}, {["x"] = 6, ["meta"] = {["fields"] = {}, ["inventory"] = {}}, ["y"] = 1, ["param1"] = 103, ["z"] = 5, ["name"] = "default:water_source"}, {["x"] = 6, ["meta"] = {["fields"] = {}, ["inventory"] = {}}, ["y"] = 1, ["param1"] = 88, ["z"] = 6, ["name"] = "default:water_source"}, {["x"] = 6, ["meta"] = {["fields"] = {}, ["inventory"] = {}}, ["y"] = 1, ["param1"] = 73, ["z"] = 7, ["name"] = "default:water_source"}, {["x"] = 6, ["meta"] = {["fields"] = {}, ["inventory"] = {}}, ["y"] = 2, ["param1"] = 170, ["z"] = 0, ["name"] = "default:water_source"}, {["x"] = 6, ["meta"] = {["fields"] = {}, ["inventory"] = {}}, ["y"] = 2, ["param1"] = 153, ["z"] = 1, ["name"] = "default:water_source"}, {["x"] = 6, ["meta"] = {["fields"] = {}, ["inventory"] = {}}, ["y"] = 2, ["param1"] = 136, ["z"] = 2, ["name"] = "default:water_source"}, {["x"] = 6, ["meta"] = {["fields"] = {}, ["inventory"] = {}}, ["y"] = 2, ["param1"] = 120, ["z"] = 3, ["name"] = "default:water_source"}, {["x"] = 6, ["meta"] = {["fields"] = {}, ["inventory"] = {}}, ["y"] = 2, ["param1"] = 104, ["z"] = 4, ["name"] = "default:water_source"}, {["x"] = 6, ["meta"] = {["fields"] = {}, ["inventory"] = {}}, ["y"] = 2, ["param1"] = 88, ["z"] = 5, ["name"] = "default:water_source"}, {["x"] = 6, ["meta"] = {["fields"] = {}, ["inventory"] = {}}, ["y"] = 2, ["param1"] = 73, ["z"] = 6, ["name"] = "default:water_source"}, {["x"] = 6, ["meta"] = {["fields"] = {}, ["inventory"] = {}}, ["y"] = 2, ["param1"] = 58, ["z"] = 7, ["name"] = "default:water_source"}, {["x"] = 6, ["meta"] = {["fields"] = {}, ["inventory"] = {}}, ["y"] = 3, ["param1"] = 153, ["z"] = 0, ["name"] = "default:water_source"}, {["x"] = 6, ["meta"] = {["fields"] = {}, ["inventory"] = {}}, ["y"] = 3, ["param1"] = 136, ["z"] = 1, ["name"] = "default:water_source"}, {["x"] = 6, ["meta"] = {["fields"] = {}, ["inventory"] = {}}, ["y"] = 3, ["param1"] = 121, ["z"] = 2, ["name"] = "default:water_source"}, {["x"] = 6, ["meta"] = {["fields"] = {}, ["inventory"] = {}}, ["y"] = 3, ["param1"] = 105, ["z"] = 3, ["name"] = "default:water_source"}, {["x"] = 6, ["meta"] = {["fields"] = {}, ["inventory"] = {}}, ["y"] = 3, ["param1"] = 89, ["z"] = 4, ["name"] = "default:water_source"}, {["x"] = 6, ["meta"] = {["fields"] = {}, ["inventory"] = {}}, ["y"] = 3, ["param1"] = 73, ["z"] = 5, ["name"] = "default:water_source"}, {["x"] = 6, ["meta"] = {["fields"] = {}, ["inventory"] = {}}, ["y"] = 3, ["param1"] = 58, ["z"] = 6, ["name"] = "default:water_source"}, {["x"] = 6, ["meta"] = {["fields"] = {}, ["inventory"] = {}}, ["y"] = 3, ["param1"] = 43, ["z"] = 7, ["name"] = "default:water_source"}, {["x"] = 6, ["meta"] = {["fields"] = {}, ["inventory"] = {}}, ["y"] = 4, ["param1"] = 136, ["z"] = 0, ["name"] = "default:water_source"}, {["x"] = 6, ["meta"] = {["fields"] = {}, ["inventory"] = {}}, ["y"] = 4, ["param1"] = 121, ["z"] = 1, ["name"] = "default:water_source"}, {["x"] = 6, ["meta"] = {["fields"] = {}, ["inventory"] = {}}, ["y"] = 4, ["param1"] = 106, ["z"] = 2, ["name"] = "default:water_source"}, {["x"] = 6, ["meta"] = {["fields"] = {}, ["inventory"] = {}}, ["y"] = 4, ["param1"] = 90, ["z"] = 3, ["name"] = "default:water_source"}, {["x"] = 6, ["meta"] = {["fields"] = {}, ["inventory"] = {}}, ["y"] = 4, ["param1"] = 74, ["z"] = 4, ["name"] = "default:water_source"}, {["x"] = 6, ["meta"] = {["fields"] = {}, ["inventory"] = {}}, ["y"] = 4, ["param1"] = 58, ["z"] = 5, ["name"] = "default:water_source"}, {["x"] = 6, ["meta"] = {["fields"] = {}, ["inventory"] = {}}, ["y"] = 4, ["param1"] = 43, ["z"] = 6, ["name"] = "default:water_source"}, {["x"] = 6, ["meta"] = {["fields"] = {}, ["inventory"] = {}}, ["y"] = 4, ["param1"] = 28, ["z"] = 7, ["name"] = "default:water_source"}, {["x"] = 6, ["meta"] = {["fields"] = {}, ["inventory"] = {}}, ["y"] = 5, ["param1"] = 121, ["z"] = 0, ["name"] = "default:water_source"}, {["x"] = 6, ["meta"] = {["fields"] = {}, ["inventory"] = {}}, ["y"] = 5, ["param1"] = 106, ["z"] = 1, ["name"] = "default:water_source"}, {["x"] = 6, ["meta"] = {["fields"] = {}, ["inventory"] = {}}, ["y"] = 5, ["param1"] = 91, ["z"] = 2, ["name"] = "default:water_source"}, {["x"] = 6, ["meta"] = {["fields"] = {}, ["inventory"] = {}}, ["y"] = 5, ["param1"] = 75, ["z"] = 3, ["name"] = "default:water_source"}, {["x"] = 6, ["meta"] = {["fields"] = {}, ["inventory"] = {}}, ["y"] = 5, ["param1"] = 59, ["z"] = 4, ["name"] = "default:water_source"}, {["x"] = 6, ["meta"] = {["fields"] = {}, ["inventory"] = {}}, ["y"] = 5, ["param1"] = 43, ["z"] = 5, ["name"] = "default:water_source"}, {["x"] = 6, ["meta"] = {["fields"] = {}, ["inventory"] = {}}, ["y"] = 5, ["param1"] = 28, ["z"] = 6, ["name"] = "default:water_source"}, {["x"] = 6, ["meta"] = {["fields"] = {}, ["inventory"] = {}}, ["y"] = 5, ["param1"] = 13, ["z"] = 7, ["name"] = "default:water_source"}, {["x"] = 6, ["meta"] = {["fields"] = {}, ["inventory"] = {}}, ["param2"] = 23, ["y"] = 27, ["param1"] = 123, ["z"] = 0, ["name"] = "rainbow:slope_stonebrick_black"}, {["x"] = 6, ["meta"] = {["fields"] = {}, ["inventory"] = {}}, ["param2"] = 3, ["y"] = 28, ["param1"] = 140, ["z"] = 0, ["name"] = "rainbow:slope_stonebrick_black"}, {["x"] = 6, ["meta"] = {["fields"] = {}, ["inventory"] = {}}, ["y"] = 31, ["z"] = 0, ["name"] = "rainbow:stonebrick_black"}, {["x"] = 6, ["meta"] = {["fields"] = {}, ["inventory"] = {}}, ["y"] = 31, ["z"] = 1, ["name"] = "rainbow:stonebrick_red"}, {["x"] = 6, ["meta"] = {["fields"] = {}, ["inventory"] = {}}, ["y"] = 31, ["z"] = 2, ["name"] = "rainbow:stonebrick_orange"}, {["x"] = 6, ["meta"] = {["fields"] = {}, ["inventory"] = {}}, ["y"] = 31, ["z"] = 3, ["name"] = "rainbow:stonebrick_yellow"}, {["x"] = 6, ["meta"] = {["fields"] = {}, ["inventory"] = {}}, ["y"] = 31, ["z"] = 4, ["name"] = "rainbow:stonebrick_lightgreen"}, {["x"] = 6, ["meta"] = {["fields"] = {}, ["inventory"] = {}}, ["y"] = 31, ["z"] = 5, ["name"] = "rainbow:stonebrick_cyan"}, {["x"] = 6, ["meta"] = {["fields"] = {}, ["inventory"] = {}}, ["y"] = 31, ["z"] = 6, ["name"] = "rainbow:stonebrick_blue"}, {["x"] = 6, ["meta"] = {["fields"] = {}, ["inventory"] = {}}, ["y"] = 31, ["z"] = 7, ["name"] = "rainbow:stonebrick_violet"}, {["x"] = 7, ["meta"] = {["fields"] = {}, ["inventory"] = {}}, ["y"] = 0, ["z"] = 0, ["name"] = "rainbow:stonebrick_black"}, {["x"] = 7, ["meta"] = {["fields"] = {}, ["inventory"] = {}}, ["y"] = 0, ["z"] = 1, ["name"] = "rainbow:stonebrick_red"}, {["x"] = 7, ["meta"] = {["fields"] = {}, ["inventory"] = {}}, ["y"] = 0, ["z"] = 2, ["name"] = "rainbow:stonebrick_orange"}, {["x"] = 7, ["meta"] = {["fields"] = {}, ["inventory"] = {}}, ["y"] = 0, ["z"] = 3, ["name"] = "rainbow:stonebrick_yellow"}, {["x"] = 7, ["meta"] = {["fields"] = {}, ["inventory"] = {}}, ["y"] = 0, ["z"] = 4, ["name"] = "rainbow:stonebrick_lightgreen"}, {["x"] = 7, ["meta"] = {["fields"] = {}, ["inventory"] = {}}, ["y"] = 0, ["z"] = 5, ["name"] = "rainbow:stonebrick_cyan"}, {["x"] = 7, ["meta"] = {["fields"] = {}, ["inventory"] = {}}, ["y"] = 0, ["z"] = 6, ["name"] = "rainbow:stonebrick_blue"}, {["x"] = 7, ["meta"] = {["fields"] = {}, ["inventory"] = {}}, ["y"] = 0, ["z"] = 7, ["name"] = "rainbow:stonebrick_violet"}, {["x"] = 7, ["meta"] = {["fields"] = {}, ["inventory"] = {}}, ["y"] = 1, ["param1"] = 170, ["z"] = 0, ["name"] = "default:water_source"}, {["x"] = 7, ["meta"] = {["fields"] = {}, ["inventory"] = {}}, ["y"] = 1, ["param1"] = 153, ["z"] = 1, ["name"] = "default:water_source"}, {["x"] = 7, ["meta"] = {["fields"] = {}, ["inventory"] = {}}, ["y"] = 1, ["param1"] = 136, ["z"] = 2, ["name"] = "default:water_source"}, {["x"] = 7, ["meta"] = {["fields"] = {}, ["inventory"] = {}}, ["y"] = 1, ["param1"] = 120, ["z"] = 3, ["name"] = "default:water_source"}, {["x"] = 7, ["meta"] = {["fields"] = {}, ["inventory"] = {}}, ["y"] = 1, ["param1"] = 104, ["z"] = 4, ["name"] = "default:water_source"}, {["x"] = 7, ["meta"] = {["fields"] = {}, ["inventory"] = {}}, ["y"] = 1, ["param1"] = 88, ["z"] = 5, ["name"] = "default:water_source"}, {["x"] = 7, ["meta"] = {["fields"] = {}, ["inventory"] = {}}, ["y"] = 1, ["param1"] = 72, ["z"] = 6, ["name"] = "default:water_source"}, {["x"] = 7, ["meta"] = {["fields"] = {}, ["inventory"] = {}}, ["y"] = 1, ["param1"] = 57, ["z"] = 7, ["name"] = "default:water_source"}, {["x"] = 7, ["meta"] = {["fields"] = {}, ["inventory"] = {}}, ["y"] = 2, ["param1"] = 153, ["z"] = 0, ["name"] = "default:water_source"}, {["x"] = 7, ["meta"] = {["fields"] = {}, ["inventory"] = {}}, ["y"] = 2, ["param1"] = 136, ["z"] = 1, ["name"] = "default:water_source"}, {["x"] = 7, ["meta"] = {["fields"] = {}, ["inventory"] = {}}, ["y"] = 2, ["param1"] = 121, ["z"] = 2, ["name"] = "default:water_source"}, {["x"] = 7, ["meta"] = {["fields"] = {}, ["inventory"] = {}}, ["y"] = 2, ["param1"] = 105, ["z"] = 3, ["name"] = "default:water_source"}, {["x"] = 7, ["meta"] = {["fields"] = {}, ["inventory"] = {}}, ["y"] = 2, ["param1"] = 89, ["z"] = 4, ["name"] = "default:water_source"}, {["x"] = 7, ["meta"] = {["fields"] = {}, ["inventory"] = {}}, ["y"] = 2, ["param1"] = 73, ["z"] = 5, ["name"] = "default:water_source"}, {["x"] = 7, ["meta"] = {["fields"] = {}, ["inventory"] = {}}, ["y"] = 2, ["param1"] = 57, ["z"] = 6, ["name"] = "default:water_source"}, {["x"] = 7, ["meta"] = {["fields"] = {}, ["inventory"] = {}}, ["y"] = 2, ["param1"] = 42, ["z"] = 7, ["name"] = "default:water_source"}, {["x"] = 7, ["meta"] = {["fields"] = {}, ["inventory"] = {}}, ["y"] = 3, ["param1"] = 136, ["z"] = 0, ["name"] = "default:water_source"}, {["x"] = 7, ["meta"] = {["fields"] = {}, ["inventory"] = {}}, ["y"] = 3, ["param1"] = 121, ["z"] = 1, ["name"] = "default:water_source"}, {["x"] = 7, ["meta"] = {["fields"] = {}, ["inventory"] = {}}, ["y"] = 3, ["param1"] = 106, ["z"] = 2, ["name"] = "default:water_source"}, {["x"] = 7, ["meta"] = {["fields"] = {}, ["inventory"] = {}}, ["y"] = 3, ["param1"] = 90, ["z"] = 3, ["name"] = "default:water_source"}, {["x"] = 7, ["meta"] = {["fields"] = {}, ["inventory"] = {}}, ["y"] = 3, ["param1"] = 74, ["z"] = 4, ["name"] = "default:water_source"}, {["x"] = 7, ["meta"] = {["fields"] = {}, ["inventory"] = {}}, ["y"] = 3, ["param1"] = 58, ["z"] = 5, ["name"] = "default:water_source"}, {["x"] = 7, ["meta"] = {["fields"] = {}, ["inventory"] = {}}, ["y"] = 3, ["param1"] = 42, ["z"] = 6, ["name"] = "default:water_source"}, {["x"] = 7, ["meta"] = {["fields"] = {}, ["inventory"] = {}}, ["y"] = 3, ["param1"] = 27, ["z"] = 7, ["name"] = "default:water_source"}, {["x"] = 7, ["meta"] = {["fields"] = {}, ["inventory"] = {}}, ["y"] = 4, ["param1"] = 121, ["z"] = 0, ["name"] = "default:water_source"}, {["x"] = 7, ["meta"] = {["fields"] = {}, ["inventory"] = {}}, ["y"] = 4, ["param1"] = 106, ["z"] = 1, ["name"] = "default:water_source"}, {["x"] = 7, ["meta"] = {["fields"] = {}, ["inventory"] = {}}, ["y"] = 4, ["param1"] = 91, ["z"] = 2, ["name"] = "default:water_source"}, {["x"] = 7, ["meta"] = {["fields"] = {}, ["inventory"] = {}}, ["y"] = 4, ["param1"] = 75, ["z"] = 3, ["name"] = "default:water_source"}, {["x"] = 7, ["meta"] = {["fields"] = {}, ["inventory"] = {}}, ["y"] = 4, ["param1"] = 59, ["z"] = 4, ["name"] = "default:water_source"}, {["x"] = 7, ["meta"] = {["fields"] = {}, ["inventory"] = {}}, ["y"] = 4, ["param1"] = 43, ["z"] = 5, ["name"] = "default:water_source"}, {["x"] = 7, ["meta"] = {["fields"] = {}, ["inventory"] = {}}, ["y"] = 4, ["param1"] = 27, ["z"] = 6, ["name"] = "default:water_source"}, {["x"] = 7, ["meta"] = {["fields"] = {}, ["inventory"] = {}}, ["y"] = 4, ["param1"] = 12, ["z"] = 7, ["name"] = "default:water_source"}, {["x"] = 7, ["meta"] = {["fields"] = {}, ["inventory"] = {}}, ["y"] = 5, ["param1"] = 106, ["z"] = 0, ["name"] = "default:water_source"}, {["x"] = 7, ["meta"] = {["fields"] = {}, ["inventory"] = {}}, ["y"] = 5, ["param1"] = 91, ["z"] = 1, ["name"] = "default:water_source"}, {["x"] = 7, ["meta"] = {["fields"] = {}, ["inventory"] = {}}, ["y"] = 5, ["param1"] = 76, ["z"] = 2, ["name"] = "default:water_source"}, {["x"] = 7, ["meta"] = {["fields"] = {}, ["inventory"] = {}}, ["y"] = 5, ["param1"] = 60, ["z"] = 3, ["name"] = "default:water_source"}, {["x"] = 7, ["meta"] = {["fields"] = {}, ["inventory"] = {}}, ["y"] = 5, ["param1"] = 44, ["z"] = 4, ["name"] = "default:water_source"}, {["x"] = 7, ["meta"] = {["fields"] = {}, ["inventory"] = {}}, ["y"] = 5, ["param1"] = 28, ["z"] = 5, ["name"] = "default:water_source"}, {["x"] = 7, ["meta"] = {["fields"] = {}, ["inventory"] = {}}, ["y"] = 5, ["param1"] = 12, ["z"] = 6, ["name"] = "default:water_source"}, {["x"] = 7, ["meta"] = {["fields"] = {}, ["inventory"] = {}}, ["y"] = 5, ["param1"] = 13, ["z"] = 7, ["name"] = "default:water_source"}, {["x"] = 7, ["meta"] = {["fields"] = {}, ["inventory"] = {}}, ["param2"] = 23, ["y"] = 26, ["param1"] = 92, ["z"] = 0, ["name"] = "rainbow:slope_stonebrick_black"}, {["x"] = 7, ["meta"] = {["fields"] = {}, ["inventory"] = {}}, ["param2"] = 3, ["y"] = 27, ["param1"] = 108, ["z"] = 0, ["name"] = "rainbow:slope_stonebrick_black"}, {["x"] = 7, ["meta"] = {["fields"] = {}, ["inventory"] = {}}, ["y"] = 31, ["z"] = 0, ["name"] = "rainbow:stonebrick_black"}, {["x"] = 7, ["meta"] = {["fields"] = {}, ["inventory"] = {}}, ["y"] = 31, ["z"] = 1, ["name"] = "rainbow:stonebrick_red"}, {["x"] = 7, ["meta"] = {["fields"] = {}, ["inventory"] = {}}, ["y"] = 31, ["z"] = 2, ["name"] = "rainbow:stonebrick_orange"}, {["x"] = 7, ["meta"] = {["fields"] = {}, ["inventory"] = {}}, ["y"] = 31, ["z"] = 3, ["name"] = "rainbow:stonebrick_yellow"}, {["x"] = 7, ["meta"] = {["fields"] = {}, ["inventory"] = {}}, ["y"] = 31, ["z"] = 4, ["name"] = "rainbow:stonebrick_lightgreen"}, {["x"] = 7, ["meta"] = {["fields"] = {}, ["inventory"] = {}}, ["y"] = 31, ["z"] = 5, ["name"] = "rainbow:stonebrick_cyan"}, {["x"] = 7, ["meta"] = {["fields"] = {}, ["inventory"] = {}}, ["y"] = 31, ["z"] = 6, ["name"] = "rainbow:stonebrick_blue"}, {["x"] = 7, ["meta"] = {["fields"] = {}, ["inventory"] = {}}, ["y"] = 31, ["z"] = 7, ["name"] = "rainbow:stonebrick_violet"}, {["x"] = 8, ["meta"] = {["fields"] = {}, ["inventory"] = {}}, ["y"] = 0, ["z"] = 0, ["name"] = "rainbow:stonebrick_yellow"}, {["x"] = 8, ["meta"] = {["fields"] = {}, ["inventory"] = {}}, ["y"] = 0, ["z"] = 1, ["name"] = "rainbow:stonebrick_red"}, {["x"] = 8, ["meta"] = {["fields"] = {}, ["inventory"] = {}}, ["y"] = 0, ["z"] = 2, ["name"] = "rainbow:stonebrick_orange"}, {["x"] = 8, ["meta"] = {["fields"] = {}, ["inventory"] = {}}, ["y"] = 0, ["z"] = 3, ["name"] = "rainbow:stonebrick_yellow"}, {["x"] = 8, ["meta"] = {["fields"] = {}, ["inventory"] = {}}, ["y"] = 0, ["z"] = 4, ["name"] = "rainbow:stonebrick_lightgreen"}, {["x"] = 8, ["meta"] = {["fields"] = {}, ["inventory"] = {}}, ["y"] = 0, ["z"] = 5, ["name"] = "rainbow:stonebrick_cyan"}, {["x"] = 8, ["meta"] = {["fields"] = {}, ["inventory"] = {}}, ["y"] = 0, ["z"] = 6, ["name"] = "rainbow:stonebrick_blue"}, {["x"] = 8, ["meta"] = {["fields"] = {}, ["inventory"] = {}}, ["y"] = 0, ["z"] = 7, ["name"] = "rainbow:stonebrick_violet"}, {["x"] = 8, ["meta"] = {["fields"] = {}, ["inventory"] = {}}, ["y"] = 1, ["z"] = 0, ["name"] = "rainbow:stonebrick_orange"}, {["x"] = 8, ["meta"] = {["fields"] = {}, ["inventory"] = {}}, ["y"] = 1, ["z"] = 1, ["name"] = "rainbow:stonebrick_red"}, {["x"] = 8, ["meta"] = {["fields"] = {}, ["inventory"] = {}}, ["y"] = 1, ["z"] = 2, ["name"] = "rainbow:stonebrick_orange"}, {["x"] = 8, ["meta"] = {["fields"] = {}, ["inventory"] = {}}, ["y"] = 1, ["z"] = 3, ["name"] = "rainbow:stonebrick_yellow"}, {["x"] = 8, ["meta"] = {["fields"] = {}, ["inventory"] = {}}, ["y"] = 1, ["z"] = 4, ["name"] = "rainbow:stonebrick_lightgreen"}, {["x"] = 8, ["meta"] = {["fields"] = {}, ["inventory"] = {}}, ["y"] = 1, ["z"] = 5, ["name"] = "rainbow:stonebrick_cyan"}, {["x"] = 8, ["meta"] = {["fields"] = {}, ["inventory"] = {}}, ["y"] = 1, ["z"] = 6, ["name"] = "rainbow:stonebrick_blue"}, {["x"] = 8, ["meta"] = {["fields"] = {}, ["inventory"] = {}}, ["y"] = 1, ["z"] = 7, ["name"] = "rainbow:stonebrick_violet"}, {["x"] = 8, ["meta"] = {["fields"] = {}, ["inventory"] = {}}, ["y"] = 2, ["z"] = 0, ["name"] = "rainbow:stonebrick_red"}, {["x"] = 8, ["meta"] = {["fields"] = {}, ["inventory"] = {}}, ["y"] = 2, ["z"] = 1, ["name"] = "rainbow:stonebrick_red"}, {["x"] = 8, ["meta"] = {["fields"] = {}, ["inventory"] = {}}, ["y"] = 2, ["z"] = 2, ["name"] = "rainbow:stonebrick_orange"}, {["x"] = 8, ["meta"] = {["fields"] = {}, ["inventory"] = {}}, ["y"] = 2, ["z"] = 3, ["name"] = "rainbow:stonebrick_yellow"}, {["x"] = 8, ["meta"] = {["fields"] = {}, ["inventory"] = {}}, ["y"] = 2, ["z"] = 4, ["name"] = "rainbow:stonebrick_lightgreen"}, {["x"] = 8, ["meta"] = {["fields"] = {}, ["inventory"] = {}}, ["y"] = 2, ["z"] = 5, ["name"] = "rainbow:stonebrick_cyan"}, {["x"] = 8, ["meta"] = {["fields"] = {}, ["inventory"] = {}}, ["y"] = 2, ["z"] = 6, ["name"] = "rainbow:stonebrick_blue"}, {["x"] = 8, ["meta"] = {["fields"] = {}, ["inventory"] = {}}, ["y"] = 2, ["z"] = 7, ["name"] = "rainbow:stonebrick_violet"}, {["x"] = 8, ["meta"] = {["fields"] = {}, ["inventory"] = {}}, ["y"] = 3, ["z"] = 0, ["name"] = "rainbow:stonebrick_violet"}, {["x"] = 8, ["meta"] = {["fields"] = {}, ["inventory"] = {}}, ["y"] = 3, ["z"] = 1, ["name"] = "rainbow:stonebrick_red"}, {["x"] = 8, ["meta"] = {["fields"] = {}, ["inventory"] = {}}, ["y"] = 3, ["z"] = 2, ["name"] = "rainbow:stonebrick_orange"}, {["x"] = 8, ["meta"] = {["fields"] = {}, ["inventory"] = {}}, ["y"] = 3, ["z"] = 3, ["name"] = "rainbow:stonebrick_yellow"}, {["x"] = 8, ["meta"] = {["fields"] = {}, ["inventory"] = {}}, ["y"] = 3, ["z"] = 4, ["name"] = "rainbow:stonebrick_lightgreen"}, {["x"] = 8, ["meta"] = {["fields"] = {}, ["inventory"] = {}}, ["y"] = 3, ["z"] = 5, ["name"] = "rainbow:stonebrick_cyan"}, {["x"] = 8, ["meta"] = {["fields"] = {}, ["inventory"] = {}}, ["y"] = 3, ["z"] = 6, ["name"] = "rainbow:stonebrick_blue"}, {["x"] = 8, ["meta"] = {["fields"] = {}, ["inventory"] = {}}, ["y"] = 3, ["z"] = 7, ["name"] = "rainbow:stonebrick_violet"}, {["x"] = 8, ["meta"] = {["fields"] = {}, ["inventory"] = {}}, ["y"] = 4, ["z"] = 0, ["name"] = "rainbow:stonebrick_blue"}, {["x"] = 8, ["meta"] = {["fields"] = {}, ["inventory"] = {}}, ["y"] = 4, ["z"] = 1, ["name"] = "rainbow:stonebrick_red"}, {["x"] = 8, ["meta"] = {["fields"] = {}, ["inventory"] = {}}, ["y"] = 4, ["z"] = 2, ["name"] = "rainbow:stonebrick_orange"}, {["x"] = 8, ["meta"] = {["fields"] = {}, ["inventory"] = {}}, ["y"] = 4, ["z"] = 3, ["name"] = "rainbow:stonebrick_yellow"}, {["x"] = 8, ["meta"] = {["fields"] = {}, ["inventory"] = {}}, ["y"] = 4, ["z"] = 4, ["name"] = "rainbow:stonebrick_lightgreen"}, {["x"] = 8, ["meta"] = {["fields"] = {}, ["inventory"] = {}}, ["y"] = 4, ["z"] = 5, ["name"] = "rainbow:stonebrick_cyan"}, {["x"] = 8, ["meta"] = {["fields"] = {}, ["inventory"] = {}}, ["y"] = 4, ["z"] = 6, ["name"] = "rainbow:stonebrick_blue"}, {["x"] = 8, ["meta"] = {["fields"] = {}, ["inventory"] = {}}, ["y"] = 4, ["z"] = 7, ["name"] = "rainbow:stonebrick_violet"}, {["x"] = 8, ["meta"] = {["fields"] = {}, ["inventory"] = {}}, ["y"] = 5, ["z"] = 0, ["name"] = "rainbow:stonebrick_cyan"}, {["x"] = 8, ["meta"] = {["fields"] = {}, ["inventory"] = {}}, ["y"] = 5, ["z"] = 1, ["name"] = "rainbow:stonebrick_red"}, {["x"] = 8, ["meta"] = {["fields"] = {}, ["inventory"] = {}}, ["y"] = 5, ["z"] = 2, ["name"] = "rainbow:stonebrick_orange"}, {["x"] = 8, ["meta"] = {["fields"] = {}, ["inventory"] = {}}, ["y"] = 5, ["z"] = 3, ["name"] = "rainbow:stonebrick_yellow"}, {["x"] = 8, ["meta"] = {["fields"] = {}, ["inventory"] = {}}, ["y"] = 5, ["z"] = 4, ["name"] = "rainbow:stonebrick_lightgreen"}, {["x"] = 8, ["meta"] = {["fields"] = {}, ["inventory"] = {}}, ["y"] = 5, ["z"] = 5, ["name"] = "rainbow:stonebrick_cyan"}, {["x"] = 8, ["meta"] = {["fields"] = {}, ["inventory"] = {}}, ["y"] = 5, ["z"] = 6, ["name"] = "rainbow:stonebrick_blue"}, {["x"] = 8, ["meta"] = {["fields"] = {}, ["inventory"] = {}}, ["y"] = 5, ["z"] = 7, ["name"] = "rainbow:stonebrick_violet"}, {["x"] = 8, ["meta"] = {["fields"] = {}, ["inventory"] = {}}, ["y"] = 6, ["z"] = 0, ["name"] = "rainbow:stonebrick_lightgreen"}, {["x"] = 8, ["meta"] = {["fields"] = {}, ["inventory"] = {}}, ["param2"] = 3, ["y"] = 6, ["param1"] = 61, ["z"] = 1, ["name"] = "rainbow:micro_stonebrick_red_15"}, {["x"] = 8, ["meta"] = {["fields"] = {}, ["inventory"] = {}}, ["param2"] = 3, ["y"] = 6, ["param1"] = 46, ["z"] = 2, ["name"] = "rainbow:micro_stonebrick_orange_15"}, {["x"] = 8, ["meta"] = {["fields"] = {}, ["inventory"] = {}}, ["param2"] = 3, ["y"] = 6, ["param1"] = 30, ["z"] = 3, ["name"] = "rainbow:micro_stonebrick_yellow_15"}, {["x"] = 8, ["meta"] = {["fields"] = {}, ["inventory"] = {}}, ["param2"] = 3, ["y"] = 6, ["param1"] = 14, ["z"] = 4, ["name"] = "rainbow:micro_stonebrick_lightgreen_15"}, {["x"] = 8, ["meta"] = {["fields"] = {}, ["inventory"] = {}}, ["param2"] = 3, ["y"] = 6, ["param1"] = 14, ["z"] = 5, ["name"] = "rainbow:micro_stonebrick_cyan_15"}, {["x"] = 8, ["meta"] = {["fields"] = {}, ["inventory"] = {}}, ["param2"] = 3, ["y"] = 6, ["param1"] = 14, ["z"] = 6, ["name"] = "rainbow:micro_stonebrick_blue_15"}, {["x"] = 8, ["meta"] = {["fields"] = {}, ["inventory"] = {}}, ["param2"] = 3, ["y"] = 6, ["param1"] = 14, ["z"] = 7, ["name"] = "rainbow:micro_stonebrick_violet_15"}, {["x"] = 8, ["meta"] = {["fields"] = {}, ["inventory"] = {}}, ["y"] = 7, ["z"] = 0, ["name"] = "rainbow:stonebrick_yellow"}, {["x"] = 8, ["meta"] = {["fields"] = {}, ["inventory"] = {}}, ["y"] = 8, ["z"] = 0, ["name"] = "rainbow:stonebrick_orange"}, {["x"] = 8, ["meta"] = {["fields"] = {}, ["inventory"] = {}}, ["y"] = 9, ["z"] = 0, ["name"] = "rainbow:stonebrick_red"}, {["x"] = 8, ["meta"] = {["fields"] = {}, ["inventory"] = {}}, ["y"] = 10, ["z"] = 0, ["name"] = "rainbow:stonebrick_violet"}, {["x"] = 8, ["meta"] = {["fields"] = {}, ["inventory"] = {}}, ["y"] = 11, ["z"] = 0, ["name"] = "rainbow:stonebrick_blue"}, {["x"] = 8, ["meta"] = {["fields"] = {}, ["inventory"] = {}}, ["y"] = 12, ["z"] = 0, ["name"] = "rainbow:stonebrick_cyan"}, {["x"] = 8, ["meta"] = {["fields"] = {}, ["inventory"] = {}}, ["y"] = 13, ["z"] = 0, ["name"] = "rainbow:stonebrick_lightgreen"}, {["x"] = 8, ["meta"] = {["fields"] = {}, ["inventory"] = {}}, ["y"] = 14, ["z"] = 0, ["name"] = "rainbow:stonebrick_yellow"}, {["x"] = 8, ["meta"] = {["fields"] = {}, ["inventory"] = {}}, ["y"] = 15, ["z"] = 0, ["name"] = "rainbow:stonebrick_orange"}, {["x"] = 8, ["meta"] = {["fields"] = {}, ["inventory"] = {}}, ["y"] = 16, ["z"] = 0, ["name"] = "rainbow:stonebrick_red"}, {["x"] = 8, ["meta"] = {["fields"] = {}, ["inventory"] = {}}, ["y"] = 17, ["z"] = 0, ["name"] = "rainbow:stonebrick_violet"}, {["x"] = 8, ["meta"] = {["fields"] = {}, ["inventory"] = {}}, ["y"] = 18, ["z"] = 0, ["name"] = "rainbow:stonebrick_blue"}, {["x"] = 8, ["meta"] = {["fields"] = {}, ["inventory"] = {}}, ["y"] = 19, ["z"] = 0, ["name"] = "rainbow:stonebrick_cyan"}, {["x"] = 8, ["meta"] = {["fields"] = {}, ["inventory"] = {}}, ["y"] = 20, ["z"] = 0, ["name"] = "rainbow:stonebrick_lightgreen"}, {["x"] = 8, ["meta"] = {["fields"] = {}, ["inventory"] = {}}, ["y"] = 21, ["z"] = 0, ["name"] = "rainbow:stonebrick_yellow"}, {["x"] = 8, ["meta"] = {["fields"] = {}, ["inventory"] = {}}, ["y"] = 22, ["z"] = 0, ["name"] = "rainbow:stonebrick_orange"}, {["x"] = 8, ["meta"] = {["fields"] = {}, ["inventory"] = {}}, ["y"] = 23, ["z"] = 0, ["name"] = "rainbow:stonebrick_red"}, {["x"] = 8, ["meta"] = {["fields"] = {}, ["inventory"] = {}}, ["y"] = 24, ["z"] = 0, ["name"] = "rainbow:stonebrick_violet"}, {["x"] = 8, ["meta"] = {["fields"] = {}, ["inventory"] = {}}, ["y"] = 25, ["z"] = 0, ["name"] = "rainbow:stonebrick_blue"}, {["x"] = 8, ["meta"] = {["fields"] = {}, ["inventory"] = {}}, ["y"] = 26, ["z"] = 0, ["name"] = "rainbow:stonebrick_cyan"}, {["x"] = 8, ["meta"] = {["fields"] = {}, ["inventory"] = {}}, ["y"] = 27, ["z"] = 0, ["name"] = "rainbow:stonebrick_lightgreen"}, {["x"] = 8, ["meta"] = {["fields"] = {}, ["inventory"] = {}}, ["param2"] = 22, ["y"] = 27, ["param1"] = 110, ["z"] = 1, ["name"] = "rainbow:slope_stonebrick_black"}, {["x"] = 8, ["meta"] = {["fields"] = {}, ["inventory"] = {}}, ["param2"] = 20, ["y"] = 27, ["param1"] = 110, ["z"] = 7, ["name"] = "rainbow:slope_stonebrick_black"}, {["x"] = 8, ["meta"] = {["fields"] = {}, ["inventory"] = {}}, ["y"] = 28, ["z"] = 0, ["name"] = "rainbow:stonebrick_yellow"}, {["x"] = 8, ["meta"] = {["fields"] = {}, ["inventory"] = {}}, ["y"] = 28, ["param1"] = 126, ["z"] = 1, ["name"] = "rainbow:slope_stonebrick_black"}, {["x"] = 8, ["meta"] = {["fields"] = {}, ["inventory"] = {}}, ["param2"] = 22, ["y"] = 28, ["param1"] = 110, ["z"] = 2, ["name"] = "rainbow:slope_stonebrick_black"}, {["x"] = 8, ["meta"] = {["fields"] = {}, ["inventory"] = {}}, ["param2"] = 20, ["y"] = 28, ["param1"] = 110, ["z"] = 6, ["name"] = "rainbow:slope_stonebrick_black"}, {["x"] = 8, ["meta"] = {["fields"] = {}, ["inventory"] = {}}, ["param2"] = 2, ["y"] = 28, ["param1"] = 126, ["z"] = 7, ["name"] = "rainbow:slope_stonebrick_black"}, {["x"] = 8, ["meta"] = {["fields"] = {}, ["inventory"] = {}}, ["y"] = 29, ["z"] = 0, ["name"] = "rainbow:stonebrick_orange"}, {["x"] = 8, ["meta"] = {["fields"] = {}, ["inventory"] = {}}, ["y"] = 29, ["z"] = 2, ["name"] = "rainbow:stonebrick_black"}, {["x"] = 8, ["meta"] = {["fields"] = {}, ["inventory"] = {}}, ["param2"] = 22, ["y"] = 29, ["param1"] = 142, ["z"] = 3, ["name"] = "rainbow:slope_stonebrick_black"}, {["x"] = 8, ["meta"] = {["fields"] = {}, ["inventory"] = {}}, ["param2"] = 20, ["y"] = 29, ["param1"] = 142, ["z"] = 5, ["name"] = "rainbow:slope_stonebrick_black"}, {["x"] = 8, ["meta"] = {["fields"] = {}, ["inventory"] = {}}, ["y"] = 29, ["z"] = 6, ["name"] = "rainbow:stonebrick_black"}, {["x"] = 8, ["meta"] = {["fields"] = {}, ["inventory"] = {}}, ["y"] = 30, ["z"] = 0, ["name"] = "rainbow:stonebrick_red"}, {["x"] = 8, ["meta"] = {["fields"] = {}, ["inventory"] = {}}, ["param2"] = 20, ["y"] = 30, ["param1"] = 158, ["z"] = 1, ["name"] = "rainbow:slope_stonebrick_black"}, {["x"] = 8, ["meta"] = {["fields"] = {}, ["inventory"] = {}}, ["param2"] = 2, ["y"] = 30, ["param1"] = 142, ["z"] = 2, ["name"] = "rainbow:slope_stonebrick_black"}, {["x"] = 8, ["meta"] = {["fields"] = {}, ["inventory"] = {}}, ["y"] = 30, ["param1"] = 158, ["z"] = 3, ["name"] = "rainbow:slope_stonebrick_black"}, {["x"] = 8, ["meta"] = {["fields"] = {}, ["inventory"] = {}}, ["y"] = 30, ["z"] = 4, ["name"] = "rainbow:stonebrick_black"}, {["x"] = 8, ["meta"] = {["fields"] = {}, ["inventory"] = {}}, ["param2"] = 2, ["y"] = 30, ["param1"] = 158, ["z"] = 5, ["name"] = "rainbow:slope_stonebrick_black"}, {["x"] = 8, ["meta"] = {["fields"] = {}, ["inventory"] = {}}, ["y"] = 30, ["param1"] = 142, ["z"] = 6, ["name"] = "rainbow:slope_stonebrick_black"}, {["x"] = 8, ["meta"] = {["fields"] = {}, ["inventory"] = {}}, ["param2"] = 22, ["y"] = 30, ["param1"] = 158, ["z"] = 7, ["name"] = "rainbow:slope_stonebrick_black"}, {["x"] = 8, ["meta"] = {["fields"] = {}, ["inventory"] = {}}, ["y"] = 31, ["z"] = 0, ["name"] = "rainbow:stonebrick_black"}, {["x"] = 8, ["meta"] = {["fields"] = {}, ["inventory"] = {}}, ["y"] = 31, ["z"] = 1, ["name"] = "rainbow:stonebrick_red"}, {["x"] = 8, ["meta"] = {["fields"] = {}, ["inventory"] = {}}, ["y"] = 31, ["z"] = 2, ["name"] = "rainbow:stonebrick_orange"}, {["x"] = 8, ["meta"] = {["fields"] = {}, ["inventory"] = {}}, ["y"] = 31, ["z"] = 3, ["name"] = "rainbow:stonebrick_yellow"}, {["x"] = 8, ["meta"] = {["fields"] = {}, ["inventory"] = {}}, ["y"] = 31, ["z"] = 4, ["name"] = "rainbow:stonebrick_lightgreen"}, {["x"] = 8, ["meta"] = {["fields"] = {}, ["inventory"] = {}}, ["y"] = 31, ["z"] = 5, ["name"] = "rainbow:stonebrick_cyan"}, {["x"] = 8, ["meta"] = {["fields"] = {}, ["inventory"] = {}}, ["y"] = 31, ["z"] = 6, ["name"] = "rainbow:stonebrick_blue"}, {["x"] = 8, ["meta"] = {["fields"] = {}, ["inventory"] = {}}, ["y"] = 31, ["z"] = 7, ["name"] = "rainbow:stonebrick_violet"}}