5:return {{["x"] = 0, ["meta"] = {["fields"] = {}, ["inventory"] = {}}, ["y"] = 0, ["param1"] = 15, ["z"] = 18, ["name"] = "default:meselamp"}, {["x"] = 0, ["meta"] = {["fields"] = {}, ["inventory"] = {}}, ["y"] = 1, ["param1"] = 15, ["z"] = 18, ["name"] = "default:meselamp"}, {["x"] = 0, ["meta"] = {["fields"] = {}, ["inventory"] = {}}, ["y"] = 2, ["param1"] = 15, ["z"] = 18, ["name"] = "default:meselamp"}, {["x"] = 0, ["meta"] = {["fields"] = {}, ["inventory"] = {}}, ["y"] = 3, ["param1"] = 15, ["z"] = 18, ["name"] = "default:meselamp"}, {["x"] = 0, ["meta"] = {["fields"] = {}, ["inventory"] = {}}, ["y"] = 4, ["param1"] = 15, ["z"] = 18, ["name"] = "default:meselamp"}, {["x"] = 0, ["meta"] = {["fields"] = {}, ["inventory"] = {}}, ["y"] = 5, ["param1"] = 15, ["z"] = 18, ["name"] = "default:meselamp"}, {["x"] = 0, ["meta"] = {["fields"] = {}, ["inventory"] = {}}, ["y"] = 6, ["param1"] = 15, ["z"] = 18, ["name"] = "default:meselamp"}, {["x"] = 0, ["meta"] = {["fields"] = {}, ["inventory"] = {}}, ["y"] = 7, ["param1"] = 15, ["z"] = 18, ["name"] = "default:meselamp"}, {["x"] = 0, ["meta"] = {["fields"] = {}, ["inventory"] = {}}, ["y"] = 8, ["param1"] = 15, ["z"] = 18, ["name"] = "default:meselamp"}, {["x"] = 1, ["meta"] = {["fields"] = {}, ["inventory"] = {}}, ["y"] = 0, ["param1"] = 15, ["z"] = 5, ["name"] = "carts:powerrail"}, {["x"] = 1, ["meta"] = {["fields"] = {["formspec"] = "size[9,2.5]field[0.3,  0;9,2;scanname;Name of player to scan for (empty for any):;${scanname}]field[0.3,1.5;4,2;digiline_channel;Digiline Channel (optional):;${digiline_channel}]button_exit[7,0.75;2,3;;Save]"}, ["inventory"] = {}}, ["y"] = 0, ["param1"] = 157, ["z"] = 14, ["name"] = "mesecons_detector:object_detector_off"}, {["x"] = 1, ["meta"] = {["fields"] = {["formspec"] = "size[9,2.5]field[0.3,  0;9,2;scanname;Name of player to scan for (empty for any):;${scanname}]field[0.3,1.5;4,2;digiline_channel;Digiline Channel (optional):;${digiline_channel}]button_exit[7,0.75;2,3;;Save]"}, ["inventory"] = {}}, ["y"] = 1, ["param1"] = 109, ["z"] = 11, ["name"] = "mesecons_detector:object_detector_off"}, {["x"] = 1, ["meta"] = {["fields"] = {["formspec"] = "size[9,2.5]field[0.3,  0;9,2;scanname;Name of player to scan for (empty for any):;${scanname}]field[0.3,1.5;4,2;digiline_channel;Digiline Channel (optional):;${digiline_channel}]button_exit[7,0.75;2,3;;Save]"}, ["inventory"] = {}}, ["y"] = 2, ["param1"] = 93, ["z"] = 10, ["name"] = "mesecons_detector:object_detector_off"}, {["x"] = 1, ["meta"] = {["fields"] = {["formspec"] = "size[9,2.5]field[0.3,  0;9,2;scanname;Name of player to scan for (empty for any):;${scanname}]field[0.3,1.5;4,2;digiline_channel;Digiline Channel (optional):;${digiline_channel}]button_exit[7,0.75;2,3;;Save]"}, ["inventory"] = {}}, ["y"] = 3, ["param1"] = 29, ["z"] = 6, ["name"] = "mesecons_detector:object_detector_off"}, {["x"] = 1, ["meta"] = {["fields"] = {["formspec"] = "size[9,2.5]field[0.3,  0;9,2;scanname;Name of player to scan for (empty for any):;${scanname}]field[0.3,1.5;4,2;digiline_channel;Digiline Channel (optional):;${digiline_channel}]button_exit[7,0.75;2,3;;Save]"}, ["inventory"] = {}}, ["y"] = 3, ["param1"] = 77, ["z"] = 9, ["name"] = "mesecons_detector:object_detector_off"}, {["x"] = 2, ["meta"] = {["fields"] = {}, ["inventory"] = {}}, ["y"] = 0, ["z"] = 9, ["name"] = "maptools:brick"}, {["x"] = 2, ["meta"] = {["fields"] = {}, ["inventory"] = {}}, ["y"] = 0, ["z"] = 10, ["name"] = "maptools:brick"}, {["x"] = 2, ["meta"] = {["fields"] = {}, ["inventory"] = {}}, ["y"] = 0, ["z"] = 11, ["name"] = "maptools:brick"}, {["x"] = 2, ["meta"] = {["fields"] = {}, ["inventory"] = {}}, ["y"] = 0, ["param1"] = 111, ["z"] = 12, ["name"] = "carts:powerrail"}, {["x"] = 2, ["meta"] = {["fields"] = {}, ["inventory"] = {}}, ["y"] = 0, ["param1"] = 127, ["z"] = 13, ["name"] = "carts:powerrail"}, {["x"] = 2, ["meta"] = {["fields"] = {["cart_acceleration"] = "0"}, ["inventory"] = {}}, ["y"] = 0, ["param1"] = 143, ["z"] = 14, ["name"] = "carts:powerrail"}, {["x"] = 2, ["meta"] = {["fields"] = {}, ["inventory"] = {}}, ["y"] = 0, ["param1"] = 159, ["z"] = 15, ["name"] = "carts:powerrail"}, {["x"] = 2, ["meta"] = {["fields"] = {["cart_acceleration"] = "0"}, ["inventory"] = {}}, ["y"] = 0, ["param1"] = 175, ["z"] = 16, ["name"] = "carts:powerrail"}, {["x"] = 2, ["meta"] = {["fields"] = {}, ["inventory"] = {}}, ["y"] = 1, ["z"] = 8, ["name"] = "maptools:brick"}, {["x"] = 2, ["meta"] = {["fields"] = {}, ["inventory"] = {}}, ["y"] = 1, ["z"] = 9, ["name"] = "maptools:brick"}, {["x"] = 2, ["meta"] = {["fields"] = {}, ["inventory"] = {}}, ["y"] = 1, ["z"] = 10, ["name"] = "maptools:brick"}, {["x"] = 2, ["meta"] = {["fields"] = {["cart_acceleration"] = "0"}, ["inventory"] = {}}, ["y"] = 1, ["param1"] = 95, ["z"] = 11, ["name"] = "carts:powerrail"}, {["x"] = 2, ["meta"] = {["fields"] = {}, ["inventory"] = {}}, ["y"] = 2, ["z"] = 3, ["name"] = "maptools:brick"}, {["x"] = 2, ["meta"] = {["fields"] = {}, ["inventory"] = {}}, ["y"] = 2, ["z"] = 4, ["name"] = "maptools:brick"}, {["x"] = 2, ["meta"] = {["fields"] = {}, ["inventory"] = {}}, ["y"] = 2, ["z"] = 5, ["name"] = "maptools:brick"}, {["x"] = 2, ["meta"] = {["fields"] = {}, ["inventory"] = {}}, ["y"] = 2, ["z"] = 6, ["name"] = "maptools:brick"}, {["x"] = 2, ["meta"] = {["fields"] = {}, ["inventory"] = {}}, ["y"] = 2, ["z"] = 7, ["name"] = "maptools:brick"}, {["x"] = 2, ["meta"] = {["fields"] = {}, ["inventory"] = {}}, ["y"] = 2, ["z"] = 8, ["name"] = "maptools:brick"}, {["x"] = 2, ["meta"] = {["fields"] = {}, ["inventory"] = {}}, ["y"] = 2, ["z"] = 9, ["name"] = "maptools:brick"}, {["x"] = 2, ["meta"] = {["fields"] = {["cart_acceleration"] = "0"}, ["inventory"] = {}}, ["y"] = 2, ["param1"] = 79, ["z"] = 10, ["name"] = "carts:powerrail"}, {["x"] = 2, ["meta"] = {["fields"] = {}, ["inventory"] = {}}, ["y"] = 3, ["param1"] = 15, ["z"] = 3, ["name"] = "carts:powerrail"}, {["x"] = 2, ["meta"] = {["fields"] = {["cart_acceleration"] = "0"}, ["inventory"] = {}}, ["y"] = 3, ["param1"] = 15, ["z"] = 4, ["name"] = "carts:powerrail"}, {["x"] = 2, ["meta"] = {["fields"] = {}, ["inventory"] = {}}, ["y"] = 3, ["param1"] = 15, ["z"] = 5, ["name"] = "carts:powerrail"}, {["x"] = 2, ["meta"] = {["fields"] = {["cart_acceleration"] = "0"}, ["inventory"] = {}}, ["y"] = 3, ["param1"] = 15, ["z"] = 6, ["name"] = "carts:powerrail"}, {["x"] = 2, ["meta"] = {["fields"] = {}, ["inventory"] = {}}, ["y"] = 3, ["param1"] = 31, ["z"] = 7, ["name"] = "carts:powerrail"}, {["x"] = 2, ["meta"] = {["fields"] = {}, ["inventory"] = {}}, ["y"] = 3, ["param1"] = 47, ["z"] = 8, ["name"] = "carts:powerrail"}, {["x"] = 2, ["meta"] = {["fields"] = {["cart_acceleration"] = "0"}, ["inventory"] = {}}, ["y"] = 3, ["param1"] = 63, ["z"] = 9, ["name"] = "carts:powerrail"}, {["x"] = 3, ["meta"] = {["fields"] = {["formspec"] = "size[9,2.5]field[0.3,  0;9,2;scanname;Name of player to scan for (empty for any):;${scanname}]field[0.3,1.5;4,2;digiline_channel;Digiline Channel (optional):;${digiline_channel}]button_exit[7,0.75;2,3;;Save]"}, ["inventory"] = {}}, ["y"] = 0, ["param1"] = 157, ["z"] = 16, ["name"] = "mesecons_detector:object_detector_off"}, {["x"] = 3, ["meta"] = {["fields"] = {}, ["inventory"] = {}}, ["y"] = 2, ["z"] = 3, ["name"] = "maptools:brick"}, {["x"] = 3, ["meta"] = {["fields"] = {["cart_acceleration"] = "0"}, ["inventory"] = {}}, ["y"] = 3, ["param1"] = 15, ["z"] = 3, ["name"] = "carts:powerrail"}, {["x"] = 3, ["meta"] = {["fields"] = {["formspec"] = "size[9,2.5]field[0.3,  0;9,2;scanname;Name of player to scan for (empty for any):;${scanname}]field[0.3,1.5;4,2;digiline_channel;Digiline Channel (optional):;${digiline_channel}]button_exit[7,0.75;2,3;;Save]"}, ["inventory"] = {}}, ["y"] = 3, ["param1"] = 13, ["z"] = 4, ["name"] = "mesecons_detector:object_detector_off"}, {["x"] = 3, ["meta"] = {["fields"] = {["scanname"] = "wolfteam", ["digiline_channel"] = "wolf", ["formspec"] = "size[9,2.5]field[0.3,  0;9,2;scanname;Name of player to scan for (empty for any):;${scanname}]field[0.3,1.5;4,2;digiline_channel;Digiline Channel (optional):;${digiline_channel}]button_exit[7,0.75;2,3;;Save]"}, ["inventory"] = {}}, ["y"] = 4, ["param1"] = 13, ["z"] = 6, ["name"] = "mesecons_detector:object_detector_off"}, {["x"] = 3, ["meta"] = {["fields"] = {["formspec"] = "size[9,2.5]field[0.3,  0;9,2;scanname;Name of player to scan for (empty for any):;${scanname}]field[0.3,1.5;4,2;digiline_channel;Digiline Channel (optional):;${digiline_channel}]button_exit[7,0.75;2,3;;Save]"}, ["inventory"] = {}}, ["y"] = 5, ["param1"] = 29, ["z"] = 8, ["name"] = "mesecons_detector:object_detector_off"}, {["x"] = 3, ["meta"] = {["fields"] = {["formspec"] = "size[9,2.5]field[0.3,  0;9,2;scanname;Name of player to scan for (empty for any):;${scanname}]field[0.3,1.5;4,2;digiline_channel;Digiline Channel (optional):;${digiline_channel}]button_exit[7,0.75;2,3;;Save]"}, ["inventory"] = {}}, ["y"] = 5, ["param1"] = 61, ["z"] = 10, ["name"] = "mesecons_detector:object_detector_off"}, {["x"] = 4, ["meta"] = {["fields"] = {}, ["inventory"] = {}}, ["y"] = 2, ["z"] = 3, ["name"] = "maptools:brick"}, {["x"] = 4, ["meta"] = {["fields"] = {}, ["inventory"] = {}}, ["y"] = 2, ["z"] = 4, ["name"] = "maptools:brick"}, {["x"] = 4, ["meta"] = {["fields"] = {}, ["inventory"] = {}}, ["y"] = 2, ["z"] = 5, ["name"] = "maptools:brick"}, {["x"] = 4, ["meta"] = {["fields"] = {}, ["inventory"] = {}}, ["y"] = 2, ["z"] = 6, ["name"] = "maptools:brick"}, {["x"] = 4, ["meta"] = {["fields"] = {}, ["inventory"] = {}}, ["y"] = 3, ["param1"] = 15, ["z"] = 3, ["name"] = "carts:powerrail"}, {["x"] = 4, ["meta"] = {["fields"] = {["cart_acceleration"] = "0"}, ["inventory"] = {}}, ["y"] = 3, ["param1"] = 15, ["z"] = 4, ["name"] = "carts:powerrail"}, {["x"] = 4, ["meta"] = {["fields"] = {}, ["inventory"] = {}}, ["y"] = 3, ["param1"] = 15, ["z"] = 5, ["name"] = "carts:powerrail"}, {["x"] = 4, ["meta"] = {["fields"] = {}, ["inventory"] = {}}, ["y"] = 3, ["z"] = 6, ["name"] = "maptools:brick"}, {["x"] = 4, ["meta"] = {["fields"] = {}, ["inventory"] = {}}, ["y"] = 3, ["z"] = 7, ["name"] = "maptools:brick"}, {["x"] = 4, ["meta"] = {["fields"] = {["cart_acceleration"] = "0"}, ["inventory"] = {}}, ["y"] = 4, ["param1"] = 15, ["z"] = 6, ["name"] = "carts:powerrail"}, {["x"] = 4, ["meta"] = {["fields"] = {}, ["inventory"] = {}}, ["y"] = 4, ["z"] = 7, ["name"] = "maptools:brick"}, {["x"] = 4, ["meta"] = {["fields"] = {}, ["inventory"] = {}}, ["y"] = 4, ["z"] = 8, ["name"] = "maptools:brick"}, {["x"] = 4, ["meta"] = {["fields"] = {}, ["inventory"] = {}}, ["y"] = 4, ["z"] = 9, ["name"] = "maptools:brick"}, {["x"] = 4, ["meta"] = {["fields"] = {}, ["inventory"] = {}}, ["y"] = 4, ["z"] = 10, ["name"] = "maptools:brick"}, {["x"] = 4, ["meta"] = {["fields"] = {}, ["inventory"] = {}}, ["y"] = 4, ["z"] = 11, ["name"] = "maptools:brick"}, {["x"] = 4, ["meta"] = {["fields"] = {}, ["inventory"] = {}}, ["y"] = 5, ["param1"] = 15, ["z"] = 7, ["name"] = "carts:powerrail"}, {["x"] = 4, ["meta"] = {["fields"] = {["cart_acceleration"] = "0"}, ["inventory"] = {}}, ["y"] = 5, ["param1"] = 15, ["z"] = 8, ["name"] = "carts:powerrail"}, {["x"] = 4, ["meta"] = {["fields"] = {}, ["inventory"] = {}}, ["y"] = 5, ["param1"] = 31, ["z"] = 9, ["name"] = "carts:powerrail"}, {["x"] = 4, ["meta"] = {["fields"] = {["cart_acceleration"] = "0"}, ["inventory"] = {}}, ["y"] = 5, ["param1"] = 47, ["z"] = 10, ["name"] = "carts:powerrail"}, {["x"] = 4, ["meta"] = {["fields"] = {}, ["inventory"] = {}}, ["y"] = 5, ["param1"] = 63, ["z"] = 11, ["name"] = "carts:powerrail"}, {["x"] = 5, ["meta"] = {["fields"] = {}, ["inventory"] = {}}, ["y"] = 4, ["z"] = 11, ["name"] = "maptools:brick"}, {["x"] = 5, ["meta"] = {["fields"] = {}, ["inventory"] = {}}, ["y"] = 5, ["param1"] = 47, ["z"] = 11, ["name"] = "carts:powerrail"}, {["x"] = 6, ["meta"] = {["fields"] = {}, ["inventory"] = {}}, ["y"] = 4, ["z"] = 7, ["name"] = "maptools:brick"}, {["x"] = 6, ["meta"] = {["fields"] = {}, ["inventory"] = {}}, ["y"] = 4, ["z"] = 8, ["name"] = "maptools:brick"}, {["x"] = 6, ["meta"] = {["fields"] = {}, ["inventory"] = {}}, ["y"] = 4, ["z"] = 9, ["name"] = "maptools:brick"}, {["x"] = 6, ["meta"] = {["fields"] = {}, ["inventory"] = {}}, ["y"] = 4, ["z"] = 10, ["name"] = "maptools:brick"}, {["x"] = 6, ["meta"] = {["fields"] = {}, ["inventory"] = {}}, ["y"] = 4, ["z"] = 11, ["name"] = "maptools:brick"}, {["x"] = 6, ["meta"] = {["fields"] = {}, ["inventory"] = {}}, ["y"] = 5, ["z"] = 6, ["name"] = "maptools:brick"}, {["x"] = 6, ["meta"] = {["fields"] = {}, ["inventory"] = {}}, ["y"] = 5, ["z"] = 7, ["name"] = "maptools:brick"}, {["x"] = 6, ["meta"] = {["fields"] = {}, ["inventory"] = {}}, ["y"] = 5, ["param1"] = 15, ["z"] = 8, ["name"] = "carts:powerrail"}, {["x"] = 6, ["meta"] = {["fields"] = {}, ["inventory"] = {}}, ["y"] = 5, ["param1"] = 15, ["z"] = 9, ["name"] = "carts:powerrail"}, {["x"] = 6, ["meta"] = {["fields"] = {}, ["inventory"] = {}}, ["y"] = 5, ["param1"] = 15, ["z"] = 10, ["name"] = "carts:powerrail"}, {["x"] = 6, ["meta"] = {["fields"] = {}, ["inventory"] = {}}, ["y"] = 5, ["param1"] = 31, ["z"] = 11, ["name"] = "carts:powerrail"}, {["x"] = 6, ["meta"] = {["fields"] = {["formspec"] = "size[9,2.5]field[0.3,  0;9,2;scanname;Name of player to scan for (empty for any):;${scanname}]field[0.3,1.5;4,2;digiline_channel;Digiline Channel (optional):;${digiline_channel}]button_exit[7,0.75;2,3;;Save]"}, ["inventory"] = {}}, ["y"] = 6, ["param1"] = 13, ["z"] = 5, ["name"] = "mesecons_detector:object_detector_off"}, {["x"] = 6, ["meta"] = {["fields"] = {["cart_acceleration"] = "0"}, ["inventory"] = {}}, ["y"] = 6, ["param1"] = 15, ["z"] = 6, ["name"] = "carts:powerrail"}, {["x"] = 6, ["meta"] = {["fields"] = {}, ["inventory"] = {}}, ["y"] = 6, ["param1"] = 15, ["z"] = 7, ["name"] = "carts:powerrail"}, {["x"] = 7, ["meta"] = {["fields"] = {}, ["inventory"] = {}}, ["y"] = 5, ["z"] = 4, ["name"] = "maptools:brick"}, {["x"] = 7, ["meta"] = {["fields"] = {}, ["inventory"] = {}}, ["y"] = 5, ["z"] = 5, ["name"] = "maptools:brick"}, {["x"] = 7, ["meta"] = {["fields"] = {}, ["inventory"] = {}}, ["y"] = 5, ["z"] = 6, ["name"] = "maptools:brick"}, {["x"] = 7, ["meta"] = {["fields"] = {["formspec"] = "size[9,2.5]field[0.3,  0;9,2;scanname;Name of player to scan for (empty for any):;${scanname}]field[0.3,1.5;4,2;digiline_channel;Digiline Channel (optional):;${digiline_channel}]button_exit[7,0.75;2,3;;Save]"}, ["inventory"] = {}}, ["y"] = 6, ["param1"] = 13, ["z"] = 3, ["name"] = "mesecons_detector:object_detector_off"}, {["x"] = 7, ["meta"] = {["fields"] = {["cart_acceleration"] = "0"}, ["inventory"] = {}}, ["y"] = 6, ["param1"] = 15, ["z"] = 4, ["name"] = "carts:powerrail"}, {["x"] = 7, ["meta"] = {["fields"] = {["cart_acceleration"] = "0"}, ["inventory"] = {}}, ["y"] = 6, ["param1"] = 15, ["z"] = 5, ["name"] = "carts:powerrail"}, {["x"] = 7, ["meta"] = {["fields"] = {}, ["inventory"] = {}}, ["y"] = 6, ["param1"] = 15, ["z"] = 6, ["name"] = "carts:powerrail"}, {["x"] = 8, ["meta"] = {["fields"] = {}, ["inventory"] = {}}, ["y"] = 5, ["z"] = 3, ["name"] = "maptools:brick"}, {["x"] = 8, ["meta"] = {["fields"] = {}, ["inventory"] = {}}, ["y"] = 5, ["z"] = 4, ["name"] = "maptools:brick"}, {["x"] = 8, ["meta"] = {["fields"] = {["cart_acceleration"] = "0"}, ["inventory"] = {}}, ["y"] = 6, ["param1"] = 15, ["z"] = 3, ["name"] = "carts:powerrail"}, {["x"] = 8, ["meta"] = {["fields"] = {}, ["inventory"] = {}}, ["y"] = 6, ["param1"] = 15, ["z"] = 4, ["name"] = "carts:powerrail"}, {["x"] = 9, ["meta"] = {["fields"] = {}, ["inventory"] = {}}, ["y"] = 5, ["z"] = 3, ["name"] = "maptools:brick"}, {["x"] = 9, ["meta"] = {["fields"] = {}, ["inventory"] = {}}, ["y"] = 6, ["param1"] = 15, ["z"] = 3, ["name"] = "carts:powerrail"}, {["x"] = 10, ["meta"] = {["fields"] = {}, ["inventory"] = {}}, ["y"] = 5, ["z"] = 3, ["name"] = "maptools:brick"}, {["x"] = 10, ["meta"] = {["fields"] = {["formspec"] = "size[9,2.5]field[0.3,  0;9,2;scanname;Name of player to scan for (empty for any):;${scanname}]field[0.3,1.5;4,2;digiline_channel;Digiline Channel (optional):;${digiline_channel}]button_exit[7,0.75;2,3;;Save]"}, ["inventory"] = {}}, ["y"] = 6, ["param1"] = 13, ["z"] = 2, ["name"] = "mesecons_detector:object_detector_off"}, {["x"] = 10, ["meta"] = {["fields"] = {["cart_acceleration"] = "0"}, ["inventory"] = {}}, ["y"] = 6, ["param1"] = 15, ["z"] = 3, ["name"] = "carts:powerrail"}, {["x"] = 11, ["meta"] = {["fields"] = {}, ["inventory"] = {}}, ["y"] = 5, ["z"] = 3, ["name"] = "maptools:brick"}, {["x"] = 11, ["meta"] = {["fields"] = {["cart_acceleration"] = "0"}, ["inventory"] = {}}, ["y"] = 6, ["param1"] = 15, ["z"] = 3, ["name"] = "carts:powerrail"}, {["x"] = 11, ["meta"] = {["fields"] = {["formspec"] = "size[9,2.5]field[0.3,  0;9,2;scanname;Name of player to scan for (empty for any):;${scanname}]field[0.3,1.5;4,2;digiline_channel;Digiline Channel (optional):;${digiline_channel}]button_exit[7,0.75;2,3;;Save]"}, ["inventory"] = {}}, ["y"] = 6, ["param1"] = 13, ["z"] = 4, ["name"] = "mesecons_detector:object_detector_off"}, {["x"] = 12, ["meta"] = {["fields"] = {}, ["inventory"] = {}}, ["y"] = 3, ["z"] = 8, ["name"] = "maptools:brick"}, {["x"] = 12, ["meta"] = {["fields"] = {}, ["inventory"] = {}}, ["y"] = 4, ["z"] = 6, ["name"] = "maptools:brick"}, {["x"] = 12, ["meta"] = {["fields"] = {}, ["inventory"] = {}}, ["y"] = 4, ["z"] = 7, ["name"] = "maptools:brick"}, {["x"] = 12, ["meta"] = {["fields"] = {}, ["inventory"] = {}}, ["y"] = 4, ["z"] = 8, ["name"] = "maptools:brick"}, {["x"] = 12, ["meta"] = {["fields"] = {}, ["inventory"] = {}}, ["y"] = 5, ["z"] = 3, ["name"] = "maptools:brick"}, {["x"] = 12, ["meta"] = {["fields"] = {}, ["inventory"] = {}}, ["y"] = 5, ["z"] = 4, ["name"] = "maptools:brick"}, {["x"] = 12, ["meta"] = {["fields"] = {}, ["inventory"] = {}}, ["y"] = 5, ["z"] = 5, ["name"] = "maptools:brick"}, {["x"] = 12, ["meta"] = {["fields"] = {}, ["inventory"] = {}}, ["y"] = 5, ["z"] = 6, ["name"] = "maptools:brick"}, {["x"] = 12, ["meta"] = {["fields"] = {}, ["inventory"] = {}}, ["y"] = 5, ["param1"] = 15, ["z"] = 7, ["name"] = "carts:powerrail"}, {["x"] = 12, ["meta"] = {["fields"] = {}, ["inventory"] = {}}, ["y"] = 5, ["param1"] = 15, ["z"] = 8, ["name"] = "carts:powerrail"}, {["x"] = 12, ["meta"] = {["fields"] = {["cart_acceleration"] = "0"}, ["inventory"] = {}}, ["y"] = 6, ["param1"] = 31, ["z"] = 3, ["name"] = "carts:powerrail"}, {["x"] = 12, ["meta"] = {["fields"] = {["cart_acceleration"] = "0"}, ["inventory"] = {}}, ["y"] = 6, ["param1"] = 15, ["z"] = 4, ["name"] = "carts:powerrail"}, {["x"] = 12, ["meta"] = {["fields"] = {["cart_acceleration"] = "0"}, ["inventory"] = {}}, ["y"] = 6, ["param1"] = 15, ["z"] = 5, ["name"] = "carts:powerrail"}, {["x"] = 12, ["meta"] = {["fields"] = {}, ["inventory"] = {}}, ["y"] = 6, ["param1"] = 15, ["z"] = 6, ["name"] = "carts:powerrail"}, {["x"] = 13, ["meta"] = {["fields"] = {}, ["inventory"] = {}}, ["y"] = 0, ["param1"] = 79, ["z"] = 1, ["name"] = "carts:powerrail"}, {["x"] = 13, ["meta"] = {["fields"] = {}, ["inventory"] = {}}, ["y"] = 2, ["z"] = 8, ["name"] = "maptools:brick"}, {["x"] = 13, ["meta"] = {["fields"] = {}, ["inventory"] = {}}, ["y"] = 3, ["z"] = 8, ["name"] = "maptools:brick"}, {["x"] = 13, ["meta"] = {["fields"] = {}, ["inventory"] = {}}, ["y"] = 4, ["param1"] = 15, ["z"] = 8, ["name"] = "carts:powerrail"}, {["x"] = 13, ["meta"] = {["fields"] = {["formspec"] = "size[9,2.5]field[0.3,  0;9,2;scanname;Name of player to scan for (empty for any):;${scanname}]field[0.3,1.5;4,2;digiline_channel;Digiline Channel (optional):;${digiline_channel}]button_exit[7,0.75;2,3;;Save]"}, ["inventory"] = {}}, ["y"] = 6, ["param1"] = 45, ["z"] = 3, ["name"] = "mesecons_detector:object_detector_off"}, {["x"] = 13, ["meta"] = {["fields"] = {["formspec"] = "size[9,2.5]field[0.3,  0;9,2;scanname;Name of player to scan for (empty for any):;${scanname}]field[0.3,1.5;4,2;digiline_channel;Digiline Channel (optional):;${digiline_channel}]button_exit[7,0.75;2,3;;Save]"}, ["inventory"] = {}}, ["y"] = 6, ["param1"] = 13, ["z"] = 5, ["name"] = "mesecons_detector:object_detector_off"}, {["x"] = 14, ["meta"] = {["fields"] = {["cart_acceleration"] = "0"}, ["inventory"] = {}}, ["y"] = 0, ["param1"] = 95, ["z"] = 1, ["name"] = "carts:powerrail"}, {["x"] = 14, ["meta"] = {["fields"] = {["formspec"] = "size[9,2.5]field[0.3,  0;9,2;scanname;Name of player to scan for (empty for any):;${scanname}]field[0.3,1.5;4,2;digiline_channel;Digiline Channel (optional):;${digiline_channel}]button_exit[7,0.75;2,3;;Save]"}, ["inventory"] = {}}, ["y"] = 0, ["param1"] = 77, ["z"] = 2, ["name"] = "mesecons_detector:object_detector_off"}, {["x"] = 14, ["meta"] = {["fields"] = {}, ["inventory"] = {}}, ["y"] = 0, ["z"] = 8, ["name"] = "maptools:brick"}, {["x"] = 14, ["meta"] = {["fields"] = {}, ["inventory"] = {}}, ["y"] = 1, ["z"] = 8, ["name"] = "maptools:brick"}, {["x"] = 14, ["meta"] = {["fields"] = {}, ["inventory"] = {}}, ["y"] = 2, ["z"] = 8, ["name"] = "maptools:brick"}, {["x"] = 14, ["meta"] = {["fields"] = {["formspec"] = "size[9,2.5]field[0.3,  0;9,2;scanname;Name of player to scan for (empty for any):;${scanname}]field[0.3,1.5;4,2;digiline_channel;Digiline Channel (optional):;${digiline_channel}]button_exit[7,0.75;2,3;;Save]"}, ["inventory"] = {}}, ["y"] = 3, ["param1"] = 13, ["z"] = 7, ["name"] = "mesecons_detector:object_detector_off"}, {["x"] = 14, ["meta"] = {["fields"] = {["cart_acceleration"] = "0"}, ["inventory"] = {}}, ["y"] = 3, ["param1"] = 15, ["z"] = 8, ["name"] = "carts:powerrail"}, {["x"] = 15, ["meta"] = {["fields"] = {}, ["inventory"] = {}}, ["y"] = 0, ["param1"] = 111, ["z"] = 1, ["name"] = "carts:powerrail"}, {["x"] = 15, ["meta"] = {["fields"] = {}, ["inventory"] = {}}, ["y"] = 0, ["z"] = 8, ["name"] = "maptools:brick"}, {["x"] = 15, ["meta"] = {["fields"] = {}, ["inventory"] = {}}, ["y"] = 1, ["z"] = 8, ["name"] = "maptools:brick"}, {["x"] = 15, ["meta"] = {["fields"] = {}, ["inventory"] = {}}, ["y"] = 2, ["param1"] = 15, ["z"] = 8, ["name"] = "carts:powerrail"}, {["x"] = 16, ["meta"] = {["fields"] = {}, ["inventory"] = {}}, ["y"] = 0, ["param1"] = 127, ["z"] = 1, ["name"] = "carts:powerrail"}, {["x"] = 16, ["meta"] = {["fields"] = {["formspec"] = "size[9,2.5]field[0.3,  0;9,2;scanname;Name of player to scan for (empty for any):;${scanname}]field[0.3,1.5;4,2;digiline_channel;Digiline Channel (optional):;${digiline_channel}]button_exit[7,0.75;2,3;;Save]"}, ["inventory"] = {}}, ["y"] = 0, ["param1"] = 61, ["z"] = 5, ["name"] = "mesecons_detector:object_detector_off"}, {["x"] = 16, ["meta"] = {["fields"] = {}, ["inventory"] = {}}, ["y"] = 0, ["z"] = 8, ["name"] = "maptools:brick"}, {["x"] = 16, ["meta"] = {["fields"] = {}, ["inventory"] = {}}, ["y"] = 1, ["param1"] = 15, ["z"] = 8, ["name"] = "carts:powerrail"}, {["x"] = 17, ["meta"] = {["fields"] = {["cart_acceleration"] = "0"}, ["inventory"] = {}}, ["y"] = 0, ["param1"] = 143, ["z"] = 1, ["name"] = "carts:powerrail"}, {["x"] = 17, ["meta"] = {["fields"] = {["formspec"] = "size[9,2.5]field[0.3,  0;9,2;scanname;Name of player to scan for (empty for any):;${scanname}]field[0.3,1.5;4,2;digiline_channel;Digiline Channel (optional):;${digiline_channel}]button_exit[7,0.75;2,3;;Save]"}, ["inventory"] = {}}, ["y"] = 0, ["param1"] = 125, ["z"] = 2, ["name"] = "mesecons_detector:object_detector_off"}, {["x"] = 17, ["meta"] = {["fields"] = {["cart_acceleration"] = "0"}, ["inventory"] = {}}, ["y"] = 0, ["param1"] = 111, ["z"] = 3, ["name"] = "carts:powerrail"}, {["x"] = 17, ["meta"] = {["fields"] = {["cart_acceleration"] = "0"}, ["inventory"] = {}}, ["y"] = 0, ["param1"] = 95, ["z"] = 4, ["name"] = "carts:powerrail"}, {["x"] = 17, ["meta"] = {["fields"] = {["cart_acceleration"] = "0"}, ["inventory"] = {}}, ["y"] = 0, ["param1"] = 79, ["z"] = 5, ["name"] = "carts:powerrail"}, {["x"] = 17, ["meta"] = {["fields"] = {["cart_acceleration"] = "0"}, ["inventory"] = {}}, ["y"] = 0, ["param1"] = 63, ["z"] = 6, ["name"] = "carts:powerrail"}, {["x"] = 17, ["meta"] = {["fields"] = {["formspec"] = "size[9,2.5]field[0.3,  0;9,2;scanname;Name of player to scan for (empty for any):;${scanname}]field[0.3,1.5;4,2;digiline_channel;Digiline Channel (optional):;${digiline_channel}]button_exit[7,0.75;2,3;;Save]"}, ["inventory"] = {}}, ["y"] = 0, ["param1"] = 45, ["z"] = 7, ["name"] = "mesecons_detector:object_detector_off"}, {["x"] = 17, ["meta"] = {["fields"] = {["cart_acceleration"] = "0"}, ["inventory"] = {}}, ["y"] = 0, ["param1"] = 31, ["z"] = 8, ["name"] = "carts:powerrail"}, {["x"] = 18, ["meta"] = {["fields"] = {}, ["inventory"] = {}}, ["y"] = 0, ["param1"] = 159, ["z"] = 1, ["name"] = "carts:powerrail"}, {["x"] = 18, ["meta"] = {["fields"] = {["cart_acceleration"] = "0"}, ["inventory"] = {}}, ["y"] = 0, ["param1"] = 127, ["z"] = 3, ["name"] = "carts:powerrail"}, {["x"] = 18, ["meta"] = {["fields"] = {["formspec"] = "size[9,2.5]field[0.3,  0;9,2;scanname;Name of player to scan for (empty for any):;${scanname}]field[0.3,1.5;4,2;digiline_channel;Digiline Channel (optional):;${digiline_channel}]button_exit[7,0.75;2,3;;Save]"}, ["inventory"] = {}}, ["y"] = 0, ["param1"] = 109, ["z"] = 4, ["name"] = "mesecons_detector:object_detector_off"}, {["x"] = 18, ["meta"] = {["fields"] = {["formspec"] = "size[9,2.5]field[0.3,  0;9,2;scanname;Name of player to scan for (empty for any):;${scanname}]field[0.3,1.5;4,2;digiline_channel;Digiline Channel (optional):;${digiline_channel}]button_exit[7,0.75;2,3;;Save]"}, ["inventory"] = {}}, ["y"] = 0, ["param1"] = 93, ["z"] = 5, ["name"] = "mesecons_detector:object_detector_off"}, {["x"] = 18, ["meta"] = {["fields"] = {["cart_acceleration"] = "0"}, ["inventory"] = {}}, ["y"] = 0, ["param1"] = 79, ["z"] = 6, ["name"] = "carts:powerrail"}, {["x"] = 18, ["meta"] = {["fields"] = {["cart_acceleration"] = "0"}, ["inventory"] = {}}, ["y"] = 0, ["param1"] = 63, ["z"] = 7, ["name"] = "carts:powerrail"}, {["x"] = 18, ["meta"] = {["fields"] = {}, ["inventory"] = {}}, ["y"] = 0, ["param1"] = 47, ["z"] = 8, ["name"] = "carts:powerrail"}, {["x"] = 19, ["meta"] = {["fields"] = {["cart_acceleration"] = "0"}, ["inventory"] = {}}, ["y"] = 0, ["param1"] = 175, ["z"] = 1, ["name"] = "carts:powerrail"}, {["x"] = 19, ["meta"] = {["fields"] = {["formspec"] = "size[9,2.5]field[0.3,  0;9,2;scanname;Name of player to scan for (empty for any):;${scanname}]field[0.3,1.5;4,2;digiline_channel;Digiline Channel (optional):;${digiline_channel}]button_exit[7,0.75;2,3;;Save]"}, ["inventory"] = {}}, ["y"] = 0, ["param1"] = 157, ["z"] = 2, ["name"] = "mesecons_detector:object_detector_off"}, {["x"] = 19, ["meta"] = {["fields"] = {["cart_acceleration"] = "0"}, ["inventory"] = {}}, ["y"] = 0, ["param1"] = 143, ["z"] = 3, ["name"] = "carts:powerrail"}, {["x"] = 20, ["meta"] = {["fields"] = {}, ["inventory"] = {}}, ["y"] = 0, ["param1"] = 191, ["z"] = 1, ["name"] = "carts:powerrail"}, {["x"] = 20, ["meta"] = {["fields"] = {["cart_acceleration"] = "0"}, ["inventory"] = {}}, ["y"] = 0, ["param1"] = 175, ["z"] = 2, ["name"] = "carts:powerrail"}, {["x"] = 20, ["meta"] = {["fields"] = {["cart_acceleration"] = "0"}, ["inventory"] = {}}, ["y"] = 0, ["param1"] = 159, ["z"] = 3, ["name"] = "carts:powerrail"}, {["x"] = 21, ["meta"] = {["fields"] = {["formspec"] = "size[9,2.5]field[0.3,  0;9,2;scanname;Name of player to scan for (empty for any):;${scanname}]field[0.3,1.5;4,2;digiline_channel;Digiline Channel (optional):;${digiline_channel}]button_exit[7,0.75;2,3;;Save]"}, ["inventory"] = {}}, ["y"] = 0, ["param1"] = 173, ["z"] = 3, ["name"] = "mesecons_detector:object_detector_off"}, {["x"] = 22, ["meta"] = {["fields"] = {}, ["inventory"] = {}}, ["y"] = 0, ["param1"] = 15, ["z"] = 0, ["name"] = "default:meselamp"}, {["x"] = 22, ["meta"] = {["fields"] = {}, ["inventory"] = {}}, ["y"] = 1, ["param1"] = 15, ["z"] = 0, ["name"] = "default:meselamp"}, {["x"] = 22, ["meta"] = {["fields"] = {}, ["inventory"] = {}}, ["y"] = 2, ["param1"] = 15, ["z"] = 0, ["name"] = "default:meselamp"}, {["x"] = 22, ["meta"] = {["fields"] = {}, ["inventory"] = {}}, ["y"] = 3, ["param1"] = 15, ["z"] = 0, ["name"] = "default:meselamp"}, {["x"] = 22, ["meta"] = {["fields"] = {}, ["inventory"] = {}}, ["y"] = 4, ["param1"] = 15, ["z"] = 0, ["name"] = "default:meselamp"}, {["x"] = 22, ["meta"] = {["fields"] = {}, ["inventory"] = {}}, ["y"] = 5, ["param1"] = 15, ["z"] = 0, ["name"] = "default:meselamp"}, {["x"] = 22, ["meta"] = {["fields"] = {}, ["inventory"] = {}}, ["y"] = 6, ["param1"] = 15, ["z"] = 0, ["name"] = "default:meselamp"}, {["x"] = 22, ["meta"] = {["fields"] = {}, ["inventory"] = {}}, ["y"] = 7, ["param1"] = 15, ["z"] = 0, ["name"] = "default:meselamp"}, {["x"] = 22, ["meta"] = {["fields"] = {}, ["inventory"] = {}}, ["y"] = 8, ["param1"] = 15, ["z"] = 0, ["name"] = "default:meselamp"}, {["x"] = 22, ["meta"] = {["fields"] = {}, ["inventory"] = {}}, ["y"] = 9, ["param1"] = 15, ["z"] = 0, ["name"] = "default:meselamp"}, {["x"] = 22, ["meta"] = {["fields"] = {}, ["inventory"] = {}}, ["y"] = 10, ["param1"] = 15, ["z"] = 0, ["name"] = "default:meselamp"}, {["x"] = 22, ["meta"] = {["fields"] = {}, ["inventory"] = {}}, ["y"] = 11, ["param1"] = 15, ["z"] = 0, ["name"] = "default:meselamp"}, {["x"] = 22, ["meta"] = {["fields"] = {}, ["inventory"] = {}}, ["y"] = 12, ["param1"] = 15, ["z"] = 0, ["name"] = "default:meselamp"}}