5:return {{["x"] = 0, ["meta"] = {["fields"] = {}, ["inventory"] = {}}, ["param2"] = 9, ["y"] = 0, ["param1"] = 189, ["z"] = 0, ["name"] = "rainbow:slope_clay_black"}, {["x"] = 0, ["meta"] = {["fields"] = {}, ["inventory"] = {}}, ["y"] = 0, ["z"] = 1, ["name"] = "rainbow:sand_black"}, {["x"] = 0, ["meta"] = {["fields"] = {}, ["inventory"] = {}}, ["param2"] = 18, ["y"] = 0, ["param1"] = 187, ["z"] = 2, ["name"] = "rainbow:slope_clay_black"}, {["x"] = 0, ["meta"] = {["fields"] = {}, ["inventory"] = {}}, ["param2"] = 1, ["y"] = 1, ["param1"] = 221, ["z"] = 1, ["name"] = "rainbow:slope_clay_black"}, {["x"] = 0, ["meta"] = {["fields"] = {}, ["inventory"] = {}}, ["param2"] = 23, ["y"] = 6, ["param1"] = 221, ["z"] = 1, ["name"] = "rainbow:slope_clay_black"}, {["x"] = 0, ["meta"] = {["fields"] = {}, ["inventory"] = {}}, ["param2"] = 9, ["y"] = 7, ["param1"] = 189, ["z"] = 0, ["name"] = "rainbow:slope_clay_black"}, {["x"] = 0, ["meta"] = {["fields"] = {}, ["inventory"] = {}}, ["y"] = 7, ["z"] = 1, ["name"] = "rainbow:sand_black"}, {["x"] = 0, ["meta"] = {["fields"] = {}, ["inventory"] = {}}, ["param2"] = 18, ["y"] = 7, ["param1"] = 187, ["z"] = 2, ["name"] = "rainbow:slope_clay_black"}, {["x"] = 1, ["meta"] = {["fields"] = {}, ["inventory"] = {}}, ["y"] = 0, ["z"] = 0, ["name"] = "rainbow:sand_black"}, {["x"] = 1, ["meta"] = {["fields"] = {}, ["inventory"] = {}}, ["param2"] = 7, ["y"] = 0, ["param1"] = 238, ["z"] = 1, ["name"] = "rainbow:red_water_flowing"}, {["x"] = 1, ["meta"] = {["fields"] = {}, ["inventory"] = {}}, ["y"] = 0, ["z"] = 2, ["name"] = "rainbow:sand_black"}, {["x"] = 1, ["meta"] = {["fields"] = {}, ["inventory"] = {}}, ["y"] = 1, ["param1"] = 222, ["z"] = 0, ["name"] = "rainbow:slope_clay_black"}, {["x"] = 1, ["meta"] = {["fields"] = {}, ["inventory"] = {}}, ["param2"] = 15, ["y"] = 1, ["param1"] = 238, ["z"] = 1, ["name"] = "rainbow:red_water_flowing"}, {["x"] = 1, ["meta"] = {["fields"] = {}, ["inventory"] = {}}, ["param2"] = 2, ["y"] = 1, ["param1"] = 221, ["z"] = 2, ["name"] = "rainbow:slope_clay_black"}, {["x"] = 1, ["meta"] = {["fields"] = {}, ["inventory"] = {}}, ["param2"] = 15, ["y"] = 2, ["param1"] = 238, ["z"] = 1, ["name"] = "rainbow:red_water_flowing"}, {["x"] = 1, ["meta"] = {["fields"] = {}, ["inventory"] = {}}, ["param2"] = 15, ["y"] = 3, ["param1"] = 238, ["z"] = 1, ["name"] = "rainbow:red_water_flowing"}, {["x"] = 1, ["meta"] = {["fields"] = {}, ["inventory"] = {}}, ["param2"] = 15, ["y"] = 4, ["param1"] = 238, ["z"] = 1, ["name"] = "rainbow:red_water_flowing"}, {["x"] = 1, ["meta"] = {["fields"] = {}, ["inventory"] = {}}, ["param2"] = 15, ["y"] = 5, ["param1"] = 238, ["z"] = 1, ["name"] = "rainbow:red_water_flowing"}, {["x"] = 1, ["meta"] = {["fields"] = {}, ["inventory"] = {}}, ["param2"] = 20, ["y"] = 6, ["param1"] = 222, ["z"] = 0, ["name"] = "rainbow:slope_clay_black"}, {["x"] = 1, ["meta"] = {["fields"] = {}, ["inventory"] = {}}, ["param2"] = 15, ["y"] = 6, ["param1"] = 238, ["z"] = 1, ["name"] = "rainbow:red_water_flowing"}, {["x"] = 1, ["meta"] = {["fields"] = {}, ["inventory"] = {}}, ["param2"] = 22, ["y"] = 6, ["param1"] = 221, ["z"] = 2, ["name"] = "rainbow:slope_clay_black"}, {["x"] = 1, ["meta"] = {["fields"] = {}, ["inventory"] = {}}, ["y"] = 7, ["z"] = 0, ["name"] = "rainbow:sand_black"}, {["x"] = 1, ["meta"] = {["fields"] = {}, ["inventory"] = {}}, ["y"] = 7, ["param1"] = 238, ["z"] = 1, ["name"] = "rainbow:red_water_source"}, {["x"] = 1, ["meta"] = {["fields"] = {}, ["inventory"] = {}}, ["y"] = 7, ["z"] = 2, ["name"] = "rainbow:sand_black"}, {["x"] = 2, ["meta"] = {["fields"] = {}, ["inventory"] = {}}, ["param2"] = 12, ["y"] = 0, ["param1"] = 190, ["z"] = 0, ["name"] = "rainbow:slope_clay_black"}, {["x"] = 2, ["meta"] = {["fields"] = {}, ["inventory"] = {}}, ["y"] = 0, ["z"] = 1, ["name"] = "rainbow:sand_black"}, {["x"] = 2, ["meta"] = {["fields"] = {}, ["inventory"] = {}}, ["param2"] = 7, ["y"] = 0, ["param1"] = 187, ["z"] = 2, ["name"] = "rainbow:slope_clay_black"}, {["x"] = 2, ["meta"] = {["fields"] = {}, ["inventory"] = {}}, ["param2"] = 3, ["y"] = 1, ["param1"] = 221, ["z"] = 1, ["name"] = "rainbow:slope_clay_black"}, {["x"] = 2, ["meta"] = {["fields"] = {}, ["inventory"] = {}}, ["param2"] = 21, ["y"] = 6, ["param1"] = 221, ["z"] = 1, ["name"] = "rainbow:slope_clay_black"}, {["x"] = 2, ["meta"] = {["fields"] = {}, ["inventory"] = {}}, ["param2"] = 12, ["y"] = 7, ["param1"] = 190, ["z"] = 0, ["name"] = "rainbow:slope_clay_black"}, {["x"] = 2, ["meta"] = {["fields"] = {}, ["inventory"] = {}}, ["y"] = 7, ["z"] = 1, ["name"] = "rainbow:sand_black"}, {["x"] = 2, ["meta"] = {["fields"] = {}, ["inventory"] = {}}, ["param2"] = 7, ["y"] = 7, ["param1"] = 187, ["z"] = 2, ["name"] = "rainbow:slope_clay_black"}}