5:return {{["x"] = 0, ["meta"] = {["fields"] = {}, ["inventory"] = {}}, ["y"] = 0, ["z"] = 0, ["name"] = "cityscape:road"}, {["x"] = 0, ["meta"] = {["fields"] = {}, ["inventory"] = {}}, ["y"] = 0, ["z"] = 1, ["name"] = "cityscape:road"}, {["x"] = 0, ["meta"] = {["fields"] = {}, ["inventory"] = {}}, ["y"] = 0, ["z"] = 2, ["name"] = "cityscape:road"}, {["x"] = 0, ["meta"] = {["fields"] = {}, ["inventory"] = {}}, ["y"] = 0, ["z"] = 3, ["name"] = "cityscape:road"}, {["x"] = 0, ["meta"] = {["fields"] = {}, ["inventory"] = {}}, ["y"] = 0, ["z"] = 4, ["name"] = "cityscape:road"}, {["x"] = 0, ["meta"] = {["fields"] = {}, ["inventory"] = {}}, ["y"] = 0, ["z"] = 5, ["name"] = "cityscape:road"}, {["x"] = 0, ["meta"] = {["fields"] = {}, ["inventory"] = {}}, ["y"] = 0, ["z"] = 6, ["name"] = "cityscape:road"}, {["x"] = 0, ["meta"] = {["fields"] = {}, ["inventory"] = {}}, ["y"] = 0, ["z"] = 7, ["name"] = "cityscape:road"}, {["x"] = 0, ["meta"] = {["fields"] = {}, ["inventory"] = {}}, ["y"] = 0, ["z"] = 8, ["name"] = "cityscape:road"}, {["x"] = 0, ["meta"] = {["fields"] = {}, ["inventory"] = {}}, ["y"] = 0, ["z"] = 9, ["name"] = "cityscape:road"}, {["x"] = 0, ["meta"] = {["fields"] = {}, ["inventory"] = {}}, ["y"] = 0, ["z"] = 10, ["name"] = "cityscape:road"}, {["x"] = 0, ["meta"] = {["fields"] = {}, ["inventory"] = {}}, ["y"] = 0, ["z"] = 11, ["name"] = "cityscape:road"}, {["x"] = 0, ["meta"] = {["fields"] = {}, ["inventory"] = {}}, ["y"] = 0, ["z"] = 12, ["name"] = "cityscape:road"}, {["x"] = 0, ["meta"] = {["fields"] = {}, ["inventory"] = {}}, ["y"] = 0, ["z"] = 13, ["name"] = "cityscape:road"}, {["x"] = 0, ["meta"] = {["fields"] = {}, ["inventory"] = {}}, ["y"] = 0, ["z"] = 14, ["name"] = "cityscape:road"}, {["x"] = 0, ["meta"] = {["fields"] = {}, ["inventory"] = {}}, ["y"] = 0, ["z"] = 15, ["name"] = "cityscape:road"}, {["x"] = 0, ["meta"] = {["fields"] = {}, ["inventory"] = {}}, ["y"] = 0, ["z"] = 16, ["name"] = "cityscape:road"}, {["x"] = 0, ["meta"] = {["fields"] = {}, ["inventory"] = {}}, ["y"] = 0, ["z"] = 17, ["name"] = "cityscape:road"}, {["x"] = 0, ["meta"] = {["fields"] = {}, ["inventory"] = {}}, ["y"] = 0, ["z"] = 18, ["name"] = "cityscape:road"}, {["x"] = 0, ["meta"] = {["fields"] = {}, ["inventory"] = {}}, ["y"] = 0, ["z"] = 19, ["name"] = "cityscape:road"}, {["x"] = 0, ["meta"] = {["fields"] = {}, ["inventory"] = {}}, ["y"] = 0, ["z"] = 20, ["name"] = "cityscape:road"}, {["x"] = 0, ["meta"] = {["fields"] = {}, ["inventory"] = {}}, ["y"] = 0, ["z"] = 21, ["name"] = "cityscape:road"}, {["x"] = 0, ["meta"] = {["fields"] = {}, ["inventory"] = {}}, ["y"] = 0, ["z"] = 22, ["name"] = "cityscape:road"}, {["x"] = 0, ["meta"] = {["fields"] = {}, ["inventory"] = {}}, ["y"] = 0, ["z"] = 23, ["name"] = "cityscape:road"}, {["x"] = 0, ["meta"] = {["fields"] = {}, ["inventory"] = {}}, ["y"] = 0, ["z"] = 24, ["name"] = "cityscape:road"}, {["x"] = 0, ["meta"] = {["fields"] = {}, ["inventory"] = {}}, ["y"] = 0, ["z"] = 25, ["name"] = "cityscape:road"}, {["x"] = 0, ["meta"] = {["fields"] = {}, ["inventory"] = {}}, ["y"] = 0, ["z"] = 26, ["name"] = "default:stone"}, {["x"] = 0, ["meta"] = {["fields"] = {}, ["inventory"] = {}}, ["y"] = 0, ["z"] = 27, ["name"] = "default:stone"}, {["x"] = 0, ["meta"] = {["fields"] = {}, ["inventory"] = {}}, ["y"] = 0, ["z"] = 28, ["name"] = "default:stone"}, {["x"] = 0, ["meta"] = {["fields"] = {}, ["inventory"] = {}}, ["y"] = 0, ["z"] = 29, ["name"] = "default:stone"}, {["x"] = 0, ["meta"] = {["fields"] = {}, ["inventory"] = {}}, ["y"] = 0, ["z"] = 30, ["name"] = "default:stone"}, {["x"] = 0, ["meta"] = {["fields"] = {}, ["inventory"] = {}}, ["y"] = 1, ["z"] = 26, ["name"] = "default:stone"}, {["x"] = 0, ["meta"] = {["fields"] = {}, ["inventory"] = {}}, ["y"] = 1, ["z"] = 27, ["name"] = "default:stone"}, {["x"] = 0, ["meta"] = {["fields"] = {}, ["inventory"] = {}}, ["y"] = 1, ["z"] = 28, ["name"] = "default:stone"}, {["x"] = 0, ["meta"] = {["fields"] = {}, ["inventory"] = {}}, ["y"] = 1, ["z"] = 29, ["name"] = "default:stone"}, {["x"] = 0, ["meta"] = {["fields"] = {}, ["inventory"] = {}}, ["y"] = 1, ["z"] = 30, ["name"] = "default:stone"}, {["x"] = 0, ["meta"] = {["fields"] = {}, ["inventory"] = {}}, ["y"] = 2, ["z"] = 26, ["name"] = "default:stone"}, {["x"] = 0, ["meta"] = {["fields"] = {}, ["inventory"] = {}}, ["y"] = 2, ["z"] = 27, ["name"] = "default:stone"}, {["x"] = 0, ["meta"] = {["fields"] = {}, ["inventory"] = {}}, ["y"] = 2, ["z"] = 28, ["name"] = "default:stone"}, {["x"] = 0, ["meta"] = {["fields"] = {}, ["inventory"] = {}}, ["y"] = 2, ["z"] = 29, ["name"] = "default:stone"}, {["x"] = 0, ["meta"] = {["fields"] = {}, ["inventory"] = {}}, ["y"] = 2, ["z"] = 30, ["name"] = "default:stone"}, {["x"] = 0, ["meta"] = {["fields"] = {}, ["inventory"] = {}}, ["y"] = 3, ["z"] = 26, ["name"] = "default:stone"}, {["x"] = 0, ["meta"] = {["fields"] = {}, ["inventory"] = {}}, ["y"] = 3, ["z"] = 27, ["name"] = "default:stone"}, {["x"] = 0, ["meta"] = {["fields"] = {}, ["inventory"] = {}}, ["y"] = 3, ["z"] = 28, ["name"] = "default:stone"}, {["x"] = 0, ["meta"] = {["fields"] = {}, ["inventory"] = {}}, ["y"] = 3, ["z"] = 29, ["name"] = "default:stone"}, {["x"] = 0, ["meta"] = {["fields"] = {}, ["inventory"] = {}}, ["y"] = 3, ["z"] = 30, ["name"] = "default:stone"}, {["x"] = 0, ["meta"] = {["fields"] = {}, ["inventory"] = {}}, ["y"] = 4, ["z"] = 26, ["name"] = "default:stone"}, {["x"] = 0, ["meta"] = {["fields"] = {}, ["inventory"] = {}}, ["y"] = 4, ["z"] = 27, ["name"] = "default:stone"}, {["x"] = 0, ["meta"] = {["fields"] = {}, ["inventory"] = {}}, ["y"] = 4, ["z"] = 28, ["name"] = "default:stone"}, {["x"] = 0, ["meta"] = {["fields"] = {}, ["inventory"] = {}}, ["y"] = 4, ["z"] = 29, ["name"] = "default:stone"}, {["x"] = 0, ["meta"] = {["fields"] = {}, ["inventory"] = {}}, ["y"] = 4, ["z"] = 30, ["name"] = "default:stone"}, {["x"] = 0, ["meta"] = {["fields"] = {}, ["inventory"] = {}}, ["y"] = 5, ["z"] = 26, ["name"] = "default:stone"}, {["x"] = 0, ["meta"] = {["fields"] = {}, ["inventory"] = {}}, ["y"] = 5, ["z"] = 27, ["name"] = "default:stone"}, {["x"] = 0, ["meta"] = {["fields"] = {}, ["inventory"] = {}}, ["y"] = 5, ["z"] = 28, ["name"] = "default:stone"}, {["x"] = 0, ["meta"] = {["fields"] = {}, ["inventory"] = {}}, ["y"] = 5, ["z"] = 29, ["name"] = "default:stone"}, {["x"] = 0, ["meta"] = {["fields"] = {}, ["inventory"] = {}}, ["y"] = 5, ["z"] = 30, ["name"] = "default:stone"}, {["x"] = 0, ["meta"] = {["fields"] = {}, ["inventory"] = {}}, ["param2"] = 3, ["y"] = 6, ["param1"] = 11, ["z"] = 26, ["name"] = "stairs:stair_road"}, {["x"] = 0, ["meta"] = {["fields"] = {}, ["inventory"] = {}}, ["param2"] = 3, ["y"] = 6, ["param1"] = 11, ["z"] = 27, ["name"] = "stairs:stair_road"}, {["x"] = 0, ["meta"] = {["fields"] = {}, ["inventory"] = {}}, ["param2"] = 3, ["y"] = 6, ["param1"] = 27, ["z"] = 28, ["name"] = "stairs:stair_road"}, {["x"] = 0, ["meta"] = {["fields"] = {}, ["inventory"] = {}}, ["param2"] = 3, ["y"] = 6, ["param1"] = 43, ["z"] = 29, ["name"] = "stairs:stair_road"}, {["x"] = 0, ["meta"] = {["fields"] = {}, ["inventory"] = {}}, ["param2"] = 3, ["y"] = 6, ["param1"] = 59, ["z"] = 30, ["name"] = "stairs:stair_road"}, {["x"] = 1, ["meta"] = {["fields"] = {}, ["inventory"] = {}}, ["y"] = 0, ["z"] = 0, ["name"] = "cityscape:road"}, {["x"] = 1, ["meta"] = {["fields"] = {}, ["inventory"] = {}}, ["y"] = 0, ["z"] = 1, ["name"] = "cityscape:road"}, {["x"] = 1, ["meta"] = {["fields"] = {}, ["inventory"] = {}}, ["y"] = 0, ["z"] = 2, ["name"] = "cityscape:road"}, {["x"] = 1, ["meta"] = {["fields"] = {}, ["inventory"] = {}}, ["y"] = 0, ["z"] = 3, ["name"] = "cityscape:road"}, {["x"] = 1, ["meta"] = {["fields"] = {}, ["inventory"] = {}}, ["y"] = 0, ["z"] = 4, ["name"] = "cityscape:road"}, {["x"] = 1, ["meta"] = {["fields"] = {}, ["inventory"] = {}}, ["y"] = 0, ["z"] = 5, ["name"] = "cityscape:road"}, {["x"] = 1, ["meta"] = {["fields"] = {}, ["inventory"] = {}}, ["y"] = 0, ["z"] = 6, ["name"] = "cityscape:road"}, {["x"] = 1, ["meta"] = {["fields"] = {}, ["inventory"] = {}}, ["y"] = 0, ["z"] = 7, ["name"] = "cityscape:road"}, {["x"] = 1, ["meta"] = {["fields"] = {}, ["inventory"] = {}}, ["y"] = 0, ["z"] = 8, ["name"] = "cityscape:road"}, {["x"] = 1, ["meta"] = {["fields"] = {}, ["inventory"] = {}}, ["y"] = 0, ["z"] = 9, ["name"] = "cityscape:road"}, {["x"] = 1, ["meta"] = {["fields"] = {}, ["inventory"] = {}}, ["y"] = 0, ["z"] = 10, ["name"] = "cityscape:road"}, {["x"] = 1, ["meta"] = {["fields"] = {}, ["inventory"] = {}}, ["y"] = 0, ["z"] = 11, ["name"] = "cityscape:road"}, {["x"] = 1, ["meta"] = {["fields"] = {}, ["inventory"] = {}}, ["y"] = 0, ["z"] = 12, ["name"] = "cityscape:road"}, {["x"] = 1, ["meta"] = {["fields"] = {}, ["inventory"] = {}}, ["y"] = 0, ["z"] = 13, ["name"] = "cityscape:road"}, {["x"] = 1, ["meta"] = {["fields"] = {}, ["inventory"] = {}}, ["y"] = 0, ["z"] = 14, ["name"] = "cityscape:road"}, {["x"] = 1, ["meta"] = {["fields"] = {}, ["inventory"] = {}}, ["y"] = 0, ["z"] = 15, ["name"] = "cityscape:road"}, {["x"] = 1, ["meta"] = {["fields"] = {}, ["inventory"] = {}}, ["y"] = 0, ["z"] = 16, ["name"] = "cityscape:road"}, {["x"] = 1, ["meta"] = {["fields"] = {}, ["inventory"] = {}}, ["y"] = 0, ["z"] = 17, ["name"] = "cityscape:road"}, {["x"] = 1, ["meta"] = {["fields"] = {}, ["inventory"] = {}}, ["y"] = 0, ["z"] = 18, ["name"] = "cityscape:road"}, {["x"] = 1, ["meta"] = {["fields"] = {}, ["inventory"] = {}}, ["y"] = 0, ["z"] = 19, ["name"] = "cityscape:road"}, {["x"] = 1, ["meta"] = {["fields"] = {}, ["inventory"] = {}}, ["y"] = 0, ["z"] = 20, ["name"] = "cityscape:road"}, {["x"] = 1, ["meta"] = {["fields"] = {}, ["inventory"] = {}}, ["y"] = 0, ["z"] = 21, ["name"] = "cityscape:road"}, {["x"] = 1, ["meta"] = {["fields"] = {}, ["inventory"] = {}}, ["y"] = 0, ["z"] = 22, ["name"] = "cityscape:road"}, {["x"] = 1, ["meta"] = {["fields"] = {}, ["inventory"] = {}}, ["y"] = 0, ["z"] = 23, ["name"] = "cityscape:road"}, {["x"] = 1, ["meta"] = {["fields"] = {}, ["inventory"] = {}}, ["y"] = 0, ["z"] = 24, ["name"] = "cityscape:road"}, {["x"] = 1, ["meta"] = {["fields"] = {}, ["inventory"] = {}}, ["y"] = 0, ["z"] = 25, ["name"] = "cityscape:road"}, {["x"] = 1, ["meta"] = {["fields"] = {}, ["inventory"] = {}}, ["y"] = 0, ["z"] = 26, ["name"] = "default:stone"}, {["x"] = 1, ["meta"] = {["fields"] = {}, ["inventory"] = {}}, ["y"] = 0, ["z"] = 27, ["name"] = "default:stone"}, {["x"] = 1, ["meta"] = {["fields"] = {}, ["inventory"] = {}}, ["y"] = 0, ["z"] = 28, ["name"] = "default:stone"}, {["x"] = 1, ["meta"] = {["fields"] = {}, ["inventory"] = {}}, ["y"] = 0, ["z"] = 29, ["name"] = "default:stone"}, {["x"] = 1, ["meta"] = {["fields"] = {}, ["inventory"] = {}}, ["y"] = 0, ["z"] = 30, ["name"] = "default:stone"}, {["x"] = 1, ["meta"] = {["fields"] = {}, ["inventory"] = {}}, ["y"] = 1, ["z"] = 26, ["name"] = "default:stone"}, {["x"] = 1, ["meta"] = {["fields"] = {}, ["inventory"] = {}}, ["y"] = 1, ["z"] = 27, ["name"] = "default:stone"}, {["x"] = 1, ["meta"] = {["fields"] = {}, ["inventory"] = {}}, ["y"] = 1, ["z"] = 28, ["name"] = "default:stone"}, {["x"] = 1, ["meta"] = {["fields"] = {}, ["inventory"] = {}}, ["y"] = 1, ["z"] = 29, ["name"] = "default:stone"}, {["x"] = 1, ["meta"] = {["fields"] = {}, ["inventory"] = {}}, ["y"] = 1, ["z"] = 30, ["name"] = "default:stone"}, {["x"] = 1, ["meta"] = {["fields"] = {}, ["inventory"] = {}}, ["y"] = 2, ["z"] = 26, ["name"] = "default:stone"}, {["x"] = 1, ["meta"] = {["fields"] = {}, ["inventory"] = {}}, ["y"] = 2, ["z"] = 27, ["name"] = "default:stone"}, {["x"] = 1, ["meta"] = {["fields"] = {}, ["inventory"] = {}}, ["y"] = 2, ["z"] = 28, ["name"] = "default:stone"}, {["x"] = 1, ["meta"] = {["fields"] = {}, ["inventory"] = {}}, ["y"] = 2, ["z"] = 29, ["name"] = "default:stone"}, {["x"] = 1, ["meta"] = {["fields"] = {}, ["inventory"] = {}}, ["y"] = 2, ["z"] = 30, ["name"] = "default:stone"}, {["x"] = 1, ["meta"] = {["fields"] = {}, ["inventory"] = {}}, ["y"] = 3, ["z"] = 26, ["name"] = "default:stone"}, {["x"] = 1, ["meta"] = {["fields"] = {}, ["inventory"] = {}}, ["y"] = 3, ["z"] = 27, ["name"] = "default:stone"}, {["x"] = 1, ["meta"] = {["fields"] = {}, ["inventory"] = {}}, ["y"] = 3, ["z"] = 28, ["name"] = "default:stone"}, {["x"] = 1, ["meta"] = {["fields"] = {}, ["inventory"] = {}}, ["y"] = 3, ["z"] = 29, ["name"] = "default:stone"}, {["x"] = 1, ["meta"] = {["fields"] = {}, ["inventory"] = {}}, ["y"] = 3, ["z"] = 30, ["name"] = "default:stone"}, {["x"] = 1, ["meta"] = {["fields"] = {}, ["inventory"] = {}}, ["y"] = 4, ["z"] = 26, ["name"] = "default:stone"}, {["x"] = 1, ["meta"] = {["fields"] = {}, ["inventory"] = {}}, ["y"] = 4, ["z"] = 27, ["name"] = "default:stone"}, {["x"] = 1, ["meta"] = {["fields"] = {}, ["inventory"] = {}}, ["y"] = 4, ["z"] = 28, ["name"] = "default:stone"}, {["x"] = 1, ["meta"] = {["fields"] = {}, ["inventory"] = {}}, ["y"] = 4, ["z"] = 29, ["name"] = "default:stone"}, {["x"] = 1, ["meta"] = {["fields"] = {}, ["inventory"] = {}}, ["y"] = 4, ["z"] = 30, ["name"] = "default:stone"}, {["x"] = 1, ["meta"] = {["fields"] = {}, ["inventory"] = {}}, ["param2"] = 3, ["y"] = 5, ["param1"] = 27, ["z"] = 26, ["name"] = "stairs:stair_road"}, {["x"] = 1, ["meta"] = {["fields"] = {}, ["inventory"] = {}}, ["param2"] = 3, ["y"] = 5, ["param1"] = 43, ["z"] = 27, ["name"] = "stairs:stair_road"}, {["x"] = 1, ["meta"] = {["fields"] = {}, ["inventory"] = {}}, ["param2"] = 3, ["y"] = 5, ["param1"] = 59, ["z"] = 28, ["name"] = "stairs:stair_road"}, {["x"] = 1, ["meta"] = {["fields"] = {}, ["inventory"] = {}}, ["param2"] = 3, ["y"] = 5, ["param1"] = 75, ["z"] = 29, ["name"] = "stairs:stair_road"}, {["x"] = 1, ["meta"] = {["fields"] = {}, ["inventory"] = {}}, ["param2"] = 3, ["y"] = 5, ["param1"] = 91, ["z"] = 30, ["name"] = "stairs:stair_road"}, {["x"] = 2, ["meta"] = {["fields"] = {}, ["inventory"] = {}}, ["y"] = 0, ["z"] = 0, ["name"] = "cityscape:road"}, {["x"] = 2, ["meta"] = {["fields"] = {}, ["inventory"] = {}}, ["y"] = 0, ["z"] = 1, ["name"] = "cityscape:road"}, {["x"] = 2, ["meta"] = {["fields"] = {}, ["inventory"] = {}}, ["y"] = 0, ["z"] = 2, ["name"] = "cityscape:road"}, {["x"] = 2, ["meta"] = {["fields"] = {}, ["inventory"] = {}}, ["y"] = 0, ["z"] = 3, ["name"] = "cityscape:road"}, {["x"] = 2, ["meta"] = {["fields"] = {}, ["inventory"] = {}}, ["y"] = 0, ["z"] = 4, ["name"] = "cityscape:road"}, {["x"] = 2, ["meta"] = {["fields"] = {}, ["inventory"] = {}}, ["y"] = 0, ["z"] = 5, ["name"] = "cityscape:road"}, {["x"] = 2, ["meta"] = {["fields"] = {}, ["inventory"] = {}}, ["y"] = 0, ["z"] = 6, ["name"] = "cityscape:road_yellow_line"}, {["x"] = 2, ["meta"] = {["fields"] = {}, ["inventory"] = {}}, ["y"] = 0, ["z"] = 7, ["name"] = "cityscape:road"}, {["x"] = 2, ["meta"] = {["fields"] = {}, ["inventory"] = {}}, ["y"] = 0, ["z"] = 8, ["name"] = "cityscape:road_yellow_line"}, {["x"] = 2, ["meta"] = {["fields"] = {}, ["inventory"] = {}}, ["y"] = 0, ["z"] = 9, ["name"] = "cityscape:road"}, {["x"] = 2, ["meta"] = {["fields"] = {}, ["inventory"] = {}}, ["y"] = 0, ["z"] = 10, ["name"] = "cityscape:road_yellow_line"}, {["x"] = 2, ["meta"] = {["fields"] = {}, ["inventory"] = {}}, ["y"] = 0, ["z"] = 11, ["name"] = "cityscape:road"}, {["x"] = 2, ["meta"] = {["fields"] = {}, ["inventory"] = {}}, ["y"] = 0, ["z"] = 12, ["name"] = "cityscape:road_yellow_line"}, {["x"] = 2, ["meta"] = {["fields"] = {}, ["inventory"] = {}}, ["y"] = 0, ["z"] = 13, ["name"] = "cityscape:road"}, {["x"] = 2, ["meta"] = {["fields"] = {}, ["inventory"] = {}}, ["y"] = 0, ["z"] = 14, ["name"] = "cityscape:road_yellow_line"}, {["x"] = 2, ["meta"] = {["fields"] = {}, ["inventory"] = {}}, ["y"] = 0, ["z"] = 15, ["name"] = "cityscape:road"}, {["x"] = 2, ["meta"] = {["fields"] = {}, ["inventory"] = {}}, ["y"] = 0, ["z"] = 16, ["name"] = "cityscape:road_yellow_line"}, {["x"] = 2, ["meta"] = {["fields"] = {}, ["inventory"] = {}}, ["y"] = 0, ["z"] = 17, ["name"] = "cityscape:road"}, {["x"] = 2, ["meta"] = {["fields"] = {}, ["inventory"] = {}}, ["y"] = 0, ["z"] = 18, ["name"] = "cityscape:road_yellow_line"}, {["x"] = 2, ["meta"] = {["fields"] = {}, ["inventory"] = {}}, ["y"] = 0, ["z"] = 19, ["name"] = "cityscape:road"}, {["x"] = 2, ["meta"] = {["fields"] = {}, ["inventory"] = {}}, ["y"] = 0, ["z"] = 20, ["name"] = "cityscape:road_yellow_line"}, {["x"] = 2, ["meta"] = {["fields"] = {}, ["inventory"] = {}}, ["y"] = 0, ["z"] = 21, ["name"] = "cityscape:road"}, {["x"] = 2, ["meta"] = {["fields"] = {}, ["inventory"] = {}}, ["y"] = 0, ["z"] = 22, ["name"] = "cityscape:road_yellow_line"}, {["x"] = 2, ["meta"] = {["fields"] = {}, ["inventory"] = {}}, ["y"] = 0, ["z"] = 23, ["name"] = "cityscape:road"}, {["x"] = 2, ["meta"] = {["fields"] = {}, ["inventory"] = {}}, ["y"] = 0, ["z"] = 24, ["name"] = "cityscape:road_yellow_line"}, {["x"] = 2, ["meta"] = {["fields"] = {}, ["inventory"] = {}}, ["y"] = 0, ["z"] = 25, ["name"] = "cityscape:road"}, {["x"] = 2, ["meta"] = {["fields"] = {}, ["inventory"] = {}}, ["y"] = 0, ["z"] = 26, ["name"] = "default:stone"}, {["x"] = 2, ["meta"] = {["fields"] = {}, ["inventory"] = {}}, ["y"] = 0, ["z"] = 27, ["name"] = "default:stone"}, {["x"] = 2, ["meta"] = {["fields"] = {}, ["inventory"] = {}}, ["y"] = 0, ["z"] = 28, ["name"] = "default:stone"}, {["x"] = 2, ["meta"] = {["fields"] = {}, ["inventory"] = {}}, ["y"] = 0, ["z"] = 29, ["name"] = "default:stone"}, {["x"] = 2, ["meta"] = {["fields"] = {}, ["inventory"] = {}}, ["y"] = 0, ["z"] = 30, ["name"] = "default:stone"}, {["x"] = 2, ["meta"] = {["fields"] = {}, ["inventory"] = {}}, ["y"] = 1, ["z"] = 26, ["name"] = "default:stone"}, {["x"] = 2, ["meta"] = {["fields"] = {}, ["inventory"] = {}}, ["y"] = 1, ["z"] = 27, ["name"] = "default:stone"}, {["x"] = 2, ["meta"] = {["fields"] = {}, ["inventory"] = {}}, ["y"] = 1, ["z"] = 28, ["name"] = "default:stone"}, {["x"] = 2, ["meta"] = {["fields"] = {}, ["inventory"] = {}}, ["y"] = 1, ["z"] = 29, ["name"] = "default:stone"}, {["x"] = 2, ["meta"] = {["fields"] = {}, ["inventory"] = {}}, ["y"] = 1, ["z"] = 30, ["name"] = "default:stone"}, {["x"] = 2, ["meta"] = {["fields"] = {}, ["inventory"] = {}}, ["y"] = 2, ["z"] = 26, ["name"] = "default:stone"}, {["x"] = 2, ["meta"] = {["fields"] = {}, ["inventory"] = {}}, ["y"] = 2, ["z"] = 27, ["name"] = "default:stone"}, {["x"] = 2, ["meta"] = {["fields"] = {}, ["inventory"] = {}}, ["y"] = 2, ["z"] = 28, ["name"] = "default:stone"}, {["x"] = 2, ["meta"] = {["fields"] = {}, ["inventory"] = {}}, ["y"] = 2, ["z"] = 29, ["name"] = "default:stone"}, {["x"] = 2, ["meta"] = {["fields"] = {}, ["inventory"] = {}}, ["y"] = 2, ["z"] = 30, ["name"] = "default:stone"}, {["x"] = 2, ["meta"] = {["fields"] = {}, ["inventory"] = {}}, ["y"] = 3, ["z"] = 26, ["name"] = "default:stone"}, {["x"] = 2, ["meta"] = {["fields"] = {}, ["inventory"] = {}}, ["y"] = 3, ["z"] = 27, ["name"] = "default:stone"}, {["x"] = 2, ["meta"] = {["fields"] = {}, ["inventory"] = {}}, ["y"] = 3, ["z"] = 28, ["name"] = "default:stone"}, {["x"] = 2, ["meta"] = {["fields"] = {}, ["inventory"] = {}}, ["y"] = 3, ["z"] = 29, ["name"] = "default:stone"}, {["x"] = 2, ["meta"] = {["fields"] = {}, ["inventory"] = {}}, ["y"] = 3, ["z"] = 30, ["name"] = "default:stone"}, {["x"] = 2, ["meta"] = {["fields"] = {}, ["inventory"] = {}}, ["param2"] = 3, ["y"] = 4, ["param1"] = 60, ["z"] = 26, ["name"] = "stairs:stair_road"}, {["x"] = 2, ["meta"] = {["fields"] = {}, ["inventory"] = {}}, ["param2"] = 3, ["y"] = 4, ["param1"] = 76, ["z"] = 27, ["name"] = "stairs:stair_road"}, {["x"] = 2, ["meta"] = {["fields"] = {}, ["inventory"] = {}}, ["param2"] = 3, ["y"] = 4, ["param1"] = 92, ["z"] = 28, ["name"] = "stairs:stair_road"}, {["x"] = 2, ["meta"] = {["fields"] = {}, ["inventory"] = {}}, ["param2"] = 3, ["y"] = 4, ["param1"] = 108, ["z"] = 29, ["name"] = "stairs:stair_road"}, {["x"] = 2, ["meta"] = {["fields"] = {}, ["inventory"] = {}}, ["param2"] = 3, ["y"] = 4, ["param1"] = 124, ["z"] = 30, ["name"] = "stairs:stair_road"}, {["x"] = 3, ["meta"] = {["fields"] = {}, ["inventory"] = {}}, ["y"] = 0, ["z"] = 0, ["name"] = "cityscape:road"}, {["x"] = 3, ["meta"] = {["fields"] = {}, ["inventory"] = {}}, ["y"] = 0, ["z"] = 1, ["name"] = "cityscape:road"}, {["x"] = 3, ["meta"] = {["fields"] = {}, ["inventory"] = {}}, ["y"] = 0, ["z"] = 2, ["name"] = "cityscape:road"}, {["x"] = 3, ["meta"] = {["fields"] = {}, ["inventory"] = {}}, ["y"] = 0, ["z"] = 3, ["name"] = "cityscape:road"}, {["x"] = 3, ["meta"] = {["fields"] = {}, ["inventory"] = {}}, ["y"] = 0, ["z"] = 4, ["name"] = "cityscape:road"}, {["x"] = 3, ["meta"] = {["fields"] = {}, ["inventory"] = {}}, ["y"] = 0, ["z"] = 5, ["name"] = "cityscape:road"}, {["x"] = 3, ["meta"] = {["fields"] = {}, ["inventory"] = {}}, ["y"] = 0, ["z"] = 6, ["name"] = "cityscape:road"}, {["x"] = 3, ["meta"] = {["fields"] = {}, ["inventory"] = {}}, ["y"] = 0, ["z"] = 7, ["name"] = "cityscape:road"}, {["x"] = 3, ["meta"] = {["fields"] = {}, ["inventory"] = {}}, ["y"] = 0, ["z"] = 8, ["name"] = "cityscape:road"}, {["x"] = 3, ["meta"] = {["fields"] = {}, ["inventory"] = {}}, ["y"] = 0, ["z"] = 9, ["name"] = "cityscape:road"}, {["x"] = 3, ["meta"] = {["fields"] = {}, ["inventory"] = {}}, ["y"] = 0, ["z"] = 10, ["name"] = "cityscape:road"}, {["x"] = 3, ["meta"] = {["fields"] = {}, ["inventory"] = {}}, ["y"] = 0, ["z"] = 11, ["name"] = "cityscape:road"}, {["x"] = 3, ["meta"] = {["fields"] = {}, ["inventory"] = {}}, ["y"] = 0, ["z"] = 12, ["name"] = "cityscape:road"}, {["x"] = 3, ["meta"] = {["fields"] = {}, ["inventory"] = {}}, ["y"] = 0, ["z"] = 13, ["name"] = "cityscape:road"}, {["x"] = 3, ["meta"] = {["fields"] = {}, ["inventory"] = {}}, ["y"] = 0, ["z"] = 14, ["name"] = "cityscape:road"}, {["x"] = 3, ["meta"] = {["fields"] = {}, ["inventory"] = {}}, ["y"] = 0, ["z"] = 15, ["name"] = "cityscape:road"}, {["x"] = 3, ["meta"] = {["fields"] = {}, ["inventory"] = {}}, ["y"] = 0, ["z"] = 16, ["name"] = "cityscape:road"}, {["x"] = 3, ["meta"] = {["fields"] = {}, ["inventory"] = {}}, ["y"] = 0, ["z"] = 17, ["name"] = "cityscape:road"}, {["x"] = 3, ["meta"] = {["fields"] = {}, ["inventory"] = {}}, ["y"] = 0, ["z"] = 18, ["name"] = "cityscape:road"}, {["x"] = 3, ["meta"] = {["fields"] = {}, ["inventory"] = {}}, ["y"] = 0, ["z"] = 19, ["name"] = "cityscape:road"}, {["x"] = 3, ["meta"] = {["fields"] = {}, ["inventory"] = {}}, ["y"] = 0, ["z"] = 20, ["name"] = "cityscape:road"}, {["x"] = 3, ["meta"] = {["fields"] = {}, ["inventory"] = {}}, ["y"] = 0, ["z"] = 21, ["name"] = "cityscape:road"}, {["x"] = 3, ["meta"] = {["fields"] = {}, ["inventory"] = {}}, ["y"] = 0, ["z"] = 22, ["name"] = "cityscape:road"}, {["x"] = 3, ["meta"] = {["fields"] = {}, ["inventory"] = {}}, ["y"] = 0, ["z"] = 23, ["name"] = "cityscape:road"}, {["x"] = 3, ["meta"] = {["fields"] = {}, ["inventory"] = {}}, ["y"] = 0, ["z"] = 24, ["name"] = "cityscape:road"}, {["x"] = 3, ["meta"] = {["fields"] = {}, ["inventory"] = {}}, ["y"] = 0, ["z"] = 25, ["name"] = "cityscape:road"}, {["x"] = 3, ["meta"] = {["fields"] = {}, ["inventory"] = {}}, ["y"] = 0, ["z"] = 26, ["name"] = "default:stone"}, {["x"] = 3, ["meta"] = {["fields"] = {}, ["inventory"] = {}}, ["y"] = 0, ["z"] = 27, ["name"] = "default:stone"}, {["x"] = 3, ["meta"] = {["fields"] = {}, ["inventory"] = {}}, ["y"] = 0, ["z"] = 28, ["name"] = "default:stone"}, {["x"] = 3, ["meta"] = {["fields"] = {}, ["inventory"] = {}}, ["y"] = 0, ["z"] = 29, ["name"] = "default:stone"}, {["x"] = 3, ["meta"] = {["fields"] = {}, ["inventory"] = {}}, ["y"] = 0, ["z"] = 30, ["name"] = "default:stone"}, {["x"] = 3, ["meta"] = {["fields"] = {}, ["inventory"] = {}}, ["y"] = 1, ["z"] = 26, ["name"] = "default:stone"}, {["x"] = 3, ["meta"] = {["fields"] = {}, ["inventory"] = {}}, ["y"] = 1, ["z"] = 27, ["name"] = "default:stone"}, {["x"] = 3, ["meta"] = {["fields"] = {}, ["inventory"] = {}}, ["y"] = 1, ["z"] = 28, ["name"] = "default:stone"}, {["x"] = 3, ["meta"] = {["fields"] = {}, ["inventory"] = {}}, ["y"] = 1, ["z"] = 29, ["name"] = "default:stone"}, {["x"] = 3, ["meta"] = {["fields"] = {}, ["inventory"] = {}}, ["y"] = 1, ["z"] = 30, ["name"] = "default:stone"}, {["x"] = 3, ["meta"] = {["fields"] = {}, ["inventory"] = {}}, ["y"] = 2, ["z"] = 26, ["name"] = "default:stone"}, {["x"] = 3, ["meta"] = {["fields"] = {}, ["inventory"] = {}}, ["y"] = 2, ["z"] = 27, ["name"] = "default:stone"}, {["x"] = 3, ["meta"] = {["fields"] = {}, ["inventory"] = {}}, ["y"] = 2, ["z"] = 28, ["name"] = "default:stone"}, {["x"] = 3, ["meta"] = {["fields"] = {}, ["inventory"] = {}}, ["y"] = 2, ["z"] = 29, ["name"] = "default:stone"}, {["x"] = 3, ["meta"] = {["fields"] = {}, ["inventory"] = {}}, ["y"] = 2, ["z"] = 30, ["name"] = "default:stone"}, {["x"] = 3, ["meta"] = {["fields"] = {}, ["inventory"] = {}}, ["param2"] = 3, ["y"] = 3, ["param1"] = 93, ["z"] = 26, ["name"] = "stairs:stair_road"}, {["x"] = 3, ["meta"] = {["fields"] = {}, ["inventory"] = {}}, ["param2"] = 3, ["y"] = 3, ["param1"] = 109, ["z"] = 27, ["name"] = "stairs:stair_road"}, {["x"] = 3, ["meta"] = {["fields"] = {}, ["inventory"] = {}}, ["param2"] = 3, ["y"] = 3, ["param1"] = 125, ["z"] = 28, ["name"] = "stairs:stair_road"}, {["x"] = 3, ["meta"] = {["fields"] = {}, ["inventory"] = {}}, ["param2"] = 3, ["y"] = 3, ["param1"] = 141, ["z"] = 29, ["name"] = "stairs:stair_road"}, {["x"] = 3, ["meta"] = {["fields"] = {}, ["inventory"] = {}}, ["param2"] = 3, ["y"] = 3, ["param1"] = 157, ["z"] = 30, ["name"] = "stairs:stair_road"}, {["x"] = 4, ["meta"] = {["fields"] = {}, ["inventory"] = {}}, ["y"] = 0, ["z"] = 0, ["name"] = "cityscape:road"}, {["x"] = 4, ["meta"] = {["fields"] = {}, ["inventory"] = {}}, ["y"] = 0, ["z"] = 1, ["name"] = "cityscape:road"}, {["x"] = 4, ["meta"] = {["fields"] = {}, ["inventory"] = {}}, ["y"] = 0, ["z"] = 2, ["name"] = "cityscape:road"}, {["x"] = 4, ["meta"] = {["fields"] = {}, ["inventory"] = {}}, ["y"] = 0, ["z"] = 3, ["name"] = "cityscape:road"}, {["x"] = 4, ["meta"] = {["fields"] = {}, ["inventory"] = {}}, ["y"] = 0, ["z"] = 4, ["name"] = "cityscape:road"}, {["x"] = 4, ["meta"] = {["fields"] = {}, ["inventory"] = {}}, ["y"] = 0, ["z"] = 5, ["name"] = "cityscape:road"}, {["x"] = 4, ["meta"] = {["fields"] = {}, ["inventory"] = {}}, ["y"] = 0, ["z"] = 6, ["name"] = "cityscape:road"}, {["x"] = 4, ["meta"] = {["fields"] = {}, ["inventory"] = {}}, ["y"] = 0, ["z"] = 7, ["name"] = "cityscape:road"}, {["x"] = 4, ["meta"] = {["fields"] = {}, ["inventory"] = {}}, ["y"] = 0, ["z"] = 8, ["name"] = "cityscape:road"}, {["x"] = 4, ["meta"] = {["fields"] = {}, ["inventory"] = {}}, ["y"] = 0, ["z"] = 9, ["name"] = "cityscape:road"}, {["x"] = 4, ["meta"] = {["fields"] = {}, ["inventory"] = {}}, ["y"] = 0, ["z"] = 10, ["name"] = "cityscape:road"}, {["x"] = 4, ["meta"] = {["fields"] = {}, ["inventory"] = {}}, ["y"] = 0, ["z"] = 11, ["name"] = "cityscape:road"}, {["x"] = 4, ["meta"] = {["fields"] = {}, ["inventory"] = {}}, ["y"] = 0, ["z"] = 12, ["name"] = "cityscape:road"}, {["x"] = 4, ["meta"] = {["fields"] = {}, ["inventory"] = {}}, ["y"] = 0, ["z"] = 13, ["name"] = "cityscape:road"}, {["x"] = 4, ["meta"] = {["fields"] = {}, ["inventory"] = {}}, ["y"] = 0, ["z"] = 14, ["name"] = "cityscape:road"}, {["x"] = 4, ["meta"] = {["fields"] = {}, ["inventory"] = {}}, ["y"] = 0, ["z"] = 15, ["name"] = "cityscape:road"}, {["x"] = 4, ["meta"] = {["fields"] = {}, ["inventory"] = {}}, ["y"] = 0, ["z"] = 16, ["name"] = "cityscape:road"}, {["x"] = 4, ["meta"] = {["fields"] = {}, ["inventory"] = {}}, ["y"] = 0, ["z"] = 17, ["name"] = "cityscape:road"}, {["x"] = 4, ["meta"] = {["fields"] = {}, ["inventory"] = {}}, ["y"] = 0, ["z"] = 18, ["name"] = "cityscape:road"}, {["x"] = 4, ["meta"] = {["fields"] = {}, ["inventory"] = {}}, ["y"] = 0, ["z"] = 19, ["name"] = "cityscape:road"}, {["x"] = 4, ["meta"] = {["fields"] = {}, ["inventory"] = {}}, ["y"] = 0, ["z"] = 20, ["name"] = "cityscape:road"}, {["x"] = 4, ["meta"] = {["fields"] = {}, ["inventory"] = {}}, ["y"] = 0, ["z"] = 21, ["name"] = "cityscape:road"}, {["x"] = 4, ["meta"] = {["fields"] = {}, ["inventory"] = {}}, ["y"] = 0, ["z"] = 22, ["name"] = "cityscape:road"}, {["x"] = 4, ["meta"] = {["fields"] = {}, ["inventory"] = {}}, ["y"] = 0, ["z"] = 23, ["name"] = "cityscape:road"}, {["x"] = 4, ["meta"] = {["fields"] = {}, ["inventory"] = {}}, ["y"] = 0, ["z"] = 24, ["name"] = "cityscape:road"}, {["x"] = 4, ["meta"] = {["fields"] = {}, ["inventory"] = {}}, ["y"] = 0, ["z"] = 25, ["name"] = "cityscape:road"}, {["x"] = 4, ["meta"] = {["fields"] = {}, ["inventory"] = {}}, ["y"] = 0, ["z"] = 26, ["name"] = "default:stone"}, {["x"] = 4, ["meta"] = {["fields"] = {}, ["inventory"] = {}}, ["y"] = 0, ["z"] = 27, ["name"] = "default:stone"}, {["x"] = 4, ["meta"] = {["fields"] = {}, ["inventory"] = {}}, ["y"] = 0, ["z"] = 28, ["name"] = "default:stone"}, {["x"] = 4, ["meta"] = {["fields"] = {}, ["inventory"] = {}}, ["y"] = 0, ["z"] = 29, ["name"] = "default:stone"}, {["x"] = 4, ["meta"] = {["fields"] = {}, ["inventory"] = {}}, ["y"] = 0, ["z"] = 30, ["name"] = "default:stone"}, {["x"] = 4, ["meta"] = {["fields"] = {}, ["inventory"] = {}}, ["y"] = 1, ["z"] = 26, ["name"] = "default:stone"}, {["x"] = 4, ["meta"] = {["fields"] = {}, ["inventory"] = {}}, ["y"] = 1, ["z"] = 27, ["name"] = "default:stone"}, {["x"] = 4, ["meta"] = {["fields"] = {}, ["inventory"] = {}}, ["y"] = 1, ["z"] = 28, ["name"] = "default:stone"}, {["x"] = 4, ["meta"] = {["fields"] = {}, ["inventory"] = {}}, ["y"] = 1, ["z"] = 29, ["name"] = "default:stone"}, {["x"] = 4, ["meta"] = {["fields"] = {}, ["inventory"] = {}}, ["y"] = 1, ["z"] = 30, ["name"] = "default:stone"}, {["x"] = 4, ["meta"] = {["fields"] = {}, ["inventory"] = {}}, ["param2"] = 3, ["y"] = 2, ["param1"] = 126, ["z"] = 26, ["name"] = "stairs:stair_road"}, {["x"] = 4, ["meta"] = {["fields"] = {}, ["inventory"] = {}}, ["param2"] = 3, ["y"] = 2, ["param1"] = 142, ["z"] = 27, ["name"] = "stairs:stair_road"}, {["x"] = 4, ["meta"] = {["fields"] = {}, ["inventory"] = {}}, ["param2"] = 3, ["y"] = 2, ["param1"] = 158, ["z"] = 28, ["name"] = "stairs:stair_road"}, {["x"] = 4, ["meta"] = {["fields"] = {}, ["inventory"] = {}}, ["param2"] = 3, ["y"] = 2, ["param1"] = 174, ["z"] = 29, ["name"] = "stairs:stair_road"}, {["x"] = 4, ["meta"] = {["fields"] = {}, ["inventory"] = {}}, ["param2"] = 3, ["y"] = 2, ["param1"] = 190, ["z"] = 30, ["name"] = "stairs:stair_road"}, {["x"] = 5, ["meta"] = {["fields"] = {}, ["inventory"] = {}}, ["y"] = 0, ["z"] = 0, ["name"] = "cityscape:road"}, {["x"] = 5, ["meta"] = {["fields"] = {}, ["inventory"] = {}}, ["y"] = 0, ["z"] = 1, ["name"] = "cityscape:road"}, {["x"] = 5, ["meta"] = {["fields"] = {}, ["inventory"] = {}}, ["y"] = 0, ["z"] = 2, ["name"] = "cityscape:road"}, {["x"] = 5, ["meta"] = {["fields"] = {}, ["inventory"] = {}}, ["y"] = 0, ["z"] = 3, ["name"] = "cityscape:road"}, {["x"] = 5, ["meta"] = {["fields"] = {}, ["inventory"] = {}}, ["y"] = 0, ["z"] = 4, ["name"] = "cityscape:road"}, {["x"] = 5, ["meta"] = {["fields"] = {}, ["inventory"] = {}}, ["y"] = 0, ["z"] = 5, ["name"] = "cityscape:sidewalk"}, {["x"] = 5, ["meta"] = {["fields"] = {}, ["inventory"] = {}}, ["y"] = 0, ["z"] = 6, ["name"] = "cityscape:sidewalk"}, {["x"] = 5, ["meta"] = {["fields"] = {}, ["inventory"] = {}}, ["y"] = 0, ["z"] = 7, ["name"] = "cityscape:sidewalk"}, {["x"] = 5, ["meta"] = {["fields"] = {}, ["inventory"] = {}}, ["y"] = 0, ["z"] = 8, ["name"] = "cityscape:sidewalk"}, {["x"] = 5, ["meta"] = {["fields"] = {}, ["inventory"] = {}}, ["y"] = 0, ["z"] = 9, ["name"] = "cityscape:sidewalk"}, {["x"] = 5, ["meta"] = {["fields"] = {}, ["inventory"] = {}}, ["y"] = 0, ["z"] = 10, ["name"] = "cityscape:sidewalk"}, {["x"] = 5, ["meta"] = {["fields"] = {}, ["inventory"] = {}}, ["y"] = 0, ["z"] = 11, ["name"] = "cityscape:sidewalk"}, {["x"] = 5, ["meta"] = {["fields"] = {}, ["inventory"] = {}}, ["y"] = 0, ["z"] = 12, ["name"] = "cityscape:sidewalk"}, {["x"] = 5, ["meta"] = {["fields"] = {}, ["inventory"] = {}}, ["y"] = 0, ["z"] = 13, ["name"] = "cityscape:sidewalk"}, {["x"] = 5, ["meta"] = {["fields"] = {}, ["inventory"] = {}}, ["y"] = 0, ["z"] = 14, ["name"] = "cityscape:sidewalk"}, {["x"] = 5, ["meta"] = {["fields"] = {}, ["inventory"] = {}}, ["y"] = 0, ["z"] = 15, ["name"] = "cityscape:sidewalk"}, {["x"] = 5, ["meta"] = {["fields"] = {}, ["inventory"] = {}}, ["y"] = 0, ["z"] = 16, ["name"] = "cityscape:sidewalk"}, {["x"] = 5, ["meta"] = {["fields"] = {}, ["inventory"] = {}}, ["y"] = 0, ["z"] = 17, ["name"] = "cityscape:sidewalk"}, {["x"] = 5, ["meta"] = {["fields"] = {}, ["inventory"] = {}}, ["y"] = 0, ["z"] = 18, ["name"] = "cityscape:sidewalk"}, {["x"] = 5, ["meta"] = {["fields"] = {}, ["inventory"] = {}}, ["y"] = 0, ["z"] = 19, ["name"] = "cityscape:sidewalk"}, {["x"] = 5, ["meta"] = {["fields"] = {}, ["inventory"] = {}}, ["y"] = 0, ["z"] = 20, ["name"] = "cityscape:sidewalk"}, {["x"] = 5, ["meta"] = {["fields"] = {}, ["inventory"] = {}}, ["y"] = 0, ["z"] = 21, ["name"] = "cityscape:sidewalk"}, {["x"] = 5, ["meta"] = {["fields"] = {}, ["inventory"] = {}}, ["y"] = 0, ["z"] = 22, ["name"] = "cityscape:sidewalk"}, {["x"] = 5, ["meta"] = {["fields"] = {}, ["inventory"] = {}}, ["y"] = 0, ["z"] = 23, ["name"] = "cityscape:sidewalk"}, {["x"] = 5, ["meta"] = {["fields"] = {}, ["inventory"] = {}}, ["y"] = 0, ["z"] = 24, ["name"] = "cityscape:sidewalk"}, {["x"] = 5, ["meta"] = {["fields"] = {}, ["inventory"] = {}}, ["y"] = 0, ["z"] = 25, ["name"] = "cityscape:sidewalk"}, {["x"] = 5, ["meta"] = {["fields"] = {}, ["inventory"] = {}}, ["y"] = 0, ["z"] = 26, ["name"] = "default:stone"}, {["x"] = 5, ["meta"] = {["fields"] = {}, ["inventory"] = {}}, ["y"] = 0, ["z"] = 27, ["name"] = "default:stone"}, {["x"] = 5, ["meta"] = {["fields"] = {}, ["inventory"] = {}}, ["y"] = 0, ["z"] = 28, ["name"] = "default:stone"}, {["x"] = 5, ["meta"] = {["fields"] = {}, ["inventory"] = {}}, ["y"] = 0, ["z"] = 29, ["name"] = "default:stone"}, {["x"] = 5, ["meta"] = {["fields"] = {}, ["inventory"] = {}}, ["y"] = 0, ["z"] = 30, ["name"] = "default:stone"}, {["x"] = 5, ["meta"] = {["fields"] = {}, ["inventory"] = {}}, ["y"] = 1, ["param1"] = 238, ["z"] = 5, ["name"] = "cityscape:streetlight"}, {["x"] = 5, ["meta"] = {["fields"] = {}, ["inventory"] = {}}, ["param2"] = 3, ["y"] = 1, ["param1"] = 158, ["z"] = 26, ["name"] = "stairs:stair_road"}, {["x"] = 5, ["meta"] = {["fields"] = {}, ["inventory"] = {}}, ["param2"] = 3, ["y"] = 1, ["param1"] = 174, ["z"] = 27, ["name"] = "stairs:stair_road"}, {["x"] = 5, ["meta"] = {["fields"] = {}, ["inventory"] = {}}, ["param2"] = 3, ["y"] = 1, ["param1"] = 190, ["z"] = 28, ["name"] = "stairs:stair_road"}, {["x"] = 5, ["meta"] = {["fields"] = {}, ["inventory"] = {}}, ["param2"] = 3, ["y"] = 1, ["param1"] = 206, ["z"] = 29, ["name"] = "stairs:stair_road"}, {["x"] = 5, ["meta"] = {["fields"] = {}, ["inventory"] = {}}, ["param2"] = 3, ["y"] = 1, ["param1"] = 222, ["z"] = 30, ["name"] = "stairs:stair_road"}, {["x"] = 6, ["meta"] = {["fields"] = {}, ["inventory"] = {}}, ["y"] = 0, ["z"] = 0, ["name"] = "cityscape:road"}, {["x"] = 6, ["meta"] = {["fields"] = {}, ["inventory"] = {}}, ["y"] = 0, ["z"] = 1, ["name"] = "cityscape:road"}, {["x"] = 6, ["meta"] = {["fields"] = {}, ["inventory"] = {}}, ["param2"] = 21, ["y"] = 0, ["z"] = 2, ["name"] = "cityscape:road_yellow_line"}, {["x"] = 6, ["meta"] = {["fields"] = {}, ["inventory"] = {}}, ["y"] = 0, ["z"] = 3, ["name"] = "cityscape:road"}, {["x"] = 6, ["meta"] = {["fields"] = {}, ["inventory"] = {}}, ["y"] = 0, ["z"] = 4, ["name"] = "cityscape:road"}, {["x"] = 6, ["meta"] = {["fields"] = {}, ["inventory"] = {}}, ["y"] = 0, ["z"] = 5, ["name"] = "cityscape:sidewalk"}, {["x"] = 6, ["meta"] = {["fields"] = {}, ["inventory"] = {}}, ["y"] = 0, ["z"] = 6, ["name"] = "cityscape:sidewalk"}, {["x"] = 6, ["meta"] = {["fields"] = {}, ["inventory"] = {}}, ["y"] = 0, ["z"] = 7, ["name"] = "cityscape:sidewalk"}, {["x"] = 6, ["meta"] = {["fields"] = {}, ["inventory"] = {}}, ["y"] = 0, ["z"] = 8, ["name"] = "cityscape:sidewalk"}, {["x"] = 6, ["meta"] = {["fields"] = {}, ["inventory"] = {}}, ["y"] = 0, ["z"] = 9, ["name"] = "cityscape:sidewalk"}, {["x"] = 6, ["meta"] = {["fields"] = {}, ["inventory"] = {}}, ["y"] = 0, ["z"] = 10, ["name"] = "cityscape:sidewalk"}, {["x"] = 6, ["meta"] = {["fields"] = {}, ["inventory"] = {}}, ["y"] = 0, ["z"] = 11, ["name"] = "cityscape:sidewalk"}, {["x"] = 6, ["meta"] = {["fields"] = {}, ["inventory"] = {}}, ["y"] = 0, ["z"] = 12, ["name"] = "cityscape:sidewalk"}, {["x"] = 6, ["meta"] = {["fields"] = {}, ["inventory"] = {}}, ["y"] = 0, ["z"] = 13, ["name"] = "cityscape:sidewalk"}, {["x"] = 6, ["meta"] = {["fields"] = {}, ["inventory"] = {}}, ["y"] = 0, ["z"] = 14, ["name"] = "cityscape:sidewalk"}, {["x"] = 6, ["meta"] = {["fields"] = {}, ["inventory"] = {}}, ["y"] = 0, ["z"] = 15, ["name"] = "cityscape:sidewalk"}, {["x"] = 6, ["meta"] = {["fields"] = {}, ["inventory"] = {}}, ["y"] = 0, ["z"] = 16, ["name"] = "cityscape:sidewalk"}, {["x"] = 6, ["meta"] = {["fields"] = {}, ["inventory"] = {}}, ["y"] = 0, ["z"] = 17, ["name"] = "cityscape:sidewalk"}, {["x"] = 6, ["meta"] = {["fields"] = {}, ["inventory"] = {}}, ["y"] = 0, ["z"] = 18, ["name"] = "cityscape:sidewalk"}, {["x"] = 6, ["meta"] = {["fields"] = {}, ["inventory"] = {}}, ["y"] = 0, ["z"] = 19, ["name"] = "cityscape:sidewalk"}, {["x"] = 6, ["meta"] = {["fields"] = {}, ["inventory"] = {}}, ["y"] = 0, ["z"] = 20, ["name"] = "cityscape:sidewalk"}, {["x"] = 6, ["meta"] = {["fields"] = {}, ["inventory"] = {}}, ["y"] = 0, ["z"] = 21, ["name"] = "cityscape:sidewalk"}, {["x"] = 6, ["meta"] = {["fields"] = {}, ["inventory"] = {}}, ["y"] = 0, ["z"] = 22, ["name"] = "cityscape:sidewalk"}, {["x"] = 6, ["meta"] = {["fields"] = {}, ["inventory"] = {}}, ["y"] = 0, ["z"] = 23, ["name"] = "cityscape:sidewalk"}, {["x"] = 6, ["meta"] = {["fields"] = {}, ["inventory"] = {}}, ["y"] = 0, ["z"] = 24, ["name"] = "cityscape:sidewalk"}, {["x"] = 6, ["meta"] = {["fields"] = {}, ["inventory"] = {}}, ["y"] = 0, ["z"] = 25, ["name"] = "cityscape:sidewalk"}, {["x"] = 6, ["meta"] = {["fields"] = {}, ["inventory"] = {}}, ["y"] = 0, ["z"] = 26, ["name"] = "cityscape:road"}, {["x"] = 6, ["meta"] = {["fields"] = {}, ["inventory"] = {}}, ["y"] = 0, ["z"] = 27, ["name"] = "cityscape:road"}, {["x"] = 6, ["meta"] = {["fields"] = {}, ["inventory"] = {}}, ["param2"] = 21, ["y"] = 0, ["z"] = 28, ["name"] = "cityscape:road_yellow_line"}, {["x"] = 6, ["meta"] = {["fields"] = {}, ["inventory"] = {}}, ["y"] = 0, ["z"] = 29, ["name"] = "cityscape:road"}, {["x"] = 6, ["meta"] = {["fields"] = {}, ["inventory"] = {}}, ["y"] = 0, ["z"] = 30, ["name"] = "cityscape:road"}, {["x"] = 6, ["meta"] = {["fields"] = {}, ["inventory"] = {}}, ["param2"] = 2, ["y"] = 1, ["param1"] = 159, ["z"] = 9, ["name"] = "trunks:twig_7"}, {["x"] = 6, ["meta"] = {["fields"] = {}, ["inventory"] = {}}, ["param2"] = 2, ["y"] = 1, ["param1"] = 143, ["z"] = 10, ["name"] = "trunks:twig_8"}, {["x"] = 6, ["meta"] = {["fields"] = {}, ["inventory"] = {}}, ["param2"] = 3, ["y"] = 1, ["param1"] = 127, ["z"] = 11, ["name"] = "trunks:twig_7"}, {["x"] = 7, ["meta"] = {["fields"] = {}, ["inventory"] = {}}, ["y"] = 0, ["z"] = 0, ["name"] = "cityscape:road"}, {["x"] = 7, ["meta"] = {["fields"] = {}, ["inventory"] = {}}, ["y"] = 0, ["z"] = 1, ["name"] = "cityscape:road"}, {["x"] = 7, ["meta"] = {["fields"] = {}, ["inventory"] = {}}, ["y"] = 0, ["z"] = 2, ["name"] = "cityscape:road"}, {["x"] = 7, ["meta"] = {["fields"] = {}, ["inventory"] = {}}, ["y"] = 0, ["z"] = 3, ["name"] = "cityscape:road"}, {["x"] = 7, ["meta"] = {["fields"] = {}, ["inventory"] = {}}, ["y"] = 0, ["z"] = 4, ["name"] = "cityscape:road"}, {["x"] = 7, ["meta"] = {["fields"] = {}, ["inventory"] = {}}, ["y"] = 0, ["z"] = 5, ["name"] = "cityscape:sidewalk"}, {["x"] = 7, ["meta"] = {["fields"] = {}, ["inventory"] = {}}, ["y"] = 0, ["z"] = 6, ["name"] = "cityscape:sidewalk"}, {["x"] = 7, ["meta"] = {["fields"] = {}, ["inventory"] = {}}, ["y"] = 0, ["z"] = 7, ["name"] = "default:dirt_with_grass"}, {["x"] = 7, ["meta"] = {["fields"] = {}, ["inventory"] = {}}, ["y"] = 0, ["z"] = 8, ["name"] = "default:dirt_with_grass"}, {["x"] = 7, ["meta"] = {["fields"] = {}, ["inventory"] = {}}, ["y"] = 0, ["z"] = 9, ["name"] = "default:dirt_with_grass"}, {["x"] = 7, ["meta"] = {["fields"] = {}, ["inventory"] = {}}, ["y"] = 0, ["z"] = 10, ["name"] = "default:dirt_with_grass"}, {["x"] = 7, ["meta"] = {["fields"] = {}, ["inventory"] = {}}, ["y"] = 0, ["z"] = 11, ["name"] = "woodsoils:grass_with_leaves_1"}, {["x"] = 7, ["meta"] = {["fields"] = {}, ["inventory"] = {}}, ["y"] = 0, ["z"] = 12, ["name"] = "woodsoils:grass_with_leaves_2"}, {["x"] = 7, ["meta"] = {["fields"] = {}, ["inventory"] = {}}, ["y"] = 0, ["z"] = 13, ["name"] = "woodsoils:dirt_with_leaves_1"}, {["x"] = 7, ["meta"] = {["fields"] = {}, ["inventory"] = {}}, ["y"] = 0, ["z"] = 14, ["name"] = "woodsoils:dirt_with_leaves_1"}, {["x"] = 7, ["meta"] = {["fields"] = {}, ["inventory"] = {}}, ["y"] = 0, ["z"] = 15, ["name"] = "woodsoils:dirt_with_leaves_1"}, {["x"] = 7, ["meta"] = {["fields"] = {}, ["inventory"] = {}}, ["y"] = 0, ["z"] = 16, ["name"] = "woodsoils:grass_with_leaves_2"}, {["x"] = 7, ["meta"] = {["fields"] = {}, ["inventory"] = {}}, ["y"] = 0, ["z"] = 17, ["name"] = "woodsoils:grass_with_leaves_1"}, {["x"] = 7, ["meta"] = {["fields"] = {}, ["inventory"] = {}}, ["y"] = 0, ["z"] = 18, ["name"] = "default:dirt_with_grass"}, {["x"] = 7, ["meta"] = {["fields"] = {}, ["inventory"] = {}}, ["y"] = 0, ["z"] = 19, ["name"] = "default:dirt_with_grass"}, {["x"] = 7, ["meta"] = {["fields"] = {}, ["inventory"] = {}}, ["y"] = 0, ["z"] = 20, ["name"] = "default:dirt_with_grass"}, {["x"] = 7, ["meta"] = {["fields"] = {}, ["inventory"] = {}}, ["y"] = 0, ["z"] = 21, ["name"] = "default:dirt_with_grass"}, {["x"] = 7, ["meta"] = {["fields"] = {}, ["inventory"] = {}}, ["y"] = 0, ["z"] = 22, ["name"] = "default:dirt_with_grass"}, {["x"] = 7, ["meta"] = {["fields"] = {}, ["inventory"] = {}}, ["y"] = 0, ["z"] = 23, ["name"] = "default:dirt_with_grass"}, {["x"] = 7, ["meta"] = {["fields"] = {}, ["inventory"] = {}}, ["y"] = 0, ["z"] = 24, ["name"] = "cityscape:sidewalk"}, {["x"] = 7, ["meta"] = {["fields"] = {}, ["inventory"] = {}}, ["y"] = 0, ["z"] = 25, ["name"] = "cityscape:sidewalk"}, {["x"] = 7, ["meta"] = {["fields"] = {}, ["inventory"] = {}}, ["y"] = 0, ["z"] = 26, ["name"] = "cityscape:road"}, {["x"] = 7, ["meta"] = {["fields"] = {}, ["inventory"] = {}}, ["y"] = 0, ["z"] = 27, ["name"] = "cityscape:road"}, {["x"] = 7, ["meta"] = {["fields"] = {}, ["inventory"] = {}}, ["y"] = 0, ["z"] = 28, ["name"] = "cityscape:road"}, {["x"] = 7, ["meta"] = {["fields"] = {}, ["inventory"] = {}}, ["y"] = 0, ["z"] = 29, ["name"] = "cityscape:road"}, {["x"] = 7, ["meta"] = {["fields"] = {}, ["inventory"] = {}}, ["y"] = 0, ["z"] = 30, ["name"] = "cityscape:road"}, {["x"] = 7, ["meta"] = {["fields"] = {}, ["inventory"] = {}}, ["y"] = 1, ["param1"] = 175, ["z"] = 7, ["name"] = "default:grass_4"}, {["x"] = 7, ["meta"] = {["fields"] = {}, ["inventory"] = {}}, ["y"] = 1, ["param1"] = 143, ["z"] = 9, ["name"] = "default:grass_2"}, {["x"] = 7, ["meta"] = {["fields"] = {}, ["inventory"] = {}}, ["param2"] = 3, ["y"] = 1, ["param1"] = 127, ["z"] = 10, ["name"] = "trunks:twig_5"}, {["x"] = 7, ["meta"] = {["fields"] = {}, ["inventory"] = {}}, ["param2"] = 3, ["y"] = 1, ["param1"] = 111, ["z"] = 11, ["name"] = "trunks:twig_8"}, {["x"] = 7, ["meta"] = {["fields"] = {}, ["inventory"] = {}}, ["y"] = 1, ["param1"] = 47, ["z"] = 21, ["name"] = "default:grass_3"}, {["x"] = 7, ["meta"] = {["fields"] = {}, ["inventory"] = {}}, ["y"] = 1, ["param1"] = 79, ["z"] = 23, ["name"] = "default:grass_2"}, {["x"] = 7, ["meta"] = {["fields"] = {["blossom_time"] = "22471752"}, ["inventory"] = {}}, ["y"] = 4, ["param1"] = 14, ["z"] = 14, ["name"] = "nature:blossom"}, {["x"] = 7, ["meta"] = {["fields"] = {}, ["inventory"] = {}}, ["y"] = 4, ["param1"] = 14, ["z"] = 15, ["name"] = "default:leaves"}, {["x"] = 7, ["meta"] = {["fields"] = {}, ["inventory"] = {}}, ["y"] = 4, ["param1"] = 14, ["z"] = 18, ["name"] = "default:leaves"}, {["x"] = 7, ["meta"] = {["fields"] = {}, ["inventory"] = {}}, ["y"] = 4, ["param1"] = 14, ["z"] = 20, ["name"] = "default:leaves"}, {["x"] = 7, ["meta"] = {["fields"] = {["blossom_time"] = "22471752"}, ["inventory"] = {}}, ["y"] = 5, ["param1"] = 30, ["z"] = 12, ["name"] = "default:leaves"}, {["x"] = 7, ["meta"] = {["fields"] = {["blossom_time"] = "22471752"}, ["inventory"] = {}}, ["y"] = 5, ["param1"] = 14, ["z"] = 13, ["name"] = "nature:blossom"}, {["x"] = 7, ["meta"] = {["fields"] = {}, ["inventory"] = {}}, ["y"] = 5, ["param1"] = 14, ["z"] = 14, ["name"] = "default:apple"}, {["x"] = 7, ["meta"] = {["fields"] = {}, ["inventory"] = {}}, ["y"] = 5, ["param1"] = 14, ["z"] = 16, ["name"] = "default:leaves"}, {["x"] = 7, ["meta"] = {["fields"] = {}, ["inventory"] = {}}, ["y"] = 5, ["param1"] = 14, ["z"] = 17, ["name"] = "default:leaves"}, {["x"] = 7, ["meta"] = {["fields"] = {}, ["inventory"] = {}}, ["y"] = 5, ["param1"] = 14, ["z"] = 19, ["name"] = "default:leaves"}, {["x"] = 7, ["meta"] = {["fields"] = {}, ["inventory"] = {}}, ["y"] = 6, ["param1"] = 14, ["z"] = 13, ["name"] = "default:leaves"}, {["x"] = 7, ["meta"] = {["fields"] = {["blossom_time"] = "22076426"}, ["inventory"] = {}}, ["y"] = 6, ["param1"] = 14, ["z"] = 14, ["name"] = "default:leaves"}, {["x"] = 7, ["meta"] = {["fields"] = {}, ["inventory"] = {}}, ["y"] = 6, ["param1"] = 14, ["z"] = 15, ["name"] = "default:leaves"}, {["x"] = 7, ["meta"] = {["fields"] = {}, ["inventory"] = {}}, ["y"] = 6, ["param1"] = 14, ["z"] = 19, ["name"] = "default:leaves"}, {["x"] = 7, ["meta"] = {["fields"] = {}, ["inventory"] = {}}, ["y"] = 6, ["param1"] = 14, ["z"] = 20, ["name"] = "default:leaves"}, {["x"] = 8, ["meta"] = {["fields"] = {}, ["inventory"] = {}}, ["y"] = 0, ["z"] = 0, ["name"] = "cityscape:road"}, {["x"] = 8, ["meta"] = {["fields"] = {}, ["inventory"] = {}}, ["y"] = 0, ["z"] = 1, ["name"] = "cityscape:road"}, {["x"] = 8, ["meta"] = {["fields"] = {}, ["inventory"] = {}}, ["param2"] = 21, ["y"] = 0, ["z"] = 2, ["name"] = "cityscape:road_yellow_line"}, {["x"] = 8, ["meta"] = {["fields"] = {}, ["inventory"] = {}}, ["y"] = 0, ["z"] = 3, ["name"] = "cityscape:road"}, {["x"] = 8, ["meta"] = {["fields"] = {}, ["inventory"] = {}}, ["y"] = 0, ["z"] = 4, ["name"] = "cityscape:road"}, {["x"] = 8, ["meta"] = {["fields"] = {}, ["inventory"] = {}}, ["y"] = 0, ["z"] = 5, ["name"] = "cityscape:sidewalk"}, {["x"] = 8, ["meta"] = {["fields"] = {}, ["inventory"] = {}}, ["y"] = 0, ["z"] = 6, ["name"] = "cityscape:sidewalk"}, {["x"] = 8, ["meta"] = {["fields"] = {}, ["inventory"] = {}}, ["y"] = 0, ["z"] = 7, ["name"] = "default:dirt_with_grass"}, {["x"] = 8, ["meta"] = {["fields"] = {}, ["inventory"] = {}}, ["y"] = 0, ["z"] = 8, ["name"] = "default:dirt_with_grass"}, {["x"] = 8, ["meta"] = {["fields"] = {}, ["inventory"] = {}}, ["y"] = 0, ["z"] = 9, ["name"] = "default:dirt_with_grass"}, {["x"] = 8, ["meta"] = {["fields"] = {}, ["inventory"] = {}}, ["y"] = 0, ["z"] = 10, ["name"] = "woodsoils:grass_with_leaves_1"}, {["x"] = 8, ["meta"] = {["fields"] = {}, ["inventory"] = {}}, ["y"] = 0, ["z"] = 11, ["name"] = "woodsoils:grass_with_leaves_2"}, {["x"] = 8, ["meta"] = {["fields"] = {}, ["inventory"] = {}}, ["y"] = 0, ["z"] = 12, ["name"] = "woodsoils:dirt_with_leaves_1"}, {["x"] = 8, ["meta"] = {["fields"] = {}, ["inventory"] = {}}, ["y"] = 0, ["z"] = 13, ["name"] = "woodsoils:dirt_with_leaves_1"}, {["x"] = 8, ["meta"] = {["fields"] = {}, ["inventory"] = {}}, ["y"] = 0, ["z"] = 14, ["name"] = "woodsoils:dirt_with_leaves_1"}, {["x"] = 8, ["meta"] = {["fields"] = {}, ["inventory"] = {}}, ["y"] = 0, ["z"] = 15, ["name"] = "woodsoils:dirt_with_leaves_1"}, {["x"] = 8, ["meta"] = {["fields"] = {}, ["inventory"] = {}}, ["y"] = 0, ["z"] = 16, ["name"] = "woodsoils:dirt_with_leaves_1"}, {["x"] = 8, ["meta"] = {["fields"] = {}, ["inventory"] = {}}, ["y"] = 0, ["z"] = 17, ["name"] = "woodsoils:grass_with_leaves_2"}, {["x"] = 8, ["meta"] = {["fields"] = {}, ["inventory"] = {}}, ["y"] = 0, ["z"] = 18, ["name"] = "woodsoils:grass_with_leaves_1"}, {["x"] = 8, ["meta"] = {["fields"] = {}, ["inventory"] = {}}, ["y"] = 0, ["z"] = 19, ["name"] = "default:dirt_with_grass"}, {["x"] = 8, ["meta"] = {["fields"] = {}, ["inventory"] = {}}, ["y"] = 0, ["z"] = 20, ["name"] = "default:dirt_with_grass"}, {["x"] = 8, ["meta"] = {["fields"] = {}, ["inventory"] = {}}, ["y"] = 0, ["z"] = 21, ["name"] = "default:dirt_with_grass"}, {["x"] = 8, ["meta"] = {["fields"] = {}, ["inventory"] = {}}, ["y"] = 0, ["z"] = 22, ["name"] = "default:dirt_with_grass"}, {["x"] = 8, ["meta"] = {["fields"] = {}, ["inventory"] = {}}, ["y"] = 0, ["z"] = 23, ["name"] = "default:dirt_with_grass"}, {["x"] = 8, ["meta"] = {["fields"] = {}, ["inventory"] = {}}, ["y"] = 0, ["z"] = 24, ["name"] = "cityscape:sidewalk"}, {["x"] = 8, ["meta"] = {["fields"] = {}, ["inventory"] = {}}, ["y"] = 0, ["z"] = 25, ["name"] = "cityscape:sidewalk"}, {["x"] = 8, ["meta"] = {["fields"] = {}, ["inventory"] = {}}, ["y"] = 0, ["z"] = 26, ["name"] = "cityscape:road"}, {["x"] = 8, ["meta"] = {["fields"] = {}, ["inventory"] = {}}, ["y"] = 0, ["z"] = 27, ["name"] = "cityscape:road"}, {["x"] = 8, ["meta"] = {["fields"] = {}, ["inventory"] = {}}, ["param2"] = 21, ["y"] = 0, ["z"] = 28, ["name"] = "cityscape:road_yellow_line"}, {["x"] = 8, ["meta"] = {["fields"] = {}, ["inventory"] = {}}, ["y"] = 0, ["z"] = 29, ["name"] = "cityscape:road"}, {["x"] = 8, ["meta"] = {["fields"] = {}, ["inventory"] = {}}, ["y"] = 0, ["z"] = 30, ["name"] = "cityscape:road"}, {["x"] = 8, ["meta"] = {["fields"] = {}, ["inventory"] = {}}, ["y"] = 1, ["param1"] = 127, ["z"] = 9, ["name"] = "default:grass_3"}, {["x"] = 8, ["meta"] = {["fields"] = {}, ["inventory"] = {}}, ["param2"] = 1, ["y"] = 1, ["param1"] = 45, ["z"] = 14, ["name"] = "trunks:treeroot"}, {["x"] = 8, ["meta"] = {["fields"] = {}, ["inventory"] = {}}, ["param2"] = 17, ["y"] = 1, ["param1"] = 13, ["z"] = 19, ["name"] = "trunks:moss"}, {["x"] = 8, ["meta"] = {["fields"] = {}, ["inventory"] = {}}, ["y"] = 1, ["param1"] = 46, ["z"] = 22, ["name"] = "bushes:youngtree2_bottom"}, {["x"] = 8, ["meta"] = {["fields"] = {}, ["inventory"] = {}}, ["y"] = 2, ["param1"] = 13, ["z"] = 15, ["name"] = "default:apple"}, {["x"] = 8, ["meta"] = {["fields"] = {}, ["inventory"] = {}}, ["y"] = 2, ["param1"] = 30, ["z"] = 22, ["name"] = "bushes:youngtree2_bottom"}, {["x"] = 8, ["meta"] = {["fields"] = {}, ["inventory"] = {}}, ["y"] = 3, ["param1"] = 13, ["z"] = 14, ["name"] = "default:leaves"}, {["x"] = 8, ["meta"] = {["fields"] = {["blossom_time"] = "22779836"}, ["inventory"] = {}}, ["y"] = 3, ["param1"] = 13, ["z"] = 15, ["name"] = "default:leaves"}, {["x"] = 8, ["meta"] = {["fields"] = {}, ["inventory"] = {}}, ["y"] = 3, ["param1"] = 14, ["z"] = 21, ["name"] = "bushes:bushbranches2"}, {["x"] = 8, ["meta"] = {["fields"] = {}, ["inventory"] = {}}, ["param2"] = 2, ["y"] = 3, ["param1"] = 14, ["z"] = 22, ["name"] = "bushes:bushbranches2"}, {["x"] = 8, ["meta"] = {["fields"] = {["blossom_time"] = "22471752"}, ["inventory"] = {}}, ["y"] = 4, ["param1"] = 13, ["z"] = 13, ["name"] = "default:leaves"}, {["x"] = 8, ["meta"] = {["fields"] = {["blossom_time"] = "22344028"}, ["inventory"] = {}}, ["y"] = 4, ["param1"] = 13, ["z"] = 14, ["name"] = "default:leaves"}, {["x"] = 8, ["meta"] = {["fields"] = {["blossom_time"] = "22462464"}, ["inventory"] = {}}, ["y"] = 4, ["param1"] = 13, ["z"] = 15, ["name"] = "default:leaves"}, {["x"] = 8, ["meta"] = {["fields"] = {}, ["inventory"] = {}}, ["y"] = 4, ["param1"] = 13, ["z"] = 16, ["name"] = "default:leaves"}, {["x"] = 8, ["meta"] = {["fields"] = {}, ["inventory"] = {}}, ["y"] = 4, ["param1"] = 13, ["z"] = 17, ["name"] = "default:leaves"}, {["x"] = 8, ["meta"] = {["fields"] = {}, ["inventory"] = {}}, ["y"] = 4, ["param1"] = 13, ["z"] = 18, ["name"] = "default:leaves"}, {["x"] = 8, ["meta"] = {["fields"] = {}, ["inventory"] = {}}, ["y"] = 4, ["param1"] = 13, ["z"] = 19, ["name"] = "default:leaves"}, {["x"] = 8, ["meta"] = {["fields"] = {}, ["inventory"] = {}}, ["y"] = 4, ["param1"] = 13, ["z"] = 20, ["name"] = "default:leaves"}, {["x"] = 8, ["meta"] = {["fields"] = {}, ["inventory"] = {}}, ["y"] = 4, ["param1"] = 14, ["z"] = 21, ["name"] = "bushes:BushLeaves1"}, {["x"] = 8, ["meta"] = {["fields"] = {}, ["inventory"] = {}}, ["y"] = 4, ["param1"] = 14, ["z"] = 22, ["name"] = "bushes:BushLeaves1"}, {["x"] = 8, ["meta"] = {["fields"] = {}, ["inventory"] = {}}, ["y"] = 5, ["param1"] = 13, ["z"] = 13, ["name"] = "default:leaves"}, {["x"] = 8, ["meta"] = {["fields"] = {["blossom_time"] = "22405901"}, ["inventory"] = {}}, ["y"] = 5, ["param1"] = 13, ["z"] = 14, ["name"] = "nature:blossom"}, {["x"] = 8, ["meta"] = {["fields"] = {["blossom_time"] = "22562334"}, ["inventory"] = {}}, ["y"] = 5, ["param1"] = 13, ["z"] = 15, ["name"] = "default:leaves"}, {["x"] = 8, ["meta"] = {["fields"] = {}, ["inventory"] = {}}, ["y"] = 5, ["param1"] = 13, ["z"] = 16, ["name"] = "default:leaves"}, {["x"] = 8, ["meta"] = {["fields"] = {}, ["inventory"] = {}}, ["y"] = 5, ["param1"] = 13, ["z"] = 17, ["name"] = "default:leaves"}, {["x"] = 8, ["meta"] = {["fields"] = {}, ["inventory"] = {}}, ["y"] = 5, ["param1"] = 14, ["z"] = 18, ["name"] = "default:leaves"}, {["x"] = 8, ["meta"] = {["fields"] = {}, ["inventory"] = {}}, ["y"] = 5, ["param1"] = 13, ["z"] = 19, ["name"] = "default:leaves"}, {["x"] = 8, ["meta"] = {["fields"] = {}, ["inventory"] = {}}, ["y"] = 5, ["param1"] = 13, ["z"] = 20, ["name"] = "default:leaves"}, {["x"] = 8, ["meta"] = {["fields"] = {["blossom_time"] = "22562338"}, ["inventory"] = {}}, ["y"] = 6, ["param1"] = 14, ["z"] = 12, ["name"] = "default:leaves"}, {["x"] = 8, ["meta"] = {["fields"] = {}, ["inventory"] = {}}, ["y"] = 6, ["param1"] = 13, ["z"] = 13, ["name"] = "default:leaves"}, {["x"] = 8, ["meta"] = {["fields"] = {["blossom_time"] = "22392358"}, ["inventory"] = {}}, ["y"] = 6, ["param1"] = 13, ["z"] = 14, ["name"] = "default:leaves"}, {["x"] = 8, ["meta"] = {["fields"] = {["blossom_time"] = "22782106"}, ["inventory"] = {}}, ["y"] = 6, ["param1"] = 13, ["z"] = 15, ["name"] = "nature:blossom"}, {["x"] = 8, ["meta"] = {["fields"] = {}, ["inventory"] = {}}, ["y"] = 6, ["param1"] = 14, ["z"] = 16, ["name"] = "default:leaves"}, {["x"] = 8, ["meta"] = {["fields"] = {}, ["inventory"] = {}}, ["y"] = 6, ["param1"] = 14, ["z"] = 17, ["name"] = "default:leaves"}, {["x"] = 8, ["meta"] = {["fields"] = {}, ["inventory"] = {}}, ["y"] = 6, ["param1"] = 14, ["z"] = 18, ["name"] = "default:leaves"}, {["x"] = 8, ["meta"] = {["fields"] = {}, ["inventory"] = {}}, ["y"] = 6, ["param1"] = 13, ["z"] = 19, ["name"] = "default:leaves"}, {["x"] = 8, ["meta"] = {["fields"] = {}, ["inventory"] = {}}, ["y"] = 6, ["param1"] = 13, ["z"] = 20, ["name"] = "default:leaves"}, {["x"] = 8, ["meta"] = {["fields"] = {}, ["inventory"] = {}}, ["y"] = 6, ["param1"] = 14, ["z"] = 21, ["name"] = "default:leaves"}, {["x"] = 8, ["meta"] = {["fields"] = {["blossom_time"] = "22471752"}, ["inventory"] = {}}, ["y"] = 7, ["param1"] = 14, ["z"] = 13, ["name"] = "default:leaves"}, {["x"] = 8, ["meta"] = {["fields"] = {["blossom_time"] = "22779890"}, ["inventory"] = {}}, ["y"] = 7, ["param1"] = 14, ["z"] = 14, ["name"] = "default:leaves"}, {["x"] = 8, ["meta"] = {["fields"] = {["blossom_time"] = "22782106"}, ["inventory"] = {}}, ["y"] = 7, ["param1"] = 14, ["z"] = 15, ["name"] = "nature:blossom"}, {["x"] = 8, ["meta"] = {["fields"] = {}, ["inventory"] = {}}, ["y"] = 7, ["param1"] = 14, ["z"] = 19, ["name"] = "default:leaves"}, {["x"] = 8, ["meta"] = {["fields"] = {}, ["inventory"] = {}}, ["y"] = 7, ["param1"] = 14, ["z"] = 20, ["name"] = "default:leaves"}, {["x"] = 9, ["meta"] = {["fields"] = {}, ["inventory"] = {}}, ["y"] = 0, ["z"] = 0, ["name"] = "cityscape:road"}, {["x"] = 9, ["meta"] = {["fields"] = {}, ["inventory"] = {}}, ["y"] = 0, ["z"] = 1, ["name"] = "cityscape:road"}, {["x"] = 9, ["meta"] = {["fields"] = {}, ["inventory"] = {}}, ["y"] = 0, ["z"] = 2, ["name"] = "cityscape:road"}, {["x"] = 9, ["meta"] = {["fields"] = {}, ["inventory"] = {}}, ["y"] = 0, ["z"] = 3, ["name"] = "cityscape:road"}, {["x"] = 9, ["meta"] = {["fields"] = {}, ["inventory"] = {}}, ["y"] = 0, ["z"] = 4, ["name"] = "cityscape:road"}, {["x"] = 9, ["meta"] = {["fields"] = {}, ["inventory"] = {}}, ["y"] = 0, ["z"] = 5, ["name"] = "cityscape:sidewalk"}, {["x"] = 9, ["meta"] = {["fields"] = {}, ["inventory"] = {}}, ["y"] = 0, ["z"] = 6, ["name"] = "cityscape:sidewalk"}, {["x"] = 9, ["meta"] = {["fields"] = {}, ["inventory"] = {}}, ["y"] = 0, ["z"] = 7, ["name"] = "default:dirt_with_grass"}, {["x"] = 9, ["meta"] = {["fields"] = {}, ["inventory"] = {}}, ["y"] = 0, ["z"] = 8, ["name"] = "default:dirt_with_grass"}, {["x"] = 9, ["meta"] = {["fields"] = {}, ["inventory"] = {}}, ["y"] = 0, ["z"] = 9, ["name"] = "default:dirt_with_grass"}, {["x"] = 9, ["meta"] = {["fields"] = {}, ["inventory"] = {}}, ["y"] = 0, ["z"] = 10, ["name"] = "woodsoils:grass_with_leaves_1"}, {["x"] = 9, ["meta"] = {["fields"] = {}, ["inventory"] = {}}, ["y"] = 0, ["z"] = 11, ["name"] = "woodsoils:grass_with_leaves_2"}, {["x"] = 9, ["meta"] = {["fields"] = {}, ["inventory"] = {}}, ["y"] = 0, ["z"] = 12, ["name"] = "woodsoils:dirt_with_leaves_1"}, {["x"] = 9, ["meta"] = {["fields"] = {}, ["inventory"] = {}}, ["y"] = 0, ["z"] = 13, ["name"] = "woodsoils:dirt_with_leaves_1"}, {["x"] = 9, ["meta"] = {["fields"] = {}, ["inventory"] = {}}, ["y"] = 0, ["z"] = 14, ["name"] = "woodsoils:dirt_with_leaves_1"}, {["x"] = 9, ["meta"] = {["fields"] = {}, ["inventory"] = {}}, ["y"] = 0, ["z"] = 15, ["name"] = "woodsoils:dirt_with_leaves_1"}, {["x"] = 9, ["meta"] = {["fields"] = {}, ["inventory"] = {}}, ["y"] = 0, ["z"] = 16, ["name"] = "woodsoils:dirt_with_leaves_1"}, {["x"] = 9, ["meta"] = {["fields"] = {}, ["inventory"] = {}}, ["y"] = 0, ["z"] = 17, ["name"] = "woodsoils:grass_with_leaves_2"}, {["x"] = 9, ["meta"] = {["fields"] = {}, ["inventory"] = {}}, ["y"] = 0, ["z"] = 18, ["name"] = "woodsoils:grass_with_leaves_1"}, {["x"] = 9, ["meta"] = {["fields"] = {}, ["inventory"] = {}}, ["y"] = 0, ["z"] = 19, ["name"] = "default:dirt"}, {["x"] = 9, ["meta"] = {["fields"] = {}, ["inventory"] = {}}, ["y"] = 0, ["z"] = 20, ["name"] = "default:dirt_with_grass"}, {["x"] = 9, ["meta"] = {["fields"] = {}, ["inventory"] = {}}, ["y"] = 0, ["z"] = 21, ["name"] = "default:dirt_with_grass"}, {["x"] = 9, ["meta"] = {["fields"] = {}, ["inventory"] = {}}, ["y"] = 0, ["z"] = 22, ["name"] = "default:dirt_with_grass"}, {["x"] = 9, ["meta"] = {["fields"] = {}, ["inventory"] = {}}, ["y"] = 0, ["z"] = 23, ["name"] = "default:dirt_with_grass"}, {["x"] = 9, ["meta"] = {["fields"] = {}, ["inventory"] = {}}, ["y"] = 0, ["z"] = 24, ["name"] = "cityscape:sidewalk"}, {["x"] = 9, ["meta"] = {["fields"] = {}, ["inventory"] = {}}, ["y"] = 0, ["z"] = 25, ["name"] = "cityscape:sidewalk"}, {["x"] = 9, ["meta"] = {["fields"] = {}, ["inventory"] = {}}, ["y"] = 0, ["z"] = 26, ["name"] = "cityscape:road"}, {["x"] = 9, ["meta"] = {["fields"] = {}, ["inventory"] = {}}, ["y"] = 0, ["z"] = 27, ["name"] = "cityscape:road"}, {["x"] = 9, ["meta"] = {["fields"] = {}, ["inventory"] = {}}, ["y"] = 0, ["z"] = 28, ["name"] = "cityscape:road"}, {["x"] = 9, ["meta"] = {["fields"] = {}, ["inventory"] = {}}, ["y"] = 0, ["z"] = 29, ["name"] = "cityscape:road"}, {["x"] = 9, ["meta"] = {["fields"] = {}, ["inventory"] = {}}, ["y"] = 0, ["z"] = 30, ["name"] = "cityscape:road"}, {["x"] = 9, ["meta"] = {["fields"] = {}, ["inventory"] = {}}, ["y"] = 1, ["param1"] = 45, ["z"] = 13, ["name"] = "trunks:treeroot"}, {["x"] = 9, ["meta"] = {["fields"] = {}, ["inventory"] = {}}, ["y"] = 1, ["z"] = 14, ["name"] = "default:tree"}, {["x"] = 9, ["meta"] = {["fields"] = {}, ["inventory"] = {}}, ["param2"] = 2, ["y"] = 1, ["param1"] = 12, ["z"] = 15, ["name"] = "trunks:treeroot"}, {["x"] = 9, ["meta"] = {["fields"] = {}, ["inventory"] = {}}, ["y"] = 1, ["param1"] = 12, ["z"] = 18, ["name"] = "trunks:treeroot"}, {["x"] = 9, ["meta"] = {["fields"] = {}, ["inventory"] = {}}, ["y"] = 1, ["z"] = 19, ["name"] = "default:tree"}, {["x"] = 9, ["meta"] = {["fields"] = {}, ["inventory"] = {}}, ["param2"] = 6, ["y"] = 1, ["param1"] = 13, ["z"] = 20, ["name"] = "trunks:moss"}, {["x"] = 9, ["meta"] = {["fields"] = {}, ["inventory"] = {}}, ["y"] = 1, ["param1"] = 14, ["z"] = 21, ["name"] = "default:grass_3"}, {["x"] = 9, ["meta"] = {["fields"] = {}, ["inventory"] = {}}, ["param2"] = 1, ["y"] = 1, ["param1"] = 31, ["z"] = 22, ["name"] = "trunks:twig_12"}, {["x"] = 9, ["meta"] = {["fields"] = {}, ["inventory"] = {}}, ["y"] = 2, ["z"] = 14, ["name"] = "default:tree"}, {["x"] = 9, ["meta"] = {["fields"] = {}, ["inventory"] = {}}, ["y"] = 2, ["z"] = 19, ["name"] = "default:tree"}, {["x"] = 9, ["meta"] = {["fields"] = {}, ["inventory"] = {}}, ["param2"] = 11, ["y"] = 3, ["param1"] = 13, ["z"] = 13, ["name"] = "trunks:moss"}, {["x"] = 9, ["meta"] = {["fields"] = {}, ["inventory"] = {}}, ["y"] = 3, ["z"] = 14, ["name"] = "default:tree"}, {["x"] = 9, ["meta"] = {["fields"] = {["blossom_time"] = "22462464"}, ["inventory"] = {}}, ["y"] = 3, ["param1"] = 12, ["z"] = 15, ["name"] = "default:leaves"}, {["x"] = 9, ["meta"] = {["fields"] = {}, ["inventory"] = {}}, ["y"] = 3, ["param1"] = 12, ["z"] = 17, ["name"] = "default:leaves"}, {["x"] = 9, ["meta"] = {["fields"] = {}, ["inventory"] = {}}, ["y"] = 3, ["param1"] = 12, ["z"] = 18, ["name"] = "default:leaves"}, {["x"] = 9, ["meta"] = {["fields"] = {}, ["inventory"] = {}}, ["y"] = 3, ["z"] = 19, ["name"] = "default:tree"}, {["x"] = 9, ["meta"] = {["fields"] = {}, ["inventory"] = {}}, ["param2"] = 7, ["y"] = 3, ["param1"] = 13, ["z"] = 20, ["name"] = "trunks:moss"}, {["x"] = 9, ["meta"] = {["fields"] = {}, ["inventory"] = {}}, ["y"] = 4, ["param1"] = 14, ["z"] = 12, ["name"] = "default:leaves"}, {["x"] = 9, ["meta"] = {["fields"] = {["blossom_time"] = "22335755"}, ["inventory"] = {}}, ["y"] = 4, ["param1"] = 13, ["z"] = 13, ["name"] = "nature:blossom"}, {["x"] = 9, ["meta"] = {["fields"] = {}, ["inventory"] = {}}, ["y"] = 4, ["z"] = 14, ["name"] = "default:tree"}, {["x"] = 9, ["meta"] = {["fields"] = {["blossom_time"] = "22335753"}, ["inventory"] = {}}, ["y"] = 4, ["param1"] = 12, ["z"] = 15, ["name"] = "default:leaves"}, {["x"] = 9, ["meta"] = {["fields"] = {}, ["inventory"] = {}}, ["y"] = 4, ["param1"] = 12, ["z"] = 16, ["name"] = "default:leaves"}, {["x"] = 9, ["meta"] = {["fields"] = {}, ["inventory"] = {}}, ["y"] = 4, ["param1"] = 13, ["z"] = 17, ["name"] = "default:leaves"}, {["x"] = 9, ["meta"] = {["fields"] = {}, ["inventory"] = {}}, ["y"] = 4, ["param1"] = 12, ["z"] = 18, ["name"] = "default:leaves"}, {["x"] = 9, ["meta"] = {["fields"] = {}, ["inventory"] = {}}, ["y"] = 4, ["z"] = 19, ["name"] = "default:tree"}, {["x"] = 9, ["meta"] = {["fields"] = {}, ["inventory"] = {}}, ["y"] = 4, ["param1"] = 13, ["z"] = 20, ["name"] = "default:leaves"}, {["x"] = 9, ["meta"] = {["fields"] = {}, ["inventory"] = {}}, ["y"] = 4, ["param1"] = 14, ["z"] = 21, ["name"] = "default:leaves"}, {["x"] = 9, ["meta"] = {["fields"] = {["blossom_time"] = "22335755"}, ["inventory"] = {}}, ["y"] = 5, ["param1"] = 14, ["z"] = 12, ["name"] = "default:leaves"}, {["x"] = 9, ["meta"] = {["fields"] = {}, ["inventory"] = {}}, ["y"] = 5, ["param1"] = 13, ["z"] = 13, ["name"] = "default:leaves"}, {["x"] = 9, ["meta"] = {["fields"] = {}, ["inventory"] = {}}, ["y"] = 5, ["z"] = 14, ["name"] = "default:tree"}, {["x"] = 9, ["meta"] = {["fields"] = {["blossom_time"] = "22782107"}, ["inventory"] = {}}, ["y"] = 5, ["param1"] = 12, ["z"] = 15, ["name"] = "default:leaves"}, {["x"] = 9, ["meta"] = {["fields"] = {}, ["inventory"] = {}}, ["y"] = 5, ["param1"] = 13, ["z"] = 16, ["name"] = "default:leaves"}, {["x"] = 9, ["meta"] = {["fields"] = {}, ["inventory"] = {}}, ["y"] = 5, ["param1"] = 13, ["z"] = 18, ["name"] = "default:leaves"}, {["x"] = 9, ["meta"] = {["fields"] = {}, ["inventory"] = {}}, ["y"] = 5, ["z"] = 19, ["name"] = "default:tree"}, {["x"] = 9, ["meta"] = {["fields"] = {}, ["inventory"] = {}}, ["y"] = 5, ["param1"] = 13, ["z"] = 20, ["name"] = "default:leaves"}, {["x"] = 9, ["meta"] = {["fields"] = {}, ["inventory"] = {}}, ["y"] = 5, ["param1"] = 14, ["z"] = 21, ["name"] = "default:leaves"}, {["x"] = 9, ["meta"] = {["fields"] = {}, ["inventory"] = {}}, ["y"] = 6, ["param1"] = 14, ["z"] = 13, ["name"] = "default:leaves"}, {["x"] = 9, ["meta"] = {["fields"] = {}, ["inventory"] = {}}, ["y"] = 6, ["param1"] = 13, ["z"] = 14, ["name"] = "default:leaves"}, {["x"] = 9, ["meta"] = {["fields"] = {["blossom_time"] = "21985390"}, ["inventory"] = {}}, ["y"] = 6, ["param1"] = 13, ["z"] = 15, ["name"] = "nature:blossom"}, {["x"] = 9, ["meta"] = {["fields"] = {}, ["inventory"] = {}}, ["y"] = 6, ["param1"] = 14, ["z"] = 16, ["name"] = "default:leaves"}, {["x"] = 9, ["meta"] = {["fields"] = {}, ["inventory"] = {}}, ["y"] = 6, ["param1"] = 14, ["z"] = 17, ["name"] = "default:leaves"}, {["x"] = 9, ["meta"] = {["fields"] = {}, ["inventory"] = {}}, ["y"] = 6, ["param1"] = 13, ["z"] = 18, ["name"] = "default:leaves"}, {["x"] = 9, ["meta"] = {["fields"] = {}, ["inventory"] = {}}, ["y"] = 6, ["param1"] = 14, ["z"] = 19, ["name"] = "default:leaves"}, {["x"] = 9, ["meta"] = {["fields"] = {}, ["inventory"] = {}}, ["y"] = 6, ["param1"] = 14, ["z"] = 20, ["name"] = "default:leaves"}, {["x"] = 9, ["meta"] = {["fields"] = {}, ["inventory"] = {}}, ["y"] = 6, ["param1"] = 14, ["z"] = 21, ["name"] = "default:leaves"}, {["x"] = 9, ["meta"] = {["fields"] = {["blossom_time"] = "22344028"}, ["inventory"] = {}}, ["y"] = 7, ["param1"] = 14, ["z"] = 14, ["name"] = "default:leaves"}, {["x"] = 9, ["meta"] = {["fields"] = {["blossom_time"] = "22169663"}, ["inventory"] = {}}, ["y"] = 7, ["param1"] = 14, ["z"] = 15, ["name"] = "default:leaves"}, {["x"] = 9, ["meta"] = {["fields"] = {}, ["inventory"] = {}}, ["y"] = 7, ["param1"] = 14, ["z"] = 17, ["name"] = "default:leaves"}, {["x"] = 9, ["meta"] = {["fields"] = {}, ["inventory"] = {}}, ["y"] = 7, ["param1"] = 14, ["z"] = 18, ["name"] = "default:leaves"}, {["x"] = 10, ["meta"] = {["fields"] = {}, ["inventory"] = {}}, ["y"] = 0, ["z"] = 0, ["name"] = "cityscape:road"}, {["x"] = 10, ["meta"] = {["fields"] = {}, ["inventory"] = {}}, ["y"] = 0, ["z"] = 1, ["name"] = "cityscape:road"}, {["x"] = 10, ["meta"] = {["fields"] = {}, ["inventory"] = {}}, ["param2"] = 21, ["y"] = 0, ["z"] = 2, ["name"] = "cityscape:road_yellow_line"}, {["x"] = 10, ["meta"] = {["fields"] = {}, ["inventory"] = {}}, ["y"] = 0, ["z"] = 3, ["name"] = "cityscape:road"}, {["x"] = 10, ["meta"] = {["fields"] = {}, ["inventory"] = {}}, ["y"] = 0, ["z"] = 4, ["name"] = "cityscape:road"}, {["x"] = 10, ["meta"] = {["fields"] = {}, ["inventory"] = {}}, ["y"] = 0, ["z"] = 5, ["name"] = "cityscape:sidewalk"}, {["x"] = 10, ["meta"] = {["fields"] = {}, ["inventory"] = {}}, ["y"] = 0, ["z"] = 6, ["name"] = "cityscape:sidewalk"}, {["x"] = 10, ["meta"] = {["fields"] = {}, ["inventory"] = {}}, ["y"] = 0, ["z"] = 7, ["name"] = "default:dirt_with_grass"}, {["x"] = 10, ["meta"] = {["fields"] = {}, ["inventory"] = {}}, ["y"] = 0, ["z"] = 8, ["name"] = "default:dirt_with_grass"}, {["x"] = 10, ["meta"] = {["fields"] = {}, ["inventory"] = {}}, ["y"] = 0, ["z"] = 9, ["name"] = "default:dirt_with_grass"}, {["x"] = 10, ["meta"] = {["fields"] = {}, ["inventory"] = {}}, ["y"] = 0, ["z"] = 10, ["name"] = "woodsoils:grass_with_leaves_1"}, {["x"] = 10, ["meta"] = {["fields"] = {}, ["inventory"] = {}}, ["y"] = 0, ["z"] = 11, ["name"] = "woodsoils:grass_with_leaves_2"}, {["x"] = 10, ["meta"] = {["fields"] = {}, ["inventory"] = {}}, ["y"] = 0, ["z"] = 12, ["name"] = "woodsoils:dirt_with_leaves_1"}, {["x"] = 10, ["meta"] = {["fields"] = {}, ["inventory"] = {}}, ["y"] = 0, ["z"] = 13, ["name"] = "woodsoils:dirt_with_leaves_1"}, {["x"] = 10, ["meta"] = {["fields"] = {}, ["inventory"] = {}}, ["y"] = 0, ["z"] = 14, ["name"] = "woodsoils:dirt_with_leaves_1"}, {["x"] = 10, ["meta"] = {["fields"] = {}, ["inventory"] = {}}, ["y"] = 0, ["z"] = 15, ["name"] = "woodsoils:dirt_with_leaves_1"}, {["x"] = 10, ["meta"] = {["fields"] = {}, ["inventory"] = {}}, ["y"] = 0, ["z"] = 16, ["name"] = "woodsoils:dirt_with_leaves_1"}, {["x"] = 10, ["meta"] = {["fields"] = {}, ["inventory"] = {}}, ["y"] = 0, ["z"] = 17, ["name"] = "woodsoils:grass_with_leaves_2"}, {["x"] = 10, ["meta"] = {["fields"] = {}, ["inventory"] = {}}, ["y"] = 0, ["z"] = 18, ["name"] = "woodsoils:grass_with_leaves_1"}, {["x"] = 10, ["meta"] = {["fields"] = {}, ["inventory"] = {}}, ["y"] = 0, ["z"] = 19, ["name"] = "default:dirt_with_grass"}, {["x"] = 10, ["meta"] = {["fields"] = {}, ["inventory"] = {}}, ["y"] = 0, ["z"] = 20, ["name"] = "default:dirt_with_grass"}, {["x"] = 10, ["meta"] = {["fields"] = {}, ["inventory"] = {}}, ["y"] = 0, ["z"] = 21, ["name"] = "default:dirt_with_grass"}, {["x"] = 10, ["meta"] = {["fields"] = {}, ["inventory"] = {}}, ["y"] = 0, ["z"] = 22, ["name"] = "default:dirt_with_grass"}, {["x"] = 10, ["meta"] = {["fields"] = {}, ["inventory"] = {}}, ["y"] = 0, ["z"] = 23, ["name"] = "default:dirt_with_grass"}, {["x"] = 10, ["meta"] = {["fields"] = {}, ["inventory"] = {}}, ["y"] = 0, ["z"] = 24, ["name"] = "cityscape:sidewalk"}, {["x"] = 10, ["meta"] = {["fields"] = {}, ["inventory"] = {}}, ["y"] = 0, ["z"] = 25, ["name"] = "cityscape:sidewalk"}, {["x"] = 10, ["meta"] = {["fields"] = {}, ["inventory"] = {}}, ["y"] = 0, ["z"] = 26, ["name"] = "cityscape:road"}, {["x"] = 10, ["meta"] = {["fields"] = {}, ["inventory"] = {}}, ["y"] = 0, ["z"] = 27, ["name"] = "cityscape:road"}, {["x"] = 10, ["meta"] = {["fields"] = {}, ["inventory"] = {}}, ["param2"] = 21, ["y"] = 0, ["z"] = 28, ["name"] = "cityscape:road_yellow_line"}, {["x"] = 10, ["meta"] = {["fields"] = {}, ["inventory"] = {}}, ["y"] = 0, ["z"] = 29, ["name"] = "cityscape:road"}, {["x"] = 10, ["meta"] = {["fields"] = {}, ["inventory"] = {}}, ["y"] = 0, ["z"] = 30, ["name"] = "cityscape:road"}, {["x"] = 10, ["meta"] = {["fields"] = {}, ["inventory"] = {}}, ["y"] = 1, ["param1"] = 111, ["z"] = 8, ["name"] = "default:grass_4"}, {["x"] = 10, ["meta"] = {["fields"] = {}, ["inventory"] = {}}, ["y"] = 1, ["param1"] = 95, ["z"] = 9, ["name"] = "default:grass_4"}, {["x"] = 10, ["meta"] = {["fields"] = {}, ["inventory"] = {}}, ["y"] = 1, ["param1"] = 13, ["z"] = 14, ["name"] = "youngtrees:youngtree_top"}, {["x"] = 10, ["meta"] = {["fields"] = {}, ["inventory"] = {}}, ["param2"] = 3, ["y"] = 1, ["param1"] = 13, ["z"] = 19, ["name"] = "trunks:treeroot"}, {["x"] = 10, ["meta"] = {["fields"] = {}, ["inventory"] = {}}, ["y"] = 1, ["param1"] = 13, ["z"] = 20, ["name"] = "default:grass_2"}, {["x"] = 10, ["meta"] = {["fields"] = {}, ["inventory"] = {}}, ["param2"] = 1, ["y"] = 1, ["param1"] = 15, ["z"] = 22, ["name"] = "trunks:moss"}, {["x"] = 10, ["meta"] = {["fields"] = {}, ["inventory"] = {}}, ["y"] = 2, ["param1"] = 14, ["z"] = 13, ["name"] = "default:apple"}, {["x"] = 10, ["meta"] = {["fields"] = {["blossom_time"] = "22333663"}, ["inventory"] = {}}, ["y"] = 3, ["param1"] = 14, ["z"] = 13, ["name"] = "default:leaves"}, {["x"] = 10, ["meta"] = {["fields"] = {}, ["inventory"] = {}}, ["y"] = 3, ["param1"] = 13, ["z"] = 14, ["name"] = "default:leaves"}, {["x"] = 10, ["meta"] = {["fields"] = {}, ["inventory"] = {}}, ["y"] = 3, ["param1"] = 13, ["z"] = 18, ["name"] = "default:leaves"}, {["x"] = 10, ["meta"] = {["fields"] = {}, ["inventory"] = {}}, ["param2"] = 12, ["y"] = 3, ["param1"] = 13, ["z"] = 19, ["name"] = "trunks:moss"}, {["x"] = 10, ["meta"] = {["fields"] = {}, ["inventory"] = {}}, ["y"] = 4, ["param1"] = 14, ["z"] = 13, ["name"] = "default:leaves"}, {["x"] = 10, ["meta"] = {["fields"] = {}, ["inventory"] = {}}, ["y"] = 4, ["param1"] = 13, ["z"] = 14, ["name"] = "default:leaves"}, {["x"] = 10, ["meta"] = {["fields"] = {}, ["inventory"] = {}}, ["y"] = 4, ["param1"] = 13, ["z"] = 15, ["name"] = "default:leaves"}, {["x"] = 10, ["meta"] = {["fields"] = {}, ["inventory"] = {}}, ["y"] = 4, ["param1"] = 13, ["z"] = 16, ["name"] = "default:leaves"}, {["x"] = 10, ["meta"] = {["fields"] = {}, ["inventory"] = {}}, ["y"] = 4, ["param1"] = 14, ["z"] = 17, ["name"] = "default:leaves"}, {["x"] = 10, ["meta"] = {["fields"] = {}, ["inventory"] = {}}, ["y"] = 4, ["param1"] = 13, ["z"] = 18, ["name"] = "default:leaves"}, {["x"] = 10, ["meta"] = {["fields"] = {}, ["inventory"] = {}}, ["y"] = 4, ["param1"] = 13, ["z"] = 19, ["name"] = "default:leaves"}, {["x"] = 10, ["meta"] = {["fields"] = {}, ["inventory"] = {}}, ["y"] = 4, ["param1"] = 13, ["z"] = 20, ["name"] = "default:leaves"}, {["x"] = 10, ["meta"] = {["fields"] = {}, ["inventory"] = {}}, ["y"] = 4, ["param1"] = 14, ["z"] = 21, ["name"] = "default:leaves"}, {["x"] = 10, ["meta"] = {["fields"] = {}, ["inventory"] = {}}, ["y"] = 5, ["param1"] = 14, ["z"] = 13, ["name"] = "default:leaves"}, {["x"] = 10, ["meta"] = {["fields"] = {["blossom_time"] = "22333663"}, ["inventory"] = {}}, ["y"] = 5, ["param1"] = 13, ["z"] = 14, ["name"] = "default:leaves"}, {["x"] = 10, ["meta"] = {["fields"] = {["blossom_time"] = "22169663"}, ["inventory"] = {}}, ["y"] = 5, ["param1"] = 13, ["z"] = 15, ["name"] = "nature:blossom"}, {["x"] = 10, ["meta"] = {["fields"] = {}, ["inventory"] = {}}, ["y"] = 5, ["param1"] = 14, ["z"] = 16, ["name"] = "default:leaves"}, {["x"] = 10, ["meta"] = {["fields"] = {}, ["inventory"] = {}}, ["y"] = 5, ["param1"] = 14, ["z"] = 18, ["name"] = "default:leaves"}, {["x"] = 10, ["meta"] = {["fields"] = {}, ["inventory"] = {}}, ["y"] = 5, ["param1"] = 13, ["z"] = 19, ["name"] = "default:leaves"}, {["x"] = 10, ["meta"] = {["fields"] = {}, ["inventory"] = {}}, ["y"] = 5, ["param1"] = 13, ["z"] = 20, ["name"] = "default:leaves"}, {["x"] = 10, ["meta"] = {["fields"] = {}, ["inventory"] = {}}, ["y"] = 5, ["param1"] = 14, ["z"] = 21, ["name"] = "default:leaves"}, {["x"] = 10, ["meta"] = {["fields"] = {}, ["inventory"] = {}}, ["y"] = 6, ["param1"] = 14, ["z"] = 13, ["name"] = "default:leaves"}, {["x"] = 10, ["meta"] = {["fields"] = {}, ["inventory"] = {}}, ["y"] = 6, ["param1"] = 13, ["z"] = 14, ["name"] = "default:leaves"}, {["x"] = 10, ["meta"] = {["fields"] = {}, ["inventory"] = {}}, ["y"] = 6, ["param1"] = 14, ["z"] = 15, ["name"] = "default:leaves"}, {["x"] = 10, ["meta"] = {["fields"] = {}, ["inventory"] = {}}, ["y"] = 6, ["param1"] = 14, ["z"] = 18, ["name"] = "default:leaves"}, {["x"] = 10, ["meta"] = {["fields"] = {}, ["inventory"] = {}}, ["y"] = 6, ["param1"] = 13, ["z"] = 19, ["name"] = "default:leaves"}, {["x"] = 10, ["meta"] = {["fields"] = {}, ["inventory"] = {}}, ["y"] = 6, ["param1"] = 14, ["z"] = 20, ["name"] = "default:leaves"}, {["x"] = 10, ["meta"] = {["fields"] = {["blossom_time"] = "22782150"}, ["inventory"] = {}}, ["y"] = 7, ["param1"] = 14, ["z"] = 13, ["name"] = "nature:blossom"}, {["x"] = 10, ["meta"] = {["fields"] = {["blossom_time"] = "22333663"}, ["inventory"] = {}}, ["y"] = 7, ["param1"] = 14, ["z"] = 14, ["name"] = "default:leaves"}, {["x"] = 10, ["meta"] = {["fields"] = {}, ["inventory"] = {}}, ["y"] = 7, ["param1"] = 14, ["z"] = 15, ["name"] = "default:leaves"}, {["x"] = 10, ["meta"] = {["fields"] = {}, ["inventory"] = {}}, ["y"] = 7, ["param1"] = 14, ["z"] = 19, ["name"] = "default:leaves"}, {["x"] = 10, ["meta"] = {["fields"] = {}, ["inventory"] = {}}, ["y"] = 7, ["param1"] = 14, ["z"] = 20, ["name"] = "default:leaves"}, {["x"] = 11, ["meta"] = {["fields"] = {}, ["inventory"] = {}}, ["y"] = 0, ["z"] = 0, ["name"] = "cityscape:road"}, {["x"] = 11, ["meta"] = {["fields"] = {}, ["inventory"] = {}}, ["y"] = 0, ["z"] = 1, ["name"] = "cityscape:road"}, {["x"] = 11, ["meta"] = {["fields"] = {}, ["inventory"] = {}}, ["y"] = 0, ["z"] = 2, ["name"] = "cityscape:road"}, {["x"] = 11, ["meta"] = {["fields"] = {}, ["inventory"] = {}}, ["y"] = 0, ["z"] = 3, ["name"] = "cityscape:road"}, {["x"] = 11, ["meta"] = {["fields"] = {}, ["inventory"] = {}}, ["y"] = 0, ["z"] = 4, ["name"] = "cityscape:road"}, {["x"] = 11, ["meta"] = {["fields"] = {}, ["inventory"] = {}}, ["y"] = 0, ["z"] = 5, ["name"] = "cityscape:sidewalk"}, {["x"] = 11, ["meta"] = {["fields"] = {}, ["inventory"] = {}}, ["y"] = 0, ["z"] = 6, ["name"] = "cityscape:sidewalk"}, {["x"] = 11, ["meta"] = {["fields"] = {}, ["inventory"] = {}}, ["y"] = 0, ["z"] = 7, ["name"] = "default:dirt_with_grass"}, {["x"] = 11, ["meta"] = {["fields"] = {}, ["inventory"] = {}}, ["y"] = 0, ["z"] = 8, ["name"] = "default:dirt_with_grass"}, {["x"] = 11, ["meta"] = {["fields"] = {}, ["inventory"] = {}}, ["y"] = 0, ["z"] = 9, ["name"] = "default:dirt_with_grass"}, {["x"] = 11, ["meta"] = {["fields"] = {}, ["inventory"] = {}}, ["y"] = 0, ["z"] = 10, ["name"] = "default:dirt_with_grass"}, {["x"] = 11, ["meta"] = {["fields"] = {}, ["inventory"] = {}}, ["y"] = 0, ["z"] = 11, ["name"] = "woodsoils:grass_with_leaves_1"}, {["x"] = 11, ["meta"] = {["fields"] = {}, ["inventory"] = {}}, ["y"] = 0, ["z"] = 12, ["name"] = "woodsoils:grass_with_leaves_2"}, {["x"] = 11, ["meta"] = {["fields"] = {}, ["inventory"] = {}}, ["y"] = 0, ["z"] = 13, ["name"] = "woodsoils:dirt_with_leaves_1"}, {["x"] = 11, ["meta"] = {["fields"] = {}, ["inventory"] = {}}, ["y"] = 0, ["z"] = 14, ["name"] = "woodsoils:dirt_with_leaves_1"}, {["x"] = 11, ["meta"] = {["fields"] = {}, ["inventory"] = {}}, ["y"] = 0, ["z"] = 15, ["name"] = "woodsoils:dirt_with_leaves_1"}, {["x"] = 11, ["meta"] = {["fields"] = {}, ["inventory"] = {}}, ["y"] = 0, ["z"] = 16, ["name"] = "woodsoils:grass_with_leaves_2"}, {["x"] = 11, ["meta"] = {["fields"] = {}, ["inventory"] = {}}, ["y"] = 0, ["z"] = 17, ["name"] = "woodsoils:grass_with_leaves_1"}, {["x"] = 11, ["meta"] = {["fields"] = {}, ["inventory"] = {}}, ["y"] = 0, ["z"] = 18, ["name"] = "default:dirt_with_grass"}, {["x"] = 11, ["meta"] = {["fields"] = {}, ["inventory"] = {}}, ["y"] = 0, ["z"] = 19, ["name"] = "default:dirt_with_grass"}, {["x"] = 11, ["meta"] = {["fields"] = {}, ["inventory"] = {}}, ["y"] = 0, ["z"] = 20, ["name"] = "default:dirt_with_grass"}, {["x"] = 11, ["meta"] = {["fields"] = {}, ["inventory"] = {}}, ["y"] = 0, ["z"] = 21, ["name"] = "default:dirt_with_grass"}, {["x"] = 11, ["meta"] = {["fields"] = {}, ["inventory"] = {}}, ["y"] = 0, ["z"] = 22, ["name"] = "default:dirt_with_grass"}, {["x"] = 11, ["meta"] = {["fields"] = {}, ["inventory"] = {}}, ["y"] = 0, ["z"] = 23, ["name"] = "default:dirt_with_grass"}, {["x"] = 11, ["meta"] = {["fields"] = {}, ["inventory"] = {}}, ["y"] = 0, ["z"] = 24, ["name"] = "cityscape:sidewalk"}, {["x"] = 11, ["meta"] = {["fields"] = {}, ["inventory"] = {}}, ["y"] = 0, ["z"] = 25, ["name"] = "cityscape:sidewalk"}, {["x"] = 11, ["meta"] = {["fields"] = {}, ["inventory"] = {}}, ["y"] = 0, ["z"] = 26, ["name"] = "cityscape:road"}, {["x"] = 11, ["meta"] = {["fields"] = {}, ["inventory"] = {}}, ["y"] = 0, ["z"] = 27, ["name"] = "cityscape:road"}, {["x"] = 11, ["meta"] = {["fields"] = {}, ["inventory"] = {}}, ["y"] = 0, ["z"] = 28, ["name"] = "cityscape:road"}, {["x"] = 11, ["meta"] = {["fields"] = {}, ["inventory"] = {}}, ["y"] = 0, ["z"] = 29, ["name"] = "cityscape:road"}, {["x"] = 11, ["meta"] = {["fields"] = {}, ["inventory"] = {}}, ["y"] = 0, ["z"] = 30, ["name"] = "cityscape:road"}, {["x"] = 11, ["meta"] = {["fields"] = {}, ["inventory"] = {}}, ["y"] = 1, ["param1"] = 79, ["z"] = 9, ["name"] = "default:grass_2"}, {["x"] = 11, ["meta"] = {["fields"] = {}, ["inventory"] = {}}, ["y"] = 1, ["param1"] = 63, ["z"] = 10, ["name"] = "default:grass_3"}, {["x"] = 11, ["meta"] = {["fields"] = {}, ["inventory"] = {}}, ["y"] = 1, ["param1"] = 14, ["z"] = 18, ["name"] = "default:grass_2"}, {["x"] = 11, ["meta"] = {["fields"] = {}, ["inventory"] = {}}, ["param2"] = 2, ["y"] = 1, ["param1"] = 14, ["z"] = 20, ["name"] = "trunks:twig_12"}, {["x"] = 11, ["meta"] = {["fields"] = {}, ["inventory"] = {}}, ["y"] = 1, ["param1"] = 15, ["z"] = 21, ["name"] = "default:grass_2"}, {["x"] = 11, ["meta"] = {["fields"] = {}, ["inventory"] = {}}, ["param2"] = 82, ["y"] = 1, ["param1"] = 14, ["z"] = 22, ["name"] = "ferns:fern_02"}, {["x"] = 11, ["meta"] = {["fields"] = {}, ["inventory"] = {}}, ["param2"] = 1, ["y"] = 1, ["param1"] = 15, ["z"] = 23, ["name"] = "trunks:moss"}, {["x"] = 11, ["meta"] = {["fields"] = {}, ["inventory"] = {}}, ["y"] = 3, ["param1"] = 14, ["z"] = 19, ["name"] = "default:leaves"}, {["x"] = 11, ["meta"] = {["fields"] = {}, ["inventory"] = {}}, ["y"] = 4, ["param1"] = 14, ["z"] = 13, ["name"] = "default:leaves"}, {["x"] = 11, ["meta"] = {["fields"] = {}, ["inventory"] = {}}, ["y"] = 4, ["param1"] = 14, ["z"] = 14, ["name"] = "default:leaves"}, {["x"] = 11, ["meta"] = {["fields"] = {}, ["inventory"] = {}}, ["y"] = 4, ["param1"] = 14, ["z"] = 18, ["name"] = "default:leaves"}, {["x"] = 11, ["meta"] = {["fields"] = {}, ["inventory"] = {}}, ["y"] = 4, ["param1"] = 14, ["z"] = 19, ["name"] = "default:leaves"}, {["x"] = 11, ["meta"] = {["fields"] = {}, ["inventory"] = {}}, ["y"] = 4, ["param1"] = 14, ["z"] = 20, ["name"] = "default:leaves"}, {["x"] = 11, ["meta"] = {["fields"] = {["blossom_time"] = "22562478"}, ["inventory"] = {}}, ["y"] = 5, ["param1"] = 14, ["z"] = 13, ["name"] = "default:leaves"}, {["x"] = 11, ["meta"] = {["fields"] = {}, ["inventory"] = {}}, ["y"] = 5, ["param1"] = 14, ["z"] = 15, ["name"] = "default:leaves"}, {["x"] = 11, ["meta"] = {["fields"] = {}, ["inventory"] = {}}, ["y"] = 5, ["param1"] = 14, ["z"] = 16, ["name"] = "default:leaves"}, {["x"] = 11, ["meta"] = {["fields"] = {}, ["inventory"] = {}}, ["y"] = 5, ["param1"] = 14, ["z"] = 17, ["name"] = "default:leaves"}, {["x"] = 11, ["meta"] = {["fields"] = {}, ["inventory"] = {}}, ["y"] = 5, ["param1"] = 14, ["z"] = 18, ["name"] = "default:leaves"}, {["x"] = 11, ["meta"] = {["fields"] = {}, ["inventory"] = {}}, ["y"] = 6, ["param1"] = 14, ["z"] = 13, ["name"] = "default:leaves"}, {["x"] = 11, ["meta"] = {["fields"] = {}, ["inventory"] = {}}, ["y"] = 6, ["param1"] = 14, ["z"] = 14, ["name"] = "default:leaves"}, {["x"] = 11, ["meta"] = {["fields"] = {["blossom_time"] = "22782107"}, ["inventory"] = {}}, ["y"] = 6, ["param1"] = 14, ["z"] = 15, ["name"] = "nature:blossom"}, {["x"] = 11, ["meta"] = {["fields"] = {}, ["inventory"] = {}}, ["y"] = 6, ["param1"] = 14, ["z"] = 19, ["name"] = "default:leaves"}, {["x"] = 11, ["meta"] = {["fields"] = {}, ["inventory"] = {}}, ["y"] = 6, ["param1"] = 14, ["z"] = 20, ["name"] = "default:leaves"}, {["x"] = 12, ["meta"] = {["fields"] = {}, ["inventory"] = {}}, ["y"] = 0, ["z"] = 0, ["name"] = "cityscape:road"}, {["x"] = 12, ["meta"] = {["fields"] = {}, ["inventory"] = {}}, ["y"] = 0, ["z"] = 1, ["name"] = "cityscape:road"}, {["x"] = 12, ["meta"] = {["fields"] = {}, ["inventory"] = {}}, ["param2"] = 21, ["y"] = 0, ["z"] = 2, ["name"] = "cityscape:road_yellow_line"}, {["x"] = 12, ["meta"] = {["fields"] = {}, ["inventory"] = {}}, ["y"] = 0, ["z"] = 3, ["name"] = "cityscape:road"}, {["x"] = 12, ["meta"] = {["fields"] = {}, ["inventory"] = {}}, ["y"] = 0, ["z"] = 4, ["name"] = "cityscape:road"}, {["x"] = 12, ["meta"] = {["fields"] = {}, ["inventory"] = {}}, ["y"] = 0, ["z"] = 5, ["name"] = "cityscape:sidewalk"}, {["x"] = 12, ["meta"] = {["fields"] = {}, ["inventory"] = {}}, ["y"] = 0, ["z"] = 6, ["name"] = "cityscape:sidewalk"}, {["x"] = 12, ["meta"] = {["fields"] = {}, ["inventory"] = {}}, ["y"] = 0, ["z"] = 7, ["name"] = "default:dirt_with_grass"}, {["x"] = 12, ["meta"] = {["fields"] = {}, ["inventory"] = {}}, ["y"] = 0, ["z"] = 8, ["name"] = "default:dirt_with_grass"}, {["x"] = 12, ["meta"] = {["fields"] = {}, ["inventory"] = {}}, ["y"] = 0, ["z"] = 9, ["name"] = "default:dirt_with_grass"}, {["x"] = 12, ["meta"] = {["fields"] = {}, ["inventory"] = {}}, ["y"] = 0, ["z"] = 10, ["name"] = "default:dirt_with_grass"}, {["x"] = 12, ["meta"] = {["fields"] = {}, ["inventory"] = {}}, ["y"] = 0, ["z"] = 11, ["name"] = "default:dirt_with_grass"}, {["x"] = 12, ["meta"] = {["fields"] = {}, ["inventory"] = {}}, ["y"] = 0, ["z"] = 12, ["name"] = "woodsoils:grass_with_leaves_1"}, {["x"] = 12, ["meta"] = {["fields"] = {}, ["inventory"] = {}}, ["y"] = 0, ["z"] = 13, ["name"] = "woodsoils:grass_with_leaves_2"}, {["x"] = 12, ["meta"] = {["fields"] = {}, ["inventory"] = {}}, ["y"] = 0, ["z"] = 14, ["name"] = "woodsoils:grass_with_leaves_2"}, {["x"] = 12, ["meta"] = {["fields"] = {}, ["inventory"] = {}}, ["y"] = 0, ["z"] = 15, ["name"] = "woodsoils:grass_with_leaves_2"}, {["x"] = 12, ["meta"] = {["fields"] = {}, ["inventory"] = {}}, ["y"] = 0, ["z"] = 16, ["name"] = "woodsoils:grass_with_leaves_1"}, {["x"] = 12, ["meta"] = {["fields"] = {}, ["inventory"] = {}}, ["y"] = 0, ["z"] = 17, ["name"] = "default:dirt_with_grass"}, {["x"] = 12, ["meta"] = {["fields"] = {}, ["inventory"] = {}}, ["y"] = 0, ["z"] = 18, ["name"] = "default:dirt_with_grass"}, {["x"] = 12, ["meta"] = {["fields"] = {}, ["inventory"] = {}}, ["y"] = 0, ["z"] = 19, ["name"] = "default:dirt_with_grass"}, {["x"] = 12, ["meta"] = {["fields"] = {}, ["inventory"] = {}}, ["y"] = 0, ["z"] = 20, ["name"] = "default:dirt_with_grass"}, {["x"] = 12, ["meta"] = {["fields"] = {}, ["inventory"] = {}}, ["y"] = 0, ["z"] = 21, ["name"] = "default:dirt_with_grass"}, {["x"] = 12, ["meta"] = {["fields"] = {}, ["inventory"] = {}}, ["y"] = 0, ["z"] = 22, ["name"] = "default:dirt_with_grass"}, {["x"] = 12, ["meta"] = {["fields"] = {}, ["inventory"] = {}}, ["y"] = 0, ["z"] = 23, ["name"] = "default:dirt_with_grass"}, {["x"] = 12, ["meta"] = {["fields"] = {}, ["inventory"] = {}}, ["y"] = 0, ["z"] = 24, ["name"] = "cityscape:sidewalk"}, {["x"] = 12, ["meta"] = {["fields"] = {}, ["inventory"] = {}}, ["y"] = 0, ["z"] = 25, ["name"] = "cityscape:sidewalk"}, {["x"] = 12, ["meta"] = {["fields"] = {}, ["inventory"] = {}}, ["y"] = 0, ["z"] = 26, ["name"] = "cityscape:road"}, {["x"] = 12, ["meta"] = {["fields"] = {}, ["inventory"] = {}}, ["y"] = 0, ["z"] = 27, ["name"] = "cityscape:road"}, {["x"] = 12, ["meta"] = {["fields"] = {}, ["inventory"] = {}}, ["param2"] = 21, ["y"] = 0, ["z"] = 28, ["name"] = "cityscape:road_yellow_line"}, {["x"] = 12, ["meta"] = {["fields"] = {}, ["inventory"] = {}}, ["y"] = 0, ["z"] = 29, ["name"] = "cityscape:road"}, {["x"] = 12, ["meta"] = {["fields"] = {}, ["inventory"] = {}}, ["y"] = 0, ["z"] = 30, ["name"] = "cityscape:road"}, {["x"] = 12, ["meta"] = {["fields"] = {}, ["inventory"] = {}}, ["y"] = 1, ["param1"] = 63, ["z"] = 9, ["name"] = "default:grass_4"}, {["x"] = 12, ["meta"] = {["fields"] = {}, ["inventory"] = {}}, ["y"] = 1, ["param1"] = 31, ["z"] = 11, ["name"] = "default:grass_1"}, {["x"] = 12, ["meta"] = {["fields"] = {}, ["inventory"] = {}}, ["param2"] = 2, ["y"] = 1, ["param1"] = 15, ["z"] = 17, ["name"] = "trunks:twig_12"}, {["x"] = 12, ["meta"] = {["fields"] = {}, ["inventory"] = {}}, ["param2"] = 1, ["y"] = 1, ["param1"] = 15, ["z"] = 18, ["name"] = "trunks:moss"}, {["x"] = 12, ["meta"] = {["fields"] = {}, ["inventory"] = {}}, ["y"] = 1, ["param1"] = 15, ["z"] = 19, ["name"] = "default:grass_1"}, {["x"] = 12, ["meta"] = {["fields"] = {}, ["inventory"] = {}}, ["param2"] = 130, ["y"] = 1, ["param1"] = 14, ["z"] = 21, ["name"] = "ferns:fern_03"}, {["x"] = 13, ["meta"] = {["fields"] = {}, ["inventory"] = {}}, ["y"] = 0, ["z"] = 0, ["name"] = "cityscape:road"}, {["x"] = 13, ["meta"] = {["fields"] = {}, ["inventory"] = {}}, ["y"] = 0, ["z"] = 1, ["name"] = "cityscape:road"}, {["x"] = 13, ["meta"] = {["fields"] = {}, ["inventory"] = {}}, ["y"] = 0, ["z"] = 2, ["name"] = "cityscape:road"}, {["x"] = 13, ["meta"] = {["fields"] = {}, ["inventory"] = {}}, ["y"] = 0, ["z"] = 3, ["name"] = "cityscape:road"}, {["x"] = 13, ["meta"] = {["fields"] = {}, ["inventory"] = {}}, ["y"] = 0, ["z"] = 4, ["name"] = "cityscape:road"}, {["x"] = 13, ["meta"] = {["fields"] = {}, ["inventory"] = {}}, ["y"] = 0, ["z"] = 5, ["name"] = "cityscape:sidewalk"}, {["x"] = 13, ["meta"] = {["fields"] = {}, ["inventory"] = {}}, ["y"] = 0, ["z"] = 6, ["name"] = "cityscape:sidewalk"}, {["x"] = 13, ["meta"] = {["fields"] = {}, ["inventory"] = {}}, ["y"] = 0, ["z"] = 7, ["name"] = "default:dirt_with_grass"}, {["x"] = 13, ["meta"] = {["fields"] = {}, ["inventory"] = {}}, ["y"] = 0, ["z"] = 8, ["name"] = "default:dirt_with_grass"}, {["x"] = 13, ["meta"] = {["fields"] = {}, ["inventory"] = {}}, ["y"] = 0, ["z"] = 9, ["name"] = "default:dirt_with_grass"}, {["x"] = 13, ["meta"] = {["fields"] = {}, ["inventory"] = {}}, ["y"] = 0, ["z"] = 10, ["name"] = "default:dirt_with_grass"}, {["x"] = 13, ["meta"] = {["fields"] = {}, ["inventory"] = {}}, ["y"] = 0, ["z"] = 11, ["name"] = "default:dirt_with_grass"}, {["x"] = 13, ["meta"] = {["fields"] = {}, ["inventory"] = {}}, ["y"] = 0, ["z"] = 12, ["name"] = "default:dirt_with_grass"}, {["x"] = 13, ["meta"] = {["fields"] = {}, ["inventory"] = {}}, ["y"] = 0, ["z"] = 13, ["name"] = "woodsoils:grass_with_leaves_1"}, {["x"] = 13, ["meta"] = {["fields"] = {}, ["inventory"] = {}}, ["y"] = 0, ["z"] = 14, ["name"] = "woodsoils:grass_with_leaves_1"}, {["x"] = 13, ["meta"] = {["fields"] = {}, ["inventory"] = {}}, ["y"] = 0, ["z"] = 15, ["name"] = "woodsoils:grass_with_leaves_1"}, {["x"] = 13, ["meta"] = {["fields"] = {}, ["inventory"] = {}}, ["y"] = 0, ["z"] = 16, ["name"] = "default:dirt_with_grass"}, {["x"] = 13, ["meta"] = {["fields"] = {}, ["inventory"] = {}}, ["y"] = 0, ["z"] = 17, ["name"] = "default:dirt_with_grass"}, {["x"] = 13, ["meta"] = {["fields"] = {}, ["inventory"] = {}}, ["y"] = 0, ["z"] = 18, ["name"] = "default:dirt_with_grass"}, {["x"] = 13, ["meta"] = {["fields"] = {}, ["inventory"] = {}}, ["y"] = 0, ["z"] = 19, ["name"] = "default:dirt_with_grass"}, {["x"] = 13, ["meta"] = {["fields"] = {}, ["inventory"] = {}}, ["y"] = 0, ["z"] = 20, ["name"] = "default:dirt_with_grass"}, {["x"] = 13, ["meta"] = {["fields"] = {}, ["inventory"] = {}}, ["y"] = 0, ["z"] = 21, ["name"] = "default:dirt_with_grass"}, {["x"] = 13, ["meta"] = {["fields"] = {}, ["inventory"] = {}}, ["y"] = 0, ["z"] = 22, ["name"] = "default:dirt_with_grass"}, {["x"] = 13, ["meta"] = {["fields"] = {}, ["inventory"] = {}}, ["y"] = 0, ["z"] = 23, ["name"] = "default:dirt_with_grass"}, {["x"] = 13, ["meta"] = {["fields"] = {}, ["inventory"] = {}}, ["y"] = 0, ["z"] = 24, ["name"] = "cityscape:sidewalk"}, {["x"] = 13, ["meta"] = {["fields"] = {}, ["inventory"] = {}}, ["y"] = 0, ["z"] = 25, ["name"] = "cityscape:sidewalk"}, {["x"] = 13, ["meta"] = {["fields"] = {}, ["inventory"] = {}}, ["y"] = 0, ["z"] = 26, ["name"] = "cityscape:road"}, {["x"] = 13, ["meta"] = {["fields"] = {}, ["inventory"] = {}}, ["y"] = 0, ["z"] = 27, ["name"] = "cityscape:road"}, {["x"] = 13, ["meta"] = {["fields"] = {}, ["inventory"] = {}}, ["y"] = 0, ["z"] = 28, ["name"] = "cityscape:road"}, {["x"] = 13, ["meta"] = {["fields"] = {}, ["inventory"] = {}}, ["y"] = 0, ["z"] = 29, ["name"] = "cityscape:road"}, {["x"] = 13, ["meta"] = {["fields"] = {}, ["inventory"] = {}}, ["y"] = 0, ["z"] = 30, ["name"] = "cityscape:road"}, {["x"] = 13, ["meta"] = {["fields"] = {}, ["inventory"] = {}}, ["y"] = 1, ["param1"] = 15, ["z"] = 11, ["name"] = "default:grass_2"}, {["x"] = 13, ["meta"] = {["fields"] = {}, ["inventory"] = {}}, ["param2"] = 2, ["y"] = 1, ["param1"] = 14, ["z"] = 16, ["name"] = "ferns:fern_01"}, {["x"] = 13, ["meta"] = {["fields"] = {}, ["inventory"] = {}}, ["y"] = 1, ["param1"] = 15, ["z"] = 17, ["name"] = "default:grass_2"}, {["x"] = 13, ["meta"] = {["fields"] = {}, ["inventory"] = {}}, ["y"] = 1, ["param1"] = 15, ["z"] = 19, ["name"] = "default:grass_1"}, {["x"] = 13, ["meta"] = {["fields"] = {}, ["inventory"] = {}}, ["param2"] = 3, ["y"] = 1, ["param1"] = 15, ["z"] = 21, ["name"] = "trunks:twig_10"}, {["x"] = 13, ["meta"] = {["fields"] = {}, ["inventory"] = {}}, ["param2"] = 3, ["y"] = 1, ["param1"] = 15, ["z"] = 22, ["name"] = "trunks:twig_11"}, {["x"] = 13, ["meta"] = {["fields"] = {}, ["inventory"] = {}}, ["param2"] = 2, ["y"] = 1, ["param1"] = 15, ["z"] = 23, ["name"] = "trunks:moss"}, {["x"] = 14, ["meta"] = {["fields"] = {}, ["inventory"] = {}}, ["y"] = 0, ["z"] = 0, ["name"] = "cityscape:road"}, {["x"] = 14, ["meta"] = {["fields"] = {}, ["inventory"] = {}}, ["y"] = 0, ["z"] = 1, ["name"] = "cityscape:road"}, {["x"] = 14, ["meta"] = {["fields"] = {}, ["inventory"] = {}}, ["param2"] = 21, ["y"] = 0, ["z"] = 2, ["name"] = "cityscape:road_yellow_line"}, {["x"] = 14, ["meta"] = {["fields"] = {}, ["inventory"] = {}}, ["y"] = 0, ["z"] = 3, ["name"] = "cityscape:road"}, {["x"] = 14, ["meta"] = {["fields"] = {}, ["inventory"] = {}}, ["y"] = 0, ["z"] = 4, ["name"] = "cityscape:road"}, {["x"] = 14, ["meta"] = {["fields"] = {}, ["inventory"] = {}}, ["y"] = 0, ["z"] = 5, ["name"] = "cityscape:sidewalk"}, {["x"] = 14, ["meta"] = {["fields"] = {}, ["inventory"] = {}}, ["y"] = 0, ["z"] = 6, ["name"] = "cityscape:sidewalk"}, {["x"] = 14, ["meta"] = {["fields"] = {}, ["inventory"] = {}}, ["y"] = 0, ["z"] = 7, ["name"] = "default:dirt_with_grass"}, {["x"] = 14, ["meta"] = {["fields"] = {}, ["inventory"] = {}}, ["y"] = 0, ["z"] = 8, ["name"] = "default:dirt_with_grass"}, {["x"] = 14, ["meta"] = {["fields"] = {}, ["inventory"] = {}}, ["y"] = 0, ["z"] = 9, ["name"] = "default:dirt_with_grass"}, {["x"] = 14, ["meta"] = {["fields"] = {}, ["inventory"] = {}}, ["y"] = 0, ["z"] = 10, ["name"] = "default:dirt_with_grass"}, {["x"] = 14, ["meta"] = {["fields"] = {}, ["inventory"] = {}}, ["y"] = 0, ["z"] = 11, ["name"] = "default:dirt_with_grass"}, {["x"] = 14, ["meta"] = {["fields"] = {}, ["inventory"] = {}}, ["y"] = 0, ["z"] = 12, ["name"] = "default:dirt_with_grass"}, {["x"] = 14, ["meta"] = {["fields"] = {}, ["inventory"] = {}}, ["y"] = 0, ["z"] = 13, ["name"] = "default:dirt_with_grass"}, {["x"] = 14, ["meta"] = {["fields"] = {}, ["inventory"] = {}}, ["y"] = 0, ["z"] = 14, ["name"] = "default:dirt_with_grass"}, {["x"] = 14, ["meta"] = {["fields"] = {}, ["inventory"] = {}}, ["y"] = 0, ["z"] = 15, ["name"] = "default:dirt_with_grass"}, {["x"] = 14, ["meta"] = {["fields"] = {}, ["inventory"] = {}}, ["y"] = 0, ["z"] = 16, ["name"] = "default:dirt_with_grass"}, {["x"] = 14, ["meta"] = {["fields"] = {}, ["inventory"] = {}}, ["y"] = 0, ["z"] = 17, ["name"] = "default:dirt_with_grass"}, {["x"] = 14, ["meta"] = {["fields"] = {}, ["inventory"] = {}}, ["y"] = 0, ["z"] = 18, ["name"] = "default:dirt_with_grass"}, {["x"] = 14, ["meta"] = {["fields"] = {}, ["inventory"] = {}}, ["y"] = 0, ["z"] = 19, ["name"] = "default:dirt_with_grass"}, {["x"] = 14, ["meta"] = {["fields"] = {}, ["inventory"] = {}}, ["y"] = 0, ["z"] = 20, ["name"] = "default:dirt_with_grass"}, {["x"] = 14, ["meta"] = {["fields"] = {}, ["inventory"] = {}}, ["y"] = 0, ["z"] = 21, ["name"] = "default:dirt_with_grass"}, {["x"] = 14, ["meta"] = {["fields"] = {}, ["inventory"] = {}}, ["y"] = 0, ["z"] = 22, ["name"] = "default:dirt_with_grass"}, {["x"] = 14, ["meta"] = {["fields"] = {}, ["inventory"] = {}}, ["y"] = 0, ["z"] = 23, ["name"] = "default:dirt_with_grass"}, {["x"] = 14, ["meta"] = {["fields"] = {}, ["inventory"] = {}}, ["y"] = 0, ["z"] = 24, ["name"] = "cityscape:sidewalk"}, {["x"] = 14, ["meta"] = {["fields"] = {}, ["inventory"] = {}}, ["y"] = 0, ["z"] = 25, ["name"] = "cityscape:sidewalk"}, {["x"] = 14, ["meta"] = {["fields"] = {}, ["inventory"] = {}}, ["y"] = 0, ["z"] = 26, ["name"] = "cityscape:road"}, {["x"] = 14, ["meta"] = {["fields"] = {}, ["inventory"] = {}}, ["y"] = 0, ["z"] = 27, ["name"] = "cityscape:road"}, {["x"] = 14, ["meta"] = {["fields"] = {}, ["inventory"] = {}}, ["param2"] = 21, ["y"] = 0, ["z"] = 28, ["name"] = "cityscape:road_yellow_line"}, {["x"] = 14, ["meta"] = {["fields"] = {}, ["inventory"] = {}}, ["y"] = 0, ["z"] = 29, ["name"] = "cityscape:road"}, {["x"] = 14, ["meta"] = {["fields"] = {}, ["inventory"] = {}}, ["y"] = 0, ["z"] = 30, ["name"] = "cityscape:road"}, {["x"] = 14, ["meta"] = {["fields"] = {}, ["inventory"] = {}}, ["y"] = 1, ["param1"] = 63, ["z"] = 7, ["name"] = "default:grass_4"}, {["x"] = 14, ["meta"] = {["fields"] = {}, ["inventory"] = {}}, ["y"] = 1, ["param1"] = 31, ["z"] = 9, ["name"] = "default:grass_1"}, {["x"] = 14, ["meta"] = {["fields"] = {}, ["inventory"] = {}}, ["y"] = 1, ["param1"] = 15, ["z"] = 10, ["name"] = "default:grass_2"}, {["x"] = 14, ["meta"] = {["fields"] = {}, ["inventory"] = {}}, ["y"] = 1, ["param1"] = 15, ["z"] = 13, ["name"] = "default:grass_2"}, {["x"] = 14, ["meta"] = {["fields"] = {}, ["inventory"] = {}}, ["param2"] = 2, ["y"] = 1, ["param1"] = 14, ["z"] = 14, ["name"] = "cityscape:park_bench"}, {["x"] = 14, ["meta"] = {["fields"] = {}, ["inventory"] = {}}, ["y"] = 1, ["param1"] = 15, ["z"] = 15, ["name"] = "default:grass_1"}, {["x"] = 14, ["meta"] = {["fields"] = {}, ["inventory"] = {}}, ["param2"] = 3, ["y"] = 1, ["param1"] = 15, ["z"] = 16, ["name"] = "trunks:twig_12"}, {["x"] = 14, ["meta"] = {["fields"] = {}, ["inventory"] = {}}, ["y"] = 1, ["param1"] = 14, ["z"] = 17, ["name"] = "youngtrees:youngtree_top"}, {["x"] = 14, ["meta"] = {["fields"] = {}, ["inventory"] = {}}, ["y"] = 1, ["param1"] = 15, ["z"] = 18, ["name"] = "default:grass_5"}, {["x"] = 14, ["meta"] = {["fields"] = {}, ["inventory"] = {}}, ["param2"] = 2, ["y"] = 1, ["param1"] = 15, ["z"] = 19, ["name"] = "trunks:twig_12"}, {["x"] = 14, ["meta"] = {["fields"] = {}, ["inventory"] = {}}, ["y"] = 1, ["param1"] = 15, ["z"] = 20, ["name"] = "default:grass_2"}, {["x"] = 14, ["meta"] = {["fields"] = {}, ["inventory"] = {}}, ["param2"] = 3, ["y"] = 1, ["param1"] = 15, ["z"] = 21, ["name"] = "trunks:twig_9"}, {["x"] = 14, ["meta"] = {["fields"] = {}, ["inventory"] = {}}, ["y"] = 1, ["param1"] = 15, ["z"] = 22, ["name"] = "default:grass_1"}, {["x"] = 15, ["meta"] = {["fields"] = {}, ["inventory"] = {}}, ["y"] = 0, ["z"] = 0, ["name"] = "cityscape:road"}, {["x"] = 15, ["meta"] = {["fields"] = {}, ["inventory"] = {}}, ["y"] = 0, ["z"] = 1, ["name"] = "cityscape:road"}, {["x"] = 15, ["meta"] = {["fields"] = {}, ["inventory"] = {}}, ["y"] = 0, ["z"] = 2, ["name"] = "cityscape:road"}, {["x"] = 15, ["meta"] = {["fields"] = {}, ["inventory"] = {}}, ["y"] = 0, ["z"] = 3, ["name"] = "cityscape:road"}, {["x"] = 15, ["meta"] = {["fields"] = {}, ["inventory"] = {}}, ["y"] = 0, ["z"] = 4, ["name"] = "cityscape:road"}, {["x"] = 15, ["meta"] = {["fields"] = {}, ["inventory"] = {}}, ["y"] = 0, ["z"] = 5, ["name"] = "cityscape:sidewalk"}, {["x"] = 15, ["meta"] = {["fields"] = {}, ["inventory"] = {}}, ["y"] = 0, ["z"] = 6, ["name"] = "cityscape:sidewalk"}, {["x"] = 15, ["meta"] = {["fields"] = {}, ["inventory"] = {}}, ["y"] = 0, ["z"] = 7, ["name"] = "default:dirt_with_grass"}, {["x"] = 15, ["meta"] = {["fields"] = {}, ["inventory"] = {}}, ["y"] = 0, ["z"] = 8, ["name"] = "default:dirt_with_grass"}, {["x"] = 15, ["meta"] = {["fields"] = {}, ["inventory"] = {}}, ["y"] = 0, ["z"] = 9, ["name"] = "default:dirt_with_grass"}, {["x"] = 15, ["meta"] = {["fields"] = {}, ["inventory"] = {}}, ["y"] = 0, ["z"] = 10, ["name"] = "default:dirt_with_grass"}, {["x"] = 15, ["meta"] = {["fields"] = {}, ["inventory"] = {}}, ["y"] = 0, ["z"] = 11, ["name"] = "default:dirt_with_grass"}, {["x"] = 15, ["meta"] = {["fields"] = {}, ["inventory"] = {}}, ["y"] = 0, ["z"] = 12, ["name"] = "default:dirt_with_grass"}, {["x"] = 15, ["meta"] = {["fields"] = {}, ["inventory"] = {}}, ["y"] = 0, ["z"] = 13, ["name"] = "default:dirt_with_grass"}, {["x"] = 15, ["meta"] = {["fields"] = {}, ["inventory"] = {}}, ["y"] = 0, ["z"] = 14, ["name"] = "default:dirt_with_grass"}, {["x"] = 15, ["meta"] = {["fields"] = {}, ["inventory"] = {}}, ["y"] = 0, ["z"] = 15, ["name"] = "default:dirt_with_grass"}, {["x"] = 15, ["meta"] = {["fields"] = {}, ["inventory"] = {}}, ["y"] = 0, ["z"] = 16, ["name"] = "default:dirt_with_grass"}, {["x"] = 15, ["meta"] = {["fields"] = {}, ["inventory"] = {}}, ["y"] = 0, ["z"] = 17, ["name"] = "default:dirt_with_grass"}, {["x"] = 15, ["meta"] = {["fields"] = {}, ["inventory"] = {}}, ["y"] = 0, ["z"] = 18, ["name"] = "default:dirt_with_grass"}, {["x"] = 15, ["meta"] = {["fields"] = {}, ["inventory"] = {}}, ["y"] = 0, ["z"] = 19, ["name"] = "default:dirt_with_grass"}, {["x"] = 15, ["meta"] = {["fields"] = {}, ["inventory"] = {}}, ["y"] = 0, ["z"] = 20, ["name"] = "default:dirt_with_grass"}, {["x"] = 15, ["meta"] = {["fields"] = {}, ["inventory"] = {}}, ["y"] = 0, ["z"] = 21, ["name"] = "default:dirt_with_grass"}, {["x"] = 15, ["meta"] = {["fields"] = {}, ["inventory"] = {}}, ["y"] = 0, ["z"] = 22, ["name"] = "default:dirt_with_grass"},