5:return {{["x"] = 1, ["meta"] = {["fields"] = {}, ["inventory"] = {}}, ["param2"] = 17, ["y"] = 6, ["param1"] = 14, ["z"] = 44, ["name"] = "rainbow:slope_wood_yellow_outer_cut"}, {["x"] = 1, ["meta"] = {["fields"] = {}, ["inventory"] = {}}, ["param2"] = 17, ["y"] = 6, ["param1"] = 14, ["z"] = 45, ["name"] = "rainbow:slope_wood_yellow"}, {["x"] = 1, ["meta"] = {["fields"] = {}, ["inventory"] = {}}, ["param2"] = 23, ["y"] = 6, ["param1"] = 14, ["z"] = 46, ["name"] = "rainbow:slope_wood_yellow_outer_cut"}, {["x"] = 1, ["meta"] = {["fields"] = {}, ["inventory"] = {}}, ["param2"] = 9, ["y"] = 7, ["param1"] = 14, ["z"] = 44, ["name"] = "rainbow:slope_wood_yellow"}, {["x"] = 1, ["meta"] = {["fields"] = {}, ["inventory"] = {}}, ["y"] = 7, ["z"] = 45, ["name"] = "rainbow:wood_yellow"}, {["x"] = 1, ["meta"] = {["fields"] = {}, ["inventory"] = {}}, ["param2"] = 5, ["y"] = 7, ["param1"] = 14, ["z"] = 46, ["name"] = "rainbow:slope_wood_yellow"}, {["x"] = 1, ["meta"] = {["fields"] = {}, ["inventory"] = {}}, ["param2"] = 1, ["y"] = 8, ["param1"] = 14, ["z"] = 44, ["name"] = "rainbow:slope_wood_yellow_outer_cut"}, {["x"] = 1, ["meta"] = {["fields"] = {}, ["inventory"] = {}}, ["param2"] = 1, ["y"] = 8, ["param1"] = 14, ["z"] = 45, ["name"] = "rainbow:slope_wood_yellow"}, {["x"] = 1, ["meta"] = {["fields"] = {}, ["inventory"] = {}}, ["param2"] = 2, ["y"] = 8, ["param1"] = 14, ["z"] = 46, ["name"] = "rainbow:slope_wood_yellow_outer_cut"}, {["x"] = 2, ["meta"] = {["fields"] = {}, ["inventory"] = {}}, ["param2"] = 20, ["y"] = 3, ["param1"] = 14, ["z"] = 43, ["name"] = "rainbow:slope_wood_red"}, {["x"] = 2, ["meta"] = {["fields"] = {}, ["inventory"] = {}}, ["y"] = 3, ["z"] = 44, ["name"] = "rainbow:wood_red"}, {["x"] = 2, ["meta"] = {["fields"] = {}, ["inventory"] = {}}, ["y"] = 3, ["z"] = 45, ["name"] = "rainbow:wood_red"}, {["x"] = 2, ["meta"] = {["fields"] = {}, ["inventory"] = {}}, ["param2"] = 22, ["y"] = 3, ["param1"] = 13, ["z"] = 46, ["name"] = "rainbow:slope_wood_red"}, {["x"] = 2, ["meta"] = {["fields"] = {}, ["inventory"] = {}}, ["y"] = 4, ["z"] = 43, ["name"] = "rainbow:wood_red"}, {["x"] = 2, ["meta"] = {["fields"] = {}, ["inventory"] = {}}, ["y"] = 4, ["z"] = 44, ["name"] = "rainbow:wood_red"}, {["x"] = 2, ["meta"] = {["fields"] = {}, ["inventory"] = {}}, ["y"] = 4, ["z"] = 45, ["name"] = "rainbow:wood_red"}, {["x"] = 2, ["meta"] = {["fields"] = {}, ["inventory"] = {}}, ["y"] = 4, ["z"] = 46, ["name"] = "rainbow:wood_red"}, {["x"] = 2, ["meta"] = {["fields"] = {}, ["inventory"] = {}}, ["param2"] = 22, ["y"] = 4, ["param1"] = 14, ["z"] = 47, ["name"] = "rainbow:slope_wood_red"}, {["x"] = 2, ["meta"] = {["fields"] = {}, ["inventory"] = {}}, ["y"] = 5, ["z"] = 40, ["name"] = "rainbow:wood_yellow"}, {["x"] = 2, ["meta"] = {["fields"] = {}, ["inventory"] = {}}, ["param2"] = 22, ["y"] = 5, ["param1"] = 14, ["z"] = 41, ["name"] = "rainbow:slope_wood_red"}, {["x"] = 2, ["meta"] = {["fields"] = {}, ["inventory"] = {}}, ["y"] = 5, ["param1"] = 14, ["z"] = 43, ["name"] = "rainbow:slope_wood_red"}, {["x"] = 2, ["meta"] = {["fields"] = {}, ["inventory"] = {}}, ["y"] = 5, ["z"] = 44, ["name"] = "rainbow:wood_red"}, {["x"] = 2, ["meta"] = {["fields"] = {}, ["inventory"] = {}}, ["y"] = 5, ["z"] = 45, ["name"] = "rainbow:wood_darkred"}, {["x"] = 2, ["meta"] = {["fields"] = {}, ["inventory"] = {}}, ["y"] = 5, ["z"] = 46, ["name"] = "rainbow:wood_red"}, {["x"] = 2, ["meta"] = {["fields"] = {}, ["inventory"] = {}}, ["param2"] = 20, ["y"] = 5, ["z"] = 47, ["name"] = "rainbow:wood_red"}, {["x"] = 2, ["meta"] = {["fields"] = {}, ["inventory"] = {}}, ["param2"] = 6, ["y"] = 5, ["param1"] = 14, ["z"] = 48, ["name"] = "rainbow:slope_wood_red_half"}, {["x"] = 2, ["meta"] = {["fields"] = {}, ["inventory"] = {}}, ["y"] = 6, ["z"] = 40, ["name"] = "rainbow:wood_yellow"}, {["x"] = 2, ["meta"] = {["fields"] = {}, ["inventory"] = {}}, ["y"] = 6, ["z"] = 41, ["name"] = "rainbow:wood_red"}, {["x"] = 2, ["meta"] = {["fields"] = {}, ["inventory"] = {}}, ["param2"] = 22, ["y"] = 6, ["param1"] = 14, ["z"] = 42, ["name"] = "rainbow:slope_wood_red"}, {["x"] = 2, ["meta"] = {["fields"] = {}, ["inventory"] = {}}, ["param2"] = 20, ["y"] = 6, ["param1"] = 14, ["z"] = 43, ["name"] = "rainbow:slope_wood_red"}, {["x"] = 2, ["meta"] = {["fields"] = {}, ["inventory"] = {}}, ["y"] = 6, ["z"] = 44, ["name"] = "rainbow:wood_darkred"}, {["x"] = 2, ["meta"] = {["fields"] = {}, ["inventory"] = {}}, ["y"] = 6, ["z"] = 45, ["name"] = "rainbow:wood_red"}, {["x"] = 2, ["meta"] = {["fields"] = {}, ["inventory"] = {}}, ["y"] = 6, ["z"] = 46, ["name"] = "rainbow:wood_darkred"}, {["x"] = 2, ["meta"] = {["fields"] = {}, ["inventory"] = {}}, ["y"] = 6, ["z"] = 47, ["name"] = "rainbow:wood_red"}, {["x"] = 2, ["meta"] = {["fields"] = {}, ["inventory"] = {}}, ["param2"] = 6, ["y"] = 6, ["param1"] = 14, ["z"] = 48, ["name"] = "rainbow:slope_wood_red_half_raised"}, {["x"] = 2, ["meta"] = {["fields"] = {}, ["inventory"] = {}}, ["param2"] = 10, ["y"] = 7, ["param1"] = 14, ["z"] = 40, ["name"] = "rainbow:slope_wood_yellow_half_raised"}, {["x"] = 2, ["meta"] = {["fields"] = {}, ["inventory"] = {}}, ["y"] = 7, ["z"] = 41, ["name"] = "rainbow:wood_red"}, {["x"] = 2, ["meta"] = {["fields"] = {}, ["inventory"] = {}}, ["y"] = 7, ["z"] = 42, ["name"] = "rainbow:wood_red"}, {["x"] = 2, ["meta"] = {["fields"] = {}, ["inventory"] = {}}, ["y"] = 7, ["z"] = 43, ["name"] = "rainbow:wood_darkred"}, {["x"] = 2, ["meta"] = {["fields"] = {}, ["inventory"] = {}}, ["y"] = 7, ["z"] = 44, ["name"] = "rainbow:wood_red"}, {["x"] = 2, ["meta"] = {["fields"] = {}, ["inventory"] = {}}, ["y"] = 7, ["z"] = 45, ["name"] = "rainbow:wood_red"}, {["x"] = 2, ["meta"] = {["fields"] = {}, ["inventory"] = {}}, ["y"] = 7, ["z"] = 46, ["name"] = "rainbow:wood_red"}, {["x"] = 2, ["meta"] = {["fields"] = {}, ["inventory"] = {}}, ["y"] = 7, ["z"] = 47, ["name"] = "rainbow:wood_darkred"}, {["x"] = 2, ["meta"] = {["fields"] = {}, ["inventory"] = {}}, ["y"] = 7, ["z"] = 48, ["name"] = "rainbow:wood_red"}, {["x"] = 2, ["meta"] = {["fields"] = {}, ["inventory"] = {}}, ["param2"] = 6, ["y"] = 7, ["param1"] = 14, ["z"] = 49, ["name"] = "rainbow:slope_wood_red_half"}, {["x"] = 2, ["meta"] = {["fields"] = {}, ["inventory"] = {}}, ["param2"] = 10, ["y"] = 8, ["param1"] = 14, ["z"] = 40, ["name"] = "rainbow:slope_wood_yellow_half"}, {["x"] = 2, ["meta"] = {["fields"] = {}, ["inventory"] = {}}, ["y"] = 8, ["z"] = 41, ["name"] = "rainbow:wood_yellow"}, {["x"] = 2, ["meta"] = {["fields"] = {}, ["inventory"] = {}}, ["y"] = 8, ["z"] = 42, ["name"] = "rainbow:wood_red"}, {["x"] = 2, ["meta"] = {["fields"] = {}, ["inventory"] = {}}, ["y"] = 8, ["z"] = 43, ["name"] = "rainbow:wood_red"}, {["x"] = 2, ["meta"] = {["fields"] = {}, ["inventory"] = {}}, ["y"] = 8, ["z"] = 44, ["name"] = "rainbow:wood_darkred"}, {["x"] = 2, ["meta"] = {["fields"] = {}, ["inventory"] = {}}, ["y"] = 8, ["z"] = 45, ["name"] = "rainbow:wood_red"}, {["x"] = 2, ["meta"] = {["fields"] = {}, ["inventory"] = {}}, ["y"] = 8, ["z"] = 46, ["name"] = "rainbow:wood_darkred"}, {["x"] = 2, ["meta"] = {["fields"] = {}, ["inventory"] = {}}, ["y"] = 8, ["z"] = 47, ["name"] = "rainbow:wood_red"}, {["x"] = 2, ["meta"] = {["fields"] = {}, ["inventory"] = {}}, ["y"] = 8, ["z"] = 48, ["name"] = "rainbow:wood_red"}, {["x"] = 2, ["meta"] = {["fields"] = {}, ["inventory"] = {}}, ["param2"] = 6, ["y"] = 8, ["param1"] = 14, ["z"] = 49, ["name"] = "rainbow:slope_wood_red_half_raised"}, {["x"] = 2, ["meta"] = {["fields"] = {}, ["inventory"] = {}}, ["y"] = 9, ["param1"] = 14, ["z"] = 41, ["name"] = "rainbow:slope_wood_yellow"}, {["x"] = 2, ["meta"] = {["fields"] = {}, ["inventory"] = {}}, ["y"] = 9, ["z"] = 42, ["name"] = "rainbow:wood_yellow"}, {["x"] = 2, ["meta"] = {["fields"] = {}, ["inventory"] = {}}, ["y"] = 9, ["z"] = 43, ["name"] = "rainbow:wood_red"}, {["x"] = 2, ["meta"] = {["fields"] = {}, ["inventory"] = {}}, ["y"] = 9, ["z"] = 44, ["name"] = "rainbow:wood_red"}, {["x"] = 2, ["meta"] = {["fields"] = {}, ["inventory"] = {}}, ["y"] = 9, ["z"] = 45, ["name"] = "rainbow:wood_darkred"}, {["x"] = 2, ["meta"] = {["fields"] = {}, ["inventory"] = {}}, ["y"] = 9, ["param1"] = 14, ["z"] = 46, ["name"] = "rainbow:slope_wood_red"}, {["x"] = 2, ["meta"] = {["fields"] = {}, ["inventory"] = {}}, ["y"] = 9, ["z"] = 47, ["name"] = "rainbow:wood_red"}, {["x"] = 2, ["meta"] = {["fields"] = {}, ["inventory"] = {}}, ["y"] = 9, ["z"] = 48, ["name"] = "rainbow:wood_red"}, {["x"] = 2, ["meta"] = {["fields"] = {}, ["inventory"] = {}}, ["y"] = 9, ["z"] = 49, ["name"] = "rainbow:wood_red"}, {["x"] = 2, ["meta"] = {["fields"] = {}, ["inventory"] = {}}, ["param2"] = 6, ["y"] = 9, ["param1"] = 14, ["z"] = 50, ["name"] = "rainbow:slope_wood_red_half"}, {["x"] = 2, ["meta"] = {["fields"] = {}, ["inventory"] = {}}, ["y"] = 10, ["param1"] = 14, ["z"] = 42, ["name"] = "rainbow:slope_wood_yellow_half"}, {["x"] = 2, ["meta"] = {["fields"] = {}, ["inventory"] = {}}, ["y"] = 10, ["param1"] = 30, ["z"] = 43, ["name"] = "rainbow:slope_wood_yellow_half_raised"}, {["x"] = 2, ["meta"] = {["fields"] = {}, ["inventory"] = {}}, ["y"] = 10, ["z"] = 44, ["name"] = "rainbow:wood_red"}, {["x"] = 2, ["meta"] = {["fields"] = {}, ["inventory"] = {}}, ["y"] = 10, ["z"] = 45, ["name"] = "rainbow:wood_red"}, {["x"] = 2, ["meta"] = {["fields"] = {}, ["inventory"] = {}}, ["y"] = 10, ["param1"] = 14, ["z"] = 47, ["name"] = "rainbow:slope_wood_red"}, {["x"] = 2, ["meta"] = {["fields"] = {}, ["inventory"] = {}}, ["y"] = 10, ["z"] = 48, ["name"] = "rainbow:wood_red"}, {["x"] = 2, ["meta"] = {["fields"] = {}, ["inventory"] = {}}, ["y"] = 10, ["z"] = 49, ["name"] = "rainbow:wood_red"}, {["x"] = 2, ["meta"] = {["fields"] = {}, ["inventory"] = {}}, ["param2"] = 6, ["y"] = 10, ["param1"] = 14, ["z"] = 50, ["name"] = "rainbow:slope_wood_red_half_raised"}, {["x"] = 2, ["meta"] = {["fields"] = {}, ["inventory"] = {}}, ["y"] = 11, ["param1"] = 62, ["z"] = 44, ["name"] = "rainbow:slope_wood_yellow"}, {["x"] = 2, ["meta"] = {["fields"] = {}, ["inventory"] = {}}, ["y"] = 11, ["z"] = 45, ["name"] = "rainbow:wood_red"}, {["x"] = 2, ["meta"] = {["fields"] = {}, ["inventory"] = {}}, ["y"] = 11, ["param1"] = 14, ["z"] = 48, ["name"] = "rainbow:slope_wood_red"}, {["x"] = 2, ["meta"] = {["fields"] = {}, ["inventory"] = {}}, ["y"] = 11, ["z"] = 49, ["name"] = "rainbow:wood_red"}, {["x"] = 2, ["meta"] = {["fields"] = {}, ["inventory"] = {}}, ["y"] = 11, ["z"] = 50, ["name"] = "rainbow:wood_red"}, {["x"] = 2, ["meta"] = {["fields"] = {}, ["inventory"] = {}}, ["param2"] = 6, ["y"] = 11, ["param1"] = 14, ["z"] = 51, ["name"] = "rainbow:slope_wood_red_half"}, {["x"] = 2, ["meta"] = {["fields"] = {}, ["inventory"] = {}}, ["param2"] = 10, ["y"] = 12, ["param1"] = 30, ["z"] = 45, ["name"] = "rainbow:slope_wood_yellow_half_raised"}, {["x"] = 2, ["meta"] = {["fields"] = {}, ["inventory"] = {}}, ["y"] = 12, ["param1"] = 14, ["z"] = 49, ["name"] = "rainbow:slope_wood_red"}, {["x"] = 2, ["meta"] = {["fields"] = {}, ["inventory"] = {}}, ["y"] = 12, ["z"] = 50, ["name"] = "rainbow:wood_red"}, {["x"] = 2, ["meta"] = {["fields"] = {}, ["inventory"] = {}}, ["param2"] = 6, ["y"] = 12, ["param1"] = 14, ["z"] = 51, ["name"] = "rainbow:slope_wood_red_half_raised"}, {["x"] = 2, ["meta"] = {["fields"] = {}, ["inventory"] = {}}, ["param2"] = 10, ["y"] = 13, ["param1"] = 14, ["z"] = 45, ["name"] = "rainbow:slope_wood_yellow_half"}, {["x"] = 2, ["meta"] = {["fields"] = {}, ["inventory"] = {}}, ["y"] = 13, ["param1"] = 14, ["z"] = 50, ["name"] = "rainbow:slope_wood_red"}, {["x"] = 2, ["meta"] = {["fields"] = {}, ["inventory"] = {}}, ["y"] = 13, ["z"] = 51, ["name"] = "rainbow:wood_red"}, {["x"] = 2, ["meta"] = {["fields"] = {}, ["inventory"] = {}}, ["param2"] = 6, ["y"] = 13, ["param1"] = 14, ["z"] = 52, ["name"] = "rainbow:slope_wood_red_half"}, {["x"] = 2, ["meta"] = {["fields"] = {}, ["inventory"] = {}}, ["y"] = 14, ["param1"] = 14, ["z"] = 51, ["name"] = "rainbow:slope_wood_red"}, {["x"] = 2, ["meta"] = {["fields"] = {}, ["inventory"] = {}}, ["param2"] = 6, ["y"] = 14, ["param1"] = 30, ["z"] = 52, ["name"] = "rainbow:slope_wood_red_half_raised"}, {["x"] = 2, ["meta"] = {["fields"] = {}, ["inventory"] = {}}, ["y"] = 15, ["param1"] = 46, ["z"] = 52, ["name"] = "rainbow:slope_wood_red"}, {["x"] = 2, ["meta"] = {["fields"] = {}, ["inventory"] = {}}, ["param2"] = 22, ["y"] = 25, ["param1"] = 239, ["z"] = 15, ["name"] = "rainbow:slope_lightcoolglass_black_half"}, {["x"] = 2, ["meta"] = {["fields"] = {}, ["inventory"] = {}}, ["y"] = 26, ["param1"] = 239, ["z"] = 15, ["name"] = "rainbow:slope_lightcoolglass_black_half_raised"}, {["x"] = 2, ["meta"] = {["fields"] = {}, ["inventory"] = {}}, ["param2"] = 22, ["y"] = 26, ["param1"] = 239, ["z"] = 16, ["name"] = "rainbow:slope_lightcoolglass_black_half_raised"}, {["x"] = 2, ["meta"] = {["fields"] = {}, ["inventory"] = {}}, ["param2"] = 22, ["y"] = 26, ["param1"] = 239, ["z"] = 17, ["name"] = "rainbow:slope_lightcoolglass_black_half"}, {["x"] = 2, ["meta"] = {["fields"] = {}, ["inventory"] = {}}, ["y"] = 27, ["param1"] = 239, ["z"] = 16, ["name"] = "rainbow:slope_lightcoolglass_black_half"}, {["x"] = 2, ["meta"] = {["fields"] = {}, ["inventory"] = {}}, ["y"] = 27, ["param1"] = 239, ["z"] = 17, ["name"] = "rainbow:slope_lightcoolglass_black_half_raised"}, {["x"] = 2, ["meta"] = {["fields"] = {}, ["inventory"] = {}}, ["param2"] = 22, ["y"] = 27, ["param1"] = 239, ["z"] = 18, ["name"] = "rainbow:slope_lightcoolglass_black_half_raised"}, {["x"] = 2, ["meta"] = {["fields"] = {}, ["inventory"] = {}}, ["param2"] = 22, ["y"] = 27, ["param1"] = 239, ["z"] = 19, ["name"] = "rainbow:slope_lightcoolglass_black_half"}, {["x"] = 2, ["meta"] = {["fields"] = {}, ["inventory"] = {}}, ["y"] = 28, ["param1"] = 239, ["z"] = 18, ["name"] = "rainbow:slope_lightcoolglass_black_half"}, {["x"] = 2, ["meta"] = {["fields"] = {}, ["inventory"] = {}}, ["y"] = 28, ["param1"] = 239, ["z"] = 19, ["name"] = "rainbow:slope_lightcoolglass_black_half_raised"}, {["x"] = 2, ["meta"] = {["fields"] = {}, ["inventory"] = {}}, ["param2"] = 22, ["y"] = 28, ["param1"] = 239, ["z"] = 20, ["name"] = "rainbow:slope_lightcoolglass_black_half_raised"}, {["x"] = 2, ["meta"] = {["fields"] = {}, ["inventory"] = {}}, ["param2"] = 22, ["y"] = 28, ["param1"] = 239, ["z"] = 21, ["name"] = "rainbow:slope_lightcoolglass_black_half"}, {["x"] = 2, ["meta"] = {["fields"] = {}, ["inventory"] = {}}, ["y"] = 29, ["param1"] = 239, ["z"] = 20, ["name"] = "rainbow:slope_lightcoolglass_black_half"}, {["x"] = 2, ["meta"] = {["fields"] = {}, ["inventory"] = {}}, ["y"] = 29, ["param1"] = 239, ["z"] = 21, ["name"] = "rainbow:slope_lightcoolglass_black_half_raised"}, {["x"] = 2, ["meta"] = {["fields"] = {}, ["inventory"] = {}}, ["param2"] = 22, ["y"] = 29, ["param1"] = 239, ["z"] = 22, ["name"] = "rainbow:slope_lightcoolglass_black_half_raised"}, {["x"] = 2, ["meta"] = {["fields"] = {}, ["inventory"] = {}}, ["param2"] = 22, ["y"] = 29, ["param1"] = 239, ["z"] = 23, ["name"] = "rainbow:slope_lightcoolglass_black_half"}, {["x"] = 2, ["meta"] = {["fields"] = {}, ["inventory"] = {}}, ["y"] = 30, ["param1"] = 239, ["z"] = 22, ["name"] = "rainbow:slope_lightcoolglass_black_half"}, {["x"] = 2, ["meta"] = {["fields"] = {}, ["inventory"] = {}}, ["y"] = 30, ["param1"] = 239, ["z"] = 23, ["name"] = "rainbow:slope_lightcoolglass_black_half_raised"}, {["x"] = 2, ["meta"] = {["fields"] = {}, ["inventory"] = {}}, ["param2"] = 22, ["y"] = 30, ["param1"] = 239, ["z"] = 24, ["name"] = "rainbow:slope_lightcoolglass_black_half_raised"}, {["x"] = 2, ["meta"] = {["fields"] = {}, ["inventory"] = {}}, ["param2"] = 22, ["y"] = 30, ["param1"] = 239, ["z"] = 25, ["name"] = "rainbow:slope_lightcoolglass_black_half"}, {["x"] = 2, ["meta"] = {["fields"] = {}, ["inventory"] = {}}, ["y"] = 31, ["param1"] = 239, ["z"] = 24, ["name"] = "rainbow:slope_lightcoolglass_black_half"}, {["x"] = 2, ["meta"] = {["fields"] = {}, ["inventory"] = {}}, ["y"] = 31, ["param1"] = 239, ["z"] = 25, ["name"] = "rainbow:slope_lightcoolglass_black_half_raised"}, {["x"] = 2, ["meta"] = {["fields"] = {}, ["inventory"] = {}}, ["param2"] = 22, ["y"] = 31, ["param1"] = 239, ["z"] = 26, ["name"] = "rainbow:slope_lightcoolglass_black_half_raised"}, {["x"] = 2, ["meta"] = {["fields"] = {}, ["inventory"] = {}}, ["param2"] = 22, ["y"] = 31, ["param1"] = 239, ["z"] = 27, ["name"] = "rainbow:slope_lightcoolglass_black_half"}, {["x"] = 2, ["meta"] = {["fields"] = {}, ["inventory"] = {}}, ["y"] = 32, ["param1"] = 239, ["z"] = 26, ["name"] = "rainbow:slope_lightcoolglass_black_half"}, {["x"] = 2, ["meta"] = {["fields"] = {}, ["inventory"] = {}}, ["y"] = 32, ["param1"] = 239, ["z"] = 27, ["name"] = "rainbow:slope_lightcoolglass_black_half_raised"}, {["x"] = 2, ["meta"] = {["fields"] = {}, ["inventory"] = {}}, ["param2"] = 22, ["y"] = 32, ["param1"] = 239, ["z"] = 28, ["name"] = "rainbow:slope_lightcoolglass_black_half_raised"}, {["x"] = 2, ["meta"] = {["fields"] = {}, ["inventory"] = {}}, ["y"] = 33, ["param1"] = 239, ["z"] = 28, ["name"] = "rainbow:slope_lightcoolglass_black_half"}, {["x"] = 3, ["meta"] = {["fields"] = {}, ["inventory"] = {}}, ["y"] = 6, ["z"] = 44, ["name"] = "rainbow:wood_black"}, {["x"] = 3, ["meta"] = {["fields"] = {}, ["inventory"] = {}}, ["y"] = 6, ["z"] = 46, ["name"] = "rainbow:wood_black"}, {["x"] = 3, ["meta"] = {["fields"] = {}, ["inventory"] = {}}, ["y"] = 7, ["z"] = 44, ["name"] = "rainbow:wood_black"}, {["x"] = 3, ["meta"] = {["fields"] = {}, ["inventory"] = {}}, ["y"] = 7, ["z"] = 45, ["name"] = "rainbow:stoneblock_yellow"}, {["x"] = 3, ["meta"] = {["fields"] = {}, ["inventory"] = {}}, ["y"] = 7, ["z"] = 46, ["name"] = "rainbow:wood_black"}, {["x"] = 3, ["meta"] = {["fields"] = {}, ["inventory"] = {}}, ["y"] = 8, ["z"] = 44, ["name"] = "rainbow:wood_black"}, {["x"] = 3, ["meta"] = {["fields"] = {}, ["inventory"] = {}}, ["y"] = 8, ["z"] = 46, ["name"] = "rainbow:wood_black"}, {["x"] = 3, ["meta"] = {["fields"] = {}, ["inventory"] = {}}, ["param2"] = 22, ["y"] = 26, ["param1"] = 239, ["z"] = 16, ["name"] = "rainbow:slope_lightcoolglass_white_half_raised"}, {["x"] = 3, ["meta"] = {["fields"] = {}, ["inventory"] = {}}, ["param2"] = 22, ["y"] = 26, ["param1"] = 239, ["z"] = 17, ["name"] = "rainbow:slope_lightcoolglass_white_half"}, {["x"] = 3, ["meta"] = {["fields"] = {}, ["inventory"] = {}}, ["y"] = 27, ["param1"] = 239, ["z"] = 16, ["name"] = "rainbow:slope_lightcoolglass_white_half"}, {["x"] = 3, ["meta"] = {["fields"] = {}, ["inventory"] = {}}, ["y"] = 27, ["param1"] = 239, ["z"] = 17, ["name"] = "rainbow:slope_lightcoolglass_white_half_raised"}, {["x"] = 3, ["meta"] = {["fields"] = {}, ["inventory"] = {}}, ["param2"] = 22, ["y"] = 27, ["param1"] = 239, ["z"] = 18, ["name"] = "rainbow:slope_lightcoolglass_white_half_raised"}, {["x"] = 3, ["meta"] = {["fields"] = {}, ["inventory"] = {}}, ["param2"] = 22, ["y"] = 27, ["param1"] = 239, ["z"] = 19, ["name"] = "rainbow:slope_lightcoolglass_white_half"}, {["x"] = 3, ["meta"] = {["fields"] = {}, ["inventory"] = {}}, ["y"] = 28, ["param1"] = 239, ["z"] = 18, ["name"] = "rainbow:slope_lightcoolglass_white_half"}, {["x"] = 3, ["meta"] = {["fields"] = {}, ["inventory"] = {}}, ["y"] = 28, ["param1"] = 239, ["z"] = 19, ["name"] = "rainbow:slope_lightcoolglass_white_half_raised"}, {["x"] = 3, ["meta"] = {["fields"] = {}, ["inventory"] = {}}, ["param2"] = 22, ["y"] = 28, ["param1"] = 239, ["z"] = 20, ["name"] = "rainbow:slope_lightcoolglass_darkred_half_raised"}, {["x"] = 3, ["meta"] = {["fields"] = {}, ["inventory"] = {}}, ["param2"] = 22, ["y"] = 28, ["param1"] = 239, ["z"] = 21, ["name"] = "rainbow:slope_lightcoolglass_darkred_half"}, {["x"] = 3, ["meta"] = {["fields"] = {}, ["inventory"] = {}}, ["y"] = 29, ["param1"] = 239, ["z"] = 20, ["name"] = "rainbow:slope_lightcoolglass_white_half"}, {["x"] = 3, ["meta"] = {["fields"] = {}, ["inventory"] = {}}, ["y"] = 29, ["param1"] = 239, ["z"] = 21, ["name"] = "rainbow:slope_lightcoolglass_white_half_raised"}, {["x"] = 3, ["meta"] = {["fields"] = {}, ["inventory"] = {}}, ["param2"] = 22, ["y"] = 29, ["param1"] = 239, ["z"] = 22, ["name"] = "rainbow:slope_lightcoolglass_darkred_half_raised"}, {["x"] = 3, ["meta"] = {["fields"] = {}, ["inventory"] = {}}, ["param2"] = 22, ["y"] = 29, ["param1"] = 239, ["z"] = 23, ["name"] = "rainbow:slope_lightcoolglass_darkred_half"}, {["x"] = 3, ["meta"] = {["fields"] = {}, ["inventory"] = {}}, ["y"] = 30, ["param1"] = 239, ["z"] = 22, ["name"] = "rainbow:slope_lightcoolglass_white_half"}, {["x"] = 3, ["meta"] = {["fields"] = {}, ["inventory"] = {}}, ["y"] = 30, ["param1"] = 239, ["z"] = 23, ["name"] = "rainbow:slope_lightcoolglass_white_half_raised"}, {["x"] = 3, ["meta"] = {["fields"] = {}, ["inventory"] = {}}, ["param2"] = 22, ["y"] = 30, ["param1"] = 239, ["z"] = 24, ["name"] = "rainbow:slope_lightcoolglass_darkred_half_raised"}, {["x"] = 3, ["meta"] = {["fields"] = {}, ["inventory"] = {}}, ["param2"] = 22, ["y"] = 30, ["param1"] = 239, ["z"] = 25, ["name"] = "rainbow:slope_lightcoolglass_white_half"}, {["x"] = 3, ["meta"] = {["fields"] = {}, ["inventory"] = {}}, ["y"] = 31, ["param1"] = 239, ["z"] = 24, ["name"] = "rainbow:slope_lightcoolglass_white_half"}, {["x"] = 3, ["meta"] = {["fields"] = {}, ["inventory"] = {}}, ["y"] = 31, ["param1"] = 239, ["z"] = 25, ["name"] = "rainbow:slope_lightcoolglass_white_half_raised"}, {["x"] = 3, ["meta"] = {["fields"] = {}, ["inventory"] = {}}, ["param2"] = 22, ["y"] = 31, ["param1"] = 239, ["z"] = 26, ["name"] = "rainbow:slope_lightcoolglass_white_half_raised"}, {["x"] = 3, ["meta"] = {["fields"] = {}, ["inventory"] = {}}, ["param2"] = 22, ["y"] = 31, ["param1"] = 239, ["z"] = 27, ["name"] = "rainbow:slope_lightcoolglass_white_half"}, {["x"] = 3, ["meta"] = {["fields"] = {}, ["inventory"] = {}}, ["y"] = 32, ["param1"] = 239, ["z"] = 26, ["name"] = "rainbow:slope_lightcoolglass_white_half"}, {["x"] = 3, ["meta"] = {["fields"] = {}, ["inventory"] = {}}, ["y"] = 32, ["param1"] = 239, ["z"] = 27, ["name"] = "rainbow:slope_lightcoolglass_white_half_raised"}, {["x"] = 4, ["meta"] = {["fields"] = {}, ["inventory"] = {}}, ["y"] = 7, ["z"] = 45, ["name"] = "rainbow:stoneblock_yellow"}, {["x"] = 4, ["meta"] = {["fields"] = {}, ["inventory"] = {}}, ["param2"] = 22, ["y"] = 26, ["param1"] = 239, ["z"] = 16, ["name"] = "rainbow:slope_lightcoolglass_white_half_raised"}, {["x"] = 4, ["meta"] = {["fields"] = {}, ["inventory"] = {}}, ["param2"] = 22, ["y"] = 26, ["param1"] = 239, ["z"] = 17, ["name"] = "rainbow:slope_lightcoolglass_white_half"}, {["x"] = 4, ["meta"] = {["fields"] = {}, ["inventory"] = {}}, ["y"] = 27, ["param1"] = 239, ["z"] = 16, ["name"] = "rainbow:slope_lightcoolglass_white_half"}, {["x"] = 4, ["meta"] = {["fields"] = {}, ["inventory"] = {}}, ["y"] = 27, ["param1"] = 239, ["z"] = 17, ["name"] = "rainbow:slope_lightcoolglass_white_half_raised"}, {["x"] = 4, ["meta"] = {["fields"] = {}, ["inventory"] = {}}, ["param2"] = 22, ["y"] = 27, ["param1"] = 239, ["z"] = 18, ["name"] = "rainbow:slope_lightcoolglass_white_half_raised"}, {["x"] = 4, ["meta"] = {["fields"] = {}, ["inventory"] = {}}, ["param2"] = 22, ["y"] = 27, ["param1"] = 239, ["z"] = 19, ["name"] = "rainbow:slope_lightcoolglass_white_half"}, {["x"] = 4, ["meta"] = {["fields"] = {}, ["inventory"] = {}}, ["y"] = 28, ["param1"] = 239, ["z"] = 18, ["name"] = "rainbow:slope_lightcoolglass_white_half"}, {["x"] = 4, ["meta"] = {["fields"] = {}, ["inventory"] = {}}, ["y"] = 28, ["param1"] = 239, ["z"] = 19, ["name"] = "rainbow:slope_lightcoolglass_white_half_raised"}, {["x"] = 4, ["meta"] = {["fields"] = {}, ["inventory"] = {}}, ["param2"] = 22, ["y"] = 28, ["param1"] = 239, ["z"] = 20, ["name"] = "rainbow:slope_lightcoolglass_white_half_raised"}, {["x"] = 4, ["meta"] = {["fields"] = {}, ["inventory"] = {}}, ["param2"] = 22, ["y"] = 28, ["param1"] = 239, ["z"] = 21, ["name"] = "rainbow:slope_lightcoolglass_white_half"}, {["x"] = 4, ["meta"] = {["fields"] = {}, ["inventory"] = {}}, ["y"] = 29, ["param1"] = 239, ["z"] = 20, ["name"] = "rainbow:slope_lightcoolglass_white_half"}, {["x"] = 4, ["meta"] = {["fields"] = {}, ["inventory"] = {}}, ["y"] = 29, ["param1"] = 239, ["z"] = 21, ["name"] = "rainbow:slope_lightcoolglass_white_half_raised"}, {["x"] = 4, ["meta"] = {["fields"] = {}, ["inventory"] = {}}, ["param2"] = 22, ["y"] = 29, ["param1"] = 239, ["z"] = 22, ["name"] = "rainbow:slope_lightcoolglass_white_half_raised"}, {["x"] = 4, ["meta"] = {["fields"] = {}, ["inventory"] = {}}, ["param2"] = 22, ["y"] = 29, ["param1"] = 239, ["z"] = 23, ["name"] = "rainbow:slope_lightcoolglass_white_half"}, {["x"] = 4, ["meta"] = {["fields"] = {}, ["inventory"] = {}}, ["y"] = 30, ["param1"] = 239, ["z"] = 22, ["name"] = "rainbow:slope_lightcoolglass_white_half"}, {["x"] = 4, ["meta"] = {["fields"] = {}, ["inventory"] = {}}, ["y"] = 30, ["param1"] = 239, ["z"] = 23, ["name"] = "rainbow:slope_lightcoolglass_white_half_raised"}, {["x"] = 4, ["meta"] = {["fields"] = {}, ["inventory"] = {}}, ["param2"] = 22, ["y"] = 30, ["param1"] = 239, ["z"] = 24, ["name"] = "rainbow:slope_lightcoolglass_white_half_raised"}, {["x"] = 4, ["meta"] = {["fields"] = {}, ["inventory"] = {}}, ["param2"] = 22, ["y"] = 30, ["param1"] = 239, ["z"] = 25, ["name"] = "rainbow:slope_lightcoolglass_white_half"}, {["x"] = 4, ["meta"] = {["fields"] = {}, ["inventory"] = {}}, ["y"] = 31, ["param1"] = 239, ["z"] = 24, ["name"] = "rainbow:slope_lightcoolglass_white_half"}, {["x"] = 4, ["meta"] = {["fields"] = {}, ["inventory"] = {}}, ["y"] = 31, ["param1"] = 239, ["z"] = 25, ["name"] = "rainbow:slope_lightcoolglass_white_half_raised"}, {["x"] = 4, ["meta"] = {["fields"] = {}, ["inventory"] = {}}, ["param2"] = 22, ["y"] = 31, ["param1"] = 239, ["z"] = 26, ["name"] = "rainbow:slope_lightcoolglass_white_half_raised"}, {["x"] = 4, ["meta"] = {["fields"] = {}, ["inventory"] = {}}, ["param2"] = 22, ["y"] = 31, ["param1"] = 239, ["z"] = 27, ["name"] = "rainbow:slope_lightcoolglass_white_half"}, {["x"] = 4, ["meta"] = {["fields"] = {}, ["inventory"] = {}}, ["y"] = 32, ["param1"] = 239, ["z"] = 26, ["name"] = "rainbow:slope_lightcoolglass_white_half"}, {["x"] = 4, ["meta"] = {["fields"] = {}, ["inventory"] = {}}, ["y"] = 32, ["param1"] = 239, ["z"] = 27, ["name"] = "rainbow:slope_lightcoolglass_white_half_raised"}, {["x"] = 5, ["meta"] = {["fields"] = {}, ["inventory"] = {}}, ["param2"] = 20, ["y"] = 6, ["param1"] = 14, ["z"] = 44, ["name"] = "rainbow:slope_wood_yellow"}, {["x"] = 5, ["meta"] = {["fields"] = {}, ["inventory"] = {}}, ["y"] = 6, ["z"] = 45, ["name"] = "rainbow:stoneblock_yellow"}, {["x"] = 5, ["meta"] = {["fields"] = {}, ["inventory"] = {}}, ["param2"] = 22, ["y"] = 6, ["param1"] = 14, ["z"] = 46, ["name"] = "rainbow:slope_wood_yellow"}, {["x"] = 5, ["meta"] = {["fields"] = {}, ["inventory"] = {}}, ["param2"] = 9, ["y"] = 7, ["param1"] = 14, ["z"] = 14, ["name"] = "rainbow:slope_wood_red"}, {["x"] = 5, ["meta"] = {["fields"] = {}, ["inventory"] = {}}, ["y"] = 7, ["z"] = 15, ["name"] = "rainbow:wood_red"}, {["x"] = 5, ["meta"] = {["fields"] = {}, ["inventory"] = {}}, ["y"] = 7, ["z"] = 16, ["name"] = "rainbow:wood_red"}, {["x"] = 5, ["meta"] = {["fields"] = {}, ["inventory"] = {}}, ["y"] = 7, ["z"] = 17, ["name"] = "rainbow:wood_red"}, {["x"] = 5, ["meta"] = {["fields"] = {}, ["inventory"] = {}}, ["param2"] = 18, ["y"] = 7, ["param1"] = 14, ["z"] = 18, ["name"] = "rainbow:slope_wood_red_half_raised"}, {["x"] = 5, ["meta"] = {["fields"] = {}, ["inventory"] = {}}, ["param2"] = 18, ["y"] = 7, ["param1"] = 14, ["z"] = 19, ["name"] = "rainbow:slope_wood_red_half"}, {["x"] = 5, ["meta"] = {["fields"] = {}, ["inventory"] = {}}, ["y"] = 7, ["z"] = 44, ["name"] = "rainbow:stoneblock_yellow"}, {["x"] = 5, ["meta"] = {["fields"] = {}, ["inventory"] = {}}, ["y"] = 7, ["z"] = 45, ["name"] = "rainbow:stoneblock_yellow"}, {["x"] = 5, ["meta"] = {["fields"] = {}, ["inventory"] = {}}, ["y"] = 7, ["z"] = 46, ["name"] = "rainbow:stoneblock_yellow"}, {["x"] = 5, ["meta"] = {["fields"] = {}, ["inventory"] = {}}, ["y"] = 8, ["param1"] = 30, ["z"] = 44, ["name"] = "rainbow:slope_wood_yellow"}, {["x"] = 5, ["meta"] = {["fields"] = {}, ["inventory"] = {}}, ["param2"] = 1, ["y"] = 8, ["z"] = 45, ["name"] = "rainbow:stoneblock_yellow"}, {["x"] = 5, ["meta"] = {["fields"] = {}, ["inventory"] = {}}, ["param2"] = 2, ["y"] = 8, ["param1"] = 14, ["z"] = 46, ["name"] = "rainbow:slope_wood_yellow"}, {["x"] = 5, ["meta"] = {["fields"] = {}, ["inventory"] = {}}, ["y"] = 10, ["param1"] = 46, ["z"] = 41, ["name"] = "rainbow:slope_wood_yellow"}, {["x"] = 5, ["meta"] = {["fields"] = {}, ["inventory"] = {}}, ["y"] = 10, ["z"] = 42, ["name"] = "rainbow:wood_darkred"}, {["x"] = 5, ["meta"] = {["fields"] = {}, ["inventory"] = {}}, ["y"] = 10, ["z"] = 43, ["name"] = "rainbow:wood_darkred"}, {["x"] = 5, ["meta"] = {["fields"] = {}, ["inventory"] = {}}, ["y"] = 10, ["z"] = 44, ["name"] = "rainbow:wood_darkred"}, {["x"] = 5, ["meta"] = {["fields"] = {}, ["inventory"] = {}}, ["y"] = 10, ["z"] = 45, ["name"] = "rainbow:wood_red"}, {["x"] = 5, ["meta"] = {["fields"] = {}, ["inventory"] = {}}, ["y"] = 10, ["z"] = 46, ["name"] = "rainbow:wood_red"}, {["x"] = 5, ["meta"] = {["fields"] = {}, ["inventory"] = {}}, ["y"] = 10, ["z"] = 47, ["name"] = "rainbow:wood_red"}, {["x"] = 5, ["meta"] = {["fields"] = {}, ["inventory"] = {}}, ["y"] = 10, ["z"] = 48, ["name"] = "rainbow:wood_darkred"}, {["x"] = 5, ["meta"] = {["fields"] = {}, ["inventory"] = {}}, ["y"] = 10, ["z"] = 49, ["name"] = "rainbow:wood_darkred"}, {["x"] = 5, ["meta"] = {["fields"] = {}, ["inventory"] = {}}, ["y"] = 10, ["z"] = 50, ["name"] = "rainbow:wood_darkred"}, {["x"] = 5, ["meta"] = {["fields"] = {}, ["inventory"] = {}}, ["y"] = 10, ["z"] = 51, ["name"] = "rainbow:wood_darkred"}, {["x"] = 5, ["meta"] = {["fields"] = {}, ["inventory"] = {}}, ["y"] = 10, ["z"] = 52, ["name"] = "rainbow:wood_darkred"}, {["x"] = 5, ["meta"] = {["fields"] = {}, ["inventory"] = {}}, ["y"] = 10, ["z"] = 53, ["name"] = "rainbow:wood_darkred"}, {["x"] = 5, ["meta"] = {["fields"] = {}, ["inventory"] = {}}, ["y"] = 11, ["param1"] = 78, ["z"] = 42, ["name"] = "rainbow:slab_wood_yellow_1"}, {["x"] = 5, ["meta"] = {["fields"] = {}, ["inventory"] = {}}, ["y"] = 11, ["param1"] = 94, ["z"] = 43, ["name"] = "rainbow:slab_wood_yellow_1"}, {["x"] = 5, ["meta"] = {["fields"] = {}, ["inventory"] = {}}, ["y"] = 11, ["param1"] = 110, ["z"] = 44, ["name"] = "rainbow:slope_wood_yellow"}, {["x"] = 5, ["meta"] = {["fields"] = {}, ["inventory"] = {}}, ["y"] = 11, ["z"] = 45, ["name"] = "rainbow:wood_darkred"}, {["x"] = 5, ["meta"] = {["fields"] = {}, ["inventory"] = {}}, ["y"] = 11, ["z"] = 46, ["name"] = "rainbow:wood_darkred"}, {["x"] = 5, ["meta"] = {["fields"] = {}, ["inventory"] = {}}, ["y"] = 11, ["z"] = 47, ["name"] = "rainbow:wood_darkred"}, {["x"] = 5, ["meta"] = {["fields"] = {}, ["inventory"] = {}}, ["y"] = 11, ["z"] = 48, ["name"] = "rainbow:wood_darkred"}, {["x"] = 5, ["meta"] = {["fields"] = {}, ["inventory"] = {}}, ["y"] = 11, ["z"] = 49, ["name"] = "rainbow:wood_red"}, {["x"] = 5, ["meta"] = {["fields"] = {}, ["inventory"] = {}}, ["y"] = 11, ["z"] = 50, ["name"] = "rainbow:wood_darkred"}, {["x"] = 5, ["meta"] = {["fields"] = {}, ["inventory"] = {}}, ["y"] = 11, ["z"] = 51, ["name"] = "rainbow:wood_darkred"}, {["x"] = 5, ["meta"] = {["fields"] = {}, ["inventory"] = {}}, ["y"] = 11, ["z"] = 52, ["name"] = "rainbow:wood_darkred"}, {["x"] = 5, ["meta"] = {["fields"] = {}, ["inventory"] = {}}, ["y"] = 11, ["z"] = 53, ["name"] = "rainbow:wood_darkred"}, {["x"] = 5, ["meta"] = {["fields"] = {}, ["inventory"] = {}}, ["y"] = 12, ["param1"] = 78, ["z"] = 45, ["name"] = "rainbow:slab_wood_yellow_1"}, {["x"] = 5, ["meta"] = {["fields"] = {}, ["inventory"] = {}}, ["y"] = 12, ["param1"] = 62, ["z"] = 46, ["name"] = "rainbow:slab_wood_yellow_1"}, {["x"] = 5, ["meta"] = {["fields"] = {}, ["inventory"] = {}}, ["y"] = 12, ["param1"] = 46, ["z"] = 47, ["name"] = "rainbow:slope_wood_yellow"}, {["x"] = 5, ["meta"] = {["fields"] = {}, ["inventory"] = {}}, ["y"] = 12, ["z"] = 48, ["name"] = "rainbow:wood_darkred"}, {["x"] = 5, ["meta"] = {["fields"] = {}, ["inventory"] = {}}, ["y"] = 12, ["z"] = 49, ["name"] = "rainbow:wood_darkred"}, {["x"] = 5, ["meta"] = {["fields"] = {}, ["inventory"] = {}}, ["y"] = 12, ["z"] = 50, ["name"] = "rainbow:wood_red"}, {["x"] = 5, ["meta"] = {["fields"] = {}, ["inventory"] = {}}, ["y"] = 12, ["z"] = 51, ["name"] = "rainbow:wood_red"}, {["x"] = 5, ["meta"] = {["fields"] = {}, ["inventory"] = {}}, ["y"] = 12, ["z"] = 52, ["name"] = "rainbow:wood_darkred"}, {["x"] = 5, ["meta"] = {["fields"] = {}, ["inventory"] = {}}, ["y"] = 12, ["z"] = 53, ["name"] = "rainbow:wood_darkred"}, {["x"] = 5, ["meta"] = {["fields"] = {}, ["inventory"] = {}}, ["y"] = 13, ["param1"] = 14, ["z"] = 48, ["name"] = "rainbow:slab_wood_yellow_1"}, {["x"] = 5, ["meta"] = {["fields"] = {}, ["inventory"] = {}}, ["y"] = 13, ["param1"] = 14, ["z"] = 49, ["name"] = "rainbow:slope_wood_yellow"}, {["x"] = 5, ["meta"] = {["fields"] = {}, ["inventory"] = {}}, ["y"] = 13, ["z"] = 50, ["name"] = "rainbow:wood_darkred"}, {["x"] = 5, ["meta"] = {["fields"] = {}, ["inventory"] = {}}, ["y"] = 13, ["z"] = 51, ["name"] = "rainbow:wood_darkred"}, {["x"] = 5, ["meta"] = {["fields"] = {}, ["inventory"] = {}}, ["y"] = 13, ["z"] = 52, ["name"] = "rainbow:wood_darkred"}, {["x"] = 5, ["meta"] = {["fields"] = {}, ["inventory"] = {}}, ["y"] = 13, ["z"] = 53, ["name"] = "rainbow:wood_darkred"}, {["x"] = 5, ["meta"] = {["fields"] = {}, ["inventory"] = {}}, ["y"] = 14, ["param1"] = 46, ["z"] = 50, ["name"] = "rainbow:slab_wood_yellow_1"}, {["x"] = 5, ["meta"] = {["fields"] = {}, ["inventory"] = {}}, ["y"] = 14, ["param1"] = 62, ["z"] = 51, ["name"] = "rainbow:slope_wood_yellow"}, {["x"] = 5, ["meta"] = {["fields"] = {}, ["inventory"] = {}}, ["y"] = 14, ["z"] = 52, ["name"] = "rainbow:wood_darkred"}, {["x"] = 5, ["meta"] = {["fields"] = {}, ["inventory"] = {}}, ["y"] = 14, ["z"] = 53, ["name"] = "rainbow:wood_red"}, {["x"] = 5, ["meta"] = {["fields"] = {}, ["inventory"] = {}}, ["y"] = 14, ["z"] = 54, ["name"] = "rainbow:wood_darkred"}, {["x"] = 5, ["meta"] = {["fields"] = {}, ["inventory"] = {}}, ["y"] = 15, ["param1"] = 94, ["z"] = 52, ["name"] = "rainbow:slope_wood_yellow"}, {["x"] = 5, ["meta"] = {["fields"] = {}, ["inventory"] = {}}, ["y"] = 15, ["z"] = 53, ["name"] = "rainbow:wood_darkred"}, {["x"] = 5, ["meta"] = {["fields"] = {}, ["inventory"] = {}}, ["y"] = 15, ["z"] = 54, ["name"] = "rainbow:wood_red"}, {["x"] = 5, ["meta"] = {["fields"] = {}, ["inventory"] = {}}, ["y"] = 16, ["param1"] = 94, ["z"] = 53, ["name"] = "rainbow:slope_wood_yellow"}, {["x"] = 5, ["meta"] = {["fields"] = {}, ["inventory"] = {}}, ["y"] = 16, ["z"] = 54, ["name"] = "rainbow:wood_darkred"}, {["x"] = 5, ["meta"] = {["fields"] = {}, ["inventory"] = {}}, ["y"] = 17, ["param1"] = 62, ["z"] = 54, ["name"] = "rainbow:slope_wood_yellow"}, {["x"] = 5, ["meta"] = {["fields"] = {}, ["inventory"] = {}}, ["param2"] = 6, ["y"] = 17, ["param1"] = 46, ["z"] = 55, ["name"] = "rainbow:stair_wood_black"}, {["x"] = 5, ["meta"] = {["fields"] = {}, ["inventory"] = {}}, ["y"] = 18, ["param1"] = 30, ["z"] = 55, ["name"] = "rainbow:slope_wood_yellow"}, {["x"] = 5, ["meta"] = {["fields"] = {}, ["inventory"] = {}}, ["param2"] = 22, ["y"] = 25, ["param1"] = 239, ["z"] = 15, ["name"] = "rainbow:slope_lightcoolglass_black_half"}, {["x"] = 5, ["meta"] = {["fields"] = {}, ["inventory"] = {}}, ["y"] = 26, ["param1"] = 239, ["z"] = 15, ["name"] = "rainbow:slope_lightcoolglass_black_half_raised"}, {["x"] = 5, ["meta"] = {["fields"] = {}, ["inventory"] = {}}, ["param2"] = 22, ["y"] = 26, ["param1"] = 239, ["z"] = 16, ["name"] = "rainbow:slope_lightcoolglass_black_half_raised"}, {["x"] = 5, ["meta"] = {["fields"] = {}, ["inventory"] = {}}, ["param2"] = 22, ["y"] = 26, ["param1"] = 239, ["z"] = 17, ["name"] = "rainbow:slope_lightcoolglass_black_half"}, {["x"] = 5, ["meta"] = {["fields"] = {}, ["inventory"] = {}}, ["y"] = 27, ["param1"] = 239, ["z"] = 16, ["name"] = "rainbow:slope_lightcoolglass_black_half"}, {["x"] = 5, ["meta"] = {["fields"] = {}, ["inventory"] = {}}, ["y"] = 27, ["param1"] = 239, ["z"] = 17, ["name"] = "rainbow:slope_lightcoolglass_black_half_raised"}, {["x"] = 5, ["meta"] = {["fields"] = {}, ["inventory"] = {}}, ["param2"] = 22, ["y"] = 27, ["param1"] = 239, ["z"] = 18, ["name"] = "rainbow:slope_lightcoolglass_black_half_raised"}, {["x"] = 5, ["meta"] = {["fields"] = {}, ["inventory"] = {}}, ["param2"] = 22, ["y"] = 27, ["param1"] = 239, ["z"] = 19, ["name"] = "rainbow:slope_lightcoolglass_black_half"}, {["x"] = 5, ["meta"] = {["fields"] = {}, ["inventory"] = {}}, ["y"] = 28, ["param1"] = 239, ["z"] = 18, ["name"] = "rainbow:slope_lightcoolglass_black_half"}, {["x"] = 5, ["meta"] = {["fields"] = {}, ["inventory"] = {}}, ["y"] = 28, ["param1"] = 239, ["z"] = 19, ["name"] = "rainbow:slope_lightcoolglass_black_half_raised"}, {["x"] = 5, ["meta"] = {["fields"] = {}, ["inventory"] = {}}, ["param2"] = 22, ["y"] = 28, ["param1"] = 239, ["z"] = 20, ["name"] = "rainbow:slope_lightcoolglass_black_half_raised"}, {["x"] = 5, ["meta"] = {["fields"] = {}, ["inventory"] = {}}, ["param2"] = 22, ["y"] = 28, ["param1"] = 239, ["z"] = 21, ["name"] = "rainbow:slope_lightcoolglass_black_half"}, {["x"] = 5, ["meta"] = {["fields"] = {}, ["inventory"] = {}}, ["y"] = 29, ["param1"] = 239, ["z"] = 20, ["name"] = "rainbow:slope_lightcoolglass_black_half"}, {["x"] = 5, ["meta"] = {["fields"] = {}, ["inventory"] = {}}, ["y"] = 29, ["param1"] = 239, ["z"] = 21, ["name"] = "rainbow:slope_lightcoolglass_black_half_raised"}, {["x"] = 5, ["meta"] = {["fields"] = {}, ["inventory"] = {}}, ["param2"] = 22, ["y"] = 29, ["param1"] = 239, ["z"] = 22, ["name"] = "rainbow:slope_lightcoolglass_black_half_raised"}, {["x"] = 5, ["meta"] = {["fields"] = {}, ["inventory"] = {}}, ["param2"] = 22, ["y"] = 29, ["param1"] = 239, ["z"] = 23, ["name"] = "rainbow:slope_lightcoolglass_black_half"}, {["x"] = 5, ["meta"] = {["fields"] = {}, ["inventory"] = {}}, ["y"] = 30, ["param1"] = 239, ["z"] = 22, ["name"] = "rainbow:slope_lightcoolglass_black_half"}, {["x"] = 5, ["meta"] = {["fields"] = {}, ["inventory"] = {}}, ["y"] = 30, ["param1"] = 239, ["z"] = 23, ["name"] = "rainbow:slope_lightcoolglass_black_half_raised"}, {["x"] = 5, ["meta"] = {["fields"] = {}, ["inventory"] = {}}, ["param2"] = 22, ["y"] = 30, ["param1"] = 239, ["z"] = 24, ["name"] = "rainbow:slope_lightcoolglass_black_half_raised"}, {["x"] = 5, ["meta"] = {["fields"] = {}, ["inventory"] = {}}, ["param2"] = 22, ["y"] = 30, ["param1"] = 239, ["z"] = 25, ["name"] = "rainbow:slope_lightcoolglass_black_half"}, {["x"] = 5, ["meta"] = {["fields"] = {}, ["inventory"] = {}}, ["y"] = 31, ["param1"] = 239, ["z"] = 24, ["name"] = "rainbow:slope_lightcoolglass_black_half"}, {["x"] = 5, ["meta"] = {["fields"] = {}, ["inventory"] = {}}, ["y"] = 31, ["param1"] = 239, ["z"] = 25, ["name"] = "rainbow:slope_lightcoolglass_black_half_raised"}, {["x"] = 5, ["meta"] = {["fields"] = {}, ["inventory"] = {}}, ["param2"] = 22, ["y"] = 31, ["param1"] = 239, ["z"] = 26, ["name"] = "rainbow:slope_lightcoolglass_black_half_raised"}, {["x"] = 5, ["meta"] = {["fields"] = {}, ["inventory"] = {}}, ["param2"] = 22, ["y"] = 31, ["param1"] = 239, ["z"] = 27, ["name"] = "rainbow:slope_lightcoolglass_black_half"}, {["x"] = 5, ["meta"] = {["fields"] = {}, ["inventory"] = {}}, ["y"] = 32, ["param1"] = 239, ["z"] = 26, ["name"] = "rainbow:slope_lightcoolglass_black_half"}, {["x"] = 5, ["meta"] = {["fields"] = {}, ["inventory"] = {}}, ["y"] = 32, ["param1"] = 239, ["z"] = 27, ["name"] = "rainbow:slope_lightcoolglass_black_half_raised"}, {["x"] = 5, ["meta"] = {["fields"] = {}, ["inventory"] = {}}, ["param2"] = 22, ["y"] = 32, ["param1"] = 239, ["z"] = 28, ["name"] = "rainbow:slope_lightcoolglass_black_half_raised"}, {["x"] = 5, ["meta"] = {["fields"] = {}, ["inventory"] = {}}, ["y"] = 33, ["param1"] = 239, ["z"] = 28, ["name"] = "rainbow:slope_lightcoolglass_black_half"}, {["x"] = 6, ["meta"] = {["fields"] = {}, ["inventory"] = {}}, ["param2"] = 9, ["y"] = 6, ["param1"] = 14, ["z"] = 23, ["name"] = "rainbow:slope_wood_darkred"}, {["x"] = 6, ["meta"] = {["fields"] = {}, ["inventory"] = {}}, ["y"] = 6, ["z"] = 24, ["name"] = "rainbow:wood_darkred"}, {["x"] = 6, ["meta"] = {["fields"] = {}, ["inventory"] = {}}, ["y"] = 6, ["z"] = 25, ["name"] = "rainbow:wood_darkred"}, {["x"] = 6, ["meta"] = {["fields"] = {}, ["inventory"] = {}}, ["y"] = 6, ["z"] = 26, ["name"] = "rainbow:wood_darkred"}, {["x"] = 6, ["meta"] = {["fields"] = {}, ["inventory"] = {}}, ["y"] = 6, ["z"] = 27, ["name"] = "rainbow:wood_darkred"}, {["x"] = 6, ["meta"] = {["fields"] = {}, ["inventory"] = {}}, ["y"] = 6, ["z"] = 28, ["name"] = "rainbow:wood_darkred"}, {["x"] = 6, ["meta"] = {["fields"] = {}, ["inventory"] = {}}, ["y"] = 6, ["z"] = 29, ["name"] = "rainbow:wood_darkred"}, {["x"] = 6, ["meta"] = {["fields"] = {}, ["inventory"] = {}}, ["y"] = 6, ["z"] = 30, ["name"] = "rainbow:wood_darkred"}, {["x"] = 6, ["meta"] = {["fields"] = {}, ["inventory"] = {}}, ["param2"] = 6, ["y"] = 6, ["param1"] = 14, ["z"] = 31, ["name"] = "rainbow:slope_wood_darkred"}, {["x"] = 6, ["meta"] = {["fields"] = {}, ["inventory"] = {}}, ["param2"] = 8, ["y"] = 6, ["param1"] = 13, ["z"] = 44, ["name"] = "rainbow:slope_wood_darkred"}, {["x"] = 6, ["meta"] = {["fields"] = {}, ["inventory"] = {}}, ["y"] = 6, ["z"] = 45, ["name"] = "rainbow:wood_darkred"}, {["x"] = 6, ["meta"] = {["fields"] = {}, ["inventory"] = {}}, ["param2"] = 6, ["y"] = 6, ["param1"] = 13, ["z"] = 46, ["name"] = "rainbow:slope_wood_darkred"}, {["x"] = 6, ["meta"] = {["fields"] = {}, ["inventory"] = {}}, ["param2"] = 16, ["y"] = 7, ["param1"] = 14, ["z"] = 13, ["name"] = "rainbow:slope_wood_red"}, {["x"] = 6, ["meta"] = {["fields"] = {}, ["inventory"] = {}}, ["y"] = 7, ["z"] = 14, ["name"] = "rainbow:wood_red"}, {["x"] = 6, ["meta"] = {["fields"] = {}, ["inventory"] = {}}, ["y"] = 7, ["z"] = 15, ["name"] = "rainbow:wood_red"}, {["x"] = 6, ["meta"] = {["fields"] = {}, ["inventory"] = {}}, ["y"] = 7, ["z"] = 16, ["name"] = "rainbow:wood_red"}, {["x"] = 6, ["meta"] = {["fields"] = {}, ["inventory"] = {}}, ["y"] = 7, ["z"] = 17, ["name"] = "rainbow:wood_red"}, {["x"] = 6, ["meta"] = {["fields"] = {}, ["inventory"] = {}}, ["y"] = 7, ["z"] = 18, ["name"] = "rainbow:wood_red"}, {["x"] = 6, ["meta"] = {["fields"] = {}, ["inventory"] = {}}, ["y"] = 7, ["z"] = 19, ["name"] = "rainbow:wood_red"}, {["x"] = 6, ["meta"] = {["fields"] = {}, ["inventory"] = {}}, ["param2"] = 5, ["y"] = 7, ["param1"] = 14, ["z"] = 20, ["name"] = "rainbow:slope_wood_red"}, {["x"] = 6, ["meta"] = {["fields"] = {}, ["inventory"] = {}}, ["y"] = 7, ["param1"] = 14, ["z"] = 25, ["name"] = "rainbow:fence_yellow"}, {["x"] = 6, ["meta"] = {["fields"] = {}, ["inventory"] = {}}, ["y"] = 7, ["param1"] = 14, ["z"] = 26, ["name"] = "rainbow:fence_yellow"}, {["x"] = 6, ["meta"] = {["fields"] = {}, ["inventory"] = {}}, ["y"] = 7, ["param1"] = 14, ["z"] = 27, ["name"] = "rainbow:fence_yellow"}, {["x"] = 6, ["meta"] = {["fields"] = {}, ["inventory"] = {}}, ["y"] = 7, ["param1"] = 14, ["z"] = 28, ["name"] = "rainbow:fence_yellow"}, {["x"] = 6, ["meta"] = {["fields"] = {}, ["inventory"] = {}}, ["y"] = 7, ["param1"] = 14, ["z"] = 29, ["name"] = "rainbow:fence_yellow"}, {["x"] = 6, ["meta"] = {["fields"] = {}, ["inventory"] = {}}, ["y"] = 7, ["param1"] = 14, ["z"] = 30, ["name"] = "rainbow:fence_yellow"}, {["x"] = 6, ["meta"] = {["fields"] = {}, ["inventory"] = {}}, ["y"] = 7, ["param1"] = 14, ["z"] = 31, ["name"] = "rainbow:fence_yellow"}, {["x"] = 6, ["meta"] = {["fields"] = {}, ["inventory"] = {}}, ["y"] = 7, ["z"] = 32, ["name"] = "rainbow:wood_darkred"}, {["x"] = 6, ["meta"] = {["fields"] = {}, ["inventory"] = {}}, ["y"] = 7, ["z"] = 33, ["name"] = "rainbow:wood_darkred"}, {["x"] = 6, ["meta"] = {["fields"] = {}, ["inventory"] = {}}, ["y"] = 7, ["z"] = 34, ["name"] = "rainbow:wood_darkred"}, {["x"] = 6, ["meta"] = {["fields"] = {}, ["inventory"] = {}}, ["y"] = 7, ["z"] = 35, ["name"] = "rainbow:wood_darkred"}, {["x"] = 6, ["meta"] = {["fields"] = {}, ["inventory"] = {}}, ["y"] = 7, ["z"] = 36, ["name"] = "rainbow:wood_darkred"}, {["x"] = 6, ["meta"] = {["fields"] = {}, ["inventory"] = {}}, ["y"] = 7, ["z"] = 37, ["name"] = "rainbow:wood_red"}, {["x"] = 6, ["meta"] = {["fields"] = {}, ["inventory"] = {}}, ["y"] = 7, ["z"] = 38, ["name"] = "rainbow:wood_red"}, {["x"] = 6, ["meta"] = {["fields"] = {}, ["inventory"] = {}}, ["y"] = 7, ["z"] = 39, ["name"] = "rainbow:wood_darkred"}, {["x"] = 6, ["meta"] = {["fields"] = {}, ["inventory"] = {}}, ["y"] = 7, ["z"] = 40, ["name"] = "rainbow:wood_darkred"}, {["x"] = 6, ["meta"] = {["fields"] = {}, ["inventory"] = {}}, ["y"] = 7, ["z"] = 41, ["name"] = "rainbow:wood_darkred"}, {["x"] = 6, ["meta"] = {["fields"] = {}, ["inventory"] = {}}, ["y"] = 7, ["z"] = 42, ["name"] = "rainbow:wood_darkred"}, {["x"] = 6, ["meta"] = {["fields"] = {}, ["inventory"] = {}}, ["y"] = 7, ["z"] = 43, ["name"] = "rainbow:wood_darkred"}, {["x"] = 6, ["meta"] = {["fields"] = {}, ["inventory"] = {}}, ["y"] = 7, ["z"] = 44, ["name"] = "rainbow:wood_darkred"}, {["x"] = 6, ["meta"] = {["fields"] = {}, ["inventory"] = {}}, ["y"] = 7, ["z"] = 45, ["name"] = "rainbow:wood_darkred"}, {["x"] = 6, ["meta"] = {["fields"] = {}, ["inventory"] = {}}, ["y"] = 7, ["z"] = 46, ["name"] = "rainbow:wood_darkred"}, {["x"] = 6, ["meta"] = {["fields"] = {}, ["inventory"] = {}}, ["y"] = 7, ["z"] = 47, ["name"] = "rainbow:wood_darkred"}, {["x"] = 6, ["meta"] = {["fields"] = {}, ["inventory"] = {}}, ["y"] = 7, ["z"] = 48, ["name"] = "rainbow:wood_darkred"}, {["x"] = 6, ["meta"] = {["fields"] = {}, ["inventory"] = {}}, ["y"] = 7, ["z"] = 49, ["name"] = "rainbow:wood_darkred"}, {["x"] = 6, ["meta"] = {["fields"] = {}, ["inventory"] = {}}, ["y"] = 7, ["z"] = 50, ["name"] = "rainbow:wood_darkred"}, {["x"] = 6, ["meta"] = {["fields"] = {}, ["inventory"] = {}}, ["y"] = 7, ["z"] = 51, ["name"] = "rainbow:wood_darkred"}, {["x"] = 6, ["meta"] = {["fields"] = {}, ["inventory"] = {}}, ["y"] = 8, ["param1"] = 14, ["z"] = 25, ["name"] = "rainbow:slab_wood_yellow_1"}, {["x"] = 6, ["meta"] = {["fields"] = {}, ["inventory"] = {}}, ["y"] = 8, ["param1"] = 14, ["z"] = 26, ["name"] = "rainbow:slab_wood_yellow_1"}, {["x"] = 6, ["meta"] = {["fields"] = {}, ["inventory"] = {}}, ["y"] = 8, ["param1"] = 14, ["z"] = 27, ["name"] = "rainbow:slab_wood_yellow_1"}, {["x"] = 6, ["meta"] = {["fields"] = {}, ["inventory"] = {}}, ["y"] = 8, ["param1"] = 14, ["z"] = 28, ["name"] = "rainbow:slab_wood_yellow_1"}, {["x"] = 6, ["meta"] = {["fields"] = {}, ["inventory"] = {}}, ["y"] = 8, ["param1"] = 14, ["z"] = 29, ["name"] = "rainbow:slab_wood_yellow_1"}, {["x"] = 6, ["meta"] = {["fields"] = {}, ["inventory"] = {}}, ["y"] = 8, ["param1"] = 14, ["z"] = 30, ["name"] = "rainbow:slab_wood_yellow_1"}, {["x"] = 6, ["meta"] = {["fields"] = {}, ["inventory"] = {}}, ["y"] = 8, ["param1"] = 14, ["z"] = 31, ["name"] = "rainbow:slab_wood_yellow_1"}, {["x"] = 6, ["meta"] = {["fields"] = {}, ["inventory"] = {}}, ["y"] = 8, ["param1"] = 14, ["z"] = 32, ["name"] = "rainbow:slab_wood_yellow_1"}, {["x"] = 6, ["meta"] = {["fields"] = {}, ["inventory"] = {}}, ["y"] = 8, ["param1"] = 14, ["z"] = 33, ["name"] = "rainbow:slab_wood_yellow_1"}, {["x"] = 6, ["meta"] = {["fields"] = {}, ["inventory"] = {}}, ["y"] = 8, ["param1"] = 14, ["z"] = 34, ["name"] = "rainbow:slab_wood_yellow_1"}, {["x"] = 6, ["meta"] = {["fields"] = {}, ["inventory"] = {}}, ["y"] = 8, ["param1"] = 14, ["z"] = 35, ["name"] = "rainbow:slope_wood_yellow"}, {["x"] = 6, ["meta"] = {["fields"] = {}, ["inventory"] = {}}, ["y"] = 8, ["z"] = 36, ["name"] = "rainbow:wood_darkred"}, {["x"] = 6, ["meta"] = {["fields"] = {}, ["inventory"] = {}}, ["y"] = 8, ["z"] = 37, ["name"] = "rainbow:wood_darkred"}, {["x"] = 6, ["meta"] = {["fields"] = {}, ["inventory"] = {}}, ["y"] = 8, ["z"] = 38, ["name"] = "rainbow:wood_darkred"}, {["x"] = 6, ["meta"] = {["fields"] = {}, ["inventory"] = {}}, ["y"] = 8, ["z"] = 39, ["name"] = "rainbow:wood_red"}, {["x"] = 6, ["meta"] = {["fields"] = {}, ["inventory"] = {}}, ["y"] = 8, ["z"] = 40, ["name"] = "rainbow:wood_darkred"}, {["x"] = 6, ["meta"] = {["fields"] = {}, ["inventory"] = {}}, ["y"] = 8, ["z"] = 41, ["name"] = "rainbow:wood_red"}, {["x"] = 6, ["meta"] = {["fields"] = {}, ["inventory"] = {}}, ["y"] = 8, ["z"] = 42, ["name"] = "rainbow:wood_darkred"}, {["x"] = 6, ["meta"] = {["fields"] = {}, ["inventory"] = {}}, ["y"] = 8, ["z"] = 43, ["name"] = "rainbow:wood_darkred"}, {["x"] = 6, ["meta"] = {["fields"] = {}, ["inventory"] = {}}, ["y"] = 8, ["z"] = 44, ["name"] = "rainbow:wood_darkred"}, {["x"] = 6, ["meta"] = {["fields"] = {}, ["inventory"] = {}}, ["y"] = 8, ["z"] = 45, ["name"] = "rainbow:wood_red"}, {["x"] = 6, ["meta"] = {["fields"] = {}, ["inventory"] = {}}, ["y"] = 8, ["z"] = 46, ["name"] = "rainbow:wood_darkred"}, {["x"] = 6, ["meta"] = {["fields"] = {}, ["inventory"] = {}}, ["y"] = 8, ["z"] = 47, ["name"] = "rainbow:wood_darkred"}, {["x"] = 6, ["meta"] = {["fields"] = {}, ["inventory"] = {}}, ["y"] = 8, ["z"] = 48, ["name"] = "rainbow:wood_darkred"}, {["x"] = 6, ["meta"] = {["fields"] = {}, ["inventory"] = {}}, ["y"] = 8, ["z"] = 49, ["name"] = "rainbow:wood_darkred"}, {["x"] = 6, ["meta"] = {["fields"] = {}, ["inventory"] = {}}, ["y"] = 8, ["z"] = 50, ["name"] = "rainbow:wood_darkred"}, {["x"] = 6, ["meta"] = {["fields"] = {}, ["inventory"] = {}}, ["y"] = 8, ["z"] = 51, ["name"] = "rainbow:wood_darkred"}, {["x"] = 6, ["meta"] = {["fields"] = {}, ["inventory"] = {}}, ["y"] = 8, ["z"] = 52, ["name"] = "rainbow:wood_darkred"}, {["x"] = 6, ["meta"] = {["fields"] = {}, ["inventory"] = {}}, ["y"] = 9, ["param1"] = 14, ["z"] = 36, ["name"] = "rainbow:slab_wood_yellow_1"}, {["x"] = 6, ["meta"] = {["fields"] = {}, ["inventory"] = {}}, ["y"] = 9, ["param1"] = 14, ["z"] = 37, ["name"] = "rainbow:slab_wood_yellow_1"}, {["x"] = 6, ["meta"] = {["fields"] = {}, ["inventory"] = {}}, ["y"] = 9, ["param1"] = 14, ["z"] = 38, ["name"] = "rainbow:slope_wood_yellow"}, {["x"] = 6, ["meta"] = {["fields"] = {}, ["inventory"] = {}}, ["y"] = 9, ["z"] = 39, ["name"] = "rainbow:wood_darkred"}, {["x"] = 6, ["meta"] = {["fields"] = {}, ["inventory"] = {}}, ["y"] = 9, ["z"] = 40, ["name"] = "rainbow:wood_darkred"}, {["x"] = 6, ["meta"] = {["fields"] = {}, ["inventory"] = {}}, ["y"] = 9, ["z"] = 41, ["name"] = "rainbow:wood_darkred"}, {["x"] = 6, ["meta"] = {["fields"] = {}, ["inventory"] = {}}, ["y"] = 9, ["z"] = 42, ["name"] = "rainbow:wood_red"}, {["x"] = 6, ["meta"] = {["fields"] = {}, ["inventory"] = {}}, ["y"] = 9, ["z"] = 43, ["name"] = "rainbow:wood_red"}, {["x"] = 6, ["meta"] = {["fields"] = {}, ["inventory"] = {}}, ["y"] = 9, ["z"] = 44, ["name"] = "rainbow:wood_darkred"}, {["x"] = 6, ["meta"] = {["fields"] = {}, ["inventory"] = {}}, ["y"] = 9, ["z"] = 45, ["name"] = "rainbow:wood_darkred"}, {["x"] = 6, ["meta"] = {["fields"] = {}, ["inventory"] = {}}, ["y"] = 9, ["z"] = 46, ["name"] = "rainbow:wood_darkred"}, {["x"] = 6, ["meta"] = {["fields"] = {}, ["inventory"] = {}}, ["y"] = 9, ["z"] = 47, ["name"] = "rainbow:wood_darkred"}, {["x"] = 6, ["meta"] = {["fields"] = {}, ["inventory"] = {}}, ["y"] = 9, ["z"] = 48, ["name"] = "rainbow:wood_darkred"}, {["x"] = 6, ["meta"] = {["fields"] = {}, ["inventory"] = {}}, ["y"] = 9, ["z"] = 49, ["name"] = "rainbow:wood_darkred"}, {["x"] = 6, ["meta"] = {["fields"] = {}, ["inventory"] = {}}, ["y"] = 9, ["z"] = 50, ["name"] = "rainbow:wood_darkred"}, {["x"] = 6, ["meta"] = {["fields"] = {}, ["inventory"] = {}}, ["y"] = 9, ["z"] = 51, ["name"] = "rainbow:wood_darkred"}, {["x"] = 6, ["meta"] = {["fields"] = {}, ["inventory"] = {}}, ["y"] = 9, ["z"] = 52, ["name"] = "rainbow:wood_darkred"}, {["x"] = 6, ["meta"] = {["fields"] = {}, ["inventory"] = {}}, ["y"] = 10, ["param1"] = 30, ["z"] = 39, ["name"] = "rainbow:slab_wood_yellow_1"}, {["x"] = 6, ["meta"] = {["fields"] = {}, ["inventory"] = {}}, ["y"] = 10, ["param1"] = 46, ["z"] = 40, ["name"] = "rainbow:slab_wood_yellow_1"}, {["x"] = 6, ["meta"] = {["fields"] = {}, ["inventory"] = {}}, ["y"] = 10, ["param1"] = 62, ["z"] = 41, ["name"] = "rainbow:slab_wood_yellow_1"}, {["x"] = 6, ["meta"] = {["fields"] = {}, ["inventory"] = {}}, ["y"] = 10, ["z"] = 46, ["name"] = "rainbow:wood_red"}, {["x"] = 6, ["meta"] = {["fields"] = {}, ["inventory"] = {}}, ["y"] = 10, ["z"] = 53, ["name"] = "rainbow:wood_darkred"}, {["x"] = 6, ["meta"] = {["fields"] = {}, ["inventory"] = {}}, ["y"] = 11, ["z"] = 46, ["name"] = "rainbow:wood_red"}, {["x"] = 6, ["meta"] = {["fields"] = {}, ["inventory"] = {}}, ["param2"] = 12, ["y"] = 11, ["param1"] = 238, ["z"] = 47, ["name"] = "rainbow:slope_lightcoolglass_white_half"}, {["x"] = 6, ["meta"] = {["fields"] = {}, ["inventory"] = {}}, ["param2"] = 14, ["y"] = 11, ["param1"] = 238, ["z"] = 48, ["name"] = "rainbow:slope_lightcoolglass_white_half"}, {["x"] = 6, ["meta"] = {["fields"] = {}, ["inventory"] = {}}, ["param2"] = 12, ["y"] = 11, ["param1"] = 238, ["z"] = 51, ["name"] = "rainbow:slope_lightcoolglass_white_half"}, {["x"] = 6, ["meta"] = {["fields"] = {}, ["inventory"] = {}}, ["param2"] = 14, ["y"] = 11, ["param1"] = 238, ["z"] = 52, ["name"] = "rainbow:slope_lightcoolglass_white_half"}, {["x"] = 6, ["meta"] = {["fields"] = {}, ["inventory"] = {}}, ["y"] = 11, ["z"] = 53, ["name"] = "rainbow:wood_darkred"}, {["x"] = 6, ["meta"] = {["fields"] = {}, ["inventory"] = {}}, ["y"] = 12, ["z"] = 46, ["name"] = "rainbow:wood_darkred"}, {["x"] = 6, ["meta"] = {["fields"] = {}, ["inventory"] = {}}, ["y"] = 12, ["z"] = 47, ["name"] = "rainbow:wood_darkred"}, {["x"] = 6, ["meta"] = {["fields"] = {}, ["inventory"] = {}}, ["y"] = 12, ["z"] = 48, ["name"] = "rainbow:wood_darkred"}, {["x"] = 6, ["meta"] = {["fields"] = {}, ["inventory"] = {}}, ["y"] = 12, ["z"] = 49, ["name"] = "rainbow:wood_darkred"}, {["x"] = 6, ["meta"] = {["fields"] = {}, ["inventory"] = {}}, ["y"] = 12, ["z"] = 50, ["name"] = "rainbow:wood_darkred"}, {["x"] = 6, ["meta"] = {["fields"] = {}, ["inventory"] = {}}, ["y"] = 12, ["z"] = 51, ["name"] = "rainbow:wood_darkred"}, {["x"] = 6, ["meta"] = {["fields"] = {}, ["inventory"] = {}}, ["y"] = 12, ["z"] = 52, ["name"] = "rainbow:wood_darkred"}, {["x"] = 6, ["meta"] = {["fields"] = {}, ["inventory"] = {}}, ["y"] = 12, ["z"] = 53, ["name"] = "rainbow:wood_darkred"}, {["x"] = 6, ["meta"] = {["fields"] = {}, ["inventory"] = {}}, ["y"] = 13, ["param1"] = 46, ["z"] = 50, ["name"] = "rainbow:stair_wood_black_alt_2"}, {["x"] = 6, ["meta"] = {["fields"] = {}, ["inventory"] = {}}, ["y"] = 13, ["z"] = 53, ["name"] = "rainbow:wood_darkred"}, {["x"] = 6, ["meta"] = {["fields"] = {}, ["inventory"] = {}}, ["y"] = 14, ["param1"] = 78, ["z"] = 51, ["name"] = "rainbow:stair_wood_black_alt_2"}, {["x"] = 6, ["meta"] = {["fields"] = {}, ["inventory"] = {}}, ["y"] = 14, ["z"] = 54, ["name"] = "rainbow:wood_darkred"}, {["x"] = 6, ["meta"] = {["fields"] = {}, ["inventory"] = {}}, ["y"] = 15, ["param1"] = 110, ["z"] = 52, ["name"] = "rainbow:stair_wood_black_alt_2"}, {["x"] = 6, ["meta"] = {["fields"] = {}, ["inventory"] = {}}, ["y"] = 15, ["z"] = 54, ["name"] = "rainbow:wood_red"}, {["x"] = 6, ["meta"] = {["fields"] = {}, ["inventory"] = {}}, ["y"] = 16, ["param1"] = 110, ["z"] = 53, ["name"] = "rainbow:stair_wood_black_alt_2"}, {["x"] = 6, ["meta"] = {["fields"] = {}, ["inventory"] = {}}, ["y"] = 16, ["z"] = 54, ["name"] = "rainbow:wood_darkred"}, {["x"] = 6, ["meta"] = {["fields"] = {}, ["inventory"] = {}}, ["y"] = 17, ["param1"] = 78, ["z"] = 54, ["name"] = "rainbow:stair_wood_black_alt_2"}, {["x"] = 6, ["meta"] = {["fields"] = {}, ["inventory"] = {}}, ["param2"] = 6, ["y"] = 17, ["param1"] = 61, ["z"] = 55, ["name"] = "rainbow:stair_wood_black"}, {["x"] = 6, ["meta"] = {["fields"] = {}, ["inventory"] = {}}, ["param2"] = 3, ["y"] = 18, ["param1"] = 46, ["z"] = 55, ["name"] = "homedecor:banister_wrought_iron_horizontal"}, {["x"] = 6, ["meta"] = {["fields"] = {}, ["inventory"] = {}}, ["param2"] = 2, ["y"] = 18, ["param1"] = 30, ["z"] = 56, ["name"] = "homedecor:banister_wrought_iron_horizontal"}, {["x"] = 6, ["meta"] = {["fields"] = {}, ["inventory"] = {}}, ["param2"] = 22, ["y"] = 26, ["param1"] = 239, ["z"] = 16, ["name"] = "rainbow:slope_lightcoolglass_white_half_raised"}, {["x"] = 6, ["meta"] = {["fields"] = {}, ["inventory"] = {}}, ["param2"] = 22, ["y"] = 26, ["param1"] = 239, ["z"] = 17, ["name"] = "rainbow:slope_lightcoolglass_white_half"}, {["x"] = 6, ["meta"] = {["fields"] = {}, ["inventory"] = {}}, ["y"] = 27, ["param1"] = 239, ["z"] = 16, ["name"] = "rainbow:slope_lightcoolglass_white_half"}, {["x"] = 6, ["meta"] = {["fields"] = {}, ["inventory"] = {}}, ["y"] = 27, ["param1"] = 239, ["z"] = 17, ["name"] = "rainbow:slope_lightcoolglass_white_half_raised"}, {["x"] = 6, ["meta"] = {["fields"] = {}, ["inventory"] = {}}, ["param2"] = 22, ["y"] = 27, ["param1"] = 239, ["z"] = 18, ["name"] = "rainbow:slope_lightcoolglass_white_half_raised"}, {["x"] = 6, ["meta"] = {["fields"] = {}, ["inventory"] = {}}, ["param2"] = 22, ["y"] = 27, ["param1"] = 239, ["z"] = 19, ["name"] = "rainbow:slope_lightcoolglass_white_half"}, {["x"] = 6, ["meta"] = {["fields"] = {}, ["inventory"] = {}}, ["y"] = 28, ["param1"] = 239, ["z"] = 18, ["name"] = "rainbow:slope_lightcoolglass_white_half"}, {["x"] = 6, ["meta"] = {["fields"] = {}, ["inventory"] = {}}, ["y"] = 28, ["param1"] = 239, ["z"] = 19, ["name"] = "rainbow:slope_lightcoolglass_white_half_raised"}, {["x"] = 6, ["meta"] = {["fields"] = {}, ["inventory"] = {}}, ["param2"] = 22, ["y"] = 28, ["param1"] = 239, ["z"] = 20, ["name"] = "rainbow:slope_lightcoolglass_white_half_raised"}, {["x"] = 6, ["meta"] = {["fields"] = {}, ["inventory"] = {}}, ["param2"] = 22, ["y"] = 28, ["param1"] = 239, ["z"] = 21, ["name"] = "rainbow:slope_lightcoolglass_white_half"}, {["x"] = 6, ["meta"] = {["fields"] = {}, ["inventory"] = {}}, ["y"] = 29, ["param1"] = 239, ["z"] = 20, ["name"] = "rainbow:slope_lightcoolglass_white_half"}, {["x"] = 6, ["meta"] = {["fields"] = {}, ["inventory"] = {}}, ["y"] = 29, ["param1"] = 239, ["z"] = 21, ["name"] = "rainbow:slope_lightcoolglass_white_half_raised"}, {["x"] = 6, ["meta"] = {["fields"] = {}, ["inventory"] = {}}, ["param2"] = 22, ["y"] = 29, ["param1"] = 239, ["z"] = 22, ["name"] = "rainbow:slope_lightcoolglass_white_half_raised"}, {["x"] = 6, ["meta"] = {["fields"] = {}, ["inventory"] = {}}, ["param2"] = 22, ["y"] = 29, ["param1"] = 239, ["z"] = 23, ["name"] = "rainbow:slope_lightcoolglass_white_half"}, {["x"] = 6, ["meta"] = {["fields"] = {}, ["inventory"] = {}}, ["y"] = 30, ["param1"] = 239, ["z"] = 22, ["name"] = "rainbow:slope_lightcoolglass_white_half"}, {["x"] = 6, ["meta"] = {["fields"] = {}, ["inventory"] = {}}, ["y"] = 30, ["param1"] = 239, ["z"] = 23, ["name"] = "rainbow:slope_lightcoolglass_white_half_raised"}, {["x"] = 6, ["meta"] = {["fields"] = {}, ["inventory"] = {}}, ["param2"] = 22, ["y"] = 30, ["param1"] = 239, ["z"] = 24, ["name"] = "rainbow:slope_lightcoolglass_white_half_raised"}, {["x"] = 6, ["meta"] = {["fields"] = {}, ["inventory"] = {}}, ["param2"] = 22, ["y"] = 30, ["param1"] = 239, ["z"] = 25, ["name"] = "rainbow:slope_lightcoolglass_white_half"}, {["x"] = 6, ["meta"] = {["fields"] = {}, ["inventory"] = {}}, ["y"] = 31, ["param1"] = 239, ["z"] = 24, ["name"] = "rainbow:slope_lightcoolglass_white_half"}, {["x"] = 6, ["meta"] = {["fields"] = {}, ["inventory"] = {}}, ["y"] = 31, ["param1"] = 239, ["z"] = 25, ["name"] = "rainbow:slope_lightcoolglass_white_half_raised"}, {["x"] = 6, ["meta"] = {["fields"] = {}, ["inventory"] = {}}, ["param2"] = 22, ["y"] = 31, ["param1"] = 239, ["z"] = 26, ["name"] = "rainbow:slope_lightcoolglass_white_half_raised"}, {["x"] = 6, ["meta"] = {["fields"] = {}, ["inventory"] = {}}, ["param2"] = 22, ["y"] = 31, ["param1"] = 239, ["z"] = 27, ["name"] = "rainbow:slope_lightcoolglass_white_half"}, {["x"] = 6, ["meta"] = {["fields"] = {}, ["inventory"] = {}}, ["y"] = 32, ["param1"] = 239, ["z"] = 26, ["name"] = "rainbow:slope_lightcoolglass_white_half"}, {["x"] = 6, ["meta"] = {["fields"] = {}, ["inventory"] = {}}, ["y"] = 32, ["param1"] = 239, ["z"] = 27, ["name"] = "rainbow:slope_lightcoolglass_white_half_raised"}, {["x"] = 7, ["meta"] = {["fields"] = {}, ["inventory"] = {}}, ["y"] = 2, ["z"] = 26, ["name"] = "rainbow:wood_darkred"}, {["x"] = 7, ["meta"] = {["fields"] = {}, ["inventory"] = {}}, ["y"] = 2, ["z"] = 27, ["name"] = "rainbow:wood_darkred"}, {["x"] = 7, ["meta"] = {["fields"] = {}, ["inventory"] = {}}, ["y"] = 2, ["z"] = 28, ["name"] = "rainbow:wood_darkred"}, {["x"] = 7, ["meta"] = {["fields"] = {}, ["inventory"] = {}}, ["y"] = 2, ["z"] = 29, ["name"] = "rainbow:wood_darkred"}, {["x"] = 7, ["meta"] = {["fields"] = {}, ["inventory"] = {}}, ["y"] = 2, ["z"] = 30, ["name"] = "rainbow:wood_darkred"}, {["x"] = 7, ["meta"] = {["fields"] = {}, ["inventory"] = {}}, ["y"] = 2, ["z"] = 31, ["name"] = "rainbow:wood_darkred"}, {["x"] = 7, ["meta"] = {["fields"] = {}, ["inventory"] = {}}, ["y"] = 2, ["z"] = 32, ["name"] = "rainbow:wood_darkred"}, {["x"] = 7, ["meta"] = {["fields"] = {}, ["inventory"] = {}}, ["y"] = 2, ["z"] = 33, ["name"] = "rainbow:wood_darkred"}, {["x"] = 7, ["meta"] = {["fields"] = {}, ["inventory"] = {}}, ["y"] = 2, ["z"] = 34, ["name"] = "rainbow:wood_darkred"}, {["x"] = 7, ["meta"] = {["fields"] = {}, ["inventory"] = {}}, ["y"] = 2, ["z"] = 35, ["name"] = "rainbow:wood_darkred"}, {["x"] = 7, ["meta"] = {["fields"] = {}, ["inventory"] = {}}, ["y"] = 2, ["z"] = 36, ["name"] = "rainbow:wood_darkred"}, {["x"] = 7, ["meta"] = {["fields"] = {}, ["inventory"] = {}}, ["y"] = 2, ["z"] = 37, ["name"] = "rainbow:wood_darkred"}, {["x"] = 7, ["meta"] = {["fields"] = {}, ["inventory"] = {}}, ["y"] = 2, ["z"] = 38, ["name"] = "rainbow:wood_darkred"}, {["x"] = 7, ["meta"] = {["fields"] = {}, ["inventory"] = {}}, ["y"] = 2, ["z"] = 39, ["name"] = "rainbow:wood_darkred"}, {["x"] = 7, ["meta"] = {["fields"] = {}, ["inventory"] = {}}, ["y"] = 2, ["z"] = 40, ["name"] = "rainbow:wood_darkred"}, {["x"] = 7, ["meta"] = {["fields"] = {}, ["inventory"] = {}}, ["y"] = 2, ["z"] = 41, ["name"] = "rainbow:wood_darkred"}, {["x"] = 7, ["meta"] = {["fields"] = {}, ["inventory"] = {}}, ["y"] = 2, ["z"] = 42, ["name"] = "rainbow:wood_darkred"}, {["x"] = 7, ["meta"] = {["fields"] = {}, ["inventory"] = {}}, ["y"] = 2, ["z"] = 43, ["name"] = "rainbow:wood_darkred"}, {["x"] = 7, ["meta"] = {["fields"] = {}, ["inventory"] = {}}, ["y"] = 2, ["z"] = 44, ["name"] = "rainbow:wood_darkred"}, {["x"] = 7, ["meta"] = {["fields"] = {}, ["inventory"] = {}}, ["y"] = 2, ["z"] = 45, ["name"] = "rainbow:wood_darkred"}, {["x"] = 7, ["meta"] = {["fields"] = {}, ["inventory"] = {}}, ["y"] = 2, ["z"] = 46, ["name"] = "rainbow:wood_darkred"}, {["x"] = 7, ["meta"] = {["fields"] = {}, ["inventory"] = {}}, ["y"] = 3, ["z"] = 24, ["name"] = "rainbow:wood_darkred"}, {["x"] = 7, ["meta"] = {["fields"] = {}, ["inventory"] = {}}, ["y"] = 3, ["z"] = 25, ["name"] = "rainbow:wood_darkred"}, {["x"] = 7, ["meta"] = {["fields"] = {}, ["inventory"] = {}}, ["y"] = 3, ["z"] = 26, ["name"] = "rainbow:wood_darkred"}, {["x"] = 7, ["meta"] = {["fields"] = {}, ["inventory"] = {}}, ["y"] = 3, ["z"] = 27, ["name"] = "rainbow:wood_darkred"}, {["x"] = 7, ["meta"] = {["fields"] = {}, ["inventory"] = {}}, ["y"] = 3, ["z"] = 28, ["name"] = "rainbow:wood_darkred"}, {["x"] = 7, ["meta"] = {["fields"] = {}, ["inventory"] = {}}, ["y"] = 3, ["z"] = 29, ["name"] = "rainbow:wood_darkred"}, {["x"] = 7, ["meta"] = {["fields"] = {}, ["inventory"] = {}}, ["y"] = 3, ["z"] = 30, ["name"] = "rainbow:wood_darkred"}, {["x"] = 7, ["meta"] = {["fields"] = {}, ["inventory"] = {}}, ["param2"] = 1, ["y"] = 3, ["z"] = 31, ["name"] = "rainbow:wood_darkred"}, {["x"] = 7, ["meta"] = {["fields"] = {}, ["inventory"] = {}}, ["y"] = 3, ["z"] = 32, ["name"] = "rainbow:wood_darkred"}, {["x"] = 7, ["meta"] = {["fields"] = {}, ["inventory"] = {}}, ["y"] = 3, ["z"] = 33, ["name"] = "rainbow:wood_darkred"}, {["x"] = 7, ["meta"] = {["fields"] = {}, ["inventory"] = {}}, ["y"] = 3, ["z"] = 34, ["name"] = "rainbow:wood_darkred"}, {["x"] = 7, ["meta"] = {["fields"] = {}, ["inventory"] = {}}, ["y"] = 3, ["z"] = 35, ["name"] = "rainbow:wood_darkred"}, {["x"] = 7, ["meta"] = {["fields"] = {}, ["inventory"] = {}}, ["y"] = 3, ["z"] = 36, ["name"] = "rainbow:wood_darkred"}, {["x"] = 7, ["meta"] = {["fields"] = {}, ["inventory"] = {}}, ["y"] = 3, ["z"] = 37, ["name"] = "rainbow:wood_darkred"}, {["x"] = 7, ["meta"] = {["fields"] = {}, ["inventory"] = {}}, ["param2"] = 1, ["y"] = 3, ["z"] = 38, ["name"] = "rainbow:wood_darkred"}, {["x"] = 7, ["meta"] = {["fields"] = {}, ["inventory"] = {}}, ["y"] = 3, ["z"] = 39, ["name"] = "rainbow:wood_darkred"}, {["x"] = 7, ["meta"] = {["fields"] = {}, ["inventory"] = {}}, ["y"] = 3, ["z"] = 40, ["name"] = "rainbow:wood_darkred"}, {["x"] = 7, ["meta"] = {["fields"] = {}, ["inventory"] = {}}, ["y"] = 3, ["z"] = 41, ["name"] = "rainbow:wood_darkred"}, {["x"] = 7, ["meta"] = {["fields"] = {}, ["inventory"] = {}}, ["y"] = 3, ["z"] = 42, ["name"] = "rainbow:wood_darkred"}, {["x"] = 7, ["meta"] = {["fields"] = {}, ["inventory"] = {}}, ["y"] = 3, ["z"] = 43, ["name"] = "rainbow:wood_darkred"}, {["x"] = 7, ["meta"] = {["fields"] = {}, ["inventory"] = {}}, ["y"] = 3, ["z"] = 44, ["name"] = "rainbow:wood_darkred"}, {["x"] = 7, ["meta"] = {["fields"] = {}, ["inventory"] = {}}, ["y"] = 3, ["z"] = 45, ["name"] = "rainbow:wood_darkred"}, {["x"] = 7, ["meta"] = {["fields"] = {}, ["inventory"] = {}}, ["y"] = 3, ["z"] = 46, ["name"] = "rainbow:wood_darkred"}, {["x"] = 7, ["meta"] = {["fields"] = {}, ["inventory"] = {}}, ["y"] = 3, ["z"] = 47, ["name"] = "rainbow:wood_darkred"}, {["x"] = 7, ["meta"] = {["fields"] = {}, ["inventory"] = {}}, ["y"] = 3, ["z"] = 48, ["name"] = "rainbow:wood_darkred"}, {["x"] = 7, ["meta"] = {["fields"] = {}, ["inventory"] = {}}, ["y"] = 4, ["z"] = 20, ["name"] = "rainbow:wood_darkred"}, {["x"] = 7, ["meta"] = {["fields"] = {}, ["inventory"] = {}}, ["y"] = 4, ["z"] = 21, ["name"] = "rainbow:wood_darkred"}, {["x"] = 7, ["meta"] = {["fields"] = {}, ["inventory"] = {}}, ["y"] = 4, ["z"] = 22, ["name"] = "rainbow:wood_darkred"}, {["x"] = 7, ["meta"] = {["fields"] = {}, ["inventory"] = {}}, ["y"] = 4, ["z"] = 23, ["name"] = "rainbow:wood_darkred"}, {["x"] = 7, ["meta"] = {["fields"] = {}, ["inventory"] = {}}, ["y"] = 4, ["z"] = 24, ["name"] = "rainbow:wood_darkred"}, {["x"] = 7, ["meta"] = {["fields"] = {}, ["inventory"] = {}}, ["y"] = 4, ["z"] = 25, ["name"] = "rainbow:wood_darkred"}, {["x"] = 7, ["meta"] = {["fields"] = {}, ["inventory"] = {}}, ["y"] = 4, ["z"] = 26, ["name"] = "rainbow:wood_darkred"}, {["x"] = 7, ["meta"] = {["fields"] = {}, ["inventory"] = {}}, ["y"] = 4, ["z"] = 27, ["name"] = "rainbow:wood_darkred"}, {["x"] = 7, ["meta"] = {["fields"] = {}, ["inventory"] = {}}, ["y"] = 4, ["z"] = 28, ["name"] = "rainbow:wood_darkred"}, {["x"] = 7, ["meta"] = {["fields"] = {}, ["inventory"] = {}}, ["y"] = 4, ["z"] = 29, ["name"] = "rainbow:wood_darkred"}, {["x"] = 7, ["meta"] = {["fields"] = {}, ["inventory"] = {}}, ["y"] = 4, ["z"] = 30, ["name"] = "rainbow:wood_darkred"}, {["x"] = 7, ["meta"] = {["fields"] = {}, ["inventory"] = {}}, ["y"] = 4, ["z"] = 31, ["name"] = "rainbow:wood_darkred"}, {["x"] = 7, ["meta"] = {["fields"] = {}, ["inventory"] = {}}, ["y"] = 4, ["z"] = 32, ["name"] = "rainbow:wood_darkred"}, {["x"] = 7, ["meta"] = {["fields"] = {}, ["inventory"] = {}}, ["y"] = 4, ["z"] = 33, ["name"] = "rainbow:wood_darkred"}, {["x"] = 7, ["meta"] = {["fields"] = {}, ["inventory"] = {}}, ["y"] = 4, ["z"] = 34, ["name"] = "rainbow:wood_darkred"}, {["x"] = 7, ["meta"] = {["fields"] = {}, ["inventory"] = {}}, ["y"] = 4, ["z"] = 35, ["name"] = "rainbow:wood_darkred"}, {["x"] = 7, ["meta"] = {["fields"] = {}, ["inventory"] = {}}, ["y"] = 4, ["z"] = 36, ["name"] = "rainbow:wood_darkred"}, {["x"] = 7, ["meta"] = {["fields"] = {}, ["inventory"] = {}}, ["y"] = 4, ["z"] = 37, ["name"] = "rainbow:wood_darkred"}, {["x"] = 7, ["meta"] = {["fields"] = {}, ["inventory"] = {}}, ["y"] = 4, ["z"] = 38, ["name"] = "rainbow:wood_darkred"}, {["x"] = 7, ["meta"] = {["fields"] = {}, ["inventory"] = {}}, ["y"] = 4, ["z"] = 39, ["name"] = "rainbow:wood_darkred"}, {["x"] = 7, ["meta"] = {["fields"] = {}, ["inventory"] = {}}, ["y"] = 4, ["z"] = 40, ["name"] = "rainbow:wood_darkred"}, {["x"] = 7, ["meta"] = {["fields"] = {}, ["inventory"] = {}}, ["y"] = 4, ["z"] = 41, ["name"] = "rainbow:wood_darkred"}, {["x"] = 7, ["meta"] = {["fields"] = {}, ["inventory"] = {}}, ["y"] = 4, ["z"] = 42, ["name"] = "rainbow:wood_darkred"}, {["x"] = 7, ["meta"] = {["fields"] = {}, ["inventory"] = {}}, ["y"] = 4, ["z"] = 43, ["name"] = "rainbow:wood_darkred"}, {["x"] = 7, ["meta"] = {["fields"] = {}, ["inventory"] = {}}, ["y"] = 4, ["z"] = 44, ["name"] = "rainbow:wood_darkred"}, {["x"] = 7, ["meta"] = {["fields"] = {}, ["inventory"] = {}}, ["y"] = 4, ["z"] = 45, ["name"] = "rainbow:wood_darkred"}, {["x"] = 7, ["meta"] = {["fields"] = {}, ["inventory"] = {}}, ["y"] = 4, ["z"] = 46, ["name"] = "rainbow:wood_darkred"}, {["x"] = 7, ["meta"] = {["fields"] = {}, ["inventory"] = {}}, ["y"] = 4, ["z"] = 47, ["name"] = "rainbow:wood_darkred"}, {["x"] = 7, ["meta"] = {["fields"] = {}, ["inventory"] = {}}, ["y"] = 4, ["z"] = 48, ["name"] = "rainbow:wood_darkred"}, {["x"] = 7, ["meta"] = {["fields"] = {}, ["inventory"] = {}}, ["y"] = 4, ["z"] = 49, ["name"] = "rainbow:wood_darkred"}, {["x"] = 7, ["meta"] = {["fields"] = {}, ["inventory"] = {}}, ["y"] = 5, ["z"] = 18, ["name"] = "rainbow:wood_darkred"}, {["x"] = 7, ["meta"] = {["fields"] = {}, ["inventory"] = {}}, ["y"] = 5, ["z"] = 19, ["name"] = "rainbow:wood_darkred"}, {["x"] = 7, ["meta"] = {["fields"] = {}, ["inventory"] = {}}, ["y"] = 5, ["z"] = 20, ["name"] = "rainbow:wood_darkred"}, {["x"] = 7, ["meta"] = {["fields"] = {}, ["inventory"] = {}}, ["y"] = 5, ["z"] = 21, ["name"] = "rainbow:wood_darkred"}, {["x"] = 7, ["meta"] = {["fields"] = {}, ["inventory"] = {}}, ["y"] = 5, ["z"] = 22, ["name"] = "rainbow:wood_darkred"}, {["x"] = 7, ["meta"] = {["fields"] = {}, ["inventory"] = {}}, ["y"] = 5, ["z"] = 23, ["name"] = "rainbow:wood_red"}, {["x"] = 7, ["meta"] = {["fields"] = {}, ["inventory"] = {}}, ["y"] = 5, ["z"] = 24, ["name"] = "rainbow:wood_darkred"}, {["x"] = 7, ["meta"] = {["fields"] = {}, ["inventory"] = {}}, ["y"] = 5, ["z"] = 25, ["name"] = "rainbow:wood_red"}, {["x"] = 7, ["meta"] = {["fields"] = {}, ["inventory"] = {}}, ["y"] = 5, ["z"] = 26, ["name"] = "rainbow:wood_red"}, {["x"] = 7, ["meta"] = {["fields"] = {}, ["inventory"] = {}}, ["y"] = 5, ["z"] = 27, ["name"] = "rainbow:wood_red"}, {["x"] = 7, ["meta"] = {["fields"] = {}, ["inventory"] = {}}, ["y"] = 5, ["z"] = 28, ["name"] = "rainbow:wood_darkred"}, {["x"] = 7, ["meta"] = {["fields"] = {}, ["inventory"] = {}}, ["y"] = 5, ["z"] = 29, ["name"] = "rainbow:wood_red"}, {["x"] = 7, ["meta"] = {["fields"] = {}, ["inventory"] = {}}, ["y"] = 5, ["z"] = 30, ["name"] = "rainbow:wood_red"}, {["x"] = 7, ["meta"] = {["fields"] = {}, ["inventory"] = {}}, ["y"] = 5, ["z"] = 31, ["name"] = "rainbow:wood_red"}, {["x"] = 7, ["meta"] = {["fields"] = {}, ["inventory"] = {}}, ["y"] = 5, ["z"] = 32, ["name"] = "rainbow:wood_darkred"}, {["x"] = 7, ["meta"] = {["fields"] = {}, ["inventory"] = {}}, ["y"] = 5, ["z"] = 33, ["name"] = "rainbow:wood_darkred"}, {["x"] = 7, ["meta"] = {["fields"] = {}, ["inventory"] = {}}, ["y"] = 5, ["z"] = 34, ["name"] = "rainbow:wood_darkred"}, {["x"] = 7, ["meta"] = {["fields"] = {}, ["inventory"] = {}}, ["y"] = 5, ["z"] = 35, ["name"] = "rainbow:wood_darkred"}, {["x"] = 7, ["meta"] = {["fields"] = {}, ["inventory"] = {}}, ["y"] = 5, ["z"] = 36, ["name"] = "rainbow:wood_darkred"}, {["x"] = 7, ["meta"] = {["fields"] = {}, ["inventory"] = {}}, ["y"] = 5, ["z"] = 37, ["name"] = "rainbow:wood_darkred"}, {["x"] = 7, ["meta"] = {["fields"] = {}, ["inventory"] = {}}, ["y"] = 5, ["z"] = 38, ["name"] = "rainbow:wood_darkred"}, {["x"] = 7, ["meta"] = {["fields"] = {}, ["inventory"] = {}}, ["y"] = 5, ["z"] = 39, ["name"] = "rainbow:wood_darkred"}, {["x"] = 7, ["meta"] = {["fields"] = {}, ["inventory"] = {}}, ["y"] = 5, ["z"] = 40, ["name"] = "rainbow:wood_darkred"}, {["x"] = 7, ["meta"] = {["fields"] = {}, ["inventory"] = {}}, ["y"] = 5, ["z"] = 41, ["name"] = "rainbow:wood_darkred"}, {["x"] = 7, ["meta"] = {["fields"] = {}, ["inventory"] = {}}, ["y"] = 5, ["z"] = 42, ["name"] = "rainbow:wood_darkred"}, {["x"] = 7, ["meta"] = {["fields"] = {}, ["inventory"] = {}}, ["y"] = 5, ["z"] = 43, ["name"] = "rainbow:wood_darkred"}, {["x"] = 7, ["meta"] = {["fields"] = {}, ["inventory"] = {}}, ["y"] = 5, ["z"] = 44, ["name"] = "rainbow:wood_darkred"}, {["x"] = 7, ["meta"] = {["fields"] = {}, ["inventory"] = {}}, ["y"] = 5, ["z"] = 45, ["name"] = "rainbow:wood_darkred"}, {["x"] = 7, ["meta"] = {["fields"] = {}, ["inventory"] = {}}, ["y"] = 5, ["z"] = 46, ["name"] = "rainbow:wood_darkred"}, {["x"] = 7, ["meta"] = {["fields"] = {}, ["inventory"] = {}}, ["y"] = 5, ["z"] = 47, ["name"] = "rainbow:wood_darkred"}, {["x"] = 7, ["meta"] = {["fields"] = {}, ["inventory"] = {}}, ["y"] = 5, ["z"] = 48, ["name"] = "rainbow:wood_darkred"}, {["x"] = 7, ["meta"] = {["fields"] = {}, ["inventory"] = {}}, ["y"] = 5, ["z"] = 49, ["name"] = "rainbow:wood_darkred"}, {["x"] = 7, ["meta"] = {["fields"] = {}, ["inventory"] = {}}, ["y"] = 5, ["z"] = 50, ["name"] = "rainbow:wood_darkred"}, {["x"] = 7, ["meta"] = {["fields"] = {}, ["inventory"] = {}}, ["y"] = 6, ["z"] = 15, ["name"] = "rainbow:wood_darkred"}, {["x"] = 7, ["meta"] = {["fields"] = {}, ["inventory"] = {}}, ["y"] = 6, ["z"] = 16, ["name"] = "rainbow:wood_darkred"}, {["x"] = 7, ["meta"] = {["fields"] = {}, ["inventory"] = {}}, ["y"] = 6, ["z"] = 17, ["name"] = "rainbow:wood_darkred"}, {["x"] = 7, ["meta"] = {["fields"] = {}, ["inventory"] = {}}, ["y"] = 6, ["z"] = 18, ["name"] = "rainbow:wood_darkred"}, {["x"] = 7, ["meta"] = {["fields"] = {}, ["inventory"] = {}}, ["y"] = 6, ["z"] = 19, ["name"] = "rainbow:wood_darkred"}, {["x"] = 7, ["meta"] = {["fields"] = {}, ["inventory"] = {}}, ["y"] = 6, ["z"] = 20, ["name"] = "rainbow:wood_darkred"}, {["x"] = 7, ["meta"] = {["fields"] = {}, ["inventory"] = {}}, ["y"] = 6, ["z"] = 21, ["name"] = "rainbow:wood_darkred"}, {["x"] = 7, ["meta"] = {["fields"] = {}, ["inventory"] = {}}, ["y"] = 6, ["z"] = 22, ["name"] = "rainbow:wood_red"}, {["x"] = 7, ["meta"] = {["fields"] = {}, ["inventory"] = {}}, ["y"] = 6, ["z"] = 23, ["name"] = "rainbow:wood_darkred"}, {["x"] = 7, ["meta"] = {["fields"] = {}, ["inventory"] = {}}, ["y"] = 6, ["z"] = 24, ["name"] = "rainbow:wood_darkred"}, {["x"] = 7, ["meta"] = {["fields"] = {}, ["inventory"] = {}}, ["y"] = 6, ["z"] = 25, ["name"] = "rainbow:wood_darkred"}, {["x"] = 7, ["meta"] = {["fields"] = {}, ["inventory"] = {}}, ["y"] = 6, ["z"] = 26, ["name"] = "rainbow:wood_darkred"}, {["x"] = 7, ["meta"] = {["fields"] = {}, ["inventory"] = {}}, ["y"] = 6, ["z"] = 27, ["name"] = "rainbow:wood_darkred"}, {["x"] = 7, ["meta"] = {["fields"] = {}, ["inventory"] = {}}, ["y"] = 6, ["z"] = 28, ["name"] = "rainbow:wood_darkred"}, {["x"] = 7, ["meta"] = {["fields"] = {}, ["inventory"] = {}}, ["y"] = 6, ["z"] = 29, ["name"] = "rainbow:wood_darkred"}, {["x"] = 7, ["meta"] = {["fields"] = {}, ["inventory"] = {}}, ["y"] = 6, ["z"] = 30, ["name"] = "rainbow:wood_darkred"}, {["x"] = 7, ["meta"] = {["fields"] = {}, ["inventory"] = {}}, ["y"] = 6, ["z"] = 31, ["name"] = "rainbow:wood_darkred"}, {["x"] = 7, ["meta"] = {["fields"] = {}, ["inventory"] = {}}, ["y"] = 6, ["z"] = 32, ["name"] = "rainbow:wood_darkred"}, {["x"] = 7, ["meta"] = {["fields"] = {}, ["inventory"] = {}}, ["y"] = 6, ["z"] = 33, ["name"] = "rainbow:wood_red"}, {["x"] = 7, ["meta"] = {["fields"] = {}, ["inventory"] = {}}, ["y"] = 6, ["z"] = 34, ["name"] = "rainbow:wood_red"}, {["x"] = 7, ["meta"] = {["fields"] = {}, ["inventory"] = {}}, ["y"] = 6, ["z"] = 35, ["name"] = "rainbow:wood_red"}, {["x"] = 7, ["meta"] = {["fields"] = {}, ["inventory"] = {}}, ["y"] = 6, ["z"] = 36, ["name"] = "rainbow:wood_darkred"}, {["x"] = 7, ["meta"] = {["fields"] = {}, ["inventory"] = {}}, ["y"] = 6, ["z"] = 37, ["name"] = "rainbow:wood_darkred"}, {["x"] = 7, ["meta"] = {["fields"] = {}, ["inventory"] = {}}, ["y"] = 6, ["z"] = 38, ["name"] = "rainbow:wood_darkred"}, {["x"] = 7, ["meta"] = {["fields"] = {}, ["inventory"] = {}}, ["y"] = 6, ["z"] = 39, ["name"] = "rainbow:wood_darkred"}, {["x"] = 7, ["meta"] = {["fields"] = {}, ["inventory"] = {}}, ["y"] = 6, ["z"] = 40, ["name"] = "rainbow:wood_darkred"}, {["x"] = 7, ["meta"] = {["fields"] = {}, ["inventory"] = {}}, ["y"] = 6, ["z"] = 41, ["name"] = "rainbow:wood_darkred"}, {["x"] = 7, ["meta"] = {["fields"] = {}, ["inventory"] = {}}, ["y"] = 6, ["z"] = 42, ["name"] = "rainbow:wood_darkred"}, {["x"] = 7, ["meta"] = {["fields"] = {}, ["inventory"] = {}}, ["y"] = 6, ["z"] = 43, ["name"] = "rainbow:wood_darkred"}, {["x"] = 7, ["meta"] = {["fields"] = {}, ["inventory"] = {}}, ["y"] = 6, ["z"] = 44, ["name"] = "rainbow:wood_darkred"}, {["x"] = 7, ["meta"] = {["fields"] = {}, ["inventory"] = {}}, ["y"] = 6, ["z"] = 45, ["name"] = "rainbow:wood_darkred"}, {["x"] = 7, ["meta"] = {["fields"] = {}, ["inventory"] = {}}, ["y"] = 6, ["z"] = 46, ["name"] = "rainbow:wood_darkred"}, {["x"] = 7, ["meta"] = {["fields"] = {}, ["inventory"] = {}}, ["y"] = 6, ["z"] = 47, ["name"] = "rainbow:wood_darkred"}, {["x"] = 7, ["meta"] = {["fields"] = {}, ["inventory"] = {}}, ["y"] = 6, ["z"] = 48, ["name"] = "rainbow:wood_darkred"}, {["x"] = 7, ["meta"] = {["fields"] = {}, ["inventory"] = {}}, ["y"] = 6, ["z"] = 49, ["name"] = "rainbow:wood_darkred"}, {["x"] = 7, ["meta"] = {["fields"] = {}, ["inventory"] = {}}, ["y"] = 6, ["z"] = 50, ["name"] = "rainbow:wood_darkred"}, {["x"] = 7, ["meta"] = {["fields"] = {}, ["inventory"] = {}}, ["y"] = 6, ["z"] = 51, ["name"] = "rainbow:wood_darkred"}, {["x"] = 7, ["meta"] = {["fields"] = {}, ["inventory"] = {}}, ["param2"] = 16, ["y"] = 7, ["param1"] = 14, ["z"] = 12, ["name"] = "rainbow:slope_wood_red"}, {["x"] = 7, ["meta"] = {["fields"] = {}, ["inventory"] = {}}, ["y"] = 7, ["z"] = 13, ["name"] = "rainbow:wood_red"}, {["x"] = 7, ["meta"] = {["fields"] = {}, ["inventory"] = {}}, ["y"] = 7, ["z"] = 14, ["name"] = "rainbow:wood_red"}, {["x"] = 7, ["meta"] = {["fields"] = {}, ["inventory"] = {}}, ["y"] = 7, ["z"] = 15, ["name"] = "rainbow:wood_darkred"}, {["x"] = 7, ["meta"] = {["fields"] = {}, ["inventory"] = {}}, ["y"] = 7, ["z"] = 16, ["name"] = "rainbow:wood_darkred"}, {["x"] = 7, ["meta"] = {["fields"] = {}, ["inventory"] = {}}, ["y"] = 7, ["z"] = 17, ["name"] = "rainbow:wood_darkred"}, {["x"] = 7, ["meta"] = {["fields"] = {}, ["inventory"] = {}}, ["y"] = 7, ["z"] = 18, ["name"] = "rainbow:wood_darkred"}, {["x"] = 7, ["meta"] = {["fields"] = {}, ["inventory"] = {}}, ["y"] = 7, ["z"] = 19, ["name"] = "rainbow:wood_darkred"}, {["x"] = 7, ["meta"] = {["fields"] = {}, ["inventory"] = {}}, ["y"] = 7, ["z"] = 20, ["name"] = "rainbow:wood_darkred"}, {["x"] = 7, ["meta"] = {["fields"] = {}, ["inventory"] = {}}, ["y"] = 7, ["z"] = 21, ["name"] = "rainbow:wood_red"}, {["x"] = 7, ["meta"] = {["fields"] = {}, ["inventory"] = {}}, ["y"] = 7, ["z"] = 22, ["name"] = "rainbow:wood_darkred"}, {["x"] = 7, ["meta"] = {["fields"] = {}, ["inventory"] = {}}, ["param2"] = 4, ["y"] = 7, ["param1"] = 14, ["z"] = 23, ["name"] = "rainbow:slab_wood_yellow_1"}, {["x"] = 7, ["meta"] = {["fields"] = {}, ["inventory"] = {}}, ["y"] = 7, ["param1"] = 14, ["z"] = 33, ["name"] = "rainbow:slab_wood_darkred_1"}, {["x"] = 7, ["meta"] = {["fields"] = {}, ["inventory"] = {}}, ["y"] = 7, ["param1"] = 14, ["z"] = 34, ["name"] = "rainbow:slab_wood_darkred_1"}, {["x"] = 7, ["meta"] = {["fields"] = {}, ["inventory"] = {}}, ["y"] = 7, ["param1"] = 14, ["z"] = 35, ["name"] = "rainbow:slab_wood_darkred_1"}, {["x"] = 7, ["meta"] = {["fields"] = {}, ["inventory"] = {}}, ["y"] = 7, ["param1"] = 30, ["z"] = 41, ["name"] = "rainbow:stair_wood_black_alt_2"}, {["x"] = 7, ["meta"] = {["fields"] = {}, ["inventory"] = {}}, ["y"] = 7, ["z"] = 46, ["name"] = "rainbow:stoneblock_yellow"}, {["x"] = 7, ["meta"] = {["fields"] = {}, ["inventory"] = {}}, ["y"] = 7, ["z"] = 51, ["name"] = "rainbow:wood_darkred"}, {["x"] = 7, ["meta"] = {["fields"] = {}, ["inventory"] = {}}, ["y"] = 8, ["z"] = 13, ["name"] = "rainbow:wood_darkred"}, {["x"] = 7, ["meta"] = {["fields"] = {}, ["inventory"] = {}}, ["y"] = 8, ["z"] = 14, ["name"] = "rainbow:wood_darkred"}, {["x"] = 7, ["meta"] = {["fields"] = {}, ["inventory"] = {}}, ["y"] = 8, ["z"] = 15, ["name"] = "rainbow:wood_darkred"}, {["x"] = 7, ["meta"] = {["fields"] = {}, ["inventory"] = {}}, ["y"] = 8, ["z"] = 16, ["name"] = "rainbow:wood_darkred"}, {["x"] = 7, ["meta"] = {["fields"] = {}, ["inventory"] = {}}, ["y"] = 8, ["z"] = 17, ["name"] = "rainbow:wood_darkred"}, {["x"] = 7, ["meta"] = {["fields"] = {}, ["inventory"] = {}}, ["y"] = 8, ["z"] = 18, ["name"] = "rainbow:wood_darkred"}, {["x"] = 7, ["meta"] = {["fields"] = {}, ["inventory"] = {}}, ["y"] = 8, ["z"] = 19, ["name"] = "rainbow:wood_darkred"}, {["x"] = 7, ["meta"] = {["fields"] = {}, ["inventory"] = {}}, ["y"] = 8, ["z"] = 20, ["name"] = "rainbow:wood_darkred"}, {["x"] = 7, ["meta"] = {["fields"] = {}, ["inventory"] = {}}, ["y"] = 8, ["z"] = 21, ["name"] = "rainbow:wood_darkred"}, {["x"] = 7, ["meta"] = {["fields"] = {}, ["inventory"] = {}}, ["param2"] = 4, ["y"] = 8, ["param1"] = 14, ["z"] = 22, ["name"] = "rainbow:slope_wood_yellow"}, {["x"] = 7, ["meta"] = {["fields"] = {}, ["inventory"] = {}}, ["y"] = 8, ["param1"] = 62, ["z"] = 42, ["name"] = "rainbow:stair_wood_black_alt_2"}, {["x"] = 7, ["meta"] = {["fields"] = {}, ["inventory"] = {}}, ["y"] = 8, ["z"] = 46, ["name"] = "rainbow:stoneblock_yellow"}, {["x"] = 7, ["meta"] = {["fields"] = {}, ["inventory"] = {}}, ["y"] = 8, ["z"] = 52, ["name"] = "rainbow:wood_darkred"}, {["x"] = 7, ["meta"] = {["fields"] = {}, ["inventory"] = {}}, ["y"] = 9, ["param1"] = 14, ["z"] = 13, ["name"] = "rainbow:slab_wood_yellow_1"}, {["x"] = 7, ["meta"] = {["fields"] = {}, ["inventory"] = {}}, ["y"] = 9, ["param1"] = 14, ["z"] = 14, ["name"] = "rainbow:slab_wood_yellow_1"}, {["x"] = 7, ["meta"] = {["fields"] = {}, ["inventory"] = {}}, ["y"] = 9, ["param1"] = 14, ["z"] = 15, ["name"] = "rainbow:slab_wood_yellow_1"}, {["x"] = 7, ["meta"] = {["fields"] = {}, ["inventory"] = {}}, ["y"] = 9, ["param1"] = 14, ["z"] = 16, ["name"] = "rainbow:slab_wood_yellow_1"}, {["x"] = 7, ["meta"] = {["fields"] = {}, ["inventory"] = {}}, ["y"] = 9, ["param1"] = 14, ["z"] = 17, ["name"] = "rainbow:slab_wood_yellow_1"}, {["x"] = 7, ["meta"] = {["fields"] = {}, ["inventory"] = {}}, ["y"] = 9, ["param1"] = 14, ["z"] = 18, ["name"] = "rainbow:slab_wood_yellow_1"}, {["x"] = 7, ["meta"] = {["fields"] = {}, ["inventory"] = {}}, ["y"] = 9, ["param1"] = 14, ["z"] = 19, ["name"] = "rainbow:slab_wood_yellow_1"}, {["x"] = 7, ["meta"] = {["fields"] = {}, ["inventory"] = {}}, ["y"] = 9, ["param1"] = 14, ["z"] = 20, ["name"] = "rainbow:slab_wood_yellow_1"}, {["x"] = 7, ["meta"] = {["fields"] = {}, ["inventory"] = {}}, ["y"] = 9, ["param1"] = 14, ["z"] = 21, ["name"] = "rainbow:slab_wood_yellow_1"}, {["x"] = 7, ["meta"] = {["fields"] = {}, ["inventory"] = {}}, ["y"] = 9, ["param1"] = 94, ["z"] = 43, ["name"] = "rainbow:stair_wood_black_alt_2"}, {["x"] = 7, ["meta"] = {["fields"] = {}, ["inventory"] = {}}, ["y"] = 9, ["z"] = 46, ["name"] = "rainbow:stoneblock_yellow"}, {["x"] = 7, ["meta"] = {["fields"] = {}, ["inventory"] = {}}, ["y"] = 9, ["z"] = 52, ["name"] = "rainbow:wood_darkred"}, {["x"] = 7, ["meta"] = {["fields"] = {}, ["inventory"] = {}}, ["y"] = 10, ["param1"] = 126, ["z"] = 44, ["name"] = "rainbow:stair_wood_black_alt_2"}, {["x"] = 7, ["meta"] = {["fields"] = {}, ["inventory"] = {}}, ["y"] = 10, ["z"] = 46, ["name"] = "rainbow:stoneblock_yellow"}, {["x"] = 7, ["meta"] = {["fields"] = {}, ["inventory"] = {}}, ["y"] = 10, ["z"] = 53, ["name"] = "rainbow:wood_darkred"}, {["x"] = 7, ["meta"] = {["fields"] = {}, ["inventory"] = {}}, ["y"] = 11, ["param1"] = 126, ["z"] = 45, ["name"] = "rainbow:stair_wood_black_alt_2"}, {["x"] = 7, ["meta"] = {["fields"] = {}, ["inventory"] = {}}, ["y"] = 11, ["z"] = 46, ["name"] = "rainbow:stoneblock_yellow"}, {["x"] = 7, ["meta"] = {["fields"] = {}, ["inventory"] = {}}, ["y"] = 11, ["z"] = 53, ["name"] = "rainbow:wood_darkred"}, {["x"] = 7, ["meta"] = {["fields"] = {}, ["inventory"] = {}}, ["y"] = 12, ["param1"] = 94, ["z"] = 46, ["name"] = "rainbow:stair_wood_black_alt_2"}, {["x"] = 7, ["meta"] = {["fields"] = {}, ["inventory"] = {}}, ["y"] = 12, ["z"] = 47, ["name"] = "rainbow:wood_darkred"}, {["x"] = 7, ["meta"] = {["fields"] = {}, ["inventory"] = {}}, ["y"] = 12, ["z"] = 48, ["name"] = "rainbow:wood_darkred"}, {["x"] = 7, ["meta"] = {["fields"] = {}, ["inventory"] = {}}, ["y"] = 12, ["z"] = 49, ["name"] = "rainbow:wood_darkred"}, {["x"] = 7, ["meta"] = {["fields"] = {}, ["inventory"] = {}}, ["y"] = 12, ["z"] = 50, ["name"] = "rainbow:wood_darkred"}, {["x"] = 7, ["meta"] = {["fields"] = {}, ["inventory"] = {}}, ["y"] = 12, ["z"] = 51, ["name"] = "rainbow:wood_darkred"}, {["x"] = 7, ["meta"] = {["fields"] = {}, ["inventory"] = {}}, ["y"] = 12, ["z"] = 52, ["name"] = "rainbow:wood_darkred"}, {["x"] = 7, ["meta"] = {["fields"] = {}, ["inventory"] = {}}, ["y"] = 12, ["z"] = 53, ["name"] = "rainbow:wood_darkred"}, {["x"] = 7, ["meta"] = {["fields"] = {}, ["inventory"] = {}}, ["param2"] = 16, ["y"] = 13, ["param1"] = 14, ["z"] = 11, ["name"] = "rainbow:slope_wood_red_half"}, {["x"] = 7, ["meta"] = {["fields"] = {}, ["inventory"] = {}}, ["param2"] = 16, ["y"] = 13, ["param1"] = 14, ["z"] = 12, ["name"] = "rainbow:slope_wood_red_half_raised"}, {["x"] = 7, ["meta"] = {["fields"] = {}, ["inventory"] = {}}, ["param2"] = 6, ["y"] = 13, ["param1"] = 14, ["z"] = 13, ["name"] = "rainbow:slope_wood_red"}, {["x"] = 7, ["meta"] = {["fields"] = {}, ["inventory"] = {}}, ["y"] = 13, ["param1"] = 61, ["z"] = 50, ["name"] = "rainbow:stair_wood_black_alt_2"}, {["x"] = 7, ["meta"] = {["fields"] = {}, ["inventory"] = {}}, ["y"] = 13, ["z"] = 53, ["name"] = "rainbow:wood_darkred"}, {["x"] = 7, ["meta"] = {["fields"] = {}, ["inventory"] = {}}, ["y"] = 14, ["param1"] = 93, ["z"] = 51, ["name"] = "rainbow:stair_wood_black_alt_2"}, {["x"] = 7, ["meta"] = {["fields"] = {}, ["inventory"] = {}}, ["y"] = 14, ["z"] = 54, ["name"] = "rainbow:wood_darkred"}, {["x"] = 7, ["meta"] = {["fields"] = {}, ["inventory"] = {}}, ["y"] = 15, ["param1"] = 125, ["z"] = 52, ["name"] = "rainbow:stair_wood_black_alt_2"}, {["x"] = 7, ["meta"] = {["fields"] = {}, ["inventory"] = {}}, ["y"] = 15, ["z"] = 54, ["name"] = "rainbow:wood_darkred"}, {["x"] = 7, ["meta"] = {["fields"] = {}, ["inventory"] = {}}, ["y"] = 16, ["param1"] = 125, ["z"] = 53, ["name"] = "rainbow:stair_wood_black_alt_2"}, {["x"] = 7, ["meta"] = {["fields"] = {}, ["inventory"] = {}}, ["y"] = 16, ["z"] = 54, ["name"] = "rainbow:wood_darkred"}, {["x"] = 7, ["meta"] = {["fields"] = {}, ["inventory"] = {}}, ["y"] = 17, ["param1"] = 93, ["z"] = 54, ["name"] = "rainbow:stair_wood_black_alt_2"}, {["x"] = 7, ["meta"] = {["fields"] = {}, ["inventory"] = {}}, ["param2"] = 6, ["y"] = 17, ["param1"] = 78, ["z"] = 55, ["name"] = "rainbow:stair_wood_black"}, {["x"] = 7, ["meta"] = {["fields"] = {}, ["inventory"] = {}}, ["y"] = 18, ["z"] = 47, ["name"] = "default:obsidian"}, {["x"] = 7, ["meta"] = {["fields"] = {}, ["inventory"] = {}}, ["y"] = 18, ["z"] = 48, ["name"] = "default:obsidian"}, {["x"] = 7, ["meta"] = {["fields"] = {}, ["inventory"] = {}}, ["y"] = 18, ["z"] = 49, ["name"] = "default:obsidian"}, {["x"] = 7, ["meta"] = {["fields"] = {}, ["inventory"] = {}}, ["y"] = 18, ["z"] = 50, ["name"] = "default:obsidian"}, {["x"] = 7, ["meta"] = {["fields"] = {}, ["inventory"] = {}}, ["y"] = 18, ["z"] = 51, ["name"] = "default:obsidian"}, {["x"] = 7, ["meta"] = {["fields"] = {}, ["inventory"] = {}}, ["param2"] = 16, ["y"] = 18, ["param1"] = 78, ["z"] = 52, ["name"] = "rainbow:slab_wood_yellow_1"}, {["x"] = 7, ["meta"] = {["fields"] = {}, ["inventory"] = {}}, ["param2"] = 16, ["y"] = 18, ["param1"] = 94, ["z"] = 53, ["name"] = "rainbow:slab_wood_yellow_1"}, {["x"] = 7, ["meta"] = {["fields"] = {}, ["inventory"] = {}}, ["param2"] = 2, ["y"] = 18, ["param1"] = 46, ["z"] = 56, ["name"] = "homedecor:banister_wrought_iron_horizontal"}, {["x"] = 7, ["meta"] = {["fields"] = {}, ["inventory"] = {}}, ["param2"] = 1, ["y"] = 19, ["param1"] = 14, ["z"] = 47, ["name"] = "homedecor:shingle_outer_corner_asphalt"}, {["x"] = 7, ["meta"] = {["fields"] = {}, ["inventory"] = {}}, ["param2"] = 1, ["y"] = 19, ["param1"] = 14, ["z"] = 48, ["name"] = "homedecor:shingle_side_asphalt"}, {["x"] = 7, ["meta"] = {["fields"] = {}, ["inventory"] = {}}, ["param2"] = 1, ["y"] = 19, ["param1"] = 14, ["z"] = 49, ["name"] = "homedecor:shingle_side_asphalt"}, {["x"] = 7, ["meta"] = {["fields"] = {}, ["inventory"] = {}}, ["param2"] = 1, ["y"] = 19, ["param1"] = 30, ["z"] = 50, ["name"] = "homedecor:shingle_side_asphalt"}, {["x"] = 7, ["meta"] = {["fields"] = {}, ["inventory"] = {}}, ["param2"] = 1, ["y"] = 19, ["param1"] = 46, ["z"] = 51, ["name"] = "homedecor:shingle_side_asphalt"}, {["x"] = 7, ["meta"] = {["fields"] = {}, ["inventory"] = {}}, ["param2"] = 19, ["y"] = 19, ["param1"] = 62, ["z"] = 52, ["name"] = "homedecor:shingle_side_asphalt"}, {["x"] = 7, ["meta"] = {["fields"] = {}, ["inventory"] = {}}, ["param2"] = 16, ["y"] = 19, ["param1"] = 78, ["z"] = 53, ["name"] = "rainbow:slab_wood_yellow_1"}, {["x"] = 7, ["meta"] = {["fields"] = {}, ["inventory"] = {}}, ["param2"] = 16, ["y"] = 20, ["param1"] = 62, ["z"] = 53, ["name"] = "rainbow:slab_wood_yellow_1"}, {["x"] = 7, ["meta"] = {["fields"] = {}, ["inventory"] = {}}, ["param2"] = 16, ["y"] = 20, ["param1"] = 46, ["z"] = 54, ["name"] = "rainbow:slab_wood_yellow_1"}, {["x"] = 7, ["meta"] = {["fields"] = {}, ["inventory"] = {}}, ["param2"] = 22, ["y"] = 26, ["param1"] = 239, ["z"] = 16, ["name"] = "rainbow:slope_lightcoolglass_white_half_raised"}, {["x"] = 7, ["meta"] = {["fields"] = {}, ["inventory"] = {}}, ["param2"] = 22, ["y"] = 26, ["param1"] = 239, ["z"] = 17, ["name"] = "rainbow:slope_lightcoolglass_white_half"}, {["x"] = 7, ["meta"] = {["fields"] = {}, ["inventory"] = {}}, ["y"] = 27, ["param1"] = 239, ["z"] = 16, ["name"] = "rainbow:slope_lightcoolglass_white_half"}, {["x"] = 7, ["meta"] = {["fields"] = {}, ["inventory"] = {}}, ["y"] = 27, ["param1"] = 239, ["z"] = 17, ["name"] = "rainbow:slope_lightcoolglass_white_half_raised"}, {["x"] = 7, ["meta"] = {["fields"] = {}, ["inventory"] = {}}, ["param2"] = 22, ["y"] = 27, ["param1"] = 239, ["z"] = 18, ["name"] = "rainbow:slope_lightcoolglass_white_half_raised"}, {["x"] = 7, ["meta"] = {["fields"] = {}, ["inventory"] = {}}, ["param2"] = 22, ["y"] = 27, ["param1"] = 239, ["z"] = 19, ["name"] = "rainbow:slope_lightcoolglass_darkred_half"}, {["x"] = 7, ["meta"] = {["fields"] = {}, ["inventory"] = {}}, ["y"] = 28, ["param1"] = 239, ["z"] = 18, ["name"] = "rainbow:slope_lightcoolglass_white_half"}, {["x"] = 7, ["meta"] = {["fields"] = {}, ["inventory"] = {}}, ["y"] = 28, ["param1"] = 239, ["z"] = 19, ["name"] = "rainbow:slope_lightcoolglass_white_half_raised"}, {["x"] = 7, ["meta"] = {["fields"] = {}, ["inventory"] = {}}, ["param2"] = 22, ["y"] = 28, ["param1"] = 239, ["z"] = 20, ["name"] = "rainbow:slope_lightcoolglass_darkred_half_raised"}, {["x"] = 7, ["meta"] = {["fields"] = {}, ["inventory"] = {}}, ["param2"] = 22, ["y"] = 28, ["param1"] = 239, ["z"] = 21, ["name"] = "rainbow:slope_lightcoolglass_darkred_half"}, {["x"] = 7, ["meta"] = {["fields"] = {}, ["inventory"] = {}}, ["y"] = 29, ["param1"] = 239, ["z"] = 20, ["name"] = "rainbow:slope_lightcoolglass_white_half"}, {["x"] = 7, ["meta"] = {["fields"] = {}, ["inventory"] = {}}, ["y"] = 29, ["param1"] = 239, ["z"] = 21, ["name"] = "rainbow:slope_lightcoolglass_white_half_raised"}, {["x"] = 7, ["meta"] = {["fields"] = {}, ["inventory"] = {}}, ["param2"] = 22, ["y"] = 29, ["param1"] = 239, ["z"] = 22, ["name"] = "rainbow:slope_lightcoolglass_darkred_half_raised"}, {["x"] = 7, ["meta"] = {["fields"] = {}, ["inventory"] = {}}, ["param2"] = 22, ["y"] = 29, ["param1"] = 239, ["z"] = 23, ["name"] = "rainbow:slope_lightcoolglass_darkred_half"}, {["x"] = 7, ["meta"] = {["fields"] = {}, ["inventory"] = {}}, ["y"] = 30, ["param1"] = 239, ["z"] = 22, ["name"] = "rainbow:slope_lightcoolglass_white_half"}, {["x"] = 7, ["meta"] = {["fields"] = {}, ["inventory"] = {}}, ["y"] = 30, ["param1"] = 239, ["z"] = 23, ["name"] = "rainbow:slope_lightcoolglass_white_half_raised"}, {["x"] = 7, ["meta"] = {["fields"] = {}, ["inventory"] = {}}, ["param2"] = 22, ["y"] = 30, ["param1"] = 239, ["z"] = 24, ["name"] = "rainbow:slope_lightcoolglass_white_half_raised"}, {["x"] = 7, ["meta"] = {["fields"] = {}, ["inventory"] = {}}, ["param2"] = 22, ["y"] = 30, ["param1"] = 239, ["z"] = 25, ["name"] = "rainbow:slope_lightcoolglass_white_half"}, {["x"] = 7, ["meta"] = {["fields"] = {}, ["inventory"] = {}}, ["y"] = 31, ["param1"] = 239, ["z"] = 24, ["name"] = "rainbow:slope_lightcoolglass_white_half"}, {["x"] = 7, ["meta"] = {["fields"] = {}, ["inventory"] = {}}, ["y"] = 31, ["param1"] = 239, ["z"] = 25, ["name"] = "rainbow:slope_lightcoolglass_white_half_raised"}, {["x"] = 7, ["meta"] = {["fields"] = {}, ["inventory"] = {}}, ["param2"] = 22, ["y"] = 31, ["param1"] = 239, ["z"] = 26, ["name"] = "rainbow:slope_lightcoolglass_white_half_raised"}, {["x"] = 7, ["meta"] = {["fields"] = {}, ["inventory"] = {}}, ["param2"] = 22, ["y"] = 31, ["param1"] = 239, ["z"] = 27, ["name"] = "rainbow:slope_lightcoolglass_white_half"}, {["x"] = 7, ["meta"] = {["fields"] = {}, ["inventory"] = {}}, ["y"] = 32, ["param1"] = 239, ["z"] = 26, ["name"] = "rainbow:slope_lightcoolglass_white_half"}, {["x"] = 7, ["meta"] = {["fields"] = {}, ["inventory"] = {}}, ["y"] = 32, ["param1"] = 239, ["z"] = 27, ["name"] = "rainbow:slope_lightcoolglass_white_half_raised"}, {["x"] = 8, ["meta"] = {["fields"] = {}, ["inventory"] = {}}, ["y"] = 2, ["z"] = 24, ["name"] = "rainbow:wood_darkred"}, {["x"] = 8, ["meta"] = {["fields"] = {}, ["inventory"] = {}}, ["y"] = 2, ["z"] = 25, ["name"] = "rainbow:wood_darkred"}, {["x"] = 8, ["meta"] = {["fields"] = {}, ["inventory"] = {}}, ["y"] = 2, ["z"] = 26, ["name"] = "rainbow:wood_darkred"}, {["x"] = 8, ["meta"] = {["fields"] = {}, ["inventory"] = {}}, ["y"] = 2, ["z"] = 27, ["name"] = "rainbow:wood_darkred"}, {["x"] = 8, ["meta"] = {["fields"] = {}, ["inventory"] = {}}, ["y"] = 2, ["z"] = 28, ["name"] = "rainbow:wood_darkred"}, {["x"] = 8, ["meta"] = {["fields"] = {}, ["inventory"] = {}}, ["y"] = 2, ["z"] = 29, ["name"] = "rainbow:wood_darkred"}, {["x"] = 8, ["meta"] = {["fields"] = {}, ["inventory"] = {}}, ["y"] = 2, ["z"] = 30, ["name"] = "rainbow:wood_darkred"}, {["x"] = 8, ["meta"] = {["fields"] = {}, ["inventory"] = {}}, ["y"] = 2, ["z"] = 31, ["name"] = "rainbow:wood_darkred"}, {["x"] = 8, ["meta"] = {["fields"] = {}, ["inventory"] = {}}, ["y"] = 2, ["z"] = 32, ["name"] = "rainbow:wood_darkred"}, {["x"] = 8, ["meta"] = {["fields"] = {}, ["inventory"] = {}}, ["y"] = 2, ["z"] = 33, ["name"] = "rainbow:wood_darkred"}, {["x"] = 8, ["meta"] = {["fields"] = {}, ["inventory"] = {}}, ["y"] = 2, ["z"] = 34, ["name"] = "rainbow:wood_darkred"}, {["x"] = 8, ["meta"] = {["fields"] = {}, ["inventory"] = {}}, ["y"] = 2, ["z"] = 35, ["name"] = "rainbow:wood_darkred"}, {["x"] = 8, ["meta"] = {["fields"] = {}, ["inventory"] = {}}, ["y"] = 2, ["z"] = 36, ["name"] = "rainbow:wood_darkred"}, {["x"] = 8, ["meta"] = {["fields"] = {}, ["inventory"] = {}}, ["y"] = 2, ["z"] = 37, ["name"] = "rainbow:wood_darkred"}, {["x"] = 8, ["meta"] = {["fields"] = {}, ["inventory"] = {}}, ["y"] = 2, ["z"] = 38, ["name"] = "rainbow:wood_darkred"}, {["x"] = 8, ["meta"] = {["fields"] = {}, ["inventory"] = {}}, ["y"] = 2, ["z"] = 39, ["name"] = "rainbow:wood_darkred"}, {["x"] = 8, ["meta"] = {["fields"] = {}, ["inventory"] = {}}, ["y"] = 2, ["z"] = 40, ["name"] = "rainbow:wood_darkred"}, {["x"] = 8, ["meta"] = {["fields"] = {}, ["inventory"] = {}}, ["y"] = 2, ["z"] = 41, ["name"] = "rainbow:wood_darkred"}, {["x"] = 8, ["meta"] = {["fields"] = {}, ["inventory"] = {}}, ["y"] = 2, ["z"] = 42, ["name"] = "rainbow:wood_darkred"}, {["x"] = 8, ["meta"] = {["fields"] = {}, ["inventory"] = {}}, ["y"] = 2, ["z"] = 43, ["name"] = "rainbow:wood_darkred"}, {["x"] = 8, ["meta"] = {["fields"] = {}, ["inventory"] = {}}, ["y"] = 2, ["z"] = 44, ["name"] = "rainbow:wood_darkred"}, {["x"] = 8, ["meta"] = {["fields"] = {}, ["inventory"] = {}}, ["y"] = 2, ["z"] = 45, ["name"] = "rainbow:wood_darkred"}, {["x"] = 8, ["meta"] = {["fields"] = {}, ["inventory"] = {}}, ["y"] = 2, ["z"] = 46, ["name"] = "rainbow:wood_darkred"}, {["x"] = 8, ["meta"] = {["fields"] = {}, ["inventory"] = {}}, ["y"] = 3, ["z"] = 19, ["name"] = "rainbow:wood_darkred"}, {["x"] = 8, ["meta"] = {["fields"] = {}, ["inventory"] = {}}, ["y"] = 3, ["z"] = 20, ["name"] = "rainbow:wood_darkred"}, {["x"] = 8, ["meta"] = {["fields"] = {}, ["inventory"] = {}}, ["y"] = 3, ["z"] = 21, ["name"] = "rainbow:wood_darkred"}, {["x"] = 8, ["meta"] = {["fields"] = {}, ["inventory"] = {}}, ["y"] = 3, ["z"] = 22, ["name"] = "rainbow:wood_darkred"}, {["x"] = 8, ["meta"] = {["fields"] = {}, ["inventory"] = {}}, ["y"] = 3, ["z"] = 23, ["name"] = "rainbow:wood_darkred"}, {["x"] = 8, ["meta"] = {["fields"] = {}, ["inventory"] = {}}, ["y"] = 3, ["z"] = 47, ["name"] = "rainbow:wood_darkred"}, {["x"] = 8, ["meta"] = {["fields"] = {}, ["inventory"] = {}}, ["y"] = 3, ["z"] = 48, ["name"] = "rainbow:wood_darkred"}, {["x"] = 8, ["meta"] = {["fields"] = {}, ["inventory"] = {}}, ["y"] = 4, ["z"] = 17, ["name"] = "rainbow:wood_darkred"}, {["x"] = 8, ["meta"] = {["fields"] = {}, ["inventory"] = {}}, ["y"] = 4, ["z"] = 18, ["name"] = "rainbow:wood_darkred"}, {["x"] = 8, ["meta"] = {["fields"] = {}, ["inventory"] = {}}, ["y"] = 4, ["z"] = 19, ["name"] = "rainbow:wood_darkred"}, {["x"] = 8, ["meta"] = {["fields"] = {}, ["inventory"] = {}}, ["y"] = 4, ["z"] = 20, ["name"] = "rainbow:wood_darkred"}, {["x"] = 8, ["meta"] = {["fields"] = {}, ["inventory"] = {}}, ["y"] = 4, ["z"] = 49, ["name"] = "rainbow:wood_darkred"}, {["x"] = 8, ["meta"] = {["fields"] = {}, ["inventory"] = {}}, ["y"] = 5, ["z"] = 15, ["name"] = "rainbow:wood_darkred"}, {["x"] = 8, ["meta"] = {["fields"] = {}, ["inventory"] = {}}, ["y"] = 5, ["z"] = 16, ["name"] = "rainbow:wood_darkred"}, {["x"] = 8, ["meta"] = {["fields"] = {}, ["inventory"] = {}}, ["y"] = 5, ["z"] = 17, ["name"] = "rainbow:wood_darkred"}, {["x"] = 8, ["meta"] = {["fields"] = {}, ["inventory"] = {}}, ["y"] = 5, ["param1"] = 238, ["z"] = 34, ["name"] = "default:meselamp"}, {["x"] = 8, ["meta"] = {["fields"] = {}, ["inventory"] = {}}, ["y"] = 5, ["z"] = 50, ["name"] = "rainbow:wood_darkred"}, {["x"] = 8, ["meta"] = {["fields"] = {}, ["inventory"] = {}}, ["y"] = 6, ["z"] = 14, ["name"] = "rainbow:wood_darkred"}, {["x"] = 8, ["meta"] = {["fields"] = {}, ["inventory"] = {}}, ["y"] = 6, ["z"] = 21, ["name"] = "rainbow:wood_white"}, {["x"] = 8, ["meta"] = {["fields"] = {}, ["inventory"] = {}}, ["y"] = 6, ["z"] = 22, ["name"] = "rainbow:wood_darkred"}, {["x"] = 8, ["meta"] = {["fields"] = {}, ["inventory"] = {}}, ["y"] = 6, ["z"] = 23, ["name"] = "rainbow:wood_darkred"}, {["x"] = 8, ["meta"] = {["fields"] = {}, ["inventory"] = {}}, ["y"] = 6, ["z"] = 24, ["name"] = "rainbow:wood_darkred"}, {["x"] = 8, ["meta"] = {["fields"] = {}, ["inventory"] = {}}, ["y"] = 6, ["z"] = 25, ["name"] = "rainbow:wood_darkred"}, {["x"] = 8, ["meta"] = {["fields"] = {}, ["inventory"] = {}}, ["y"] = 6, ["z"] = 26, ["name"] = "rainbow:wood_darkred"}, {["x"] = 8, ["meta"] = {["fields"] = {}, ["inventory"] = {}}, ["y"] = 6, ["z"] = 27, ["name"] = "rainbow:wood_darkred"}, {["x"] = 8, ["meta"] = {["fields"] = {}, ["inventory"] = {}}, ["y"] = 6, ["z"] = 28, ["name"] = "rainbow:wood_darkred"}, {["x"] = 8, ["meta"] = {["fields"] = {}, ["inventory"] = {}}, ["y"] = 6, ["z"] = 29, ["name"] = "rainbow:wood_darkred"}, {["x"] = 8, ["meta"] = {["fields"] = {}, ["inventory"] = {}}, ["y"] = 6, ["z"] = 30, ["name"] = "rainbow:wood_darkred"},