5:return {{["x"] = 0, ["meta"] = {["fields"] = {}, ["inventory"] = {}}, ["y"] = 0, ["z"] = 0, ["name"] = "default:dirt_with_grass"}, {["x"] = 0, ["meta"] = {["fields"] = {}, ["inventory"] = {}}, ["y"] = 0, ["z"] = 1, ["name"] = "default:dirt_with_grass"}, {["x"] = 1, ["meta"] = {["fields"] = {}, ["inventory"] = {}}, ["y"] = 0, ["z"] = 0, ["name"] = "default:dirt_with_grass"}, {["x"] = 1, ["meta"] = {["fields"] = {}, ["inventory"] = {}}, ["y"] = 0, ["z"] = 1, ["name"] = "default:dirt_with_grass"}, {["x"] = 1, ["meta"] = {["fields"] = {}, ["inventory"] = {}}, ["y"] = 0, ["z"] = 2, ["name"] = "default:dirt_with_grass"}, {["x"] = 1, ["meta"] = {["fields"] = {}, ["inventory"] = {}}, ["y"] = 0, ["z"] = 3, ["name"] = "default:dirt_with_grass"}, {["x"] = 1, ["meta"] = {["fields"] = {}, ["inventory"] = {}}, ["y"] = 1, ["param1"] = 13, ["z"] = 1, ["name"] = "technic:hv_cable"}, {["x"] = 1, ["meta"] = {["fields"] = {}, ["inventory"] = {}}, ["y"] = 1, ["param1"] = 13, ["z"] = 2, ["name"] = "technic:hv_cable"}, {["x"] = 1, ["meta"] = {["fields"] = {}, ["inventory"] = {}}, ["y"] = 1, ["param1"] = 13, ["z"] = 3, ["name"] = "technic:hv_cable"}, {["x"] = 1, ["meta"] = {["fields"] = {}, ["inventory"] = {}}, ["y"] = 1, ["param1"] = 13, ["z"] = 4, ["name"] = "technic:hv_cable"}, {["x"] = 1, ["meta"] = {["fields"] = {}, ["inventory"] = {}}, ["y"] = 1, ["param1"] = 13, ["z"] = 5, ["name"] = "technic:hv_cable"}, {["x"] = 1, ["meta"] = {["fields"] = {["HV_EU_input"] = "0", ["HV_EU_timeout"] = "2", ["HV_EU_supply"] = "3800", ["infotext"] = "Arrayed Solar HV Generator Active (3 800 EU)"}, ["inventory"] = {}}, ["y"] = 2, ["param1"] = 13, ["z"] = 1, ["name"] = "technic:solar_array_hv"}, {["x"] = 1, ["meta"] = {["fields"] = {["HV_EU_input"] = "0", ["HV_EU_timeout"] = "2", ["HV_EU_supply"] = "3800", ["infotext"] = "Arrayed Solar HV Generator Active (3 800 EU)"}, ["inventory"] = {}}, ["y"] = 2, ["param1"] = 13, ["z"] = 2, ["name"] = "technic:solar_array_hv"}, {["x"] = 1, ["meta"] = {["fields"] = {["HV_EU_input"] = "0", ["HV_EU_timeout"] = "2", ["HV_EU_supply"] = "3800", ["infotext"] = "Arrayed Solar HV Generator Active (3 800 EU)"}, ["inventory"] = {}}, ["y"] = 2, ["param1"] = 13, ["z"] = 3, ["name"] = "technic:solar_array_hv"}, {["x"] = 1, ["meta"] = {["fields"] = {["HV_EU_input"] = "0", ["HV_EU_timeout"] = "2", ["HV_EU_supply"] = "3800", ["infotext"] = "Arrayed Solar HV Generator Active (3 800 EU)"}, ["inventory"] = {}}, ["y"] = 2, ["param1"] = 13, ["z"] = 4, ["name"] = "technic:solar_array_hv"}, {["x"] = 1, ["meta"] = {["fields"] = {["infotext"] = "Arrayed Solar HV Generator Active (3 800 EU)", ["HV_EU_timeout"] = "1", ["HV_EU_supply"] = "3800"}, ["inventory"] = {}}, ["y"] = 2, ["param1"] = 13, ["z"] = 5, ["name"] = "technic:solar_array_hv"}, {["x"] = 2, ["meta"] = {["fields"] = {}, ["inventory"] = {}}, ["y"] = 0, ["z"] = 0, ["name"] = "default:dirt_with_grass"}, {["x"] = 2, ["meta"] = {["fields"] = {}, ["inventory"] = {}}, ["y"] = 0, ["z"] = 1, ["name"] = "default:dirt_with_grass"}, {["x"] = 2, ["meta"] = {["fields"] = {}, ["inventory"] = {}}, ["y"] = 0, ["z"] = 2, ["name"] = "default:dirt_with_grass"}, {["x"] = 2, ["meta"] = {["fields"] = {}, ["inventory"] = {}}, ["y"] = 0, ["z"] = 3, ["name"] = "default:dirt_with_grass"}, {["x"] = 2, ["meta"] = {["fields"] = {}, ["inventory"] = {}}, ["y"] = 0, ["z"] = 4, ["name"] = "default:dirt_with_grass"}, {["x"] = 2, ["meta"] = {["fields"] = {}, ["inventory"] = {}}, ["y"] = 0, ["z"] = 5, ["name"] = "default:dirt_with_grass"}, {["x"] = 2, ["meta"] = {["fields"] = {}, ["inventory"] = {}}, ["y"] = 0, ["z"] = 6, ["name"] = "default:dirt_with_grass"}, {["x"] = 2, ["meta"] = {["fields"] = {}, ["inventory"] = {}}, ["y"] = 1, ["param1"] = 13, ["z"] = 1, ["name"] = "technic:hv_cable"}, {["x"] = 2, ["meta"] = {["fields"] = {}, ["inventory"] = {}}, ["y"] = 1, ["param1"] = 12, ["z"] = 2, ["name"] = "technic:hv_cable"}, {["x"] = 2, ["meta"] = {["fields"] = {}, ["inventory"] = {}}, ["y"] = 1, ["param1"] = 12, ["z"] = 3, ["name"] = "technic:hv_cable"}, {["x"] = 2, ["meta"] = {["fields"] = {}, ["inventory"] = {}}, ["y"] = 1, ["param1"] = 12, ["z"] = 4, ["name"] = "technic:hv_cable"}, {["x"] = 2, ["meta"] = {["fields"] = {}, ["inventory"] = {}}, ["y"] = 1, ["param1"] = 13, ["z"] = 5, ["name"] = "technic:hv_cable"}, {["x"] = 2, ["meta"] = {["fields"] = {["HV_EU_input"] = "0", ["HV_EU_timeout"] = "2", ["HV_EU_supply"] = "3800", ["infotext"] = "Arrayed Solar HV Generator Active (3 800 EU)"}, ["inventory"] = {}}, ["y"] = 2, ["param1"] = 13, ["z"] = 1, ["name"] = "technic:solar_array_hv"}, {["x"] = 2, ["meta"] = {["fields"] = {["HV_EU_input"] = "0", ["HV_EU_timeout"] = "2", ["HV_EU_supply"] = "3800", ["infotext"] = "Arrayed Solar HV Generator Active (3 800 EU)"}, ["inventory"] = {}}, ["y"] = 2, ["param1"] = 13, ["z"] = 2, ["name"] = "technic:solar_array_hv"}, {["x"] = 2, ["meta"] = {["fields"] = {["HV_EU_input"] = "0", ["HV_EU_timeout"] = "2", ["HV_EU_supply"] = "3800", ["infotext"] = "Arrayed Solar HV Generator Active (3 800 EU)"}, ["inventory"] = {}}, ["y"] = 2, ["param1"] = 13, ["z"] = 3, ["name"] = "technic:solar_array_hv"}, {["x"] = 2, ["meta"] = {["fields"] = {["HV_EU_input"] = "0", ["HV_EU_timeout"] = "2", ["HV_EU_supply"] = "3800", ["infotext"] = "Arrayed Solar HV Generator Active (3 800 EU)"}, ["inventory"] = {}}, ["y"] = 2, ["param1"] = 13, ["z"] = 4, ["name"] = "technic:solar_array_hv"}, {["x"] = 2, ["meta"] = {["fields"] = {["infotext"] = "Arrayed Solar HV Generator Active (3 800 EU)", ["HV_EU_timeout"] = "1", ["HV_EU_supply"] = "3800"}, ["inventory"] = {}}, ["y"] = 2, ["param1"] = 13, ["z"] = 5, ["name"] = "technic:solar_array_hv"}, {["x"] = 3, ["meta"] = {["fields"] = {}, ["inventory"] = {}}, ["y"] = 0, ["z"] = 0, ["name"] = "default:dirt_with_grass"}, {["x"] = 3, ["meta"] = {["fields"] = {}, ["inventory"] = {}}, ["y"] = 0, ["z"] = 1, ["name"] = "default:dirt_with_grass"}, {["x"] = 3, ["meta"] = {["fields"] = {}, ["inventory"] = {}}, ["y"] = 0, ["z"] = 2, ["name"] = "default:dirt_with_grass"}, {["x"] = 3, ["meta"] = {["fields"] = {}, ["inventory"] = {}}, ["y"] = 0, ["z"] = 3, ["name"] = "default:dirt_with_grass"}, {["x"] = 3, ["meta"] = {["fields"] = {}, ["inventory"] = {}}, ["y"] = 0, ["z"] = 4, ["name"] = "default:dirt_with_grass"}, {["x"] = 3, ["meta"] = {["fields"] = {}, ["inventory"] = {}}, ["y"] = 0, ["z"] = 5, ["name"] = "default:dirt_with_grass"}, {["x"] = 3, ["meta"] = {["fields"] = {}, ["inventory"] = {}}, ["y"] = 0, ["z"] = 6, ["name"] = "default:dirt_with_grass"}, {["x"] = 3, ["meta"] = {["fields"] = {}, ["inventory"] = {}}, ["y"] = 1, ["param1"] = 13, ["z"] = 1, ["name"] = "technic:hv_cable"}, {["x"] = 3, ["meta"] = {["fields"] = {}, ["inventory"] = {}}, ["y"] = 1, ["param1"] = 12, ["z"] = 2, ["name"] = "technic:hv_cable"}, {["x"] = 3, ["meta"] = {["fields"] = {}, ["inventory"] = {}}, ["y"] = 1, ["param1"] = 12, ["z"] = 3, ["name"] = "technic:hv_cable"}, {["x"] = 3, ["meta"] = {["fields"] = {}, ["inventory"] = {}}, ["y"] = 1, ["param1"] = 12, ["z"] = 4, ["name"] = "technic:hv_cable"}, {["x"] = 3, ["meta"] = {["fields"] = {}, ["inventory"] = {}}, ["y"] = 1, ["param1"] = 13, ["z"] = 5, ["name"] = "technic:hv_cable"}, {["x"] = 3, ["meta"] = {["fields"] = {["HV_EU_input"] = "0", ["HV_EU_timeout"] = "2", ["HV_EU_supply"] = "3800", ["infotext"] = "Arrayed Solar HV Generator Active (3 800 EU)"}, ["inventory"] = {}}, ["y"] = 2, ["param1"] = 13, ["z"] = 1, ["name"] = "technic:solar_array_hv"}, {["x"] = 3, ["meta"] = {["fields"] = {["HV_EU_input"] = "0", ["HV_EU_timeout"] = "2", ["HV_EU_supply"] = "3800", ["infotext"] = "Arrayed Solar HV Generator Active (3 800 EU)"}, ["inventory"] = {}}, ["y"] = 2, ["param1"] = 13, ["z"] = 2, ["name"] = "technic:solar_array_hv"}, {["x"] = 3, ["meta"] = {["fields"] = {["HV_EU_input"] = "0", ["HV_EU_timeout"] = "2", ["HV_EU_supply"] = "3800", ["infotext"] = "Arrayed Solar HV Generator Active (3 800 EU)"}, ["inventory"] = {}}, ["y"] = 2, ["param1"] = 13, ["z"] = 3, ["name"] = "technic:solar_array_hv"}, {["x"] = 3, ["meta"] = {["fields"] = {["HV_EU_input"] = "0", ["HV_EU_timeout"] = "2", ["HV_EU_supply"] = "3800", ["infotext"] = "Arrayed Solar HV Generator Active (3 800 EU)"}, ["inventory"] = {}}, ["y"] = 2, ["param1"] = 13, ["z"] = 4, ["name"] = "technic:solar_array_hv"}, {["x"] = 3, ["meta"] = {["fields"] = {["infotext"] = "Arrayed Solar HV Generator Active (3 800 EU)", ["HV_EU_timeout"] = "1", ["HV_EU_supply"] = "3800"}, ["inventory"] = {}}, ["y"] = 2, ["param1"] = 13, ["z"] = 5, ["name"] = "technic:solar_array_hv"}, {["x"] = 4, ["meta"] = {["fields"] = {}, ["inventory"] = {}}, ["y"] = 0, ["z"] = 0, ["name"] = "default:dirt_with_grass"}, {["x"] = 4, ["meta"] = {["fields"] = {}, ["inventory"] = {}}, ["y"] = 0, ["z"] = 1, ["name"] = "default:dirt_with_grass"}, {["x"] = 4, ["meta"] = {["fields"] = {}, ["inventory"] = {}}, ["y"] = 0, ["z"] = 2, ["name"] = "default:dirt_with_grass"}, {["x"] = 4, ["meta"] = {["fields"] = {}, ["inventory"] = {}}, ["y"] = 0, ["z"] = 3, ["name"] = "default:dirt_with_grass"}, {["x"] = 4, ["meta"] = {["fields"] = {}, ["inventory"] = {}}, ["y"] = 0, ["z"] = 4, ["name"] = "default:dirt_with_grass"}, {["x"] = 4, ["meta"] = {["fields"] = {}, ["inventory"] = {}}, ["y"] = 0, ["z"] = 5, ["name"] = "default:dirt_with_grass"}, {["x"] = 4, ["meta"] = {["fields"] = {}, ["inventory"] = {}}, ["y"] = 0, ["z"] = 6, ["name"] = "default:dirt_with_grass"}, {["x"] = 4, ["meta"] = {["fields"] = {}, ["inventory"] = {}}, ["y"] = 1, ["param1"] = 13, ["z"] = 1, ["name"] = "technic:hv_cable"}, {["x"] = 4, ["meta"] = {["fields"] = {}, ["inventory"] = {}}, ["y"] = 1, ["param1"] = 13, ["z"] = 2, ["name"] = "technic:hv_cable"}, {["x"] = 4, ["meta"] = {["fields"] = {}, ["inventory"] = {}}, ["y"] = 1, ["param1"] = 13, ["z"] = 3, ["name"] = "technic:hv_cable"}, {["x"] = 4, ["meta"] = {["fields"] = {}, ["inventory"] = {}}, ["y"] = 1, ["param1"] = 13, ["z"] = 4, ["name"] = "technic:hv_cable"}, {["x"] = 4, ["meta"] = {["fields"] = {}, ["inventory"] = {}}, ["y"] = 1, ["param1"] = 13, ["z"] = 5, ["name"] = "technic:hv_cable"}, {["x"] = 4, ["meta"] = {["fields"] = {["HV_EU_input"] = "0", ["HV_EU_timeout"] = "2", ["HV_EU_supply"] = "3800", ["infotext"] = "Arrayed Solar HV Generator Active (3 800 EU)"}, ["inventory"] = {}}, ["y"] = 2, ["param1"] = 13, ["z"] = 1, ["name"] = "technic:solar_array_hv"}, {["x"] = 4, ["meta"] = {["fields"] = {["HV_EU_input"] = "0", ["HV_EU_timeout"] = "2", ["HV_EU_supply"] = "3800", ["infotext"] = "Arrayed Solar HV Generator Active (3 800 EU)"}, ["inventory"] = {}}, ["y"] = 2, ["param1"] = 13, ["z"] = 2, ["name"] = "technic:solar_array_hv"}, {["x"] = 4, ["meta"] = {["fields"] = {["HV_EU_input"] = "0", ["HV_EU_timeout"] = "2", ["HV_EU_supply"] = "3800", ["infotext"] = "Arrayed Solar HV Generator Active (3 800 EU)"}, ["inventory"] = {}}, ["y"] = 2, ["param1"] = 13, ["z"] = 3, ["name"] = "technic:solar_array_hv"}, {["x"] = 4, ["meta"] = {["fields"] = {["HV_EU_input"] = "0", ["HV_EU_timeout"] = "2", ["HV_EU_supply"] = "3800", ["infotext"] = "Arrayed Solar HV Generator Active (3 800 EU)"}, ["inventory"] = {}}, ["y"] = 2, ["param1"] = 13, ["z"] = 4, ["name"] = "technic:solar_array_hv"}, {["x"] = 4, ["meta"] = {["fields"] = {["infotext"] = "Arrayed Solar HV Generator Active (3 800 EU)", ["HV_EU_timeout"] = "1", ["HV_EU_supply"] = "3800"}, ["inventory"] = {}}, ["y"] = 2, ["param1"] = 13, ["z"] = 5, ["name"] = "technic:solar_array_hv"}, {["x"] = 5, ["meta"] = {["fields"] = {}, ["inventory"] = {}}, ["y"] = 0, ["z"] = 0, ["name"] = "default:dirt_with_grass"}, {["x"] = 5, ["meta"] = {["fields"] = {}, ["inventory"] = {}}, ["y"] = 0, ["z"] = 1, ["name"] = "default:dirt_with_grass"}, {["x"] = 5, ["meta"] = {["fields"] = {}, ["inventory"] = {}}, ["y"] = 0, ["z"] = 2, ["name"] = "default:dirt_with_grass"}, {["x"] = 5, ["meta"] = {["fields"] = {}, ["inventory"] = {}}, ["y"] = 0, ["z"] = 3, ["name"] = "default:dirt_with_grass"}, {["x"] = 5, ["meta"] = {["fields"] = {}, ["inventory"] = {}}, ["y"] = 0, ["z"] = 4, ["name"] = "default:dirt_with_grass"}, {["x"] = 5, ["meta"] = {["fields"] = {}, ["inventory"] = {}}, ["y"] = 0, ["z"] = 5, ["name"] = "default:dirt_with_grass"}, {["x"] = 5, ["meta"] = {["fields"] = {}, ["inventory"] = {}}, ["y"] = 0, ["z"] = 6, ["name"] = "default:dirt_with_grass"}, {["x"] = 5, ["meta"] = {["fields"] = {}, ["inventory"] = {}}, ["y"] = 1, ["param1"] = 15, ["z"] = 3, ["name"] = "technic:hv_cable"}, {["x"] = 6, ["meta"] = {["fields"] = {}, ["inventory"] = {}}, ["y"] = 0, ["z"] = 0, ["name"] = "default:dirt_with_grass"}, {["x"] = 6, ["meta"] = {["fields"] = {}, ["inventory"] = {}}, ["y"] = 0, ["z"] = 1, ["name"] = "default:dirt_with_grass"}, {["x"] = 6, ["meta"] = {["fields"] = {}, ["inventory"] = {}}, ["y"] = 0, ["z"] = 2, ["name"] = "default:dirt_with_grass"}, {["x"] = 6, ["meta"] = {["fields"] = {}, ["inventory"] = {}}, ["y"] = 0, ["z"] = 3, ["name"] = "default:dirt_with_grass"}, {["x"] = 6, ["meta"] = {["fields"] = {}, ["inventory"] = {}}, ["y"] = 0, ["z"] = 4, ["name"] = "default:dirt_with_grass"}, {["x"] = 6, ["meta"] = {["fields"] = {}, ["inventory"] = {}}, ["y"] = 0, ["z"] = 5, ["name"] = "default:dirt_with_grass"}, {["x"] = 6, ["meta"] = {["fields"] = {}, ["inventory"] = {}}, ["y"] = 0, ["z"] = 6, ["name"] = "default:dirt_with_grass"}, {["x"] = 6, ["meta"] = {["fields"] = {["HV_EU_input"] = "0", ["HV_EU_demand"] = "0", ["formspec"] = "invsize[8,9;]image[1,1;1,2;technic_power_meter_bg.png]list[current_name;src;3,1;1,1;]image[4,1;1,1;technic_battery_reload.png]list[current_name;dst;5,1;1,1;]label[0,0;HV Battery Box]label[3,0;Charge]label[5,0;Discharge]label[1,3;Power level]list[current_player;main;0,5;8,4;]listring[current_name;dst]listring[current_player;main]listring[current_name;src]listring[current_player;main]list[current_name;upgrade1;3.5,3;1,1;]list[current_name;upgrade2;4.5,3;1,1;]label[3.5,4;Upgrade Slots]listring[current_name;upgrade1]listring[current_player;main]listring[current_name;upgrade2]listring[current_player;main]image[1,1;1,2;technic_power_meter_bg.png^[lowpart:100:technic_power_meter_fg.png]", ["internal_EU_charge"] = "1000000", ["HV_EU_supply"] = "400000", ["tube_time"] = "0", ["infotext"] = "HV Battery Box: 1 000 000/1 000 000 Idle", ["HV_EU_timeout"] = "2", ["last_side_shown"] = "8"}, ["inventory"] = {["upgrade2"] = {""}, ["src"] = {""}, ["upgrade1"] = {""}, ["dst"] = {""}}}, ["param2"] = 1, ["y"] = 1, ["z"] = 1, ["name"] = "technic:hv_battery_box8"}, {["x"] = 6, ["meta"] = {["fields"] = {}, ["inventory"] = {}}, ["y"] = 1, ["param1"] = 13, ["z"] = 2, ["name"] = "technic:hv_cable"}, {["x"] = 6, ["meta"] = {["fields"] = {}, ["inventory"] = {}}, ["y"] = 1, ["param1"] = 13, ["z"] = 3, ["name"] = "technic:hv_cable"}, {["x"] = 6, ["meta"] = {["fields"] = {}, ["inventory"] = {}}, ["y"] = 1, ["param1"] = 13, ["z"] = 4, ["name"] = "technic:hv_cable"}, {["x"] = 6, ["meta"] = {["fields"] = {["HV_EU_input"] = "0", ["HV_EU_demand"] = "0", ["shape"] = "0", ["formspec"] = "size[5,2.25]field[0.3,0.5;2,1;range;Range;5]button[3,0.2;2,1;shape1;Sphere]button[0,1;5,1;mesecon_mode_1;Ignoring Mesecon Signal]button[0,1.75;5,1;enable;HV Forcefield Emitter Disabled]", ["mesecon_effect"] = "0", ["HV_EU_timeout"] = "1", ["mesecon_mode"] = "0", ["enabled"] = "0", ["range"] = "5", ["infotext"] = "HV Forcefield Emitter Disabled"}, ["inventory"] = {}}, ["y"] = 1, ["z"] = 5, ["name"] = "technic:forcefield_emitter_off"}, {["x"] = 6, ["meta"] = {["fields"] = {["infotext"] = "Switching Station. Supply: 76 000 Demand: 0", ["active"] = "1", ["HV_EU_timeout"] = "2"}, ["inventory"] = {}}, ["y"] = 2, ["z"] = 2, ["name"] = "technic:switching_station"}, {["x"] = 6, ["meta"] = {["fields"] = {["infotext"] = "Switching Station. Supply: 76 000 Demand: 0 (Slave)", ["active"] = "1", ["HV_EU_timeout"] = "2", ["active_pos"] = "return {[\"y\"] = 23, [\"x\"] = 392, [\"z\"] = 3085}"}, ["inventory"] = {}}, ["y"] = 2, ["z"] = 3, ["name"] = "technic:switching_station"}, {["x"] = 6, ["meta"] = {["fields"] = {["infotext"] = "Switching Station. Supply: 76 000 Demand: 0 (Slave)", ["active"] = "1", ["HV_EU_timeout"] = "2", ["active_pos"] = "return {[\"y\"] = 23, [\"x\"] = 392, [\"z\"] = 3085}"}, ["inventory"] = {}}, ["y"] = 2, ["z"] = 4, ["name"] = "technic:switching_station"}, {["x"] = 7, ["meta"] = {["fields"] = {}, ["inventory"] = {}}, ["y"] = 0, ["z"] = 0, ["name"] = "default:dirt_with_grass"}, {["x"] = 7, ["meta"] = {["fields"] = {}, ["inventory"] = {}}, ["y"] = 0, ["z"] = 1, ["name"] = "default:dirt_with_grass"}, {["x"] = 7, ["meta"] = {["fields"] = {}, ["inventory"] = {}}, ["y"] = 0, ["z"] = 2, ["name"] = "default:dirt_with_grass"}, {["x"] = 7, ["meta"] = {["fields"] = {}, ["inventory"] = {}}, ["y"] = 0, ["z"] = 3, ["name"] = "default:dirt_with_grass"}, {["x"] = 7, ["meta"] = {["fields"] = {}, ["inventory"] = {}}, ["y"] = 0, ["z"] = 4, ["name"] = "default:dirt_with_grass"}, {["x"] = 7, ["meta"] = {["fields"] = {}, ["inventory"] = {}}, ["y"] = 0, ["z"] = 5, ["name"] = "default:dirt_with_grass"}, {["x"] = 7, ["meta"] = {["fields"] = {}, ["inventory"] = {}}, ["y"] = 0, ["z"] = 6, ["name"] = "default:dirt_with_grass"}}