5:return {{["x"] = 0, ["meta"] = {["fields"] = {["infotext"] = "Command Block\
(owned by Nigel)\
Commands: give @nearest stone 99", ["owner"] = "Nigel", ["commands"] = "give @nearest stone 99", ["formspec"] = "invsize[9,5;]textarea[0.5,0.5;8.5,4;commands;Commands;give @nearest stone 99]label[1,3.8;@nearest, @farthest, and @random are replaced by the respective player names]button_exit[3.3,4.5;2,1;submit;Submit]"}, ["inventory"] = {}}, ["y"] = 0, ["z"] = 0, ["name"] = "mesecons_commandblock:commandblock_off"}, {["x"] = 0, ["meta"] = {["fields"] = {["infotext"] = "Command Block\
(owned by Nigel)\
Commands: give @nearest glass 99", ["owner"] = "Nigel", ["commands"] = "give @nearest glass 99", ["formspec"] = "invsize[9,5;]textarea[0.5,0.5;8.5,4;commands;Commands;give @nearest glass 99]label[1,3.8;@nearest, @farthest, and @random are replaced by the respective player names]button_exit[3.3,4.5;2,1;submit;Submit]"}, ["inventory"] = {}}, ["y"] = 0, ["z"] = 1, ["name"] = "mesecons_commandblock:commandblock_off"}, {["x"] = 0, ["meta"] = {["fields"] = {["infotext"] = "Command Block\
(owned by Nigel)\
Commands: give @nearest protector:door_steel 5", ["owner"] = "Nigel", ["commands"] = "give @nearest protector:door_steel 5", ["formspec"] = "invsize[9,5;]textarea[0.5,0.5;8.5,4;commands;Commands;give @nearest protector:door_steel 5]label[1,3.8;@nearest, @farthest, and @random are replaced by the respective player names]button_exit[3.3,4.5;2,1;submit;Submit]"}, ["inventory"] = {}}, ["y"] = 0, ["z"] = 2, ["name"] = "mesecons_commandblock:commandblock_off"}, {["x"] = 0, ["meta"] = {["fields"] = {["infotext"] = "Command Block\
(owned by Nigel)\
Commands: give @nearest protector:protect 5", ["owner"] = "Nigel", ["commands"] = "give @nearest protector:protect 5", ["formspec"] = "invsize[9,5;]textarea[0.5,0.5;8.5,4;commands;Commands;give @nearest protector:protect 5]label[1,3.8;@nearest, @farthest, and @random are replaced by the respective player names]button_exit[3.3,4.5;2,1;submit;Submit]"}, ["inventory"] = {}}, ["y"] = 0, ["z"] = 3, ["name"] = "mesecons_commandblock:commandblock_off"}, {["x"] = 0, ["meta"] = {["fields"] = {["infotext"] = "Command Block\
(owned by Nigel)\
Commands: give @nearest maptools:coalblock 99", ["owner"] = "Nigel", ["commands"] = "give @nearest maptools:coalblock 99", ["formspec"] = "invsize[9,5;]textarea[0.5,0.5;8.5,4;commands;Commands;give @nearest maptools:coalblock 99]label[1,3.8;@nearest, @farthest, and @random are replaced by the respective player names]button_exit[3.3,4.5;2,1;submit;Submit]"}, ["inventory"] = {}}, ["y"] = 0, ["z"] = 4, ["name"] = "mesecons_commandblock:commandblock_off"}, {["x"] = 0, ["meta"] = {["fields"] = {["infotext"] = "Command Block\
(owned by Nigel)\
Commands: give @nearest wood 99", ["owner"] = "Nigel", ["commands"] = "give @nearest wood 99", ["formspec"] = "invsize[9,5;]textarea[0.5,0.5;8.5,4;commands;Commands;give @nearest wood 99]label[1,3.8;@nearest, @farthest, and @random are replaced by the respective player names]button_exit[3.3,4.5;2,1;submit;Submit]"}, ["inventory"] = {}}, ["y"] = 0, ["z"] = 5, ["name"] = "mesecons_commandblock:commandblock_off"}, {["x"] = 0, ["meta"] = {["fields"] = {}, ["inventory"] = {}}, ["y"] = 1, ["z"] = 0, ["name"] = "default:stone"}, {["x"] = 0, ["meta"] = {["fields"] = {}, ["inventory"] = {}}, ["y"] = 1, ["param1"] = 205, ["z"] = 1, ["name"] = "default:glass"}, {["x"] = 0, ["meta"] = {["fields"] = {}, ["inventory"] = {}}, ["param2"] = 3, ["y"] = 1, ["param1"] = 205, ["z"] = 2, ["name"] = "protector:door_steel_b_1"}, {["x"] = 0, ["meta"] = {["fields"] = {["infotext"] = "Protection (owned by Nigel)", ["owner"] = "Nigel"}, ["inventory"] = {}}, ["y"] = 1, ["param1"] = 205, ["z"] = 3, ["name"] = "protector:protect"}, {["x"] = 0, ["meta"] = {["fields"] = {}, ["inventory"] = {}}, ["y"] = 1, ["z"] = 4, ["name"] = "maptools:coalblock"}, {["x"] = 0, ["meta"] = {["fields"] = {}, ["inventory"] = {}}, ["y"] = 1, ["z"] = 5, ["name"] = "default:wood"}, {["x"] = 0, ["meta"] = {["fields"] = {}, ["inventory"] = {}}, ["y"] = 2, ["z"] = 0, ["name"] = "default:stone"}, {["x"] = 0, ["meta"] = {["fields"] = {}, ["inventory"] = {}}, ["y"] = 2, ["param1"] = 221, ["z"] = 1, ["name"] = "default:glass"}, {["x"] = 0, ["meta"] = {["fields"] = {}, ["inventory"] = {}}, ["param2"] = 3, ["y"] = 2, ["param1"] = 221, ["z"] = 2, ["name"] = "protector:door_steel_t_1"}, {["x"] = 0, ["meta"] = {["fields"] = {["infotext"] = "Protection (owned by Nigel)", ["owner"] = "Nigel"}, ["inventory"] = {}}, ["y"] = 2, ["param1"] = 221, ["z"] = 3, ["name"] = "protector:protect"}, {["x"] = 0, ["meta"] = {["fields"] = {}, ["inventory"] = {}}, ["y"] = 2, ["z"] = 4, ["name"] = "default:coalblock"}, {["x"] = 0, ["meta"] = {["fields"] = {}, ["inventory"] = {}}, ["y"] = 2, ["z"] = 5, ["name"] = "default:wood"}, {["x"] = 0, ["meta"] = {["fields"] = {}, ["inventory"] = {}}, ["y"] = 3, ["z"] = 0, ["name"] = "projection_light:light"}, {["x"] = 0, ["meta"] = {["fields"] = {}, ["inventory"] = {}}, ["y"] = 3, ["z"] = 1, ["name"] = "projection_light:light"}, {["x"] = 0, ["meta"] = {["fields"] = {}, ["inventory"] = {}}, ["y"] = 3, ["z"] = 2, ["name"] = "projection_light:light"}, {["x"] = 0, ["meta"] = {["fields"] = {}, ["inventory"] = {}}, ["y"] = 3, ["z"] = 3, ["name"] = "projection_light:light"}, {["x"] = 0, ["meta"] = {["fields"] = {}, ["inventory"] = {}}, ["y"] = 3, ["z"] = 4, ["name"] = "projection_light:light"}, {["x"] = 0, ["meta"] = {["fields"] = {}, ["inventory"] = {}}, ["y"] = 3, ["z"] = 5, ["name"] = "projection_light:light"}, {["x"] = 1, ["meta"] = {["fields"] = {}, ["inventory"] = {}}, ["y"] = 0, ["param1"] = 13, ["z"] = 0, ["name"] = "default:sandstonebrick"}, {["x"] = 1, ["meta"] = {["fields"] = {}, ["inventory"] = {}}, ["y"] = 0, ["param1"] = 13, ["z"] = 1, ["name"] = "default:sandstonebrick"}, {["x"] = 1, ["meta"] = {["fields"] = {}, ["inventory"] = {}}, ["y"] = 0, ["param1"] = 13, ["z"] = 2, ["name"] = "default:sandstonebrick"}, {["x"] = 1, ["meta"] = {["fields"] = {}, ["inventory"] = {}}, ["y"] = 0, ["param1"] = 13, ["z"] = 3, ["name"] = "default:sandstonebrick"}, {["x"] = 1, ["meta"] = {["fields"] = {}, ["inventory"] = {}}, ["y"] = 0, ["param1"] = 13, ["z"] = 4, ["name"] = "default:sandstonebrick"}, {["x"] = 1, ["meta"] = {["fields"] = {}, ["inventory"] = {}}, ["y"] = 0, ["param1"] = 13, ["z"] = 5, ["name"] = "default:sandstonebrick"}, {["x"] = 1, ["meta"] = {["fields"] = {}, ["inventory"] = {}}, ["param2"] = 3, ["y"] = 1, ["param1"] = 205, ["z"] = 0, ["name"] = "mesecons_button:button_off"}, {["x"] = 1, ["meta"] = {["fields"] = {}, ["inventory"] = {}}, ["param2"] = 3, ["y"] = 1, ["param1"] = 205, ["z"] = 1, ["name"] = "mesecons_button:button_off"}, {["x"] = 1, ["meta"] = {["fields"] = {}, ["inventory"] = {}}, ["param2"] = 3, ["y"] = 1, ["param1"] = 205, ["z"] = 2, ["name"] = "mesecons_button:button_off"}, {["x"] = 1, ["meta"] = {["fields"] = {}, ["inventory"] = {}}, ["param2"] = 3, ["y"] = 1, ["param1"] = 205, ["z"] = 3, ["name"] = "mesecons_button:button_off"}, {["x"] = 1, ["meta"] = {["fields"] = {}, ["inventory"] = {}}, ["param2"] = 3, ["y"] = 1, ["param1"] = 205, ["z"] = 4, ["name"] = "mesecons_button:button_off"}, {["x"] = 1, ["meta"] = {["fields"] = {}, ["inventory"] = {}}, ["param2"] = 3, ["y"] = 1, ["param1"] = 205, ["z"] = 5, ["name"] = "mesecons_button:button_off"}, {["x"] = 1, ["meta"] = {["fields"] = {["infotext"] = "FREE\
STONE ", ["text"] = "FREE\
STONE\
", ["__signslib_new_format"] = "1", ["formspec"] = "size[6,4]textarea[0,-0.3;6.5,3;text;;${text}]button_exit[2,3.4;2,1;ok;Write]background[-0.5,-0.5;7,5;bg_signs_lib.jpg]"}, ["inventory"] = {}}, ["param2"] = 3, ["y"] = 2, ["param1"] = 221, ["z"] = 0, ["name"] = "signs:sign_wall_white_black"}, {["x"] = 1, ["meta"] = {["fields"] = {["infotext"] = "FREE\
GLASS ", ["text"] = "FREE\
GLASS\
", ["__signslib_new_format"] = "1", ["formspec"] = "size[6,4]textarea[0,-0.3;6.5,3;text;;${text}]button_exit[2,3.4;2,1;ok;Write]background[-0.5,-0.5;7,5;bg_signs_lib.jpg]"}, ["inventory"] = {}}, ["param2"] = 3, ["y"] = 2, ["param1"] = 221, ["z"] = 1, ["name"] = "signs:sign_wall_white_black"}, {["x"] = 1, ["meta"] = {["fields"] = {["infotext"] = "FREE\
PROTECTED\
DOORS ", ["text"] = "FREE\
PROTECTED\
DOORS", ["__signslib_new_format"] = "1", ["formspec"] = "size[6,4]textarea[0,-0.3;6.5,3;text;;${text}]button_exit[2,3.4;2,1;ok;Write]background[-0.5,-0.5;7,5;bg_signs_lib.jpg]"}, ["inventory"] = {}}, ["param2"] = 3, ["y"] = 2, ["param1"] = 221, ["z"] = 2, ["name"] = "signs:sign_wall_white_black"}, {["x"] = 1, ["meta"] = {["fields"] = {["infotext"] = "FREE\
PROTECTION\
BLOCKS ", ["text"] = "FREE\
PROTECTION\
BLOCKS", ["__signslib_new_format"] = "1", ["formspec"] = "size[6,4]textarea[0,-0.3;6.5,3;text;;${text}]button_exit[2,3.4;2,1;ok;Write]background[-0.5,-0.5;7,5;bg_signs_lib.jpg]"}, ["inventory"] = {}}, ["param2"] = 3, ["y"] = 2, ["param1"] = 221, ["z"] = 3, ["name"] = "signs:sign_wall_white_black"}, {["x"] = 1, ["meta"] = {["fields"] = {["infotext"] = "FREE\
COAL ", ["text"] = "FREE \
COAL", ["__signslib_new_format"] = "1", ["formspec"] = "size[6,4]textarea[0,-0.3;6.5,3;text;;${text}]button_exit[2,3.4;2,1;ok;Write]background[-0.5,-0.5;7,5;bg_signs_lib.jpg]"}, ["inventory"] = {}}, ["param2"] = 3, ["y"] = 2, ["param1"] = 221, ["z"] = 4, ["name"] = "signs:sign_wall_white_black"}, {["x"] = 1, ["meta"] = {["fields"] = {["infotext"] = "FREE WOOD ", ["text"] = "FREE WOOD", ["__signslib_new_format"] = "1", ["formspec"] = "size[6,4]textarea[0,-0.3;6.5,3;text;;${text}]button_exit[2,3.4;2,1;ok;Write]background[-0.5,-0.5;7,5;bg_signs_lib.jpg]"}, ["inventory"] = {}}, ["param2"] = 3, ["y"] = 2, ["param1"] = 221, ["z"] = 5, ["name"] = "signs:sign_wall_white_black"}, {["x"] = 1, ["meta"] = {["fields"] = {}, ["inventory"] = {}}, ["y"] = 3, ["z"] = 0, ["name"] = "projection_light:light"}, {["x"] = 1, ["meta"] = {["fields"] = {}, ["inventory"] = {}}, ["y"] = 3, ["z"] = 1, ["name"] = "projection_light:light"}, {["x"] = 1, ["meta"] = {["fields"] = {}, ["inventory"] = {}}, ["y"] = 3, ["z"] = 2, ["name"] = "projection_light:light"}, {["x"] = 1, ["meta"] = {["fields"] = {}, ["inventory"] = {}}, ["y"] = 3, ["z"] = 3, ["name"] = "projection_light:light"}, {["x"] = 1, ["meta"] = {["fields"] = {}, ["inventory"] = {}}, ["y"] = 3, ["z"] = 4, ["name"] = "projection_light:light"}, {["x"] = 1, ["meta"] = {["fields"] = {}, ["inventory"] = {}}, ["y"] = 3, ["z"] = 5, ["name"] = "projection_light:light"}, {["x"] = 2, ["meta"] = {["fields"] = {}, ["inventory"] = {}}, ["y"] = 0, ["param1"] = 13, ["z"] = 0, ["name"] = "default:sandstonebrick"}, {["x"] = 2, ["meta"] = {["fields"] = {}, ["inventory"] = {}}, ["y"] = 0, ["param1"] = 13, ["z"] = 1, ["name"] = "default:sandstonebrick"}, {["x"] = 2, ["meta"] = {["fields"] = {}, ["inventory"] = {}}, ["y"] = 0, ["param1"] = 13, ["z"] = 2, ["name"] = "default:sandstonebrick"}, {["x"] = 2, ["meta"] = {["fields"] = {}, ["inventory"] = {}}, ["y"] = 0, ["param1"] = 13, ["z"] = 3, ["name"] = "default:sandstonebrick"}, {["x"] = 2, ["meta"] = {["fields"] = {}, ["inventory"] = {}}, ["y"] = 0, ["param1"] = 13, ["z"] = 4, ["name"] = "default:sandstonebrick"}, {["x"] = 2, ["meta"] = {["fields"] = {}, ["inventory"] = {}}, ["y"] = 0, ["param1"] = 29, ["z"] = 5, ["name"] = "default:sandstonebrick"}, {["x"] = 2, ["meta"] = {["fields"] = {}, ["inventory"] = {}}, ["param2"] = 3, ["y"] = 3, ["param1"] = 15, ["z"] = 1, ["name"] = "spell:Sign_F"}, {["x"] = 2, ["meta"] = {["fields"] = {}, ["inventory"] = {}}, ["param2"] = 3, ["y"] = 3, ["param1"] = 15, ["z"] = 2, ["name"] = "spell:Sign_R"}, {["x"] = 2, ["meta"] = {["fields"] = {}, ["inventory"] = {}}, ["param2"] = 3, ["y"] = 3, ["param1"] = 15, ["z"] = 3, ["name"] = "spell:Sign_E"}, {["x"] = 2, ["meta"] = {["fields"] = {}, ["inventory"] = {}}, ["param2"] = 3, ["y"] = 3, ["param1"] = 15, ["z"] = 4, ["name"] = "spell:Sign_E"}}