5:return {{["x"] = 1, ["meta"] = {["fields"] = {}, ["inventory"] = {}}, ["param2"] = 3, ["y"] = 0, ["param1"] = 206, ["z"] = 1, ["name"] = "homedecor:fence_picket_corner_white"}, {["x"] = 1, ["meta"] = {["fields"] = {}, ["inventory"] = {}}, ["param2"] = 3, ["y"] = 0, ["param1"] = 222, ["z"] = 2, ["name"] = "homedecor:fence_picket_white"}, {["x"] = 1, ["meta"] = {["fields"] = {}, ["inventory"] = {}}, ["param2"] = 3, ["y"] = 0, ["param1"] = 206, ["z"] = 3, ["name"] = "homedecor:fence_picket_white"}, {["x"] = 1, ["meta"] = {["fields"] = {}, ["inventory"] = {}}, ["param2"] = 3, ["y"] = 0, ["param1"] = 190, ["z"] = 4, ["name"] = "homedecor:fence_picket_white"}, {["x"] = 1, ["meta"] = {["fields"] = {}, ["inventory"] = {}}, ["param2"] = 3, ["y"] = 0, ["param1"] = 174, ["z"] = 5, ["name"] = "homedecor:fence_picket_white"}, {["x"] = 1, ["meta"] = {["fields"] = {}, ["inventory"] = {}}, ["param2"] = 3, ["y"] = 0, ["param1"] = 158, ["z"] = 6, ["name"] = "homedecor:fence_picket_white"}, {["x"] = 1, ["meta"] = {["fields"] = {}, ["inventory"] = {}}, ["param2"] = 3, ["y"] = 0, ["param1"] = 142, ["z"] = 7, ["name"] = "homedecor:fence_picket_white"}, {["x"] = 1, ["meta"] = {["fields"] = {}, ["inventory"] = {}}, ["param2"] = 3, ["y"] = 0, ["param1"] = 126, ["z"] = 8, ["name"] = "homedecor:fence_picket_white"}, {["x"] = 1, ["meta"] = {["fields"] = {}, ["inventory"] = {}}, ["param2"] = 3, ["y"] = 0, ["param1"] = 110, ["z"] = 9, ["name"] = "homedecor:fence_picket_white"}, {["x"] = 1, ["meta"] = {["fields"] = {}, ["inventory"] = {}}, ["param2"] = 3, ["y"] = 0, ["param1"] = 94, ["z"] = 10, ["name"] = "homedecor:fence_picket_white"}, {["x"] = 1, ["meta"] = {["fields"] = {}, ["inventory"] = {}}, ["param2"] = 3, ["y"] = 0, ["param1"] = 110, ["z"] = 11, ["name"] = "homedecor:fence_picket_white"}, {["x"] = 1, ["meta"] = {["fields"] = {}, ["inventory"] = {}}, ["param2"] = 3, ["y"] = 0, ["param1"] = 126, ["z"] = 12, ["name"] = "homedecor:fence_picket_white"}, {["x"] = 1, ["meta"] = {["fields"] = {}, ["inventory"] = {}}, ["param2"] = 3, ["y"] = 0, ["param1"] = 142, ["z"] = 13, ["name"] = "homedecor:fence_picket_white"}, {["x"] = 1, ["meta"] = {["fields"] = {}, ["inventory"] = {}}, ["param2"] = 3, ["y"] = 0, ["param1"] = 158, ["z"] = 14, ["name"] = "homedecor:fence_picket_white"}, {["x"] = 1, ["meta"] = {["fields"] = {}, ["inventory"] = {}}, ["param2"] = 3, ["y"] = 0, ["param1"] = 174, ["z"] = 15, ["name"] = "homedecor:fence_picket_white"}, {["x"] = 1, ["meta"] = {["fields"] = {}, ["inventory"] = {}}, ["param2"] = 3, ["y"] = 0, ["param1"] = 190, ["z"] = 16, ["name"] = "homedecor:fence_picket_white"}, {["x"] = 1, ["meta"] = {["fields"] = {}, ["inventory"] = {}}, ["param2"] = 3, ["y"] = 0, ["param1"] = 206, ["z"] = 17, ["name"] = "homedecor:fence_picket_white"}, {["x"] = 1, ["meta"] = {["fields"] = {}, ["inventory"] = {}}, ["param2"] = 3, ["y"] = 0, ["param1"] = 222, ["z"] = 18, ["name"] = "homedecor:fence_picket_white"}, {["x"] = 1, ["meta"] = {["fields"] = {}, ["inventory"] = {}}, ["y"] = 0, ["param1"] = 206, ["z"] = 19, ["name"] = "homedecor:fence_picket_corner_white"}, {["x"] = 2, ["meta"] = {["fields"] = {}, ["inventory"] = {}}, ["param2"] = 2, ["y"] = 0, ["param1"] = 222, ["z"] = 1, ["name"] = "homedecor:fence_picket_white"}, {["x"] = 2, ["meta"] = {["fields"] = {}, ["inventory"] = {}}, ["y"] = 0, ["param1"] = 239, ["z"] = 2, ["name"] = "default:mese_post_light"}, {["x"] = 2, ["meta"] = {["fields"] = {}, ["inventory"] = {}}, ["y"] = 0, ["param1"] = 239, ["z"] = 18, ["name"] = "default:mese_post_light"}, {["x"] = 2, ["meta"] = {["fields"] = {}, ["inventory"] = {}}, ["y"] = 0, ["param1"] = 222, ["z"] = 19, ["name"] = "homedecor:fence_picket_white"}, {["x"] = 3, ["meta"] = {["fields"] = {}, ["inventory"] = {}}, ["param2"] = 2, ["y"] = 0, ["param1"] = 206, ["z"] = 1, ["name"] = "homedecor:fence_picket_white"}, {["x"] = 3, ["meta"] = {["fields"] = {}, ["inventory"] = {}}, ["y"] = 0, ["param1"] = 206, ["z"] = 19, ["name"] = "homedecor:fence_picket_white"}, {["x"] = 3, ["meta"] = {["fields"] = {}, ["inventory"] = {}}, ["y"] = 9, ["z"] = 3, ["name"] = "default:steelblock"}, {["x"] = 3, ["meta"] = {["fields"] = {}, ["inventory"] = {}}, ["y"] = 9, ["z"] = 4, ["name"] = "default:steelblock"}, {["x"] = 3, ["meta"] = {["fields"] = {}, ["inventory"] = {}}, ["y"] = 9, ["z"] = 5, ["name"] = "default:steelblock"}, {["x"] = 3, ["meta"] = {["fields"] = {}, ["inventory"] = {}}, ["y"] = 9, ["z"] = 6, ["name"] = "default:steelblock"}, {["x"] = 3, ["meta"] = {["fields"] = {}, ["inventory"] = {}}, ["y"] = 9, ["z"] = 7, ["name"] = "default:steelblock"}, {["x"] = 3, ["meta"] = {["fields"] = {}, ["inventory"] = {}}, ["y"] = 9, ["z"] = 8, ["name"] = "default:steelblock"}, {["x"] = 3, ["meta"] = {["fields"] = {}, ["inventory"] = {}}, ["y"] = 9, ["z"] = 9, ["name"] = "default:steelblock"}, {["x"] = 3, ["meta"] = {["fields"] = {}, ["inventory"] = {}}, ["y"] = 9, ["z"] = 10, ["name"] = "default:steelblock"}, {["x"] = 3, ["meta"] = {["fields"] = {}, ["inventory"] = {}}, ["y"] = 9, ["z"] = 11, ["name"] = "default:steelblock"}, {["x"] = 3, ["meta"] = {["fields"] = {}, ["inventory"] = {}}, ["y"] = 9, ["z"] = 12, ["name"] = "default:steelblock"}, {["x"] = 3, ["meta"] = {["fields"] = {}, ["inventory"] = {}}, ["y"] = 9, ["z"] = 13, ["name"] = "default:steelblock"}, {["x"] = 3, ["meta"] = {["fields"] = {}, ["inventory"] = {}}, ["y"] = 9, ["z"] = 14, ["name"] = "default:steelblock"}, {["x"] = 3, ["meta"] = {["fields"] = {}, ["inventory"] = {}}, ["y"] = 9, ["z"] = 15, ["name"] = "default:steelblock"}, {["x"] = 3, ["meta"] = {["fields"] = {}, ["inventory"] = {}}, ["y"] = 9, ["z"] = 16, ["name"] = "default:steelblock"}, {["x"] = 3, ["meta"] = {["fields"] = {}, ["inventory"] = {}}, ["y"] = 9, ["z"] = 17, ["name"] = "default:steelblock"}, {["x"] = 3, ["meta"] = {["fields"] = {}, ["inventory"] = {}}, ["y"] = 10, ["param1"] = 207, ["z"] = 3, ["name"] = "xpanes:pane"}, {["x"] = 3, ["meta"] = {["fields"] = {}, ["inventory"] = {}}, ["param2"] = 3, ["y"] = 10, ["param1"] = 223, ["z"] = 4, ["name"] = "xpanes:pane_flat"}, {["x"] = 3, ["meta"] = {["fields"] = {}, ["inventory"] = {}}, ["param2"] = 3, ["y"] = 10, ["param1"] = 207, ["z"] = 5, ["name"] = "xpanes:pane_flat"}, {["x"] = 3, ["meta"] = {["fields"] = {}, ["inventory"] = {}}, ["param2"] = 3, ["y"] = 10, ["param1"] = 191, ["z"] = 6, ["name"] = "xpanes:pane_flat"}, {["x"] = 3, ["meta"] = {["fields"] = {}, ["inventory"] = {}}, ["param2"] = 3, ["y"] = 10, ["param1"] = 175, ["z"] = 7, ["name"] = "xpanes:pane_flat"}, {["x"] = 3, ["meta"] = {["fields"] = {}, ["inventory"] = {}}, ["param2"] = 3, ["y"] = 10, ["param1"] = 159, ["z"] = 8, ["name"] = "xpanes:pane_flat"}, {["x"] = 3, ["meta"] = {["fields"] = {}, ["inventory"] = {}}, ["param2"] = 3, ["y"] = 10, ["param1"] = 159, ["z"] = 9, ["name"] = "xpanes:pane_flat"}, {["x"] = 3, ["meta"] = {["fields"] = {}, ["inventory"] = {}}, ["param2"] = 3, ["y"] = 10, ["param1"] = 159, ["z"] = 10, ["name"] = "xpanes:pane_flat"}, {["x"] = 3, ["meta"] = {["fields"] = {}, ["inventory"] = {}}, ["param2"] = 3, ["y"] = 10, ["param1"] = 159, ["z"] = 11, ["name"] = "xpanes:pane_flat"}, {["x"] = 3, ["meta"] = {["fields"] = {}, ["inventory"] = {}}, ["param2"] = 3, ["y"] = 10, ["param1"] = 159, ["z"] = 12, ["name"] = "xpanes:pane_flat"}, {["x"] = 3, ["meta"] = {["fields"] = {}, ["inventory"] = {}}, ["param2"] = 3, ["y"] = 10, ["param1"] = 175, ["z"] = 13, ["name"] = "xpanes:pane_flat"}, {["x"] = 3, ["meta"] = {["fields"] = {}, ["inventory"] = {}}, ["param2"] = 3, ["y"] = 10, ["param1"] = 191, ["z"] = 14, ["name"] = "xpanes:pane_flat"}, {["x"] = 3, ["meta"] = {["fields"] = {}, ["inventory"] = {}}, ["param2"] = 3, ["y"] = 10, ["param1"] = 207, ["z"] = 15, ["name"] = "xpanes:pane_flat"}, {["x"] = 3, ["meta"] = {["fields"] = {}, ["inventory"] = {}}, ["param2"] = 3, ["y"] = 10, ["param1"] = 223, ["z"] = 16, ["name"] = "xpanes:pane_flat"}, {["x"] = 3, ["meta"] = {["fields"] = {}, ["inventory"] = {}}, ["y"] = 10, ["param1"] = 207, ["z"] = 17, ["name"] = "xpanes:pane"}, {["x"] = 4, ["meta"] = {["fields"] = {}, ["inventory"] = {}}, ["param2"] = 2, ["y"] = 0, ["param1"] = 206, ["z"] = 1, ["name"] = "homedecor:fence_picket_white"}, {["x"] = 4, ["meta"] = {["fields"] = {}, ["inventory"] = {}}, ["y"] = 0, ["param1"] = 190, ["z"] = 19, ["name"] = "homedecor:fence_picket_white"}, {["x"] = 4, ["meta"] = {["fields"] = {}, ["inventory"] = {}}, ["y"] = 9, ["z"] = 3, ["name"] = "default:steelblock"}, {["x"] = 4, ["meta"] = {["fields"] = {}, ["inventory"] = {}}, ["y"] = 9, ["z"] = 4, ["name"] = "default:steelblock"}, {["x"] = 4, ["meta"] = {["fields"] = {}, ["inventory"] = {}}, ["y"] = 9, ["z"] = 5, ["name"] = "default:steelblock"}, {["x"] = 4, ["meta"] = {["fields"] = {}, ["inventory"] = {}}, ["y"] = 9, ["z"] = 6, ["name"] = "default:steelblock"}, {["x"] = 4, ["meta"] = {["fields"] = {}, ["inventory"] = {}}, ["y"] = 9, ["z"] = 7, ["name"] = "default:steelblock"}, {["x"] = 4, ["meta"] = {["fields"] = {}, ["inventory"] = {}}, ["y"] = 9, ["z"] = 8, ["name"] = "default:steelblock"}, {["x"] = 4, ["meta"] = {["fields"] = {}, ["inventory"] = {}}, ["y"] = 9, ["z"] = 9, ["name"] = "default:steelblock"}, {["x"] = 4, ["meta"] = {["fields"] = {}, ["inventory"] = {}}, ["y"] = 9, ["z"] = 10, ["name"] = "default:steelblock"}, {["x"] = 4, ["meta"] = {["fields"] = {}, ["inventory"] = {}}, ["y"] = 9, ["z"] = 11, ["name"] = "default:steelblock"}, {["x"] = 4, ["meta"] = {["fields"] = {}, ["inventory"] = {}}, ["y"] = 9, ["z"] = 12, ["name"] = "default:steelblock"}, {["x"] = 4, ["meta"] = {["fields"] = {}, ["inventory"] = {}}, ["y"] = 9, ["z"] = 13, ["name"] = "default:steelblock"}, {["x"] = 4, ["meta"] = {["fields"] = {}, ["inventory"] = {}}, ["y"] = 9, ["z"] = 14, ["name"] = "default:steelblock"}, {["x"] = 4, ["meta"] = {["fields"] = {}, ["inventory"] = {}}, ["y"] = 9, ["z"] = 15, ["name"] = "default:steelblock"}, {["x"] = 4, ["meta"] = {["fields"] = {}, ["inventory"] = {}}, ["y"] = 9, ["z"] = 16, ["name"] = "default:steelblock"}, {["x"] = 4, ["meta"] = {["fields"] = {}, ["inventory"] = {}}, ["y"] = 9, ["z"] = 17, ["name"] = "default:steelblock"}, {["x"] = 4, ["meta"] = {["fields"] = {}, ["inventory"] = {}}, ["y"] = 10, ["param1"] = 223, ["z"] = 3, ["name"] = "xpanes:pane_flat"}, {["x"] = 4, ["meta"] = {["fields"] = {}, ["inventory"] = {}}, ["y"] = 10, ["param1"] = 239, ["z"] = 4, ["name"] = "default:mese_post_light"}, {["x"] = 4, ["meta"] = {["fields"] = {}, ["inventory"] = {}}, ["y"] = 10, ["param1"] = 239, ["z"] = 16, ["name"] = "default:mese_post_light"}, {["x"] = 4, ["meta"] = {["fields"] = {}, ["inventory"] = {}}, ["y"] = 10, ["param1"] = 223, ["z"] = 17, ["name"] = "xpanes:pane_flat"}, {["x"] = 5, ["meta"] = {["fields"] = {}, ["inventory"] = {}}, ["param2"] = 2, ["y"] = 0, ["param1"] = 206, ["z"] = 1, ["name"] = "homedecor:fence_picket_white"}, {["x"] = 5, ["meta"] = {["fields"] = {}, ["inventory"] = {}}, ["y"] = 0, ["param1"] = 174, ["z"] = 19, ["name"] = "homedecor:fence_picket_white"}, {["x"] = 5, ["meta"] = {["fields"] = {}, ["inventory"] = {}}, ["y"] = 8, ["param1"] = 238, ["z"] = 5, ["name"] = "default:mese_post_light"}, {["x"] = 5, ["meta"] = {["fields"] = {}, ["inventory"] = {}}, ["y"] = 8, ["param1"] = 238, ["z"] = 10, ["name"] = "default:mese_post_light"}, {["x"] = 5, ["meta"] = {["fields"] = {}, ["inventory"] = {}}, ["y"] = 8, ["param1"] = 238, ["z"] = 15, ["name"] = "default:mese_post_light"}, {["x"] = 5, ["meta"] = {["fields"] = {}, ["inventory"] = {}}, ["y"] = 9, ["z"] = 3, ["name"] = "default:steelblock"}, {["x"] = 5, ["meta"] = {["fields"] = {}, ["inventory"] = {}}, ["y"] = 9, ["z"] = 4, ["name"] = "default:steelblock"}, {["x"] = 5, ["meta"] = {["fields"] = {}, ["inventory"] = {}}, ["y"] = 9, ["z"] = 5, ["name"] = "default:steelblock"}, {["x"] = 5, ["meta"] = {["fields"] = {}, ["inventory"] = {}}, ["y"] = 9, ["z"] = 6, ["name"] = "default:steelblock"}, {["x"] = 5, ["meta"] = {["fields"] = {}, ["inventory"] = {}}, ["y"] = 9, ["z"] = 7, ["name"] = "default:steelblock"}, {["x"] = 5, ["meta"] = {["fields"] = {}, ["inventory"] = {}}, ["y"] = 9, ["z"] = 8, ["name"] = "default:steelblock"}, {["x"] = 5, ["meta"] = {["fields"] = {}, ["inventory"] = {}}, ["y"] = 9, ["z"] = 9, ["name"] = "default:steelblock"}, {["x"] = 5, ["meta"] = {["fields"] = {}, ["inventory"] = {}}, ["y"] = 9, ["z"] = 10, ["name"] = "default:steelblock"}, {["x"] = 5, ["meta"] = {["fields"] = {}, ["inventory"] = {}}, ["y"] = 9, ["z"] = 11, ["name"] = "default:steelblock"}, {["x"] = 5, ["meta"] = {["fields"] = {}, ["inventory"] = {}}, ["y"] = 9, ["z"] = 12, ["name"] = "default:steelblock"}, {["x"] = 5, ["meta"] = {["fields"] = {}, ["inventory"] = {}}, ["y"] = 9, ["z"] = 13, ["name"] = "default:steelblock"}, {["x"] = 5, ["meta"] = {["fields"] = {}, ["inventory"] = {}}, ["y"] = 9, ["z"] = 14, ["name"] = "default:steelblock"}, {["x"] = 5, ["meta"] = {["fields"] = {}, ["inventory"] = {}}, ["y"] = 9, ["z"] = 15, ["name"] = "default:steelblock"}, {["x"] = 5, ["meta"] = {["fields"] = {}, ["inventory"] = {}}, ["y"] = 9, ["z"] = 16, ["name"] = "default:steelblock"}, {["x"] = 5, ["meta"] = {["fields"] = {}, ["inventory"] = {}}, ["y"] = 9, ["z"] = 17, ["name"] = "default:steelblock"}, {["x"] = 5, ["meta"] = {["fields"] = {}, ["inventory"] = {}}, ["y"] = 10, ["param1"] = 207, ["z"] = 3, ["name"] = "xpanes:pane_flat"}, {["x"] = 5, ["meta"] = {["fields"] = {}, ["inventory"] = {}}, ["y"] = 10, ["param1"] = 207, ["z"] = 17, ["name"] = "xpanes:pane_flat"}, {["x"] = 6, ["meta"] = {["fields"] = {}, ["inventory"] = {}}, ["param2"] = 2, ["y"] = 0, ["param1"] = 206, ["z"] = 1, ["name"] = "homedecor:fence_picket_white"}, {["x"] = 6, ["meta"] = {["fields"] = {}, ["inventory"] = {}}, ["y"] = 0, ["z"] = 6, ["name"] = "default:steelblock"}, {["x"] = 6, ["meta"] = {["fields"] = {}, ["inventory"] = {}}, ["y"] = 0, ["z"] = 7, ["name"] = "default:steelblock"}, {["x"] = 6, ["meta"] = {["fields"] = {}, ["inventory"] = {}}, ["y"] = 0, ["z"] = 8, ["name"] = "default:steelblock"}, {["x"] = 6, ["meta"] = {["fields"] = {}, ["inventory"] = {}}, ["y"] = 0, ["z"] = 9, ["name"] = "default:steelblock"}, {["x"] = 6, ["meta"] = {["fields"] = {}, ["inventory"] = {}}, ["y"] = 0, ["z"] = 10, ["name"] = "default:steelblock"}, {["x"] = 6, ["meta"] = {["fields"] = {}, ["inventory"] = {}}, ["y"] = 0, ["z"] = 11, ["name"] = "default:steelblock"}, {["x"] = 6, ["meta"] = {["fields"] = {}, ["inventory"] = {}}, ["y"] = 0, ["z"] = 12, ["name"] = "default:steelblock"}, {["x"] = 6, ["meta"] = {["fields"] = {}, ["inventory"] = {}}, ["y"] = 0, ["z"] = 13, ["name"] = "default:steelblock"}, {["x"] = 6, ["meta"] = {["fields"] = {}, ["inventory"] = {}}, ["y"] = 0, ["z"] = 14, ["name"] = "default:steelblock"}, {["x"] = 6, ["meta"] = {["fields"] = {}, ["inventory"] = {}}, ["y"] = 0, ["param1"] = 158, ["z"] = 19, ["name"] = "homedecor:fence_picket_white"}, {["x"] = 6, ["meta"] = {["fields"] = {}, ["inventory"] = {}}, ["y"] = 1, ["z"] = 6, ["name"] = "default:steelblock"}, {["x"] = 6, ["meta"] = {["fields"] = {}, ["inventory"] = {}}, ["y"] = 1, ["z"] = 7, ["name"] = "default:steelblock"}, {["x"] = 6, ["meta"] = {["fields"] = {}, ["inventory"] = {}}, ["y"] = 1, ["z"] = 8, ["name"] = "default:steelblock"}, {["x"] = 6, ["meta"] = {["fields"] = {}, ["inventory"] = {}}, ["y"] = 1, ["param1"] = 173, ["z"] = 9, ["name"] = "default:obsidian_glass"}, {["x"] = 6, ["meta"] = {["fields"] = {}, ["inventory"] = {}}, ["y"] = 1, ["param1"] = 174, ["z"] = 10, ["name"] = "default:obsidian_glass"}, {["x"] = 6, ["meta"] = {["fields"] = {}, ["inventory"] = {}}, ["y"] = 1, ["param1"] = 173, ["z"] = 11, ["name"] = "default:obsidian_glass"}, {["x"] = 6, ["meta"] = {["fields"] = {}, ["inventory"] = {}}, ["y"] = 1, ["z"] = 12, ["name"] = "default:steelblock"}, {["x"] = 6, ["meta"] = {["fields"] = {}, ["inventory"] = {}}, ["y"] = 1, ["z"] = 13, ["name"] = "default:steelblock"}, {["x"] = 6, ["meta"] = {["fields"] = {}, ["inventory"] = {}}, ["y"] = 1, ["z"] = 14, ["name"] = "default:steelblock"}, {["x"] = 6, ["meta"] = {["fields"] = {}, ["inventory"] = {}}, ["y"] = 2, ["z"] = 6, ["name"] = "default:steelblock"}, {["x"] = 6, ["meta"] = {["fields"] = {}, ["inventory"] = {}}, ["y"] = 2, ["z"] = 7, ["name"] = "default:steelblock"}, {["x"] = 6, ["meta"] = {["fields"] = {}, ["inventory"] = {}}, ["y"] = 2, ["z"] = 8, ["name"] = "default:steelblock"}, {["x"] = 6, ["meta"] = {["fields"] = {}, ["inventory"] = {}}, ["y"] = 2, ["param1"] = 189, ["z"] = 9, ["name"] = "default:obsidian_glass"}, {["x"] = 6, ["meta"] = {["fields"] = {}, ["inventory"] = {}}, ["y"] = 2, ["param1"] = 190, ["z"] = 10, ["name"] = "default:obsidian_glass"}, {["x"] = 6, ["meta"] = {["fields"] = {}, ["inventory"] = {}}, ["y"] = 2, ["param1"] = 190, ["z"] = 11, ["name"] = "default:obsidian_glass"}, {["x"] = 6, ["meta"] = {["fields"] = {}, ["inventory"] = {}}, ["y"] = 2, ["z"] = 12, ["name"] = "default:steelblock"}, {["x"] = 6, ["meta"] = {["fields"] = {}, ["inventory"] = {}}, ["y"] = 2, ["z"] = 13, ["name"] = "default:steelblock"}, {["x"] = 6, ["meta"] = {["fields"] = {}, ["inventory"] = {}}, ["y"] = 2, ["z"] = 14, ["name"] = "default:steelblock"}, {["x"] = 6, ["meta"] = {["fields"] = {}, ["inventory"] = {}}, ["y"] = 3, ["z"] = 6, ["name"] = "default:steelblock"}, {["x"] = 6, ["meta"] = {["fields"] = {}, ["inventory"] = {}}, ["y"] = 3, ["z"] = 7, ["name"] = "default:steelblock"}, {["x"] = 6, ["meta"] = {["fields"] = {}, ["inventory"] = {}}, ["y"] = 3, ["z"] = 8, ["name"] = "default:steelblock"}, {["x"] = 6, ["meta"] = {["fields"] = {}, ["inventory"] = {}}, ["y"] = 3, ["z"] = 9, ["name"] = "default:steelblock"}, {["x"] = 6, ["meta"] = {["fields"] = {}, ["inventory"] = {}}, ["y"] = 3, ["z"] = 10, ["name"] = "default:steelblock"}, {["x"] = 6, ["meta"] = {["fields"] = {}, ["inventory"] = {}}, ["y"] = 3, ["z"] = 11, ["name"] = "default:steelblock"}, {["x"] = 6, ["meta"] = {["fields"] = {}, ["inventory"] = {}}, ["y"] = 3, ["z"] = 12, ["name"] = "default:steelblock"}, {["x"] = 6, ["meta"] = {["fields"] = {}, ["inventory"] = {}}, ["y"] = 3, ["z"] = 13, ["name"] = "default:steelblock"}, {["x"] = 6, ["meta"] = {["fields"] = {}, ["inventory"] = {}}, ["y"] = 3, ["z"] = 14, ["name"] = "default:steelblock"}, {["x"] = 6, ["meta"] = {["fields"] = {}, ["inventory"] = {}}, ["y"] = 4, ["z"] = 6, ["name"] = "default:steelblock"}, {["x"] = 6, ["meta"] = {["fields"] = {}, ["inventory"] = {}}, ["y"] = 4, ["z"] = 7, ["name"] = "default:steelblock"}, {["x"] = 6, ["meta"] = {["fields"] = {}, ["inventory"] = {}}, ["y"] = 4, ["z"] = 8, ["name"] = "default:steelblock"}, {["x"] = 6, ["meta"] = {["fields"] = {}, ["inventory"] = {}}, ["y"] = 4, ["z"] = 9, ["name"] = "default:steelblock"}, {["x"] = 6, ["meta"] = {["fields"] = {}, ["inventory"] = {}}, ["y"] = 4, ["z"] = 10, ["name"] = "default:steelblock"}, {["x"] = 6, ["meta"] = {["fields"] = {}, ["inventory"] = {}}, ["y"] = 4, ["z"] = 11, ["name"] = "default:steelblock"}, {["x"] = 6, ["meta"] = {["fields"] = {}, ["inventory"] = {}}, ["y"] = 4, ["z"] = 12, ["name"] = "default:steelblock"}, {["x"] = 6, ["meta"] = {["fields"] = {}, ["inventory"] = {}}, ["y"] = 4, ["z"] = 13, ["name"] = "default:steelblock"}, {["x"] = 6, ["meta"] = {["fields"] = {}, ["inventory"] = {}}, ["y"] = 4, ["z"] = 14, ["name"] = "default:steelblock"}, {["x"] = 6, ["meta"] = {["fields"] = {}, ["inventory"] = {}}, ["y"] = 5, ["z"] = 6, ["name"] = "default:steelblock"}, {["x"] = 6, ["meta"] = {["fields"] = {}, ["inventory"] = {}}, ["y"] = 5, ["z"] = 7, ["name"] = "default:steelblock"}, {["x"] = 6, ["meta"] = {["fields"] = {}, ["inventory"] = {}}, ["y"] = 5, ["z"] = 8, ["name"] = "default:steelblock"}, {["x"] = 6, ["meta"] = {["fields"] = {}, ["inventory"] = {}}, ["y"] = 5, ["z"] = 9, ["name"] = "default:steelblock"}, {["x"] = 6, ["meta"] = {["fields"] = {}, ["inventory"] = {}}, ["y"] = 5, ["z"] = 10, ["name"] = "default:steelblock"}, {["x"] = 6, ["meta"] = {["fields"] = {}, ["inventory"] = {}}, ["y"] = 5, ["z"] = 11, ["name"] = "default:steelblock"}, {["x"] = 6, ["meta"] = {["fields"] = {}, ["inventory"] = {}}, ["y"] = 5, ["z"] = 12, ["name"] = "default:steelblock"}, {["x"] = 6, ["meta"] = {["fields"] = {}, ["inventory"] = {}}, ["y"] = 5, ["z"] = 13, ["name"] = "default:steelblock"}, {["x"] = 6, ["meta"] = {["fields"] = {}, ["inventory"] = {}}, ["y"] = 5, ["z"] = 14, ["name"] = "default:steelblock"}, {["x"] = 6, ["meta"] = {["fields"] = {}, ["inventory"] = {}}, ["y"] = 6, ["z"] = 6, ["name"] = "default:steelblock"}, {["x"] = 6, ["meta"] = {["fields"] = {}, ["inventory"] = {}}, ["y"] = 6, ["z"] = 7, ["name"] = "default:steelblock"}, {["x"] = 6, ["meta"] = {["fields"] = {}, ["inventory"] = {}}, ["y"] = 6, ["param1"] = 190, ["z"] = 8, ["name"] = "default:obsidian_glass"}, {["x"] = 6, ["meta"] = {["fields"] = {}, ["inventory"] = {}}, ["y"] = 6, ["param1"] = 190, ["z"] = 9, ["name"] = "default:obsidian_glass"}, {["x"] = 6, ["meta"] = {["fields"] = {}, ["inventory"] = {}}, ["y"] = 6, ["param1"] = 190, ["z"] = 10, ["name"] = "default:obsidian_glass"}, {["x"] = 6, ["meta"] = {["fields"] = {}, ["inventory"] = {}}, ["y"] = 6, ["param1"] = 190, ["z"] = 11, ["name"] = "default:obsidian_glass"}, {["x"] = 6, ["meta"] = {["fields"] = {}, ["inventory"] = {}}, ["y"] = 6, ["param1"] = 190, ["z"] = 12, ["name"] = "default:obsidian_glass"}, {["x"] = 6, ["meta"] = {["fields"] = {}, ["inventory"] = {}}, ["y"] = 6, ["z"] = 13, ["name"] = "default:steelblock"}, {["x"] = 6, ["meta"] = {["fields"] = {}, ["inventory"] = {}}, ["y"] = 6, ["z"] = 14, ["name"] = "default:steelblock"}, {["x"] = 6, ["meta"] = {["fields"] = {}, ["inventory"] = {}}, ["y"] = 7, ["z"] = 6, ["name"] = "default:steelblock"}, {["x"] = 6, ["meta"] = {["fields"] = {}, ["inventory"] = {}}, ["y"] = 7, ["z"] = 7, ["name"] = "default:steelblock"}, {["x"] = 6, ["meta"] = {["fields"] = {}, ["inventory"] = {}}, ["y"] = 7, ["param1"] = 190, ["z"] = 8, ["name"] = "default:obsidian_glass"}, {["x"] = 6, ["meta"] = {["fields"] = {}, ["inventory"] = {}}, ["y"] = 7, ["param1"] = 190, ["z"] = 9, ["name"] = "default:obsidian_glass"}, {["x"] = 6, ["meta"] = {["fields"] = {}, ["inventory"] = {}}, ["y"] = 7, ["param1"] = 206, ["z"] = 10, ["name"] = "default:obsidian_glass"}, {["x"] = 6, ["meta"] = {["fields"] = {}, ["inventory"] = {}}, ["y"] = 7, ["param1"] = 190, ["z"] = 11, ["name"] = "default:obsidian_glass"}, {["x"] = 6, ["meta"] = {["fields"] = {}, ["inventory"] = {}}, ["y"] = 7, ["param1"] = 190, ["z"] = 12, ["name"] = "default:obsidian_glass"}, {["x"] = 6, ["meta"] = {["fields"] = {}, ["inventory"] = {}}, ["y"] = 7, ["z"] = 13, ["name"] = "default:steelblock"}, {["x"] = 6, ["meta"] = {["fields"] = {}, ["inventory"] = {}}, ["y"] = 7, ["z"] = 14, ["name"] = "default:steelblock"}, {["x"] = 6, ["meta"] = {["fields"] = {}, ["inventory"] = {}}, ["y"] = 8, ["z"] = 6, ["name"] = "default:steelblock"}, {["x"] = 6, ["meta"] = {["fields"] = {}, ["inventory"] = {}}, ["y"] = 8, ["z"] = 7, ["name"] = "default:steelblock"}, {["x"] = 6, ["meta"] = {["fields"] = {}, ["inventory"] = {}}, ["y"] = 8, ["z"] = 8, ["name"] = "default:steelblock"}, {["x"] = 6, ["meta"] = {["fields"] = {}, ["inventory"] = {}}, ["y"] = 8, ["z"] = 9, ["name"] = "default:steelblock"}, {["x"] = 6, ["meta"] = {["fields"] = {}, ["inventory"] = {}}, ["y"] = 8, ["z"] = 10, ["name"] = "default:steelblock"}, {["x"] = 6, ["meta"] = {["fields"] = {}, ["inventory"] = {}}, ["y"] = 8, ["z"] = 11, ["name"] = "default:steelblock"}, {["x"] = 6, ["meta"] = {["fields"] = {}, ["inventory"] = {}}, ["y"] = 8, ["z"] = 12, ["name"] = "default:steelblock"}, {["x"] = 6, ["meta"] = {["fields"] = {}, ["inventory"] = {}}, ["y"] = 8, ["z"] = 13, ["name"] = "default:steelblock"}, {["x"] = 6, ["meta"] = {["fields"] = {}, ["inventory"] = {}}, ["y"] = 8, ["z"] = 14, ["name"] = "default:steelblock"}, {["x"] = 6, ["meta"] = {["fields"] = {}, ["inventory"] = {}}, ["y"] = 9, ["z"] = 3, ["name"] = "default:steelblock"}, {["x"] = 6, ["meta"] = {["fields"] = {}, ["inventory"] = {}}, ["y"] = 9, ["z"] = 4, ["name"] = "default:steelblock"}, {["x"] = 6, ["meta"] = {["fields"] = {}, ["inventory"] = {}}, ["y"] = 9, ["z"] = 5, ["name"] = "default:steelblock"}, {["x"] = 6, ["meta"] = {["fields"] = {}, ["inventory"] = {}}, ["y"] = 9, ["z"] = 6, ["name"] = "default:steelblock"}, {["x"] = 6, ["meta"] = {["fields"] = {}, ["inventory"] = {}}, ["y"] = 9, ["z"] = 7, ["name"] = "default:steelblock"}, {["x"] = 6, ["meta"] = {["fields"] = {}, ["inventory"] = {}}, ["y"] = 9, ["z"] = 8, ["name"] = "default:steelblock"}, {["x"] = 6, ["meta"] = {["fields"] = {}, ["inventory"] = {}}, ["y"] = 9, ["z"] = 9, ["name"] = "default:steelblock"}, {["x"] = 6, ["meta"] = {["fields"] = {}, ["inventory"] = {}}, ["y"] = 9, ["z"] = 10, ["name"] = "default:steelblock"}, {["x"] = 6, ["meta"] = {["fields"] = {}, ["inventory"] = {}}, ["y"] = 9, ["z"] = 11, ["name"] = "default:steelblock"}, {["x"] = 6, ["meta"] = {["fields"] = {}, ["inventory"] = {}}, ["y"] = 9, ["z"] = 12, ["name"] = "default:steelblock"}, {["x"] = 6, ["meta"] = {["fields"] = {}, ["inventory"] = {}}, ["y"] = 9, ["z"] = 13, ["name"] = "default:steelblock"}, {["x"] = 6, ["meta"] = {["fields"] = {}, ["inventory"] = {}}, ["y"] = 9, ["z"] = 14, ["name"] = "default:steelblock"}, {["x"] = 6, ["meta"] = {["fields"] = {}, ["inventory"] = {}}, ["y"] = 9, ["z"] = 15, ["name"] = "default:steelblock"}, {["x"] = 6, ["meta"] = {["fields"] = {}, ["inventory"] = {}}, ["y"] = 9, ["z"] = 16, ["name"] = "default:steelblock"}, {["x"] = 6, ["meta"] = {["fields"] = {}, ["inventory"] = {}}, ["y"] = 9, ["z"] = 17, ["name"] = "default:steelblock"}, {["x"] = 6, ["meta"] = {["fields"] = {}, ["inventory"] = {}}, ["y"] = 10, ["param1"] = 191, ["z"] = 3, ["name"] = "xpanes:pane_flat"}, {["x"] = 6, ["meta"] = {["fields"] = {}, ["inventory"] = {}}, ["y"] = 10, ["z"] = 6, ["name"] = "default:steelblock"}, {["x"] = 6, ["meta"] = {["fields"] = {}, ["inventory"] = {}}, ["y"] = 10, ["param1"] = 206, ["z"] = 7, ["name"] = "default:obsidian_glass"}, {["x"] = 6, ["meta"] = {["fields"] = {}, ["inventory"] = {}}, ["y"] = 10, ["param1"] = 206, ["z"] = 8, ["name"] = "default:obsidian_glass"}, {["x"] = 6, ["meta"] = {["fields"] = {}, ["inventory"] = {}}, ["y"] = 10, ["param1"] = 206, ["z"] = 9, ["name"] = "default:obsidian_glass"}, {["x"] = 6, ["meta"] = {["fields"] = {}, ["inventory"] = {}}, ["y"] = 10, ["param1"] = 206, ["z"] = 10, ["name"] = "default:obsidian_glass"}, {["x"] = 6, ["meta"] = {["fields"] = {}, ["inventory"] = {}}, ["y"] = 10, ["param1"] = 206, ["z"] = 11, ["name"] = "default:obsidian_glass"}, {["x"] = 6, ["meta"] = {["fields"] = {}, ["inventory"] = {}}, ["y"] = 10, ["param1"] = 206, ["z"] = 12, ["name"] = "default:obsidian_glass"}, {["x"] = 6, ["meta"] = {["fields"] = {}, ["inventory"] = {}}, ["y"] = 10, ["param1"] = 206, ["z"] = 13, ["name"] = "default:obsidian_glass"}, {["x"] = 6, ["meta"] = {["fields"] = {}, ["inventory"] = {}}, ["y"] = 10, ["z"] = 14, ["name"] = "default:steelblock"}, {["x"] = 6, ["meta"] = {["fields"] = {}, ["inventory"] = {}}, ["y"] = 10, ["param1"] = 191, ["z"] = 17, ["name"] = "xpanes:pane_flat"}, {["x"] = 6, ["meta"] = {["fields"] = {}, ["inventory"] = {}}, ["y"] = 11, ["z"] = 6, ["name"] = "default:steelblock"}, {["x"] = 6, ["meta"] = {["fields"] = {}, ["inventory"] = {}}, ["y"] = 11, ["param1"] = 190, ["z"] = 7, ["name"] = "default:obsidian_glass"}, {["x"] = 6, ["meta"] = {["fields"] = {}, ["inventory"] = {}}, ["y"] = 11, ["param1"] = 190, ["z"] = 8, ["name"] = "default:obsidian_glass"}, {["x"] = 6, ["meta"] = {["fields"] = {}, ["inventory"] = {}}, ["y"] = 11, ["param1"] = 190, ["z"] = 9, ["name"] = "default:obsidian_glass"}, {["x"] = 6, ["meta"] = {["fields"] = {}, ["inventory"] = {}}, ["y"] = 11, ["param1"] = 190, ["z"] = 10, ["name"] = "default:obsidian_glass"}, {["x"] = 6, ["meta"] = {["fields"] = {}, ["inventory"] = {}}, ["y"] = 11, ["param1"] = 190, ["z"] = 11, ["name"] = "default:obsidian_glass"}, {["x"] = 6, ["meta"] = {["fields"] = {}, ["inventory"] = {}}, ["y"] = 11, ["param1"] = 190, ["z"] = 12, ["name"] = "default:obsidian_glass"}, {["x"] = 6, ["meta"] = {["fields"] = {}, ["inventory"] = {}}, ["y"] = 11, ["param1"] = 190, ["z"] = 13, ["name"] = "default:obsidian_glass"}, {["x"] = 6, ["meta"] = {["fields"] = {}, ["inventory"] = {}}, ["y"] = 11, ["z"] = 14, ["name"] = "default:steelblock"}, {["x"] = 6, ["meta"] = {["fields"] = {}, ["inventory"] = {}}, ["y"] = 12, ["z"] = 6, ["name"] = "default:steelblock"}, {["x"] = 6, ["meta"] = {["fields"] = {}, ["inventory"] = {}}, ["y"] = 12, ["param1"] = 190, ["z"] = 7, ["name"] = "default:obsidian_glass"}, {["x"] = 6, ["meta"] = {["fields"] = {}, ["inventory"] = {}}, ["y"] = 12, ["param1"] = 190, ["z"] = 8, ["name"] = "default:obsidian_glass"}, {["x"] = 6, ["meta"] = {["fields"] = {}, ["inventory"] = {}}, ["y"] = 12, ["param1"] = 190, ["z"] = 9, ["name"] = "default:obsidian_glass"}, {["x"] = 6, ["meta"] = {["fields"] = {}, ["inventory"] = {}}, ["y"] = 12, ["param1"] = 190, ["z"] = 10, ["name"] = "default:obsidian_glass"}, {["x"] = 6, ["meta"] = {["fields"] = {}, ["inventory"] = {}}, ["y"] = 12, ["param1"] = 190, ["z"] = 11, ["name"] = "default:obsidian_glass"}, {["x"] = 6, ["meta"] = {["fields"] = {}, ["inventory"] = {}}, ["y"] = 12, ["param1"] = 190, ["z"] = 12, ["name"] = "default:obsidian_glass"}, {["x"] = 6, ["meta"] = {["fields"] = {}, ["inventory"] = {}}, ["y"] = 12, ["param1"] = 190, ["z"] = 13, ["name"] = "default:obsidian_glass"}, {["x"] = 6, ["meta"] = {["fields"] = {}, ["inventory"] = {}}, ["y"] = 12, ["z"] = 14, ["name"] = "default:steelblock"}, {["x"] = 6, ["meta"] = {["fields"] = {}, ["inventory"] = {}}, ["y"] = 13, ["z"] = 6, ["name"] = "default:steelblock"}, {["x"] = 6, ["meta"] = {["fields"] = {}, ["inventory"] = {}}, ["y"] = 13, ["param1"] = 206, ["z"] = 7, ["name"] = "default:obsidian_glass"}, {["x"] = 6, ["meta"] = {["fields"] = {}, ["inventory"] = {}}, ["y"] = 13, ["param1"] = 206, ["z"] = 8, ["name"] = "default:obsidian_glass"}, {["x"] = 6, ["meta"] = {["fields"] = {}, ["inventory"] = {}}, ["y"] = 13, ["param1"] = 206, ["z"] = 9, ["name"] = "default:obsidian_glass"}, {["x"] = 6, ["meta"] = {["fields"] = {}, ["inventory"] = {}}, ["y"] = 13, ["param1"] = 206, ["z"] = 10, ["name"] = "default:obsidian_glass"}, {["x"] = 6, ["meta"] = {["fields"] = {}, ["inventory"] = {}}, ["y"] = 13, ["param1"] = 206, ["z"] = 11, ["name"] = "default:obsidian_glass"}, {["x"] = 6, ["meta"] = {["fields"] = {}, ["inventory"] = {}}, ["y"] = 13, ["param1"] = 206, ["z"] = 12, ["name"] = "default:obsidian_glass"}, {["x"] = 6, ["meta"] = {["fields"] = {}, ["inventory"] = {}}, ["y"] = 13, ["param1"] = 206, ["z"] = 13, ["name"] = "default:obsidian_glass"}, {["x"] = 6, ["meta"] = {["fields"] = {}, ["inventory"] = {}}, ["y"] = 13, ["z"] = 14, ["name"] = "default:steelblock"}, {["x"] = 6, ["meta"] = {["fields"] = {}, ["inventory"] = {}}, ["y"] = 14, ["z"] = 6, ["name"] = "default:steelblock"}, {["x"] = 6, ["meta"] = {["fields"] = {}, ["inventory"] = {}}, ["y"] = 14, ["z"] = 7, ["name"] = "default:steelblock"}, {["x"] = 6, ["meta"] = {["fields"] = {}, ["inventory"] = {}}, ["y"] = 14, ["z"] = 8, ["name"] = "default:steelblock"}, {["x"] = 6, ["meta"] = {["fields"] = {}, ["inventory"] = {}}, ["y"] = 14, ["z"] = 9, ["name"] = "default:steelblock"}, {["x"] = 6, ["meta"] = {["fields"] = {}, ["inventory"] = {}}, ["y"] = 14, ["z"] = 10, ["name"] = "default:steelblock"}, {["x"] = 6, ["meta"] = {["fields"] = {}, ["inventory"] = {}}, ["y"] = 14, ["z"] = 11, ["name"] = "default:steelblock"}, {["x"] = 6, ["meta"] = {["fields"] = {}, ["inventory"] = {}}, ["y"] = 14, ["z"] = 12, ["name"] = "default:steelblock"}, {["x"] = 6, ["meta"] = {["fields"] = {}, ["inventory"] = {}}, ["y"] = 14, ["z"] = 13, ["name"] = "default:steelblock"}, {["x"] = 6, ["meta"] = {["fields"] = {}, ["inventory"] = {}}, ["y"] = 14, ["z"] = 14, ["name"] = "default:steelblock"}, {["x"] = 7, ["meta"] = {["fields"] = {}, ["inventory"] = {}}, ["param2"] = 2, ["y"] = 0, ["param1"] = 206, ["z"] = 1, ["name"] = "homedecor:fence_picket_white"}, {["x"] = 7, ["meta"] = {["fields"] = {}, ["inventory"] = {}}, ["y"] = 0, ["z"] = 6, ["name"] = "default:steelblock"}, {["x"] = 7, ["meta"] = {["fields"] = {["formspec"] = "size[8,7;]bgcolor[#080808BB;true]background[5,5;1,1;gui_formbg.png;true]listcolors[#00000069;#5A5A5A;#141318;#30434C;#FFF]list[context;books;0,0.3;8,2;]list[current_player;main;0,2.85;8,1;]list[current_player;main;0,4.08;8,3;8]listring[context;books]listring[current_player;main]image[0,2.85;1,1;gui_hb_bg.png]image[1,2.85;1,1;gui_hb_bg.png]image[2,2.85;1,1;gui_hb_bg.png]image[3,2.85;1,1;gui_hb_bg.png]image[4,2.85;1,1;gui_hb_bg.png]image[5,2.85;1,1;gui_hb_bg.png]image[6,2.85;1,1;gui_hb_bg.png]image[7,2.85;1,1;gui_hb_bg.png]image[0,0.3;1,1;default_bookshelf_slot.png]image[1,0.3;1,1;default_bookshelf_slot.png]image[2,0.3;1,1;default_bookshelf_slot.png]image[3,0.3;1,1;default_bookshelf_slot.png]image[4,0.3;1,1;default_bookshelf_slot.png]image[5,0.3;1,1;default_bookshelf_slot.png]image[6,0.3;1,1;default_bookshelf_slot.png]image[7,0.3;1,1;default_bookshelf_slot.png]image[0,1.3;1,1;default_bookshelf_slot.png]image[1,1.3;1,1;default_bookshelf_slot.png]image[2,1.3;1,1;default_bookshelf_slot.png]image[3,1.3;1,1;default_bookshelf_slot.png]image[4,1.3;1,1;default_bookshelf_slot.png]image[5,1.3;1,1;default_bookshelf_slot.png]image[6,1.3;1,1;default_bookshelf_slot.png]image[7,1.3;1,1;default_bookshelf_slot.png]"}, ["inventory"] = {["books"] = {"", "", "", "", "", "", "", "", "", "", "", "", "", "", "", ""}}}, ["param2"] = 3, ["y"] = 0, ["param1"] = 174, ["z"] = 7, ["name"] = "default:bookshelf"}, {["x"] = 7, ["meta"] = {["fields"] = {}, ["inventory"] = {}}, ["param2"] = 3, ["y"] = 0, ["param1"] = 191, ["z"] = 8, ["name"] = "ts_furniture:rainbow_wood_white_table"}, {["x"] = 7, ["meta"] = {["fields"] = {}, ["inventory"] = {}}, ["param2"] = 3, ["y"] = 0, ["param1"] = 174, ["z"] = 9, ["name"] = "ts_furniture:rainbow_wood_white_table"}, {["x"] = 7, ["meta"] = {["fields"] = {}, ["inventory"] = {}}, ["param2"] = 3, ["y"] = 0, ["param1"] = 175, ["z"] = 10, ["name"] = "ts_furniture:rainbow_wood_white_table"}, {["x"] = 7, ["meta"] = {["fields"] = {}, ["inventory"] = {}}, ["param2"] = 3, ["y"] = 0, ["param1"] = 174, ["z"] = 11, ["name"] = "ts_furniture:rainbow_wood_white_table"}, {["x"] = 7, ["meta"] = {["fields"] = {}, ["inventory"] = {}}, ["param2"] = 3, ["y"] = 0, ["param1"] = 190, ["z"] = 12, ["name"] = "ts_furniture:rainbow_wood_white_table"}, {["x"] = 7, ["meta"] = {["fields"] = {["formspec"] = "size[8,7;]bgcolor[#080808BB;true]background[5,5;1,1;gui_formbg.png;true]listcolors[#00000069;#5A5A5A;#141318;#30434C;#FFF]list[context;books;0,0.3;8,2;]list[current_player;main;0,2.85;8,1;]list[current_player;main;0,4.08;8,3;8]listring[context;books]listring[current_player;main]image[0,2.85;1,1;gui_hb_bg.png]image[1,2.85;1,1;gui_hb_bg.png]image[2,2.85;1,1;gui_hb_bg.png]image[3,2.85;1,1;gui_hb_bg.png]image[4,2.85;1,1;gui_hb_bg.png]image[5,2.85;1,1;gui_hb_bg.png]image[6,2.85;1,1;gui_hb_bg.png]image[7,2.85;1,1;gui_hb_bg.png]image[0,0.3;1,1;default_bookshelf_slot.png]image[1,0.3;1,1;default_bookshelf_slot.png]image[2,0.3;1,1;default_bookshelf_slot.png]image[3,0.3;1,1;default_bookshelf_slot.png]image[4,0.3;1,1;default_bookshelf_slot.png]image[5,0.3;1,1;default_bookshelf_slot.png]image[6,0.3;1,1;default_bookshelf_slot.png]image[7,0.3;1,1;default_bookshelf_slot.png]image[0,1.3;1,1;default_bookshelf_slot.png]image[1,1.3;1,1;default_bookshelf_slot.png]image[2,1.3;1,1;default_bookshelf_slot.png]image[3,1.3;1,1;default_bookshelf_slot.png]image[4,1.3;1,1;default_bookshelf_slot.png]image[5,1.3;1,1;default_bookshelf_slot.png]image[6,1.3;1,1;default_bookshelf_slot.png]image[7,1.3;1,1;default_bookshelf_slot.png]"}, ["inventory"] = {["books"] = {"", "", "", "", "", "", "", "", "", "", "", "", "", "", "", ""}}}, ["param2"] = 3, ["y"] = 0, ["param1"] = 173, ["z"] = 13, ["name"] = "default:bookshelf"}, {["x"] = 7, ["meta"] = {["fields"] = {}, ["inventory"] = {}}, ["y"] = 0, ["z"] = 14, ["name"] = "default:steelblock"}, {["x"] = 7, ["meta"] = {["fields"] = {}, ["inventory"] = {}}, ["y"] = 0, ["param1"] = 142, ["z"] = 19, ["name"] = "homedecor:fence_picket_white"}, {["x"] = 7, ["meta"] = {["fields"] = {}, ["inventory"] = {}}, ["y"] = 1, ["z"] = 6, ["name"] = "default:steelblock"}, {["x"] = 7, ["meta"] = {["fields"] = {["formspec"] = "size[8,7;]bgcolor[#080808BB;true]background[5,5;1,1;gui_formbg.png;true]listcolors[#00000069;#5A5A5A;#141318;#30434C;#FFF]list[context;books;0,0.3;8,2;]list[current_player;main;0,2.85;8,1;]list[current_player;main;0,4.08;8,3;8]listring[context;books]listring[current_player;main]image[0,2.85;1,1;gui_hb_bg.png]image[1,2.85;1,1;gui_hb_bg.png]image[2,2.85;1,1;gui_hb_bg.png]image[3,2.85;1,1;gui_hb_bg.png]image[4,2.85;1,1;gui_hb_bg.png]image[5,2.85;1,1;gui_hb_bg.png]image[6,2.85;1,1;gui_hb_bg.png]image[7,2.85;1,1;gui_hb_bg.png]image[0,0.3;1,1;default_bookshelf_slot.png]image[1,0.3;1,1;default_bookshelf_slot.png]image[2,0.3;1,1;default_bookshelf_slot.png]image[3,0.3;1,1;default_bookshelf_slot.png]image[4,0.3;1,1;default_bookshelf_slot.png]image[5,0.3;1,1;default_bookshelf_slot.png]image[6,0.3;1,1;default_bookshelf_slot.png]image[7,0.3;1,1;default_bookshelf_slot.png]image[0,1.3;1,1;default_bookshelf_slot.png]image[1,1.3;1,1;default_bookshelf_slot.png]image[2,1.3;1,1;default_bookshelf_slot.png]image[3,1.3;1,1;default_bookshelf_slot.png]image[4,1.3;1,1;default_bookshelf_slot.png]image[5,1.3;1,1;default_bookshelf_slot.png]image[6,1.3;1,1;default_bookshelf_slot.png]image[7,1.3;1,1;default_bookshelf_slot.png]"}, ["inventory"] = {["books"] = {"", "", "", "", "", "", "", "", "", "", "", "", "", "", "", ""}}}, ["param2"] = 3, ["y"] = 1, ["param1"] = 190, ["z"] = 7, ["name"] = "default:bookshelf"}, {["x"] = 7, ["meta"] = {["fields"] = {}, ["inventory"] = {}}, ["param2"] = 3, ["y"] = 1, ["param1"] = 190, ["z"] = 11, ["name"] = "computer:vanio"}, {["x"] = 7, ["meta"] = {["fields"] = {}, ["inventory"] = {}}, ["param2"] = 3, ["y"] = 1, ["param1"] = 206, ["z"] = 12, ["name"] = "computer:tower"}, {["x"] = 7, ["meta"] = {["fields"] = {["formspec"] = "size[8,7;]bgcolor[#080808BB;true]background[5,5;1,1;gui_formbg.png;true]listcolors[#00000069;#5A5A5A;#141318;#30434C;#FFF]list[context;books;0,0.3;8,2;]list[current_player;main;0,2.85;8,1;]list[current_player;main;0,4.08;8,3;8]listring[context;books]listring[current_player;main]image[0,2.85;1,1;gui_hb_bg.png]image[1,2.85;1,1;gui_hb_bg.png]image[2,2.85;1,1;gui_hb_bg.png]image[3,2.85;1,1;gui_hb_bg.png]image[4,2.85;1,1;gui_hb_bg.png]image[5,2.85;1,1;gui_hb_bg.png]image[6,2.85;1,1;gui_hb_bg.png]image[7,2.85;1,1;gui_hb_bg.png]image[0,0.3;1,1;default_bookshelf_slot.png]image[1,0.3;1,1;default_bookshelf_slot.png]image[2,0.3;1,1;default_bookshelf_slot.png]image[3,0.3;1,1;default_bookshelf_slot.png]image[4,0.3;1,1;default_bookshelf_slot.png]image[5,0.3;1,1;default_bookshelf_slot.png]image[6,0.3;1,1;default_bookshelf_slot.png]image[7,0.3;1,1;default_bookshelf_slot.png]image[0,1.3;1,1;default_bookshelf_slot.png]image[1,1.3;1,1;default_bookshelf_slot.png]image[2,1.3;1,1;default_bookshelf_slot.png]image[3,1.3;1,1;default_bookshelf_slot.png]image[4,1.3;1,1;default_bookshelf_slot.png]image[5,1.3;1,1;default_bookshelf_slot.png]image[6,1.3;1,1;default_bookshelf_slot.png]image[7,1.3;1,1;default_bookshelf_slot.png]"}, ["inventory"] = {["books"] = {"", "", "", "", "", "", "", "", "", "", "", "", "", "", "", ""}}}, ["param2"] = 3, ["y"] = 1, ["param1"] = 189, ["z"] = 13, ["name"] = "default:bookshelf"}, {["x"] = 7, ["meta"] = {["fields"] = {}, ["inventory"] = {}}, ["y"] = 1, ["z"] = 14, ["name"] = "default:steelblock"}, {["x"] = 7, ["meta"] = {["fields"] = {}, ["inventory"] = {}}, ["y"] = 2, ["z"] = 6, ["name"] = "default:steelblock"}, {["x"] = 7, ["meta"] = {["fields"] = {["formspec"] = "size[8,7;]bgcolor[#080808BB;true]background[5,5;1,1;gui_formbg.png;true]listcolors[#00000069;#5A5A5A;#141318;#30434C;#FFF]list[context;books;0,0.3;8,2;]list[current_player;main;0,2.85;8,1;]list[current_player;main;0,4.08;8,3;8]listring[context;books]listring[current_player;main]image[0,2.85;1,1;gui_hb_bg.png]image[1,2.85;1,1;gui_hb_bg.png]image[2,2.85;1,1;gui_hb_bg.png]image[3,2.85;1,1;gui_hb_bg.png]image[4,2.85;1,1;gui_hb_bg.png]image[5,2.85;1,1;gui_hb_bg.png]image[6,2.85;1,1;gui_hb_bg.png]image[7,2.85;1,1;gui_hb_bg.png]image[0,0.3;1,1;default_bookshelf_slot.png]image[1,0.3;1,1;default_bookshelf_slot.png]image[2,0.3;1,1;default_bookshelf_slot.png]image[3,0.3;1,1;default_bookshelf_slot.png]image[4,0.3;1,1;default_bookshelf_slot.png]image[5,0.3;1,1;default_bookshelf_slot.png]image[6,0.3;1,1;default_bookshelf_slot.png]image[7,0.3;1,1;default_bookshelf_slot.png]image[0,1.3;1,1;default_bookshelf_slot.png]image[1,1.3;1,1;default_bookshelf_slot.png]image[2,1.3;1,1;default_bookshelf_slot.png]image[3,1.3;1,1;default_bookshelf_slot.png]image[4,1.3;1,1;default_bookshelf_slot.png]image[5,1.3;1,1;default_bookshelf_slot.png]image[6,1.3;1,1;default_bookshelf_slot.png]image[7,1.3;1,1;default_bookshelf_slot.png]"}, ["inventory"] = {["books"] = {"", "", "", "", "", "", "", "", "", "", "", "", "", "", "", ""}}}, ["param2"] = 3, ["y"] = 2, ["param1"] = 206, ["z"] = 7, ["name"] = "default:bookshelf"}, {["x"] = 7, ["meta"] = {["fields"] = {}, ["inventory"] = {}}, ["param2"] = 3, ["y"] = 2, ["param1"] = 223, ["z"] = 8, ["name"] = "default:torch_wall"}, {["x"] = 7, ["meta"] = {["fields"] = {}, ["inventory"] = {}}, ["param2"] = 3, ["y"] = 2, ["param1"] = 222, ["z"] = 12, ["name"] = "default:torch_wall"}, {["x"] = 7, ["meta"] = {["fields"] = {["formspec"] = "size[8,7;]bgcolor[#080808BB;true]background[5,5;1,1;gui_formbg.png;true]listcolors[#00000069;#5A5A5A;#141318;#30434C;#FFF]list[context;books;0,0.3;8,2;]list[current_player;main;0,2.85;8,1;]list[current_player;main;0,4.08;8,3;8]listring[context;books]listring[current_player;main]image[0,2.85;1,1;gui_hb_bg.png]image[1,2.85;1,1;gui_hb_bg.png]image[2,2.85;1,1;gui_hb_bg.png]image[3,2.85;1,1;gui_hb_bg.png]image[4,2.85;1,1;gui_hb_bg.png]image[5,2.85;1,1;gui_hb_bg.png]image[6,2.85;1,1;gui_hb_bg.png]image[7,2.85;1,1;gui_hb_bg.png]image[0,0.3;1,1;default_bookshelf_slot.png]image[1,0.3;1,1;default_bookshelf_slot.png]image[2,0.3;1,1;default_bookshelf_slot.png]image[3,0.3;1,1;default_bookshelf_slot.png]image[4,0.3;1,1;default_bookshelf_slot.png]image[5,0.3;1,1;default_bookshelf_slot.png]image[6,0.3;1,1;default_bookshelf_slot.png]image[7,0.3;1,1;default_bookshelf_slot.png]image[0,1.3;1,1;default_bookshelf_slot.png]image[1,1.3;1,1;default_bookshelf_slot.png]image[2,1.3;1,1;default_bookshelf_slot.png]image[3,1.3;1,1;default_bookshelf_slot.png]image[4,1.3;1,1;default_bookshelf_slot.png]image[5,1.3;1,1;default_bookshelf_slot.png]image[6,1.3;1,1;default_bookshelf_slot.png]image[7,1.3;1,1;default_bookshelf_slot.png]"}, ["inventory"] = {["books"] = {"", "", "", "", "", "", "", "", "", "", "", "", "", "", "", ""}}}, ["param2"] = 3, ["y"] = 2, ["param1"] = 206, ["z"] = 13, ["name"] = "default:bookshelf"}, {["x"] = 7, ["meta"] = {["fields"] = {}, ["inventory"] = {}}, ["y"] = 2, ["z"] = 14, ["name"] = "default:steelblock"}, {["x"] = 7, ["meta"] = {["fields"] = {}, ["inventory"] = {}}, ["y"] = 3, ["z"] = 6, ["name"] = "default:steelblock"}, {["x"] = 7, ["meta"] = {["fields"] = {}, ["inventory"] = {}}, ["y"] = 3, ["z"] = 14, ["name"] = "default:steelblock"}, {["x"] = 7, ["meta"] = {["fields"] = {}, ["inventory"] = {}}, ["y"] = 4, ["z"] = 6, ["name"] = "default:steelblock"}, {["x"] = 7, ["meta"] = {["fields"] = {}, ["inventory"] = {}}, ["y"] = 4, ["param1"] = 238, ["z"] = 7, ["name"] = "default:meselamp"}, {["x"] = 7, ["meta"] = {["fields"] = {}, ["inventory"] = {}}, ["y"] = 4, ["param1"] = 239, ["z"] = 8, ["name"] = "default:meselamp"}, {["x"] = 7, ["meta"] = {["fields"] = {}, ["inventory"] = {}}, ["y"] = 4, ["param1"] = 238, ["z"] = 9, ["name"] = "default:meselamp"}, {["x"] = 7, ["meta"] = {["fields"] = {}, ["inventory"] = {}}, ["y"] = 4, ["param1"] = 239, ["z"] = 10, ["name"] = "default:meselamp"}, {["x"] = 7, ["meta"] = {["fields"] = {}, ["inventory"] = {}}, ["y"] = 4, ["param1"] = 239, ["z"] = 11, ["name"] = "default:meselamp"}, {["x"] = 7, ["meta"] = {["fields"] = {}, ["inventory"] = {}}, ["y"] = 4, ["param1"] = 238, ["z"] = 12, ["name"] = "default:meselamp"}, {["x"] = 7, ["meta"] = {["fields"] = {}, ["inventory"] = {}}, ["y"] = 4, ["param1"] = 239, ["z"] = 13, ["name"] = "default:meselamp"}, {["x"] = 7, ["meta"] = {["fields"] = {}, ["inventory"] = {}}, ["y"] = 4, ["z"] = 14, ["name"] = "default:steelblock"}, {["x"] = 7, ["meta"] = {["fields"] = {}, ["inventory"] = {}}, ["y"] = 5, ["z"] = 6, ["name"] = "default:steelblock"}, {["x"] = 7, ["meta"] = {["fields"] = {}, ["inventory"] = {}}, ["param2"] = 3, ["y"] = 5, ["param1"] = 222, ["z"] = 7, ["name"] = "homedecor:air_conditioner"}, {["x"] = 7, ["meta"] = {["fields"] = {}, ["inventory"] = {}}, ["param2"] = 3, ["y"] = 5, ["param1"] = 222, ["z"] = 9, ["name"] = "homedecor:sink"}, {["x"] = 7, ["meta"] = {["fields"] = {}, ["inventory"] = {}}, ["param2"] = 3, ["y"] = 5, ["param1"] = 222, ["z"] = 12, ["name"] = "homedecor:bathtub_clawfoot_chrome_taps"}, {["x"] = 7, ["meta"] = {["fields"] = {}, ["inventory"] = {}}, ["y"] = 5, ["z"] = 14, ["name"] = "default:steelblock"}, {["x"] = 7, ["meta"] = {["fields"] = {}, ["inventory"] = {}}, ["y"] = 6, ["z"] = 6, ["name"] = "default:steelblock"}, {["x"] = 7, ["meta"] = {["fields"] = {}, ["inventory"] = {}}, ["y"] = 6, ["z"] = 14, ["name"] = "default:steelblock"}, {["x"] = 7, ["meta"] = {["fields"] = {}, ["inventory"] = {}}, ["y"] = 7, ["z"] = 6, ["name"] = "default:steelblock"}, {["x"] = 7, ["meta"] = {["fields"] = {}, ["inventory"] = {}}, ["y"] = 7, ["z"] = 14, ["name"] = "default:steelblock"}, {["x"] = 7, ["meta"] = {["fields"] = {}, ["inventory"] = {}}, ["y"] = 8, ["z"] = 6, ["name"] = "default:steelblock"}, {["x"] = 7, ["meta"] = {["fields"] = {}, ["inventory"] = {}}, ["y"] = 8, ["z"] = 14, ["name"] = "default:steelblock"}, {["x"] = 7, ["meta"] = {["fields"] = {}, ["inventory"] = {}}, ["y"] = 9, ["z"] = 3, ["name"] = "default:steelblock"}, {["x"] = 7, ["meta"] = {["fields"] = {}, ["inventory"] = {}}, ["y"] = 9, ["z"] = 4, ["name"] = "default:steelblock"}, {["x"] = 7, ["meta"] = {["fields"] = {}, ["inventory"] = {}}, ["y"] = 9, ["z"] = 5, ["name"] = "default:steelblock"}, {["x"] = 7, ["meta"] = {["fields"] = {}, ["inventory"] = {}}, ["y"] = 9, ["z"] = 6, ["name"] = "default:steelblock"}, {["x"] = 7, ["meta"] = {["fields"] = {}, ["inventory"] = {}}, ["y"] = 9, ["param1"] = 239, ["z"] = 7, ["name"] = "default:meselamp"}, {["x"] = 7, ["meta"] = {["fields"] = {}, ["inventory"] = {}}, ["y"] = 9, ["param1"] = 239, ["z"] = 8, ["name"] = "default:meselamp"}, {["x"] = 7, ["meta"] = {["fields"] = {}, ["inventory"] = {}}, ["y"] = 9, ["param1"] = 239, ["z"] = 9, ["name"] = "default:meselamp"}, {["x"] = 7, ["meta"] = {["fields"] = {}, ["inventory"] = {}}, ["y"] = 9, ["param1"] = 239, ["z"] = 10, ["name"] = "default:meselamp"}, {["x"] = 7, ["meta"] = {["fields"] = {}, ["inventory"] = {}}, ["y"] = 9, ["param1"] = 239, ["z"] = 11, ["name"] = "default:meselamp"}, {["x"] = 7, ["meta"] = {["fields"] = {}, ["inventory"] = {}}, ["y"] = 9, ["param1"] = 239, ["z"] = 12, ["name"] = "default:meselamp"}, {["x"] = 7, ["meta"] = {["fields"] = {}, ["inventory"] = {}}, ["y"] = 9, ["param1"] = 239, ["z"] = 13, ["name"] = "default:meselamp"}, {["x"] = 7, ["meta"] = {["fields"] = {}, ["inventory"] = {}}, ["y"] = 9, ["z"] = 14, ["name"] = "default:steelblock"}, {["x"] = 7, ["meta"] = {["fields"] = {}, ["inventory"] = {}}, ["y"] = 9, ["z"] = 15, ["name"] = "default:steelblock"}, {["x"] = 7, ["meta"] = {["fields"] = {}, ["inventory"] = {}}, ["y"] = 9, ["z"] = 16, ["name"] = "default:steelblock"}, {["x"] = 7, ["meta"] = {["fields"] = {}, ["inventory"] = {}}, ["y"] = 9, ["z"] = 17, ["name"] = "default:steelblock"}, {["x"] = 7, ["meta"] = {["fields"] = {}, ["inventory"] = {}}, ["y"] = 10, ["param1"] = 175, ["z"] = 3, ["name"] = "xpanes:pane_flat"}, {["x"] = 7, ["meta"] = {["fields"] = {}, ["inventory"] = {}}, ["y"] = 10, ["param1"] = 206, ["z"] = 6, ["name"] = "default:obsidian_glass"}, {["x"] = 7, ["meta"] = {["fields"] = {}, ["inventory"] = {}}, ["y"] = 10, ["param1"] = 206, ["z"] = 14, ["name"] = "default:obsidian_glass"}, {["x"] = 7, ["meta"] = {["fields"] = {}, ["inventory"] = {}}, ["y"] = 10, ["param1"] = 175, ["z"] = 17, ["name"] = "xpanes:pane_flat"}, {["x"] = 7, ["meta"] = {["fields"] = {}, ["inventory"] = {}}, ["y"] = 11, ["param1"] = 190, ["z"] = 6, ["name"] = "default:obsidian_glass"}, {["x"] = 7, ["meta"] = {["fields"] = {}, ["inventory"] = {}}, ["y"] = 11, ["param1"] = 190, ["z"] = 14, ["name"] = "default:obsidian_glass"}, {["x"] = 7, ["meta"] = {["fields"] = {}, ["inventory"] = {}}, ["y"] = 12, ["param1"] = 190, ["z"] = 6, ["name"] = "default:obsidian_glass"}, {["x"] = 7, ["meta"] = {["fields"] = {}, ["inventory"] = {}}, ["y"] = 12, ["param1"] = 190, ["z"] = 14, ["name"] = "default:obsidian_glass"}, {["x"] = 7, ["meta"] = {["fields"] = {}, ["inventory"] = {}}, ["y"] = 13, ["param1"] = 206, ["z"] = 6, ["name"] = "default:obsidian_glass"}, {["x"] = 7, ["meta"] = {["fields"] = {}, ["inventory"] = {}}, ["y"] = 13, ["param1"] = 206, ["z"] = 14, ["name"] = "default:obsidian_glass"}, {["x"] = 7, ["meta"] = {["fields"] = {}, ["inventory"] = {}}, ["y"] = 14, ["z"] = 6, ["name"] = "default:steelblock"}, {["x"] = 7, ["meta"] = {["fields"] = {}, ["inventory"] = {}}, ["y"] = 14, ["param1"] = 239, ["z"] = 7, ["name"] = "default:meselamp"}, {["x"] = 7, ["meta"] = {["fields"] = {}, ["inventory"] = {}}, ["y"] = 14, ["param1"] = 239, ["z"] = 8, ["name"] = "default:meselamp"}, {["x"] = 7, ["meta"] = {["fields"] = {}, ["inventory"] = {}}, ["y"] = 14, ["param1"] = 239, ["z"] = 9, ["name"] = "default:meselamp"}, {["x"] = 7, ["meta"] = {["fields"] = {}, ["inventory"] = {}}, ["y"] = 14, ["param1"] = 239, ["z"] = 10, ["name"] = "default:meselamp"}, {["x"] = 7, ["meta"] = {["fields"] = {}, ["inventory"] = {}}, ["y"] = 14, ["param1"] = 239, ["z"] = 11, ["name"] = "default:meselamp"}, {["x"] = 7, ["meta"] = {["fields"] = {}, ["inventory"] = {}}, ["y"] = 14, ["param1"] = 239, ["z"] = 12, ["name"] = "default:meselamp"}, {["x"] = 7, ["meta"] = {["fields"] = {}, ["inventory"] = {}}, ["y"] = 14, ["param1"] = 239, ["z"] = 13, ["name"] = "default:meselamp"}, {["x"] = 7, ["meta"] = {["fields"] = {}, ["inventory"] = {}}, ["y"] = 14, ["z"] = 14, ["name"] = "default:steelblock"}, {["x"] = 8, ["meta"] = {["fields"] = {}, ["inventory"] = {}}, ["param2"] = 2, ["y"] = 0, ["param1"] = 206, ["z"] = 1, ["name"] = "homedecor:fence_picket_white"}, {["x"] = 8, ["meta"] = {["fields"] = {}, ["inventory"] = {}}, ["y"] = 0, ["z"] = 6, ["name"] = "default:steelblock"}, {["x"] = 8, ["meta"] = {["fields"] = {}, ["inventory"] = {}}, ["param2"] = 1, ["y"] = 0, ["param1"] = 175, ["z"] = 8, ["name"] = "ts_furniture:rainbow_wood_white_chair"}, {["x"] = 8, ["meta"] = {["fields"] = {}, ["inventory"] = {}}, ["param2"] = 1, ["y"] = 0, ["param1"] = 175, ["z"] = 9, ["name"] = "ts_furniture:rainbow_wood_white_chair"}, {["x"] = 8, ["meta"] = {["fields"] = {}, ["inventory"] = {}}, ["param2"] = 1, ["y"] = 0, ["param1"] = 175, ["z"] = 10, ["name"] = "ts_furniture:rainbow_wood_white_chair"}, {["x"] = 8, ["meta"] = {["fields"] = {}, ["inventory"] = {}}, ["param2"] = 1, ["y"] = 0, ["param1"] = 175, ["z"] = 11, ["name"] = "ts_furniture:rainbow_wood_white_chair"}, {["x"] = 8, ["meta"] = {["fields"] = {}, ["inventory"] = {}}, ["param2"] = 1, ["y"] = 0, ["param1"] = 175, ["z"] = 12, ["name"] = "ts_furniture:rainbow_wood_white_chair"}, {["x"] = 8, ["meta"] = {["fields"] = {}, ["inventory"] = {}}, ["y"] = 0, ["z"] = 14, ["name"] = "default:steelblock"}, {["x"] = 8, ["meta"] = {["fields"] = {}, ["inventory"] = {}}, ["y"] = 0, ["param1"] = 158, ["z"] = 19, ["name"] = "homedecor:fence_picket_white"}, {["x"] = 8, ["meta"] = {["fields"] = {}, ["inventory"] = {}}, ["y"] = 1, ["z"] = 6, ["name"] = "default:steelblock"}, {["x"] = 8, ["meta"] = {["fields"] = {}, ["inventory"] = {}}, ["y"] = 1, ["z"] = 14, ["name"] = "default:steelblock"}, {["x"] = 8, ["meta"] = {["fields"] = {}, ["inventory"] = {}}, ["y"] = 2, ["z"] = 6, ["name"] = "default:steelblock"}, {["x"] = 8, ["meta"] = {["fields"] = {}, ["inventory"] = {}}, ["param2"] = 5, ["y"] = 2, ["param1"] = 223, ["z"] = 7, ["name"] = "default:torch_wall"}, {["x"] = 8, ["meta"] = {["fields"] = {}, ["inventory"] = {}}, ["param2"] = 4, ["y"] = 2, ["param1"] = 222, ["z"] = 13, ["name"] = "default:torch_wall"}, {["x"] = 8, ["meta"] = {["fields"] = {}, ["inventory"] = {}}, ["y"] = 2, ["z"] = 14, ["name"] = "default:steelblock"}, {["x"] = 8, ["meta"] = {["fields"] = {}, ["inventory"] = {}}, ["y"] = 3, ["z"] = 6, ["name"] = "default:steelblock"}, {["x"] = 8, ["meta"] = {["fields"] = {}, ["inventory"] = {}}, ["y"] = 3, ["z"] = 14, ["name"] = "default:steelblock"}, {["x"] = 8, ["meta"] = {["fields"] = {}, ["inventory"] = {}}, ["y"] = 4, ["z"] = 6, ["name"] = "default:steelblock"}, {["x"] = 8, ["meta"] = {["fields"] = {}, ["inventory"] = {}}, ["y"] = 4, ["param1"] = 239, ["z"] = 7, ["name"] = "default:meselamp"}, {["x"] = 8, ["meta"] = {["fields"] = {}, ["inventory"] = {}}, ["y"] = 4, ["param1"] = 239, ["z"] = 8, ["name"] = "default:meselamp"}, {["x"] = 8, ["meta"] = {["fields"] = {}, ["inventory"] = {}}, ["y"] = 4, ["param1"] = 239, ["z"] = 9, ["name"] = "default:meselamp"}, {["x"] = 8, ["meta"] = {["fields"] = {}, ["inventory"] = {}}, ["y"] = 4, ["param1"] = 239, ["z"] = 10, ["name"] = "default:meselamp"}, {["x"] = 8, ["meta"] = {["fields"] = {}, ["inventory"] = {}}, ["y"] = 4, ["param1"] = 239, ["z"] = 11, ["name"] = "default:meselamp"}, {["x"] = 8, ["meta"] = {["fields"] = {}, ["inventory"] = {}}, ["y"] = 4, ["param1"] = 239, ["z"] = 12, ["name"] = "default:meselamp"}, {["x"] = 8, ["meta"] = {["fields"] = {}, ["inventory"] = {}}, ["y"] = 4, ["param1"] = 238, ["z"] = 13, ["name"] = "default:meselamp"}, {["x"] = 8, ["meta"] = {["fields"] = {}, ["inventory"] = {}}, ["y"] = 4, ["z"] = 14, ["name"] = "default:steelblock"}, {["x"] = 8, ["meta"] = {["fields"] = {}, ["inventory"] = {}}, ["y"] = 5, ["z"] = 6, ["name"] = "default:steelblock"}, {["x"] = 8, ["meta"] = {["fields"] = {}, ["inventory"] = {}}, ["y"] = 5, ["param1"] = 222, ["z"] = 13, ["name"] = "homedecor:toilet"}, {["x"] = 8, ["meta"] = {["fields"] = {}, ["inventory"] = {}}, ["y"] = 5, ["z"] = 14, ["name"] = "default:steelblock"}, {["x"] = 8, ["meta"] = {["fields"] = {}, ["inventory"] = {}}, ["y"] = 6, ["param1"] = 190, ["z"] = 6, ["name"] = "default:obsidian_glass"}, {["x"] = 8, ["meta"] = {["fields"] = {}, ["inventory"] = {}}, ["y"] = 6, ["param1"] = 190, ["z"] = 14, ["name"] = "default:obsidian_glass"}, {["x"] = 8, ["meta"] = {["fields"] = {}, ["inventory"] = {}}, ["y"] = 7, ["param1"] = 190, ["z"] = 6, ["name"] = "default:obsidian_glass"}, {["x"] = 8, ["meta"] = {["fields"] = {}, ["inventory"] = {}}, ["y"] = 7, ["param1"] = 190, ["z"] = 14, ["name"] = "default:obsidian_glass"}, {["x"] = 8, ["meta"] = {["fields"] = {}, ["inventory"] = {}}, ["y"] = 8, ["z"] = 6, ["name"] = "default:steelblock"}, {["x"] = 8, ["meta"] = {["fields"] = {}, ["inventory"] = {}}, ["y"] = 8, ["z"] = 14, ["name"] = "default:steelblock"}, {["x"] = 8, ["meta"] = {["fields"] = {}, ["inventory"] = {}}, ["y"] = 9, ["z"] = 3, ["name"] = "default:steelblock"}, {["x"] = 8, ["meta"] = {["fields"] = {}, ["inventory"] = {}}, ["y"] = 9, ["z"] = 4, ["name"] = "default:steelblock"}, {["x"] = 8, ["meta"] = {["fields"] = {}, ["inventory"] = {}}, ["y"] = 9, ["z"] = 5, ["name"] = "default:steelblock"}, {["x"] = 8, ["meta"] = {["fields"] = {}, ["inventory"] = {}}, ["y"] = 9, ["z"] = 6, ["name"] = "default:steelblock"}, {["x"] = 8, ["meta"] = {["fields"] = {}, ["inventory"] = {}}, ["y"] = 9, ["param1"] = 239, ["z"] = 7, ["name"] = "default:meselamp"}, {["x"] = 8, ["meta"] = {["fields"] = {}, ["inventory"] = {}}, ["y"] = 9, ["param1"] = 239, ["z"] = 8, ["name"] = "default:meselamp"}, {["x"] = 8, ["meta"] = {["fields"] = {}, ["inventory"] = {}}, ["y"] = 9, ["param1"] = 239, ["z"] = 9, ["name"] = "default:meselamp"}, {["x"] = 8, ["meta"] = {["fields"] = {}, ["inventory"] = {}}, ["y"] = 9, ["param1"] = 239, ["z"] = 10, ["name"] = "default:meselamp"}, {["x"] = 8, ["meta"] = {["fields"] = {}, ["inventory"] = {}}, ["y"] = 9, ["param1"] = 239, ["z"] = 11, ["name"] = "default:meselamp"}, {["x"] = 8, ["meta"] = {["fields"] = {}, ["inventory"] = {}}, ["y"] = 9, ["param1"] = 239, ["z"] = 12, ["name"] = "default:meselamp"}, {["x"] = 8, ["meta"] = {["fields"] = {}, ["inventory"] = {}}, ["y"] = 9, ["param1"] = 239, ["z"] = 13, ["name"] = "default:meselamp"}, {["x"] = 8, ["meta"] = {["fields"] = {}, ["inventory"] = {}}, ["y"] = 9, ["z"] = 14, ["name"] = "default:steelblock"}, {["x"] = 8, ["meta"] = {["fields"] = {}, ["inventory"] = {}}, ["y"] = 9, ["z"] = 15, ["name"] = "default:steelblock"}, {["x"] = 8, ["meta"] = {["fields"] = {}, ["inventory"] = {}}, ["y"] = 9, ["z"] = 16, ["name"] = "default:steelblock"}, {["x"] = 8, ["meta"] = {["fields"] = {}, ["inventory"] = {}}, ["y"] = 9, ["z"] = 17, ["name"] = "default:steelblock"}, {["x"] = 8, ["meta"] = {["fields"] = {}, ["inventory"] = {}}, ["y"] = 10, ["param1"] = 159, ["z"] = 3, ["name"] = "xpanes:pane_flat"}, {["x"] = 8, ["meta"] = {["fields"] = {}, ["inventory"] = {}}, ["y"] = 10, ["param1"] = 206, ["z"] = 6, ["name"] = "default:obsidian_glass"}, {["x"] = 8, ["meta"] = {["fields"] = {}, ["inventory"] = {}}, ["y"] = 10, ["param1"] = 206, ["z"] = 14, ["name"] = "default:obsidian_glass"}, {["x"] = 8, ["meta"] = {["fields"] = {}, ["inventory"] = {}}, ["y"] = 10, ["param1"] = 159, ["z"] = 17, ["name"] = "xpanes:pane_flat"}, {["x"] = 8, ["meta"] = {["fields"] = {}, ["inventory"] = {}}, ["y"] = 11, ["param1"] = 190, ["z"] = 6, ["name"] = "default:obsidian_glass"}, {["x"] = 8, ["meta"] = {["fields"] = {}, ["inventory"] = {}}, ["y"] = 11, ["param1"] = 190, ["z"] = 14, ["name"] = "default:obsidian_glass"}, {["x"] = 8, ["meta"] = {["fields"] = {}, ["inventory"] = {}}, ["y"] = 12, ["param1"] = 190, ["z"] = 6, ["name"] = "default:obsidian_glass"}, {["x"] = 8, ["meta"] = {["fields"] = {}, ["inventory"] = {}}, ["y"] = 12, ["param1"] = 190, ["z"] = 14, ["name"] = "default:obsidian_glass"}, {["x"] = 8, ["meta"] = {["fields"] = {}, ["inventory"] = {}}, ["y"] = 13, ["param1"] = 206, ["z"] = 6, ["name"] = "default:obsidian_glass"}, {["x"] = 8, ["meta"] = {["fields"] = {}, ["inventory"] = {}}, ["y"] = 13, ["param1"] = 206, ["z"] = 14, ["name"] = "default:obsidian_glass"}, {["x"] = 8, ["meta"] = {["fields"] = {}, ["inventory"] = {}}, ["y"] = 14, ["z"] = 6, ["name"] = "default:steelblock"}, {["x"] = 8, ["meta"] = {["fields"] = {}, ["inventory"] = {}}, ["y"] = 14, ["param1"] = 239, ["z"] = 7, ["name"] = "default:meselamp"}, {["x"] = 8, ["meta"] = {["fields"] = {}, ["inventory"] = {}}, ["y"] = 14, ["param1"] = 239, ["z"] = 8, ["name"] = "default:meselamp"}, {["x"] = 8, ["meta"] = {["fields"] = {}, ["inventory"] = {}}, ["y"] = 14, ["param1"] = 239, ["z"] = 9, ["name"] = "default:meselamp"}, {["x"] = 8, ["meta"] = {["fields"] = {}, ["inventory"] = {}}, ["y"] = 14, ["param1"] = 239, ["z"] = 10, ["name"] = "default:meselamp"}, {["x"] = 8, ["meta"] = {["fields"] = {}, ["inventory"] = {}}, ["y"] = 14, ["param1"] = 239, ["z"] = 11, ["name"] = "default:meselamp"}, {["x"] = 8, ["meta"] = {["fields"] = {}, ["inventory"] = {}}, ["y"] = 14, ["param1"] = 239, ["z"] = 12, ["name"] = "default:meselamp"}, {["x"] = 8, ["meta"] = {["fields"] = {}, ["inventory"] = {}}, ["y"] = 14, ["param1"] = 239, ["z"] = 13, ["name"] = "default:meselamp"}, {["x"] = 8, ["meta"] = {["fields"] = {}, ["inventory"] = {}}, ["y"] = 14, ["z"] = 14, ["name"] = "default:steelblock"}, {["x"] = 9, ["meta"] = {["fields"] = {}, ["inventory"] = {}}, ["param2"] = 2, ["y"] = 0, ["param1"] = 206, ["z"] = 1, ["name"] = "homedecor:fence_picket_white"}, {["x"] = 9, ["meta"] = {["fields"] = {}, ["inventory"] = {}}, ["y"] = 0, ["z"] = 6, ["name"] = "default:steelblock"}, {["x"] = 9, ["meta"] = {["fields"] = {["infotext"] = "Ender Chest", ["formspec"] = " size[8,9]\
\9\9\9\9list[current_player;enderchest;0,0;8,4;]\
\9\9\9\9list[current_player;main;0,5;8,4;]\
\9\9\9\9listring[current_player;enderchest]\
\9\9\9\9listring[current_player;main] bgcolor[#080808BB;true]background[5,5;1,1;gui_formbg.png;true]listcolors[#00000069;#5A5A5A;#141318;#30434C;#FFF]image[0,5;1,1;gui_hb_bg.png]image[1,5;1,1;gui_hb_bg.png]image[2,5;1,1;gui_hb_bg.png]image[3,5;1,1;gui_hb_bg.png]image[4,5;1,1;gui_hb_bg.png]image[5,5;1,1;gui_hb_bg.png]image[6,5;1,1;gui_hb_bg.png]image[7,5;1,1;gui_hb_bg.png]"}, ["inventory"] = {}}, ["y"] = 0, ["z"] = 13, ["name"] = "xdecor:enderchest"}, {["x"] = 9, ["meta"] = {["fields"] = {}, ["inventory"] = {}}, ["y"] = 0, ["z"] = 14, ["name"] = "default:steelblock"}, {["x"] = 9, ["meta"] = {["fields"] = {}, ["inventory"] = {}}, ["y"] = 0, ["param1"] = 174, ["z"] = 19, ["name"] = "homedecor:fence_picket_white"}, {["x"] = 9, ["meta"] = {["fields"] = {}, ["inventory"] = {}}, ["y"] = 1, ["param1"] = 174, ["z"] = 6, ["name"] = "default:obsidian_glass"}, {["x"] = 9, ["meta"] = {["fields"] = {}, ["inventory"] = {}}, ["y"] = 1, ["param1"] = 173, ["z"] = 14, ["name"] = "default:obsidian_glass"}, {["x"] = 9, ["meta"] = {["fields"] = {}, ["inventory"] = {}}, ["y"] = 2, ["param1"] = 190, ["z"] = 6, ["name"] = "default:obsidian_glass"}, {["x"] = 9, ["meta"] = {["fields"] = {}, ["inventory"] = {}}, ["y"] = 2, ["param1"] = 189, ["z"] = 14, ["name"] = "default:obsidian_glass"}, {["x"] = 9, ["meta"] = {["fields"] = {}, ["inventory"] = {}}, ["y"] = 3, ["z"] = 6, ["name"] = "default:steelblock"}, {["x"] = 9, ["meta"] = {["fields"] = {}, ["inventory"] = {}}, ["y"] = 3, ["z"] = 14, ["name"] = "default:steelblock"}, {["x"] = 9, ["meta"] = {["fields"] = {}, ["inventory"] = {}}, ["y"] = 4, ["z"] = 6, ["name"] = "default:steelblock"}, {["x"] = 9, ["meta"] = {["fields"] = {}, ["inventory"] = {}}, ["y"] = 4, ["param1"] = 239, ["z"] = 7, ["name"] = "default:meselamp"}, {["x"] = 9, ["meta"] = {["fields"] = {}, ["inventory"] = {}}, ["y"] = 4, ["param1"] = 239, ["z"] = 8, ["name"] = "default:meselamp"}, {["x"] = 9, ["meta"] = {["fields"] = {}, ["inventory"] = {}}, ["y"] = 4, ["param1"] = 239, ["z"] = 9, ["name"] = "default:meselamp"}, {["x"] = 9, ["meta"] = {["fields"] = {}, ["inventory"] = {}}, ["y"] = 4, ["param1"] = 239, ["z"] = 10, ["name"] = "default:meselamp"}, {["x"] = 9, ["meta"] = {["fields"] = {}, ["inventory"] = {}}, ["y"] = 4, ["param1"] = 239, ["z"] = 11, ["name"] = "default:meselamp"}, {["x"] = 9, ["meta"] = {["fields"] = {}, ["inventory"] = {}}, ["y"] = 4, ["param1"] = 239, ["z"] = 12, ["name"] = "default:meselamp"}, {["x"] = 9, ["meta"] = {["fields"] = {}, ["inventory"] = {}}, ["y"] = 4, ["param1"] = 238, ["z"] = 13, ["name"] = "default:meselamp"}, {["x"] = 9, ["meta"] = {["fields"] = {}, ["inventory"] = {}}, ["y"] = 4, ["z"] = 14, ["name"] = "default:steelblock"}, {["x"] = 9, ["meta"] = {["fields"] = {}, ["inventory"] = {}}, ["y"] = 5, ["z"] = 6, ["name"] = "default:steelblock"}, {["x"] = 9, ["meta"] = {["fields"] = {}, ["inventory"] = {}}, ["y"] = 5, ["param1"] = 222, ["z"] = 13, ["name"] = "homedecor:toilet_paper"}, {["x"] = 9, ["meta"] = {["fields"] = {}, ["inventory"] = {}}, ["y"] = 5, ["z"] = 14, ["name"] = "default:steelblock"}, {["x"] = 9, ["meta"] = {["fields"] = {}, ["inventory"] = {}}, ["y"] = 6, ["param1"] = 190, ["z"] = 6, ["name"] = "default:obsidian_glass"}, {["x"] = 9, ["meta"] = {["fields"] = {}, ["inventory"] = {}}, ["y"] = 6, ["param1"] = 190, ["z"] = 14, ["name"] = "default:obsidian_glass"}, {["x"] = 9, ["meta"] = {["fields"] = {}, ["inventory"] = {}}, ["y"] = 7, ["param1"] = 190, ["z"] = 6, ["name"] = "default:obsidian_glass"}, {["x"] = 9, ["meta"] = {["fields"] = {}, ["inventory"] = {}}, ["y"] = 7, ["param1"] = 190, ["z"] = 14, ["name"] = "default:obsidian_glass"}, {["x"] = 9, ["meta"] = {["fields"] = {}, ["inventory"] = {}}, ["y"] = 8, ["z"] = 6, ["name"] = "default:steelblock"}, {["x"] = 9, ["meta"] = {["fields"] = {}, ["inventory"] = {}}, ["y"] = 8, ["z"] = 14, ["name"] = "default:steelblock"}, {["x"] = 9, ["meta"] = {["fields"] = {}, ["inventory"] = {}}, ["y"] = 9, ["z"] = 3, ["name"] = "default:steelblock"}, {["x"] = 9, ["meta"] = {["fields"] = {}, ["inventory"] = {}}, ["y"] = 9, ["z"] = 4, ["name"] = "default:steelblock"}, {["x"] = 9, ["meta"] = {["fields"] = {}, ["inventory"] = {}}, ["y"] = 9, ["z"] = 5, ["name"] = "default:steelblock"}, {["x"] = 9, ["meta"] = {["fields"] = {}, ["inventory"] = {}}, ["y"] = 9, ["z"] = 6, ["name"] = "default:steelblock"}, {["x"] = 9, ["meta"] = {["fields"] = {}, ["inventory"] = {}}, ["y"] = 9, ["param1"] = 239, ["z"] = 7, ["name"] = "default:meselamp"}, {["x"] = 9, ["meta"] = {["fields"] = {}, ["inventory"] = {}}, ["y"] = 9, ["param1"] = 239, ["z"] = 8, ["name"] = "default:meselamp"}, {["x"] = 9, ["meta"] = {["fields"] = {}, ["inventory"] = {}}, ["y"] = 9, ["param1"] = 239, ["z"] = 9, ["name"] = "default:meselamp"}, {["x"] = 9, ["meta"] = {["fields"] = {}, ["inventory"] = {}}, ["y"] = 9, ["param1"] = 239, ["z"] = 10, ["name"] = "default:meselamp"}, {["x"] = 9, ["meta"] = {["fields"] = {}, ["inventory"] = {}}, ["y"] = 9, ["param1"] = 239, ["z"] = 11, ["name"] = "default:meselamp"}, {["x"] = 9, ["meta"] = {["fields"] = {}, ["inventory"] = {}}, ["y"] = 9, ["param1"] = 239, ["z"] = 12, ["name"] = "default:meselamp"}, {["x"] = 9, ["meta"] = {["fields"] = {}, ["inventory"] = {}}, ["y"] = 9, ["param1"] = 239, ["z"] = 13, ["name"] = "default:meselamp"}, {["x"] = 9, ["meta"] = {["fields"] = {}, ["inventory"] = {}}, ["y"] = 9, ["z"] = 14, ["name"] = "default:steelblock"}, {["x"] = 9, ["meta"] = {["fields"] = {}, ["inventory"] = {}}, ["y"] = 9, ["z"] = 15, ["name"] = "default:steelblock"}, {["x"] = 9, ["meta"] = {["fields"] = {}, ["inventory"] = {}}, ["y"] = 9, ["z"] = 16, ["name"] = "default:steelblock"}, {["x"] = 9, ["meta"] = {["fields"] = {}, ["inventory"] = {}}, ["y"] = 9, ["z"] = 17, ["name"] = "default:steelblock"}, {["x"] = 9, ["meta"] = {["fields"] = {}, ["inventory"] = {}}, ["y"] = 10, ["param1"] = 159, ["z"] = 3, ["name"] = "xpanes:pane_flat"}, {["x"] = 9, ["meta"] = {["fields"] = {}, ["inventory"] = {}}, ["y"] = 10, ["param1"] = 206, ["z"] = 6, ["name"] = "default:obsidian_glass"}, {["x"] = 9, ["meta"] = {["fields"] = {}, ["inventory"] = {}}, ["y"] = 10, ["param1"] = 206, ["z"] = 14, ["name"] = "default:obsidian_glass"}, {["x"] = 9, ["meta"] = {["fields"] = {}, ["inventory"] = {}}, ["y"] = 10, ["param1"] = 159, ["z"] = 17, ["name"] = "xpanes:pane_flat"}, {["x"] = 9, ["meta"] = {["fields"] = {}, ["inventory"] = {}}, ["y"] = 11, ["param1"] = 190, ["z"] = 6, ["name"] = "default:obsidian_glass"}, {["x"] = 9, ["meta"] = {["fields"] = {}, ["inventory"] = {}}, ["y"] = 11, ["param1"] = 190, ["z"] = 14, ["name"] = "default:obsidian_glass"}, {["x"] = 9, ["meta"] = {["fields"] = {}, ["inventory"] = {}}, ["y"] = 12, ["param1"] = 190, ["z"] = 6, ["name"] = "default:obsidian_glass"}, {["x"] = 9, ["meta"] = {["fields"] = {}, ["inventory"] = {}}, ["y"] = 12, ["param1"] = 190, ["z"] = 14, ["name"] = "default:obsidian_glass"}, {["x"] = 9, ["meta"] = {["fields"] = {}, ["inventory"] = {}}, ["y"] = 13, ["param1"] = 206, ["z"] = 6, ["name"] = "default:obsidian_glass"}, {["x"] = 9, ["meta"] = {["fields"] = {}, ["inventory"] = {}}, ["y"] = 13, ["param1"] = 206, ["z"] = 14, ["name"] = "default:obsidian_glass"}, {["x"] = 9, ["meta"] = {["fields"] = {}, ["inventory"] = {}}, ["y"] = 14, ["z"] = 6, ["name"] = "default:steelblock"}, {["x"] = 9, ["meta"] = {["fields"] = {}, ["inventory"] = {}}, ["y"] = 14, ["param1"] = 239, ["z"] = 7, ["name"] = "default:meselamp"}, {["x"] = 9, ["meta"] = {["fields"] = {}, ["inventory"] = {}}, ["y"] = 14, ["param1"] = 239, ["z"] = 8, ["name"] = "default:meselamp"}, {["x"] = 9, ["meta"] = {["fields"] = {}, ["inventory"] = {}}, ["y"] = 14, ["param1"] = 239, ["z"] = 9, ["name"] = "default:meselamp"}, {["x"] = 9, ["meta"] = {["fields"] = {}, ["inventory"] = {}}, ["y"] = 14, ["param1"] = 239, ["z"] = 10, ["name"] = "default:meselamp"}, {["x"] = 9, ["meta"] = {["fields"] = {}, ["inventory"] = {}}, ["y"] = 14, ["param1"] = 239, ["z"] = 11, ["name"] = "default:meselamp"}, {["x"] = 9, ["meta"] = {["fields"] = {}, ["inventory"] = {}}, ["y"] = 14, ["param1"] = 239, ["z"] = 12, ["name"] = "default:meselamp"}, {["x"] = 9, ["meta"] = {["fields"] = {}, ["inventory"] = {}}, ["y"] = 14, ["param1"] = 239, ["z"] = 13, ["name"] = "default:meselamp"}, {["x"] = 9, ["meta"] = {["fields"] = {}, ["inventory"] = {}}, ["y"] = 14, ["z"] = 14, ["name"] = "default:steelblock"}, {["x"] = 10, ["meta"] = {["fields"] = {}, ["inventory"] = {}}, ["param2"] = 2, ["y"] = 0, ["param1"] = 206, ["z"] = 1, ["name"] = "homedecor:fence_picket_white"}, {["x"] = 10, ["meta"] = {["fields"] = {}, ["inventory"] = {}}, ["y"] = 0, ["z"] = 6, ["name"] = "default:steelblock"}, {["x"] = 10, ["meta"] = {["fields"] = {["infotext"] = "Ender Chest", ["formspec"] = " size[8,9]\
\9\9\9\9list[current_player;enderchest;0,0;8,4;]\
\9\9\9\9list[current_player;main;0,5;8,4;]\
\9\9\9\9listring[current_player;enderchest]\
\9\9\9\9listring[current_player;main] bgcolor[#080808BB;true]background[5,5;1,1;gui_formbg.png;true]listcolors[#00000069;#5A5A5A;#141318;#30434C;#FFF]image[0,5;1,1;gui_hb_bg.png]image[1,5;1,1;gui_hb_bg.png]image[2,5;1,1;gui_hb_bg.png]image[3,5;1,1;gui_hb_bg.png]image[4,5;1,1;gui_hb_bg.png]image[5,5;1,1;gui_hb_bg.png]image[6,5;1,1;gui_hb_bg.png]image[7,5;1,1;gui_hb_bg.png]"}, ["inventory"] = {}}, ["y"] = 0, ["z"] = 13, ["name"] = "xdecor:enderchest"}, {["x"] = 10, ["meta"] = {["fields"] = {}, ["inventory"] = {}}, ["y"] = 0, ["z"] = 14, ["name"] = "default:steelblock"}, {["x"] = 10, ["meta"] = {["fields"] = {}, ["inventory"] = {}}, ["y"] = 0, ["param1"] = 190, ["z"] = 19, ["name"] = "homedecor:fence_picket_white"}, {["x"] = 10, ["meta"] = {["fields"] = {}, ["inventory"] = {}}, ["y"] = 1, ["param1"] = 174, ["z"] = 6, ["name"] = "default:obsidian_glass"}, {["x"] = 10, ["meta"] = {["fields"] = {}, ["inventory"] = {}}, ["y"] = 1, ["param1"] = 174, ["z"] = 14, ["name"] = "default:obsidian_glass"}, {["x"] = 10, ["meta"] = {["fields"] = {}, ["inventory"] = {}}, ["y"] = 2, ["param1"] = 190, ["z"] = 6, ["name"] = "default:obsidian_glass"}, {["x"] = 10, ["meta"] = {["fields"] = {}, ["inventory"] = {}}, ["y"] = 2, ["param1"] = 190, ["z"] = 14, ["name"] = "default:obsidian_glass"}, {["x"] = 10, ["meta"] = {["fields"] = {}, ["inventory"] = {}}, ["y"] = 3, ["z"] = 6, ["name"] = "default:steelblock"}, {["x"] = 10, ["meta"] = {["fields"] = {}, ["inventory"] = {}}, ["y"] = 3, ["z"] = 14, ["name"] = "default:steelblock"}, {["x"] = 10, ["meta"] = {["fields"] = {}, ["inventory"] = {}}, ["y"] = 4, ["z"] = 6, ["name"] = "default:steelblock"}, {["x"] = 10, ["meta"] = {["fields"] = {}, ["inventory"] = {}}, ["y"] = 4, ["param1"] = 239, ["z"] = 7, ["name"] = "default:meselamp"}, {["x"] = 10, ["meta"] = {["fields"] = {}, ["inventory"] = {}}, ["y"] = 4, ["param1"] = 239, ["z"] = 8, ["name"] = "default:meselamp"}, {["x"] = 10, ["meta"] = {["fields"] = {}, ["inventory"] = {}}, ["y"] = 4, ["param1"] = 239, ["z"] = 9, ["name"] = "default:meselamp"}, {["x"] = 10, ["meta"] = {["fields"] = {}, ["inventory"] = {}}, ["y"] = 4, ["param1"] = 239, ["z"] = 10, ["name"] = "default:meselamp"}, {["x"] = 10, ["meta"] = {["fields"] = {}, ["inventory"] = {}}, ["y"] = 4, ["param1"] = 239, ["z"] = 11, ["name"] = "default:meselamp"}, {["x"] = 10, ["meta"] = {["fields"] = {}, ["inventory"] = {}}, ["y"] = 4, ["param1"] = 239, ["z"] = 12, ["name"] = "default:meselamp"}, {["x"] = 10, ["meta"] = {["fields"] = {}, ["inventory"] = {}}, ["y"] = 4, ["param1"] = 239, ["z"] = 13, ["name"] = "default:meselamp"}, {["x"] = 10, ["meta"] = {["fields"] = {}, ["inventory"] = {}}, ["y"] = 4, ["z"] = 14, ["name"] = "default:steelblock"}, {["x"] = 10, ["meta"] = {["fields"] = {}, ["inventory"] = {}}, ["y"] = 4, ["z"] = 15, ["name"] = "spell:Letter_S"}, {["x"] = 10, ["meta"] = {["fields"] = {}, ["inventory"] = {}}, ["y"] = 5, ["z"] = 6, ["name"] = "default:steelblock"}, {["x"] = 10, ["meta"] = {["fields"] = {}, ["inventory"] = {}}, ["y"] = 5, ["z"] = 14, ["name"] = "default:steelblock"}, {["x"] = 10, ["meta"] = {["fields"] = {}, ["inventory"] = {}}, ["y"] = 6, ["param1"] = 190, ["z"] = 6, ["name"] = "default:obsidian_glass"}, {["x"] = 10, ["meta"] = {["fields"] = {}, ["inventory"] = {}}, ["y"] = 6, ["param1"] = 190, ["z"] = 14, ["name"] = "default:obsidian_glass"}, {["x"] = 10, ["meta"] = {["fields"] = {}, ["inventory"] = {}}, ["y"] = 7, ["param1"] = 190, ["z"] = 6, ["name"] = "default:obsidian_glass"}, {["x"] = 10, ["meta"] = {["fields"] = {}, ["inventory"] = {}}, ["y"] = 7, ["param1"] = 190, ["z"] = 14, ["name"] = "default:obsidian_glass"}, {["x"] = 10, ["meta"] = {["fields"] = {}, ["inventory"] = {}}, ["y"] = 8, ["z"] = 6, ["name"] = "default:steelblock"}, {["x"] = 10, ["meta"] = {["fields"] = {}, ["inventory"] = {}}, ["y"] = 8, ["z"] = 14, ["name"] = "default:steelblock"}, {["x"] = 10, ["meta"] = {["fields"] = {}, ["inventory"] = {}}, ["y"] = 9, ["z"] = 3, ["name"] = "default:steelblock"}, {["x"] = 10, ["meta"] = {["fields"] = {}, ["inventory"] = {}}, ["y"] = 9, ["z"] = 4, ["name"] = "default:steelblock"}, {["x"] = 10, ["meta"] = {["fields"] = {}, ["inventory"] = {}}, ["y"] = 9, ["z"] = 5, ["name"] = "default:steelblock"}, {["x"] = 10, ["meta"] = {["fields"] = {}, ["inventory"] = {}}, ["y"] = 9, ["z"] = 6, ["name"] = "default:steelblock"}, {["x"] = 10, ["meta"] = {["fields"] = {}, ["inventory"] = {}}, ["y"] = 9, ["param1"] = 239, ["z"] = 7, ["name"] = "default:meselamp"}, {["x"] = 10, ["meta"] = {["fields"] = {}, ["inventory"] = {}}, ["y"] = 9, ["param1"] = 239, ["z"] = 8, ["name"] = "default:meselamp"}, {["x"] = 10, ["meta"] = {["fields"] = {}, ["inventory"] = {}}, ["y"] = 9, ["param1"] = 239, ["z"] = 9, ["name"] = "default:meselamp"}, {["x"] = 10, ["meta"] = {["fields"] = {}, ["inventory"] = {}}, ["y"] = 9, ["param1"] = 239, ["z"] = 10, ["name"] = "default:meselamp"}, {["x"] = 10, ["meta"] = {["fields"] = {}, ["inventory"] = {}}, ["y"] = 9, ["param1"] = 239, ["z"] = 11, ["name"] = "default:meselamp"}, {["x"] = 10, ["meta"] = {["fields"] = {}, ["inventory"] = {}}, ["y"] = 9, ["param1"] = 239, ["z"] = 12, ["name"] = "default:meselamp"}, {["x"] = 10, ["meta"] = {["fields"] = {}, ["inventory"] = {}}, ["y"] = 9, ["param1"] = 239, ["z"] = 13, ["name"] = "default:meselamp"}, {["x"] = 10, ["meta"] = {["fields"] = {}, ["inventory"] = {}}, ["y"] = 9, ["z"] = 14, ["name"] = "default:steelblock"}, {["x"] = 10, ["meta"] = {["fields"] = {}, ["inventory"] = {}}, ["y"] = 9, ["z"] = 15, ["name"] = "default:steelblock"}, {["x"] = 10, ["meta"] = {["fields"] = {}, ["inventory"] = {}}, ["y"] = 9, ["z"] = 16, ["name"] = "default:steelblock"}, {["x"] = 10, ["meta"] = {["fields"] = {}, ["inventory"] = {}}, ["y"] = 9, ["z"] = 17, ["name"] = "default:steelblock"}, {["x"] = 10, ["meta"] = {["fields"] = {}, ["inventory"] = {}}, ["y"] = 10, ["param1"] = 159, ["z"] = 3, ["name"] = "xpanes:pane_flat"}, {["x"] = 10, ["meta"] = {["fields"] = {}, ["inventory"] = {}}, ["y"] = 10, ["param1"] = 206, ["z"] = 6, ["name"] = "default:obsidian_glass"}, {["x"] = 10, ["meta"] = {["fields"] = {}, ["inventory"] = {}}, ["y"] = 10, ["param1"] = 206, ["z"] = 14, ["name"] = "default:obsidian_glass"}, {["x"] = 10, ["meta"] = {["fields"] = {}, ["inventory"] = {}}, ["y"] = 10, ["param1"] = 159, ["z"] = 17, ["name"] = "xpanes:pane_flat"}, {["x"] = 10, ["meta"] = {["fields"] = {}, ["inventory"] = {}}, ["y"] = 11, ["param1"] = 190, ["z"] = 6, ["name"] = "default:obsidian_glass"}, {["x"] = 10, ["meta"] = {["fields"] = {}, ["inventory"] = {}}, ["y"] = 11, ["param1"] = 190, ["z"] = 14, ["name"] = "default:obsidian_glass"}, {["x"] = 10, ["meta"] = {["fields"] = {}, ["inventory"] = {}}, ["y"] = 12, ["param1"] = 190, ["z"] = 6, ["name"] = "default:obsidian_glass"}, {["x"] = 10, ["meta"] = {["fields"] = {}, ["inventory"] = {}}, ["y"] = 12, ["param1"] = 190, ["z"] = 14, ["name"] = "default:obsidian_glass"}, {["x"] = 10, ["meta"] = {["fields"] = {}, ["inventory"] = {}}, ["y"] = 13, ["param1"] = 206, ["z"] = 6, ["name"] = "default:obsidian_glass"}, {["x"] = 10, ["meta"] = {["fields"] = {}, ["inventory"] = {}}, ["y"] = 13, ["param1"] = 206, ["z"] = 14, ["name"] = "default:obsidian_glass"}, {["x"] = 10, ["meta"] = {["fields"] = {}, ["inventory"] = {}}, ["y"] = 14, ["z"] = 6, ["name"] = "default:steelblock"}, {["x"] = 10, ["meta"] = {["fields"] = {}, ["inventory"] = {}}, ["y"] = 14, ["param1"] = 239, ["z"] = 7, ["name"] = "default:meselamp"}, {["x"] = 10, ["meta"] = {["fields"] = {}, ["inventory"] = {}}, ["y"] = 14, ["param1"] = 239, ["z"] = 8, ["name"] = "default:meselamp"}, {["x"] = 10, ["meta"] = {["fields"] = {}, ["inventory"] = {}}, ["y"] = 14, ["param1"] = 239, ["z"] = 9, ["name"] = "default:meselamp"}, {["x"] = 10, ["meta"] = {["fields"] = {}, ["inventory"] = {}}, ["y"] = 14, ["param1"] = 239, ["z"] = 10, ["name"] = "default:meselamp"}, {["x"] = 10, ["meta"] = {["fields"] = {}, ["inventory"] = {}}, ["y"] = 14, ["param1"] = 239, ["z"] = 11, ["name"] = "default:meselamp"}, {["x"] = 10, ["meta"] = {["fields"] = {}, ["inventory"] = {}}, ["y"] = 14, ["param1"] = 239, ["z"] = 12, ["name"] = "default:meselamp"}, {["x"] = 10, ["meta"] = {["fields"] = {}, ["inventory"] = {}}, ["y"] = 14, ["param1"] = 239, ["z"] = 13, ["name"] = "default:meselamp"}, {["x"] = 10, ["meta"] = {["fields"] = {}, ["inventory"] = {}}, ["y"] = 14, ["z"] = 14, ["name"] = "default:steelblock"}, {["x"] = 11, ["meta"] = {["fields"] = {}, ["inventory"] = {}}, ["param2"] = 2, ["y"] = 0, ["param1"] = 206, ["z"] = 1, ["name"] = "homedecor:fence_picket_white"}, {["x"] = 11, ["meta"] = {["fields"] = {}, ["inventory"] = {}}, ["y"] = 0, ["z"] = 6, ["name"] = "default:steelblock"}, {["x"] = 11, ["meta"] = {["fields"] = {}, ["inventory"] = {}}, ["y"] = 0, ["z"] = 14, ["name"] = "default:steelblock"}, {["x"] = 11, ["meta"] = {["fields"] = {}, ["inventory"] = {}}, ["y"] = 0, ["z"] = 19, ["name"] = "default:obsidianbrick"}, {["x"] = 11, ["meta"] = {["fields"] = {}, ["inventory"] = {}}, ["y"] = 1, ["param1"] = 174, ["z"] = 6, ["name"] = "default:obsidian_glass"}, {["x"] = 11, ["meta"] = {["fields"] = {}, ["inventory"] = {}}, ["y"] = 1, ["z"] = 14, ["name"] = "default:steelblock"}, {["x"] = 11, ["meta"] = {["fields"] = {}, ["inventory"] = {}}, ["y"] = 1, ["z"] = 19, ["name"] = "default:obsidianbrick"}, {["x"] = 11, ["meta"] = {["fields"] = {}, ["inventory"] = {}}, ["y"] = 2, ["param1"] = 190, ["z"] = 6, ["name"] = "default:obsidian_glass"}, {["x"] = 11, ["meta"] = {["fields"] = {}, ["inventory"] = {}}, ["y"] = 2, ["z"] = 14, ["name"] = "default:steelblock"}, {["x"] = 11, ["meta"] = {["fields"] = {}, ["inventory"] = {}}, ["y"] = 2, ["param1"] = 239, ["z"] = 19, ["name"] = "default:mese_post_light"}, {["x"] = 11, ["meta"] = {["fields"] = {}, ["inventory"] = {}}, ["y"] = 3, ["z"] = 6, ["name"] = "default:steelblock"}, {["x"] = 11, ["meta"] = {["fields"] = {}, ["inventory"] = {}}, ["y"] = 3, ["z"] = 14, ["name"] = "default:steelblock"}, {["x"] = 11, ["meta"] = {["fields"] = {}, ["inventory"] = {}}, ["y"] = 4, ["z"] = 6, ["name"] = "default:steelblock"}, {["x"] = 11, ["meta"] = {["fields"] = {}, ["inventory"] = {}}, ["y"] = 4, ["param1"] = 239, ["z"] = 7, ["name"] = "default:meselamp"}, {["x"] = 11, ["meta"] = {["fields"] = {}, ["inventory"] = {}}, ["y"] = 4, ["param1"] = 239, ["z"] = 8, ["name"] = "default:meselamp"}, {["x"] = 11, ["meta"] = {["fields"] = {}, ["inventory"] = {}}, ["y"] = 4, ["param1"] = 239, ["z"] = 9, ["name"] = "default:meselamp"}, {["x"] = 11, ["meta"] = {["fields"] = {}, ["inventory"] = {}}, ["y"] = 4, ["param1"] = 239, ["z"] = 10, ["name"] = "default:meselamp"}, {["x"] = 11, ["meta"] = {["fields"] = {}, ["inventory"] = {}}, ["y"] = 4, ["param1"] = 239, ["z"] = 11, ["name"] = "default:meselamp"}, {["x"] = 11, ["meta"] = {["fields"] = {}, ["inventory"] = {}}, ["y"] = 4, ["param1"] = 239, ["z"] = 12, ["name"] = "default:meselamp"}, {["x"] = 11, ["meta"] = {["fields"] = {}, ["inventory"] = {}}, ["y"] = 4, ["param1"] = 239, ["z"] = 13, ["name"] = "default:meselamp"}, {["x"] = 11, ["meta"] = {["fields"] = {}, ["inventory"] = {}}, ["y"] = 4, ["z"] = 14, ["name"] = "default:steelblock"}, {["x"] = 11, ["meta"] = {["fields"] = {}, ["inventory"] = {}}, ["y"] = 4, ["z"] = 15, ["name"] = "spell:Letter_E"}, {["x"] = 11, ["meta"] = {["fields"] = {}, ["inventory"] = {}}, ["y"] = 5, ["z"] = 6, ["name"] = "default:steelblock"}, {["x"] = 11, ["meta"] = {["fields"] = {}, ["inventory"] = {}}, ["y"] = 5, ["z"] = 14, ["name"] = "default:steelblock"}, {["x"] = 11, ["meta"] = {["fields"] = {}, ["inventory"] = {}}, ["y"] = 6, ["param1"] = 190, ["z"] = 6, ["name"] = "default:obsidian_glass"}, {["x"] = 11, ["meta"] = {["fields"] = {}, ["inventory"] = {}}, ["y"] = 6, ["param1"] = 190, ["z"] = 14, ["name"] = "default:obsidian_glass"}, {["x"] = 11, ["meta"] = {["fields"] = {}, ["inventory"] = {}}, ["y"] = 7, ["param1"] = 190, ["z"] = 6, ["name"] = "default:obsidian_glass"}, {["x"] = 11, ["meta"] = {["fields"] = {}, ["inventory"] = {}}, ["y"] = 7, ["param1"] = 190, ["z"] = 14, ["name"] = "default:obsidian_glass"}, {["x"] = 11, ["meta"] = {["fields"] = {}, ["inventory"] = {}}, ["y"] = 8, ["z"] = 6, ["name"] = "default:steelblock"}, {["x"] = 11, ["meta"] = {["fields"] = {}, ["inventory"] = {}}, ["y"] = 8, ["z"] = 14, ["name"] = "default:steelblock"}, {["x"] = 11, ["meta"] = {["fields"] = {}, ["inventory"] = {}}, ["y"] = 9, ["z"] = 3, ["name"] = "default:steelblock"}, {["x"] = 11, ["meta"] = {["fields"] = {}, ["inventory"] = {}}, ["y"] = 9, ["z"] = 4, ["name"] = "default:steelblock"}, {["x"] = 11, ["meta"] = {["fields"] = {}, ["inventory"] = {}}, ["y"] = 9, ["z"] = 5, ["name"] = "default:steelblock"}, {["x"] = 11, ["meta"] = {["fields"] = {}, ["inventory"] = {}}, ["y"] = 9, ["z"] = 6, ["name"] = "default:steelblock"}, {["x"] = 11, ["meta"] = {["fields"] = {}, ["inventory"] = {}}, ["y"] = 9, ["param1"] = 239, ["z"] = 7, ["name"] = "default:meselamp"}, {["x"] = 11, ["meta"] = {["fields"] = {}, ["inventory"] = {}}, ["y"] = 9, ["param1"] = 239, ["z"] = 8, ["name"] = "default:meselamp"}, {["x"] = 11, ["meta"] = {["fields"] = {}, ["inventory"] = {}}, ["y"] = 9, ["param1"] = 239, ["z"] = 9, ["name"] = "default:meselamp"}, {["x"] = 11, ["meta"] = {["fields"] = {}, ["inventory"] = {}}, ["y"] = 9, ["param1"] = 239, ["z"] = 10, ["name"] = "default:meselamp"}, {["x"] = 11, ["meta"] = {["fields"] = {}, ["inventory"] = {}}, ["y"] = 9, ["param1"] = 239, ["z"] = 11, ["name"] = "default:meselamp"}, {["x"] = 11, ["meta"] = {["fields"] = {}, ["inventory"] = {}}, ["y"] = 9, ["param1"] = 239, ["z"] = 12, ["name"] = "default:meselamp"}, {["x"] = 11, ["meta"] = {["fields"] = {}, ["inventory"] = {}}, ["y"] = 9, ["param1"] = 239, ["z"] = 13, ["name"] = "default:meselamp"}, {["x"] = 11, ["meta"] = {["fields"] = {}, ["inventory"] = {}}, ["y"] = 9, ["z"] = 14, ["name"] = "default:steelblock"}, {["x"] = 11, ["meta"] = {["fields"] = {}, ["inventory"] = {}}, ["y"] = 9, ["z"] = 15, ["name"] = "default:steelblock"}, {["x"] = 11, ["meta"] = {["fields"] = {}, ["inventory"] = {}}, ["y"] = 9, ["z"] = 16, ["name"] = "default:steelblock"}, {["x"] = 11, ["meta"] = {["fields"] = {}, ["inventory"] = {}}, ["y"] = 9, ["z"] = 17, ["name"] = "default:steelblock"}, {["x"] = 11, ["meta"] = {["fields"] = {}, ["inventory"] = {}}, ["y"] = 10, ["param1"] = 159, ["z"] = 3, ["name"] = "xpanes:pane_flat"}, {["x"] = 11, ["meta"] = {["fields"] = {}, ["inventory"] = {}}, ["y"] = 10, ["param1"] = 206, ["z"] = 6, ["name"] = "default:obsidian_glass"}, {["x"] = 11, ["meta"] = {["fields"] = {}, ["inventory"] = {}}, ["y"] = 10, ["param1"] = 206, ["z"] = 14, ["name"] = "default:obsidian_glass"}, {["x"] = 11, ["meta"] = {["fields"] = {}, ["inventory"] = {}}, ["y"] = 10, ["param1"] = 159, ["z"] = 17, ["name"] = "xpanes:pane_flat"}, {["x"] = 11, ["meta"] = {["fields"] = {}, ["inventory"] = {}}, ["y"] = 11, ["param1"] = 190, ["z"] = 6, ["name"] = "default:obsidian_glass"}, {["x"] = 11, ["meta"] = {["fields"] = {}, ["inventory"] = {}}, ["y"] = 11, ["param1"] = 190, ["z"] = 14, ["name"] = "default:obsidian_glass"}, {["x"] = 11, ["meta"] = {["fields"] = {}, ["inventory"] = {}}, ["y"] = 12, ["param1"] = 190, ["z"] = 6, ["name"] = "default:obsidian_glass"}, {["x"] = 11, ["meta"] = {["fields"] = {}, ["inventory"] = {}}, ["y"] = 12, ["param1"] = 190, ["z"] = 14, ["name"] = "default:obsidian_glass"}, {["x"] = 11, ["meta"] = {["fields"] = {}, ["inventory"] = {}}, ["y"] = 13, ["param1"] = 206, ["z"] = 6, ["name"] = "default:obsidian_glass"}, {["x"] = 11, ["meta"] = {["fields"] = {}, ["inventory"] = {}}, ["y"] = 13, ["param1"] = 206, ["z"] = 14, ["name"] = "default:obsidian_glass"}, {["x"] = 11, ["meta"] = {["fields"] = {}, ["inventory"] = {}}, ["y"] = 14, ["z"] = 6, ["name"] = "default:steelblock"}, {["x"] = 11, ["meta"] = {["fields"] = {}, ["inventory"] = {}}, ["y"] = 14, ["param1"] = 239, ["z"] = 7, ["name"] = "default:meselamp"}, {["x"] = 11, ["meta"] = {["fields"] = {}, ["inventory"] = {}}, ["y"] = 14, ["param1"] = 239, ["z"] = 8, ["name"] = "default:meselamp"}, {["x"] = 11, ["meta"] = {["fields"] = {}, ["inventory"] = {}}, ["y"] = 14, ["param1"] = 239, ["z"] = 9, ["name"] = "default:meselamp"}, {["x"] = 11, ["meta"] = {["fields"] = {}, ["inventory"] = {}}, ["y"] = 14, ["param1"] = 239, ["z"] = 10, ["name"] = "default:meselamp"}, {["x"] = 11, ["meta"] = {["fields"] = {}, ["inventory"] = {}}, ["y"] = 14, ["param1"] = 239, ["z"] = 11, ["name"] = "default:meselamp"}, {["x"] = 11, ["meta"] = {["fields"] = {}, ["inventory"] = {}}, ["y"] = 14, ["param1"] = 239, ["z"] = 12, ["name"] = "default:meselamp"}, {["x"] = 11, ["meta"] = {["fields"] = {}, ["inventory"] = {}}, ["y"] = 14, ["param1"] = 239, ["z"] = 13, ["name"] = "default:meselamp"}, {["x"] = 11, ["meta"] = {["fields"] = {}, ["inventory"] = {}}, ["y"] = 14, ["z"] = 14, ["name"] = "default:steelblock"}, {["x"] = 12, ["meta"] = {["fields"] = {}, ["inventory"] = {}}, ["param2"] = 2, ["y"] = 0, ["param1"] = 206, ["z"] = 1, ["name"] = "homedecor:fence_picket_white"}, {["x"] = 12, ["meta"] = {["fields"] = {}, ["inventory"] = {}}, ["y"] = 0, ["z"] = 6, ["name"] = "default:steelblock"}, {["x"] = 12, ["meta"] = {["fields"] = {}, ["inventory"] = {}}, ["param2"] = 5, ["y"] = 0, ["param1"] = 159, ["z"] = 7, ["name"] = "default:ladder_wood"}, {["x"] = 12, ["meta"] = {["fields"] = {["state"] = "3"}, ["inventory"] = {}}, ["param2"] = 1, ["y"] = 0, ["param1"] = 174, ["z"] = 14, ["name"] = "doors:door_obsidian_glass_a"}, {["x"] = 12, ["meta"] = {["fields"] = {}, ["inventory"] = {}}, ["y"] = 1, ["param1"] = 158, ["z"] = 6, ["name"] = "default:obsidian_glass"}, {["x"] = 12, ["meta"] = {["fields"] = {}, ["inventory"] = {}}, ["param2"] = 5, ["y"] = 1, ["param1"] = 175, ["z"] = 7, ["name"] = "default:ladder_wood"}, {["x"] = 12, ["meta"] = {["fields"] = {}, ["inventory"] = {}}, ["param2"] = 1, ["y"] = 1, ["param1"] = 190, ["z"] = 14, ["name"] = "doors:hidden"}, {["x"] = 12, ["meta"] = {["fields"] = {}, ["inventory"] = {}}, ["y"] = 2, ["param1"] = 174, ["z"] = 6, ["name"] = "default:obsidian_glass"}, {["x"] = 12, ["meta"] = {["fields"] = {}, ["inventory"] = {}}, ["param2"] = 5, ["y"] = 2, ["param1"] = 191, ["z"] = 7, ["name"] = "default:ladder_wood"}, {["x"] = 12, ["meta"] = {["fields"] = {}, ["inventory"] = {}}, ["param2"] = 4, ["y"] = 2, ["param1"] = 223, ["z"] = 13, ["name"] = "default:torch_wall"}, {["x"] = 12, ["meta"] = {["fields"] = {}, ["inventory"] = {}}, ["y"] = 2, ["z"] = 14, ["name"] = "default:steelblock"}, {["x"] = 12, ["meta"] = {["fields"] = {}, ["inventory"] = {}}, ["param2"] = 5, ["y"] = 2, ["param1"] = 221, ["z"] = 15, ["name"] = "default:torch_wall"}, {["x"] = 12, ["meta"] = {["fields"] = {}, ["inventory"] = {}}, ["y"] = 3, ["z"] = 6, ["name"] = "default:steelblock"}, {["x"] = 12, ["meta"] = {["fields"] = {}, ["inventory"] = {}}, ["param2"] = 5, ["y"] = 3, ["param1"] = 207, ["z"] = 7, ["name"] = "default:ladder_wood"}, {["x"] = 12, ["meta"] = {["fields"] = {}, ["inventory"] = {}}, ["y"] = 3, ["z"] = 14, ["name"] = "default:steelblock"}, {["x"] = 12, ["meta"] = {["fields"] = {}, ["inventory"] = {}}, ["y"] = 4, ["z"] = 6, ["name"] = "default:steelblock"}, {["x"] = 12, ["meta"] = {["fields"] = {}, ["inventory"] = {}}, ["param2"] = 5, ["y"] = 4, ["param1"] = 223, ["z"] = 7, ["name"] = "default:ladder_wood"}, {["x"] = 12, ["meta"] = {["fields"] = {}, ["inventory"] = {}}, ["y"] = 4, ["param1"] = 239, ["z"] = 8, ["name"] = "default:meselamp"}, {["x"] = 12, ["meta"] = {["fields"] = {}, ["inventory"] = {}}, ["y"] = 4, ["param1"] = 239, ["z"] = 9, ["name"] = "default:meselamp"}, {["x"] = 12, ["meta"] = {["fields"] = {}, ["inventory"] = {}}, ["y"] = 4, ["param1"] = 239, ["z"] = 10, ["name"] = "default:meselamp"}, {["x"] = 12, ["meta"] = {["fields"] = {}, ["inventory"] = {}}, ["y"] = 4, ["param1"] = 239, ["z"] = 11, ["name"] = "default:meselamp"}, {["x"] = 12, ["meta"] = {["fields"] = {}, ["inventory"] = {}}, ["y"] = 4, ["param1"] = 239, ["z"] = 12, ["name"] = "default:meselamp"}, {["x"] = 12, ["meta"] = {["fields"] = {}, ["inventory"] = {}}, ["y"] = 4, ["param1"] = 239, ["z"] = 13, ["name"] = "default:meselamp"}, {["x"] = 12, ["meta"] = {["fields"] = {}, ["inventory"] = {}}, ["y"] = 4, ["z"] = 14, ["name"] = "default:steelblock"}, {["x"] = 12, ["meta"] = {["fields"] = {}, ["inventory"] = {}}, ["y"] = 4, ["z"] = 15, ["name"] = "spell:Letter_C"}, {["x"] = 12, ["meta"] = {["fields"] = {}, ["inventory"] = {}}, ["y"] = 5, ["z"] = 6, ["name"] = "default:steelblock"}, {["x"] = 12, ["meta"] = {["fields"] = {}, ["inventory"] = {}}, ["param2"] = 5, ["y"] = 5, ["param1"] = 207, ["z"] = 7, ["name"] = "default:ladder_wood"}, {["x"] = 12, ["meta"] = {["fields"] = {}, ["inventory"] = {}}, ["y"] = 5, ["z"] = 14, ["name"] = "default:steelblock"}, {["x"] = 12, ["meta"] = {["fields"] = {}, ["inventory"] = {}}, ["y"] = 6, ["param1"] = 190, ["z"] = 6, ["name"] = "default:obsidian_glass"}, {["x"] = 12, ["meta"] = {["fields"] = {}, ["inventory"] = {}}, ["param2"] = 5, ["y"] = 6, ["param1"] = 191, ["z"] = 7, ["name"] = "default:ladder_wood"}, {["x"] = 12, ["meta"] = {["fields"] = {}, ["inventory"] = {}}, ["y"] = 6, ["param1"] = 190, ["z"] = 14, ["name"] = "default:obsidian_glass"}, {["x"] = 12, ["meta"] = {["fields"] = {}, ["inventory"] = {}}, ["y"] = 7, ["param1"] = 206, ["z"] = 6, ["name"] = "default:obsidian_glass"}, {["x"] = 12, ["meta"] = {["fields"] = {}, ["inventory"] = {}}, ["param2"] = 5, ["y"] = 7, ["param1"] = 191, ["z"] = 7, ["name"] = "default:ladder_wood"}, {["x"] = 12, ["meta"] = {["fields"] = {}, ["inventory"] = {}}, ["y"] = 7, ["param1"] = 206, ["z"] = 14, ["name"] = "default:obsidian_glass"}, {["x"] = 12, ["meta"] = {["fields"] = {}, ["inventory"] = {}}, ["y"] = 8, ["param1"] = 238, ["z"] = 5, ["name"] = "default:mese_post_light"}, {["x"] = 12, ["meta"] = {["fields"] = {}, ["inventory"] = {}}, ["y"] = 8, ["z"] = 6, ["name"] = "default:steelblock"}, {["x"] = 12, ["meta"] = {["fields"] = {}, ["inventory"] = {}}, ["param2"] = 5, ["y"] = 8, ["param1"] = 207, ["z"] = 7, ["name"] = "default:ladder_wood"}, {["x"] = 12, ["meta"] = {["fields"] = {}, ["inventory"] = {}}, ["y"] = 8, ["z"] = 14, ["name"] = "default:steelblock"}, {["x"] = 12, ["meta"] = {["fields"] = {}, ["inventory"] = {}}, ["y"] = 8, ["param1"] = 238, ["z"] = 15, ["name"] = "default:mese_post_light"}, {["x"] = 12, ["meta"] = {["fields"] = {}, ["inventory"] = {}}, ["y"] = 9, ["z"] = 3, ["name"] = "default:steelblock"}, {["x"] = 12, ["meta"] = {["fields"] = {}, ["inventory"] = {}}, ["y"] = 9, ["z"] = 4, ["name"] = "default:steelblock"}, {["x"] = 12, ["meta"] = {["fields"] = {}, ["inventory"] = {}}, ["y"] = 9, ["z"] = 5, ["name"] = "default:steelblock"}, {["x"] = 12, ["meta"] = {["fields"] = {}, ["inventory"] = {}}, ["y"] = 9, ["z"] = 6, ["name"] = "default:steelblock"}, {["x"] = 12, ["meta"] = {["fields"] = {}, ["inventory"] = {}}, ["param2"] = 5, ["y"] = 9, ["param1"] = 223, ["z"] = 7, ["name"] = "default:ladder_wood"}, {["x"] = 12, ["meta"] = {["fields"] = {}, ["inventory"] = {}}, ["y"] = 9, ["param1"] = 239, ["z"] = 8, ["name"] = "default:meselamp"}, {["x"] = 12, ["meta"] = {["fields"] = {}, ["inventory"] = {}}, ["y"] = 9, ["param1"] = 239, ["z"] = 9, ["name"] = "default:meselamp"}, {["x"] = 12, ["meta"] = {["fields"] = {}, ["inventory"] = {}}, ["y"] = 9, ["param1"] = 239, ["z"] = 10, ["name"] = "default:meselamp"}, {["x"] = 12, ["meta"] = {["fields"] = {}, ["inventory"] = {}}, ["y"] = 9, ["param1"] = 239, ["z"] = 11, ["name"] = "default:meselamp"}, {["x"] = 12, ["meta"] = {["fields"] = {}, ["inventory"] = {}}, ["y"] = 9, ["param1"] = 239, ["z"] = 12, ["name"] = "default:meselamp"}, {["x"] = 12, ["meta"] = {["fields"] = {}, ["inventory"] = {}}, ["y"] = 9, ["param1"] = 239, ["z"] = 13, ["name"] = "default:meselamp"}, {["x"] = 12, ["meta"] = {["fields"] = {}, ["inventory"] = {}}, ["y"] = 9, ["z"] = 14, ["name"] = "default:steelblock"}, {["x"] = 12, ["meta"] = {["fields"] = {}, ["inventory"] = {}}, ["y"] = 9, ["z"] = 15, ["name"] = "default:steelblock"}, {["x"] = 12, ["meta"] = {["fields"] = {}, ["inventory"] = {}}, ["y"] = 9, ["z"] = 16, ["name"] = "default:steelblock"}, {["x"] = 12, ["meta"] = {["fields"] = {}, ["inventory"] = {}}, ["y"] = 9, ["z"] = 17, ["name"] = "default:steelblock"}, {["x"] = 12, ["meta"] = {["fields"] = {}, ["inventory"] = {}}, ["y"] = 10, ["param1"] = 143, ["z"] = 3, ["name"] = "xpanes:pane_flat"}, {["x"] = 12, ["meta"] = {["fields"] = {}, ["inventory"] = {}}, ["y"] = 10, ["param1"] = 190, ["z"] = 6, ["name"] = "default:obsidian_glass"}, {["x"] = 12, ["meta"] = {["fields"] = {["state"] = "2"}, ["inventory"] = {}}, ["param2"] = 2, ["y"] = 10, ["param1"] = 206, ["z"] = 14, ["name"] = "doors:door_obsidian_glass_b"}, {["x"] = 12, ["meta"] = {["fields"] = {}, ["inventory"] = {}}, ["y"] = 10, ["param1"] = 159, ["z"] = 17, ["name"] = "xpanes:pane_flat"}, {["x"] = 12, ["meta"] = {["fields"] = {}, ["inventory"] = {}}, ["y"] = 11, ["param1"] = 174, ["z"] = 6, ["name"] = "default:obsidian_glass"}, {["x"] = 12, ["meta"] = {["fields"] = {}, ["inventory"] = {}}, ["param2"] = 1, ["y"] = 11, ["param1"] = 190, ["z"] = 14, ["name"] = "doors:hidden"}, {["x"] = 12, ["meta"] = {["fields"] = {}, ["inventory"] = {}}, ["y"] = 12, ["param1"] = 190, ["z"] = 6, ["name"] = "default:obsidian_glass"}, {["x"] = 12, ["meta"] = {["fields"] = {}, ["inventory"] = {}}, ["y"] = 12, ["param1"] = 190, ["z"] = 14, ["name"] = "default:obsidian_glass"}, {["x"] = 12, ["meta"] = {["fields"] = {}, ["inventory"] = {}}, ["y"] = 13, ["param1"] = 206, ["z"] = 6, ["name"] = "default:obsidian_glass"}, {["x"] = 12, ["meta"] = {["fields"] = {}, ["inventory"] = {}}, ["y"] = 13, ["param1"] = 206, ["z"] = 14, ["name"] = "default:obsidian_glass"}, {["x"] = 12, ["meta"] = {["fields"] = {}, ["inventory"] = {}}, ["y"] = 14, ["z"] = 6, ["name"] = "default:steelblock"}, {["x"] = 12, ["meta"] = {["fields"] = {}, ["inventory"] = {}}, ["y"] = 14, ["param1"] = 239, ["z"] = 7, ["name"] = "default:meselamp"}, {["x"] = 12, ["meta"] = {["fields"] = {}, ["inventory"] = {}}, ["y"] = 14, ["param1"] = 239, ["z"] = 8, ["name"] = "default:meselamp"}, {["x"] = 12, ["meta"] = {["fields"] = {}, ["inventory"] = {}}, ["y"] = 14, ["param1"] = 239, ["z"] = 9, ["name"] = "default:meselamp"}, {["x"] = 12, ["meta"] = {["fields"] = {}, ["inventory"] = {}}, ["y"] = 14, ["param1"] = 239, ["z"] = 10, ["name"] = "default:meselamp"}, {["x"] = 12, ["meta"] = {["fields"] = {}, ["inventory"] = {}}, ["y"] = 14, ["param1"] = 239, ["z"] = 11, ["name"] = "default:meselamp"}, {["x"] = 12, ["meta"] = {["fields"] = {}, ["inventory"] = {}}, ["y"] = 14, ["param1"] = 239, ["z"] = 12, ["name"] = "default:meselamp"}, {["x"] = 12, ["meta"] = {["fields"] = {}, ["inventory"] = {}}, ["y"] = 14, ["param1"] = 239, ["z"] = 13, ["name"] = "default:meselamp"}, {["x"] = 12, ["meta"] = {["fields"] = {}, ["inventory"] = {}}, ["y"] = 14, ["z"] = 14, ["name"] = "default:steelblock"}, {["x"] = 13, ["meta"] = {["fields"] = {}, ["inventory"] = {}}, ["param2"] = 2, ["y"] = 0, ["param1"] = 206, ["z"] = 1, ["name"] = "homedecor:fence_picket_white"}, {["x"] = 13, ["meta"] = {["fields"] = {}, ["inventory"] = {}}, ["y"] = 0, ["z"] = 6, ["name"] = "default:steelblock"}, {["x"] = 13, ["meta"] = {["fields"] = {}, ["inventory"] = {}}, ["param2"] = 5, ["y"] = 0, ["param1"] = 159, ["z"] = 7, ["name"] = "default:ladder_wood"}, {["x"] = 13, ["meta"] = {["fields"] = {["state"] = "1"}, ["inventory"] = {}}, ["param2"] = 3, ["y"] = 0, ["param1"] = 174, ["z"] = 14, ["name"] = "doors:door_obsidian_glass_b"}, {["x"] = 13, ["meta"] = {["fields"] = {}, ["inventory"] = {}}, ["y"] = 1, ["param1"] = 158, ["z"] = 6, ["name"] = "default:obsidian_glass"}, {["x"] = 13, ["meta"] = {["fields"] = {}, ["inventory"] = {}}, ["param2"] = 5, ["y"] = 1, ["param1"] = 175, ["z"] = 7, ["name"] = "default:ladder_wood"}, {["x"] = 13, ["meta"] = {["fields"] = {}, ["inventory"] = {}}, ["param2"] = 2, ["y"] = 1, ["param1"] = 190, ["z"] = 14, ["name"] = "doors:hidden"}, {["x"] = 13, ["meta"] = {["fields"] = {}, ["inventory"] = {}}, ["y"] = 2, ["param1"] = 174, ["z"] = 6, ["name"] = "default:obsidian_glass"}, {["x"] = 13, ["meta"] = {["fields"] = {}, ["inventory"] = {}}, ["param2"] = 5, ["y"] = 2, ["param1"] = 191, ["z"] = 7, ["name"] = "default:ladder_wood"}, {["x"] = 13, ["meta"] = {["fields"] = {}, ["inventory"] = {}}, ["param2"] = 4, ["y"] = 2, ["param1"] = 223, ["z"] = 13, ["name"] = "default:torch_wall"}, {["x"] = 13, ["meta"] = {["fields"] = {}, ["inventory"] = {}}, ["y"] = 2, ["z"] = 14, ["name"] = "default:steelblock"}, {["x"] = 13, ["meta"] = {["fields"] = {}, ["inventory"] = {}}, ["param2"] = 5, ["y"] = 2, ["param1"] = 221, ["z"] = 15, ["name"] = "default:torch_wall"}, {["x"] = 13, ["meta"] = {["fields"] = {}, ["inventory"] = {}}, ["y"] = 3, ["z"] = 6, ["name"] = "default:steelblock"}, {["x"] = 13, ["meta"] = {["fields"] = {}, ["inventory"] = {}}, ["param2"] = 5, ["y"] = 3, ["param1"] = 207, ["z"] = 7, ["name"] = "default:ladder_wood"}, {["x"] = 13, ["meta"] = {["fields"] = {}, ["inventory"] = {}}, ["y"] = 3, ["z"] = 14, ["name"] = "default:steelblock"}, {["x"] = 13, ["meta"] = {["fields"] = {}, ["inventory"] = {}}, ["y"] = 4, ["z"] = 6, ["name"] = "default:steelblock"}, {["x"] = 13, ["meta"] = {["fields"] = {}, ["inventory"] = {}}, ["param2"] = 5, ["y"] = 4, ["param1"] = 223, ["z"] = 7, ["name"] = "default:ladder_wood"}, {["x"] = 13, ["meta"] = {["fields"] = {}, ["inventory"] = {}}, ["y"] = 4, ["param1"] = 239, ["z"] = 8, ["name"] = "default:meselamp"}, {["x"] = 13, ["meta"] = {["fields"] = {}, ["inventory"] = {}}, ["y"] = 4, ["param1"] = 239, ["z"] = 9, ["name"] = "default:meselamp"}, {["x"] = 13, ["meta"] = {["fields"] = {}, ["inventory"] = {}}, ["y"] = 4, ["param1"] = 239, ["z"] = 10, ["name"] = "default:meselamp"}, {["x"] = 13, ["meta"] = {["fields"] = {}, ["inventory"] = {}}, ["y"] = 4, ["param1"] = 239, ["z"] = 11, ["name"] = "default:meselamp"}, {["x"] = 13, ["meta"] = {["fields"] = {}, ["inventory"] = {}}, ["y"] = 4, ["param1"] = 239, ["z"] = 12, ["name"] = "default:meselamp"}, {["x"] = 13, ["meta"] = {["fields"] = {}, ["inventory"] = {}}, ["y"] = 4, ["param1"] = 239, ["z"] = 13, ["name"] = "default:meselamp"}, {["x"] = 13, ["meta"] = {["fields"] = {}, ["inventory"] = {}}, ["y"] = 4, ["z"] = 14, ["name"] = "default:steelblock"}, {["x"] = 13, ["meta"] = {["fields"] = {}, ["inventory"] = {}}, ["y"] = 4, ["z"] = 15, ["name"] = "spell:Letter_L"}, {["x"] = 13, ["meta"] = {["fields"] = {}, ["inventory"] = {}}, ["y"] = 5, ["z"] = 6, ["name"] = "default:steelblock"}, {["x"] = 13, ["meta"] = {["fields"] = {}, ["inventory"] = {}}, ["param2"] = 5, ["y"] = 5, ["param1"] = 207, ["z"] = 7, ["name"] = "default:ladder_wood"}, {["x"] = 13, ["meta"] = {["fields"] = {}, ["inventory"] = {}}, ["y"] = 5, ["z"] = 14, ["name"] = "default:steelblock"}, {["x"] = 13, ["meta"] = {["fields"] = {}, ["inventory"] = {}}, ["y"] = 6, ["param1"] = 190, ["z"] = 6, ["name"] = "default:obsidian_glass"}, {["x"] = 13, ["meta"] = {["fields"] = {}, ["inventory"] = {}}, ["param2"] = 5, ["y"] = 6, ["param1"] = 191, ["z"] = 7, ["name"] = "default:ladder_wood"}, {["x"] = 13, ["meta"] = {["fields"] = {},