5:return {{["x"] = 0, ["meta"] = {["fields"] = {}, ["inventory"] = {}}, ["y"] = 0, ["z"] = 1, ["name"] = "default:dirt_with_grass"}, {["x"] = 0, ["meta"] = {["fields"] = {}, ["inventory"] = {}}, ["y"] = 0, ["z"] = 2, ["name"] = "default:dirt_with_grass"}, {["x"] = 0, ["meta"] = {["fields"] = {}, ["inventory"] = {}}, ["y"] = 0, ["z"] = 3, ["name"] = "default:dirt_with_grass"}, {["x"] = 0, ["meta"] = {["fields"] = {}, ["inventory"] = {}}, ["y"] = 0, ["z"] = 4, ["name"] = "default:dirt_with_grass"}, {["x"] = 0, ["meta"] = {["fields"] = {}, ["inventory"] = {}}, ["y"] = 0, ["z"] = 5, ["name"] = "default:dirt"}, {["x"] = 0, ["meta"] = {["fields"] = {}, ["inventory"] = {}}, ["y"] = 0, ["z"] = 6, ["name"] = "default:dirt"}, {["x"] = 0, ["meta"] = {["fields"] = {}, ["inventory"] = {}}, ["y"] = 0, ["z"] = 7, ["name"] = "default:dirt"}, {["x"] = 0, ["meta"] = {["fields"] = {}, ["inventory"] = {}}, ["y"] = 0, ["z"] = 8, ["name"] = "default:dirt_with_grass"}, {["x"] = 0, ["meta"] = {["fields"] = {}, ["inventory"] = {}}, ["y"] = 0, ["z"] = 9, ["name"] = "default:dirt_with_grass"}, {["x"] = 0, ["meta"] = {["fields"] = {}, ["inventory"] = {}}, ["y"] = 0, ["z"] = 10, ["name"] = "default:dirt_with_grass"}, {["x"] = 0, ["meta"] = {["fields"] = {}, ["inventory"] = {}}, ["y"] = 0, ["z"] = 11, ["name"] = "default:dirt_with_grass"}, {["x"] = 0, ["meta"] = {["fields"] = {}, ["inventory"] = {}}, ["y"] = 0, ["z"] = 12, ["name"] = "default:dirt_with_grass"}, {["x"] = 0, ["meta"] = {["fields"] = {}, ["inventory"] = {}}, ["y"] = 0, ["z"] = 17, ["name"] = "default:snowblock"}, {["x"] = 0, ["meta"] = {["fields"] = {}, ["inventory"] = {}}, ["y"] = 1, ["z"] = 5, ["name"] = "default:dirt_with_grass"}, {["x"] = 0, ["meta"] = {["fields"] = {}, ["inventory"] = {}}, ["y"] = 1, ["z"] = 6, ["name"] = "default:dirt_with_grass"}, {["x"] = 0, ["meta"] = {["fields"] = {}, ["inventory"] = {}}, ["y"] = 1, ["z"] = 7, ["name"] = "default:dirt_with_grass"}, {["x"] = 0, ["meta"] = {["fields"] = {}, ["inventory"] = {}}, ["y"] = 1, ["param1"] = 111, ["z"] = 9, ["name"] = "default:grass_3"}, {["x"] = 0, ["meta"] = {["fields"] = {}, ["inventory"] = {}}, ["y"] = 22, ["z"] = 7, ["name"] = "default:obsidianbrick"}, {["x"] = 0, ["meta"] = {["fields"] = {}, ["inventory"] = {}}, ["y"] = 22, ["z"] = 10, ["name"] = "default:obsidianbrick"}, {["x"] = 0, ["meta"] = {["fields"] = {}, ["inventory"] = {}}, ["y"] = 23, ["z"] = 7, ["name"] = "default:obsidianbrick"}, {["x"] = 0, ["meta"] = {["fields"] = {}, ["inventory"] = {}}, ["y"] = 23, ["z"] = 10, ["name"] = "default:obsidianbrick"}, {["x"] = 0, ["meta"] = {["fields"] = {}, ["inventory"] = {}}, ["y"] = 24, ["z"] = 7, ["name"] = "default:obsidianbrick"}, {["x"] = 0, ["meta"] = {["fields"] = {}, ["inventory"] = {}}, ["y"] = 24, ["z"] = 10, ["name"] = "default:obsidianbrick"}, {["x"] = 0, ["meta"] = {["fields"] = {}, ["inventory"] = {}}, ["y"] = 25, ["z"] = 7, ["name"] = "default:obsidianbrick"}, {["x"] = 0, ["meta"] = {["fields"] = {}, ["inventory"] = {}}, ["y"] = 25, ["z"] = 10, ["name"] = "default:obsidianbrick"}, {["x"] = 0, ["meta"] = {["fields"] = {}, ["inventory"] = {}}, ["y"] = 26, ["z"] = 7, ["name"] = "default:obsidianbrick"}, {["x"] = 0, ["meta"] = {["fields"] = {}, ["inventory"] = {}}, ["y"] = 26, ["z"] = 10, ["name"] = "default:obsidianbrick"}, {["x"] = 1, ["meta"] = {["fields"] = {}, ["inventory"] = {}}, ["y"] = 0, ["z"] = 0, ["name"] = "default:dirt_with_grass"}, {["x"] = 1, ["meta"] = {["fields"] = {}, ["inventory"] = {}}, ["y"] = 0, ["z"] = 1, ["name"] = "default:dirt_with_grass"}, {["x"] = 1, ["meta"] = {["fields"] = {}, ["inventory"] = {}}, ["y"] = 0, ["z"] = 2, ["name"] = "default:dirt_with_grass"}, {["x"] = 1, ["meta"] = {["fields"] = {}, ["inventory"] = {}}, ["y"] = 0, ["z"] = 3, ["name"] = "default:dirt"}, {["x"] = 1, ["meta"] = {["fields"] = {}, ["inventory"] = {}}, ["y"] = 0, ["z"] = 4, ["name"] = "default:dirt"}, {["x"] = 1, ["meta"] = {["fields"] = {}, ["inventory"] = {}}, ["y"] = 0, ["z"] = 5, ["name"] = "default:dirt"}, {["x"] = 1, ["meta"] = {["fields"] = {}, ["inventory"] = {}}, ["y"] = 0, ["z"] = 6, ["name"] = "default:dirt"}, {["x"] = 1, ["meta"] = {["fields"] = {}, ["inventory"] = {}}, ["y"] = 0, ["z"] = 7, ["name"] = "default:dirt"}, {["x"] = 1, ["meta"] = {["fields"] = {}, ["inventory"] = {}}, ["y"] = 0, ["z"] = 8, ["name"] = "default:dirt"}, {["x"] = 1, ["meta"] = {["fields"] = {}, ["inventory"] = {}}, ["y"] = 0, ["z"] = 9, ["name"] = "default:dirt"}, {["x"] = 1, ["meta"] = {["fields"] = {}, ["inventory"] = {}}, ["y"] = 0, ["z"] = 10, ["name"] = "default:dirt"}, {["x"] = 1, ["meta"] = {["fields"] = {}, ["inventory"] = {}}, ["y"] = 0, ["z"] = 11, ["name"] = "default:dirt"}, {["x"] = 1, ["meta"] = {["fields"] = {}, ["inventory"] = {}}, ["y"] = 0, ["z"] = 12, ["name"] = "default:dirt"}, {["x"] = 1, ["meta"] = {["fields"] = {}, ["inventory"] = {}}, ["y"] = 0, ["z"] = 14, ["name"] = "default:tree"}, {["x"] = 1, ["meta"] = {["fields"] = {}, ["inventory"] = {}}, ["y"] = 0, ["z"] = 16, ["name"] = "default:snowblock"}, {["x"] = 1, ["meta"] = {["fields"] = {}, ["inventory"] = {}}, ["y"] = 1, ["z"] = 3, ["name"] = "default:dirt_with_grass"}, {["x"] = 1, ["meta"] = {["fields"] = {}, ["inventory"] = {}}, ["y"] = 1, ["z"] = 4, ["name"] = "default:dirt_with_grass"}, {["x"] = 1, ["meta"] = {["fields"] = {}, ["inventory"] = {}}, ["y"] = 1, ["z"] = 5, ["name"] = "default:dirt_with_grass"}, {["x"] = 1, ["meta"] = {["fields"] = {}, ["inventory"] = {}}, ["y"] = 1, ["z"] = 6, ["name"] = "default:dirt_with_grass"}, {["x"] = 1, ["meta"] = {["fields"] = {}, ["inventory"] = {}}, ["y"] = 1, ["z"] = 7, ["name"] = "default:dirt_with_grass"}, {["x"] = 1, ["meta"] = {["fields"] = {}, ["inventory"] = {}}, ["y"] = 1, ["z"] = 8, ["name"] = "default:dirt_with_grass"}, {["x"] = 1, ["meta"] = {["fields"] = {}, ["inventory"] = {}}, ["y"] = 1, ["z"] = 9, ["name"] = "default:dirt_with_grass"}, {["x"] = 1, ["meta"] = {["fields"] = {}, ["inventory"] = {}}, ["y"] = 1, ["z"] = 10, ["name"] = "default:dirt_with_grass"}, {["x"] = 1, ["meta"] = {["fields"] = {}, ["inventory"] = {}}, ["y"] = 1, ["z"] = 11, ["name"] = "default:dirt_with_grass"}, {["x"] = 1, ["meta"] = {["fields"] = {}, ["inventory"] = {}}, ["y"] = 1, ["z"] = 12, ["name"] = "default:dirt_with_grass"}, {["x"] = 1, ["meta"] = {["fields"] = {}, ["inventory"] = {}}, ["y"] = 1, ["z"] = 14, ["name"] = "default:tree"}, {["x"] = 1, ["meta"] = {["fields"] = {}, ["inventory"] = {}}, ["y"] = 2, ["param1"] = 157, ["z"] = 10, ["name"] = "default:grass_3"}, {["x"] = 1, ["meta"] = {["fields"] = {}, ["inventory"] = {}}, ["y"] = 22, ["z"] = 7, ["name"] = "default:obsidianbrick"}, {["x"] = 1, ["meta"] = {["fields"] = {}, ["inventory"] = {}}, ["y"] = 22, ["z"] = 10, ["name"] = "default:obsidianbrick"}, {["x"] = 1, ["meta"] = {["fields"] = {}, ["inventory"] = {}}, ["y"] = 23, ["z"] = 7, ["name"] = "default:obsidianbrick"}, {["x"] = 1, ["meta"] = {["fields"] = {}, ["inventory"] = {}}, ["y"] = 23, ["z"] = 10, ["name"] = "default:obsidianbrick"}, {["x"] = 1, ["meta"] = {["fields"] = {}, ["inventory"] = {}}, ["y"] = 24, ["z"] = 7, ["name"] = "default:obsidianbrick"}, {["x"] = 1, ["meta"] = {["fields"] = {}, ["inventory"] = {}}, ["y"] = 24, ["z"] = 10, ["name"] = "default:obsidianbrick"}, {["x"] = 1, ["meta"] = {["fields"] = {}, ["inventory"] = {}}, ["y"] = 35, ["z"] = 7, ["name"] = "default:obsidianbrick"}, {["x"] = 1, ["meta"] = {["fields"] = {}, ["inventory"] = {}}, ["y"] = 35, ["z"] = 10, ["name"] = "default:obsidianbrick"}, {["x"] = 1, ["meta"] = {["fields"] = {}, ["inventory"] = {}}, ["y"] = 36, ["z"] = 7, ["name"] = "default:obsidianbrick"}, {["x"] = 1, ["meta"] = {["fields"] = {}, ["inventory"] = {}}, ["y"] = 36, ["z"] = 10, ["name"] = "default:obsidianbrick"}, {["x"] = 1, ["meta"] = {["fields"] = {}, ["inventory"] = {}}, ["y"] = 37, ["z"] = 7, ["name"] = "default:obsidianbrick"}, {["x"] = 1, ["meta"] = {["fields"] = {}, ["inventory"] = {}}, ["y"] = 37, ["z"] = 10, ["name"] = "default:obsidianbrick"}, {["x"] = 1, ["meta"] = {["fields"] = {}, ["inventory"] = {}}, ["y"] = 38, ["z"] = 7, ["name"] = "default:obsidianbrick"}, {["x"] = 1, ["meta"] = {["fields"] = {}, ["inventory"] = {}}, ["y"] = 38, ["z"] = 10, ["name"] = "default:obsidianbrick"}, {["x"] = 1, ["meta"] = {["fields"] = {}, ["inventory"] = {}}, ["y"] = 39, ["z"] = 7, ["name"] = "default:obsidianbrick"}, {["x"] = 1, ["meta"] = {["fields"] = {}, ["inventory"] = {}}, ["y"] = 39, ["z"] = 10, ["name"] = "default:obsidianbrick"}, {["x"] = 1, ["meta"] = {["fields"] = {}, ["inventory"] = {}}, ["y"] = 40, ["z"] = 7, ["name"] = "default:obsidianbrick"}, {["x"] = 1, ["meta"] = {["fields"] = {}, ["inventory"] = {}}, ["y"] = 40, ["z"] = 10, ["name"] = "default:obsidianbrick"}, {["x"] = 1, ["meta"] = {["fields"] = {}, ["inventory"] = {}}, ["y"] = 41, ["z"] = 7, ["name"] = "default:obsidianbrick"}, {["x"] = 1, ["meta"] = {["fields"] = {}, ["inventory"] = {}}, ["y"] = 41, ["z"] = 10, ["name"] = "default:obsidianbrick"}, {["x"] = 1, ["meta"] = {["fields"] = {}, ["inventory"] = {}}, ["y"] = 42, ["z"] = 7, ["name"] = "default:obsidianbrick"}, {["x"] = 1, ["meta"] = {["fields"] = {}, ["inventory"] = {}}, ["y"] = 42, ["z"] = 10, ["name"] = "default:obsidianbrick"}, {["x"] = 1, ["meta"] = {["fields"] = {}, ["inventory"] = {}}, ["y"] = 43, ["z"] = 7, ["name"] = "default:obsidianbrick"}, {["x"] = 1, ["meta"] = {["fields"] = {}, ["inventory"] = {}}, ["y"] = 43, ["z"] = 10, ["name"] = "default:obsidianbrick"}, {["x"] = 1, ["meta"] = {["fields"] = {}, ["inventory"] = {}}, ["y"] = 44, ["z"] = 7, ["name"] = "default:obsidianbrick"}, {["x"] = 1, ["meta"] = {["fields"] = {}, ["inventory"] = {}}, ["y"] = 44, ["z"] = 10, ["name"] = "default:obsidianbrick"}, {["x"] = 1, ["meta"] = {["fields"] = {}, ["inventory"] = {}}, ["y"] = 45, ["z"] = 7, ["name"] = "default:obsidianbrick"}, {["x"] = 1, ["meta"] = {["fields"] = {}, ["inventory"] = {}}, ["y"] = 45, ["z"] = 10, ["name"] = "default:obsidianbrick"}, {["x"] = 1, ["meta"] = {["fields"] = {}, ["inventory"] = {}}, ["y"] = 46, ["z"] = 7, ["name"] = "default:obsidianbrick"}, {["x"] = 1, ["meta"] = {["fields"] = {}, ["inventory"] = {}}, ["y"] = 46, ["z"] = 10, ["name"] = "default:obsidianbrick"}, {["x"] = 1, ["meta"] = {["fields"] = {}, ["inventory"] = {}}, ["y"] = 47, ["z"] = 7, ["name"] = "default:obsidianbrick"}, {["x"] = 1, ["meta"] = {["fields"] = {}, ["inventory"] = {}}, ["y"] = 47, ["z"] = 10, ["name"] = "default:obsidianbrick"}, {["x"] = 1, ["meta"] = {["fields"] = {}, ["inventory"] = {}}, ["y"] = 48, ["z"] = 7, ["name"] = "default:obsidianbrick"}, {["x"] = 1, ["meta"] = {["fields"] = {}, ["inventory"] = {}}, ["y"] = 48, ["z"] = 10, ["name"] = "default:obsidianbrick"}, {["x"] = 1, ["meta"] = {["fields"] = {}, ["inventory"] = {}}, ["y"] = 49, ["z"] = 7, ["name"] = "default:obsidianbrick"}, {["x"] = 1, ["meta"] = {["fields"] = {}, ["inventory"] = {}}, ["y"] = 49, ["z"] = 10, ["name"] = "default:obsidianbrick"}, {["x"] = 1, ["meta"] = {["fields"] = {}, ["inventory"] = {}}, ["y"] = 50, ["z"] = 7, ["name"] = "default:obsidianbrick"}, {["x"] = 1, ["meta"] = {["fields"] = {}, ["inventory"] = {}}, ["y"] = 50, ["z"] = 10, ["name"] = "default:obsidianbrick"}, {["x"] = 1, ["meta"] = {["fields"] = {}, ["inventory"] = {}}, ["y"] = 51, ["z"] = 7, ["name"] = "default:obsidianbrick"}, {["x"] = 1, ["meta"] = {["fields"] = {}, ["inventory"] = {}}, ["y"] = 51, ["z"] = 10, ["name"] = "default:obsidianbrick"}, {["x"] = 2, ["meta"] = {["fields"] = {}, ["inventory"] = {}}, ["y"] = 0, ["z"] = 0, ["name"] = "default:dirt"}, {["x"] = 2, ["meta"] = {["fields"] = {}, ["inventory"] = {}}, ["y"] = 0, ["z"] = 1, ["name"] = "default:dirt"}, {["x"] = 2, ["meta"] = {["fields"] = {}, ["inventory"] = {}}, ["y"] = 0, ["z"] = 2, ["name"] = "default:dirt"}, {["x"] = 2, ["meta"] = {["fields"] = {}, ["inventory"] = {}}, ["y"] = 0, ["z"] = 3, ["name"] = "default:dirt"}, {["x"] = 2, ["meta"] = {["fields"] = {}, ["inventory"] = {}}, ["y"] = 0, ["z"] = 4, ["name"] = "default:dirt"}, {["x"] = 2, ["meta"] = {["fields"] = {}, ["inventory"] = {}}, ["y"] = 0, ["z"] = 5, ["name"] = "default:dirt"}, {["x"] = 2, ["meta"] = {["fields"] = {}, ["inventory"] = {}}, ["y"] = 0, ["z"] = 6, ["name"] = "default:dirt"}, {["x"] = 2, ["meta"] = {["fields"] = {}, ["inventory"] = {}}, ["y"] = 0, ["z"] = 7, ["name"] = "default:dirt"}, {["x"] = 2, ["meta"] = {["fields"] = {}, ["inventory"] = {}}, ["y"] = 0, ["z"] = 8, ["name"] = "default:dirt"}, {["x"] = 2, ["meta"] = {["fields"] = {}, ["inventory"] = {}}, ["y"] = 0, ["z"] = 9, ["name"] = "default:dirt"}, {["x"] = 2, ["meta"] = {["fields"] = {}, ["inventory"] = {}}, ["y"] = 0, ["z"] = 10, ["name"] = "default:dirt"}, {["x"] = 2, ["meta"] = {["fields"] = {}, ["inventory"] = {}}, ["y"] = 0, ["z"] = 11, ["name"] = "default:dirt"}, {["x"] = 2, ["meta"] = {["fields"] = {}, ["inventory"] = {}}, ["y"] = 0, ["z"] = 12, ["name"] = "default:dirt"}, {["x"] = 2, ["meta"] = {["fields"] = {}, ["inventory"] = {}}, ["y"] = 0, ["z"] = 13, ["name"] = "default:dirt"}, {["x"] = 2, ["meta"] = {["fields"] = {}, ["inventory"] = {}}, ["y"] = 0, ["z"] = 14, ["name"] = "default:dirt"}, {["x"] = 2, ["meta"] = {["fields"] = {}, ["inventory"] = {}}, ["y"] = 0, ["z"] = 15, ["name"] = "default:obsidianbrick"}, {["x"] = 2, ["meta"] = {["fields"] = {}, ["inventory"] = {}}, ["y"] = 1, ["z"] = 0, ["name"] = "default:dirt_with_grass"}, {["x"] = 2, ["meta"] = {["fields"] = {}, ["inventory"] = {}}, ["y"] = 1, ["z"] = 1, ["name"] = "default:dirt_with_grass"}, {["x"] = 2, ["meta"] = {["fields"] = {}, ["inventory"] = {}}, ["y"] = 1, ["z"] = 2, ["name"] = "default:dirt"}, {["x"] = 2, ["meta"] = {["fields"] = {}, ["inventory"] = {}}, ["y"] = 1, ["z"] = 3, ["name"] = "default:dirt"}, {["x"] = 2, ["meta"] = {["fields"] = {}, ["inventory"] = {}}, ["y"] = 1, ["z"] = 4, ["name"] = "default:dirt"}, {["x"] = 2, ["meta"] = {["fields"] = {}, ["inventory"] = {}}, ["y"] = 1, ["z"] = 5, ["name"] = "default:dirt"}, {["x"] = 2, ["meta"] = {["fields"] = {}, ["inventory"] = {}}, ["y"] = 1, ["z"] = 6, ["name"] = "default:dirt"}, {["x"] = 2, ["meta"] = {["fields"] = {}, ["inventory"] = {}}, ["y"] = 1, ["z"] = 7, ["name"] = "default:dirt"}, {["x"] = 2, ["meta"] = {["fields"] = {}, ["inventory"] = {}}, ["y"] = 1, ["z"] = 8, ["name"] = "default:dirt"}, {["x"] = 2, ["meta"] = {["fields"] = {}, ["inventory"] = {}}, ["y"] = 1, ["z"] = 9, ["name"] = "default:dirt"}, {["x"] = 2, ["meta"] = {["fields"] = {}, ["inventory"] = {}}, ["y"] = 1, ["z"] = 10, ["name"] = "default:dirt"}, {["x"] = 2, ["meta"] = {["fields"] = {}, ["inventory"] = {}}, ["y"] = 1, ["z"] = 11, ["name"] = "default:dirt"}, {["x"] = 2, ["meta"] = {["fields"] = {}, ["inventory"] = {}}, ["y"] = 1, ["z"] = 12, ["name"] = "default:dirt"}, {["x"] = 2, ["meta"] = {["fields"] = {}, ["inventory"] = {}}, ["y"] = 1, ["z"] = 13, ["name"] = "default:dirt"}, {["x"] = 2, ["meta"] = {["fields"] = {}, ["inventory"] = {}}, ["y"] = 1, ["z"] = 14, ["name"] = "default:obsidianbrick"}, {["x"] = 2, ["meta"] = {["fields"] = {}, ["inventory"] = {}}, ["y"] = 1, ["z"] = 15, ["name"] = "default:obsidianbrick"}, {["x"] = 2, ["meta"] = {["fields"] = {}, ["inventory"] = {}}, ["y"] = 2, ["z"] = 2, ["name"] = "default:obsidianbrick"}, {["x"] = 2, ["meta"] = {["fields"] = {}, ["inventory"] = {}}, ["y"] = 2, ["z"] = 3, ["name"] = "default:obsidianbrick"}, {["x"] = 2, ["meta"] = {["fields"] = {}, ["inventory"] = {}}, ["y"] = 2, ["z"] = 4, ["name"] = "default:obsidianbrick"}, {["x"] = 2, ["meta"] = {["fields"] = {}, ["inventory"] = {}}, ["y"] = 2, ["z"] = 5, ["name"] = "default:obsidianbrick"}, {["x"] = 2, ["meta"] = {["fields"] = {}, ["inventory"] = {}}, ["y"] = 2, ["z"] = 6, ["name"] = "default:obsidianbrick"}, {["x"] = 2, ["meta"] = {["fields"] = {}, ["inventory"] = {}}, ["y"] = 2, ["z"] = 7, ["name"] = "default:obsidianbrick"}, {["x"] = 2, ["meta"] = {["fields"] = {}, ["inventory"] = {}}, ["y"] = 2, ["z"] = 8, ["name"] = "default:obsidianbrick"}, {["x"] = 2, ["meta"] = {["fields"] = {}, ["inventory"] = {}}, ["y"] = 2, ["z"] = 9, ["name"] = "default:obsidianbrick"}, {["x"] = 2, ["meta"] = {["fields"] = {}, ["inventory"] = {}}, ["y"] = 2, ["z"] = 10, ["name"] = "default:obsidianbrick"}, {["x"] = 2, ["meta"] = {["fields"] = {}, ["inventory"] = {}}, ["y"] = 2, ["z"] = 11, ["name"] = "default:obsidianbrick"}, {["x"] = 2, ["meta"] = {["fields"] = {}, ["inventory"] = {}}, ["y"] = 2, ["z"] = 12, ["name"] = "default:obsidianbrick"}, {["x"] = 2, ["meta"] = {["fields"] = {}, ["inventory"] = {}}, ["y"] = 2, ["z"] = 13, ["name"] = "default:obsidianbrick"}, {["x"] = 2, ["meta"] = {["fields"] = {}, ["inventory"] = {}}, ["y"] = 2, ["z"] = 14, ["name"] = "default:obsidianbrick"}, {["x"] = 2, ["meta"] = {["fields"] = {}, ["inventory"] = {}}, ["y"] = 2, ["z"] = 15, ["name"] = "default:obsidianbrick"}, {["x"] = 2, ["meta"] = {["fields"] = {}, ["inventory"] = {}}, ["y"] = 21, ["z"] = 7, ["name"] = "default:obsidianbrick"}, {["x"] = 2, ["meta"] = {["fields"] = {}, ["inventory"] = {}}, ["y"] = 21, ["z"] = 10, ["name"] = "default:obsidianbrick"}, {["x"] = 2, ["meta"] = {["fields"] = {}, ["inventory"] = {}}, ["y"] = 22, ["z"] = 7, ["name"] = "default:obsidianbrick"}, {["x"] = 2, ["meta"] = {["fields"] = {}, ["inventory"] = {}}, ["y"] = 22, ["z"] = 10, ["name"] = "default:obsidianbrick"}, {["x"] = 2, ["meta"] = {["fields"] = {}, ["inventory"] = {}}, ["y"] = 23, ["z"] = 7, ["name"] = "default:obsidianbrick"}, {["x"] = 2, ["meta"] = {["fields"] = {}, ["inventory"] = {}}, ["y"] = 23, ["z"] = 10, ["name"] = "default:obsidianbrick"}, {["x"] = 2, ["meta"] = {["fields"] = {}, ["inventory"] = {}}, ["y"] = 34, ["z"] = 10, ["name"] = "default:obsidianbrick"}, {["x"] = 2, ["meta"] = {["fields"] = {}, ["inventory"] = {}}, ["y"] = 35, ["z"] = 7, ["name"] = "default:obsidianbrick"}, {["x"] = 2, ["meta"] = {["fields"] = {}, ["inventory"] = {}}, ["y"] = 35, ["z"] = 10, ["name"] = "default:obsidianbrick"}, {["x"] = 2, ["meta"] = {["fields"] = {}, ["inventory"] = {}}, ["y"] = 36, ["z"] = 7, ["name"] = "default:obsidianbrick"}, {["x"] = 2, ["meta"] = {["fields"] = {}, ["inventory"] = {}}, ["y"] = 36, ["z"] = 10, ["name"] = "default:obsidianbrick"}, {["x"] = 2, ["meta"] = {["fields"] = {}, ["inventory"] = {}}, ["y"] = 37, ["z"] = 7, ["name"] = "default:obsidianbrick"}, {["x"] = 2, ["meta"] = {["fields"] = {}, ["inventory"] = {}}, ["y"] = 37, ["z"] = 10, ["name"] = "default:obsidianbrick"}, {["x"] = 2, ["meta"] = {["fields"] = {}, ["inventory"] = {}}, ["y"] = 38, ["z"] = 7, ["name"] = "default:obsidianbrick"}, {["x"] = 2, ["meta"] = {["fields"] = {}, ["inventory"] = {}}, ["y"] = 38, ["z"] = 10, ["name"] = "default:obsidianbrick"}, {["x"] = 2, ["meta"] = {["fields"] = {}, ["inventory"] = {}}, ["y"] = 39, ["z"] = 7, ["name"] = "default:obsidianbrick"}, {["x"] = 2, ["meta"] = {["fields"] = {}, ["inventory"] = {}}, ["y"] = 39, ["z"] = 10, ["name"] = "default:obsidianbrick"}, {["x"] = 3, ["meta"] = {["fields"] = {}, ["inventory"] = {}}, ["y"] = 0, ["z"] = 0, ["name"] = "default:dirt"}, {["x"] = 3, ["meta"] = {["fields"] = {}, ["inventory"] = {}}, ["y"] = 0, ["z"] = 1, ["name"] = "default:dirt"}, {["x"] = 3, ["meta"] = {["fields"] = {}, ["inventory"] = {}}, ["y"] = 0, ["z"] = 2, ["name"] = "default:dirt"}, {["x"] = 3, ["meta"] = {["fields"] = {}, ["inventory"] = {}}, ["y"] = 0, ["z"] = 3, ["name"] = "default:dirt"}, {["x"] = 3, ["meta"] = {["fields"] = {}, ["inventory"] = {}}, ["y"] = 0, ["z"] = 4, ["name"] = "default:dirt"}, {["x"] = 3, ["meta"] = {["fields"] = {}, ["inventory"] = {}}, ["y"] = 0, ["z"] = 5, ["name"] = "default:dirt"}, {["x"] = 3, ["meta"] = {["fields"] = {}, ["inventory"] = {}}, ["y"] = 0, ["z"] = 6, ["name"] = "default:dirt"}, {["x"] = 3, ["meta"] = {["fields"] = {}, ["inventory"] = {}}, ["y"] = 0, ["z"] = 7, ["name"] = "default:dirt"}, {["x"] = 3, ["meta"] = {["fields"] = {}, ["inventory"] = {}}, ["y"] = 0, ["z"] = 8, ["name"] = "default:dirt"}, {["x"] = 3, ["meta"] = {["fields"] = {}, ["inventory"] = {}}, ["y"] = 0, ["z"] = 9, ["name"] = "default:dirt"}, {["x"] = 3, ["meta"] = {["fields"] = {}, ["inventory"] = {}}, ["y"] = 0, ["z"] = 10, ["name"] = "default:dirt"}, {["x"] = 3, ["meta"] = {["fields"] = {}, ["inventory"] = {}}, ["y"] = 0, ["z"] = 11, ["name"] = "default:dirt"}, {["x"] = 3, ["meta"] = {["fields"] = {}, ["inventory"] = {}}, ["y"] = 0, ["z"] = 12, ["name"] = "default:dirt"}, {["x"] = 3, ["meta"] = {["fields"] = {}, ["inventory"] = {}}, ["y"] = 0, ["z"] = 13, ["name"] = "default:dirt"}, {["x"] = 3, ["meta"] = {["fields"] = {}, ["inventory"] = {}}, ["y"] = 0, ["z"] = 14, ["name"] = "default:dirt"}, {["x"] = 3, ["meta"] = {["fields"] = {}, ["inventory"] = {}}, ["y"] = 0, ["z"] = 15, ["name"] = "default:dirt"}, {["x"] = 3, ["meta"] = {["fields"] = {}, ["inventory"] = {}}, ["y"] = 1, ["z"] = 0, ["name"] = "default:dirt_with_grass"}, {["x"] = 3, ["meta"] = {["fields"] = {}, ["inventory"] = {}}, ["y"] = 1, ["z"] = 1, ["name"] = "default:dirt_with_grass"}, {["x"] = 3, ["meta"] = {["fields"] = {}, ["inventory"] = {}}, ["y"] = 1, ["z"] = 2, ["name"] = "default:dirt"}, {["x"] = 3, ["meta"] = {["fields"] = {}, ["inventory"] = {}}, ["y"] = 1, ["z"] = 3, ["name"] = "default:dirt"}, {["x"] = 3, ["meta"] = {["fields"] = {}, ["inventory"] = {}}, ["y"] = 1, ["z"] = 4, ["name"] = "default:dirt"}, {["x"] = 3, ["meta"] = {["fields"] = {}, ["inventory"] = {}}, ["y"] = 1, ["z"] = 5, ["name"] = "default:dirt"}, {["x"] = 3, ["meta"] = {["fields"] = {}, ["inventory"] = {}}, ["y"] = 1, ["z"] = 6, ["name"] = "default:dirt"}, {["x"] = 3, ["meta"] = {["fields"] = {}, ["inventory"] = {}}, ["y"] = 1, ["z"] = 7, ["name"] = "default:dirt"}, {["x"] = 3, ["meta"] = {["fields"] = {}, ["inventory"] = {}}, ["y"] = 1, ["z"] = 8, ["name"] = "default:dirt"}, {["x"] = 3, ["meta"] = {["fields"] = {}, ["inventory"] = {}}, ["y"] = 1, ["z"] = 9, ["name"] = "default:dirt"}, {["x"] = 3, ["meta"] = {["fields"] = {}, ["inventory"] = {}}, ["y"] = 1, ["z"] = 10, ["name"] = "default:dirt"}, {["x"] = 3, ["meta"] = {["fields"] = {}, ["inventory"] = {}}, ["y"] = 1, ["z"] = 11, ["name"] = "default:dirt"}, {["x"] = 3, ["meta"] = {["fields"] = {}, ["inventory"] = {}}, ["y"] = 1, ["z"] = 12, ["name"] = "default:dirt"}, {["x"] = 3, ["meta"] = {["fields"] = {}, ["inventory"] = {}}, ["y"] = 1, ["z"] = 13, ["name"] = "default:dirt"}, {["x"] = 3, ["meta"] = {["fields"] = {}, ["inventory"] = {}}, ["y"] = 1, ["z"] = 14, ["name"] = "default:dirt"}, {["x"] = 3, ["meta"] = {["fields"] = {}, ["inventory"] = {}}, ["y"] = 1, ["z"] = 15, ["name"] = "default:obsidianbrick"}, {["x"] = 3, ["meta"] = {["fields"] = {}, ["inventory"] = {}}, ["y"] = 2, ["z"] = 2, ["name"] = "default:obsidianbrick"}, {["x"] = 3, ["meta"] = {["fields"] = {}, ["inventory"] = {}}, ["param2"] = 3, ["y"] = 2, ["z"] = 3, ["name"] = "default:lava_flowing"}, {["x"] = 3, ["meta"] = {["fields"] = {}, ["inventory"] = {}}, ["param2"] = 4, ["y"] = 2, ["z"] = 4, ["name"] = "default:lava_flowing"}, {["x"] = 3, ["meta"] = {["fields"] = {}, ["inventory"] = {}}, ["param2"] = 5, ["y"] = 2, ["z"] = 5, ["name"] = "default:lava_flowing"}, {["x"] = 3, ["meta"] = {["fields"] = {}, ["inventory"] = {}}, ["param2"] = 6, ["y"] = 2, ["z"] = 6, ["name"] = "default:lava_flowing"}, {["x"] = 3, ["meta"] = {["fields"] = {}, ["inventory"] = {}}, ["param2"] = 5, ["y"] = 2, ["z"] = 7, ["name"] = "default:lava_flowing"}, {["x"] = 3, ["meta"] = {["fields"] = {}, ["inventory"] = {}}, ["y"] = 2, ["z"] = 8, ["name"] = "default:obsidianbrick"}, {["x"] = 3, ["meta"] = {["fields"] = {}, ["inventory"] = {}}, ["y"] = 2, ["z"] = 9, ["name"] = "default:dirt"}, {["x"] = 3, ["meta"] = {["fields"] = {}, ["inventory"] = {}}, ["param2"] = 5, ["y"] = 2, ["z"] = 10, ["name"] = "default:lava_flowing"}, {["x"] = 3, ["meta"] = {["fields"] = {}, ["inventory"] = {}}, ["param2"] = 6, ["y"] = 2, ["z"] = 11, ["name"] = "default:lava_flowing"}, {["x"] = 3, ["meta"] = {["fields"] = {}, ["inventory"] = {}}, ["param2"] = 5, ["y"] = 2, ["z"] = 12, ["name"] = "default:lava_flowing"}, {["x"] = 3, ["meta"] = {["fields"] = {}, ["inventory"] = {}}, ["param2"] = 4, ["y"] = 2, ["z"] = 13, ["name"] = "default:lava_flowing"}, {["x"] = 3, ["meta"] = {["fields"] = {}, ["inventory"] = {}}, ["param2"] = 3, ["y"] = 2, ["z"] = 14, ["name"] = "default:lava_flowing"}, {["x"] = 3, ["meta"] = {["fields"] = {}, ["inventory"] = {}}, ["y"] = 2, ["z"] = 15, ["name"] = "default:obsidianbrick"}, {["x"] = 3, ["meta"] = {["fields"] = {}, ["inventory"] = {}}, ["y"] = 3, ["z"] = 8, ["name"] = "default:obsidian"}, {["x"] = 3, ["meta"] = {["fields"] = {}, ["inventory"] = {}}, ["y"] = 3, ["z"] = 9, ["name"] = "default:obsidian"}, {["x"] = 3, ["meta"] = {["fields"] = {}, ["inventory"] = {}}, ["y"] = 4, ["z"] = 8, ["name"] = "default:obsidian"}, {["x"] = 3, ["meta"] = {["fields"] = {}, ["inventory"] = {}}, ["y"] = 4, ["z"] = 9, ["name"] = "default:obsidian"}, {["x"] = 3, ["meta"] = {["fields"] = {}, ["inventory"] = {}}, ["y"] = 5, ["z"] = 8, ["name"] = "default:obsidianbrick"}, {["x"] = 3, ["meta"] = {["fields"] = {}, ["inventory"] = {}}, ["y"] = 5, ["z"] = 9, ["name"] = "default:obsidianbrick"}, {["x"] = 3, ["meta"] = {["fields"] = {}, ["inventory"] = {}}, ["y"] = 6, ["z"] = 8, ["name"] = "default:obsidianbrick"}, {["x"] = 3, ["meta"] = {["fields"] = {}, ["inventory"] = {}}, ["y"] = 6, ["z"] = 9, ["name"] = "default:obsidianbrick"}, {["x"] = 3, ["meta"] = {["fields"] = {}, ["inventory"] = {}}, ["y"] = 7, ["z"] = 8, ["name"] = "default:obsidianbrick"}, {["x"] = 3, ["meta"] = {["fields"] = {}, ["inventory"] = {}}, ["y"] = 7, ["z"] = 9, ["name"] = "default:obsidianbrick"}, {["x"] = 3, ["meta"] = {["fields"] = {}, ["inventory"] = {}}, ["y"] = 8, ["z"] = 8, ["name"] = "default:obsidianbrick"}, {["x"] = 3, ["meta"] = {["fields"] = {}, ["inventory"] = {}}, ["y"] = 8, ["z"] = 9, ["name"] = "default:obsidianbrick"}, {["x"] = 3, ["meta"] = {["fields"] = {}, ["inventory"] = {}}, ["y"] = 9, ["z"] = 8, ["name"] = "default:obsidianbrick"}, {["x"] = 3, ["meta"] = {["fields"] = {}, ["inventory"] = {}}, ["y"] = 9, ["z"] = 9, ["name"] = "default:obsidianbrick"}, {["x"] = 3, ["meta"] = {["fields"] = {}, ["inventory"] = {}}, ["y"] = 10, ["z"] = 8, ["name"] = "default:obsidianbrick"}, {["x"] = 3, ["meta"] = {["fields"] = {}, ["inventory"] = {}}, ["y"] = 10, ["z"] = 9, ["name"] = "default:obsidianbrick"}, {["x"] = 3, ["meta"] = {["fields"] = {}, ["inventory"] = {}}, ["y"] = 11, ["z"] = 8, ["name"] = "default:obsidianbrick"}, {["x"] = 3, ["meta"] = {["fields"] = {}, ["inventory"] = {}}, ["y"] = 11, ["z"] = 9, ["name"] = "default:obsidianbrick"}, {["x"] = 3, ["meta"] = {["fields"] = {}, ["inventory"] = {}}, ["y"] = 12, ["z"] = 8, ["name"] = "default:obsidianbrick"}, {["x"] = 3, ["meta"] = {["fields"] = {}, ["inventory"] = {}}, ["y"] = 12, ["z"] = 9, ["name"] = "default:obsidianbrick"}, {["x"] = 3, ["meta"] = {["fields"] = {}, ["inventory"] = {}}, ["y"] = 13, ["z"] = 8, ["name"] = "default:obsidianbrick"}, {["x"] = 3, ["meta"] = {["fields"] = {}, ["inventory"] = {}}, ["y"] = 13, ["z"] = 9, ["name"] = "default:obsidianbrick"}, {["x"] = 3, ["meta"] = {["fields"] = {}, ["inventory"] = {}}, ["y"] = 14, ["z"] = 8, ["name"] = "default:obsidianbrick"}, {["x"] = 3, ["meta"] = {["fields"] = {}, ["inventory"] = {}}, ["y"] = 14, ["z"] = 9, ["name"] = "default:obsidianbrick"}, {["x"] = 3, ["meta"] = {["fields"] = {}, ["inventory"] = {}}, ["y"] = 15, ["z"] = 8, ["name"] = "default:obsidianbrick"}, {["x"] = 3, ["meta"] = {["fields"] = {}, ["inventory"] = {}}, ["y"] = 15, ["z"] = 9, ["name"] = "default:obsidianbrick"}, {["x"] = 3, ["meta"] = {["fields"] = {}, ["inventory"] = {}}, ["y"] = 16, ["z"] = 8, ["name"] = "default:obsidianbrick"}, {["x"] = 3, ["meta"] = {["fields"] = {}, ["inventory"] = {}}, ["y"] = 16, ["z"] = 9, ["name"] = "default:obsidianbrick"}, {["x"] = 3, ["meta"] = {["fields"] = {}, ["inventory"] = {}}, ["y"] = 17, ["z"] = 8, ["name"] = "default:obsidianbrick"}, {["x"] = 3, ["meta"] = {["fields"] = {}, ["inventory"] = {}}, ["y"] = 17, ["z"] = 9, ["name"] = "default:obsidianbrick"}, {["x"] = 3, ["meta"] = {["fields"] = {}, ["inventory"] = {}}, ["y"] = 18, ["z"] = 8, ["name"] = "default:obsidianbrick"}, {["x"] = 3, ["meta"] = {["fields"] = {}, ["inventory"] = {}}, ["y"] = 18, ["z"] = 9, ["name"] = "default:obsidianbrick"}, {["x"] = 3, ["meta"] = {["fields"] = {}, ["inventory"] = {}}, ["y"] = 19, ["z"] = 7, ["name"] = "default:obsidianbrick"}, {["x"] = 3, ["meta"] = {["fields"] = {}, ["inventory"] = {}}, ["y"] = 19, ["z"] = 8, ["name"] = "default:obsidianbrick"}, {["x"] = 3, ["meta"] = {["fields"] = {}, ["inventory"] = {}}, ["y"] = 19, ["z"] = 9, ["name"] = "default:obsidianbrick"}, {["x"] = 3, ["meta"] = {["fields"] = {}, ["inventory"] = {}}, ["y"] = 19, ["z"] = 10, ["name"] = "default:obsidianbrick"}, {["x"] = 3, ["meta"] = {["fields"] = {}, ["inventory"] = {}}, ["y"] = 20, ["z"] = 7, ["name"] = "default:obsidianbrick"}, {["x"] = 3, ["meta"] = {["fields"] = {}, ["inventory"] = {}}, ["y"] = 20, ["z"] = 8, ["name"] = "default:obsidianbrick"}, {["x"] = 3, ["meta"] = {["fields"] = {}, ["inventory"] = {}}, ["y"] = 20, ["z"] = 9, ["name"] = "default:obsidianbrick"}, {["x"] = 3, ["meta"] = {["fields"] = {}, ["inventory"] = {}}, ["y"] = 20, ["z"] = 10, ["name"] = "default:obsidianbrick"}, {["x"] = 3, ["meta"] = {["fields"] = {}, ["inventory"] = {}}, ["y"] = 21, ["z"] = 7, ["name"] = "default:obsidianbrick"}, {["x"] = 3, ["meta"] = {["fields"] = {}, ["inventory"] = {}}, ["y"] = 21, ["z"] = 8, ["name"] = "default:obsidianbrick"}, {["x"] = 3, ["meta"] = {["fields"] = {}, ["inventory"] = {}}, ["y"] = 21, ["z"] = 9, ["name"] = "default:obsidianbrick"}, {["x"] = 3, ["meta"] = {["fields"] = {}, ["inventory"] = {}}, ["y"] = 21, ["z"] = 10, ["name"] = "default:obsidianbrick"}, {["x"] = 3, ["meta"] = {["fields"] = {}, ["inventory"] = {}}, ["y"] = 22, ["z"] = 7, ["name"] = "default:obsidianbrick"}, {["x"] = 3, ["meta"] = {["fields"] = {}, ["inventory"] = {}}, ["y"] = 22, ["z"] = 8, ["name"] = "default:obsidianbrick"}, {["x"] = 3, ["meta"] = {["fields"] = {}, ["inventory"] = {}}, ["y"] = 22, ["z"] = 9, ["name"] = "default:obsidianbrick"}, {["x"] = 3, ["meta"] = {["fields"] = {}, ["inventory"] = {}}, ["y"] = 22, ["z"] = 10, ["name"] = "default:obsidianbrick"}, {["x"] = 3, ["meta"] = {["fields"] = {}, ["inventory"] = {}}, ["y"] = 23, ["z"] = 8, ["name"] = "default:obsidianbrick"}, {["x"] = 3, ["meta"] = {["fields"] = {}, ["inventory"] = {}}, ["y"] = 23, ["z"] = 9, ["name"] = "default:obsidianbrick"}, {["x"] = 3, ["meta"] = {["fields"] = {}, ["inventory"] = {}}, ["y"] = 24, ["z"] = 8, ["name"] = "default:obsidianbrick"}, {["x"] = 3, ["meta"] = {["fields"] = {}, ["inventory"] = {}}, ["y"] = 24, ["z"] = 9, ["name"] = "default:obsidianbrick"}, {["x"] = 3, ["meta"] = {["fields"] = {}, ["inventory"] = {}}, ["y"] = 25, ["z"] = 8, ["name"] = "default:obsidianbrick"}, {["x"] = 3, ["meta"] = {["fields"] = {}, ["inventory"] = {}}, ["y"] = 25, ["z"] = 9, ["name"] = "default:obsidianbrick"}, {["x"] = 3, ["meta"] = {["fields"] = {}, ["inventory"] = {}}, ["y"] = 26, ["z"] = 8, ["name"] = "default:obsidianbrick"}, {["x"] = 3, ["meta"] = {["fields"] = {}, ["inventory"] = {}}, ["y"] = 26, ["z"] = 9, ["name"] = "default:obsidianbrick"}, {["x"] = 3, ["meta"] = {["fields"] = {}, ["inventory"] = {}}, ["y"] = 27, ["z"] = 8, ["name"] = "default:obsidianbrick"}, {["x"] = 3, ["meta"] = {["fields"] = {}, ["inventory"] = {}}, ["y"] = 27, ["z"] = 9, ["name"] = "default:obsidianbrick"}, {["x"] = 3, ["meta"] = {["fields"] = {}, ["inventory"] = {}}, ["y"] = 28, ["z"] = 8, ["name"] = "default:obsidianbrick"}, {["x"] = 3, ["meta"] = {["fields"] = {}, ["inventory"] = {}}, ["y"] = 28, ["z"] = 9, ["name"] = "default:obsidianbrick"}, {["x"] = 3, ["meta"] = {["fields"] = {}, ["inventory"] = {}}, ["y"] = 34, ["z"] = 7, ["name"] = "default:obsidianbrick"}, {["x"] = 3, ["meta"] = {["fields"] = {}, ["inventory"] = {}}, ["y"] = 34, ["z"] = 10, ["name"] = "default:obsidianbrick"}, {["x"] = 3, ["meta"] = {["fields"] = {}, ["inventory"] = {}}, ["y"] = 35, ["z"] = 7, ["name"] = "default:obsidianbrick"}, {["x"] = 3, ["meta"] = {["fields"] = {}, ["inventory"] = {}}, ["y"] = 35, ["z"] = 10, ["name"] = "default:obsidianbrick"}, {["x"] = 3, ["meta"] = {["fields"] = {}, ["inventory"] = {}}, ["y"] = 36, ["z"] = 7, ["name"] = "default:obsidianbrick"}, {["x"] = 3, ["meta"] = {["fields"] = {}, ["inventory"] = {}}, ["y"] = 36, ["z"] = 10, ["name"] = "default:obsidianbrick"}, {["x"] = 3, ["meta"] = {["fields"] = {}, ["inventory"] = {}}, ["y"] = 37, ["z"] = 7, ["name"] = "default:obsidianbrick"}, {["x"] = 3, ["meta"] = {["fields"] = {}, ["inventory"] = {}}, ["y"] = 37, ["z"] = 10, ["name"] = "default:obsidianbrick"}, {["x"] = 4, ["meta"] = {["fields"] = {}, ["inventory"] = {}}, ["y"] = 0, ["z"] = 0, ["name"] = "default:dirt"}, {["x"] = 4, ["meta"] = {["fields"] = {}, ["inventory"] = {}}, ["y"] = 0, ["z"] = 1, ["name"] = "default:dirt"}, {["x"] = 4, ["meta"] = {["fields"] = {}, ["inventory"] = {}}, ["y"] = 0, ["z"] = 2, ["name"] = "default:dirt"}, {["x"] = 4, ["meta"] = {["fields"] = {}, ["inventory"] = {}}, ["y"] = 0, ["z"] = 3, ["name"] = "default:dirt"}, {["x"] = 4, ["meta"] = {["fields"] = {}, ["inventory"] = {}}, ["y"] = 0, ["z"] = 4, ["name"] = "default:dirt"}, {["x"] = 4, ["meta"] = {["fields"] = {}, ["inventory"] = {}}, ["y"] = 0, ["z"] = 5, ["name"] = "default:dirt"}, {["x"] = 4, ["meta"] = {["fields"] = {}, ["inventory"] = {}}, ["y"] = 0, ["z"] = 6, ["name"] = "default:dirt"}, {["x"] = 4, ["meta"] = {["fields"] = {}, ["inventory"] = {}}, ["y"] = 0, ["z"] = 7, ["name"] = "default:dirt"}, {["x"] = 4, ["meta"] = {["fields"] = {}, ["inventory"] = {}}, ["y"] = 0, ["z"] = 8, ["name"] = "default:dirt"}, {["x"] = 4, ["meta"] = {["fields"] = {}, ["inventory"] = {}}, ["y"] = 0, ["z"] = 9, ["name"] = "default:dirt"}, {["x"] = 4, ["meta"] = {["fields"] = {}, ["inventory"] = {}}, ["y"] = 0, ["z"] = 10, ["name"] = "default:dirt"}, {["x"] = 4, ["meta"] = {["fields"] = {}, ["inventory"] = {}}, ["y"] = 0, ["z"] = 11, ["name"] = "default:dirt"}, {["x"] = 4, ["meta"] = {["fields"] = {}, ["inventory"] = {}}, ["y"] = 0, ["z"] = 12, ["name"] = "default:dirt"}, {["x"] = 4, ["meta"] = {["fields"] = {}, ["inventory"] = {}}, ["y"] = 0, ["z"] = 13, ["name"] = "default:dirt"}, {["x"] = 4, ["meta"] = {["fields"] = {}, ["inventory"] = {}}, ["y"] = 0, ["z"] = 14, ["name"] = "default:dirt"}, {["x"] = 4, ["meta"] = {["fields"] = {}, ["inventory"] = {}}, ["y"] = 0, ["z"] = 15, ["name"] = "default:dirt"}, {["x"] = 4, ["meta"] = {["fields"] = {}, ["inventory"] = {}}, ["y"] = 1, ["z"] = 0, ["name"] = "default:dirt_with_grass"}, {["x"] = 4, ["meta"] = {["fields"] = {}, ["inventory"] = {}}, ["y"] = 1, ["z"] = 1, ["name"] = "default:dirt_with_grass"}, {["x"] = 4, ["meta"] = {["fields"] = {}, ["inventory"] = {}}, ["y"] = 1, ["z"] = 2, ["name"] = "default:dirt"}, {["x"] = 4, ["meta"] = {["fields"] = {}, ["inventory"] = {}}, ["y"] = 1, ["z"] = 3, ["name"] = "default:dirt"}, {["x"] = 4, ["meta"] = {["fields"] = {}, ["inventory"] = {}}, ["y"] = 1, ["z"] = 4, ["name"] = "default:dirt"}, {["x"] = 4, ["meta"] = {["fields"] = {}, ["inventory"] = {}}, ["y"] = 1, ["z"] = 5, ["name"] = "default:dirt"}, {["x"] = 4, ["meta"] = {["fields"] = {}, ["inventory"] = {}}, ["y"] = 1, ["z"] = 6, ["name"] = "default:dirt"}, {["x"] = 4, ["meta"] = {["fields"] = {}, ["inventory"] = {}}, ["y"] = 1, ["z"] = 7, ["name"] = "default:dirt"}, {["x"] = 4, ["meta"] = {["fields"] = {}, ["inventory"] = {}}, ["y"] = 1, ["z"] = 8, ["name"] = "default:dirt"}, {["x"] = 4, ["meta"] = {["fields"] = {}, ["inventory"] = {}}, ["y"] = 1, ["z"] = 9, ["name"] = "default:dirt"}, {["x"] = 4, ["meta"] = {["fields"] = {}, ["inventory"] = {}}, ["y"] = 1, ["z"] = 10, ["name"] = "default:dirt"}, {["x"] = 4, ["meta"] = {["fields"] = {}, ["inventory"] = {}}, ["y"] = 1, ["z"] = 11, ["name"] = "default:dirt"}, {["x"] = 4, ["meta"] = {["fields"] = {}, ["inventory"] = {}}, ["y"] = 1, ["z"] = 12, ["name"] = "default:dirt"}, {["x"] = 4, ["meta"] = {["fields"] = {}, ["inventory"] = {}}, ["y"] = 1, ["z"] = 13, ["name"] = "default:dirt"}, {["x"] = 4, ["meta"] = {["fields"] = {}, ["inventory"] = {}}, ["y"] = 1, ["z"] = 14, ["name"] = "default:dirt"}, {["x"] = 4, ["meta"] = {["fields"] = {}, ["inventory"] = {}}, ["y"] = 1, ["z"] = 15, ["name"] = "default:obsidianbrick"}, {["x"] = 4, ["meta"] = {["fields"] = {}, ["inventory"] = {}}, ["y"] = 2, ["param1"] = 159, ["z"] = 1, ["name"] = "default:grass_3"}, {["x"] = 4, ["meta"] = {["fields"] = {}, ["inventory"] = {}}, ["y"] = 2, ["z"] = 2, ["name"] = "default:obsidianbrick"}, {["x"] = 4, ["meta"] = {["fields"] = {}, ["inventory"] = {}}, ["param2"] = 4, ["y"] = 2, ["z"] = 3, ["name"] = "default:lava_flowing"}, {["x"] = 4, ["meta"] = {["fields"] = {}, ["inventory"] = {}}, ["param2"] = 5, ["y"] = 2, ["z"] = 4, ["name"] = "default:lava_flowing"}, {["x"] = 4, ["meta"] = {["fields"] = {}, ["inventory"] = {}}, ["param2"] = 6, ["y"] = 2, ["z"] = 5, ["name"] = "default:lava_flowing"}, {["x"] = 4, ["meta"] = {["fields"] = {}, ["inventory"] = {}}, ["param2"] = 7, ["y"] = 2, ["z"] = 6, ["name"] = "default:lava_flowing"}, {["x"] = 4, ["meta"] = {["fields"] = {}, ["inventory"] = {}}, ["y"] = 2, ["z"] = 7, ["name"] = "default:dirt"}, {["x"] = 4, ["meta"] = {["fields"] = {}, ["inventory"] = {}}, ["y"] = 2, ["z"] = 8, ["name"] = "default:dirt"}, {["x"] = 4, ["meta"] = {["fields"] = {}, ["inventory"] = {}}, ["y"] = 2, ["z"] = 9, ["name"] = "default:dirt"}, {["x"] = 4, ["meta"] = {["fields"] = {}, ["inventory"] = {}}, ["y"] = 2, ["z"] = 10, ["name"] = "default:dirt"}, {["x"] = 4, ["meta"] = {["fields"] = {}, ["inventory"] = {}}, ["param2"] = 7, ["y"] = 2, ["z"] = 11, ["name"] = "default:lava_flowing"}, {["x"] = 4, ["meta"] = {["fields"] = {}, ["inventory"] = {}}, ["param2"] = 6, ["y"] = 2, ["z"] = 12, ["name"] = "default:lava_flowing"}, {["x"] = 4, ["meta"] = {["fields"] = {}, ["inventory"] = {}}, ["param2"] = 5, ["y"] = 2, ["z"] = 13, ["name"] = "default:lava_flowing"}, {["x"] = 4, ["meta"] = {["fields"] = {}, ["inventory"] = {}}, ["param2"] = 4, ["y"] = 2, ["z"] = 14, ["name"] = "default:lava_flowing"}, {["x"] = 4, ["meta"] = {["fields"] = {}, ["inventory"] = {}}, ["y"] = 2, ["z"] = 15, ["name"] = "default:obsidianbrick"}, {["x"] = 4, ["meta"] = {["fields"] = {}, ["inventory"] = {}}, ["param2"] = 15, ["y"] = 3, ["z"] = 6, ["name"] = "default:lava_flowing"}, {["x"] = 4, ["meta"] = {["fields"] = {}, ["inventory"] = {}}, ["y"] = 3, ["z"] = 7, ["name"] = "default:obsidian"}, {["x"] = 4, ["meta"] = {["fields"] = {}, ["inventory"] = {}}, ["y"] = 3, ["z"] = 8, ["name"] = "default:obsidian"}, {["x"] = 4, ["meta"] = {["fields"] = {}, ["inventory"] = {}}, ["y"] = 3, ["z"] = 9, ["name"] = "default:obsidian"}, {["x"] = 4, ["meta"] = {["fields"] = {}, ["inventory"] = {}}, ["y"] = 3, ["z"] = 10, ["name"] = "default:obsidian"}, {["x"] = 4, ["meta"] = {["fields"] = {}, ["inventory"] = {}}, ["param2"] = 15, ["y"] = 3, ["z"] = 11, ["name"] = "default:lava_flowing"}, {["x"] = 4, ["meta"] = {["fields"] = {}, ["inventory"] = {}}, ["param2"] = 15, ["y"] = 4, ["z"] = 6, ["name"] = "default:lava_flowing"}, {["x"] = 4, ["meta"] = {["fields"] = {}, ["inventory"] = {}}, ["y"] = 4, ["z"] = 7, ["name"] = "default:obsidian"}, {["x"] = 4, ["meta"] = {["fields"] = {}, ["inventory"] = {}}, ["y"] = 4, ["z"] = 8, ["name"] = "default:obsidian"}, {["x"] = 4, ["meta"] = {["fields"] = {}, ["inventory"] = {}}, ["y"] = 4, ["z"] = 9, ["name"] = "default:obsidian"}, {["x"] = 4, ["meta"] = {["fields"] = {}, ["inventory"] = {}}, ["y"] = 4, ["z"] = 10, ["name"] = "default:obsidian"}, {["x"] = 4, ["meta"] = {["fields"] = {}, ["inventory"] = {}}, ["param2"] = 15, ["y"] = 4, ["z"] = 11, ["name"] = "default:lava_flowing"}, {["x"] = 4, ["meta"] = {["fields"] = {}, ["inventory"] = {}}, ["param2"] = 15, ["y"] = 5, ["z"] = 6, ["name"] = "default:lava_flowing"}, {["x"] = 4, ["meta"] = {["fields"] = {}, ["inventory"] = {}}, ["y"] = 5, ["z"] = 7, ["name"] = "default:obsidianbrick"}, {["x"] = 4, ["meta"] = {["fields"] = {}, ["inventory"] = {}}, ["y"] = 5, ["z"] = 8, ["name"] = "default:obsidianbrick"}, {["x"] = 4, ["meta"] = {["fields"] = {}, ["inventory"] = {}}, ["y"] = 5, ["z"] = 9, ["name"] = "default:obsidianbrick"}, {["x"] = 4, ["meta"] = {["fields"] = {}, ["inventory"] = {}}, ["y"] = 5, ["z"] = 10, ["name"] = "default:obsidianbrick"}, {["x"] = 4, ["meta"] = {["fields"] = {}, ["inventory"] = {}}, ["param2"] = 15, ["y"] = 5, ["z"] = 11, ["name"] = "default:lava_flowing"}, {["x"] = 4, ["meta"] = {["fields"] = {}, ["inventory"] = {}}, ["param2"] = 15, ["y"] = 6, ["z"] = 6, ["name"] = "default:lava_flowing"}, {["x"] = 4, ["meta"] = {["fields"] = {}, ["inventory"] = {}}, ["y"] = 6, ["z"] = 7, ["name"] = "default:obsidianbrick"}, {["x"] = 4, ["meta"] = {["fields"] = {}, ["inventory"] = {}}, ["y"] = 6, ["z"] = 8, ["name"] = "default:obsidianbrick"}, {["x"] = 4, ["meta"] = {["fields"] = {}, ["inventory"] = {}}, ["y"] = 6, ["z"] = 9, ["name"] = "default:obsidianbrick"}, {["x"] = 4, ["meta"] = {["fields"] = {}, ["inventory"] = {}}, ["y"] = 6, ["z"] = 10, ["name"] = "default:obsidianbrick"}, {["x"] = 4, ["meta"] = {["fields"] = {}, ["inventory"] = {}}, ["param2"] = 15, ["y"] = 6, ["z"] = 11, ["name"] = "default:lava_flowing"}, {["x"] = 4, ["meta"] = {["fields"] = {}, ["inventory"] = {}}, ["param2"] = 15, ["y"] = 7, ["z"] = 6, ["name"] = "default:lava_flowing"}, {["x"] = 4, ["meta"] = {["fields"] = {}, ["inventory"] = {}}, ["y"] = 7, ["z"] = 7, ["name"] = "default:obsidianbrick"}, {["x"] = 4, ["meta"] = {["fields"] = {}, ["inventory"] = {}}, ["y"] = 7, ["z"] = 8, ["name"] = "default:obsidianbrick"}, {["x"] = 4, ["meta"] = {["fields"] = {}, ["inventory"] = {}}, ["y"] = 7, ["z"] = 9, ["name"] = "default:obsidianbrick"}, {["x"] = 4, ["meta"] = {["fields"] = {}, ["inventory"] = {}}, ["y"] = 7, ["z"] = 10, ["name"] = "default:obsidianbrick"}, {["x"] = 4, ["meta"] = {["fields"] = {}, ["inventory"] = {}}, ["param2"] = 15, ["y"] = 7, ["z"] = 11, ["name"] = "default:lava_flowing"}, {["x"] = 4, ["meta"] = {["fields"] = {}, ["inventory"] = {}}, ["param2"] = 15, ["y"] = 8, ["z"] = 6, ["name"] = "default:lava_flowing"}, {["x"] = 4, ["meta"] = {["fields"] = {}, ["inventory"] = {}}, ["y"] = 8, ["z"] = 7, ["name"] = "default:obsidianbrick"}, {["x"] = 4, ["meta"] = {["fields"] = {}, ["inventory"] = {}}, ["y"] = 8, ["z"] = 8, ["name"] = "default:obsidianbrick"}, {["x"] = 4, ["meta"] = {["fields"] = {}, ["inventory"] = {}}, ["y"] = 8, ["z"] = 9, ["name"] = "default:obsidianbrick"}, {["x"] = 4, ["meta"] = {["fields"] = {}, ["inventory"] = {}}, ["y"] = 8, ["z"] = 10, ["name"] = "default:obsidianbrick"}, {["x"] = 4, ["meta"] = {["fields"] = {}, ["inventory"] = {}}, ["param2"] = 15, ["y"] = 8, ["z"] = 11, ["name"] = "default:lava_flowing"}, {["x"] = 4, ["meta"] = {["fields"] = {}, ["inventory"] = {}}, ["y"] = 8, ["z"] = 12, ["name"] = "default:obsidianbrick"}, {["x"] = 4, ["meta"] = {["fields"] = {}, ["inventory"] = {}}, ["param2"] = 15, ["y"] = 9, ["z"] = 6, ["name"] = "default:lava_flowing"}, {["x"] = 4, ["meta"] = {["fields"] = {}, ["inventory"] = {}}, ["y"] = 9, ["z"] = 7, ["name"] = "default:obsidianbrick"}, {["x"] = 4, ["meta"] = {["fields"] = {}, ["inventory"] = {}}, ["y"] = 9, ["z"] = 8, ["name"] = "default:obsidianbrick"}, {["x"] = 4, ["meta"] = {["fields"] = {}, ["inventory"] = {}}, ["y"] = 9, ["z"] = 9, ["name"] = "default:obsidianbrick"}, {["x"] = 4, ["meta"] = {["fields"] = {}, ["inventory"] = {}}, ["y"] = 9, ["z"] = 10, ["name"] = "default:obsidianbrick"}, {["x"] = 4, ["meta"] = {["fields"] = {}, ["inventory"] = {}}, ["param2"] = 15, ["y"] = 9, ["z"] = 11, ["name"] = "default:lava_flowing"}, {["x"] = 4, ["meta"] = {["fields"] = {}, ["inventory"] = {}}, ["y"] = 9, ["z"] = 12, ["name"] = "default:obsidianbrick"}, {["x"] = 4, ["meta"] = {["fields"] = {}, ["inventory"] = {}}, ["param2"] = 15, ["y"] = 10, ["z"] = 6, ["name"] = "default:lava_flowing"}, {["x"] = 4, ["meta"] = {["fields"] = {}, ["inventory"] = {}}, ["y"] = 10, ["z"] = 7, ["name"] = "default:obsidianbrick"}, {["x"] = 4, ["meta"] = {["fields"] = {}, ["inventory"] = {}}, ["y"] = 10, ["z"] = 8, ["name"] = "default:obsidianbrick"}, {["x"] = 4, ["meta"] = {["fields"] = {}, ["inventory"] = {}}, ["y"] = 10, ["z"] = 9, ["name"] = "default:obsidianbrick"}, {["x"] = 4, ["meta"] = {["fields"] = {}, ["inventory"] = {}}, ["y"] = 10, ["z"] = 10, ["name"] = "default:obsidianbrick"}, {["x"] = 4, ["meta"] = {["fields"] = {}, ["inventory"] = {}}, ["param2"] = 15, ["y"] = 10, ["z"] = 11, ["name"] = "default:lava_flowing"}, {["x"] = 4, ["meta"] = {["fields"] = {}, ["inventory"] = {}}, ["param2"] = 15, ["y"] = 11, ["z"] = 6, ["name"] = "default:lava_flowing"}, {["x"] = 4, ["meta"] = {["fields"] = {}, ["inventory"] = {}}, ["y"] = 11, ["z"] = 7, ["name"] = "default:obsidianbrick"}, {["x"] = 4, ["meta"] = {["fields"] = {}, ["inventory"] = {}}, ["y"] = 11, ["z"] = 8, ["name"] = "default:obsidianbrick"}, {["x"] = 4, ["meta"] = {["fields"] = {}, ["inventory"] = {}}, ["y"] = 11, ["z"] = 9, ["name"] = "default:obsidianbrick"}, {["x"] = 4, ["meta"] = {["fields"] = {}, ["inventory"] = {}}, ["y"] = 11, ["z"] = 10, ["name"] = "default:obsidianbrick"}, {["x"] = 4, ["meta"] = {["fields"] = {}, ["inventory"] = {}}, ["param2"] = 15, ["y"] = 11, ["z"] = 11, ["name"] = "default:lava_flowing"}, {["x"] = 4, ["meta"] = {["fields"] = {}, ["inventory"] = {}}, ["param2"] = 15, ["y"] = 12, ["z"] = 6, ["name"] = "default:lava_flowing"}, {["x"] = 4, ["meta"] = {["fields"] = {}, ["inventory"] = {}}, ["y"] = 12, ["z"] = 7, ["name"] = "default:obsidianbrick"}, {["x"] = 4, ["meta"] = {["fields"] = {}, ["inventory"] = {}}, ["y"] = 12, ["z"] = 8, ["name"] = "default:obsidianbrick"}, {["x"] = 4, ["meta"] = {["fields"] = {}, ["inventory"] = {}}, ["y"] = 12, ["z"] = 9, ["name"] = "default:obsidianbrick"}, {["x"] = 4, ["meta"] = {["fields"] = {}, ["inventory"] = {}}, ["y"] = 12, ["z"] = 10, ["name"] = "default:obsidianbrick"}, {["x"] = 4, ["meta"] = {["fields"] = {}, ["inventory"] = {}}, ["param2"] = 15, ["y"] = 12, ["z"] = 11, ["name"] = "default:lava_flowing"}, {["x"] = 4, ["meta"] = {["fields"] = {}, ["inventory"] = {}}, ["param2"] = 15, ["y"] = 13, ["z"] = 6, ["name"] = "default:lava_flowing"}, {["x"] = 4, ["meta"] = {["fields"] = {}, ["inventory"] = {}}, ["y"] = 13, ["z"] = 7, ["name"] = "default:obsidianbrick"}, {["x"] = 4, ["meta"] = {["fields"] = {}, ["inventory"] = {}}, ["y"] = 13, ["z"] = 8, ["name"] = "default:obsidianbrick"}, {["x"] = 4, ["meta"] = {["fields"] = {}, ["inventory"] = {}}, ["y"] = 13, ["z"] = 9, ["name"] = "default:obsidianbrick"}, {["x"] = 4, ["meta"] = {["fields"] = {}, ["inventory"] = {}}, ["y"] = 13, ["z"] = 10, ["name"] = "default:obsidianbrick"}, {["x"] = 4, ["meta"] = {["fields"] = {}, ["inventory"] = {}}, ["param2"] = 15, ["y"] = 13, ["z"] = 11, ["name"] = "default:lava_flowing"}, {["x"] = 4, ["meta"] = {["fields"] = {}, ["inventory"] = {}}, ["param2"] = 15, ["y"] = 14, ["z"] = 6, ["name"] = "default:lava_flowing"}, {["x"] = 4, ["meta"] = {["fields"] = {}, ["inventory"] = {}}, ["y"] = 14, ["z"] = 7, ["name"] = "default:obsidianbrick"}, {["x"] = 4, ["meta"] = {["fields"] = {}, ["inventory"] = {}}, ["y"] = 14, ["z"] = 8, ["name"] = "default:obsidianbrick"}, {["x"] = 4, ["meta"] = {["fields"] = {}, ["inventory"] = {}}, ["y"] = 14, ["z"] = 9, ["name"] = "default:obsidianbrick"}, {["x"] = 4, ["meta"] = {["fields"] = {}, ["inventory"] = {}}, ["y"] = 14, ["z"] = 10, ["name"] = "default:obsidianbrick"}, {["x"] = 4, ["meta"] = {["fields"] = {}, ["inventory"] = {}}, ["param2"] = 15, ["y"] = 14, ["z"] = 11, ["name"] = "default:lava_flowing"}, {["x"] = 4, ["meta"] = {["fields"] = {}, ["inventory"] = {}}, ["param2"] = 15, ["y"] = 15, ["z"] = 6, ["name"] = "default:lava_flowing"}, {["x"] = 4, ["meta"] = {["fields"] = {}, ["inventory"] = {}}, ["y"] = 15, ["z"] = 7, ["name"] = "default:obsidianbrick"}, {["x"] = 4, ["meta"] = {["fields"] = {}, ["inventory"] = {}}, ["y"] = 15, ["z"] = 8, ["name"] = "default:obsidianbrick"}, {["x"] = 4, ["meta"] = {["fields"] = {}, ["inventory"] = {}}, ["y"] = 15, ["z"] = 9, ["name"] = "default:obsidianbrick"}, {["x"] = 4, ["meta"] = {["fields"] = {}, ["inventory"] = {}}, ["y"] = 15, ["z"] = 10, ["name"] = "default:obsidianbrick"}, {["x"] = 4, ["meta"] = {["fields"] = {}, ["inventory"] = {}}, ["param2"] = 15, ["y"] = 15, ["z"] = 11, ["name"] = "default:lava_flowing"}, {["x"] = 4, ["meta"] = {["fields"] = {}, ["inventory"] = {}}, ["param2"] = 15, ["y"] = 16, ["z"] = 6, ["name"] = "default:lava_flowing"}, {["x"] = 4, ["meta"] = {["fields"] = {}, ["inventory"] = {}}, ["y"] = 16, ["z"] = 7, ["name"] = "default:obsidianbrick"}, {["x"] = 4, ["meta"] = {["fields"] = {}, ["inventory"] = {}}, ["y"] = 16, ["z"] = 8, ["name"] = "default:obsidianbrick"}, {["x"] = 4, ["meta"] = {["fields"] = {}, ["inventory"] = {}}, ["y"] = 16, ["z"] = 9, ["name"] = "default:obsidianbrick"}, {["x"] = 4, ["meta"] = {["fields"] = {}, ["inventory"] = {}}, ["y"] = 16, ["z"] = 10, ["name"] = "default:obsidianbrick"}, {["x"] = 4, ["meta"] = {["fields"] = {}, ["inventory"] = {}}, ["param2"] = 15, ["y"] = 16, ["z"] = 11, ["name"] = "default:lava_flowing"}, {["x"] = 4, ["meta"] = {["fields"] = {}, ["inventory"] = {}}, ["y"] = 17, ["z"] = 5, ["name"] = "default:obsidianbrick"}, {["x"] = 4, ["meta"] = {["fields"] = {}, ["inventory"] = {}}, ["param2"] = 15, ["y"] = 17, ["z"] = 6, ["name"] = "default:lava_flowing"}, {["x"] = 4, ["meta"] = {["fields"] = {}, ["inventory"] = {}}, ["y"] = 17, ["z"] = 7, ["name"] = "default:obsidianbrick"}, {["x"] = 4, ["meta"] = {["fields"] = {}, ["inventory"] = {}}, ["y"] = 17, ["z"] = 8, ["name"] = "default:obsidianbrick"}, {["x"] = 4, ["meta"] = {["fields"] = {}, ["inventory"] = {}}, ["y"] = 17, ["z"] = 9, ["name"] = "default:obsidianbrick"}, {["x"] = 4, ["meta"] = {["fields"] = {}, ["inventory"] = {}}, ["y"] = 17, ["z"] = 10, ["name"] = "default:obsidianbrick"}, {["x"] = 4, ["meta"] = {["fields"] = {}, ["inventory"] = {}}, ["param2"] = 15, ["y"] = 17, ["z"] = 11, ["name"] = "default:lava_flowing"}, {["x"] = 4, ["meta"] = {["fields"] = {}, ["inventory"] = {}}, ["y"] = 18, ["z"] = 5, ["name"] = "default:obsidianbrick"}, {["x"] = 4, ["meta"] = {["fields"] = {}, ["inventory"] = {}}, ["param2"] = 15, ["y"] = 18, ["z"] = 6, ["name"] = "default:lava_flowing"}, {["x"] = 4, ["meta"] = {["fields"] = {}, ["inventory"] = {}}, ["y"] = 18, ["z"] = 7, ["name"] = "default:obsidianbrick"}, {["x"] = 4, ["meta"] = {["fields"] = {}, ["inventory"] = {}}, ["y"] = 18, ["z"] = 8, ["name"] = "default:obsidianbrick"}, {["x"] = 4, ["meta"] = {["fields"] = {}, ["inventory"] = {}}, ["y"] = 18, ["z"] = 9, ["name"] = "default:obsidianbrick"}, {["x"] = 4, ["meta"] = {["fields"] = {}, ["inventory"] = {}}, ["y"] = 18, ["z"] = 10, ["name"] = "default:obsidianbrick"}, {["x"] = 4, ["meta"] = {["fields"] = {}, ["inventory"] = {}}, ["param2"] = 15, ["y"] = 18, ["z"] = 11, ["name"] = "default:lava_flowing"}, {["x"] = 4, ["meta"] = {["fields"] = {}, ["inventory"] = {}}, ["param2"] = 15, ["y"] = 19, ["z"] = 6, ["name"] = "default:lava_flowing"}, {["x"] = 4, ["meta"] = {["fields"] = {}, ["inventory"] = {}}, ["y"] = 19, ["z"] = 7, ["name"] = "default:obsidianbrick"}, {["x"] = 4, ["meta"] = {["fields"] = {}, ["inventory"] = {}}, ["y"] = 19, ["z"] = 8, ["name"] = "default:obsidianbrick"}, {["x"] = 4, ["meta"] = {["fields"] = {}, ["inventory"] = {}}, ["y"] = 19, ["z"] = 9, ["name"] = "default:obsidianbrick"}, {["x"] = 4, ["meta"] = {["fields"] = {}, ["inventory"] = {}}, ["y"] = 19, ["z"] = 10, ["name"] = "default:obsidianbrick"}, {["x"] = 4, ["meta"] = {["fields"] = {}, ["inventory"] = {}}, ["param2"] = 15, ["y"] = 19, ["z"] = 11, ["name"] = "default:lava_flowing"}, {["x"] = 4, ["meta"] = {["fields"] = {}, ["inventory"] = {}}, ["param2"] = 15, ["y"] = 20, ["z"] = 6, ["name"] = "default:lava_flowing"}, {["x"] = 4, ["meta"] = {["fields"] = {}, ["inventory"] = {}}, ["y"] = 20, ["z"] = 7, ["name"] = "default:obsidianbrick"}, {["x"] = 4, ["meta"] = {["fields"] = {}, ["inventory"] = {}}, ["y"] = 20, ["z"] = 8, ["name"] = "default:obsidianbrick"}, {["x"] = 4, ["meta"] = {["fields"] = {}, ["inventory"] = {}}, ["y"] = 20, ["z"] = 9, ["name"] = "default:obsidianbrick"}, {["x"] = 4, ["meta"] = {["fields"] = {}, ["inventory"] = {}}, ["y"] = 20, ["z"] = 10, ["name"] = "default:obsidianbrick"}, {["x"] = 4, ["meta"] = {["fields"] = {}, ["inventory"] = {}}, ["param2"] = 15, ["y"] = 20, ["z"] = 11, ["name"] = "default:lava_flowing"}, {["x"] = 4, ["meta"] = {["fields"] = {}, ["inventory"] = {}}, ["param2"] = 15, ["y"] = 21, ["z"] = 6, ["name"] = "default:lava_flowing"}, {["x"] = 4, ["meta"] = {["fields"] = {}, ["inventory"] = {}}, ["y"] = 21, ["z"] = 7, ["name"] = "default:obsidianbrick"}, {["x"] = 4, ["meta"] = {["fields"] = {}, ["inventory"] = {}}, ["y"] = 21, ["z"] = 8, ["name"] = "default:obsidianbrick"}, {["x"] = 4, ["meta"] = {["fields"] = {}, ["inventory"] = {}}, ["y"] = 21, ["z"] = 9, ["name"] = "default:obsidianbrick"}, {["x"] = 4, ["meta"] = {["fields"] = {}, ["inventory"] = {}}, ["y"] = 21, ["z"] = 10, ["name"] = "default:obsidianbrick"}, {["x"] = 4, ["meta"] = {["fields"] = {}, ["inventory"] = {}}, ["param2"] = 15, ["y"] = 21, ["z"] = 11, ["name"] = "default:lava_flowing"}, {["x"] = 4, ["meta"] = {["fields"] = {}, ["inventory"] = {}}, ["param2"] = 15, ["y"] = 22, ["z"] = 6, ["name"] = "default:lava_flowing"}, {["x"] = 4, ["meta"] = {["fields"] = {}, ["inventory"] = {}}, ["y"] = 22, ["z"] = 7, ["name"] = "default:obsidianbrick"}, {["x"] = 4, ["meta"] = {["fields"] = {}, ["inventory"] = {}}, ["y"] = 22, ["z"] = 8, ["name"] = "default:obsidianbrick"}, {["x"] = 4, ["meta"] = {["fields"] = {}, ["inventory"] = {}}, ["y"] = 22, ["z"] = 9, ["name"] = "default:obsidianbrick"}, {["x"] = 4, ["meta"] = {["fields"] = {}, ["inventory"] = {}}, ["y"] = 22, ["z"] = 10, ["name"] = "default:obsidianbrick"}, {["x"] = 4, ["meta"] = {["fields"] = {}, ["inventory"] = {}}, ["param2"] = 15, ["y"] = 22, ["z"] = 11, ["name"] = "default:lava_flowing"}, {["x"] = 4, ["meta"] = {["fields"] = {}, ["inventory"] = {}}, ["param2"] = 15, ["y"] = 23, ["z"] = 6, ["name"] = "default:lava_flowing"}, {["x"] = 4, ["meta"] = {["fields"] = {}, ["inventory"] = {}}, ["y"] = 23, ["z"] = 7, ["name"] = "default:obsidianbrick"}, {["x"] = 4, ["meta"] = {["fields"] = {}, ["inventory"] = {}}, ["y"] = 23, ["z"] = 8, ["name"] = "default:obsidianbrick"}, {["x"] = 4, ["meta"] = {["fields"] = {}, ["inventory"] = {}}, ["y"] = 23, ["z"] = 9, ["name"] = "default:obsidianbrick"}, {["x"] = 4, ["meta"] = {["fields"] = {}, ["inventory"] = {}}, ["y"] = 23, ["z"] = 10, ["name"] = "default:obsidianbrick"}, {["x"] = 4, ["meta"] = {["fields"] = {}, ["inventory"] = {}}, ["param2"] = 15, ["y"] = 23, ["z"] = 11, ["name"] = "default:lava_flowing"}, {["x"] = 4, ["meta"] = {["fields"] = {}, ["inventory"] = {}}, ["param2"] = 15, ["y"] = 24, ["z"] = 6, ["name"] = "default:lava_flowing"}, {["x"] = 4, ["meta"] = {["fields"] = {}, ["inventory"] = {}}, ["y"] = 24, ["z"] = 7, ["name"] = "default:obsidianbrick"}, {["x"] = 4, ["meta"] = {["fields"] = {}, ["inventory"] = {}}, ["y"] = 24, ["z"] = 8, ["name"] = "default:obsidianbrick"}, {["x"] = 4, ["meta"] = {["fields"] = {}, ["inventory"] = {}}, ["y"] = 24, ["z"] = 9, ["name"] = "default:obsidianbrick"}, {["x"] = 4, ["meta"] = {["fields"] = {}, ["inventory"] = {}}, ["y"] = 24, ["z"] = 10, ["name"] = "default:obsidianbrick"}, {["x"] = 4, ["meta"] = {["fields"] = {}, ["inventory"] = {}}, ["param2"] = 15, ["y"] = 24, ["z"] = 11, ["name"] = "default:lava_flowing"}, {["x"] = 4, ["meta"] = {["fields"] = {}, ["inventory"] = {}}, ["param2"] = 15, ["y"] = 25, ["z"] = 6, ["name"] = "default:lava_flowing"}, {["x"] = 4, ["meta"] = {["fields"] = {}, ["inventory"] = {}}, ["y"] = 25, ["z"] = 7, ["name"] = "default:obsidianbrick"}, {["x"] = 4, ["meta"] = {["fields"] = {}, ["inventory"] = {}}, ["y"] = 25, ["z"] = 8, ["name"] = "default:obsidianbrick"}, {["x"] = 4, ["meta"] = {["fields"] = {}, ["inventory"] = {}}, ["y"] = 25, ["z"] = 9, ["name"] = "default:obsidianbrick"}, {["x"] = 4, ["meta"] = {["fields"] = {}, ["inventory"] = {}}, ["y"] = 25, ["z"] = 10, ["name"] = "default:obsidianbrick"}, {["x"] = 4, ["meta"] = {["fields"] = {}, ["inventory"] = {}}, ["param2"] = 15, ["y"] = 25, ["z"] = 11, ["name"] = "default:lava_flowing"}, {["x"] = 4, ["meta"] = {["fields"] = {}, ["inventory"] = {}}, ["param2"] = 15, ["y"] = 26, ["z"] = 6, ["name"] = "default:lava_flowing"}, {["x"] = 4, ["meta"] = {["fields"] = {}, ["inventory"] = {}}, ["y"] = 26, ["z"] = 7, ["name"] = "default:obsidianbrick"}, {["x"] = 4, ["meta"] = {["fields"] = {}, ["inventory"] = {}}, ["y"] = 26, ["z"] = 8, ["name"] = "default:obsidianbrick"}, {["x"] = 4, ["meta"] = {["fields"] = {}, ["inventory"] = {}}, ["y"] = 26, ["z"] = 9, ["name"] = "default:obsidianbrick"}, {["x"] = 4, ["meta"] = {["fields"] = {}, ["inventory"] = {}}, ["y"] = 26, ["z"] = 10, ["name"] = "default:obsidianbrick"}, {["x"] = 4, ["meta"] = {["fields"] = {}, ["inventory"] = {}}, ["param2"] = 15, ["y"] = 26, ["z"] = 11, ["name"] = "default:lava_flowing"}, {["x"] = 4, ["meta"] = {["fields"] = {}, ["inventory"] = {}}, ["param2"] = 15, ["y"] = 27, ["z"] = 6, ["name"] = "default:lava_flowing"}, {["x"] = 4, ["meta"] = {["fields"] = {}, ["inventory"] = {}}, ["y"] = 27, ["z"] = 7, ["name"] = "default:obsidianbrick"}, {["x"] = 4, ["meta"] = {["fields"] = {}, ["inventory"] = {}}, ["y"] = 27, ["z"] = 8, ["name"] = "default:obsidianbrick"}, {["x"] = 4, ["meta"] = {["fields"] = {}, ["inventory"] = {}}, ["y"] = 27, ["z"] = 9, ["name"] = "default:obsidianbrick"}, {["x"] = 4, ["meta"] = {["fields"] = {}, ["inventory"] = {}}, ["y"] = 27, ["z"] = 10, ["name"] = "default:obsidianbrick"}, {["x"] = 4, ["meta"] = {["fields"] = {}, ["inventory"] = {}}, ["param2"] = 15, ["y"] = 27, ["z"] = 11, ["name"] = "default:lava_flowing"}, {["x"] = 4, ["meta"] = {["fields"] = {}, ["inventory"] = {}}, ["param2"] = 15, ["y"] = 28, ["z"] = 6, ["name"] = "default:lava_flowing"}, {["x"] = 4, ["meta"] = {["fields"] = {}, ["inventory"] = {}}, ["y"] = 28, ["z"] = 7, ["name"] = "default:obsidianbrick"}, {["x"] = 4, ["meta"] = {["fields"] = {}, ["inventory"] = {}}, ["y"] = 28, ["z"] = 8, ["name"] = "default:obsidianbrick"}, {["x"] = 4, ["meta"] = {["fields"] = {}, ["inventory"] = {}}, ["y"] = 28, ["z"] = 9, ["name"] = "default:obsidianbrick"}, {["x"] = 4, ["meta"] = {["fields"] = {}, ["inventory"] = {}}, ["y"] = 28, ["z"] = 10, ["name"] = "default:obsidianbrick"}, {["x"] = 4, ["meta"] = {["fields"] = {}, ["inventory"] = {}}, ["param2"] = 15, ["y"] = 28, ["z"] = 11, ["name"] = "default:lava_flowing"}, {["x"] = 4, ["meta"] = {["fields"] = {}, ["inventory"] = {}}, ["param2"] = 14, ["y"] = 29, ["z"] = 6, ["name"] = "default:lava_flowing"}, {["x"] = 4, ["meta"] = {["fields"] = {}, ["inventory"] = {}}, ["y"] = 29, ["z"] = 8, ["name"] = "default:obsidianbrick"}, {["x"] = 4, ["meta"] = {["fields"] = {}, ["inventory"] = {}}, ["y"] = 29, ["z"] = 9, ["name"] = "default:obsidianbrick"}, {["x"] = 4, ["meta"] = {["fields"] = {}, ["inventory"] = {}}, ["param2"] = 14, ["y"] = 29, ["z"] = 11, ["name"] = "default:lava_flowing"}, {["x"] = 4, ["meta"] = {["fields"] = {}, ["inventory"] = {}}, ["y"] = 30, ["z"] = 8, ["name"] = "default:obsidianbrick"}, {["x"] = 4, ["meta"] = {["fields"] = {}, ["inventory"] = {}}, ["y"] = 30, ["z"] = 9, ["name"] = "default:obsidianbrick"}, {["x"] = 4, ["meta"] = {["fields"] = {}, ["inventory"] = {}}, ["y"] = 31, ["z"] = 8, ["name"] = "default:obsidianbrick"}, {["x"] = 4, ["meta"] = {["fields"] = {}, ["inventory"] = {}}, ["y"] = 31, ["z"] = 9, ["name"] = "default:obsidianbrick"}, {["x"] = 4, ["meta"] = {["fields"] = {}, ["inventory"] = {}}, ["y"] = 32, ["z"] = 7, ["name"] = "default:obsidianbrick"}, {["x"] = 4, ["meta"] = {["fields"] = {}, ["inventory"] = {}}, ["y"] = 32, ["z"] = 8, ["name"] = "default:obsidianbrick"}, {["x"] = 4, ["meta"] = {["fields"] = {}, ["inventory"] = {}}, ["y"] = 32, ["z"] = 9, ["name"] = "default:obsidianbrick"}, {["x"] = 4, ["meta"] = {["fields"] = {}, ["inventory"] = {}}, ["y"] = 32, ["z"] = 10, ["name"] = "default:obsidianbrick"}, {["x"] = 4, ["meta"] = {["fields"] = {}, ["inventory"] = {}}, ["y"] = 33, ["z"] = 7, ["name"] = "default:obsidianbrick"}, {["x"] = 4, ["meta"] = {["fields"] = {}, ["inventory"] = {}}, ["y"] = 33, ["z"] = 8, ["name"] = "default:obsidianbrick"}, {["x"] = 4, ["meta"] = {["fields"] = {}, ["inventory"] = {}}, ["y"] = 33, ["z"] = 9, ["name"] = "default:obsidianbrick"}, {["x"] = 4, ["meta"] = {["fields"] = {}, ["inventory"] = {}}, ["y"] = 33, ["z"] = 10, ["name"] = "default:obsidianbrick"}, {["x"] = 4, ["meta"] = {["fields"] = {}, ["inventory"] = {}}, ["y"] = 34, ["z"] = 7, ["name"] = "default:obsidianbrick"}, {["x"] = 4, ["meta"] = {["fields"] = {}, ["inventory"] = {}}, ["y"] = 34, ["z"] = 8, ["name"] = "default:obsidianbrick"}, {["x"] = 4, ["meta"] = {["fields"] = {}, ["inventory"] = {}}, ["y"] = 34, ["z"] = 9, ["name"] = "default:obsidianbrick"}, {["x"] = 4, ["meta"] = {["fields"] = {}, ["inventory"] = {}}, ["y"] = 34, ["z"] = 10, ["name"] = "default:obsidianbrick"}, {["x"] = 4, ["meta"] = {["fields"] = {}, ["inventory"] = {}}, ["y"] = 35, ["z"] = 5, ["name"] = "default:obsidianbrick"}, {["x"] = 4, ["meta"] = {["fields"] = {}, ["inventory"] = {}}, ["y"] = 35, ["z"] = 6, ["name"] = "default:obsidianbrick"}, {["x"] = 4, ["meta"] = {["fields"] = {}, ["inventory"] = {}}, ["y"] = 35, ["z"] = 7, ["name"] = "default:obsidianbrick"}, {["x"] = 4, ["meta"] = {["fields"] = {}, ["inventory"] = {}}, ["y"] = 35, ["z"] = 8, ["name"] = "default:obsidianbrick"}, {["x"] = 4, ["meta"] = {["fields"] = {}, ["inventory"] = {}}, ["y"] = 35, ["z"] = 9, ["name"] = "default:obsidianbrick"}, {["x"] = 4, ["meta"] = {["fields"] = {}, ["inventory"] = {}}, ["y"] = 35, ["z"] = 10, ["name"] = "default:obsidianbrick"}, {["x"] = 4, ["meta"] = {["fields"] = {}, ["inventory"] = {}}, ["y"] = 35, ["z"] = 11, ["name"] = "default:obsidianbrick"}, {["x"] = 4, ["meta"] = {["fields"] = {}, ["inventory"] = {}}, ["y"] = 35, ["z"] = 12, ["name"] = "default:obsidianbrick"}, {["x"] = 4, ["meta"] = {["fields"] = {}, ["inventory"] = {}}, ["y"] = 36, ["z"] = 6, ["name"] = "default:obsidianbrick"}, {["x"] = 4, ["meta"] = {["fields"] = {}, ["inventory"] = {}}, ["y"] = 36, ["z"] = 7, ["name"] = "default:obsidianbrick"}, {["x"] = 4, ["meta"] = {["fields"] = {}, ["inventory"] = {}}, ["y"] = 36, ["z"] = 8, ["name"] = "default:obsidianbrick"}, {["x"] = 4, ["meta"] = {["fields"] = {}, ["inventory"] = {}}, ["y"] = 36, ["z"] = 9, ["name"] = "default:obsidianbrick"}, {["x"] = 4, ["meta"] = {["fields"] = {}, ["inventory"] = {}}, ["y"] = 36, ["z"] = 10, ["name"] = "default:obsidianbrick"}, {["x"] = 4, ["meta"] = {["fields"] = {}, ["inventory"] = {}}, ["y"] = 36, ["z"] = 11, ["name"] = "default:obsidianbrick"}, {["x"] = 5, ["meta"] = {["fields"] = {}, ["inventory"] = {}}, ["y"] = 0, ["z"] = 0, ["name"] = "default:dirt"}, {["x"] = 5, ["meta"] = {["fields"] = {}, ["inventory"] = {}}, ["y"] = 0, ["z"] = 1, ["name"] = "default:dirt"}, {["x"] = 5, ["meta"] = {["fields"] = {}, ["inventory"] = {}}, ["y"] = 0, ["z"] = 2, ["name"] = "default:dirt"}, {["x"] = 5, ["meta"] = {["fields"] = {}, ["inventory"] = {}}, ["y"] = 0, ["z"] = 3, ["name"] = "default:dirt"}, {["x"] = 5, ["meta"] = {["fields"] = {}, ["inventory"] = {}}, ["y"] = 0, ["z"] = 4, ["name"] = "default:dirt"}, {["x"] = 5, ["meta"] = {["fields"] = {}, ["inventory"] = {}}, ["y"] = 0, ["z"] = 5, ["name"] = "default:dirt"}, {["x"] = 5, ["meta"] = {["fields"] = {}, ["inventory"] = {}}, ["y"] = 0, ["z"] = 6, ["name"] = "default:dirt"}, {["x"] = 5, ["meta"] = {["fields"] = {}, ["inventory"] = {}}, ["y"] = 0, ["z"] = 7, ["name"] = "default:dirt"}, {["x"] = 5, ["meta"] = {["fields"] = {}, ["inventory"] = {}}, ["y"] = 0, ["z"] = 8, ["name"] = "default:dirt"}, {["x"] = 5, ["meta"] = {["fields"] = {}, ["inventory"] = {}}, ["y"] = 0, ["z"] = 9, ["name"] = "default:dirt"}, {["x"] = 5, ["meta"] = {["fields"] = {}, ["inventory"] = {}}, ["y"] = 0, ["z"] = 10, ["name"] = "default:dirt"}, {["x"] = 5, ["meta"] = {["fields"] = {}, ["inventory"] = {}}, ["y"] = 0, ["z"] = 11, ["name"] = "default:dirt"}, {["x"] = 5, ["meta"] = {["fields"] = {}, ["inventory"] = {}}, ["y"] = 0, ["z"] = 12, ["name"] = "default:dirt"}, {["x"] = 5, ["meta"] = {["fields"] = {}, ["inventory"] = {}}, ["y"] = 0, ["z"] = 13, ["name"] = "default:stone"}, {["x"] = 5, ["meta"] = {["fields"] = {}, ["inventory"] = {}}, ["y"] = 0, ["z"] = 14, ["name"] = "default:dirt"}, {["x"] = 5, ["meta"] = {["fields"] = {}, ["inventory"] = {}}, ["y"] = 0, ["z"] = 15, ["name"] = "default:dirt"}, {["x"] = 5, ["meta"] = {["fields"] = {}, ["inventory"] = {}}, ["y"] = 1, ["z"] = 0, ["name"] = "default:dirt_with_grass"}, {["x"] = 5, ["meta"] = {["fields"] = {}, ["inventory"] = {}}, ["y"] = 1, ["z"] = 1, ["name"] = "default:dirt_with_grass"}, {["x"] = 5, ["meta"] = {["fields"] = {}, ["inventory"] = {}}, ["y"] = 1, ["z"] = 2, ["name"] = "default:dirt"}, {["x"] = 5, ["meta"] = {["fields"] = {}, ["inventory"] = {}}, ["y"] = 1, ["z"] = 3, ["name"] = "default:dirt"}, {["x"] = 5, ["meta"] = {["fields"] = {}, ["inventory"] = {}}, ["y"] = 1, ["z"] = 4, ["name"] = "default:dirt"}, {["x"] = 5, ["meta"] = {["fields"] = {}, ["inventory"] = {}}, ["y"] = 1, ["z"] = 5, ["name"] = "default:dirt"}, {["x"] = 5, ["meta"] = {["fields"] = {}, ["inventory"] = {}}, ["y"] = 1, ["z"] = 6, ["name"] = "default:dirt"}, {["x"] = 5, ["meta"] = {["fields"] = {}, ["inventory"] = {}}, ["y"] = 1, ["z"] = 7, ["name"] = "default:dirt"}, {["x"] = 5, ["meta"] = {["fields"] = {}, ["inventory"] = {}}, ["y"] = 1, ["z"] = 8, ["name"] = "default:dirt"}, {["x"] = 5, ["meta"] = {["fields"] = {}, ["inventory"] = {}}, ["y"] = 1, ["z"] = 9, ["name"] = "default:dirt"}, {["x"] = 5, ["meta"] = {["fields"] = {}, ["inventory"] = {}}, ["y"] = 1, ["z"] = 10, ["name"] = "default:dirt"}, {["x"] = 5, ["meta"] = {["fields"] = {}, ["inventory"] = {}}, ["y"] = 1, ["z"] = 11, ["name"] = "default:dirt"}, {["x"] = 5, ["meta"] = {["fields"] = {}, ["inventory"] = {}}, ["y"] = 1, ["z"] = 12, ["name"] = "default:dirt"}, {["x"] = 5, ["meta"] = {["fields"] = {}, ["inventory"] = {}}, ["y"] = 1, ["z"] = 13, ["name"] = "default:dirt"}, {["x"] = 5, ["meta"] = {["fields"] = {}, ["inventory"] = {}}, ["y"] = 1, ["z"] = 14, ["name"] = "default:dirt"}, {["x"] = 5, ["meta"] = {["fields"] = {}, ["inventory"] = {}}, ["y"] = 1, ["z"] = 15, ["name"] = "default:obsidianbrick"}, {["x"] = 5, ["meta"] = {["fields"] = {}, ["inventory"] = {}}, ["y"] = 2, ["z"] = 2, ["name"] = "default:obsidianbrick"}, {["x"] = 5, ["meta"] = {["fields"] = {}, ["inventory"] = {}}, ["param2"] = 5, ["y"] = 2, ["z"] = 3, ["name"] = "default:lava_flowing"}, {["x"] = 5, ["meta"] = {["fields"] = {}, ["inventory"] = {}}, ["param2"] = 6, ["y"] = 2, ["z"] = 4, ["name"] = "default:lava_flowing"}, {["x"] = 5, ["meta"] = {["fields"] = {}, ["inventory"] = {}}, ["param2"] = 5, ["y"] = 2, ["z"] = 5, ["name"] = "default:lava_flowing"}, {["x"] = 5, ["meta"] = {["fields"] = {}, ["inventory"] = {}}, ["y"] = 2, ["z"] = 6, ["name"] = "default:dirt"}, {["x"] = 5, ["meta"] = {["fields"] = {}, ["inventory"] = {}}, ["y"] = 2, ["z"] = 7, ["name"] = "default:dirt"}, {["x"] = 5, ["meta"] = {["fields"] = {}, ["inventory"] = {}}, ["y"] = 2, ["z"] = 8, ["name"] = "default:dirt_with_grass"}, {["x"] = 5, ["meta"] = {["fields"] = {}, ["inventory"] = {}}, ["y"] = 2, ["z"] = 9, ["name"] = "default:dirt_with_grass"}, {["x"] = 5, ["meta"] = {["fields"] = {}, ["inventory"] = {}}, ["y"] = 2, ["z"] = 10, ["name"] = "default:dirt"}, {["x"] = 5, ["meta"] = {["fields"] = {}, ["inventory"] = {}}, ["y"] = 2, ["z"] = 11, ["name"] = "default:dirt"}, {["x"] = 5, ["meta"] = {["fields"] = {}, ["inventory"] = {}}, ["param2"] = 5, ["y"] = 2, ["z"] = 12, ["name"] = "default:lava_flowing"}, {["x"] = 5, ["meta"] = {["fields"] = {}, ["inventory"] = {}}, ["param2"] = 6, ["y"] = 2, ["z"] = 13, ["name"] = "default:lava_flowing"}, {["x"] = 5, ["meta"] = {["fields"] = {}, ["inventory"] = {}}, ["param2"] = 5, ["y"] = 2, ["z"] = 14, ["name"] = "default:lava_flowing"}, {["x"] = 5, ["meta"] = {["fields"] = {}, ["inventory"] = {}}, ["y"] = 2, ["z"] = 15, ["name"] = "default:obsidianbrick"}, {["x"] = 5, ["meta"] = {["fields"] = {}, ["inventory"] = {}}, ["y"] = 3, ["z"] = 6, ["name"] = "default:obsidian"}, {["x"] = 5, ["meta"] = {["fields"] = {}, ["inventory"] = {}}, ["y"] = 3, ["z"] = 7, ["name"] = "default:obsidian"}, {["x"] = 5, ["meta"] = {["fields"] = {}, ["inventory"] = {}}, ["y"] = 3, ["z"] = 10, ["name"] = "default:obsidian"}, {["x"] = 5, ["meta"] = {["fields"] = {}, ["inventory"] = {}}, ["y"] = 3, ["z"] = 11, ["name"] = "default:obsidian"}, {["x"] = 5, ["meta"] = {["fields"] = {}, ["inventory"] = {}}, ["y"] = 4, ["z"] = 6, ["name"] = "default:obsidian"}, {["x"] = 5, ["meta"] = {["fields"] = {}, ["inventory"] = {}}, ["y"] = 4, ["z"] = 7, ["name"] = "default:obsidian"}, {["x"] = 5, ["meta"] = {["fields"] = {}, ["inventory"] = {}}, ["y"] = 4, ["z"] = 10, ["name"] = "default:obsidian"}, {["x"] = 5, ["meta"] = {["fields"] = {}, ["inventory"] = {}}, ["y"] = 4, ["z"] = 11, ["name"] = "default:obsidian"}, {["x"] = 5, ["meta"] = {["fields"] = {}, ["inventory"] = {}}, ["y"] = 5, ["z"] = 6, ["name"] = "default:obsidianbrick"}, {["x"] = 5, ["meta"] = {["fields"] = {}, ["inventory"] = {}}, ["y"] = 5, ["z"] = 7, ["name"] = "default:obsidianbrick"}, {["x"] = 5, ["meta"] = {["fields"] = {}, ["inventory"] = {}}, ["y"] = 5, ["z"] = 10, ["name"] = "default:obsidianbrick"}, {["x"] = 5, ["meta"] = {["fields"] = {}, ["inventory"] = {}}, ["y"] = 5, ["z"] = 11, ["name"] = "default:obsidianbrick"}, {["x"] = 5, ["meta"] = {["fields"] = {}, ["inventory"] = {}}, ["y"] = 6, ["z"] = 6, ["name"] = "default:obsidianbrick"}, {["x"] = 5, ["meta"] = {["fields"] = {}, ["inventory"] = {}}, ["y"] = 6, ["z"] = 7, ["name"] = "default:obsidianbrick"}, {["x"] = 5, ["meta"] = {["fields"] = {}, ["inventory"] = {}}, ["y"] = 6, ["z"] = 10, ["name"] = "default:obsidianbrick"}, {["x"] = 5, ["meta"] = {["fields"] = {}, ["inventory"] = {}}, ["y"] = 6, ["z"] = 11, ["name"] = "default:obsidianbrick"}, {["x"] = 5, ["meta"] = {["fields"] = {}, ["inventory"] = {}}, ["y"] = 7, ["z"] = 6, ["name"] = "default:obsidianbrick"}, {["x"] = 5, ["meta"] = {["fields"] = {}, ["inventory"] = {}}, ["y"] = 7, ["z"] = 7, ["name"] = "default:obsidianbrick"}, {["x"] = 5, ["meta"] = {["fields"] = {}, ["inventory"] = {}}, ["y"] = 7, ["z"] = 10, ["name"] = "default:obsidianbrick"}, {["x"] = 5, ["meta"] = {["fields"] = {}, ["inventory"] = {}}, ["y"] = 7, ["z"] = 11, ["name"] = "default:obsidianbrick"}, {["x"] = 5, ["meta"] = {["fields"] = {}, ["inventory"] = {}}, ["y"] = 8, ["z"] = 6, ["name"] = "default:obsidianbrick"}, {["x"] = 5, ["meta"] = {["fields"] = {}, ["inventory"] = {}}, ["y"] = 8, ["z"] = 7, ["name"] = "default:obsidianbrick"}, {["x"] = 5, ["meta"] = {["fields"] = {}, ["inventory"] = {}}, ["y"] = 8, ["z"] = 10, ["name"] = "default:obsidianbrick"}, {["x"] = 5, ["meta"] = {["fields"] = {}, ["inventory"] = {}}, ["y"] = 8, ["z"] = 11, ["name"] = "default:obsidianbrick"}, {["x"] = 5, ["meta"] = {["fields"] = {}, ["inventory"] = {}}, ["y"] = 8, ["z"] = 12, ["name"] = "default:obsidianbrick"}, {["x"] = 5, ["meta"] = {["fields"] = {}, ["inventory"] = {}}, ["y"] = 8, ["z"] = 13, ["name"] = "default:obsidianbrick"}, {["x"] = 5, ["meta"] = {["fields"] = {}, ["inventory"] = {}}, ["y"] = 9, ["z"] = 6, ["name"] = "default:obsidianbrick"}, {["x"] = 5, ["meta"] = {["fields"] = {}, ["inventory"] = {}}, ["y"] = 9, ["z"] = 7, ["name"] = "default:obsidianbrick"}, {["x"] = 5, ["meta"] = {["fields"] = {}, ["inventory"] = {}}, ["y"] = 9, ["z"] = 10, ["name"] = "default:obsidianbrick"}, {["x"] = 5, ["meta"] = {["fields"] = {}, ["inventory"] = {}}, ["y"] = 9, ["z"] = 11, ["name"] = "default:obsidianbrick"}, {["x"] = 5, ["meta"] = {["fields"] = {}, ["inventory"] = {}}, ["param2"] = 7, ["y"] = 9, ["z"] = 12, ["name"] = "default:lava_flowing"}, {["x"] = 5, ["meta"] = {["fields"] = {}, ["inventory"] = {}}, ["y"] = 9, ["z"] = 13, ["name"] = "default:obsidianbrick"}, {["x"] = 5, ["meta"] = {["fields"] = {}, ["inventory"] = {}}, ["y"] = 10, ["z"] = 6, ["name"] = "default:obsidianbrick"}, {["x"] = 5, ["meta"] = {["fields"] = {}, ["inventory"] = {}}, ["y"] = 10, ["z"] = 7, ["name"] = "default:obsidianbrick"}, {["x"] = 5, ["meta"] = {["fields"] = {}, ["inventory"] = {}}, ["y"] = 10, ["z"] = 10, ["name"] = "default:obsidianbrick"}, {["x"] = 5, ["meta"] = {["fields"] = {}, ["inventory"] = {}}, ["y"] = 10, ["z"] = 11, ["name"] = "default:obsidianbrick"}, {["x"] = 5, ["meta"] = {["fields"] = {}, ["inventory"] = {}}, ["param2"] = 15, ["y"] = 10, ["z"] = 12, ["name"] = "default:lava_flowing"}, {["x"] = 5, ["meta"] = {["fields"] = {}, ["inventory"] = {}}, ["y"] = 11, ["z"] = 6, ["name"] = "default:obsidianbrick"}, {["x"] = 5, ["meta"] = {["fields"] = {}, ["inventory"] = {}}, ["y"] = 11, ["z"] = 7, ["name"] = "default:obsidianbrick"}, {["x"] = 5, ["meta"] = {["fields"] = {}, ["inventory"] = {}}, ["y"] = 11, ["z"] = 10, ["name"] = "default:obsidianbrick"}, {["x"] = 5, ["meta"] = {["fields"] = {}, ["inventory"] = {}}, ["y"] = 11, ["z"] = 11, ["name"] = "default:obsidianbrick"}, {["x"] = 5, ["meta"] = {["fields"] = {}, ["inventory"] = {}}, ["param2"] = 15, ["y"] = 11, ["z"] = 12, ["name"] = "default:lava_flowing"}, {["x"] = 5, ["meta"] = {["fields"] = {}, ["inventory"] = {}}, ["y"] = 12, ["z"] = 6, ["name"] = "default:obsidianbrick"}, {["x"] = 5, ["meta"] = {["fields"] = {}, ["inventory"] = {}}, ["y"] = 12, ["z"] = 7, ["name"] = "default:obsidianbrick"}, {["x"] = 5, ["meta"] = {["fields"] = {}, ["inventory"] = {}}, ["y"] = 12, ["z"] = 10, ["name"] = "default:obsidianbrick"}, {["x"] = 5, ["meta"] = {["fields"] = {}, ["inventory"] = {}}, ["y"] = 12, ["z"] = 11, ["name"] = "default:obsidianbrick"}, {["x"] = 5, ["meta"] = {["fields"] = {}, ["inventory"] = {}}, ["param2"] = 15, ["y"] = 12, ["z"] = 12, ["name"] = "default:lava_flowing"}, {["x"] = 5, ["meta"] = {["fields"] = {}, ["inventory"] = {}}, ["y"] = 13, ["z"] = 6, ["name"] = "default:obsidianbrick"}, {["x"] = 5, ["meta"] = {["fields"] = {}, ["inventory"] = {}}, ["y"] = 13, ["z"] = 7, ["name"] = "default:obsidianbrick"}, {["x"] = 5, ["meta"] = {["fields"] = {}, ["inventory"] = {}}, ["y"] = 13, ["z"] = 10, ["name"] = "default:obsidianbrick"}, {["x"] = 5, ["meta"] = {["fields"] = {}, ["inventory"] = {}}, ["y"] = 13, ["z"] = 11, ["name"] = "default:obsidianbrick"}, {["x"] = 5, ["meta"] = {["fields"] = {}, ["inventory"] = {}}, ["param2"] = 15, ["y"] = 13, ["z"] = 12, ["name"] = "default:lava_flowing"}, {["x"] = 5, ["meta"] = {["fields"] = {}, ["inventory"] = {}}, ["y"] = 14, ["z"] = 6, ["name"] = "default:obsidianbrick"}, {["x"] = 5, ["meta"] = {["fields"] = {}, ["inventory"] = {}}, ["y"] = 14, ["z"] = 7, ["name"] = "default:obsidianbrick"}, {["x"] = 5, ["meta"] = {["fields"] = {}, ["inventory"] = {}}, ["y"] = 14, ["z"] = 10, ["name"] = "default:obsidianbrick"}, {["x"] = 5, ["meta"] = {["fields"] = {}, ["inventory"] = {}}, ["y"] = 14, ["z"] = 11, ["name"] = "default:obsidianbrick"}, {["x"] = 5, ["meta"] = {["fields"] = {}, ["inventory"] = {}}, ["param2"] = 15, ["y"] = 14, ["z"] = 12, ["name"] = "default:lava_flowing"}, {["x"] = 5, ["meta"] = {["fields"] = {}, ["inventory"] = {}}, ["y"] = 15, ["z"] = 6, ["name"] = "default:obsidianbrick"}, {["x"] = 5, ["meta"] = {["fields"] = {}, ["inventory"] = {}}, ["y"] = 15, ["z"] = 7, ["name"] = "default:obsidianbrick"}, {["x"] = 5, ["meta"] = {["fields"] = {}, ["inventory"] = {}}, ["y"] = 15, ["z"] = 10, ["name"] = "default:obsidianbrick"}, {["x"] = 5, ["meta"] = {["fields"] = {}, ["inventory"] = {}}, ["y"] = 15, ["z"] = 11, ["name"] = "default:obsidianbrick"}, {["x"] = 5, ["meta"] = {["fields"] = {}, ["inventory"] = {}}, ["param2"] = 15, ["y"] = 15, ["z"] = 12, ["name"] = "default:lava_flowing"}, {["x"] = 5, ["meta"] = {["fields"] = {}, ["inventory"] = {}}, ["y"] = 16, ["z"] = 6, ["name"] = "default:obsidianbrick"}, {["x"] = 5, ["meta"] = {["fields"] = {}, ["inventory"] = {}}, ["y"] = 16, ["z"] = 7, ["name"] = "default:obsidianbrick"}, {["x"] = 5, ["meta"] = {["fields"] = {}, ["inventory"] = {}}, ["y"] = 16, ["z"] = 10, ["name"] = "default:obsidianbrick"}, {["x"] = 5, ["meta"] = {["fields"] = {}, ["inventory"] = {}}, ["y"] = 16, ["z"] = 11, ["name"] = "default:obsidianbrick"}, {["x"] = 5, ["meta"] = {["fields"] = {}, ["inventory"] = {}}, ["param2"] = 15, ["y"] = 16, ["z"] = 12, ["name"] = "default:lava_flowing"}, {["x"] = 5, ["meta"] = {["fields"] = {}, ["inventory"] = {}}, ["y"] = 17, ["z"] = 4, ["name"] = "default:obsidianbrick"}, {["x"] = 5, ["meta"] = {["fields"] = {}, ["inventory"] = {}}, ["y"] = 17, ["z"] = 5, ["name"] = "default:obsidianbrick"}, {["x"] = 5, ["meta"] = {["fields"] = {}, ["inventory"] = {}}, ["y"] = 17, ["z"] = 6, ["name"] = "default:obsidianbrick"}, {["x"] = 5, ["meta"] = {["fields"] = {}, ["inventory"] = {}}, ["y"] = 17, ["z"] = 7, ["name"] = "default:obsidianbrick"}, {["x"] = 5, ["meta"] = {["fields"] = {}, ["inventory"] = {}}, ["y"] = 17, ["z"] = 10, ["name"] = "default:obsidianbrick"}, {["x"] = 5, ["meta"] = {["fields"] = {}, ["inventory"] = {}}, ["y"] = 17, ["z"] = 11, ["name"] = "default:obsidianbrick"}, {["x"] = 5, ["meta"] = {["fields"] = {}, ["inventory"] = {}}, ["param2"] = 15, ["y"] = 17, ["z"] = 12, ["name"] = "default:lava_flowing"}, {["x"] = 5, ["meta"] = {["fields"] = {}, ["inventory"] = {}}, ["y"] = 18, ["z"] = 4, ["name"] = "default:obsidianbrick"}, {["x"] = 5, ["meta"] = {["fields"] = {}, ["inventory"] = {}}, ["param2"] = 7, ["y"] = 18, ["z"] = 5, ["name"] = "default:lava_flowing"}, {["x"] = 5, ["meta"] = {["fields"] = {}, ["inventory"] = {}}, ["y"] = 18, ["z"] = 6, ["name"] = "default:obsidianbrick"}, {["x"] = 5, ["meta"] = {["fields"] = {}, ["inventory"] = {}}, ["y"] = 18, ["z"] = 7, ["name"] = "default:obsidianbrick"}, {["x"] = 5, ["meta"] = {["fields"] = {}, ["inventory"] = {}}, ["y"] = 18, ["z"] = 10, ["name"] = "default:obsidianbrick"}, {["x"] = 5, ["meta"] = {["fields"] = {}, ["inventory"] = {}}, ["y"] = 18, ["z"] = 11, ["name"] = "default:obsidianbrick"}, {["x"] = 5, ["meta"] = {["fields"] = {}, ["inventory"] = {}}, ["param2"] = 15, ["y"] = 18, ["z"] = 12, ["name"] = "default:lava_flowing"}, {["x"] = 5, ["meta"] = {["fields"] = {}, ["inventory"] = {}}, ["param2"] = 15, ["y"] = 19, ["z"] = 5, ["name"] = "default:lava_flowing"}, {["x"] = 5, ["meta"] = {["fields"] = {}, ["inventory"] = {}}, ["y"] = 19, ["z"] = 6, ["name"] = "default:obsidianbrick"}, {["x"] = 5, ["meta"] = {["fields"] = {}, ["inventory"] = {}}, ["y"] = 19, ["z"] = 7, ["name"] = "default:obsidianbrick"}, {["x"] = 5, ["meta"] = {["fields"] = {}, ["inventory"] = {}}, ["y"] = 19, ["z"] = 10, ["name"] = "default:obsidianbrick"}, {["x"] = 5, ["meta"] = {["fields"] = {}, ["inventory"] = {}}, ["y"] = 19, ["z"] = 11, ["name"] = "default:obsidianbrick"}, {["x"] = 5, ["meta"] = {["fields"] = {}, ["inventory"] = {}}, ["param2"] = 15, ["y"] = 19, ["z"] = 12, ["name"] = "default:lava_flowing"}, {["x"] = 5, ["meta"] = {["fields"] = {}, ["inventory"] = {}}, ["param2"] = 15, ["y"] = 20, ["z"] = 5, ["name"] = "default:lava_flowing"}, {["x"] = 5, ["meta"] = {["fields"] = {}, ["inventory"] = {}}, ["y"] = 20, ["z"] = 6, ["name"] = "default:obsidianbrick"}, {["x"] = 5, ["meta"] = {["fields"] = {}, ["inventory"] = {}}, ["y"] = 20, ["z"] = 7, ["name"] = "default:obsidianbrick"}, {["x"] = 5, ["meta"] = {["fields"] = {}, ["inventory"] = {}}, ["y"] = 20, ["z"] = 10, ["name"] = "default:obsidianbrick"}, {["x"] = 5, ["meta"] = {["fields"] = {}, ["inventory"] = {}}, ["y"] = 20, ["z"] = 11, ["name"] = "default:obsidianbrick"}, {["x"] = 5, ["meta"] = {["fields"] = {}, ["inventory"] = {}}, ["param2"] = 15, ["y"] = 20, ["z"] = 12, ["name"] = "default:lava_flowing"}, {["x"] = 5, ["meta"] = {["fields"] = {}, ["inventory"] = {}}, ["param2"] = 15, ["y"] = 21, ["z"] = 5, ["name"] = "default:lava_flowing"}, {["x"] = 5, ["meta"] = {["fields"] = {}, ["inventory"] = {}}, ["y"] = 21, ["z"] = 6, ["name"] = "default:obsidianbrick"}, {["x"] = 5, ["meta"] = {["fields"] = {}, ["inventory"] = {}}, ["y"] = 21, ["z"] = 7, ["name"] = "default:obsidianbrick"}, {["x"] = 5, ["meta"] = {["fields"] = {}, ["inventory"] = {}}, ["y"] = 21, ["z"] = 10, ["name"] = "default:obsidianbrick"}, {["x"] = 5, ["meta"] = {["fields"] = {}, ["inventory"] = {}}, ["y"] = 21, ["z"] = 11, ["name"] = "default:obsidianbrick"}, {["x"] = 5, ["meta"] = {["fields"] = {}, ["inventory"] = {}}, ["param2"] = 15, ["y"] = 21, ["z"] = 12, ["name"] = "default:lava_flowing"}, {["x"] = 5, ["meta"] = {["fields"] = {}, ["inventory"] = {}}, ["param2"] = 15, ["y"] = 22, ["z"] = 5, ["name"] = "default:lava_flowing"}, {["x"] = 5, ["meta"] = {["fields"] = {}, ["inventory"] = {}}, ["y"] = 22, ["z"] = 6, ["name"] = "default:obsidianbrick"}, {["x"] = 5, ["meta"] = {["fields"] = {}, ["inventory"] = {}}, ["y"] = 22, ["z"] = 7, ["name"] = "default:obsidianbrick"}, {["x"] = 5, ["meta"] = {["fields"] = {}, ["inventory"] = {}}, ["y"] = 22, ["z"] = 10, ["name"] = "default:obsidianbrick"}, {["x"] = 5, ["meta"] = {["fields"] = {}, ["inventory"] = {}}, ["y"] = 22, ["z"] = 11, ["name"] = "default:obsidianbrick"}, {["x"] = 5, ["meta"] = {["fields"] = {}, ["inventory"] = {}}, ["param2"] = 15, ["y"] = 22, ["z"] = 12, ["name"] = "default:lava_flowing"}, {["x"] = 5, ["meta"] = {["fields"] = {}, ["inventory"] = {}}, ["param2"] = 15, ["y"] = 23, ["z"] = 5, ["name"] = "default:lava_flowing"}, {["x"] = 5, ["meta"] = {["fields"] = {}, ["inventory"] = {}}, ["y"] = 23, ["z"] = 6, ["name"] = "default:obsidianbrick"}, {["x"] = 5, ["meta"] = {["fields"] = {}, ["inventory"] = {}}, ["y"] = 23, ["z"] = 7, ["name"] = "default:obsidianbrick"}, {["x"] = 5, ["meta"] = {["fields"] = {}, ["inventory"] = {}}, ["y"] = 23, ["z"] = 10, ["name"] = "default:obsidianbrick"}, {["x"] = 5, ["meta"] = {["fields"] = {}, ["inventory"] = {}}, ["y"] = 23, ["z"] = 11, ["name"] = "default:obsidianbrick"}, {["x"] = 5, ["meta"] = {["fields"] = {}, ["inventory"] = {}}, ["param2"] = 15, ["y"] = 23, ["z"] = 12, ["name"] = "default:lava_flowing"}, {["x"] = 5, ["meta"] = {["fields"] = {}, ["inventory"] = {}}, ["param2"] = 15, ["y"] = 24, ["z"] = 5, ["name"] = "default:lava_flowing"}, {["x"] = 5, ["meta"] = {["fields"] = {}, ["inventory"] = {}}, ["y"] = 24, ["z"] = 6, ["name"] = "default:obsidianbrick"}, {["x"] = 5, ["meta"] = {["fields"] = {}, ["inventory"] = {}}, ["y"] = 24, ["z"] = 7, ["name"] = "default:obsidianbrick"}, {["x"] = 5, ["meta"] = {["fields"] = {}, ["inventory"] = {}}, ["y"] = 24, ["z"] = 10, ["name"] = "default:obsidianbrick"}, {["x"] = 5, ["meta"] = {["fields"] = {}, ["inventory"] = {}}, ["y"] = 24, ["z"] = 11, ["name"] = "default:obsidianbrick"}, {["x"] = 5, ["meta"] = {["fields"] = {}, ["inventory"] = {}}, ["param2"] = 15, ["y"] = 24, ["z"] = 12, ["name"] = "default:lava_flowing"}, {["x"] = 5, ["meta"] = {["fields"] = {}, ["inventory"] = {}}, ["param2"] = 15, ["y"] = 25, ["z"] = 5, ["name"] = "default:lava_flowing"}, {["x"] = 5, ["meta"] = {["fields"] = {}, ["inventory"] = {}}, ["y"] = 25, ["z"] = 6, ["name"] = "default:obsidianbrick"}, {["x"] = 5, ["meta"] = {["fields"] = {}, ["inventory"] = {}}, ["y"] = 25, ["z"] = 7, ["name"] = "default:obsidianbrick"}, {["x"] = 5, ["meta"] = {["fields"] = {}, ["inventory"] = {}}, ["y"] = 25, ["z"] = 10, ["name"] = "default:obsidianbrick"}, {["x"] = 5, ["meta"] = {["fields"] = {}, ["inventory"] = {}}, ["y"] = 25, ["z"] = 11, ["name"] = "default:obsidianbrick"}, {["x"] = 5, ["meta"] = {["fields"] = {}, ["inventory"] = {}}, ["param2"] = 15, ["y"] = 25, ["z"] = 12, ["name"] = "default:lava_flowing"}, {["x"] = 5, ["meta"] = {["fields"] = {}, ["inventory"] = {}}, ["param2"] = 15, ["y"] = 26, ["z"] = 5, ["name"] = "default:lava_flowing"}, {["x"] = 5, ["meta"] = {["fields"] = {}, ["inventory"] = {}}, ["y"] = 26, ["z"] = 6, ["name"] = "default:obsidianbrick"}, {["x"] = 5, ["meta"] = {["fields"] = {}, ["inventory"] = {}}, ["y"] = 26, ["z"] = 7, ["name"] = "default:obsidianbrick"}, {["x"] = 5, ["meta"] = {["fields"] = {}, ["inventory"] = {}}, ["y"] = 26, ["z"] = 10, ["name"] = "default:obsidianbrick"}, {["x"] = 5, ["meta"] = {["fields"] = {}, ["inventory"] = {}}, ["y"] = 26, ["z"] = 11, ["name"] = "default:obsidianbrick"}, {["x"] = 5, ["meta"] = {["fields"] = {}, ["inventory"] = {}}, ["param2"] = 15, ["y"] = 26, ["z"] = 12, ["name"] = "default:lava_flowing"}, {["x"] = 5, ["meta"] = {["fields"] = {}, ["inventory"] = {}}, ["param2"] = 15, ["y"] = 27, ["z"] = 5, ["name"] = "default:lava_flowing"}, {["x"] = 5, ["meta"] = {["fields"] = {}, ["inventory"] = {}}, ["y"] = 27, ["z"] = 6, ["name"] = "default:obsidianbrick"}, {["x"] = 5, ["meta"] = {["fields"] = {}, ["inventory"] = {}}, ["y"] = 27, ["z"] = 7, ["name"] = "default:obsidianbrick"}, {["x"] = 5, ["meta"] = {["fields"] = {}, ["inventory"] = {}}, ["y"] = 27, ["z"] = 10, ["name"] = "default:obsidianbrick"}, {["x"] = 5, ["meta"] = {["fields"] = {}, ["inventory"] = {}}, ["y"] = 27, ["z"] = 11, ["name"] = "default:obsidianbrick"}, {["x"] = 5, ["meta"] = {["fields"] = {}, ["inventory"] = {}}, ["param2"] = 15, ["y"] = 27, ["z"] = 12, ["name"] = "default:lava_flowing"}, {["x"] = 5, ["meta"] = {["fields"] = {}, ["inventory"] = {}}, ["param2"] = 15, ["y"] = 28, ["z"] = 5, ["name"] = "default:lava_flowing"}, {["x"] = 5, ["meta"] = {["fields"] = {}, ["inventory"] = {}}, ["y"] = 28, ["z"] = 6, ["name"] = "default:obsidianbrick"}, {["x"] = 5, ["meta"] = {["fields"] = {}, ["inventory"] = {}}, ["y"] = 28, ["z"] = 7, ["name"] = "default:obsidianbrick"}, {["x"] = 5, ["meta"] = {["fields"] = {}, ["inventory"] = {}}, ["y"] = 28, ["z"] = 8, ["name"] = "default:obsidianbrick"}, {["x"] = 5, ["meta"] = {["fields"] = {}, ["inventory"] = {}}, ["y"] = 28, ["z"] = 9, ["name"] = "default:obsidianbrick"}, {["x"] = 5, ["meta"] = {["fields"] = {}, ["inventory"] = {}}, ["y"] = 28, ["z"] = 10, ["name"] = "default:obsidianbrick"}, {["x"] = 5, ["meta"] = {["fields"] = {}, ["inventory"] = {}}, ["y"] = 28, ["z"] = 11, ["name"] = "default:obsidianbrick"}, {["x"] = 5, ["meta"] = {["fields"] = {}, ["inventory"] = {}}, ["param2"] = 15, ["y"] = 28, ["z"] = 12, ["name"] = "default:lava_flowing"}, {["x"] = 5, ["meta"] = {["fields"] = {}, ["inventory"] = {}}, ["param2"] = 14, ["y"] = 29, ["z"] = 5, ["name"] = "default:lava_flowing"}, {["x"] = 5, ["meta"] = {["fields"] = {}, ["inventory"] = {}}, ["param2"] = 7, ["y"] = 29, ["z"] = 6, ["name"] = "default:lava_flowing"}, {["x"] = 5, ["meta"] = {["fields"] = {}, ["inventory"] = {}}, ["y"] = 29, ["z"] = 7, ["name"] = "default:obsidianbrick"}, {["x"] = 5, ["meta"] = {["fields"] = {}, ["inventory"] = {}}, ["y"] = 29, ["z"] = 8, ["name"] = "default:obsidianbrick"}, {["x"] = 5, ["meta"] = {["fields"] = {}, ["inventory"] = {}}, ["y"] = 29, ["z"] = 9, ["name"] = "default:obsidianbrick"}, {["x"] = 5, ["meta"] = {["fields"] = {}, ["inventory"] = {}}, ["y"] = 29, ["z"] = 10, ["name"] = "default:obsidianbrick"}, {["x"] = 5, ["meta"] = {["fields"] = {}, ["inventory"] = {}}, ["param2"] = 7, ["y"] = 29, ["z"] = 11, ["name"] = "default:lava_flowing"}, {["x"] = 5, ["meta"] = {["fields"] = {}, ["inventory"] = {}}, ["param2"] = 14, ["y"] = 29, ["z"] = 12, ["name"] = "default:lava_flowing"}, {["x"] = 5, ["meta"] = {["fields"] = {}, ["inventory"] = {}}, ["param2"] = 15, ["y"] = 30, ["z"] = 6, ["name"] = "default:lava_flowing"}, {["x"] = 5, ["meta"] = {["fields"] = {}, ["inventory"] = {}}, ["y"] = 30, ["z"] = 7, ["name"] = "default:obsidianbrick"}, {["x"] = 5, ["meta"] = {["fields"] = {}, ["inventory"] = {}}, ["y"] = 30, ["z"] = 8, ["name"] = "default:obsidianbrick"}, {["x"] = 5, ["meta"] = {["fields"] = {}, ["inventory"] = {}}, ["y"] = 30, ["z"] = 9, ["name"] = "default:obsidianbrick"}, {["x"] = 5, ["meta"] = {["fields"] = {}, ["inventory"] = {}}, ["y"] = 30, ["z"] = 10, ["name"] = "default:obsidianbrick"}, {["x"] = 5, ["meta"] = {["fields"] = {}, ["inventory"] = {}}, ["param2"] = 15, ["y"] = 30, ["z"] = 11, ["name"] = "default:lava_flowing"}, {["x"] = 5, ["meta"] = {["fields"] = {}, ["inventory"] = {}}, ["param2"] = 15, ["y"] = 31, ["z"] = 6, ["name"] = "default:lava_flowing"}, {["x"] = 5, ["meta"] = {["fields"] = {}, ["inventory"] = {}}, ["y"] = 31, ["z"] = 7, ["name"] = "default:obsidianbrick"}, {["x"] = 5, ["meta"] = {["fields"] = {}, ["inventory"] = {}}, ["y"] = 31, ["z"] = 8, ["name"] = "default:obsidianbrick"}, {["x"] = 5, ["meta"] = {["fields"] = {}, ["inventory"] = {}}, ["y"] = 31, ["z"] = 9, ["name"] = "default:obsidianbrick"}, {["x"] = 5, ["meta"] = {["fields"] = {}, ["inventory"] = {}}, ["y"] = 31, ["z"] = 10, ["name"] = "default:obsidianbrick"}, {["x"] = 5, ["meta"] = {["fields"] = {}, ["inventory"] = {}}, ["param2"] = 15, ["y"] = 31, ["z"] = 11, ["name"] = "default:lava_flowing"}, {["x"] = 5, ["meta"] = {["fields"] = {}, ["inventory"] = {}}, ["param2"] = 15, ["y"] = 32, ["z"] = 6, ["name"] = "default:lava_flowing"}, {["x"] = 5, ["meta"] = {["fields"] = {}, ["inventory"] = {}}, ["y"] = 32, ["z"] = 7, ["name"] = "default:obsidianbrick"}, {["x"] = 5, ["meta"] = {["fields"] = {}, ["inventory"] = {}}, ["y"] = 32, ["z"] = 8, ["name"] = "default:obsidianbrick"}, {["x"] = 5, ["meta"] = {["fields"] = {}, ["inventory"] = {}}, ["y"] = 32, ["z"] = 9, ["name"] = "default:obsidianbrick"}, {["x"] = 5, ["meta"] = {["fields"] = {}, ["inventory"] = {}}, ["y"] = 32, ["z"] = 10, ["name"] = "default:obsidianbrick"}, {["x"] = 5, ["meta"] = {["fields"] = {}, ["inventory"] = {}}, ["param2"] = 15, ["y"] = 32, ["z"] = 11, ["name"] = "default:lava_flowing"}, {["x"] = 5, ["meta"] = {["fields"] = {}, ["inventory"] = {}}, ["param2"] = 15, ["y"] = 33, ["z"] = 6, ["name"] = "default:lava_flowing"}, {["x"] = 5, ["meta"] = {["fields"] = {}, ["inventory"] = {}}, ["y"] = 33, ["z"] = 7, ["name"] = "default:obsidianbrick"}, {["x"] = 5, ["meta"] = {["fields"] = {}, ["inventory"] = {}}, ["y"] = 33, ["z"] = 8, ["name"] = "default:obsidianbrick"}, {["x"] = 5, ["meta"] = {["fields"] = {}, ["inventory"] = {}}, ["y"] = 33, ["z"] = 9, ["name"] = "default:obsidianbrick"}, {["x"] = 5, ["meta"] = {["fields"] = {}, ["inventory"] = {}}, ["y"] = 33, ["z"] = 10, ["name"] = "default:obsidianbrick"}, {["x"] = 5, ["meta"] = {["fields"] = {}, ["inventory"] = {}}, ["param2"] = 15, ["y"] = 33, ["z"] = 11, ["name"] = "default:lava_flowing"}, {["x"] = 5, ["meta"] = {["fields"] = {}, ["inventory"] = {}}, ["param2"] = 15, ["y"] = 34, ["z"] = 6, ["name"] = "default:lava_flowing"}, {["x"] = 5, ["meta"] = {["fields"] = {}, ["inventory"] = {}}, ["y"] = 34, ["z"] = 7, ["name"] = "default:obsidianbrick"}, {["x"] = 5, ["meta"] = {["fields"] = {}, ["inventory"] = {}}, ["y"] = 34, ["z"] = 8, ["name"] = "default:obsidianbrick"}, {["x"] = 5, ["meta"] = {["fields"] = {}, ["inventory"] = {}}, ["y"] = 34, ["z"] = 9, ["name"] = "default:obsidianbrick"}, {["x"] = 5, ["meta"] = {["fields"] = {}, ["inventory"] = {}}, ["y"] = 34, ["z"] = 10, ["name"] = "default:obsidianbrick"}, {["x"] = 5, ["meta"] = {["fields"] = {}, ["inventory"] = {}}, ["param2"] = 15, ["y"] = 34, ["z"] = 11, ["name"] = "default:lava_flowing"}, {["x"] = 5, ["meta"] = {["fields"] = {}, ["inventory"] = {}}, ["y"] = 35, ["z"] = 4, ["name"] = "default:obsidianbrick"}, {["x"] = 5, ["meta"] = {["fields"] = {}, ["inventory"] = {}}, ["y"] = 35, ["z"] = 5, ["name"] = "default:obsidianbrick"}, {["x"] = 5, ["meta"] = {["fields"] = {}, ["inventory"] = {}}, ["y"] = 35, ["z"] = 6, ["name"] = "default:lava_source"}, {["x"] = 5, ["meta"] = {["fields"] = {}, ["inventory"] = {}}, ["y"] = 35, ["z"] = 7, ["name"] = "default:obsidianbrick"}, {["x"] = 5, ["meta"] = {["fields"] = {}, ["inventory"] = {}}, ["y"] = 35, ["z"] = 8, ["name"] = "default:obsidianbrick"}, {["x"] = 5, ["meta"] = {["fields"] = {}, ["inventory"] = {}}, ["y"] = 35, ["z"] = 9, ["name"] = "default:obsidianbrick"}, {["x"] = 5, ["meta"] = {["fields"] = {}, ["inventory"] = {}}, ["y"] = 35, ["z"] = 10, ["name"] = "default:obsidianbrick"}, {["x"] = 5, ["meta"] = {["fields"] = {}, ["inventory"] = {}}, ["y"] = 35, ["z"] = 11, ["name"] = "default:lava_source"}, {["x"] = 5, ["meta"] = {["fields"] = {}, ["inventory"] = {}}, ["y"] = 35, ["z"] = 12, ["name"] = "default:obsidianbrick"}, {["x"] = 5, ["meta"] = {["fields"] = {}, ["inventory"] = {}}, ["y"] = 35, ["z"] = 13, ["name"] = "default:obsidianbrick"}, {["x"] = 5, ["meta"] = {["fields"] = {}, ["inventory"] = {}}, ["y"] = 36, ["z"] = 5, ["name"] = "default:obsidianbrick"}, {["x"] = 5, ["meta"] = {["fields"] = {}, ["inventory"] = {}}, ["y"] = 36, ["z"] = 12, ["name"] = "default:obsidianbrick"}, {["x"] = 6, ["meta"] = {["fields"] = {}, ["inventory"] = {}}, ["y"] = 0, ["z"] = 0, ["name"] = "default:dirt"}, {["x"] = 6, ["meta"] = {["fields"] = {}, ["inventory"] = {}}, ["y"] = 0, ["z"] = 1, ["name"] = "default:dirt"}, {["x"] = 6, ["meta"] = {["fields"] = {}, ["inventory"] = {}}, ["y"] = 0, ["z"] = 2, ["name"] = "default:dirt"}, {["x"] = 6, ["meta"] = {["fields"] = {}, ["inventory"] = {}}, ["y"] = 0, ["z"] = 3, ["name"] = "default:dirt"}, {["x"] = 6, ["meta"] = {["fields"] = {}, ["inventory"] = {}}, ["y"] = 0, ["z"] = 4, ["name"] = "default:dirt"}, {["x"] = 6, ["meta"] = {["fields"] = {}, ["inventory"] = {}}, ["y"] = 0, ["z"] = 5, ["name"] = "default:dirt"}, {["x"] = 6, ["meta"] = {["fields"] = {}, ["inventory"] = {}}, ["y"] = 0, ["z"] = 6, ["name"] = "default:dirt"}, {["x"] = 6, ["meta"] = {["fields"] = {}, ["inventory"] = {}}, ["y"] = 0, ["z"] = 7, ["name"] = "default:dirt"}, {["x"] = 6, ["meta"] = {["fields"] = {}, ["inventory"] = {}}, ["y"] = 0, ["z"] = 8, ["name"] = "default:dirt"}, {["x"] = 6, ["meta"] = {["fields"] = {}, ["inventory"] = {}}, ["y"] = 0, ["z"] = 9, ["name"] = "default:dirt"}, {["x"] = 6, ["meta"] = {["fields"] = {}, ["inventory"] = {}}, ["y"] = 0, ["z"] = 10, ["name"] = "default:dirt"}, {["x"] = 6, ["meta"] = {["fields"] = {}, ["inventory"] = {}}, ["y"] = 0, ["z"] = 11, ["name"] = "default:dirt"}, {["x"] = 6, ["meta"] = {["fields"] = {}, ["inventory"] = {}}, ["y"] = 0, ["z"] = 12, ["name"] = "default:dirt"}, {["x"] = 6, ["meta"] = {["fields"] = {}, ["inventory"] = {}}, ["y"] = 0, ["z"] = 13, ["name"] = "default:stone"}, {["x"] = 6, ["meta"] = {["fields"] = {}, ["inventory"] = {}}, ["y"] = 0, ["z"] = 14, ["name"] = "default:dirt"}, {["x"] = 6, ["meta"] = {["fields"] = {}, ["inventory"] = {}}, ["y"] = 0, ["z"] = 15, ["name"] = "default:dirt"}, {["x"] = 6, ["meta"] = {["fields"] = {}, ["inventory"] = {}}, ["y"] = 1, ["z"] = 0, ["name"] = "default:dirt_with_grass"}, {["x"] = 6, ["meta"] = {["fields"] = {}, ["inventory"] = {}}, ["y"] = 1, ["z"] = 1, ["name"] = "default:dirt_with_grass"}, {["x"] = 6, ["meta"] = {["fields"] = {}, ["inventory"] = {}}, ["y"] = 1, ["z"] = 2, ["name"] = "default:dirt"}, {["x"] = 6, ["meta"] = {["fields"] = {}, ["inventory"] = {}}, ["y"] = 1, ["z"] = 3, ["name"] = "default:dirt"}, {["x"] = 6, ["meta"] = {["fields"] = {}, ["inventory"] = {}}, ["y"] = 1, ["z"] = 4, ["name"] = "default:dirt"}, {["x"] = 6, ["meta"] = {["fields"] = {}, ["inventory"] = {}}, ["y"] = 1, ["z"] = 5, ["name"] = "default:dirt"}, {["x"] = 6, ["meta"] = {["fields"] = {}, ["inventory"] = {}}, ["y"] = 1, ["z"] = 6, ["name"] = "default:dirt"}, {["x"] = 6, ["meta"] = {["fields"] = {}, ["inventory"] = {}}, ["y"] = 1, ["z"] = 7, ["name"] = "default:dirt"}, {["x"] = 6, ["meta"] = {["fields"] = {}, ["inventory"] = {}}, ["y"] = 1, ["z"] = 8, ["name"] = "default:dirt"}, {["x"] = 6, ["meta"] = {["fields"] = {}, ["inventory"] = {}}, ["y"] = 1, ["z"] = 9, ["name"] = "default:dirt"}, {["x"] = 6, ["meta"] = {["fields"] = {}, ["inventory"] = {}}, ["y"] = 1, ["z"] = 10, ["name"] = "default:dirt"}, {["x"] = 6, ["meta"] = {["fields"] = {}, ["inventory"] = {}}, ["y"] = 1, ["z"] = 11, ["name"] = "default:dirt"}, {["x"] = 6, ["meta"] = {["fields"] = {}, ["inventory"] = {}}, ["y"] = 1, ["z"] = 12, ["name"] = "default:dirt"}, {["x"] = 6, ["meta"] = {["fields"] = {}, ["inventory"] = {}}, ["y"] = 1, ["z"] = 13, ["name"] = "default:dirt"}, {["x"] = 6, ["meta"] = {["fields"] = {}, ["inventory"] = {}}, ["y"] = 1, ["z"] = 14, ["name"] = "default:dirt"}, {["x"] = 6, ["meta"] = {["fields"] = {}, ["inventory"] = {}}, ["y"] = 1, ["z"] = 15, ["name"] = "default:obsidianbrick"}, {["x"] = 6, ["meta"] = {["fields"] = {}, ["inventory"] = {}}, ["y"] = 2, ["z"] = 2, ["name"] = "default:obsidianbrick"}, {["x"] = 6, ["meta"] = {["fields"] = {}, ["inventory"] = {}}, ["param2"] = 6, ["y"] = 2, ["z"] = 3, ["name"] = "default:lava_flowing"}, {["x"] = 6, ["meta"] = {["fields"] = {}, ["inventory"] = {}}, ["param2"] = 7, ["y"] = 2, ["z"] = 4, ["name"] = "default:lava_flowing"}, {["x"] = 6, ["meta"] = {["fields"] = {}, ["inventory"] = {}}, ["y"] = 2, ["z"] = 5, ["name"] = "default:dirt"}, {["x"] = 6, ["meta"] = {["fields"] = {}, ["inventory"] = {}}, ["y"] = 2, ["z"] = 6, ["name"] = "default:dirt"}, {["x"] = 6, ["meta"] = {["fields"] = {}, ["inventory"] = {}}, ["y"] = 2, ["z"] = 7, ["name"] = "default:dirt_with_grass"}, {["x"] = 6, ["meta"] = {["fields"] = {}, ["inventory"] = {}}, ["y"] = 2, ["z"] = 8, ["name"] = "default:dirt_with_grass"}, {["x"] = 6, ["meta"] = {["fields"] = {}, ["inventory"] = {}}, ["y"] = 2, ["z"] = 9, ["name"] = "default:dirt_with_grass"}, {["x"] = 6, ["meta"] = {["fields"] = {}, ["inventory"] = {}}, ["y"] = 2, ["z"] = 10, ["name"] = "default:dirt_with_grass"}, {["x"] = 6, ["meta"] = {["fields"] = {}, ["inventory"] = {}}, ["y"] = 2, ["z"] = 11, ["name"] = "default:dirt"}, {["x"] = 6, ["meta"] = {["fields"] = {}, ["inventory"] = {}}, ["y"] = 2, ["z"] = 12, ["name"] = "default:dirt"}, {["x"] = 6, ["meta"] = {["fields"] = {}, ["inventory"] = {}}, ["param2"] = 7, ["y"] = 2, ["z"] = 13, ["name"] = "default:lava_flowing"}, {["x"] = 6, ["meta"] = {["fields"] = {}, ["inventory"] = {}}, ["param2"] = 6, ["y"] = 2, ["z"] = 14, ["name"] = "default:lava_flowing"}, {["x"] = 6, ["meta"] = {["fields"] = {}, ["inventory"] = {}}, ["y"] = 2, ["z"] = 15, ["name"] = "default:obsidianbrick"}, {["x"] = 6, ["meta"] = {["fields"] = {}, ["inventory"] = {}}, ["param2"] = 15, ["y"] = 3, ["z"] = 4, ["name"] = "default:lava_flowing"}, {["x"] = 6, ["meta"] = {["fields"] = {}, ["inventory"] = {}}, ["y"] = 3, ["z"] = 5, ["name"] = "default:obsidian"}, {["x"] = 6, ["meta"] = {["fields"] = {}, ["inventory"] = {}}, ["y"] = 3, ["z"] = 6, ["name"] = "default:obsidian"}, {["x"] = 6, ["meta"] = {["fields"] = {}, ["inventory"] = {}}, ["y"] = 3, ["z"] = 11, ["name"] = "default:obsidian"}, {["x"] = 6, ["meta"] = {["fields"] = {}, ["inventory"] = {}}, ["y"] = 3, ["z"] = 12, ["name"] = "default:obsidian"}, {["x"] = 6, ["meta"] = {["fields"] = {}, ["inventory"] = {}}, ["param2"] = 15, ["y"] = 3, ["z"] = 13, ["name"] = "default:lava_flowing"}, {["x"] = 6, ["meta"] = {["fields"] = {}, ["inventory"] = {}}, ["param2"] = 15, ["y"] = 4, ["z"] = 4, ["name"] = "default:lava_flowing"}, {["x"] = 6, ["meta"] = {["fields"] = {}, ["inventory"] = {}}, ["y"] = 4, ["z"] = 5, ["name"] = "default:obsidian"}, {["x"] = 6, ["meta"] = {["fields"] = {}, ["inventory"] = {}}, ["y"] = 4, ["z"] = 6, ["name"] = "default:obsidian"}, {["x"] = 6, ["meta"] = {["fields"] = {}, ["inventory"] = {}}, ["y"] = 4, ["z"] = 11, ["name"] = "default:obsidian"}, {["x"] = 6, ["meta"] = {["fields"] = {}, ["inventory"] = {}}, ["y"] = 4, ["z"] = 12, ["name"] = "default:obsidian"}, {["x"] = 6, ["meta"] = {["fields"] = {}, ["inventory"] = {}}, ["param2"] = 15, ["y"] = 4, ["z"] = 13, ["name"] = "default:lava_flowing"}, {["x"] = 6, ["meta"] = {["fields"] = {}, ["inventory"] = {}}, ["param2"] = 15, ["y"] = 5, ["z"] = 4, ["name"] = "default:lava_flowing"}, {["x"] = 6, ["meta"] = {["fields"] = {}, ["inventory"] = {}}, ["y"] = 5, ["z"] = 5, ["name"] = "default:obsidianbrick"}, {["x"] = 6, ["meta"] = {["fields"] = {}, ["inventory"] = {}}, ["y"] = 5, ["z"] = 6, ["name"] = "default:obsidianbrick"}, {["x"] = 6, ["meta"] = {["fields"] = {}, ["inventory"] = {}}, ["y"] = 5, ["z"] = 11, ["name"] = "default:obsidianbrick"}, {["x"] = 6, ["meta"] = {["fields"] = {}, ["inventory"] = {}}, ["y"] = 5, ["z"] = 12, ["name"] = "default:obsidianbrick"}, {["x"] = 6, ["meta"] = {["fields"] = {}, ["inventory"] = {}}, ["param2"] = 15, ["y"] = 5, ["z"] = 13, ["name"] = "default:lava_flowing"}, {["x"] = 6, ["meta"] = {["fields"] = {}, ["inventory"] = {}},