5:return {{["x"] = 0, ["meta"] = {["fields"] = {}, ["inventory"] = {}}, ["param2"] = 1, ["y"] = 0, ["param1"] = 94, ["z"] = 4, ["name"] = "rainbow:slope_render_white_outer"}, {["x"] = 0, ["meta"] = {["fields"] = {}, ["inventory"] = {}}, ["param2"] = 2, ["y"] = 0, ["param1"] = 111, ["z"] = 5, ["name"] = "moreblocks:slope_steelblock_outer"}, {["x"] = 0, ["meta"] = {["fields"] = {}, ["inventory"] = {}}, ["param2"] = 1, ["y"] = 0, ["param1"] = 111, ["z"] = 7, ["name"] = "moreblocks:slope_steelblock_outer"}, {["x"] = 0, ["meta"] = {["fields"] = {}, ["inventory"] = {}}, ["param2"] = 2, ["y"] = 0, ["param1"] = 94, ["z"] = 8, ["name"] = "rainbow:slope_render_white_outer"}, {["x"] = 0, ["meta"] = {["fields"] = {["infotext"] = "Marker at (42,223,-18) (placed by Nigel). Right-click to update.", ["time"] = "1495489776", ["owner"] = "Nigel"}, ["inventory"] = {}}, ["param2"] = 1, ["y"] = 0, ["param1"] = 30, ["z"] = 12, ["name"] = "markers:mark"}, {["x"] = 1, ["meta"] = {["fields"] = {}, ["inventory"] = {}}, ["param2"] = 1, ["y"] = 0, ["param1"] = 62, ["z"] = 3, ["name"] = "rainbow:slope_render_white_outer"}, {["x"] = 1, ["meta"] = {["fields"] = {}, ["inventory"] = {}}, ["y"] = 0, ["param1"] = 111, ["z"] = 4, ["name"] = "rainbow:render_white"}, {["x"] = 1, ["meta"] = {["fields"] = {}, ["inventory"] = {}}, ["param2"] = 2, ["y"] = 0, ["param1"] = 126, ["z"] = 5, ["name"] = "rainbow:slope_render_white"}, {["x"] = 1, ["meta"] = {["fields"] = {}, ["inventory"] = {}}, ["y"] = 0, ["param1"] = 126, ["z"] = 7, ["name"] = "rainbow:slope_render_white"}, {["x"] = 1, ["meta"] = {["fields"] = {}, ["inventory"] = {}}, ["y"] = 0, ["param1"] = 111, ["z"] = 8, ["name"] = "rainbow:render_white"}, {["x"] = 1, ["meta"] = {["fields"] = {}, ["inventory"] = {}}, ["param2"] = 2, ["y"] = 0, ["param1"] = 62, ["z"] = 9, ["name"] = "rainbow:slope_render_white_outer"}, {["x"] = 1, ["meta"] = {["fields"] = {}, ["inventory"] = {}}, ["y"] = 1, ["param1"] = 95, ["z"] = 4, ["name"] = "rainbow:render_white"}, {["x"] = 1, ["meta"] = {["fields"] = {}, ["inventory"] = {}}, ["y"] = 1, ["param1"] = 95, ["z"] = 8, ["name"] = "rainbow:render_white"}, {["x"] = 1, ["meta"] = {["fields"] = {}, ["inventory"] = {}}, ["y"] = 2, ["param1"] = 79, ["z"] = 4, ["name"] = "rainbow:render_white"}, {["x"] = 1, ["meta"] = {["fields"] = {}, ["inventory"] = {}}, ["param2"] = 22, ["y"] = 2, ["param1"] = 94, ["z"] = 5, ["name"] = "rainbow:slope_render_white"}, {["x"] = 1, ["meta"] = {["fields"] = {}, ["inventory"] = {}}, ["param2"] = 20, ["y"] = 2, ["param1"] = 94, ["z"] = 7, ["name"] = "rainbow:slope_render_white"}, {["x"] = 1, ["meta"] = {["fields"] = {}, ["inventory"] = {}}, ["y"] = 2, ["param1"] = 79, ["z"] = 8, ["name"] = "rainbow:render_white"}, {["x"] = 1, ["meta"] = {["fields"] = {}, ["inventory"] = {}}, ["y"] = 3, ["param1"] = 63, ["z"] = 4, ["name"] = "rainbow:render_white"}, {["x"] = 1, ["meta"] = {["fields"] = {}, ["inventory"] = {}}, ["y"] = 3, ["param1"] = 79, ["z"] = 5, ["name"] = "rainbow:render_white"}, {["x"] = 1, ["meta"] = {["fields"] = {}, ["inventory"] = {}}, ["y"] = 3, ["z"] = 6, ["name"] = "rainbow:render_white"}, {["x"] = 1, ["meta"] = {["fields"] = {}, ["inventory"] = {}}, ["y"] = 3, ["param1"] = 79, ["z"] = 7, ["name"] = "rainbow:render_white"}, {["x"] = 1, ["meta"] = {["fields"] = {}, ["inventory"] = {}}, ["y"] = 3, ["param1"] = 63, ["z"] = 8, ["name"] = "rainbow:render_white"}, {["x"] = 1, ["meta"] = {["fields"] = {}, ["inventory"] = {}}, ["y"] = 4, ["param1"] = 47, ["z"] = 4, ["name"] = "rainbow:render_white"}, {["x"] = 1, ["meta"] = {["fields"] = {}, ["inventory"] = {}}, ["y"] = 4, ["param1"] = 63, ["z"] = 5, ["name"] = "rainbow:render_white"}, {["x"] = 1, ["meta"] = {["fields"] = {}, ["inventory"] = {}}, ["y"] = 4, ["param1"] = 79, ["z"] = 6, ["name"] = "rainbow:render_white"}, {["x"] = 1, ["meta"] = {["fields"] = {}, ["inventory"] = {}}, ["y"] = 4, ["param1"] = 63, ["z"] = 7, ["name"] = "rainbow:render_white"}, {["x"] = 1, ["meta"] = {["fields"] = {}, ["inventory"] = {}}, ["y"] = 4, ["param1"] = 47, ["z"] = 8, ["name"] = "rainbow:render_white"}, {["x"] = 1, ["meta"] = {["fields"] = {}, ["inventory"] = {}}, ["y"] = 5, ["param1"] = 111, ["z"] = 4, ["name"] = "rainbow:render_white"}, {["x"] = 1, ["meta"] = {["fields"] = {}, ["inventory"] = {}}, ["param2"] = 2, ["y"] = 5, ["param1"] = 46, ["z"] = 5, ["name"] = "rainbow:slope_render_white"}, {["x"] = 1, ["meta"] = {["fields"] = {}, ["inventory"] = {}}, ["y"] = 5, ["param1"] = 46, ["z"] = 7, ["name"] = "rainbow:slope_render_white"}, {["x"] = 1, ["meta"] = {["fields"] = {}, ["inventory"] = {}}, ["y"] = 5, ["param1"] = 111, ["z"] = 8, ["name"] = "rainbow:render_white"}, {["x"] = 1, ["meta"] = {["fields"] = {}, ["inventory"] = {}}, ["y"] = 6, ["param1"] = 95, ["z"] = 4, ["name"] = "rainbow:render_white"}, {["x"] = 1, ["meta"] = {["fields"] = {}, ["inventory"] = {}}, ["y"] = 6, ["param1"] = 95, ["z"] = 8, ["name"] = "rainbow:render_white"}, {["x"] = 1, ["meta"] = {["fields"] = {}, ["inventory"] = {}}, ["y"] = 7, ["param1"] = 79, ["z"] = 4, ["name"] = "rainbow:render_white"}, {["x"] = 1, ["meta"] = {["fields"] = {}, ["inventory"] = {}}, ["param2"] = 22, ["y"] = 7, ["param1"] = 14, ["z"] = 5, ["name"] = "rainbow:slope_render_white"}, {["x"] = 1, ["meta"] = {["fields"] = {}, ["inventory"] = {}}, ["param2"] = 20, ["y"] = 7, ["param1"] = 14, ["z"] = 7, ["name"] = "rainbow:slope_render_white"}, {["x"] = 1, ["meta"] = {["fields"] = {}, ["inventory"] = {}}, ["y"] = 7, ["param1"] = 79, ["z"] = 8, ["name"] = "rainbow:render_white"}, {["x"] = 1, ["meta"] = {["fields"] = {}, ["inventory"] = {}}, ["y"] = 8, ["param1"] = 63, ["z"] = 4, ["name"] = "rainbow:render_white"}, {["x"] = 1, ["meta"] = {["fields"] = {}, ["inventory"] = {}}, ["y"] = 8, ["param1"] = 79, ["z"] = 5, ["name"] = "rainbow:render_white"}, {["x"] = 1, ["meta"] = {["fields"] = {}, ["inventory"] = {}}, ["y"] = 8, ["z"] = 6, ["name"] = "rainbow:render_white"}, {["x"] = 1, ["meta"] = {["fields"] = {}, ["inventory"] = {}}, ["y"] = 8, ["param1"] = 79, ["z"] = 7, ["name"] = "rainbow:render_white"}, {["x"] = 1, ["meta"] = {["fields"] = {}, ["inventory"] = {}}, ["y"] = 8, ["param1"] = 63, ["z"] = 8, ["name"] = "rainbow:render_white"}, {["x"] = 1, ["meta"] = {["fields"] = {}, ["inventory"] = {}}, ["y"] = 9, ["param1"] = 47, ["z"] = 4, ["name"] = "rainbow:render_white"}, {["x"] = 1, ["meta"] = {["fields"] = {}, ["inventory"] = {}}, ["y"] = 9, ["param1"] = 63, ["z"] = 5, ["name"] = "rainbow:render_white"}, {["x"] = 1, ["meta"] = {["fields"] = {}, ["inventory"] = {}}, ["y"] = 9, ["param1"] = 79, ["z"] = 6, ["name"] = "rainbow:render_white"}, {["x"] = 1, ["meta"] = {["fields"] = {}, ["inventory"] = {}}, ["y"] = 9, ["param1"] = 63, ["z"] = 7, ["name"] = "rainbow:render_white"}, {["x"] = 1, ["meta"] = {["fields"] = {}, ["inventory"] = {}}, ["y"] = 9, ["param1"] = 47, ["z"] = 8, ["name"] = "rainbow:render_white"}, {["x"] = 1, ["meta"] = {["fields"] = {}, ["inventory"] = {}}, ["y"] = 10, ["param1"] = 111, ["z"] = 4, ["name"] = "rainbow:render_white"}, {["x"] = 1, ["meta"] = {["fields"] = {}, ["inventory"] = {}}, ["param2"] = 2, ["y"] = 10, ["param1"] = 14, ["z"] = 5, ["name"] = "rainbow:slope_render_white"}, {["x"] = 1, ["meta"] = {["fields"] = {}, ["inventory"] = {}}, ["y"] = 10, ["param1"] = 14, ["z"] = 7, ["name"] = "rainbow:slope_render_white"}, {["x"] = 1, ["meta"] = {["fields"] = {}, ["inventory"] = {}}, ["y"] = 10, ["param1"] = 111, ["z"] = 8, ["name"] = "rainbow:render_white"}, {["x"] = 1, ["meta"] = {["fields"] = {}, ["inventory"] = {}}, ["y"] = 11, ["param1"] = 95, ["z"] = 4, ["name"] = "rainbow:render_white"}, {["x"] = 1, ["meta"] = {["fields"] = {}, ["inventory"] = {}}, ["y"] = 11, ["param1"] = 95, ["z"] = 8, ["name"] = "rainbow:render_white"}, {["x"] = 1, ["meta"] = {["fields"] = {}, ["inventory"] = {}}, ["y"] = 12, ["param1"] = 79, ["z"] = 4, ["name"] = "rainbow:render_white"}, {["x"] = 1, ["meta"] = {["fields"] = {}, ["inventory"] = {}}, ["param2"] = 22, ["y"] = 12, ["param1"] = 14, ["z"] = 5, ["name"] = "rainbow:slope_render_white"}, {["x"] = 1, ["meta"] = {["fields"] = {}, ["inventory"] = {}}, ["param2"] = 20, ["y"] = 12, ["param1"] = 14, ["z"] = 7, ["name"] = "rainbow:slope_render_white"}, {["x"] = 1, ["meta"] = {["fields"] = {}, ["inventory"] = {}}, ["y"] = 12, ["param1"] = 79, ["z"] = 8, ["name"] = "rainbow:render_white"}, {["x"] = 1, ["meta"] = {["fields"] = {}, ["inventory"] = {}}, ["y"] = 13, ["param1"] = 63, ["z"] = 4, ["name"] = "rainbow:render_white"}, {["x"] = 1, ["meta"] = {["fields"] = {}, ["inventory"] = {}}, ["y"] = 13, ["param1"] = 79, ["z"] = 5, ["name"] = "rainbow:render_white"}, {["x"] = 1, ["meta"] = {["fields"] = {}, ["inventory"] = {}}, ["y"] = 13, ["z"] = 6, ["name"] = "rainbow:render_white"}, {["x"] = 1, ["meta"] = {["fields"] = {}, ["inventory"] = {}}, ["y"] = 13, ["param1"] = 79, ["z"] = 7, ["name"] = "rainbow:render_white"}, {["x"] = 1, ["meta"] = {["fields"] = {}, ["inventory"] = {}}, ["y"] = 13, ["param1"] = 63, ["z"] = 8, ["name"] = "rainbow:render_white"}, {["x"] = 1, ["meta"] = {["fields"] = {}, ["inventory"] = {}}, ["y"] = 14, ["param1"] = 47, ["z"] = 4, ["name"] = "rainbow:render_white"}, {["x"] = 1, ["meta"] = {["fields"] = {}, ["inventory"] = {}}, ["y"] = 14, ["param1"] = 63, ["z"] = 5, ["name"] = "rainbow:render_white"}, {["x"] = 1, ["meta"] = {["fields"] = {}, ["inventory"] = {}}, ["y"] = 14, ["param1"] = 79, ["z"] = 6, ["name"] = "rainbow:render_white"}, {["x"] = 1, ["meta"] = {["fields"] = {}, ["inventory"] = {}}, ["y"] = 14, ["param1"] = 63, ["z"] = 7, ["name"] = "rainbow:render_white"}, {["x"] = 1, ["meta"] = {["fields"] = {}, ["inventory"] = {}}, ["y"] = 14, ["param1"] = 47, ["z"] = 8, ["name"] = "rainbow:render_white"}, {["x"] = 1, ["meta"] = {["fields"] = {}, ["inventory"] = {}}, ["y"] = 15, ["param1"] = 111, ["z"] = 4, ["name"] = "rainbow:render_white"}, {["x"] = 1, ["meta"] = {["fields"] = {}, ["inventory"] = {}}, ["param2"] = 2, ["y"] = 15, ["param1"] = 14, ["z"] = 5, ["name"] = "rainbow:slope_render_white"}, {["x"] = 1, ["meta"] = {["fields"] = {}, ["inventory"] = {}}, ["y"] = 15, ["param1"] = 14, ["z"] = 7, ["name"] = "rainbow:slope_render_white"}, {["x"] = 1, ["meta"] = {["fields"] = {}, ["inventory"] = {}}, ["y"] = 15, ["param1"] = 111, ["z"] = 8, ["name"] = "rainbow:render_white"}, {["x"] = 1, ["meta"] = {["fields"] = {}, ["inventory"] = {}}, ["y"] = 16, ["param1"] = 95, ["z"] = 4, ["name"] = "rainbow:render_white"}, {["x"] = 1, ["meta"] = {["fields"] = {}, ["inventory"] = {}}, ["y"] = 16, ["param1"] = 95, ["z"] = 8, ["name"] = "rainbow:render_white"}, {["x"] = 1, ["meta"] = {["fields"] = {}, ["inventory"] = {}}, ["y"] = 17, ["param1"] = 79, ["z"] = 4, ["name"] = "rainbow:render_white"}, {["x"] = 1, ["meta"] = {["fields"] = {}, ["inventory"] = {}}, ["param2"] = 22, ["y"] = 17, ["param1"] = 14, ["z"] = 5, ["name"] = "rainbow:slope_render_white"}, {["x"] = 1, ["meta"] = {["fields"] = {}, ["inventory"] = {}}, ["param2"] = 20, ["y"] = 17, ["param1"] = 14, ["z"] = 7, ["name"] = "rainbow:slope_render_white"}, {["x"] = 1, ["meta"] = {["fields"] = {}, ["inventory"] = {}}, ["y"] = 17, ["param1"] = 79, ["z"] = 8, ["name"] = "rainbow:render_white"}, {["x"] = 1, ["meta"] = {["fields"] = {}, ["inventory"] = {}}, ["y"] = 18, ["param1"] = 63, ["z"] = 4, ["name"] = "rainbow:render_white"}, {["x"] = 1, ["meta"] = {["fields"] = {}, ["inventory"] = {}}, ["y"] = 18, ["param1"] = 79, ["z"] = 5, ["name"] = "rainbow:render_white"}, {["x"] = 1, ["meta"] = {["fields"] = {}, ["inventory"] = {}}, ["y"] = 18, ["z"] = 6, ["name"] = "rainbow:render_white"}, {["x"] = 1, ["meta"] = {["fields"] = {}, ["inventory"] = {}}, ["y"] = 18, ["param1"] = 79, ["z"] = 7, ["name"] = "rainbow:render_white"}, {["x"] = 1, ["meta"] = {["fields"] = {}, ["inventory"] = {}}, ["y"] = 18, ["param1"] = 63, ["z"] = 8, ["name"] = "rainbow:render_white"}, {["x"] = 1, ["meta"] = {["fields"] = {}, ["inventory"] = {}}, ["y"] = 19, ["param1"] = 47, ["z"] = 4, ["name"] = "rainbow:render_white"}, {["x"] = 1, ["meta"] = {["fields"] = {}, ["inventory"] = {}}, ["y"] = 19, ["param1"] = 63, ["z"] = 5, ["name"] = "rainbow:render_white"}, {["x"] = 1, ["meta"] = {["fields"] = {}, ["inventory"] = {}}, ["y"] = 19, ["param1"] = 79, ["z"] = 6, ["name"] = "rainbow:render_white"}, {["x"] = 1, ["meta"] = {["fields"] = {}, ["inventory"] = {}}, ["y"] = 19, ["param1"] = 63, ["z"] = 7, ["name"] = "rainbow:render_white"}, {["x"] = 1, ["meta"] = {["fields"] = {}, ["inventory"] = {}}, ["y"] = 19, ["param1"] = 47, ["z"] = 8, ["name"] = "rainbow:render_white"}, {["x"] = 2, ["meta"] = {["fields"] = {}, ["inventory"] = {}}, ["param2"] = 1, ["y"] = 0, ["param1"] = 30, ["z"] = 2, ["name"] = "rainbow:slope_render_white_outer"}, {["x"] = 2, ["meta"] = {["fields"] = {}, ["inventory"] = {}}, ["y"] = 0, ["param1"] = 111, ["z"] = 3, ["name"] = "rainbow:render_white"}, {["x"] = 2, ["meta"] = {["fields"] = {}, ["inventory"] = {}}, ["y"] = 0, ["param1"] = 111, ["z"] = 9, ["name"] = "rainbow:render_white"}, {["x"] = 2, ["meta"] = {["fields"] = {}, ["inventory"] = {}}, ["param2"] = 2, ["y"] = 0, ["param1"] = 30, ["z"] = 10, ["name"] = "rainbow:slope_render_white_outer"}, {["x"] = 2, ["meta"] = {["fields"] = {}, ["inventory"] = {}}, ["y"] = 1, ["param1"] = 95, ["z"] = 3, ["name"] = "rainbow:render_white"}, {["x"] = 2, ["meta"] = {["fields"] = {}, ["inventory"] = {}}, ["y"] = 1, ["param1"] = 95, ["z"] = 9, ["name"] = "rainbow:render_white"}, {["x"] = 2, ["meta"] = {["fields"] = {}, ["inventory"] = {}}, ["y"] = 2, ["param1"] = 79, ["z"] = 3, ["name"] = "rainbow:render_white"}, {["x"] = 2, ["meta"] = {["fields"] = {}, ["inventory"] = {}}, ["y"] = 2, ["param1"] = 79, ["z"] = 9, ["name"] = "rainbow:render_white"}, {["x"] = 2, ["meta"] = {["fields"] = {}, ["inventory"] = {}}, ["y"] = 3, ["param1"] = 63, ["z"] = 3, ["name"] = "rainbow:render_white"}, {["x"] = 2, ["meta"] = {["fields"] = {}, ["inventory"] = {}}, ["param2"] = 21, ["y"] = 3, ["param1"] = 75, ["z"] = 4, ["name"] = "rainbow:slab_render_white_1"}, {["x"] = 2, ["meta"] = {["fields"] = {}, ["inventory"] = {}}, ["param2"] = 21, ["y"] = 3, ["param1"] = 92, ["z"] = 5, ["name"] = "rainbow:slab_render_white_1"}, {["x"] = 2, ["meta"] = {["fields"] = {}, ["inventory"] = {}}, ["param2"] = 21, ["y"] = 3, ["param1"] = 108, ["z"] = 6, ["name"] = "rainbow:slab_render_white_1"}, {["x"] = 2, ["meta"] = {["fields"] = {}, ["inventory"] = {}}, ["param2"] = 21, ["y"] = 3, ["param1"] = 92, ["z"] = 7, ["name"] = "rainbow:slab_render_white_1"}, {["x"] = 2, ["meta"] = {["fields"] = {}, ["inventory"] = {}}, ["param2"] = 20, ["y"] = 3, ["param1"] = 75, ["z"] = 8, ["name"] = "rainbow:slab_render_white_1"}, {["x"] = 2, ["meta"] = {["fields"] = {}, ["inventory"] = {}}, ["y"] = 3, ["param1"] = 63, ["z"] = 9, ["name"] = "rainbow:render_white"}, {["x"] = 2, ["meta"] = {["fields"] = {}, ["inventory"] = {}}, ["y"] = 4, ["param1"] = 47, ["z"] = 3, ["name"] = "rainbow:render_white"}, {["x"] = 2, ["meta"] = {["fields"] = {}, ["inventory"] = {}}, ["y"] = 4, ["param1"] = 47, ["z"] = 9, ["name"] = "rainbow:render_white"}, {["x"] = 2, ["meta"] = {["fields"] = {}, ["inventory"] = {}}, ["y"] = 5, ["param1"] = 111, ["z"] = 3, ["name"] = "rainbow:render_white"}, {["x"] = 2, ["meta"] = {["fields"] = {}, ["inventory"] = {}}, ["y"] = 5, ["param1"] = 111, ["z"] = 9, ["name"] = "rainbow:render_white"}, {["x"] = 2, ["meta"] = {["fields"] = {}, ["inventory"] = {}}, ["y"] = 6, ["param1"] = 95, ["z"] = 3, ["name"] = "rainbow:render_white"}, {["x"] = 2, ["meta"] = {["fields"] = {}, ["inventory"] = {}}, ["y"] = 6, ["param1"] = 95, ["z"] = 9, ["name"] = "rainbow:render_white"}, {["x"] = 2, ["meta"] = {["fields"] = {}, ["inventory"] = {}}, ["y"] = 7, ["param1"] = 79, ["z"] = 3, ["name"] = "rainbow:render_white"}, {["x"] = 2, ["meta"] = {["fields"] = {}, ["inventory"] = {}}, ["y"] = 7, ["param1"] = 79, ["z"] = 9, ["name"] = "rainbow:render_white"}, {["x"] = 2, ["meta"] = {["fields"] = {}, ["inventory"] = {}}, ["y"] = 8, ["param1"] = 63, ["z"] = 3, ["name"] = "rainbow:render_white"}, {["x"] = 2, ["meta"] = {["fields"] = {}, ["inventory"] = {}}, ["param2"] = 21, ["y"] = 8, ["param1"] = 11, ["z"] = 4, ["name"] = "rainbow:slab_render_white_1"}, {["x"] = 2, ["meta"] = {["fields"] = {}, ["inventory"] = {}}, ["param2"] = 21, ["y"] = 8, ["param1"] = 12, ["z"] = 5, ["name"] = "rainbow:slab_render_white_1"}, {["x"] = 2, ["meta"] = {["fields"] = {}, ["inventory"] = {}}, ["param2"] = 21, ["y"] = 8, ["param1"] = 28, ["z"] = 6, ["name"] = "rainbow:slab_render_white_1"}, {["x"] = 2, ["meta"] = {["fields"] = {}, ["inventory"] = {}}, ["param2"] = 21, ["y"] = 8, ["param1"] = 12, ["z"] = 7, ["name"] = "rainbow:slab_render_white_1"}, {["x"] = 2, ["meta"] = {["fields"] = {}, ["inventory"] = {}}, ["param2"] = 21, ["y"] = 8, ["param1"] = 11, ["z"] = 8, ["name"] = "rainbow:slab_render_white_1"}, {["x"] = 2, ["meta"] = {["fields"] = {}, ["inventory"] = {}}, ["y"] = 8, ["param1"] = 63, ["z"] = 9, ["name"] = "rainbow:render_white"}, {["x"] = 2, ["meta"] = {["fields"] = {}, ["inventory"] = {}}, ["y"] = 9, ["param1"] = 47, ["z"] = 3, ["name"] = "rainbow:render_white"}, {["x"] = 2, ["meta"] = {["fields"] = {}, ["inventory"] = {}}, ["y"] = 9, ["param1"] = 47, ["z"] = 9, ["name"] = "rainbow:render_white"}, {["x"] = 2, ["meta"] = {["fields"] = {}, ["inventory"] = {}}, ["y"] = 10, ["param1"] = 111, ["z"] = 3, ["name"] = "rainbow:render_white"}, {["x"] = 2, ["meta"] = {["fields"] = {}, ["inventory"] = {}}, ["y"] = 10, ["param1"] = 111, ["z"] = 9, ["name"] = "rainbow:render_white"}, {["x"] = 2, ["meta"] = {["fields"] = {}, ["inventory"] = {}}, ["y"] = 11, ["param1"] = 95, ["z"] = 3, ["name"] = "rainbow:render_white"}, {["x"] = 2, ["meta"] = {["fields"] = {}, ["inventory"] = {}}, ["y"] = 11, ["param1"] = 95, ["z"] = 9, ["name"] = "rainbow:render_white"}, {["x"] = 2, ["meta"] = {["fields"] = {}, ["inventory"] = {}}, ["y"] = 12, ["param1"] = 79, ["z"] = 3, ["name"] = "rainbow:render_white"}, {["x"] = 2, ["meta"] = {["fields"] = {}, ["inventory"] = {}}, ["y"] = 12, ["param1"] = 79, ["z"] = 9, ["name"] = "rainbow:render_white"}, {["x"] = 2, ["meta"] = {["fields"] = {}, ["inventory"] = {}}, ["y"] = 13, ["param1"] = 63, ["z"] = 3, ["name"] = "rainbow:render_white"}, {["x"] = 2, ["meta"] = {["fields"] = {}, ["inventory"] = {}}, ["param2"] = 21, ["y"] = 13, ["param1"] = 11, ["z"] = 4, ["name"] = "rainbow:slab_render_white_1"}, {["x"] = 2, ["meta"] = {["fields"] = {}, ["inventory"] = {}}, ["param2"] = 21, ["y"] = 13, ["param1"] = 12, ["z"] = 5, ["name"] = "rainbow:slab_render_white_1"}, {["x"] = 2, ["meta"] = {["fields"] = {}, ["inventory"] = {}}, ["param2"] = 21, ["y"] = 13, ["param1"] = 12, ["z"] = 6, ["name"] = "rainbow:slab_render_white_1"}, {["x"] = 2, ["meta"] = {["fields"] = {}, ["inventory"] = {}}, ["param2"] = 21, ["y"] = 13, ["param1"] = 12, ["z"] = 7, ["name"] = "rainbow:slab_render_white_1"}, {["x"] = 2, ["meta"] = {["fields"] = {}, ["inventory"] = {}}, ["param2"] = 21, ["y"] = 13, ["param1"] = 11, ["z"] = 8, ["name"] = "rainbow:slab_render_white_1"}, {["x"] = 2, ["meta"] = {["fields"] = {}, ["inventory"] = {}}, ["y"] = 13, ["param1"] = 63, ["z"] = 9, ["name"] = "rainbow:render_white"}, {["x"] = 2, ["meta"] = {["fields"] = {}, ["inventory"] = {}}, ["y"] = 14, ["param1"] = 47, ["z"] = 3, ["name"] = "rainbow:render_white"}, {["x"] = 2, ["meta"] = {["fields"] = {}, ["inventory"] = {}}, ["y"] = 14, ["param1"] = 47, ["z"] = 9, ["name"] = "rainbow:render_white"}, {["x"] = 2, ["meta"] = {["fields"] = {}, ["inventory"] = {}}, ["y"] = 15, ["param1"] = 111, ["z"] = 3, ["name"] = "rainbow:render_white"}, {["x"] = 2, ["meta"] = {["fields"] = {}, ["inventory"] = {}}, ["y"] = 15, ["param1"] = 111, ["z"] = 9, ["name"] = "rainbow:render_white"}, {["x"] = 2, ["meta"] = {["fields"] = {}, ["inventory"] = {}}, ["y"] = 16, ["param1"] = 95, ["z"] = 3, ["name"] = "rainbow:render_white"}, {["x"] = 2, ["meta"] = {["fields"] = {}, ["inventory"] = {}}, ["y"] = 16, ["param1"] = 95, ["z"] = 9, ["name"] = "rainbow:render_white"}, {["x"] = 2, ["meta"] = {["fields"] = {}, ["inventory"] = {}}, ["y"] = 17, ["param1"] = 79, ["z"] = 3, ["name"] = "rainbow:render_white"}, {["x"] = 2, ["meta"] = {["fields"] = {}, ["inventory"] = {}}, ["y"] = 17, ["param1"] = 79, ["z"] = 9, ["name"] = "rainbow:render_white"}, {["x"] = 2, ["meta"] = {["fields"] = {}, ["inventory"] = {}}, ["y"] = 18, ["param1"] = 63, ["z"] = 3, ["name"] = "rainbow:render_white"}, {["x"] = 2, ["meta"] = {["fields"] = {}, ["inventory"] = {}}, ["param2"] = 21, ["y"] = 18, ["param1"] = 11, ["z"] = 4, ["name"] = "rainbow:slab_render_white_1"}, {["x"] = 2, ["meta"] = {["fields"] = {}, ["inventory"] = {}}, ["param2"] = 21, ["y"] = 18, ["param1"] = 12, ["z"] = 5, ["name"] = "rainbow:slab_render_white_1"}, {["x"] = 2, ["meta"] = {["fields"] = {}, ["inventory"] = {}}, ["param2"] = 21, ["y"] = 18, ["param1"] = 12, ["z"] = 6, ["name"] = "rainbow:slab_render_white_1"}, {["x"] = 2, ["meta"] = {["fields"] = {}, ["inventory"] = {}}, ["param2"] = 21, ["y"] = 18, ["param1"] = 12, ["z"] = 7, ["name"] = "rainbow:slab_render_white_1"}, {["x"] = 2, ["meta"] = {["fields"] = {}, ["inventory"] = {}}, ["param2"] = 21, ["y"] = 18, ["param1"] = 11, ["z"] = 8, ["name"] = "rainbow:slab_render_white_1"}, {["x"] = 2, ["meta"] = {["fields"] = {}, ["inventory"] = {}}, ["y"] = 18, ["param1"] = 63, ["z"] = 9, ["name"] = "rainbow:render_white"}, {["x"] = 2, ["meta"] = {["fields"] = {}, ["inventory"] = {}}, ["y"] = 19, ["param1"] = 47, ["z"] = 3, ["name"] = "rainbow:render_white"}, {["x"] = 2, ["meta"] = {["fields"] = {}, ["inventory"] = {}}, ["y"] = 19, ["param1"] = 47, ["z"] = 9, ["name"] = "rainbow:render_white"}, {["x"] = 2, ["meta"] = {["fields"] = {}, ["inventory"] = {}}, ["y"] = 20, ["z"] = 4, ["name"] = "rainbow:render_white"}, {["x"] = 2, ["meta"] = {["fields"] = {}, ["inventory"] = {}}, ["y"] = 20, ["param1"] = 191, ["z"] = 5, ["name"] = "rainbow:render_white"}, {["x"] = 2, ["meta"] = {["fields"] = {}, ["inventory"] = {}}, ["y"] = 20, ["z"] = 6, ["name"] = "rainbow:render_white"}, {["x"] = 2, ["meta"] = {["fields"] = {}, ["inventory"] = {}}, ["y"] = 20, ["param1"] = 191, ["z"] = 7, ["name"] = "rainbow:render_white"}, {["x"] = 2, ["meta"] = {["fields"] = {}, ["inventory"] = {}}, ["y"] = 20, ["param1"] = 175, ["z"] = 8, ["name"] = "rainbow:render_white"}, {["x"] = 2, ["meta"] = {["fields"] = {}, ["inventory"] = {}}, ["y"] = 21, ["param1"] = 159, ["z"] = 4, ["name"] = "rainbow:render_white"}, {["x"] = 2, ["meta"] = {["fields"] = {}, ["inventory"] = {}}, ["y"] = 21, ["param1"] = 175, ["z"] = 5, ["name"] = "rainbow:render_white"}, {["x"] = 2, ["meta"] = {["fields"] = {}, ["inventory"] = {}}, ["y"] = 21, ["param1"] = 191, ["z"] = 6, ["name"] = "rainbow:render_white"}, {["x"] = 2, ["meta"] = {["fields"] = {}, ["inventory"] = {}}, ["y"] = 21, ["param1"] = 175, ["z"] = 7, ["name"] = "rainbow:render_white"}, {["x"] = 2, ["meta"] = {["fields"] = {}, ["inventory"] = {}}, ["y"] = 21, ["param1"] = 159, ["z"] = 8, ["name"] = "rainbow:render_white"}, {["x"] = 2, ["meta"] = {["fields"] = {}, ["inventory"] = {}}, ["y"] = 22, ["param1"] = 143, ["z"] = 4, ["name"] = "rainbow:render_white"}, {["x"] = 2, ["meta"] = {["fields"] = {}, ["inventory"] = {}}, ["y"] = 22, ["param1"] = 159, ["z"] = 5, ["name"] = "rainbow:render_white"}, {["x"] = 2, ["meta"] = {["fields"] = {}, ["inventory"] = {}}, ["y"] = 22, ["param1"] = 175, ["z"] = 6, ["name"] = "rainbow:render_white"}, {["x"] = 2, ["meta"] = {["fields"] = {}, ["inventory"] = {}}, ["y"] = 22, ["param1"] = 159, ["z"] = 7, ["name"] = "rainbow:render_white"}, {["x"] = 2, ["meta"] = {["fields"] = {}, ["inventory"] = {}}, ["y"] = 22, ["param1"] = 143, ["z"] = 8, ["name"] = "rainbow:render_white"}, {["x"] = 2, ["meta"] = {["fields"] = {}, ["inventory"] = {}}, ["y"] = 23, ["param1"] = 127, ["z"] = 4, ["name"] = "rainbow:render_white"}, {["x"] = 2, ["meta"] = {["fields"] = {}, ["inventory"] = {}}, ["y"] = 23, ["param1"] = 143, ["z"] = 5, ["name"] = "rainbow:render_white"}, {["x"] = 2, ["meta"] = {["fields"] = {}, ["inventory"] = {}}, ["y"] = 23, ["param1"] = 159, ["z"] = 6, ["name"] = "rainbow:render_white"}, {["x"] = 2, ["meta"] = {["fields"] = {}, ["inventory"] = {}}, ["y"] = 23, ["param1"] = 143, ["z"] = 7, ["name"] = "rainbow:render_white"}, {["x"] = 2, ["meta"] = {["fields"] = {}, ["inventory"] = {}}, ["y"] = 23, ["param1"] = 127, ["z"] = 8, ["name"] = "rainbow:render_white"}, {["x"] = 2, ["meta"] = {["fields"] = {}, ["inventory"] = {}}, ["y"] = 24, ["param1"] = 111, ["z"] = 4, ["name"] = "rainbow:render_white"}, {["x"] = 2, ["meta"] = {["fields"] = {}, ["inventory"] = {}}, ["y"] = 24, ["param1"] = 127, ["z"] = 5, ["name"] = "rainbow:render_white"}, {["x"] = 2, ["meta"] = {["fields"] = {}, ["inventory"] = {}}, ["y"] = 24, ["param1"] = 143, ["z"] = 6, ["name"] = "rainbow:render_white"}, {["x"] = 2, ["meta"] = {["fields"] = {}, ["inventory"] = {}}, ["y"] = 24, ["param1"] = 127, ["z"] = 7, ["name"] = "rainbow:render_white"}, {["x"] = 2, ["meta"] = {["fields"] = {}, ["inventory"] = {}}, ["y"] = 24, ["param1"] = 111, ["z"] = 8, ["name"] = "rainbow:render_white"}, {["x"] = 2, ["meta"] = {["fields"] = {}, ["inventory"] = {}}, ["y"] = 25, ["param1"] = 95, ["z"] = 4, ["name"] = "rainbow:render_white"}, {["x"] = 2, ["meta"] = {["fields"] = {}, ["inventory"] = {}}, ["y"] = 25, ["param1"] = 111, ["z"] = 5, ["name"] = "rainbow:render_white"}, {["x"] = 2, ["meta"] = {["fields"] = {}, ["inventory"] = {}}, ["y"] = 25, ["param1"] = 127, ["z"] = 6, ["name"] = "rainbow:render_white"}, {["x"] = 2, ["meta"] = {["fields"] = {}, ["inventory"] = {}}, ["y"] = 25, ["param1"] = 111, ["z"] = 7, ["name"] = "rainbow:render_white"}, {["x"] = 2, ["meta"] = {["fields"] = {}, ["inventory"] = {}}, ["y"] = 25, ["param1"] = 95, ["z"] = 8, ["name"] = "rainbow:render_white"}, {["x"] = 2, ["meta"] = {["fields"] = {}, ["inventory"] = {}}, ["y"] = 26, ["param1"] = 79, ["z"] = 4, ["name"] = "rainbow:render_white"}, {["x"] = 2, ["meta"] = {["fields"] = {}, ["inventory"] = {}}, ["y"] = 26, ["param1"] = 95, ["z"] = 5, ["name"] = "rainbow:render_white"}, {["x"] = 2, ["meta"] = {["fields"] = {}, ["inventory"] = {}}, ["y"] = 26, ["param1"] = 111, ["z"] = 6, ["name"] = "rainbow:render_white"}, {["x"] = 2, ["meta"] = {["fields"] = {}, ["inventory"] = {}}, ["y"] = 26, ["param1"] = 95, ["z"] = 7, ["name"] = "rainbow:render_white"}, {["x"] = 2, ["meta"] = {["fields"] = {}, ["inventory"] = {}}, ["y"] = 26, ["param1"] = 79, ["z"] = 8, ["name"] = "rainbow:render_white"}, {["x"] = 2, ["meta"] = {["fields"] = {}, ["inventory"] = {}}, ["y"] = 27, ["param1"] = 63, ["z"] = 4, ["name"] = "rainbow:render_white"}, {["x"] = 2, ["meta"] = {["fields"] = {}, ["inventory"] = {}}, ["y"] = 27, ["param1"] = 79, ["z"] = 5, ["name"] = "rainbow:render_white"}, {["x"] = 2, ["meta"] = {["fields"] = {}, ["inventory"] = {}}, ["y"] = 27, ["param1"] = 95, ["z"] = 6, ["name"] = "rainbow:render_white"}, {["x"] = 2, ["meta"] = {["fields"] = {}, ["inventory"] = {}}, ["y"] = 27, ["param1"] = 79, ["z"] = 7, ["name"] = "rainbow:render_white"}, {["x"] = 2, ["meta"] = {["fields"] = {}, ["inventory"] = {}}, ["y"] = 27, ["param1"] = 63, ["z"] = 8, ["name"] = "rainbow:render_white"}, {["x"] = 2, ["meta"] = {["fields"] = {}, ["inventory"] = {}}, ["y"] = 28, ["param1"] = 47, ["z"] = 4, ["name"] = "rainbow:render_white"}, {["x"] = 2, ["meta"] = {["fields"] = {}, ["inventory"] = {}}, ["y"] = 28, ["param1"] = 63, ["z"] = 5, ["name"] = "rainbow:render_white"}, {["x"] = 2, ["meta"] = {["fields"] = {}, ["inventory"] = {}}, ["y"] = 28, ["param1"] = 79, ["z"] = 6, ["name"] = "rainbow:render_white"}, {["x"] = 2, ["meta"] = {["fields"] = {}, ["inventory"] = {}}, ["y"] = 28, ["param1"] = 63, ["z"] = 7, ["name"] = "rainbow:render_white"}, {["x"] = 2, ["meta"] = {["fields"] = {}, ["inventory"] = {}}, ["y"] = 28, ["param1"] = 47, ["z"] = 8, ["name"] = "rainbow:render_white"}, {["x"] = 2, ["meta"] = {["fields"] = {}, ["inventory"] = {}}, ["y"] = 29, ["param1"] = 31, ["z"] = 4, ["name"] = "rainbow:render_white"}, {["x"] = 2, ["meta"] = {["fields"] = {}, ["inventory"] = {}}, ["y"] = 29, ["param1"] = 47, ["z"] = 5, ["name"] = "rainbow:render_white"}, {["x"] = 2, ["meta"] = {["fields"] = {}, ["inventory"] = {}}, ["y"] = 29, ["param1"] = 63, ["z"] = 6, ["name"] = "rainbow:render_white"}, {["x"] = 2, ["meta"] = {["fields"] = {}, ["inventory"] = {}}, ["y"] = 29, ["param1"] = 47, ["z"] = 7, ["name"] = "rainbow:render_white"}, {["x"] = 2, ["meta"] = {["fields"] = {}, ["inventory"] = {}}, ["y"] = 29, ["param1"] = 31, ["z"] = 8, ["name"] = "rainbow:render_white"}, {["x"] = 2, ["meta"] = {["fields"] = {}, ["inventory"] = {}}, ["y"] = 30, ["param1"] = 15, ["z"] = 4, ["name"] = "rainbow:render_white"}, {["x"] = 2, ["meta"] = {["fields"] = {}, ["inventory"] = {}}, ["y"] = 30, ["param1"] = 31, ["z"] = 5, ["name"] = "rainbow:render_white"}, {["x"] = 2, ["meta"] = {["fields"] = {}, ["inventory"] = {}}, ["y"] = 30, ["param1"] = 47, ["z"] = 6, ["name"] = "rainbow:render_white"}, {["x"] = 2, ["meta"] = {["fields"] = {}, ["inventory"] = {}}, ["y"] = 30, ["param1"] = 31, ["z"] = 7, ["name"] = "rainbow:render_white"}, {["x"] = 2, ["meta"] = {["fields"] = {}, ["inventory"] = {}}, ["y"] = 30, ["param1"] = 15, ["z"] = 8, ["name"] = "rainbow:render_white"}, {["x"] = 2, ["meta"] = {["fields"] = {}, ["inventory"] = {}}, ["y"] = 31, ["param1"] = 15, ["z"] = 4, ["name"] = "rainbow:render_white"}, {["x"] = 2, ["meta"] = {["fields"] = {}, ["inventory"] = {}}, ["y"] = 31, ["param1"] = 15, ["z"] = 5, ["name"] = "rainbow:render_white"}, {["x"] = 2, ["meta"] = {["fields"] = {}, ["inventory"] = {}}, ["y"] = 31, ["param1"] = 31, ["z"] = 6, ["name"] = "rainbow:render_white"}, {["x"] = 2, ["meta"] = {["fields"] = {}, ["inventory"] = {}}, ["y"] = 31, ["param1"] = 15, ["z"] = 7, ["name"] = "rainbow:render_white"}, {["x"] = 2, ["meta"] = {["fields"] = {}, ["inventory"] = {}}, ["y"] = 31, ["param1"] = 15, ["z"] = 8, ["name"] = "rainbow:render_white"}, {["x"] = 2, ["meta"] = {["fields"] = {}, ["inventory"] = {}}, ["y"] = 32, ["param1"] = 15, ["z"] = 4, ["name"] = "rainbow:render_white"}, {["x"] = 2, ["meta"] = {["fields"] = {}, ["inventory"] = {}}, ["y"] = 32, ["param1"] = 15, ["z"] = 5, ["name"] = "rainbow:render_white"}, {["x"] = 2, ["meta"] = {["fields"] = {}, ["inventory"] = {}}, ["y"] = 32, ["param1"] = 15, ["z"] = 6, ["name"] = "rainbow:render_white"}, {["x"] = 2, ["meta"] = {["fields"] = {}, ["inventory"] = {}}, ["y"] = 32, ["param1"] = 15, ["z"] = 7, ["name"] = "rainbow:render_white"}, {["x"] = 2, ["meta"] = {["fields"] = {}, ["inventory"] = {}}, ["y"] = 32, ["param1"] = 15, ["z"] = 8, ["name"] = "rainbow:render_white"}, {["x"] = 2, ["meta"] = {["fields"] = {}, ["inventory"] = {}}, ["y"] = 33, ["param1"] = 15, ["z"] = 4, ["name"] = "rainbow:render_white"}, {["x"] = 2, ["meta"] = {["fields"] = {}, ["inventory"] = {}}, ["y"] = 33, ["param1"] = 15, ["z"] = 5, ["name"] = "rainbow:render_white"}, {["x"] = 2, ["meta"] = {["fields"] = {}, ["inventory"] = {}}, ["y"] = 33, ["param1"] = 15, ["z"] = 6, ["name"] = "rainbow:render_white"}, {["x"] = 2, ["meta"] = {["fields"] = {}, ["inventory"] = {}}, ["y"] = 33, ["param1"] = 15, ["z"] = 7, ["name"] = "rainbow:render_white"}, {["x"] = 2, ["meta"] = {["fields"] = {}, ["inventory"] = {}}, ["y"] = 33, ["param1"] = 15, ["z"] = 8, ["name"] = "rainbow:render_white"}, {["x"] = 2, ["meta"] = {["fields"] = {}, ["inventory"] = {}}, ["y"] = 34, ["param1"] = 15, ["z"] = 4, ["name"] = "rainbow:render_white"}, {["x"] = 2, ["meta"] = {["fields"] = {}, ["inventory"] = {}}, ["y"] = 34, ["param1"] = 15, ["z"] = 5, ["name"] = "rainbow:render_white"}, {["x"] = 2, ["meta"] = {["fields"] = {}, ["inventory"] = {}}, ["y"] = 34, ["param1"] = 15, ["z"] = 6, ["name"] = "rainbow:render_white"}, {["x"] = 2, ["meta"] = {["fields"] = {}, ["inventory"] = {}}, ["y"] = 34, ["param1"] = 15, ["z"] = 7, ["name"] = "rainbow:render_white"}, {["x"] = 2, ["meta"] = {["fields"] = {}, ["inventory"] = {}}, ["y"] = 34, ["param1"] = 15, ["z"] = 8, ["name"] = "rainbow:render_white"}, {["x"] = 2, ["meta"] = {["fields"] = {}, ["inventory"] = {}}, ["y"] = 35, ["param1"] = 15, ["z"] = 4, ["name"] = "rainbow:render_white"}, {["x"] = 2, ["meta"] = {["fields"] = {}, ["inventory"] = {}}, ["y"] = 35, ["param1"] = 15, ["z"] = 5, ["name"] = "rainbow:render_white"}, {["x"] = 2, ["meta"] = {["fields"] = {}, ["inventory"] = {}}, ["y"] = 35, ["param1"] = 15, ["z"] = 6, ["name"] = "rainbow:render_white"}, {["x"] = 2, ["meta"] = {["fields"] = {}, ["inventory"] = {}}, ["y"] = 35, ["param1"] = 15, ["z"] = 7, ["name"] = "rainbow:render_white"}, {["x"] = 2, ["meta"] = {["fields"] = {}, ["inventory"] = {}}, ["y"] = 35, ["param1"] = 15, ["z"] = 8, ["name"] = "rainbow:render_white"}, {["x"] = 2, ["meta"] = {["fields"] = {}, ["inventory"] = {}}, ["y"] = 36, ["param1"] = 15, ["z"] = 4, ["name"] = "rainbow:render_white"}, {["x"] = 2, ["meta"] = {["fields"] = {}, ["inventory"] = {}}, ["y"] = 36, ["param1"] = 15, ["z"] = 5, ["name"] = "rainbow:render_white"}, {["x"] = 2, ["meta"] = {["fields"] = {}, ["inventory"] = {}}, ["y"] = 36, ["param1"] = 15, ["z"] = 6, ["name"] = "rainbow:render_white"}, {["x"] = 2, ["meta"] = {["fields"] = {}, ["inventory"] = {}}, ["y"] = 36, ["param1"] = 15, ["z"] = 7, ["name"] = "rainbow:render_white"}, {["x"] = 2, ["meta"] = {["fields"] = {}, ["inventory"] = {}}, ["y"] = 36, ["param1"] = 15, ["z"] = 8, ["name"] = "rainbow:render_white"}, {["x"] = 2, ["meta"] = {["fields"] = {}, ["inventory"] = {}}, ["y"] = 37, ["param1"] = 15, ["z"] = 4, ["name"] = "rainbow:render_white"}, {["x"] = 2, ["meta"] = {["fields"] = {}, ["inventory"] = {}}, ["y"] = 37, ["param1"] = 15, ["z"] = 5, ["name"] = "rainbow:render_white"}, {["x"] = 2, ["meta"] = {["fields"] = {}, ["inventory"] = {}}, ["y"] = 37, ["param1"] = 15, ["z"] = 6, ["name"] = "rainbow:render_white"}, {["x"] = 2, ["meta"] = {["fields"] = {}, ["inventory"] = {}}, ["y"] = 37, ["param1"] = 15, ["z"] = 7, ["name"] = "rainbow:render_white"}, {["x"] = 2, ["meta"] = {["fields"] = {}, ["inventory"] = {}}, ["y"] = 37, ["param1"] = 15, ["z"] = 8, ["name"] = "rainbow:render_white"}, {["x"] = 2, ["meta"] = {["fields"] = {}, ["inventory"] = {}}, ["y"] = 38, ["param1"] = 15, ["z"] = 4, ["name"] = "rainbow:render_white"}, {["x"] = 2, ["meta"] = {["fields"] = {}, ["inventory"] = {}}, ["y"] = 38, ["param1"] = 15, ["z"] = 5, ["name"] = "rainbow:render_white"}, {["x"] = 2, ["meta"] = {["fields"] = {}, ["inventory"] = {}}, ["y"] = 38, ["param1"] = 15, ["z"] = 6, ["name"] = "rainbow:render_white"}, {["x"] = 2, ["meta"] = {["fields"] = {}, ["inventory"] = {}}, ["y"] = 38, ["param1"] = 15, ["z"] = 7, ["name"] = "rainbow:render_white"}, {["x"] = 2, ["meta"] = {["fields"] = {}, ["inventory"] = {}}, ["y"] = 38, ["param1"] = 15, ["z"] = 8, ["name"] = "rainbow:render_white"}, {["x"] = 2, ["meta"] = {["fields"] = {}, ["inventory"] = {}}, ["param2"] = 1, ["y"] = 39, ["param1"] = 15, ["z"] = 4, ["name"] = "moreblocks:slope_steelblock_outer"}, {["x"] = 2, ["meta"] = {["fields"] = {}, ["inventory"] = {}}, ["param2"] = 1, ["y"] = 39, ["param1"] = 15, ["z"] = 5, ["name"] = "moreblocks:slope_steelblock"}, {["x"] = 2, ["meta"] = {["fields"] = {}, ["inventory"] = {}}, ["param2"] = 1, ["y"] = 39, ["param1"] = 15, ["z"] = 6, ["name"] = "moreblocks:slope_steelblock"}, {["x"] = 2, ["meta"] = {["fields"] = {}, ["inventory"] = {}}, ["param2"] = 1, ["y"] = 39, ["param1"] = 15, ["z"] = 7, ["name"] = "moreblocks:slope_steelblock"}, {["x"] = 2, ["meta"] = {["fields"] = {}, ["inventory"] = {}}, ["param2"] = 2, ["y"] = 39, ["param1"] = 15, ["z"] = 8, ["name"] = "moreblocks:slope_steelblock_outer"}, {["x"] = 3, ["meta"] = {["fields"] = {}, ["inventory"] = {}}, ["param2"] = 1, ["y"] = 0, ["param1"] = 62, ["z"] = 1, ["name"] = "rainbow:slope_render_white_outer"}, {["x"] = 3, ["meta"] = {["fields"] = {}, ["inventory"] = {}}, ["y"] = 0, ["param1"] = 111, ["z"] = 2, ["name"] = "rainbow:render_white"}, {["x"] = 3, ["meta"] = {["fields"] = {}, ["inventory"] = {}}, ["param2"] = 20, ["y"] = 0, ["param1"] = 139, ["z"] = 4, ["name"] = "rainbow:slope_render_white"}, {["x"] = 3, ["meta"] = {["fields"] = {}, ["inventory"] = {}}, ["param2"] = 2, ["y"] = 0, ["param1"] = 156, ["z"] = 5, ["name"] = "rainbow:slope_render_white"}, {["x"] = 3, ["meta"] = {["fields"] = {}, ["inventory"] = {}}, ["y"] = 0, ["param1"] = 111, ["z"] = 10, ["name"] = "rainbow:render_white"}, {["x"] = 3, ["meta"] = {["fields"] = {}, ["inventory"] = {}}, ["param2"] = 2, ["y"] = 0, ["param1"] = 62, ["z"] = 11, ["name"] = "rainbow:slope_render_white_outer"}, {["x"] = 3, ["meta"] = {["fields"] = {}, ["inventory"] = {}}, ["y"] = 1, ["param1"] = 95, ["z"] = 2, ["name"] = "rainbow:render_white"}, {["x"] = 3, ["meta"] = {["fields"] = {}, ["inventory"] = {}}, ["y"] = 1, ["z"] = 3, ["name"] = "rainbow:render_white"}, {["x"] = 3, ["meta"] = {["fields"] = {}, ["inventory"] = {}}, ["param2"] = 2, ["y"] = 1, ["param1"] = 122, ["z"] = 4, ["name"] = "rainbow:slope_render_white"}, {["x"] = 3, ["meta"] = {["fields"] = {}, ["inventory"] = {}}, ["y"] = 1, ["param1"] = 95, ["z"] = 10, ["name"] = "rainbow:render_white"}, {["x"] = 3, ["meta"] = {["fields"] = {}, ["inventory"] = {}}, ["y"] = 2, ["param1"] = 79, ["z"] = 2, ["name"] = "rainbow:render_white"}, {["x"] = 3, ["meta"] = {["fields"] = {}, ["inventory"] = {}}, ["y"] = 2, ["param1"] = 79, ["z"] = 10, ["name"] = "rainbow:render_white"}, {["x"] = 3, ["meta"] = {["fields"] = {}, ["inventory"] = {}}, ["y"] = 3, ["param1"] = 63, ["z"] = 2, ["name"] = "rainbow:render_white"}, {["x"] = 3, ["meta"] = {["fields"] = {}, ["inventory"] = {}}, ["param2"] = 21, ["y"] = 3, ["param1"] = 90, ["z"] = 4, ["name"] = "rainbow:slab_render_white_1"}, {["x"] = 3, ["meta"] = {["fields"] = {}, ["inventory"] = {}}, ["param2"] = 21, ["y"] = 3, ["param1"] = 107, ["z"] = 5, ["name"] = "rainbow:slab_render_white_1"}, {["x"] = 3, ["meta"] = {["fields"] = {}, ["inventory"] = {}}, ["param2"] = 21, ["y"] = 3, ["param1"] = 123, ["z"] = 6, ["name"] = "rainbow:slab_render_white_1"}, {["x"] = 3, ["meta"] = {["fields"] = {}, ["inventory"] = {}}, ["param2"] = 21, ["y"] = 3, ["param1"] = 107, ["z"] = 7, ["name"] = "rainbow:slab_render_white_1"}, {["x"] = 3, ["meta"] = {["fields"] = {}, ["inventory"] = {}}, ["param2"] = 21, ["y"] = 3, ["param1"] = 90, ["z"] = 8, ["name"] = "rainbow:slab_render_white_1"}, {["x"] = 3, ["meta"] = {["fields"] = {}, ["inventory"] = {}}, ["param2"] = 21, ["y"] = 3, ["param1"] = 73, ["z"] = 9, ["name"] = "rainbow:slab_render_white_1"}, {["x"] = 3, ["meta"] = {["fields"] = {}, ["inventory"] = {}}, ["y"] = 3, ["param1"] = 63, ["z"] = 10, ["name"] = "rainbow:render_white"}, {["x"] = 3, ["meta"] = {["fields"] = {}, ["inventory"] = {}}, ["y"] = 4, ["param1"] = 47, ["z"] = 2, ["name"] = "rainbow:render_white"}, {["x"] = 3, ["meta"] = {["fields"] = {}, ["inventory"] = {}}, ["param2"] = 20, ["y"] = 4, ["param1"] = 91, ["z"] = 5, ["name"] = "rainbow:slope_render_white"}, {["x"] = 3, ["meta"] = {["fields"] = {}, ["inventory"] = {}}, ["param2"] = 2, ["y"] = 4, ["param1"] = 107, ["z"] = 6, ["name"] = "rainbow:slope_render_white"}, {["x"] = 3, ["meta"] = {["fields"] = {}, ["inventory"] = {}}, ["y"] = 4, ["param1"] = 47, ["z"] = 10, ["name"] = "rainbow:render_white"}, {["x"] = 3, ["meta"] = {["fields"] = {}, ["inventory"] = {}}, ["y"] = 5, ["param1"] = 111, ["z"] = 2, ["name"] = "rainbow:render_white"}, {["x"] = 3, ["meta"] = {["fields"] = {}, ["inventory"] = {}}, ["param2"] = 20, ["y"] = 5, ["param1"] = 59, ["z"] = 4, ["name"] = "rainbow:slope_render_white"}, {["x"] = 3, ["meta"] = {["fields"] = {}, ["inventory"] = {}}, ["param2"] = 2, ["y"] = 5, ["param1"] = 76, ["z"] = 5, ["name"] = "rainbow:slope_render_white"}, {["x"] = 3, ["meta"] = {["fields"] = {}, ["inventory"] = {}}, ["y"] = 5, ["param1"] = 111, ["z"] = 10, ["name"] = "rainbow:render_white"}, {["x"] = 3, ["meta"] = {["fields"] = {}, ["inventory"] = {}}, ["y"] = 6, ["param1"] = 95, ["z"] = 2, ["name"] = "rainbow:render_white"}, {["x"] = 3, ["meta"] = {["fields"] = {}, ["inventory"] = {}}, ["y"] = 6, ["z"] = 3, ["name"] = "rainbow:render_white"}, {["x"] = 3, ["meta"] = {["fields"] = {}, ["inventory"] = {}}, ["param2"] = 2, ["y"] = 6, ["param1"] = 43, ["z"] = 4, ["name"] = "rainbow:slope_render_white"}, {["x"] = 3, ["meta"] = {["fields"] = {}, ["inventory"] = {}}, ["y"] = 6, ["param1"] = 95, ["z"] = 10, ["name"] = "rainbow:render_white"}, {["x"] = 3, ["meta"] = {["fields"] = {}, ["inventory"] = {}}, ["y"] = 7, ["param1"] = 79, ["z"] = 2, ["name"] = "rainbow:render_white"}, {["x"] = 3, ["meta"] = {["fields"] = {}, ["inventory"] = {}}, ["y"] = 7, ["param1"] = 79, ["z"] = 10, ["name"] = "rainbow:render_white"}, {["x"] = 3, ["meta"] = {["fields"] = {}, ["inventory"] = {}}, ["y"] = 8, ["param1"] = 63, ["z"] = 2, ["name"] = "rainbow:render_white"}, {["x"] = 3, ["meta"] = {["fields"] = {}, ["inventory"] = {}}, ["param2"] = 21, ["y"] = 8, ["param1"] = 10, ["z"] = 4, ["name"] = "rainbow:slab_render_white_1"}, {["x"] = 3, ["meta"] = {["fields"] = {}, ["inventory"] = {}}, ["param2"] = 21, ["y"] = 8, ["param1"] = 27, ["z"] = 5, ["name"] = "rainbow:slab_render_white_1"}, {["x"] = 3, ["meta"] = {["fields"] = {}, ["inventory"] = {}}, ["param2"] = 21, ["y"] = 8, ["param1"] = 43, ["z"] = 6, ["name"] = "rainbow:slab_render_white_1"}, {["x"] = 3, ["meta"] = {["fields"] = {}, ["inventory"] = {}}, ["param2"] = 21, ["y"] = 8, ["param1"] = 27, ["z"] = 7, ["name"] = "rainbow:slab_render_white_1"}, {["x"] = 3, ["meta"] = {["fields"] = {}, ["inventory"] = {}}, ["param2"] = 21, ["y"] = 8, ["param1"] = 10, ["z"] = 8, ["name"] = "rainbow:slab_render_white_1"}, {["x"] = 3, ["meta"] = {["fields"] = {}, ["inventory"] = {}}, ["param2"] = 21, ["y"] = 8, ["param1"] = 9, ["z"] = 9, ["name"] = "rainbow:slab_render_white_1"}, {["x"] = 3, ["meta"] = {["fields"] = {}, ["inventory"] = {}}, ["y"] = 8, ["param1"] = 63, ["z"] = 10, ["name"] = "rainbow:render_white"}, {["x"] = 3, ["meta"] = {["fields"] = {}, ["inventory"] = {}}, ["y"] = 9, ["param1"] = 47, ["z"] = 2, ["name"] = "rainbow:render_white"}, {["x"] = 3, ["meta"] = {["fields"] = {}, ["inventory"] = {}}, ["param2"] = 20, ["y"] = 9, ["param1"] = 11, ["z"] = 5, ["name"] = "rainbow:slope_render_white"}, {["x"] = 3, ["meta"] = {["fields"] = {}, ["inventory"] = {}}, ["param2"] = 2, ["y"] = 9, ["param1"] = 27, ["z"] = 6, ["name"] = "rainbow:slope_render_white"}, {["x"] = 3, ["meta"] = {["fields"] = {}, ["inventory"] = {}}, ["y"] = 9, ["param1"] = 47, ["z"] = 10, ["name"] = "rainbow:render_white"}, {["x"] = 3, ["meta"] = {["fields"] = {}, ["inventory"] = {}}, ["y"] = 10, ["param1"] = 111, ["z"] = 2, ["name"] = "rainbow:render_white"}, {["x"] = 3, ["meta"] = {["fields"] = {}, ["inventory"] = {}}, ["param2"] = 20, ["y"] = 10, ["param1"] = 11, ["z"] = 4, ["name"] = "rainbow:slope_render_white"}, {["x"] = 3, ["meta"] = {["fields"] = {}, ["inventory"] = {}}, ["param2"] = 2, ["y"] = 10, ["param1"] = 12, ["z"] = 5, ["name"] = "rainbow:slope_render_white"}, {["x"] = 3, ["meta"] = {["fields"] = {}, ["inventory"] = {}}, ["y"] = 10, ["param1"] = 111, ["z"] = 10, ["name"] = "rainbow:render_white"}, {["x"] = 3, ["meta"] = {["fields"] = {}, ["inventory"] = {}}, ["y"] = 11, ["param1"] = 95, ["z"] = 2, ["name"] = "rainbow:render_white"}, {["x"] = 3, ["meta"] = {["fields"] = {}, ["inventory"] = {}}, ["y"] = 11, ["z"] = 3, ["name"] = "rainbow:render_white"}, {["x"] = 3, ["meta"] = {["fields"] = {}, ["inventory"] = {}}, ["param2"] = 2, ["y"] = 11, ["param1"] = 11, ["z"] = 4, ["name"] = "rainbow:slope_render_white"}, {["x"] = 3, ["meta"] = {["fields"] = {}, ["inventory"] = {}}, ["y"] = 11, ["param1"] = 95, ["z"] = 10, ["name"] = "rainbow:render_white"}, {["x"] = 3, ["meta"] = {["fields"] = {}, ["inventory"] = {}}, ["y"] = 12, ["param1"] = 79, ["z"] = 2, ["name"] = "rainbow:render_white"}, {["x"] = 3, ["meta"] = {["fields"] = {}, ["inventory"] = {}}, ["y"] = 12, ["param1"] = 79, ["z"] = 10, ["name"] = "rainbow:render_white"}, {["x"] = 3, ["meta"] = {["fields"] = {}, ["inventory"] = {}}, ["y"] = 13, ["param1"] = 63, ["z"] = 2, ["name"] = "rainbow:render_white"}, {["x"] = 3, ["meta"] = {["fields"] = {}, ["inventory"] = {}}, ["param2"] = 21, ["y"] = 13, ["param1"] = 10, ["z"] = 4, ["name"] = "rainbow:slab_render_white_1"}, {["x"] = 3, ["meta"] = {["fields"] = {}, ["inventory"] = {}}, ["param2"] = 21, ["y"] = 13, ["param1"] = 11, ["z"] = 5, ["name"] = "rainbow:slab_render_white_1"}, {["x"] = 3, ["meta"] = {["fields"] = {}, ["inventory"] = {}}, ["param2"] = 21, ["y"] = 13, ["param1"] = 11, ["z"] = 6, ["name"] = "rainbow:slab_render_white_1"}, {["x"] = 3, ["meta"] = {["fields"] = {}, ["inventory"] = {}}, ["param2"] = 21, ["y"] = 13, ["param1"] = 11, ["z"] = 7, ["name"] = "rainbow:slab_render_white_1"}, {["x"] = 3, ["meta"] = {["fields"] = {}, ["inventory"] = {}}, ["param2"] = 21, ["y"] = 13, ["param1"] = 10, ["z"] = 8, ["name"] = "rainbow:slab_render_white_1"}, {["x"] = 3, ["meta"] = {["fields"] = {}, ["inventory"] = {}}, ["param2"] = 21, ["y"] = 13, ["param1"] = 9, ["z"] = 9, ["name"] = "rainbow:slab_render_white_1"}, {["x"] = 3, ["meta"] = {["fields"] = {}, ["inventory"] = {}}, ["y"] = 13, ["param1"] = 63, ["z"] = 10, ["name"] = "rainbow:render_white"}, {["x"] = 3, ["meta"] = {["fields"] = {}, ["inventory"] = {}}, ["y"] = 14, ["param1"] = 47, ["z"] = 2, ["name"] = "rainbow:render_white"}, {["x"] = 3, ["meta"] = {["fields"] = {}, ["inventory"] = {}}, ["param2"] = 20, ["y"] = 14, ["param1"] = 11, ["z"] = 5, ["name"] = "rainbow:slope_render_white"}, {["x"] = 3, ["meta"] = {["fields"] = {}, ["inventory"] = {}}, ["param2"] = 2, ["y"] = 14, ["param1"] = 11, ["z"] = 6, ["name"] = "rainbow:slope_render_white"}, {["x"] = 3, ["meta"] = {["fields"] = {}, ["inventory"] = {}}, ["y"] = 14, ["z"] = 10, ["name"] = "rainbow:render_white"}, {["x"] = 3, ["meta"] = {["fields"] = {}, ["inventory"] = {}}, ["y"] = 15, ["param1"] = 111, ["z"] = 2, ["name"] = "rainbow:render_white"}, {["x"] = 3, ["meta"] = {["fields"] = {}, ["inventory"] = {}}, ["param2"] = 20, ["y"] = 15, ["param1"] = 11, ["z"] = 4, ["name"] = "rainbow:slope_render_white"}, {["x"] = 3, ["meta"] = {["fields"] = {}, ["inventory"] = {}}, ["param2"] = 2, ["y"] = 15, ["param1"] = 12, ["z"] = 5, ["name"] = "rainbow:slope_render_white"}, {["x"] = 3, ["meta"] = {["fields"] = {}, ["inventory"] = {}}, ["y"] = 15, ["param1"] = 111, ["z"] = 10, ["name"] = "rainbow:render_white"}, {["x"] = 3, ["meta"] = {["fields"] = {}, ["inventory"] = {}}, ["y"] = 16, ["param1"] = 95, ["z"] = 2, ["name"] = "rainbow:render_white"}, {["x"] = 3, ["meta"] = {["fields"] = {}, ["inventory"] = {}}, ["y"] = 16, ["z"] = 3, ["name"] = "rainbow:render_white"}, {["x"] = 3, ["meta"] = {["fields"] = {}, ["inventory"] = {}}, ["param2"] = 2, ["y"] = 16, ["param1"] = 11, ["z"] = 4, ["name"] = "rainbow:slope_render_white"}, {["x"] = 3, ["meta"] = {["fields"] = {}, ["inventory"] = {}}, ["y"] = 16, ["param1"] = 95, ["z"] = 10, ["name"] = "rainbow:render_white"}, {["x"] = 3, ["meta"] = {["fields"] = {}, ["inventory"] = {}}, ["y"] = 17, ["param1"] = 79, ["z"] = 2, ["name"] = "rainbow:render_white"}, {["x"] = 3, ["meta"] = {["fields"] = {}, ["inventory"] = {}}, ["y"] = 17, ["param1"] = 79, ["z"] = 10, ["name"] = "rainbow:render_white"}, {["x"] = 3, ["meta"] = {["fields"] = {}, ["inventory"] = {}}, ["y"] = 18, ["param1"] = 63, ["z"] = 2, ["name"] = "rainbow:render_white"}, {["x"] = 3, ["meta"] = {["fields"] = {}, ["inventory"] = {}}, ["param2"] = 21, ["y"] = 18, ["param1"] = 10, ["z"] = 4, ["name"] = "rainbow:slab_render_white_1"}, {["x"] = 3, ["meta"] = {["fields"] = {}, ["inventory"] = {}}, ["param2"] = 21, ["y"] = 18, ["param1"] = 11, ["z"] = 5, ["name"] = "rainbow:slab_render_white_1"}, {["x"] = 3, ["meta"] = {["fields"] = {}, ["inventory"] = {}}, ["param2"] = 21, ["y"] = 18, ["param1"] = 11, ["z"] = 6, ["name"] = "rainbow:slab_render_white_1"}, {["x"] = 3, ["meta"] = {["fields"] = {}, ["inventory"] = {}}, ["param2"] = 21, ["y"] = 18, ["param1"] = 11, ["z"] = 7, ["name"] = "rainbow:slab_render_white_1"}, {["x"] = 3, ["meta"] = {["fields"] = {}, ["inventory"] = {}}, ["param2"] = 21, ["y"] = 18, ["param1"] = 10, ["z"] = 8, ["name"] = "rainbow:slab_render_white_1"}, {["x"] = 3, ["meta"] = {["fields"] = {}, ["inventory"] = {}}, ["param2"] = 21, ["y"] = 18, ["param1"] = 9, ["z"] = 9, ["name"] = "rainbow:slab_render_white_1"}, {["x"] = 3, ["meta"] = {["fields"] = {}, ["inventory"] = {}}, ["y"] = 18, ["param1"] = 63, ["z"] = 10, ["name"] = "rainbow:render_white"}, {["x"] = 3, ["meta"] = {["fields"] = {}, ["inventory"] = {}}, ["y"] = 19, ["param1"] = 47, ["z"] = 2, ["name"] = "rainbow:render_white"}, {["x"] = 3, ["meta"] = {["fields"] = {}, ["inventory"] = {}}, ["y"] = 19, ["param1"] = 47, ["z"] = 10, ["name"] = "rainbow:render_white"}, {["x"] = 3, ["meta"] = {["fields"] = {}, ["inventory"] = {}}, ["y"] = 20, ["z"] = 3, ["name"] = "rainbow:render_white"}, {["x"] = 3, ["meta"] = {["fields"] = {}, ["inventory"] = {}}, ["y"] = 20, ["param1"] = 175, ["z"] = 8, ["name"] = "rainbow:render_white"}, {["x"] = 3, ["meta"] = {["fields"] = {}, ["inventory"] = {}}, ["y"] = 20, ["param1"] = 159, ["z"] = 9, ["name"] = "rainbow:render_white"}, {["x"] = 3, ["meta"] = {["fields"] = {}, ["inventory"] = {}}, ["y"] = 21, ["param1"] = 143, ["z"] = 3, ["name"] = "rainbow:render_white"}, {["x"] = 3, ["meta"] = {["fields"] = {}, ["inventory"] = {}}, ["y"] = 21, ["param1"] = 159, ["z"] = 8, ["name"] = "rainbow:render_white"}, {["x"] = 3, ["meta"] = {["fields"] = {}, ["inventory"] = {}}, ["y"] = 21, ["param1"] = 143, ["z"] = 9, ["name"] = "rainbow:render_white"}, {["x"] = 3, ["meta"] = {["fields"] = {}, ["inventory"] = {}}, ["y"] = 22, ["param1"] = 127, ["z"] = 3, ["name"] = "rainbow:render_white"}, {["x"] = 3, ["meta"] = {["fields"] = {}, ["inventory"] = {}}, ["y"] = 22, ["param1"] = 143, ["z"] = 8, ["name"] = "rainbow:render_white"}, {["x"] = 3, ["meta"] = {["fields"] = {}, ["inventory"] = {}}, ["y"] = 22, ["param1"] = 127, ["z"] = 9, ["name"] = "rainbow:render_white"}, {["x"] = 3, ["meta"] = {["fields"] = {}, ["inventory"] = {}}, ["y"] = 23, ["param1"] = 111, ["z"] = 3, ["name"] = "rainbow:render_white"}, {["x"] = 3, ["meta"] = {["fields"] = {}, ["inventory"] = {}}, ["y"] = 23, ["param1"] = 127, ["z"] = 8, ["name"] = "rainbow:render_white"}, {["x"] = 3, ["meta"] = {["fields"] = {}, ["inventory"] = {}}, ["y"] = 23, ["param1"] = 111, ["z"] = 9, ["name"] = "rainbow:render_white"}, {["x"] = 3, ["meta"] = {["fields"] = {}, ["inventory"] = {}}, ["y"] = 24, ["param1"] = 95, ["z"] = 3, ["name"] = "rainbow:render_white"}, {["x"] = 3, ["meta"] = {["fields"] = {}, ["inventory"] = {}}, ["y"] = 24, ["param1"] = 111, ["z"] = 8, ["name"] = "rainbow:render_white"}, {["x"] = 3, ["meta"] = {["fields"] = {}, ["inventory"] = {}}, ["y"] = 24, ["param1"] = 95, ["z"] = 9, ["name"] = "rainbow:render_white"}, {["x"] = 3, ["meta"] = {["fields"] = {}, ["inventory"] = {}}, ["y"] = 25, ["param1"] = 79, ["z"] = 3, ["name"] = "rainbow:render_white"}, {["x"] = 3, ["meta"] = {["fields"] = {}, ["inventory"] = {}}, ["y"] = 25, ["param1"] = 95, ["z"] = 8, ["name"] = "rainbow:render_white"}, {["x"] = 3, ["meta"] = {["fields"] = {}, ["inventory"] = {}}, ["y"] = 25, ["param1"] = 79, ["z"] = 9, ["name"] = "rainbow:render_white"}, {["x"] = 3, ["meta"] = {["fields"] = {}, ["inventory"] = {}}, ["y"] = 26, ["param1"] = 63, ["z"] = 3, ["name"] = "rainbow:render_white"}, {["x"] = 3, ["meta"] = {["fields"] = {}, ["inventory"] = {}}, ["y"] = 26, ["param1"] = 79, ["z"] = 8, ["name"] = "rainbow:render_white"}, {["x"] = 3, ["meta"] = {["fields"] = {}, ["inventory"] = {}}, ["y"] = 26, ["param1"] = 63, ["z"] = 9, ["name"] = "rainbow:render_white"}, {["x"] = 3, ["meta"] = {["fields"] = {}, ["inventory"] = {}}, ["y"] = 27, ["param1"] = 47, ["z"] = 3, ["name"] = "rainbow:render_white"}, {["x"] = 3, ["meta"] = {["fields"] = {}, ["inventory"] = {}}, ["y"] = 27, ["param1"] = 63, ["z"] = 8, ["name"] = "rainbow:render_white"}, {["x"] = 3, ["meta"] = {["fields"] = {}, ["inventory"] = {}}, ["y"] = 27, ["param1"] = 47, ["z"] = 9, ["name"] = "rainbow:render_white"}, {["x"] = 3, ["meta"] = {["fields"] = {}, ["inventory"] = {}}, ["y"] = 28, ["param1"] = 31, ["z"] = 3, ["name"] = "rainbow:render_white"}, {["x"] = 3, ["meta"] = {["fields"] = {}, ["inventory"] = {}}, ["y"] = 28, ["param1"] = 47, ["z"] = 4, ["name"] = "rainbow:render_white"}, {["x"] = 3, ["meta"] = {["fields"] = {}, ["inventory"] = {}}, ["y"] = 28, ["param1"] = 47, ["z"] = 8, ["name"] = "rainbow:render_white"}, {["x"] = 3, ["meta"] = {["fields"] = {}, ["inventory"] = {}}, ["y"] = 28, ["param1"] = 31, ["z"] = 9, ["name"] = "rainbow:render_white"}, {["x"] = 3, ["meta"] = {["fields"] = {}, ["inventory"] = {}}, ["y"] = 29, ["param1"] = 15, ["z"] = 3, ["name"] = "rainbow:render_white"}, {["x"] = 3, ["meta"] = {["fields"] = {}, ["inventory"] = {}}, ["y"] = 29, ["param1"] = 31, ["z"] = 4, ["name"] = "rainbow:render_white"}, {["x"] = 3, ["meta"] = {["fields"] = {}, ["inventory"] = {}}, ["y"] = 29, ["param1"] = 31, ["z"] = 8, ["name"] = "rainbow:render_white"}, {["x"] = 3, ["meta"] = {["fields"] = {}, ["inventory"] = {}}, ["y"] = 29, ["param1"] = 15, ["z"] = 9, ["name"] = "rainbow:render_white"}, {["x"] = 3, ["meta"] = {["fields"] = {}, ["inventory"] = {}}, ["y"] = 30, ["param1"] = 15, ["z"] = 3, ["name"] = "rainbow:render_white"}, {["x"] = 3, ["meta"] = {["fields"] = {}, ["inventory"] = {}}, ["y"] = 30, ["param1"] = 15, ["z"] = 4, ["name"] = "rainbow:render_white"}, {["x"] = 3, ["meta"] = {["fields"] = {}, ["inventory"] = {}}, ["y"] = 30, ["param1"] = 15, ["z"] = 8, ["name"] = "rainbow:render_white"}, {["x"] = 3, ["meta"] = {["fields"] = {}, ["inventory"] = {}}, ["y"] = 30, ["param1"] = 15, ["z"] = 9, ["name"] = "rainbow:render_white"}, {["x"] = 3, ["meta"] = {["fields"] = {}, ["inventory"] = {}}, ["y"] = 31, ["param1"] = 15, ["z"] = 3, ["name"] = "rainbow:render_white"}, {["x"] = 3, ["meta"] = {["fields"] = {}, ["inventory"] = {}}, ["y"] = 31, ["param1"] = 15, ["z"] = 4, ["name"] = "rainbow:render_white"}, {["x"] = 3, ["meta"] = {["fields"] = {}, ["inventory"] = {}}, ["y"] = 31, ["param1"] = 15, ["z"] = 8, ["name"] = "rainbow:render_white"}, {["x"] = 3, ["meta"] = {["fields"] = {}, ["inventory"] = {}}, ["y"] = 31, ["param1"] = 15, ["z"] = 9, ["name"] = "rainbow:render_white"}, {["x"] = 3, ["meta"] = {["fields"] = {}, ["inventory"] = {}}, ["y"] = 32, ["param1"] = 15, ["z"] = 3, ["name"] = "rainbow:render_white"}, {["x"] = 3, ["meta"] = {["fields"] = {}, ["inventory"] = {}}, ["y"] = 32, ["param1"] = 15, ["z"] = 4, ["name"] = "rainbow:render_white"}, {["x"] = 3, ["meta"] = {["fields"] = {}, ["inventory"] = {}}, ["y"] = 32, ["param1"] = 15, ["z"] = 8, ["name"] = "rainbow:render_white"}, {["x"] = 3, ["meta"] = {["fields"] = {}, ["inventory"] = {}}, ["y"] = 32, ["param1"] = 15, ["z"] = 9, ["name"] = "rainbow:render_white"}, {["x"] = 3, ["meta"] = {["fields"] = {}, ["inventory"] = {}}, ["y"] = 33, ["param1"] = 15, ["z"] = 3, ["name"] = "rainbow:render_white"}, {["x"] = 3, ["meta"] = {["fields"] = {}, ["inventory"] = {}}, ["y"] = 33, ["param1"] = 15, ["z"] = 4, ["name"] = "rainbow:render_white"}, {["x"] = 3, ["meta"] = {["fields"] = {}, ["inventory"] = {}}, ["y"] = 33, ["param1"] = 15, ["z"] = 8, ["name"] = "rainbow:render_white"}, {["x"] = 3, ["meta"] = {["fields"] = {}, ["inventory"] = {}}, ["y"] = 33, ["param1"] = 15, ["z"] = 9, ["name"] = "rainbow:render_white"}, {["x"] = 3, ["meta"] = {["fields"] = {}, ["inventory"] = {}}, ["y"] = 34, ["param1"] = 15, ["z"] = 3, ["name"] = "rainbow:render_white"}, {["x"] = 3, ["meta"] = {["fields"] = {}, ["inventory"] = {}}, ["y"] = 34, ["param1"] = 15, ["z"] = 4, ["name"] = "rainbow:render_white"}, {["x"] = 3, ["meta"] = {["fields"] = {}, ["inventory"] = {}}, ["y"] = 34, ["param1"] = 15, ["z"] = 8, ["name"] = "rainbow:render_white"}, {["x"] = 3, ["meta"] = {["fields"] = {}, ["inventory"] = {}}, ["y"] = 34, ["param1"] = 15, ["z"] = 9, ["name"] = "rainbow:render_white"}, {["x"] = 3, ["meta"] = {["fields"] = {}, ["inventory"] = {}}, ["y"] = 35, ["param1"] = 15, ["z"] = 3, ["name"] = "rainbow:render_white"}, {["x"] = 3, ["meta"] = {["fields"] = {}, ["inventory"] = {}}, ["y"] = 35, ["param1"] = 15, ["z"] = 4, ["name"] = "rainbow:render_white"}, {["x"] = 3, ["meta"] = {["fields"] = {}, ["inventory"] = {}}, ["y"] = 35, ["param1"] = 15, ["z"] = 8, ["name"] = "rainbow:render_white"}, {["x"] = 3, ["meta"] = {["fields"] = {}, ["inventory"] = {}}, ["y"] = 35, ["param1"] = 15, ["z"] = 9, ["name"] = "rainbow:render_white"}, {["x"] = 3, ["meta"] = {["fields"] = {}, ["inventory"] = {}}, ["y"] = 36, ["param1"] = 15, ["z"] = 3, ["name"] = "rainbow:render_white"}, {["x"] = 3, ["meta"] = {["fields"] = {}, ["inventory"] = {}}, ["y"] = 36, ["param1"] = 15, ["z"] = 4, ["name"] = "rainbow:render_white"}, {["x"] = 3, ["meta"] = {["fields"] = {}, ["inventory"] = {}}, ["y"] = 36, ["param1"] = 15, ["z"] = 8, ["name"] = "rainbow:render_white"}, {["x"] = 3, ["meta"] = {["fields"] = {}, ["inventory"] = {}}, ["y"] = 36, ["param1"] = 15, ["z"] = 9, ["name"] = "rainbow:render_white"}, {["x"] = 3, ["meta"] = {["fields"] = {}, ["inventory"] = {}}, ["y"] = 37, ["param1"] = 15, ["z"] = 3, ["name"] = "rainbow:render_white"}, {["x"] = 3, ["meta"] = {["fields"] = {}, ["inventory"] = {}}, ["y"] = 37, ["param1"] = 15, ["z"] = 4, ["name"] = "rainbow:render_white"}, {["x"] = 3, ["meta"] = {["fields"] = {}, ["inventory"] = {}}, ["y"] = 37, ["param1"] = 15, ["z"] = 8, ["name"] = "rainbow:render_white"}, {["x"] = 3, ["meta"] = {["fields"] = {}, ["inventory"] = {}}, ["y"] = 37, ["param1"] = 15, ["z"] = 9, ["name"] = "rainbow:render_white"}, {["x"] = 3, ["meta"] = {["fields"] = {}, ["inventory"] = {}}, ["y"] = 38, ["param1"] = 15, ["z"] = 3, ["name"] = "rainbow:render_white"}, {["x"] = 3, ["meta"] = {["fields"] = {}, ["inventory"] = {}}, ["y"] = 38, ["param1"] = 15, ["z"] = 4, ["name"] = "rainbow:render_white"}, {["x"] = 3, ["meta"] = {["fields"] = {}, ["inventory"] = {}}, ["y"] = 38, ["z"] = 6, ["name"] = "default:meselamp"}, {["x"] = 3, ["meta"] = {["fields"] = {}, ["inventory"] = {}}, ["y"] = 38, ["param1"] = 15, ["z"] = 8, ["name"] = "rainbow:render_white"}, {["x"] = 3, ["meta"] = {["fields"] = {}, ["inventory"] = {}}, ["y"] = 38, ["param1"] = 15, ["z"] = 9, ["name"] = "rainbow:render_white"}, {["x"] = 3, ["meta"] = {["fields"] = {}, ["inventory"] = {}}, ["param2"] = 1, ["y"] = 39, ["param1"] = 15, ["z"] = 3, ["name"] = "moreblocks:slope_steelblock_outer"}, {["x"] = 3, ["meta"] = {["fields"] = {}, ["inventory"] = {}}, ["y"] = 39, ["z"] = 4, ["name"] = "rainbow:render_white"}, {["x"] = 3, ["meta"] = {["fields"] = {}, ["inventory"] = {}}, ["y"] = 39, ["param1"] = 207, ["z"] = 5, ["name"] = "rainbow:render_white"}, {["x"] = 3, ["meta"] = {["fields"] = {}, ["inventory"] = {}}, ["y"] = 39, ["param1"] = 223, ["z"] = 6, ["name"] = "rainbow:render_white"}, {["x"] = 3, ["meta"] = {["fields"] = {}, ["inventory"] = {}}, ["y"] = 39, ["param1"] = 207, ["z"] = 7, ["name"] = "rainbow:render_white"}, {["x"] = 3, ["meta"] = {["fields"] = {}, ["inventory"] = {}}, ["y"] = 39, ["z"] = 8, ["name"] = "rainbow:render_white"}, {["x"] = 3, ["meta"] = {["fields"] = {}, ["inventory"] = {}}, ["param2"] = 2, ["y"] = 39, ["param1"] = 15, ["z"] = 9, ["name"] = "moreblocks:slope_steelblock_outer"}, {["x"] = 3, ["meta"] = {["fields"] = {}, ["inventory"] = {}}, ["param2"] = 1, ["y"] = 40, ["param1"] = 15, ["z"] = 4, ["name"] = "moreblocks:slope_steelblock_outer"}, {["x"] = 3, ["meta"] = {["fields"] = {}, ["inventory"] = {}}, ["y"] = 40, ["param1"] = 191, ["z"] = 5, ["name"] = "rainbow:render_white"}, {["x"] = 3, ["meta"] = {["fields"] = {}, ["inventory"] = {}}, ["y"] = 40, ["param1"] = 207, ["z"] = 6, ["name"] = "rainbow:render_white"}, {["x"] = 3, ["meta"] = {["fields"] = {}, ["inventory"] = {}}, ["y"] = 40, ["param1"] = 191, ["z"] = 7, ["name"] = "rainbow:render_white"}, {["x"] = 3, ["meta"] = {["fields"] = {}, ["inventory"] = {}}, ["param2"] = 2, ["y"] = 40, ["param1"] = 15, ["z"] = 8, ["name"] = "moreblocks:slope_steelblock_outer"}, {["x"] = 3, ["meta"] = {["fields"] = {}, ["inventory"] = {}}, ["y"] = 41, ["param1"] = 175, ["z"] = 5, ["name"] = "rainbow:render_white"}, {["x"] = 3, ["meta"] = {["fields"] = {}, ["inventory"] = {}}, ["y"] = 41, ["param1"] = 191, ["z"] = 6, ["name"] = "rainbow:render_white"}, {["x"] = 3, ["meta"] = {["fields"] = {}, ["inventory"] = {}}, ["y"] = 41, ["param1"] = 175, ["z"] = 7, ["name"] = "rainbow:render_white"}, {["x"] = 3, ["meta"] = {["fields"] = {}, ["inventory"] = {}}, ["y"] = 42, ["param1"] = 159, ["z"] = 5, ["name"] = "rainbow:render_white"}, {["x"] = 3, ["meta"] = {["fields"] = {}, ["inventory"] = {}}, ["y"] = 42, ["param1"] = 175, ["z"] = 6, ["name"] = "rainbow:render_white"}, {["x"] = 3, ["meta"] = {["fields"] = {}, ["inventory"] = {}}, ["y"] = 42, ["param1"] = 159, ["z"] = 7, ["name"] = "rainbow:render_white"}, {["x"] = 3, ["meta"] = {["fields"] = {}, ["inventory"] = {}}, ["y"] = 43, ["param1"] = 143, ["z"] = 5, ["name"] = "rainbow:render_white"}, {["x"] = 3, ["meta"] = {["fields"] = {}, ["inventory"] = {}}, ["y"] = 43, ["param1"] = 159, ["z"] = 6, ["name"] = "rainbow:render_white"}, {["x"] = 3, ["meta"] = {["fields"] = {}, ["inventory"] = {}}, ["y"] = 43, ["param1"] = 143, ["z"] = 7, ["name"] = "rainbow:render_white"}, {["x"] = 3, ["meta"] = {["fields"] = {}, ["inventory"] = {}}, ["y"] = 44, ["param1"] = 127, ["z"] = 5, ["name"] = "rainbow:render_white"}, {["x"] = 3, ["meta"] = {["fields"] = {}, ["inventory"] = {}}, ["y"] = 44, ["param1"] = 143, ["z"] = 6, ["name"] = "rainbow:render_white"}, {["x"] = 3, ["meta"] = {["fields"] = {}, ["inventory"] = {}}, ["y"] = 44, ["param1"] = 127, ["z"] = 7, ["name"] = "rainbow:render_white"}, {["x"] = 3, ["meta"] = {["fields"] = {}, ["inventory"] = {}}, ["y"] = 45, ["param1"] = 111, ["z"] = 5, ["name"] = "rainbow:render_white"}, {["x"] = 3, ["meta"] = {["fields"] = {}, ["inventory"] = {}}, ["y"] = 45, ["param1"] = 127, ["z"] = 6, ["name"] = "rainbow:render_white"}, {["x"] = 3, ["meta"] = {["fields"] = {}, ["inventory"] = {}}, ["y"] = 45, ["param1"] = 111, ["z"] = 7, ["name"] = "rainbow:render_white"}, {["x"] = 3, ["meta"] = {["fields"] = {}, ["inventory"] = {}}, ["y"] = 46, ["param1"] = 95, ["z"] = 5, ["name"] = "rainbow:render_white"}, {["x"] = 3, ["meta"] = {["fields"] = {}, ["inventory"] = {}}, ["y"] = 46, ["param1"] = 111, ["z"] = 6, ["name"] = "rainbow:render_white"}, {["x"] = 3, ["meta"] = {["fields"] = {}, ["inventory"] = {}}, ["y"] = 46, ["param1"] = 95, ["z"] = 7, ["name"] = "rainbow:render_white"}, {["x"] = 3, ["meta"] = {["fields"] = {}, ["inventory"] = {}}, ["y"] = 47, ["param1"] = 79, ["z"] = 5, ["name"] = "rainbow:render_white"}, {["x"] = 3, ["meta"] = {["fields"] = {}, ["inventory"] = {}}, ["y"] = 47, ["param1"] = 95, ["z"] = 6, ["name"] = "rainbow:render_white"}, {["x"] = 3, ["meta"] = {["fields"] = {}, ["inventory"] = {}}, ["y"] = 47, ["param1"] = 79, ["z"] = 7, ["name"] = "rainbow:render_white"}, {["x"] = 3, ["meta"] = {["fields"] = {}, ["inventory"] = {}}, ["y"] = 48, ["param1"] = 63, ["z"] = 5, ["name"] = "rainbow:render_white"}, {["x"] = 3, ["meta"] = {["fields"] = {}, ["inventory"] = {}}, ["y"] = 48, ["param1"] = 79, ["z"] = 6, ["name"] = "rainbow:render_white"}, {["x"] = 3, ["meta"] = {["fields"] = {}, ["inventory"] = {}}, ["y"] = 48, ["param1"] = 63, ["z"] = 7, ["name"] = "rainbow:render_white"}, {["x"] = 3, ["meta"] = {["fields"] = {}, ["inventory"] = {}}, ["y"] = 49, ["param1"] = 47, ["z"] = 5, ["name"] = "rainbow:render_white"}, {["x"] = 3, ["meta"] = {["fields"] = {}, ["inventory"] = {}}, ["y"] = 49, ["param1"] = 63, ["z"] = 6, ["name"] = "rainbow:render_white"}, {["x"] = 3, ["meta"] = {["fields"] = {}, ["inventory"] = {}}, ["y"] = 49, ["param1"] = 47, ["z"] = 7, ["name"] = "rainbow:render_white"}, {["x"] = 3, ["meta"] = {["fields"] = {}, ["inventory"] = {}}, ["y"] = 50, ["param1"] = 31, ["z"] = 5, ["name"] = "rainbow:render_white"}, {["x"] = 3, ["meta"] = {["fields"] = {}, ["inventory"] = {}}, ["y"] = 50, ["param1"] = 47, ["z"] = 6, ["name"] = "rainbow:render_white"}, {["x"] = 3, ["meta"] = {["fields"] = {}, ["inventory"] = {}}, ["y"] = 50, ["param1"] = 31, ["z"] = 7, ["name"] = "rainbow:render_white"}, {["x"] = 3, ["meta"] = {["fields"] = {}, ["inventory"] = {}}, ["y"] = 51, ["param1"] = 15, ["z"] = 5, ["name"] = "rainbow:render_white"}, {["x"] = 3, ["meta"] = {["fields"] = {}, ["inventory"] = {}}, ["y"] = 51, ["param1"] = 31, ["z"] = 6, ["name"] = "rainbow:render_white"}, {["x"] = 3, ["meta"] = {["fields"] = {}, ["inventory"] = {}}, ["y"] = 51, ["param1"] = 15, ["z"] = 7, ["name"] = "rainbow:render_white"}, {["x"] = 3, ["meta"] = {["fields"] = {}, ["inventory"] = {}}, ["y"] = 52, ["param1"] = 15, ["z"] = 5, ["name"] = "rainbow:render_white"}, {["x"] = 3, ["meta"] = {["fields"] = {}, ["inventory"] = {}}, ["y"] = 52, ["param1"] = 15, ["z"] = 6, ["name"] = "rainbow:render_white"}, {["x"] = 3, ["meta"] = {["fields"] = {}, ["inventory"] = {}}, ["y"] = 52, ["param1"] = 15, ["z"] = 7, ["name"] = "rainbow:render_white"}, {["x"] = 3, ["meta"] = {["fields"] = {}, ["inventory"] = {}}, ["y"] = 53, ["param1"] = 15, ["z"] = 5, ["name"] = "rainbow:render_white"}, {["x"] = 3, ["meta"] = {["fields"] = {}, ["inventory"] = {}}, ["y"] = 53, ["param1"] = 15, ["z"] = 6, ["name"] = "rainbow:render_white"}, {["x"] = 3, ["meta"] = {["fields"] = {}, ["inventory"] = {}}, ["y"] = 53, ["param1"] = 15, ["z"] = 7, ["name"] = "rainbow:render_white"}, {["x"] = 3, ["meta"] = {["fields"] = {}, ["inventory"] = {}}, ["y"] = 54, ["param1"] = 15, ["z"] = 5, ["name"] = "rainbow:render_white"}, {["x"] = 3, ["meta"] = {["fields"] = {}, ["inventory"] = {}}, ["y"] = 54, ["param1"] = 15, ["z"] = 6, ["name"] = "rainbow:render_white"}, {["x"] = 3, ["meta"] = {["fields"] = {}, ["inventory"] = {}}, ["y"] = 54, ["param1"] = 15, ["z"] = 7, ["name"] = "rainbow:render_white"}, {["x"] = 3, ["meta"] = {["fields"] = {}, ["inventory"] = {}}, ["y"] = 55, ["param1"] = 15, ["z"] = 5, ["name"] = "rainbow:render_white"}, {["x"] = 3, ["meta"] = {["fields"] = {}, ["inventory"] = {}}, ["y"] = 55, ["param1"] = 15, ["z"] = 6, ["name"] = "rainbow:render_white"}, {["x"] = 3, ["meta"] = {["fields"] = {}, ["inventory"] = {}}, ["y"] = 55, ["param1"] = 15, ["z"] = 7, ["name"] = "rainbow:render_white"}, {["x"] = 3, ["meta"] = {["fields"] = {}, ["inventory"] = {}}, ["y"] = 56, ["param1"] = 15, ["z"] = 5, ["name"] = "rainbow:render_white"}, {["x"] = 3, ["meta"] = {["fields"] = {}, ["inventory"] = {}}, ["y"] = 56, ["param1"] = 15, ["z"] = 6, ["name"] = "rainbow:render_white"}, {["x"] = 3, ["meta"] = {["fields"] = {}, ["inventory"] = {}}, ["y"] = 56, ["param1"] = 15, ["z"] = 7, ["name"] = "rainbow:render_white"}, {["x"] = 3, ["meta"] = {["fields"] = {}, ["inventory"] = {}}, ["y"] = 57, ["param1"] = 15, ["z"] = 5, ["name"] = "rainbow:render_white"}, {["x"] = 3, ["meta"] = {["fields"] = {}, ["inventory"] = {}}, ["y"] = 57, ["param1"] = 15, ["z"] = 6, ["name"] = "rainbow:render_white"}, {["x"] = 3, ["meta"] = {["fields"] = {}, ["inventory"] = {}}, ["y"] = 57, ["param1"] = 15, ["z"] = 7, ["name"] = "rainbow:render_white"}, {["x"] = 3, ["meta"] = {["fields"] = {}, ["inventory"] = {}}, ["y"] = 58, ["param1"] = 15, ["z"] = 5, ["name"] = "rainbow:render_white"}, {["x"] = 3, ["meta"] = {["fields"] = {}, ["inventory"] = {}}, ["y"] = 58, ["param1"] = 15, ["z"] = 6, ["name"] = "rainbow:render_white"}, {["x"] = 3, ["meta"] = {["fields"] = {}, ["inventory"] = {}}, ["y"] = 58, ["param1"] = 15, ["z"] = 7, ["name"] = "rainbow:render_white"}, {["x"] = 3, ["meta"] = {["fields"] = {}, ["inventory"] = {}}, ["param2"] = 1, ["y"] = 59, ["param1"] = 15, ["z"] = 5, ["name"] = "moreblocks:slope_steelblock_outer"}, {["x"] = 3, ["meta"] = {["fields"] = {}, ["inventory"] = {}}, ["param2"] = 1, ["y"] = 59, ["param1"] = 15, ["z"] = 6, ["name"] = "moreblocks:slope_steelblock"}, {["x"] = 3, ["meta"] = {["fields"] = {}, ["inventory"] = {}}, ["param2"] = 2, ["y"] = 59, ["param1"] = 15, ["z"] = 7, ["name"] = "moreblocks:slope_steelblock_outer"}, {["x"] = 4, ["meta"] = {["fields"] = {}, ["inventory"] = {}}, ["param2"] = 1, ["y"] = 0, ["param1"] = 94, ["z"] = 0, ["name"] = "rainbow:slope_render_white_outer"}, {["x"] = 4, ["meta"] = {["fields"] = {}, ["inventory"] = {}}, ["y"] = 0, ["param1"] = 111, ["z"] = 1, ["name"] = "rainbow:render_white"}, {["x"] = 4, ["meta"] = {["fields"] = {}, ["inventory"] = {}}, ["y"] = 0, ["param1"] = 111, ["z"] = 11, ["name"] = "rainbow:render_white"}, {["x"] = 4, ["meta"] = {["fields"] = {}, ["inventory"] = {}}, ["param2"] = 2, ["y"] = 0, ["param1"] = 94, ["z"] = 12, ["name"] = "rainbow:slope_render_white_outer"}, {["x"] = 4, ["meta"] = {["fields"] = {}, ["inventory"] = {}}, ["y"] = 1, ["param1"] = 95, ["z"] = 1, ["name"] = "rainbow:render_white"}, {["x"] = 4, ["meta"] = {["fields"] = {}, ["inventory"] = {}}, ["param2"] = 21, ["y"] = 1, ["param1"] = 123, ["z"] = 3, ["name"] = "rainbow:slope_render_white"}, {["x"] = 4, ["meta"] = {["fields"] = {}, ["inventory"] = {}}, ["y"] = 1, ["param1"] = 95, ["z"] = 11, ["name"] = "rainbow:render_white"}, {["x"] = 4, ["meta"] = {["fields"] = {}, ["inventory"] = {}}, ["y"] = 2, ["param1"] = 79, ["z"] = 1, ["name"] = "rainbow:render_white"}, {["x"] = 4, ["meta"] = {["fields"] = {}, ["inventory"] = {}}, ["param2"] = 1, ["y"] = 2, ["param1"] = 107, ["z"] = 3, ["name"] = "rainbow:slope_render_white"}, {["x"] = 4, ["meta"] = {["fields"] = {}, ["inventory"] = {}}, ["y"] = 2, ["param1"] = 79, ["z"] = 11, ["name"] = "rainbow:render_white"}, {["x"] = 4, ["meta"] = {["fields"] = {}, ["inventory"] = {}}, ["y"] = 3, ["param1"] = 63, ["z"] = 1, ["name"] = "rainbow:render_white"}, {["x"] = 4, ["meta"] = {["fields"] = {}, ["inventory"] = {}}, ["param2"] = 21, ["y"] = 3, ["param1"] = 75, ["z"] = 2, ["name"] = "rainbow:slab_render_white_1"}, {["x"] = 4, ["meta"] = {["fields"] = {}, ["inventory"] = {}}, ["param2"] = 21, ["y"] = 3, ["param1"] = 105, ["z"] = 4, ["name"] = "rainbow:slab_render_white_1"}, {["x"] = 4, ["meta"] = {["fields"] = {}, ["inventory"] = {}}, ["param2"] = 21, ["y"] = 3, ["param1"] = 122, ["z"] = 5, ["name"] = "rainbow:slab_render_white_1"}, {["x"] = 4, ["meta"] = {["fields"] = {}, ["inventory"] = {}}, ["param2"] = 21, ["y"] = 3, ["param1"] = 138, ["z"] = 6, ["name"] = "rainbow:slab_render_white_1"}, {["x"] = 4, ["meta"] = {["fields"] = {}, ["inventory"] = {}}, ["param2"] = 21, ["y"] = 3, ["param1"] = 122, ["z"] = 7, ["name"] = "rainbow:slab_render_white_1"}, {["x"] = 4, ["meta"] = {["fields"] = {}, ["inventory"] = {}}, ["param2"] = 21, ["y"] = 3, ["param1"] = 105, ["z"] = 8, ["name"] = "rainbow:slab_render_white_1"}, {["x"] = 4, ["meta"] = {["fields"] = {}, ["inventory"] = {}}, ["param2"] = 21, ["y"] = 3, ["param1"] = 90, ["z"] = 9, ["name"] = "rainbow:slab_render_white_1"}, {["x"] = 4, ["meta"] = {["fields"] = {}, ["inventory"] = {}}, ["param2"] = 20, ["y"] = 3, ["param1"] = 75, ["z"] = 10, ["name"] = "rainbow:slab_render_white_1"}, {["x"] = 4, ["meta"] = {["fields"] = {}, ["inventory"] = {}}, ["y"] = 3, ["param1"] = 63, ["z"] = 11, ["name"] = "rainbow:render_white"}, {["x"] = 4, ["meta"] = {["fields"] = {}, ["inventory"] = {}}, ["y"] = 4, ["param1"] = 47, ["z"] = 1, ["name"] = "rainbow:render_white"}, {["x"] = 4, ["meta"] = {["fields"] = {}, ["inventory"] = {}}, ["y"] = 4, ["param1"] = 47, ["z"] = 11, ["name"] = "rainbow:render_white"}, {["x"] = 4, ["meta"] = {["fields"] = {}, ["inventory"] = {}}, ["y"] = 5, ["param1"] = 111, ["z"] = 1, ["name"] = "rainbow:render_white"}, {["x"] = 4, ["meta"] = {["fields"] = {}, ["inventory"] = {}}, ["y"] = 5, ["param1"] = 111, ["z"] = 11, ["name"] = "rainbow:render_white"}, {["x"] = 4, ["meta"] = {["fields"] = {}, ["inventory"] = {}}, ["y"] = 6, ["param1"] = 95, ["z"] = 1, ["name"] = "rainbow:render_white"}, {["x"] = 4, ["meta"] = {["fields"] = {}, ["inventory"] = {}}, ["param2"] = 21, ["y"] = 6, ["param1"] = 43, ["z"] = 3, ["name"] = "rainbow:slope_render_white"}, {["x"] = 4, ["meta"] = {["fields"] = {}, ["inventory"] = {}}, ["y"] = 6, ["param1"] = 95, ["z"] = 11, ["name"] = "rainbow:render_white"}, {["x"] = 4, ["meta"] = {["fields"] = {}, ["inventory"] = {}}, ["y"] = 7, ["param1"] = 79, ["z"] = 1, ["name"] = "rainbow:render_white"}, {["x"] = 4, ["meta"] = {["fields"] = {}, ["inventory"] = {}}, ["param2"] = 1, ["y"] = 7, ["param1"] = 27, ["z"] = 3, ["name"] = "rainbow:slope_render_white"}, {["x"] = 4, ["meta"] = {["fields"] = {}, ["inventory"] = {}}, ["y"] = 7, ["param1"] = 79, ["z"] = 11, ["name"] = "rainbow:render_white"}, {["x"] = 4, ["meta"] = {["fields"] = {}, ["inventory"] = {}}, ["y"] = 8, ["param1"] = 63, ["z"] = 1, ["name"] = "rainbow:render_white"}, {["x"] = 4, ["meta"] = {["fields"] = {}, ["inventory"] = {}}, ["param2"] = 21, ["y"] = 8, ["param1"] = 11, ["z"] = 2, ["name"] = "rainbow:slab_render_white_1"}, {["x"] = 4, ["meta"] = {["fields"] = {}, ["inventory"] = {}}, ["param2"] = 21, ["y"] = 8, ["param1"] = 25, ["z"] = 4, ["name"] = "rainbow:slab_render_white_1"}, {["x"] = 4, ["meta"] = {["fields"] = {}, ["inventory"] = {}}, ["param2"] = 21, ["y"] = 8, ["param1"] = 42, ["z"] = 5, ["name"] = "rainbow:slab_render_white_1"}, {["x"] = 4, ["meta"] = {["fields"] = {}, ["inventory"] = {}}, ["param2"] = 21, ["y"] = 8, ["param1"] = 58, ["z"] = 6, ["name"] = "rainbow:slab_render_white_1"}, {["x"] = 4, ["meta"] = {["fields"] = {}, ["inventory"] = {}}, ["param2"] = 21, ["y"] = 8, ["param1"] = 42, ["z"] = 7, ["name"] = "rainbow:slab_render_white_1"}, {["x"] = 4, ["meta"] = {["fields"] = {}, ["inventory"] = {}}, ["param2"] = 21, ["y"] = 8, ["param1"] = 25, ["z"] = 8, ["name"] = "rainbow:slab_render_white_1"}, {["x"] = 4, ["meta"] = {["fields"] = {}, ["inventory"] = {}}, ["param2"] = 21, ["y"] = 8, ["param1"] = 10, ["z"] = 9, ["name"] = "rainbow:slab_render_white_1"}, {["x"] = 4, ["meta"] = {["fields"] = {}, ["inventory"] = {}}, ["param2"] = 21, ["y"] = 8, ["param1"] = 11, ["z"] = 10, ["name"] = "rainbow:slab_render_white_1"}, {["x"] = 4, ["meta"] = {["fields"] = {}, ["inventory"] = {}}, ["y"] = 8, ["param1"] = 63, ["z"] = 11, ["name"] = "rainbow:render_white"}, {["x"] = 4, ["meta"] = {["fields"] = {}, ["inventory"] = {}}, ["y"] = 9, ["param1"] = 47, ["z"] = 1, ["name"] = "rainbow:render_white"}, {["x"] = 4, ["meta"] = {["fields"] = {}, ["inventory"] = {}}, ["y"] = 9, ["param1"] = 47, ["z"] = 11, ["name"] = "rainbow:render_white"}, {["x"] = 4, ["meta"] = {["fields"] = {}, ["inventory"] = {}}, ["y"] = 10, ["param1"] = 111, ["z"] = 1, ["name"] = "rainbow:render_white"}, {["x"] = 4, ["meta"] = {["fields"] = {}, ["inventory"] = {}}, ["y"] = 10, ["param1"] = 111, ["z"] = 11, ["name"] = "rainbow:render_white"}, {["x"] = 4, ["meta"] = {["fields"] = {}, ["inventory"] = {}}, ["y"] = 11, ["param1"] = 95, ["z"] = 1, ["name"] = "rainbow:render_white"}, {["x"] = 4, ["meta"] = {["fields"] = {}, ["inventory"] = {}}, ["param2"] = 21, ["y"] = 11, ["param1"] = 11, ["z"] = 3, ["name"] = "rainbow:slope_render_white"}, {["x"] = 4, ["meta"] = {["fields"] = {}, ["inventory"] = {}}, ["y"] = 11, ["param1"] = 95, ["z"] = 11, ["name"] = "rainbow:render_white"}, {["x"] = 4, ["meta"] = {["fields"] = {}, ["inventory"] = {}}, ["y"] = 12, ["param1"] = 79, ["z"] = 1, ["name"] = "rainbow:render_white"}, {["x"] = 4, ["meta"] = {["fields"] = {}, ["inventory"] = {}}, ["param2"] = 1, ["y"] = 12, ["param1"] = 11, ["z"] = 3, ["name"] = "rainbow:slope_render_white"}, {["x"] = 4, ["meta"] = {["fields"] = {}, ["inventory"] = {}}, ["y"] = 12, ["param1"] = 79, ["z"] = 11, ["name"] = "rainbow:render_white"}, {["x"] = 4, ["meta"] = {["fields"] = {}, ["inventory"] = {}}, ["y"] = 13, ["param1"] = 63, ["z"] = 1, ["name"] = "rainbow:render_white"}, {["x"] = 4, ["meta"] = {["fields"] = {}, ["inventory"] = {}}, ["param2"] = 21, ["y"] = 13, ["param1"] = 11, ["z"] = 2, ["name"] = "rainbow:slab_render_white_1"}, {["x"] = 4, ["meta"] = {["fields"] = {}, ["inventory"] = {}}, ["param2"] = 21, ["y"] = 13, ["param1"] = 9, ["z"] = 4, ["name"] = "rainbow:slab_render_white_1"}, {["x"] = 4, ["meta"] = {["fields"] = {}, ["inventory"] = {}}, ["param2"] = 21, ["y"] = 13, ["param1"] = 10, ["z"] = 5, ["name"] = "rainbow:slab_render_white_1"}, {["x"] = 4, ["meta"] = {["fields"] = {}, ["inventory"] = {}}, ["param2"] = 21, ["y"] = 13, ["param1"] = 10, ["z"] = 6, ["name"] = "rainbow:slab_render_white_1"}, {["x"] = 4, ["meta"] = {["fields"] = {}, ["inventory"] = {}}, ["param2"] = 21, ["y"] = 13, ["param1"] = 10, ["z"] = 7, ["name"] = "rainbow:slab_render_white_1"}, {["x"] = 4, ["meta"] = {["fields"] = {}, ["inventory"] = {}}, ["param2"] = 21, ["y"] = 13, ["param1"] = 9, ["z"] = 8, ["name"] = "rainbow:slab_render_white_1"}, {["x"] = 4, ["meta"] = {["fields"] = {}, ["inventory"] = {}}, ["param2"] = 21, ["y"] = 13, ["param1"] = 10, ["z"] = 9, ["name"] = "rainbow:slab_render_white_1"}, {["x"] = 4, ["meta"] = {["fields"] = {}, ["inventory"] = {}}, ["param2"] = 20, ["y"] = 13, ["param1"] = 11, ["z"] = 10, ["name"] = "rainbow:slab_render_white_1"}, {["x"] = 4, ["meta"] = {["fields"] = {}, ["inventory"] = {}}, ["y"] = 13, ["param1"] = 63, ["z"] = 11, ["name"] = "rainbow:render_white"}, {["x"] = 4, ["meta"] = {["fields"] = {}, ["inventory"] = {}}, ["y"] = 14, ["param1"] = 47, ["z"] = 1, ["name"] = "rainbow:render_white"}, {["x"] = 4, ["meta"] = {["fields"] = {}, ["inventory"] = {}}, ["y"] = 14, ["param1"] = 47, ["z"] = 11, ["name"] = "rainbow:render_white"}, {["x"] = 4, ["meta"] = {["fields"] = {}, ["inventory"] = {}}, ["y"] = 15, ["param1"] = 111, ["z"] = 1, ["name"] = "rainbow:render_white"}, {["x"] = 4, ["meta"] = {["fields"] = {}, ["inventory"] = {}}, ["y"] = 15, ["param1"] = 111, ["z"] = 11, ["name"] = "rainbow:render_white"}, {["x"] = 4, ["meta"] = {["fields"] = {}, ["inventory"] = {}}, ["y"] = 16, ["param1"] = 95, ["z"] = 1, ["name"] = "rainbow:render_white"}, {["x"] = 4, ["meta"] = {["fields"] = {}, ["inventory"] = {}}, ["param2"] = 21, ["y"] = 16, ["param1"] = 11, ["z"] = 3, ["name"] = "rainbow:slope_render_white"}, {["x"] = 4, ["meta"] = {["fields"] = {}, ["inventory"] = {}}, ["y"] = 16, ["param1"] = 95, ["z"] = 11, ["name"] = "rainbow:render_white"}, {["x"] = 4, ["meta"] = {["fields"] = {}, ["inventory"] = {}}, ["y"] = 17, ["param1"] = 79, ["z"] = 1, ["name"] = "rainbow:render_white"}, {["x"] = 4, ["meta"] = {["fields"] = {}, ["inventory"] = {}}, ["param2"] = 1, ["y"] = 17, ["param1"] = 11, ["z"] = 3, ["name"] = "rainbow:slope_render_white"}, {["x"] = 4, ["meta"] = {["fields"] = {}, ["inventory"] = {}}, ["y"] = 17, ["param1"] = 79, ["z"] = 11, ["name"] = "rainbow:render_white"}, {["x"] = 4, ["meta"] = {["fields"] = {}, ["inventory"] = {}}, ["y"] = 18, ["param1"] = 63, ["z"] = 1, ["name"] = "rainbow:render_white"}, {["x"] = 4, ["meta"] = {["fields"] = {}, ["inventory"] = {}}, ["param2"] = 22, ["y"] = 18, ["param1"] = 11, ["z"] = 2, ["name"] = "rainbow:slab_render_white_1"}, {["x"] = 4, ["meta"] = {["fields"] = {}, ["inventory"] = {}}, ["param2"] = 21, ["y"] = 18, ["param1"] = 9, ["z"] = 4, ["name"] = "rainbow:slab_render_white_1"}, {["x"] = 4, ["meta"] = {["fields"] = {}, ["inventory"] = {}}, ["param2"] = 21, ["y"] = 18, ["param1"] = 10, ["z"] = 5, ["name"] = "rainbow:slab_render_white_1"}, {["x"] = 4, ["meta"] = {["fields"] = {}, ["inventory"] = {}}, ["param2"] = 21, ["y"] = 18, ["param1"] = 10, ["z"] = 6, ["name"] = "rainbow:slab_render_white_1"}, {["x"] = 4, ["meta"] = {["fields"] = {}, ["inventory"] = {}}, ["param2"] = 21, ["y"] = 18, ["param1"] = 10, ["z"] = 7, ["name"] = "rainbow:slab_render_white_1"}, {["x"] = 4, ["meta"] = {["fields"] = {}, ["inventory"] = {}}, ["param2"] = 21, ["y"] = 18, ["param1"] = 9, ["z"] = 8, ["name"] = "rainbow:slab_render_white_1"}, {["x"] = 4, ["meta"] = {["fields"] = {}, ["inventory"] = {}}, ["param2"] = 21, ["y"] = 18, ["param1"] = 10, ["z"] = 9, ["name"] = "rainbow:slab_render_white_1"}, {["x"] = 4, ["meta"] = {["fields"] = {}, ["inventory"] = {}}, ["param2"] = 20, ["y"] = 18, ["param1"] = 11, ["z"] = 10, ["name"] = "rainbow:slab_render_white_1"}, {["x"] = 4, ["meta"] = {["fields"] = {}, ["inventory"] = {}}, ["y"] = 18, ["param1"] = 63, ["z"] = 11, ["name"] = "rainbow:render_white"}, {["x"] = 4, ["meta"] = {["fields"] = {}, ["inventory"] = {}}, ["y"] = 19, ["param1"] = 47, ["z"] = 1, ["name"] = "rainbow:render_white"}, {["x"] = 4, ["meta"] = {["fields"] = {}, ["inventory"] = {}}, ["y"] = 19, ["param1"] = 47, ["z"] = 11, ["name"] = "rainbow:render_white"}, {["x"] = 4, ["meta"] = {["fields"] = {}, ["inventory"] = {}}, ["y"] = 20, ["param1"] = 175, ["z"] = 2, ["name"] = "rainbow:render_white"}, {["x"] = 4, ["meta"] = {["fields"] = {}, ["inventory"] = {}}, ["y"] = 20, ["param1"] = 159, ["z"] = 9, ["name"] = "rainbow:render_white"}, {["x"] = 4, ["meta"] = {["fields"] = {}, ["inventory"] = {}}, ["y"] = 20, ["param1"] = 143, ["z"] = 10, ["name"] = "rainbow:render_white"}, {["x"] = 4, ["meta"] = {["fields"] = {}, ["inventory"] = {}}, ["y"] = 21, ["param1"] = 159, ["z"] = 2, ["name"] = "rainbow:render_white"}, {["x"] = 4, ["meta"] = {["fields"] = {}, ["inventory"] = {}}, ["y"] = 21, ["param1"] = 143, ["z"] = 9, ["name"] = "rainbow:render_white"}, {["x"] = 4, ["meta"] = {["fields"] = {}, ["inventory"] = {}}, ["y"] = 21, ["param1"] = 127, ["z"] = 10, ["name"] = "rainbow:render_white"}, {["x"] = 4, ["meta"] = {["fields"] = {}, ["inventory"] = {}}, ["y"] = 22, ["param1"] = 143, ["z"] = 2, ["name"] = "rainbow:render_white"}, {["x"] = 4, ["meta"] = {["fields"] = {}, ["inventory"] = {}}, ["y"] = 22, ["param1"] = 127, ["z"] = 9, ["name"] = "rainbow:render_white"}, {["x"] = 4, ["meta"] = {["fields"] = {}, ["inventory"] = {}}, ["y"] = 22, ["param1"] = 111, ["z"] = 10, ["name"] = "rainbow:render_white"}, {["x"] = 4, ["meta"] = {["fields"] = {}, ["inventory"] = {}}, ["y"] = 23, ["param1"] = 127, ["z"] = 2, ["name"] = "rainbow:render_white"}, {["x"] = 4, ["meta"] = {["fields"] = {}, ["inventory"] = {}}, ["y"] = 23, ["param1"] = 111, ["z"] = 9, ["name"] = "rainbow:render_white"}, {["x"] = 4, ["meta"] = {["fields"] = {}, ["inventory"] = {}}, ["y"] = 23, ["param1"] = 95, ["z"] = 10, ["name"] = "rainbow:render_white"}, {["x"] = 4, ["meta"] = {["fields"] = {}, ["inventory"] = {}}, ["y"] = 24, ["param1"] = 111, ["z"] = 2, ["name"] = "rainbow:render_white"}, {["x"] = 4, ["meta"] = {["fields"] = {}, ["inventory"] = {}}, ["y"] = 24, ["param1"] = 95, ["z"] = 9, ["name"] = "rainbow:render_white"}, {["x"] = 4, ["meta"] = {["fields"] = {}, ["inventory"] = {}}, ["y"] = 24, ["param1"] = 79, ["z"] = 10, ["name"] = "rainbow:render_white"}, {["x"] = 4, ["meta"] = {["fields"] = {}, ["inventory"] = {}}, ["y"] = 25, ["param1"] = 95, ["z"] = 2, ["name"] = "rainbow:render_white"}, {["x"] = 4, ["meta"] = {["fields"] = {}, ["inventory"] = {}}, ["y"] = 25, ["param1"] = 79, ["z"] = 9, ["name"] = "rainbow:render_white"}, {["x"] = 4, ["meta"] = {["fields"] = {}, ["inventory"] = {}}, ["y"] = 25, ["param1"] = 63, ["z"] = 10, ["name"] = "rainbow:render_white"}, {["x"] = 4, ["meta"] = {["fields"] = {}, ["inventory"] = {}}, ["y"] = 26, ["param1"] = 79, ["z"] = 2, ["name"] = "rainbow:render_white"}, {["x"] = 4, ["meta"] = {["fields"] = {}, ["inventory"] = {}}, ["y"] = 26, ["param1"] = 63, ["z"] = 9, ["name"] = "rainbow:render_white"}, {["x"] = 4, ["meta"] = {["fields"] = {}, ["inventory"] = {}}, ["y"] = 26, ["param1"] = 47, ["z"] = 10, ["name"] = "rainbow:render_white"}, {["x"] = 4, ["meta"] = {["fields"] = {}, ["inventory"] = {}}, ["y"] = 27, ["param1"] = 63, ["z"] = 2, ["name"] = "rainbow:render_white"}, {["x"] = 4, ["meta"] = {["fields"] = {}, ["inventory"] = {}}, ["y"] = 27, ["param1"] = 47, ["z"] = 9, ["name"] = "rainbow:render_white"}, {["x"] = 4, ["meta"] = {["fields"] = {}, ["inventory"] = {}}, ["y"] = 27, ["param1"] = 31, ["z"] = 10, ["name"] = "rainbow:render_white"}, {["x"] = 4, ["meta"] = {["fields"] = {}, ["inventory"] = {}}, ["y"] = 28, ["param1"] = 47, ["z"] = 2, ["name"] = "rainbow:render_white"}, {["x"] = 4, ["meta"] = {["fields"] = {}, ["inventory"] = {}}, ["y"] = 28, ["param1"] = 31, ["z"] = 9, ["name"] = "rainbow:render_white"}, {["x"] = 4, ["meta"] = {["fields"] = {}, ["inventory"] = {}}, ["y"] = 28, ["param1"] = 15, ["z"] = 10, ["name"] = "rainbow:render_white"}, {["x"] = 4, ["meta"] = {["fields"] = {}, ["inventory"] = {}}, ["y"] = 29, ["param1"] = 31, ["z"] = 2, ["name"] = "rainbow:render_white"}, {["x"] = 4, ["meta"] = {["fields"] = {}, ["inventory"] = {}}, ["y"] = 29, ["param1"] = 15, ["z"] = 9, ["name"] = "rainbow:render_white"}, {["x"] = 4, ["meta"] = {["fields"] = {}, ["inventory"] = {}}, ["y"] = 29, ["param1"] = 15, ["z"] = 10, ["name"] = "rainbow:render_white"}, {["x"] = 4, ["meta"] = {["fields"] = {}, ["inventory"] = {}}, ["y"] = 30, ["param1"] = 15, ["z"] = 2, ["name"] = "rainbow:render_white"}, {["x"] = 4, ["meta"] = {["fields"] = {}, ["inventory"] = {}}, ["y"] = 30, ["param1"] = 15, ["z"] = 9, ["name"] = "rainbow:render_white"}, {["x"] = 4, ["meta"] = {["fields"] = {}, ["inventory"] = {}}, ["y"] = 30, ["param1"] = 15, ["z"] = 10, ["name"] = "rainbow:render_white"}, {["x"] = 4, ["meta"] = {["fields"] = {}, ["inventory"] = {}}, ["y"] = 31, ["param1"] = 15, ["z"] = 2, ["name"] = "rainbow:render_white"}, {["x"] = 4, ["meta"] = {["fields"] = {}, ["inventory"] = {}}, ["y"] = 31, ["param1"] = 15, ["z"] = 3, ["name"] = "rainbow:render_white"}, {["x"] = 4, ["meta"] = {["fields"] = {}, ["inventory"] = {}}, ["y"] = 31, ["param1"] = 15, ["z"] = 9, ["name"] = "rainbow:render_white"}, {["x"] = 4, ["meta"] = {["fields"] = {}, ["inventory"] = {}}, ["y"] = 31, ["param1"] = 15, ["z"] = 10, ["name"] = "rainbow:render_white"}, {["x"] = 4, ["meta"] = {["fields"] = {}, ["inventory"] = {}}, ["y"] = 32, ["param1"] = 15, ["z"] = 2, ["name"] = "rainbow:render_white"}, {["x"] = 4, ["meta"] = {["fields"] = {}, ["inventory"] = {}}, ["y"] = 32, ["param1"] = 15, ["z"] = 3, ["name"] = "rainbow:render_white"}, {["x"] = 4, ["meta"] = {["fields"] = {}, ["inventory"] = {}}, ["y"] = 32, ["param1"] = 15, ["z"] = 9, ["name"] = "rainbow:render_white"}, {["x"] = 4, ["meta"] = {["fields"] = {}, ["inventory"] = {}}, ["y"] = 32, ["param1"] = 15, ["z"] = 10, ["name"] = "rainbow:render_white"}, {["x"] = 4, ["meta"] = {["fields"] = {}, ["inventory"] = {}}, ["y"] = 33, ["param1"] = 15, ["z"] = 2, ["name"] = "rainbow:render_white"}, {["x"] = 4, ["meta"] = {["fields"] = {}, ["inventory"] = {}}, ["y"] = 33, ["param1"] = 15, ["z"] = 3, ["name"] = "rainbow:render_white"}, {["x"] = 4, ["meta"] = {["fields"] = {}, ["inventory"] = {}}, ["y"] = 33, ["param1"] = 15, ["z"] = 9, ["name"] = "rainbow:render_white"}, {["x"] = 4, ["meta"] = {["fields"] = {}, ["inventory"] = {}}, ["y"] = 33, ["param1"] = 15, ["z"] = 10, ["name"] = "rainbow:render_white"}, {["x"] = 4, ["meta"] = {["fields"] = {}, ["inventory"] = {}}, ["y"] = 34, ["param1"] = 15, ["z"] = 2, ["name"] = "rainbow:render_white"}, {["x"] = 4, ["meta"] = {["fields"] = {}, ["inventory"] = {}}, ["y"] = 34, ["param1"] = 15, ["z"] = 3, ["name"] = "rainbow:render_white"}, {["x"] = 4, ["meta"] = {["fields"] = {}, ["inventory"] = {}}, ["y"] = 34, ["param1"] = 15, ["z"] = 9, ["name"] = "rainbow:render_white"}, {["x"] = 4, ["meta"] = {["fields"] = {}, ["inventory"] = {}}, ["y"] = 34, ["param1"] = 15, ["z"] = 10, ["name"] = "rainbow:render_white"}, {["x"] = 4, ["meta"] = {["fields"] = {}, ["inventory"] = {}}, ["y"] = 35, ["param1"] = 15, ["z"] = 2, ["name"] = "rainbow:render_white"}, {["x"] = 4, ["meta"] = {["fields"] = {}, ["inventory"] = {}}, ["y"] = 35, ["param1"] = 15, ["z"] = 3, ["name"] = "rainbow:render_white"}, {["x"] = 4, ["meta"] = {["fields"] = {}, ["inventory"] = {}}, ["y"] = 35, ["param1"] = 15, ["z"] = 9, ["name"] = "rainbow:render_white"}, {["x"] = 4, ["meta"] = {["fields"] = {}, ["inventory"] = {}}, ["y"] = 35, ["param1"] = 15, ["z"] = 10, ["name"] = "rainbow:render_white"}, {["x"] = 4, ["meta"] = {["fields"] = {}, ["inventory"] = {}}, ["y"] = 36, ["param1"] = 15, ["z"] = 2, ["name"] = "rainbow:render_white"}, {["x"] = 4, ["meta"] = {["fields"] = {}, ["inventory"] = {}}, ["y"] = 36, ["param1"] = 15, ["z"] = 3, ["name"] = "rainbow:render_white"}, {["x"] = 4, ["meta"] = {["fields"] = {}, ["inventory"] = {}}, ["y"] = 36, ["param1"] = 15, ["z"] = 9, ["name"] = "rainbow:render_white"}, {["x"] = 4, ["meta"] = {["fields"] = {}, ["inventory"] = {}}, ["y"] = 36, ["param1"] = 15, ["z"] = 10, ["name"] = "rainbow:render_white"}, {["x"] = 4, ["meta"] = {["fields"] = {}, ["inventory"] = {}}, ["y"] = 37, ["param1"] = 15, ["z"] = 2, ["name"] = "rainbow:render_white"}, {["x"] = 4, ["meta"] = {["fields"] = {}, ["inventory"] = {}}, ["y"] = 37, ["param1"] = 15, ["z"] = 3, ["name"] = "rainbow:render_white"}, {["x"] = 4, ["meta"] = {["fields"] = {}, ["inventory"] = {}}, ["y"] = 37, ["param1"] = 15, ["z"] = 9, ["name"] = "rainbow:render_white"}, {["x"] = 4, ["meta"] = {["fields"] = {}, ["inventory"] = {}}, ["y"] = 37, ["param1"] = 15, ["z"] = 10, ["name"] = "rainbow:render_white"}, {["x"] = 4, ["meta"] = {["fields"] = {}, ["inventory"] = {}}, ["y"] = 38, ["param1"] = 15, ["z"] = 2, ["name"] = "rainbow:render_white"}, {["x"] = 4, ["meta"] = {["fields"] = {}, ["inventory"] = {}}, ["y"] = 38, ["param1"] = 15, ["z"] = 3, ["name"] = "rainbow:render_white"}, {["x"] = 4, ["meta"] = {["fields"] = {}, ["inventory"] = {}}, ["y"] = 38, ["z"] = 6, ["name"] = "default:meselamp"}, {["x"] = 4, ["meta"] = {["fields"] = {}, ["inventory"] = {}}, ["y"] = 38, ["param1"] = 15, ["z"] = 9, ["name"] = "rainbow:render_white"}, {["x"] = 4, ["meta"] = {["fields"] = {}, ["inventory"] = {}}, ["y"] = 38, ["param1"] = 15, ["z"] = 10, ["name"] = "rainbow:render_white"}, {["x"] = 4, ["meta"] = {["fields"] = {}, ["inventory"] = {}}, ["param2"] = 1, ["y"] = 39, ["param1"] = 15, ["z"] = 2, ["name"] = "moreblocks:slope_steelblock_outer"}, {["x"] = 4, ["meta"] = {["fields"] = {}, ["inventory"] = {}}, ["y"] = 39, ["z"] = 3, ["name"] = "rainbow:render_white"}, {["x"] = 4, ["meta"] = {["fields"] = {}, ["inventory"] = {}}, ["y"] = 39, ["param1"] = 191, ["z"] = 4, ["name"] = "rainbow:render_white"}, {["x"] = 4, ["meta"] = {["fields"] = {}, ["inventory"] = {}}, ["y"] = 39, ["param1"] = 191, ["z"] = 8, ["name"] = "rainbow:render_white"}, {["x"] = 4, ["meta"] = {["fields"] = {}, ["inventory"] = {}}, ["y"] = 39, ["z"] = 9, ["name"] = "rainbow:render_white"}, {["x"] = 4, ["meta"] = {["fields"] = {}, ["inventory"] = {}}, ["param2"] = 2, ["y"] = 39, ["param1"] = 15, ["z"] = 10, ["name"] = "moreblocks:slope_steelblock_outer"}, {["x"] = 4, ["meta"] = {["fields"] = {}, ["inventory"] = {}}, ["param2"] = 1, ["y"] = 40, ["param1"] = 15, ["z"] = 3, ["name"] = "moreblocks:slope_steelblock_outer"}, {["x"] = 4, ["meta"] = {["fields"] = {}, ["inventory"] = {}}, ["y"] = 40, ["param1"] = 175, ["z"] = 4, ["name"] = "rainbow:render_white"}, {["x"] = 4, ["meta"] = {["fields"] = {}, ["inventory"] = {}}, ["y"] = 40, ["param1"] = 175, ["z"] = 8, ["name"] = "rainbow:render_white"}, {["x"] = 4, ["meta"] = {["fields"] = {}, ["inventory"] = {}}, ["param2"] = 2, ["y"] = 40, ["param1"] = 15, ["z"] = 9, ["name"] = "moreblocks:slope_steelblock_outer"}, {["x"] = 4, ["meta"] = {["fields"] = {}, ["inventory"] = {}}, ["y"] = 41, ["param1"] = 159, ["z"] = 4, ["name"] = "rainbow:render_white"}, {["x"] = 4, ["meta"] = {["fields"] = {}, ["inventory"] = {}}, ["y"] = 41, ["param1"] = 159, ["z"] = 8, ["name"] = "rainbow:render_white"}, {["x"] = 4, ["meta"] = {["fields"] = {}, ["inventory"] = {}}, ["y"] = 42, ["param1"] = 143, ["z"] = 4, ["name"] = "rainbow:render_white"}, {["x"] = 4, ["meta"] = {["fields"] = {}, ["inventory"] = {}}, ["y"] = 42, ["param1"] = 143, ["z"] = 8, ["name"] = "rainbow:render_white"}, {["x"] = 4, ["meta"] = {["fields"] = {}, ["inventory"] = {}}, ["y"] = 43, ["param1"] = 127, ["z"] = 4, ["name"] = "rainbow:render_white"}, {["x"] = 4, ["meta"] = {["fields"] = {}, ["inventory"] = {}}, ["y"] = 43, ["param1"] = 127, ["z"] = 8, ["name"] = "rainbow:render_white"}, {["x"] = 4, ["meta"] = {["fields"] = {}, ["inventory"] = {}}, ["y"] = 44, ["param1"] = 111, ["z"] = 4, ["name"] = "rainbow:render_white"}, {["x"] = 4, ["meta"] = {["fields"] = {}, ["inventory"] = {}}, ["y"] = 44, ["param1"] = 111, ["z"] = 8, ["name"] = "rainbow:render_white"}, {["x"] = 4, ["meta"] = {["fields"] = {}, ["inventory"] = {}}, ["y"] = 45, ["param1"] = 95, ["z"] = 4, ["name"] = "rainbow:render_white"}, {["x"] = 4, ["meta"] = {["fields"] = {}, ["inventory"] = {}}, ["y"] = 45, ["param1"] = 95, ["z"] = 8, ["name"] = "rainbow:render_white"}, {["x"] = 4, ["meta"] = {["fields"] = {}, ["inventory"] = {}}, ["y"] = 46, ["param1"] = 79, ["z"] = 4, ["name"] = "rainbow:render_white"}, {["x"] = 4, ["meta"] = {["fields"] = {}, ["inventory"] = {}}, ["y"] = 46, ["param1"] = 79, ["z"] = 8, ["name"] = "rainbow:render_white"}, {["x"] = 4, ["meta"] = {["fields"] = {}, ["inventory"] = {}}, ["y"] = 47, ["param1"] = 63, ["z"] = 4, ["name"] = "rainbow:render_white"}, {["x"] = 4, ["meta"] = {["fields"] = {}, ["inventory"] = {}}, ["y"] = 47, ["param1"] = 63, ["z"] = 8, ["name"] = "rainbow:render_white"}, {["x"] = 4, ["meta"] = {["fields"] = {}, ["inventory"] = {}}, ["y"] = 48, ["param1"] = 47, ["z"] = 4, ["name"] = "rainbow:render_white"}, {["x"] = 4, ["meta"] = {["fields"] = {}, ["inventory"] = {}}, ["y"] = 48, ["param1"] = 47, ["z"] = 8, ["name"] = "rainbow:render_white"}, {["x"] = 4, ["meta"] = {["fields"] = {}, ["inventory"] = {}}, ["y"] = 49, ["param1"] = 31, ["z"] = 4, ["name"] = "rainbow:render_white"}, {["x"] = 4, ["meta"] = {["fields"] = {}, ["inventory"] = {}}, ["y"] = 49, ["param1"] = 31, ["z"] = 8, ["name"] = "rainbow:render_white"}, {["x"] = 4, ["meta"] = {["fields"] = {}, ["inventory"] = {}}, ["y"] = 50, ["param1"] = 15, ["z"] = 4, ["name"] = "rainbow:render_white"}, {["x"] = 4, ["meta"] = {["fields"] = {}, ["inventory"] = {}}, ["y"] = 50, ["param1"] = 15, ["z"] = 8, ["name"] = "rainbow:render_white"}, {["x"] = 4, ["meta"] = {["fields"] = {}, ["inventory"] = {}}, ["y"] = 51, ["param1"] = 15, ["z"] = 4, ["name"] = "rainbow:render_white"}, {["x"] = 4, ["meta"] = {["fields"] = {}, ["inventory"] = {}}, ["y"] = 51, ["param1"] = 15, ["z"] = 8, ["name"] = "rainbow:render_white"}, {["x"] = 4, ["meta"] = {["fields"] = {}, ["inventory"] = {}}, ["y"] = 52, ["param1"] = 15, ["z"] = 4, ["name"] = "rainbow:render_white"}, {["x"] = 4, ["meta"] = {["fields"] = {}, ["inventory"] = {}}, ["y"] = 52, ["param1"] = 15, ["z"] = 8, ["name"] = "rainbow:render_white"}, {["x"] = 4, ["meta"] = {["fields"] = {}, ["inventory"] = {}}, ["y"] = 53, ["param1"] = 15, ["z"] = 4, ["name"] = "rainbow:render_white"}, {["x"] = 4, ["meta"] = {["fields"] = {}, ["inventory"] = {}}, ["y"] = 53, ["param1"] = 15, ["z"] = 8, ["name"] = "rainbow:render_white"}, {["x"] = 4, ["meta"] = {["fields"] = {}, ["inventory"] = {}}, ["y"] = 54, ["param1"] = 15, ["z"] = 4, ["name"] = "rainbow:render_white"}, {["x"] = 4, ["meta"] = {["fields"] = {}, ["inventory"] = {}}, ["y"] = 54, ["param1"] = 15, ["z"] = 8, ["name"] = "rainbow:render_white"}, {["x"] = 4, ["meta"] = {["fields"] = {}, ["inventory"] = {}}, ["y"] = 55, ["param1"] = 15, ["z"] = 4, ["name"] = "rainbow:render_white"}, {["x"] = 4, ["meta"] = {["fields"] = {}, ["inventory"] = {}}, ["y"] = 55, ["param1"] = 15, ["z"] = 8, ["name"] = "rainbow:render_white"}, {["x"] = 4, ["meta"] = {["fields"] = {}, ["inventory"] = {}}, ["y"] = 56, ["param1"] = 15, ["z"] = 4, ["name"] = "rainbow:render_white"}, {["x"] = 4, ["meta"] = {["fields"] = {}, ["inventory"] = {}}, ["y"] = 56, ["param1"] = 15, ["z"] = 8, ["name"] = "rainbow:render_white"}, {["x"] = 4, ["meta"] = {["fields"] = {}, ["inventory"] = {}}, ["y"] = 57, ["param1"] = 15, ["z"] = 4, ["name"] = "rainbow:render_white"}, {["x"] = 4, ["meta"] = {["fields"] = {}, ["inventory"] = {}}, ["y"] = 57, ["param1"] = 15, ["z"] = 8, ["name"] = "rainbow:render_white"}, {["x"] = 4, ["meta"] = {["fields"] = {}, ["inventory"] = {}}, ["y"] = 58, ["param1"] = 15, ["z"] = 4, ["name"] = "rainbow:render_white"}, {["x"] = 4, ["meta"] = {["fields"] = {}, ["inventory"] = {}}, ["y"] = 58, ["param1"] = 15, ["z"] = 8, ["name"] = "rainbow:render_white"}, {["x"] = 4, ["meta"] = {["fields"] = {}, ["inventory"] = {}}, ["param2"] = 1, ["y"] = 59, ["param1"] = 15, ["z"] = 4, ["name"] = "moreblocks:slope_steelblock_outer"}, {["x"] = 4, ["meta"] = {["fields"] = {}, ["inventory"] = {}}, ["y"] = 59, ["param1"] = 191, ["z"] = 5, ["name"] = "rainbow:render_white"}, {["x"] = 4, ["meta"] = {["fields"] = {}, ["inventory"] = {}}, ["y"] = 59, ["param1"] = 207, ["z"] = 6, ["name"] = "rainbow:render_white"}, {["x"] = 4, ["meta"] = {["fields"] = {}, ["inventory"] = {}}, ["y"] = 59, ["param1"] = 191, ["z"] = 7, ["name"] = "rainbow:render_white"}, {["x"] = 4, ["meta"] = {["fields"] = {}, ["inventory"] = {}}, ["param2"] = 2, ["y"] = 59, ["param1"] = 15, ["z"] = 8, ["name"] = "moreblocks:slope_steelblock_outer"}, {["x"] = 4, ["meta"] = {["fields"] = {}, ["inventory"] = {}}, ["y"] = 60, ["param1"] = 175, ["z"] = 5, ["name"] = "rainbow:render_white"}, {["x"] = 4, ["meta"] = {["fields"] = {}, ["inventory"] = {}}, ["y"] = 60, ["param1"] = 191, ["z"] = 6, ["name"] = "rainbow:render_white"}, {["x"] = 4, ["meta"] = {["fields"] = {}, ["inventory"] = {}}, ["y"] = 60, ["param1"] = 175, ["z"] = 7, ["name"] = "rainbow:render_white"}, {["x"] = 4, ["meta"] = {["fields"] = {}, ["inventory"] = {}}, ["y"] = 61, ["param1"] = 159, ["z"] = 5, ["name"] = "rainbow:render_white"}, {["x"] = 4, ["meta"] = {["fields"] = {}, ["inventory"] = {}}, ["y"] = 61, ["param1"] = 175, ["z"] = 6, ["name"] = "rainbow:render_white"}, {["x"] = 4, ["meta"] = {["fields"] = {}, ["inventory"] = {}}, ["y"] = 61, ["param1"] = 159, ["z"] = 7, ["name"] = "rainbow:render_white"}, {["x"] = 4, ["meta"] = {["fields"] = {}, ["inventory"] = {}}, ["y"] = 62, ["param1"] = 143, ["z"] = 5, ["name"] = "rainbow:render_white"}, {["x"] = 4, ["meta"] = {["fields"] = {}, ["inventory"] = {}}, ["y"] = 62, ["param1"] = 159, ["z"] = 6, ["name"] = "rainbow:render_white"}, {["x"] = 4, ["meta"] = {["fields"] = {}, ["inventory"] = {}}, ["y"] = 62, ["param1"] = 143, ["z"] = 7, ["name"] = "rainbow:render_white"}, {["x"] = 4, ["meta"] = {["fields"] = {}, ["inventory"] = {}}, ["y"] = 63, ["param1"] = 127, ["z"] = 5, ["name"] = "rainbow:render_white"}, {["x"] = 4, ["meta"] = {["fields"] = {}, ["inventory"] = {}}, ["y"] = 63, ["param1"] = 143, ["z"] = 6, ["name"] = "rainbow:render_white"}, {["x"] = 4, ["meta"] = {["fields"] = {}, ["inventory"] = {}}, ["y"] = 63, ["param1"] = 127, ["z"] = 7, ["name"] = "rainbow:render_white"}, {["x"] = 4, ["meta"] = {["fields"] = {}, ["inventory"] = {}}, ["y"] = 64, ["param1"] = 111, ["z"] = 5, ["name"] = "rainbow:render_white"}, {["x"] = 4, ["meta"] = {["fields"] = {}, ["inventory"] = {}}, ["y"] = 64, ["param1"] = 127, ["z"] = 6, ["name"] = "rainbow:render_white"}, {["x"] = 4, ["meta"] = {["fields"] = {}, ["inventory"] = {}}, ["y"] = 64, ["param1"] = 111, ["z"] = 7, ["name"] = "rainbow:render_white"}, {["x"] = 4, ["meta"] = {["fields"] = {}, ["inventory"] = {}}, ["y"] = 65, ["param1"] = 95, ["z"] = 5, ["name"] = "rainbow:render_white"}, {["x"] = 4, ["meta"] = {["fields"] = {}, ["inventory"] = {}}, ["y"] = 65, ["param1"] = 111, ["z"] = 6, ["name"] = "rainbow:render_white"}, {["x"] = 4, ["meta"] = {["fields"] = {}, ["inventory"] = {}}, ["y"] = 65, ["param1"] = 95, ["z"] = 7, ["name"] = "rainbow:render_white"}, {["x"] = 4, ["meta"] = {["fields"] = {}, ["inventory"] = {}}, ["y"] = 66, ["param1"] = 79, ["z"] = 5, ["name"] = "rainbow:render_white"}, {["x"] = 4, ["meta"] = {["fields"] = {}, ["inventory"] = {}}, ["y"] = 66, ["param1"] = 95, ["z"] = 6, ["name"] = "rainbow:render_white"}, {["x"] = 4, ["meta"] = {["fields"] = {}, ["inventory"] = {}}, ["y"] = 66, ["param1"] = 79, ["z"] = 7, ["name"] = "rainbow:render_white"}, {["x"] = 4, ["meta"] = {["fields"] = {}, ["inventory"] = {}}, ["y"] = 67, ["param1"] = 63, ["z"] = 5, ["name"] = "rainbow:render_white"}, {["x"] = 4, ["meta"] = {["fields"] = {}, ["inventory"] = {}}, ["y"] = 67, ["param1"] = 79, ["z"] = 6, ["name"] = "rainbow:render_white"}, {["x"] = 4, ["meta"] = {["fields"] = {}, ["inventory"] = {}}, ["y"] = 67, ["param1"] = 63, ["z"] = 7, ["name"] = "rainbow:render_white"}, {["x"] = 4, ["meta"] = {["fields"] = {}, ["inventory"] = {}}, ["y"] = 68, ["param1"] = 47, ["z"] = 5, ["name"] = "rainbow:render_white"}, {["x"] = 4, ["meta"] = {["fields"] = {}, ["inventory"] = {}},