5:return {{["x"] = 0, ["meta"] = {["fields"] = {}, ["inventory"] = {}}, ["y"] = 0, ["z"] = 20, ["name"] = "default:cobble"}, {["x"] = 0, ["meta"] = {["fields"] = {}, ["inventory"] = {}}, ["param2"] = 4, ["y"] = 22, ["param1"] = 15, ["z"] = 8, ["name"] = "default:torch"}, {["x"] = 0, ["meta"] = {["fields"] = {}, ["inventory"] = {}}, ["y"] = 22, ["z"] = 9, ["name"] = "wool:green"}, {["x"] = 0, ["meta"] = {["fields"] = {}, ["inventory"] = {}}, ["y"] = 22, ["z"] = 10, ["name"] = "wool:green"}, {["x"] = 0, ["meta"] = {["fields"] = {}, ["inventory"] = {}}, ["y"] = 22, ["z"] = 11, ["name"] = "wool:green"}, {["x"] = 0, ["meta"] = {["fields"] = {}, ["inventory"] = {}}, ["y"] = 22, ["z"] = 12, ["name"] = "wool:green"}, {["x"] = 0, ["meta"] = {["fields"] = {}, ["inventory"] = {}}, ["param2"] = 5, ["y"] = 22, ["param1"] = 15, ["z"] = 13, ["name"] = "default:torch"}, {["x"] = 0, ["meta"] = {["fields"] = {}, ["inventory"] = {}}, ["param2"] = 4, ["y"] = 34, ["param1"] = 15, ["z"] = 9, ["name"] = "default:torch"}, {["x"] = 0, ["meta"] = {["fields"] = {}, ["inventory"] = {}}, ["y"] = 34, ["z"] = 10, ["name"] = "wool:white"}, {["x"] = 0, ["meta"] = {["fields"] = {}, ["inventory"] = {}}, ["y"] = 34, ["z"] = 11, ["name"] = "wool:white"}, {["x"] = 0, ["meta"] = {["fields"] = {}, ["inventory"] = {}}, ["param2"] = 5, ["y"] = 34, ["param1"] = 15, ["z"] = 12, ["name"] = "default:torch"}, {["x"] = 1, ["meta"] = {["fields"] = {}, ["inventory"] = {}}, ["y"] = 0, ["param1"] = 107, ["z"] = 11, ["name"] = "flowers:rose"}, {["x"] = 1, ["meta"] = {["fields"] = {}, ["inventory"] = {}}, ["y"] = 0, ["z"] = 19, ["name"] = "default:cobble"}, {["x"] = 1, ["meta"] = {["fields"] = {}, ["inventory"] = {}}, ["y"] = 22, ["z"] = 8, ["name"] = "wool:green"}, {["x"] = 1, ["meta"] = {["fields"] = {}, ["inventory"] = {}}, ["y"] = 22, ["z"] = 9, ["name"] = "wool:green"}, {["x"] = 1, ["meta"] = {["fields"] = {}, ["inventory"] = {}}, ["y"] = 22, ["z"] = 10, ["name"] = "wool:green"}, {["x"] = 1, ["meta"] = {["fields"] = {}, ["inventory"] = {}}, ["y"] = 22, ["z"] = 11, ["name"] = "wool:green"}, {["x"] = 1, ["meta"] = {["fields"] = {}, ["inventory"] = {}}, ["y"] = 22, ["z"] = 12, ["name"] = "wool:green"}, {["x"] = 1, ["meta"] = {["fields"] = {}, ["inventory"] = {}}, ["y"] = 22, ["z"] = 13, ["name"] = "wool:green"}, {["x"] = 1, ["meta"] = {["fields"] = {}, ["inventory"] = {}}, ["param2"] = 4, ["y"] = 34, ["param1"] = 15, ["z"] = 8, ["name"] = "default:torch"}, {["x"] = 1, ["meta"] = {["fields"] = {}, ["inventory"] = {}}, ["y"] = 34, ["z"] = 9, ["name"] = "wool:white"}, {["x"] = 1, ["meta"] = {["fields"] = {}, ["inventory"] = {}}, ["y"] = 34, ["z"] = 10, ["name"] = "wool:white"}, {["x"] = 1, ["meta"] = {["fields"] = {}, ["inventory"] = {}}, ["y"] = 34, ["z"] = 11, ["name"] = "wool:white"}, {["x"] = 1, ["meta"] = {["fields"] = {}, ["inventory"] = {}}, ["y"] = 34, ["z"] = 12, ["name"] = "wool:white"}, {["x"] = 1, ["meta"] = {["fields"] = {}, ["inventory"] = {}}, ["param2"] = 5, ["y"] = 34, ["param1"] = 15, ["z"] = 13, ["name"] = "default:torch"}, {["x"] = 2, ["meta"] = {["fields"] = {}, ["inventory"] = {}}, ["y"] = 0, ["param1"] = 108, ["z"] = 12, ["name"] = "flowers:rose"}, {["x"] = 2, ["meta"] = {["fields"] = {}, ["inventory"] = {}}, ["y"] = 0, ["z"] = 18, ["name"] = "default:cobble"}, {["x"] = 2, ["meta"] = {["fields"] = {}, ["inventory"] = {}}, ["y"] = 22, ["z"] = 8, ["name"] = "wool:green"}, {["x"] = 2, ["meta"] = {["fields"] = {}, ["inventory"] = {}}, ["y"] = 22, ["z"] = 9, ["name"] = "wool:green"}, {["x"] = 2, ["meta"] = {["fields"] = {}, ["inventory"] = {}}, ["y"] = 22, ["z"] = 10, ["name"] = "wool:green"}, {["x"] = 2, ["meta"] = {["fields"] = {}, ["inventory"] = {}}, ["y"] = 22, ["z"] = 11, ["name"] = "wool:green"}, {["x"] = 2, ["meta"] = {["fields"] = {}, ["inventory"] = {}}, ["y"] = 22, ["z"] = 12, ["name"] = "wool:green"}, {["x"] = 2, ["meta"] = {["fields"] = {}, ["inventory"] = {}}, ["y"] = 22, ["z"] = 13, ["name"] = "wool:green"}, {["x"] = 2, ["meta"] = {["fields"] = {}, ["inventory"] = {}}, ["y"] = 34, ["z"] = 8, ["name"] = "wool:white"}, {["x"] = 2, ["meta"] = {["fields"] = {}, ["inventory"] = {}}, ["y"] = 34, ["z"] = 9, ["name"] = "wool:white"}, {["x"] = 2, ["meta"] = {["fields"] = {}, ["inventory"] = {}}, ["y"] = 34, ["z"] = 10, ["name"] = "wool:white"}, {["x"] = 2, ["meta"] = {["fields"] = {}, ["inventory"] = {}}, ["y"] = 34, ["z"] = 11, ["name"] = "wool:white"}, {["x"] = 2, ["meta"] = {["fields"] = {}, ["inventory"] = {}}, ["y"] = 34, ["z"] = 12, ["name"] = "wool:white"}, {["x"] = 2, ["meta"] = {["fields"] = {}, ["inventory"] = {}}, ["y"] = 34, ["z"] = 13, ["name"] = "wool:white"}, {["x"] = 3, ["meta"] = {["fields"] = {}, ["inventory"] = {}}, ["y"] = 0, ["param1"] = 63, ["z"] = 5, ["name"] = "flowers:rose"}, {["x"] = 3, ["meta"] = {["fields"] = {}, ["inventory"] = {}}, ["y"] = 0, ["z"] = 17, ["name"] = "default:cobble"}, {["x"] = 3, ["meta"] = {["fields"] = {}, ["inventory"] = {}}, ["y"] = 9, ["z"] = 8, ["name"] = "darkage:desert_stone_with_iron"}, {["x"] = 3, ["meta"] = {["fields"] = {}, ["inventory"] = {}}, ["y"] = 9, ["z"] = 9, ["name"] = "darkage:desert_stone_with_iron"}, {["x"] = 3, ["meta"] = {["fields"] = {}, ["inventory"] = {}}, ["y"] = 9, ["z"] = 10, ["name"] = "darkage:desert_stone_with_iron"}, {["x"] = 3, ["meta"] = {["fields"] = {}, ["inventory"] = {}}, ["y"] = 9, ["z"] = 11, ["name"] = "darkage:desert_stone_with_iron"}, {["x"] = 3, ["meta"] = {["fields"] = {}, ["inventory"] = {}}, ["y"] = 9, ["z"] = 12, ["name"] = "darkage:desert_stone_with_iron"}, {["x"] = 3, ["meta"] = {["fields"] = {}, ["inventory"] = {}}, ["y"] = 9, ["z"] = 13, ["name"] = "darkage:desert_stone_with_iron"}, {["x"] = 3, ["meta"] = {["fields"] = {}, ["inventory"] = {}}, ["y"] = 10, ["z"] = 8, ["name"] = "darkage:desert_stone_with_iron"}, {["x"] = 3, ["meta"] = {["fields"] = {}, ["inventory"] = {}}, ["y"] = 10, ["z"] = 9, ["name"] = "darkage:desert_stone_with_iron"}, {["x"] = 3, ["meta"] = {["fields"] = {}, ["inventory"] = {}}, ["y"] = 10, ["z"] = 10, ["name"] = "darkage:desert_stone_with_iron"}, {["x"] = 3, ["meta"] = {["fields"] = {}, ["inventory"] = {}}, ["y"] = 10, ["z"] = 11, ["name"] = "darkage:desert_stone_with_iron"}, {["x"] = 3, ["meta"] = {["fields"] = {}, ["inventory"] = {}}, ["y"] = 10, ["z"] = 12, ["name"] = "darkage:desert_stone_with_iron"}, {["x"] = 3, ["meta"] = {["fields"] = {}, ["inventory"] = {}}, ["y"] = 10, ["z"] = 13, ["name"] = "darkage:desert_stone_with_iron"}, {["x"] = 3, ["meta"] = {["fields"] = {}, ["inventory"] = {}}, ["param2"] = 1, ["y"] = 11, ["z"] = 8, ["name"] = "default:torch"}, {["x"] = 3, ["meta"] = {["fields"] = {}, ["inventory"] = {}}, ["param2"] = 1, ["y"] = 11, ["z"] = 13, ["name"] = "default:torch"}, {["x"] = 3, ["meta"] = {["fields"] = {}, ["inventory"] = {}}, ["y"] = 22, ["z"] = 8, ["name"] = "wool:green"}, {["x"] = 3, ["meta"] = {["fields"] = {}, ["inventory"] = {}}, ["y"] = 22, ["z"] = 9, ["name"] = "wool:green"}, {["x"] = 3, ["meta"] = {["fields"] = {}, ["inventory"] = {}}, ["y"] = 22, ["z"] = 10, ["name"] = "wool:green"}, {["x"] = 3, ["meta"] = {["fields"] = {}, ["inventory"] = {}}, ["y"] = 22, ["z"] = 11, ["name"] = "wool:green"}, {["x"] = 3, ["meta"] = {["fields"] = {}, ["inventory"] = {}}, ["y"] = 22, ["z"] = 12, ["name"] = "wool:green"}, {["x"] = 3, ["meta"] = {["fields"] = {}, ["inventory"] = {}}, ["y"] = 22, ["z"] = 13, ["name"] = "wool:green"}, {["x"] = 3, ["meta"] = {["fields"] = {}, ["inventory"] = {}}, ["y"] = 34, ["z"] = 8, ["name"] = "wool:white"}, {["x"] = 3, ["meta"] = {["fields"] = {}, ["inventory"] = {}}, ["y"] = 34, ["z"] = 9, ["name"] = "wool:white"}, {["x"] = 3, ["meta"] = {["fields"] = {}, ["inventory"] = {}}, ["y"] = 34, ["z"] = 10, ["name"] = "wool:white"}, {["x"] = 3, ["meta"] = {["fields"] = {}, ["inventory"] = {}}, ["y"] = 34, ["z"] = 11, ["name"] = "wool:white"}, {["x"] = 3, ["meta"] = {["fields"] = {}, ["inventory"] = {}}, ["y"] = 34, ["z"] = 12, ["name"] = "wool:white"}, {["x"] = 3, ["meta"] = {["fields"] = {}, ["inventory"] = {}}, ["y"] = 34, ["z"] = 13, ["name"] = "wool:white"}, {["x"] = 4, ["meta"] = {["fields"] = {}, ["inventory"] = {}}, ["y"] = 0, ["z"] = 9, ["name"] = "darkage:desert_stone_with_iron"}, {["x"] = 4, ["meta"] = {["fields"] = {}, ["inventory"] = {}}, ["y"] = 0, ["z"] = 10, ["name"] = "darkage:desert_stone_with_iron"}, {["x"] = 4, ["meta"] = {["fields"] = {}, ["inventory"] = {}}, ["y"] = 0, ["z"] = 11, ["name"] = "darkage:desert_stone_with_iron"}, {["x"] = 4, ["meta"] = {["fields"] = {}, ["inventory"] = {}}, ["y"] = 0, ["z"] = 12, ["name"] = "darkage:desert_stone_with_iron"}, {["x"] = 4, ["meta"] = {["fields"] = {}, ["inventory"] = {}}, ["y"] = 0, ["z"] = 16, ["name"] = "default:cobble"}, {["x"] = 4, ["meta"] = {["fields"] = {}, ["inventory"] = {}}, ["y"] = 1, ["z"] = 9, ["name"] = "darkage:desert_stone_with_iron"}, {["x"] = 4, ["meta"] = {["fields"] = {}, ["inventory"] = {}}, ["y"] = 1, ["param1"] = 170, ["z"] = 10, ["name"] = "building_blocks:woodglass"}, {["x"] = 4, ["meta"] = {["fields"] = {}, ["inventory"] = {}}, ["y"] = 1, ["param1"] = 170, ["z"] = 11, ["name"] = "building_blocks:woodglass"}, {["x"] = 4, ["meta"] = {["fields"] = {}, ["inventory"] = {}}, ["y"] = 1, ["z"] = 12, ["name"] = "darkage:desert_stone_with_iron"}, {["x"] = 4, ["meta"] = {["fields"] = {}, ["inventory"] = {}}, ["y"] = 2, ["z"] = 9, ["name"] = "darkage:desert_stone_with_iron"}, {["x"] = 4, ["meta"] = {["fields"] = {}, ["inventory"] = {}}, ["y"] = 2, ["z"] = 10, ["name"] = "darkage:desert_stone_with_iron"}, {["x"] = 4, ["meta"] = {["fields"] = {}, ["inventory"] = {}}, ["y"] = 2, ["z"] = 11, ["name"] = "darkage:desert_stone_with_iron"}, {["x"] = 4, ["meta"] = {["fields"] = {}, ["inventory"] = {}}, ["y"] = 2, ["z"] = 12, ["name"] = "darkage:desert_stone_with_iron"}, {["x"] = 4, ["meta"] = {["fields"] = {}, ["inventory"] = {}}, ["y"] = 3, ["z"] = 9, ["name"] = "darkage:desert_stone_with_iron"}, {["x"] = 4, ["meta"] = {["fields"] = {}, ["inventory"] = {}}, ["y"] = 3, ["z"] = 10, ["name"] = "darkage:desert_stone_with_iron"}, {["x"] = 4, ["meta"] = {["fields"] = {}, ["inventory"] = {}}, ["y"] = 3, ["z"] = 11, ["name"] = "darkage:desert_stone_with_iron"}, {["x"] = 4, ["meta"] = {["fields"] = {}, ["inventory"] = {}}, ["y"] = 3, ["z"] = 12, ["name"] = "darkage:desert_stone_with_iron"}, {["x"] = 4, ["meta"] = {["fields"] = {}, ["inventory"] = {}}, ["y"] = 4, ["z"] = 9, ["name"] = "darkage:desert_stone_with_iron"}, {["x"] = 4, ["meta"] = {["fields"] = {}, ["inventory"] = {}}, ["y"] = 4, ["z"] = 10, ["name"] = "darkage:desert_stone_with_iron"}, {["x"] = 4, ["meta"] = {["fields"] = {}, ["inventory"] = {}}, ["y"] = 4, ["z"] = 11, ["name"] = "darkage:desert_stone_with_iron"}, {["x"] = 4, ["meta"] = {["fields"] = {}, ["inventory"] = {}}, ["y"] = 4, ["z"] = 12, ["name"] = "darkage:desert_stone_with_iron"}, {["x"] = 4, ["meta"] = {["fields"] = {}, ["inventory"] = {}}, ["y"] = 5, ["z"] = 9, ["name"] = "darkage:desert_stone_with_iron"}, {["x"] = 4, ["meta"] = {["fields"] = {}, ["inventory"] = {}}, ["y"] = 5, ["param1"] = 170, ["z"] = 10, ["name"] = "building_blocks:woodglass"}, {["x"] = 4, ["meta"] = {["fields"] = {}, ["inventory"] = {}}, ["y"] = 5, ["param1"] = 170, ["z"] = 11, ["name"] = "building_blocks:woodglass"}, {["x"] = 4, ["meta"] = {["fields"] = {}, ["inventory"] = {}}, ["y"] = 5, ["z"] = 12, ["name"] = "darkage:desert_stone_with_iron"}, {["x"] = 4, ["meta"] = {["fields"] = {}, ["inventory"] = {}}, ["y"] = 6, ["z"] = 9, ["name"] = "darkage:desert_stone_with_iron"}, {["x"] = 4, ["meta"] = {["fields"] = {}, ["inventory"] = {}}, ["y"] = 6, ["z"] = 10, ["name"] = "darkage:desert_stone_with_iron"}, {["x"] = 4, ["meta"] = {["fields"] = {}, ["inventory"] = {}}, ["y"] = 6, ["z"] = 11, ["name"] = "darkage:desert_stone_with_iron"}, {["x"] = 4, ["meta"] = {["fields"] = {}, ["inventory"] = {}}, ["y"] = 6, ["z"] = 12, ["name"] = "darkage:desert_stone_with_iron"}, {["x"] = 4, ["meta"] = {["fields"] = {}, ["inventory"] = {}}, ["y"] = 7, ["z"] = 9, ["name"] = "darkage:desert_stone_with_iron"}, {["x"] = 4, ["meta"] = {["fields"] = {}, ["inventory"] = {}}, ["y"] = 7, ["z"] = 10, ["name"] = "darkage:desert_stone_with_iron"}, {["x"] = 4, ["meta"] = {["fields"] = {}, ["inventory"] = {}}, ["y"] = 7, ["z"] = 11, ["name"] = "darkage:desert_stone_with_iron"}, {["x"] = 4, ["meta"] = {["fields"] = {}, ["inventory"] = {}}, ["y"] = 7, ["z"] = 12, ["name"] = "darkage:desert_stone_with_iron"}, {["x"] = 4, ["meta"] = {["fields"] = {}, ["inventory"] = {}}, ["y"] = 8, ["z"] = 9, ["name"] = "darkage:desert_stone_with_iron"}, {["x"] = 4, ["meta"] = {["fields"] = {}, ["inventory"] = {}}, ["y"] = 8, ["z"] = 10, ["name"] = "darkage:desert_stone_with_iron"}, {["x"] = 4, ["meta"] = {["fields"] = {}, ["inventory"] = {}}, ["y"] = 8, ["z"] = 11, ["name"] = "darkage:desert_stone_with_iron"}, {["x"] = 4, ["meta"] = {["fields"] = {}, ["inventory"] = {}}, ["y"] = 8, ["z"] = 12, ["name"] = "darkage:desert_stone_with_iron"}, {["x"] = 4, ["meta"] = {["fields"] = {}, ["inventory"] = {}}, ["y"] = 9, ["z"] = 7, ["name"] = "darkage:desert_stone_with_iron"}, {["x"] = 4, ["meta"] = {["fields"] = {}, ["inventory"] = {}}, ["y"] = 9, ["z"] = 8, ["name"] = "darkage:desert_stone_with_iron"}, {["x"] = 4, ["meta"] = {["fields"] = {}, ["inventory"] = {}}, ["y"] = 9, ["z"] = 9, ["name"] = "darkage:desert_stone_with_iron"}, {["x"] = 4, ["meta"] = {["fields"] = {}, ["inventory"] = {}}, ["y"] = 9, ["z"] = 10, ["name"] = "darkage:desert_stone_with_iron"}, {["x"] = 4, ["meta"] = {["fields"] = {}, ["inventory"] = {}}, ["y"] = 9, ["z"] = 11, ["name"] = "darkage:desert_stone_with_iron"}, {["x"] = 4, ["meta"] = {["fields"] = {}, ["inventory"] = {}}, ["y"] = 9, ["z"] = 12, ["name"] = "darkage:desert_stone_with_iron"}, {["x"] = 4, ["meta"] = {["fields"] = {}, ["inventory"] = {}}, ["y"] = 9, ["z"] = 13, ["name"] = "darkage:desert_stone_with_iron"}, {["x"] = 4, ["meta"] = {["fields"] = {}, ["inventory"] = {}}, ["y"] = 9, ["z"] = 14, ["name"] = "darkage:desert_stone_with_iron"}, {["x"] = 4, ["meta"] = {["fields"] = {}, ["inventory"] = {}}, ["y"] = 10, ["z"] = 7, ["name"] = "darkage:desert_stone_with_iron"}, {["x"] = 4, ["meta"] = {["fields"] = {}, ["inventory"] = {}}, ["y"] = 10, ["z"] = 8, ["name"] = "darkage:desert_stone_with_iron"}, {["x"] = 4, ["meta"] = {["fields"] = {}, ["inventory"] = {}}, ["y"] = 10, ["z"] = 13, ["name"] = "darkage:desert_stone_with_iron"}, {["x"] = 4, ["meta"] = {["fields"] = {}, ["inventory"] = {}}, ["y"] = 10, ["z"] = 14, ["name"] = "darkage:desert_stone_with_iron"}, {["x"] = 4, ["meta"] = {["fields"] = {}, ["inventory"] = {}}, ["y"] = 22, ["z"] = 8, ["name"] = "wool:green"}, {["x"] = 4, ["meta"] = {["fields"] = {}, ["inventory"] = {}}, ["y"] = 22, ["z"] = 9, ["name"] = "wool:green"}, {["x"] = 4, ["meta"] = {["fields"] = {}, ["inventory"] = {}}, ["y"] = 22, ["z"] = 10, ["name"] = "wool:green"}, {["x"] = 4, ["meta"] = {["fields"] = {}, ["inventory"] = {}}, ["y"] = 22, ["z"] = 11, ["name"] = "wool:green"}, {["x"] = 4, ["meta"] = {["fields"] = {}, ["inventory"] = {}}, ["y"] = 22, ["z"] = 12, ["name"] = "wool:green"}, {["x"] = 4, ["meta"] = {["fields"] = {}, ["inventory"] = {}}, ["y"] = 22, ["z"] = 13, ["name"] = "wool:green"}, {["x"] = 4, ["meta"] = {["fields"] = {}, ["inventory"] = {}}, ["y"] = 34, ["z"] = 8, ["name"] = "wool:white"}, {["x"] = 4, ["meta"] = {["fields"] = {}, ["inventory"] = {}}, ["y"] = 34, ["z"] = 9, ["name"] = "wool:white"}, {["x"] = 4, ["meta"] = {["fields"] = {}, ["inventory"] = {}}, ["y"] = 34, ["z"] = 10, ["name"] = "wool:white"}, {["x"] = 4, ["meta"] = {["fields"] = {}, ["inventory"] = {}}, ["y"] = 34, ["z"] = 11, ["name"] = "wool:white"}, {["x"] = 4, ["meta"] = {["fields"] = {}, ["inventory"] = {}}, ["y"] = 34, ["z"] = 12, ["name"] = "wool:white"}, {["x"] = 4, ["meta"] = {["fields"] = {}, ["inventory"] = {}}, ["y"] = 34, ["z"] = 13, ["name"] = "wool:white"}, {["x"] = 5, ["meta"] = {["fields"] = {}, ["inventory"] = {}}, ["y"] = 0, ["param1"] = 45, ["z"] = 6, ["name"] = "flowers:rose"}, {["x"] = 5, ["meta"] = {["fields"] = {}, ["inventory"] = {}}, ["y"] = 0, ["z"] = 8, ["name"] = "darkage:desert_stone_with_iron"}, {["x"] = 5, ["meta"] = {["fields"] = {}, ["inventory"] = {}}, ["param2"] = 2, ["y"] = 0, ["param1"] = 187, ["z"] = 9, ["name"] = "homedecor:table"}, {["x"] = 5, ["meta"] = {["fields"] = {}, ["inventory"] = {}}, ["y"] = 0, ["param1"] = 187, ["z"] = 10, ["name"] = "lrfurn:sofa_red"}, {["x"] = 5, ["meta"] = {["fields"] = {}, ["inventory"] = {}}, ["param2"] = 3, ["y"] = 0, ["param1"] = 187, ["z"] = 12, ["name"] = "homedecor:table"}, {["x"] = 5, ["meta"] = {["fields"] = {}, ["inventory"] = {}}, ["y"] = 0, ["z"] = 13, ["name"] = "darkage:desert_stone_with_iron"}, {["x"] = 5, ["meta"] = {["fields"] = {}, ["inventory"] = {}}, ["y"] = 1, ["z"] = 8, ["name"] = "darkage:desert_stone_with_iron"}, {["x"] = 5, ["meta"] = {["fields"] = {}, ["inventory"] = {}}, ["param2"] = 2, ["y"] = 1, ["param1"] = 204, ["z"] = 9, ["name"] = "homedecor:table_lamp_red_off"}, {["x"] = 5, ["meta"] = {["fields"] = {}, ["inventory"] = {}}, ["param2"] = 3, ["y"] = 1, ["param1"] = 204, ["z"] = 12, ["name"] = "homedecor:table_lamp_red_off"}, {["x"] = 5, ["meta"] = {["fields"] = {}, ["inventory"] = {}}, ["y"] = 1, ["z"] = 13, ["name"] = "darkage:desert_stone_with_iron"}, {["x"] = 5, ["meta"] = {["fields"] = {}, ["inventory"] = {}}, ["y"] = 2, ["z"] = 8, ["name"] = "darkage:desert_stone_with_iron"}, {["x"] = 5, ["meta"] = {["fields"] = {}, ["inventory"] = {}}, ["param2"] = 3, ["y"] = 2, ["z"] = 9, ["name"] = "default:torch"}, {["x"] = 5, ["meta"] = {["fields"] = {}, ["inventory"] = {}}, ["param2"] = 3, ["y"] = 2, ["z"] = 12, ["name"] = "default:torch"}, {["x"] = 5, ["meta"] = {["fields"] = {}, ["inventory"] = {}}, ["y"] = 2, ["z"] = 13, ["name"] = "darkage:desert_stone_with_iron"}, {["x"] = 5, ["meta"] = {["fields"] = {}, ["inventory"] = {}}, ["y"] = 3, ["z"] = 8, ["name"] = "darkage:desert_stone_with_iron"}, {["x"] = 5, ["meta"] = {["fields"] = {}, ["inventory"] = {}}, ["y"] = 3, ["z"] = 9, ["name"] = "default:stone"}, {["x"] = 5, ["meta"] = {["fields"] = {}, ["inventory"] = {}}, ["y"] = 3, ["z"] = 10, ["name"] = "default:stone"}, {["x"] = 5, ["meta"] = {["fields"] = {}, ["inventory"] = {}}, ["y"] = 3, ["z"] = 11, ["name"] = "default:stone"}, {["x"] = 5, ["meta"] = {["fields"] = {}, ["inventory"] = {}}, ["y"] = 3, ["z"] = 12, ["name"] = "default:stone"}, {["x"] = 5, ["meta"] = {["fields"] = {}, ["inventory"] = {}}, ["y"] = 3, ["z"] = 13, ["name"] = "darkage:desert_stone_with_iron"}, {["x"] = 5, ["meta"] = {["fields"] = {}, ["inventory"] = {}}, ["y"] = 4, ["z"] = 8, ["name"] = "darkage:desert_stone_with_iron"}, {["x"] = 5, ["meta"] = {["fields"] = {}, ["inventory"] = {}}, ["y"] = 4, ["z"] = 9, ["name"] = "default:dirt"}, {["x"] = 5, ["meta"] = {["fields"] = {}, ["inventory"] = {}}, ["param2"] = 5, ["y"] = 4, ["param1"] = 170, ["z"] = 10, ["name"] = "homedecor:utility_table_top"}, {["x"] = 5, ["meta"] = {["fields"] = {}, ["inventory"] = {}}, ["param2"] = 4, ["y"] = 4, ["param1"] = 170, ["z"] = 11, ["name"] = "homedecor:utility_table_top"}, {["x"] = 5, ["meta"] = {["fields"] = {}, ["inventory"] = {}}, ["y"] = 4, ["z"] = 12, ["name"] = "default:dirt"}, {["x"] = 5, ["meta"] = {["fields"] = {}, ["inventory"] = {}}, ["y"] = 4, ["z"] = 13, ["name"] = "darkage:desert_stone_with_iron"}, {["x"] = 5, ["meta"] = {["fields"] = {}, ["inventory"] = {}}, ["y"] = 5, ["z"] = 8, ["name"] = "darkage:desert_stone_with_iron"}, {["x"] = 5, ["meta"] = {["fields"] = {}, ["inventory"] = {}}, ["y"] = 5, ["param1"] = 204, ["z"] = 9, ["name"] = "default:junglegrass"}, {["x"] = 5, ["meta"] = {["fields"] = {}, ["inventory"] = {}}, ["y"] = 5, ["param1"] = 204, ["z"] = 12, ["name"] = "default:junglegrass"}, {["x"] = 5, ["meta"] = {["fields"] = {}, ["inventory"] = {}}, ["y"] = 5, ["z"] = 13, ["name"] = "darkage:desert_stone_with_iron"}, {["x"] = 5, ["meta"] = {["fields"] = {}, ["inventory"] = {}}, ["y"] = 6, ["z"] = 8, ["name"] = "darkage:desert_stone_with_iron"}, {["x"] = 5, ["meta"] = {["fields"] = {}, ["inventory"] = {}}, ["param2"] = 3, ["y"] = 6, ["z"] = 9, ["name"] = "default:torch"}, {["x"] = 5, ["meta"] = {["fields"] = {}, ["inventory"] = {}}, ["param2"] = 3, ["y"] = 6, ["z"] = 12, ["name"] = "default:torch"}, {["x"] = 5, ["meta"] = {["fields"] = {}, ["inventory"] = {}}, ["y"] = 6, ["z"] = 13, ["name"] = "darkage:desert_stone_with_iron"}, {["x"] = 5, ["meta"] = {["fields"] = {}, ["inventory"] = {}}, ["y"] = 7, ["z"] = 8, ["name"] = "darkage:desert_stone_with_iron"}, {["x"] = 5, ["meta"] = {["fields"] = {}, ["inventory"] = {}}, ["y"] = 7, ["z"] = 9, ["name"] = "default:stone"}, {["x"] = 5, ["meta"] = {["fields"] = {}, ["inventory"] = {}}, ["y"] = 7, ["z"] = 10, ["name"] = "default:stone"}, {["x"] = 5, ["meta"] = {["fields"] = {}, ["inventory"] = {}}, ["y"] = 7, ["z"] = 11, ["name"] = "default:stone"}, {["x"] = 5, ["meta"] = {["fields"] = {}, ["inventory"] = {}}, ["y"] = 7, ["z"] = 12, ["name"] = "default:stone"}, {["x"] = 5, ["meta"] = {["fields"] = {}, ["inventory"] = {}}, ["y"] = 7, ["z"] = 13, ["name"] = "darkage:desert_stone_with_iron"}, {["x"] = 5, ["meta"] = {["fields"] = {}, ["inventory"] = {}}, ["y"] = 8, ["z"] = 8, ["name"] = "darkage:desert_stone_with_iron"}, {["x"] = 5, ["meta"] = {["fields"] = {}, ["inventory"] = {}}, ["y"] = 8, ["z"] = 9, ["name"] = "default:dirt_with_grass"}, {["x"] = 5, ["meta"] = {["fields"] = {}, ["inventory"] = {}}, ["y"] = 8, ["z"] = 10, ["name"] = "building_blocks:fakegrass"}, {["x"] = 5, ["meta"] = {["fields"] = {}, ["inventory"] = {}}, ["y"] = 8, ["z"] = 11, ["name"] = "default:dirt_with_grass"}, {["x"] = 5, ["meta"] = {["fields"] = {}, ["inventory"] = {}}, ["y"] = 8, ["z"] = 12, ["name"] = "default:dirt_with_grass"}, {["x"] = 5, ["meta"] = {["fields"] = {}, ["inventory"] = {}}, ["y"] = 8, ["z"] = 13, ["name"] = "darkage:desert_stone_with_iron"}, {["x"] = 5, ["meta"] = {["fields"] = {}, ["inventory"] = {}}, ["y"] = 9, ["z"] = 6, ["name"] = "darkage:desert_stone_with_iron"}, {["x"] = 5, ["meta"] = {["fields"] = {}, ["inventory"] = {}}, ["y"] = 9, ["z"] = 7, ["name"] = "darkage:desert_stone_with_iron"}, {["x"] = 5, ["meta"] = {["fields"] = {}, ["inventory"] = {}}, ["y"] = 9, ["z"] = 8, ["name"] = "darkage:desert_stone_with_iron"}, {["x"] = 5, ["meta"] = {["fields"] = {}, ["inventory"] = {}}, ["y"] = 9, ["param1"] = 140, ["z"] = 9, ["name"] = "default:junglegrass"}, {["x"] = 5, ["meta"] = {["fields"] = {}, ["inventory"] = {}}, ["y"] = 9, ["param1"] = 140, ["z"] = 12, ["name"] = "default:junglegrass"}, {["x"] = 5, ["meta"] = {["fields"] = {}, ["inventory"] = {}}, ["y"] = 9, ["z"] = 13, ["name"] = "darkage:desert_stone_with_iron"}, {["x"] = 5, ["meta"] = {["fields"] = {}, ["inventory"] = {}}, ["y"] = 9, ["z"] = 14, ["name"] = "darkage:desert_stone_with_iron"}, {["x"] = 5, ["meta"] = {["fields"] = {}, ["inventory"] = {}}, ["y"] = 9, ["z"] = 15, ["name"] = "darkage:desert_stone_with_iron"}, {["x"] = 5, ["meta"] = {["fields"] = {}, ["inventory"] = {}}, ["y"] = 10, ["z"] = 6, ["name"] = "darkage:desert_stone_with_iron"}, {["x"] = 5, ["meta"] = {["fields"] = {}, ["inventory"] = {}}, ["y"] = 10, ["z"] = 7, ["name"] = "darkage:desert_stone_with_iron"}, {["x"] = 5, ["meta"] = {["fields"] = {}, ["inventory"] = {}}, ["y"] = 10, ["z"] = 14, ["name"] = "darkage:desert_stone_with_iron"}, {["x"] = 5, ["meta"] = {["fields"] = {}, ["inventory"] = {}}, ["y"] = 10, ["z"] = 15, ["name"] = "darkage:desert_stone_with_iron"}, {["x"] = 5, ["meta"] = {["fields"] = {}, ["inventory"] = {}}, ["y"] = 22, ["z"] = 8, ["name"] = "wool:green"}, {["x"] = 5, ["meta"] = {["fields"] = {}, ["inventory"] = {}}, ["y"] = 22, ["z"] = 9, ["name"] = "wool:green"}, {["x"] = 5, ["meta"] = {["fields"] = {}, ["inventory"] = {}}, ["y"] = 22, ["z"] = 10, ["name"] = "wool:green"}, {["x"] = 5, ["meta"] = {["fields"] = {}, ["inventory"] = {}}, ["y"] = 22, ["z"] = 11, ["name"] = "wool:green"}, {["x"] = 5, ["meta"] = {["fields"] = {}, ["inventory"] = {}}, ["y"] = 22, ["z"] = 12, ["name"] = "wool:green"}, {["x"] = 5, ["meta"] = {["fields"] = {}, ["inventory"] = {}}, ["y"] = 22, ["z"] = 13, ["name"] = "wool:green"}, {["x"] = 5, ["meta"] = {["fields"] = {}, ["inventory"] = {}}, ["param2"] = 4, ["y"] = 34, ["param1"] = 15, ["z"] = 8, ["name"] = "default:torch"}, {["x"] = 5, ["meta"] = {["fields"] = {}, ["inventory"] = {}}, ["y"] = 34, ["z"] = 9, ["name"] = "wool:white"}, {["x"] = 5, ["meta"] = {["fields"] = {}, ["inventory"] = {}}, ["y"] = 34, ["z"] = 10, ["name"] = "wool:white"}, {["x"] = 5, ["meta"] = {["fields"] = {}, ["inventory"] = {}}, ["y"] = 34, ["z"] = 11, ["name"] = "wool:white"}, {["x"] = 5, ["meta"] = {["fields"] = {}, ["inventory"] = {}}, ["y"] = 34, ["z"] = 12, ["name"] = "wool:white"}, {["x"] = 5, ["meta"] = {["fields"] = {}, ["inventory"] = {}}, ["param2"] = 5, ["y"] = 34, ["param1"] = 15, ["z"] = 13, ["name"] = "default:torch"}, {["x"] = 6, ["meta"] = {["fields"] = {}, ["inventory"] = {}}, ["y"] = 0, ["z"] = 7, ["name"] = "darkage:desert_stone_with_iron"}, {["x"] = 6, ["meta"] = {["fields"] = {}, ["inventory"] = {}}, ["param2"] = 2, ["y"] = 0, ["param1"] = 170, ["z"] = 8, ["name"] = "lrfurn:armchair_red"}, {["x"] = 6, ["meta"] = {["fields"] = {}, ["inventory"] = {}}, ["y"] = 0, ["param1"] = 170, ["z"] = 13, ["name"] = "lrfurn:armchair_red"}, {["x"] = 6, ["meta"] = {["fields"] = {}, ["inventory"] = {}}, ["y"] = 0, ["z"] = 14, ["name"] = "darkage:desert_stone_with_iron"}, {["x"] = 6, ["meta"] = {["fields"] = {}, ["inventory"] = {}}, ["y"] = 1, ["z"] = 7, ["name"] = "darkage:desert_stone_with_iron"}, {["x"] = 6, ["meta"] = {["fields"] = {}, ["inventory"] = {}}, ["y"] = 1, ["z"] = 14, ["name"] = "darkage:desert_stone_with_iron"}, {["x"] = 6, ["meta"] = {["fields"] = {}, ["inventory"] = {}}, ["y"] = 2, ["z"] = 7, ["name"] = "darkage:desert_stone_with_iron"}, {["x"] = 6, ["meta"] = {["fields"] = {}, ["inventory"] = {}}, ["y"] = 2, ["z"] = 14, ["name"] = "darkage:desert_stone_with_iron"}, {["x"] = 6, ["meta"] = {["fields"] = {}, ["inventory"] = {}}, ["y"] = 3, ["z"] = 7, ["name"] = "darkage:desert_stone_with_iron"}, {["x"] = 6, ["meta"] = {["fields"] = {}, ["inventory"] = {}}, ["y"] = 3, ["z"] = 8, ["name"] = "default:stone"}, {["x"] = 6, ["meta"] = {["fields"] = {}, ["inventory"] = {}}, ["y"] = 3, ["z"] = 9, ["name"] = "default:stone"}, {["x"] = 6, ["meta"] = {["fields"] = {}, ["inventory"] = {}}, ["y"] = 3, ["z"] = 10, ["name"] = "default:stone"}, {["x"] = 6, ["meta"] = {["fields"] = {}, ["inventory"] = {}}, ["y"] = 3, ["z"] = 11, ["name"] = "default:stone"}, {["x"] = 6, ["meta"] = {["fields"] = {}, ["inventory"] = {}}, ["y"] = 3, ["z"] = 12, ["name"] = "default:stone"}, {["x"] = 6, ["meta"] = {["fields"] = {}, ["inventory"] = {}}, ["y"] = 3, ["z"] = 13, ["name"] = "default:stone"}, {["x"] = 6, ["meta"] = {["fields"] = {}, ["inventory"] = {}}, ["y"] = 3, ["z"] = 14, ["name"] = "darkage:desert_stone_with_iron"}, {["x"] = 6, ["meta"] = {["fields"] = {}, ["inventory"] = {}}, ["y"] = 4, ["z"] = 7, ["name"] = "darkage:desert_stone_with_iron"}, {["x"] = 6, ["meta"] = {["fields"] = {}, ["inventory"] = {}}, ["param2"] = 3, ["y"] = 4, ["param1"] = 170, ["z"] = 9, ["name"] = "homedecor:utility_table_top"}, {["x"] = 6, ["meta"] = {["fields"] = {}, ["inventory"] = {}}, ["param2"] = 3, ["y"] = 4, ["param1"] = 170, ["z"] = 12, ["name"] = "homedecor:utility_table_top"}, {["x"] = 6, ["meta"] = {["fields"] = {}, ["inventory"] = {}}, ["y"] = 4, ["z"] = 14, ["name"] = "darkage:desert_stone_with_iron"}, {["x"] = 6, ["meta"] = {["fields"] = {}, ["inventory"] = {}}, ["y"] = 5, ["z"] = 7, ["name"] = "darkage:desert_stone_with_iron"}, {["x"] = 6, ["meta"] = {["fields"] = {}, ["inventory"] = {}}, ["y"] = 5, ["z"] = 14, ["name"] = "darkage:desert_stone_with_iron"}, {["x"] = 6, ["meta"] = {["fields"] = {}, ["inventory"] = {}}, ["y"] = 6, ["z"] = 7, ["name"] = "darkage:desert_stone_with_iron"}, {["x"] = 6, ["meta"] = {["fields"] = {}, ["inventory"] = {}}, ["y"] = 6, ["z"] = 14, ["name"] = "darkage:desert_stone_with_iron"}, {["x"] = 6, ["meta"] = {["fields"] = {}, ["inventory"] = {}}, ["y"] = 7, ["z"] = 7, ["name"] = "darkage:desert_stone_with_iron"}, {["x"] = 6, ["meta"] = {["fields"] = {}, ["inventory"] = {}}, ["y"] = 7, ["z"] = 8, ["name"] = "default:stone"}, {["x"] = 6, ["meta"] = {["fields"] = {}, ["inventory"] = {}}, ["y"] = 7, ["z"] = 9, ["name"] = "default:stone"}, {["x"] = 6, ["meta"] = {["fields"] = {}, ["inventory"] = {}}, ["y"] = 7, ["z"] = 10, ["name"] = "default:stone"}, {["x"] = 6, ["meta"] = {["fields"] = {}, ["inventory"] = {}}, ["y"] = 7, ["z"] = 11, ["name"] = "default:stone"}, {["x"] = 6, ["meta"] = {["fields"] = {}, ["inventory"] = {}}, ["y"] = 7, ["z"] = 12, ["name"] = "default:stone"}, {["x"] = 6, ["meta"] = {["fields"] = {}, ["inventory"] = {}}, ["y"] = 7, ["z"] = 13, ["name"] = "default:stone"}, {["x"] = 6, ["meta"] = {["fields"] = {}, ["inventory"] = {}}, ["y"] = 7, ["z"] = 14, ["name"] = "darkage:desert_stone_with_iron"}, {["x"] = 6, ["meta"] = {["fields"] = {}, ["inventory"] = {}}, ["y"] = 8, ["z"] = 7, ["name"] = "darkage:desert_stone_with_iron"}, {["x"] = 6, ["meta"] = {["fields"] = {}, ["inventory"] = {}}, ["y"] = 8, ["z"] = 8, ["name"] = "default:dirt_with_grass"}, {["x"] = 6, ["meta"] = {["fields"] = {}, ["inventory"] = {}}, ["y"] = 8, ["z"] = 9, ["name"] = "default:dirt_with_grass"}, {["x"] = 6, ["meta"] = {["fields"] = {}, ["inventory"] = {}}, ["y"] = 8, ["z"] = 10, ["name"] = "building_blocks:fakegrass"}, {["x"] = 6, ["meta"] = {["fields"] = {}, ["inventory"] = {}}, ["y"] = 8, ["z"] = 11, ["name"] = "building_blocks:fakegrass"}, {["x"] = 6, ["meta"] = {["fields"] = {}, ["inventory"] = {}}, ["y"] = 8, ["z"] = 12, ["name"] = "default:dirt_with_grass"}, {["x"] = 6, ["meta"] = {["fields"] = {}, ["inventory"] = {}}, ["y"] = 8, ["z"] = 13, ["name"] = "default:dirt_with_grass"}, {["x"] = 6, ["meta"] = {["fields"] = {}, ["inventory"] = {}}, ["y"] = 8, ["z"] = 14, ["name"] = "darkage:desert_stone_with_iron"}, {["x"] = 6, ["meta"] = {["fields"] = {}, ["inventory"] = {}}, ["y"] = 9, ["z"] = 5, ["name"] = "darkage:desert_stone_with_iron"}, {["x"] = 6, ["meta"] = {["fields"] = {}, ["inventory"] = {}}, ["y"] = 9, ["z"] = 6, ["name"] = "darkage:desert_stone_with_iron"}, {["x"] = 6, ["meta"] = {["fields"] = {}, ["inventory"] = {}}, ["y"] = 9, ["z"] = 7, ["name"] = "darkage:desert_stone_with_iron"}, {["x"] = 6, ["meta"] = {["fields"] = {}, ["inventory"] = {}}, ["y"] = 9, ["z"] = 14, ["name"] = "darkage:desert_stone_with_iron"}, {["x"] = 6, ["meta"] = {["fields"] = {}, ["inventory"] = {}}, ["y"] = 9, ["z"] = 15, ["name"] = "darkage:desert_stone_with_iron"}, {["x"] = 6, ["meta"] = {["fields"] = {}, ["inventory"] = {}}, ["y"] = 9, ["z"] = 16, ["name"] = "darkage:desert_stone_with_iron"}, {["x"] = 6, ["meta"] = {["fields"] = {}, ["inventory"] = {}}, ["y"] = 10, ["z"] = 5, ["name"] = "darkage:desert_stone_with_iron"}, {["x"] = 6, ["meta"] = {["fields"] = {}, ["inventory"] = {}}, ["y"] = 10, ["z"] = 6, ["name"] = "darkage:desert_stone_with_iron"}, {["x"] = 6, ["meta"] = {["fields"] = {}, ["inventory"] = {}}, ["y"] = 10, ["z"] = 15, ["name"] = "darkage:desert_stone_with_iron"}, {["x"] = 6, ["meta"] = {["fields"] = {}, ["inventory"] = {}}, ["y"] = 10, ["z"] = 16, ["name"] = "darkage:desert_stone_with_iron"}, {["x"] = 6, ["meta"] = {["fields"] = {}, ["inventory"] = {}}, ["param2"] = 4, ["y"] = 22, ["param1"] = 15, ["z"] = 8, ["name"] = "default:torch"}, {["x"] = 6, ["meta"] = {["fields"] = {}, ["inventory"] = {}}, ["y"] = 22, ["z"] = 9, ["name"] = "wool:green"}, {["x"] = 6, ["meta"] = {["fields"] = {}, ["inventory"] = {}}, ["y"] = 22, ["z"] = 10, ["name"] = "wool:green"}, {["x"] = 6, ["meta"] = {["fields"] = {}, ["inventory"] = {}}, ["y"] = 22, ["z"] = 11, ["name"] = "wool:green"}, {["x"] = 6, ["meta"] = {["fields"] = {}, ["inventory"] = {}}, ["y"] = 22, ["z"] = 12, ["name"] = "wool:green"}, {["x"] = 6, ["meta"] = {["fields"] = {}, ["inventory"] = {}}, ["param2"] = 5, ["y"] = 22, ["param1"] = 15, ["z"] = 13, ["name"] = "default:torch"}, {["x"] = 6, ["meta"] = {["fields"] = {}, ["inventory"] = {}}, ["param2"] = 4, ["y"] = 34, ["param1"] = 15, ["z"] = 9, ["name"] = "default:torch"}, {["x"] = 6, ["meta"] = {["fields"] = {}, ["inventory"] = {}}, ["y"] = 34, ["z"] = 10, ["name"] = "wool:white"}, {["x"] = 6, ["meta"] = {["fields"] = {}, ["inventory"] = {}}, ["y"] = 34, ["z"] = 11, ["name"] = "wool:white"}, {["x"] = 6, ["meta"] = {["fields"] = {}, ["inventory"] = {}}, ["param2"] = 5, ["y"] = 34, ["param1"] = 15, ["z"] = 12, ["name"] = "default:torch"}, {["x"] = 7, ["meta"] = {["fields"] = {}, ["inventory"] = {}}, ["y"] = 0, ["z"] = 6, ["name"] = "darkage:desert_stone_with_iron"}, {["x"] = 7, ["meta"] = {["fields"] = {["infotext"] = "Kitchen Cabinet", ["formspec"] = "size[8,8]bgcolor[#080808BB;true]background[5,5;1,1;gui_formbg.png;true]listcolors[#00000069;#5A5A5A;#141318;#30434C;#FFF]list[context;main;0,0;8,3;]list[current_player;main;0,4;8,4;]"}, ["inventory"] = {["main"] = {"", "", "", "", "", "", "", "", "", "", "", "", "", "", "", "", "", "", "", "", "", "", "", ""}}}, ["param2"] = 3, ["y"] = 0, ["param1"] = 170, ["z"] = 7, ["name"] = "homedecor:kitchen_cabinet_marble"}, {["x"] = 7, ["meta"] = {["fields"] = {}, ["inventory"] = {}}, ["y"] = 0, ["z"] = 15, ["name"] = "darkage:desert_stone_with_iron"}, {["x"] = 7, ["meta"] = {["fields"] = {}, ["inventory"] = {}}, ["y"] = 1, ["z"] = 6, ["name"] = "darkage:desert_stone_with_iron"}, {["x"] = 7, ["meta"] = {["fields"] = {}, ["inventory"] = {}}, ["param2"] = 3, ["y"] = 1, ["param1"] = 170, ["z"] = 7, ["name"] = "homedecor:toaster"}, {["x"] = 7, ["meta"] = {["fields"] = {}, ["inventory"] = {}}, ["y"] = 1, ["z"] = 15, ["name"] = "darkage:desert_stone_with_iron"}, {["x"] = 7, ["meta"] = {["fields"] = {}, ["inventory"] = {}}, ["y"] = 2, ["z"] = 6, ["name"] = "darkage:desert_stone_with_iron"}, {["x"] = 7, ["meta"] = {["fields"] = {}, ["inventory"] = {}}, ["y"] = 2, ["z"] = 10, ["name"] = "default:stone"}, {["x"] = 7, ["meta"] = {["fields"] = {}, ["inventory"] = {}}, ["y"] = 2, ["z"] = 11, ["name"] = "default:stone"}, {["x"] = 7, ["meta"] = {["fields"] = {}, ["inventory"] = {}}, ["y"] = 2, ["z"] = 15, ["name"] = "darkage:desert_stone_with_iron"}, {["x"] = 7, ["meta"] = {["fields"] = {}, ["inventory"] = {}}, ["y"] = 3, ["z"] = 6, ["name"] = "darkage:desert_stone_with_iron"}, {["x"] = 7, ["meta"] = {["fields"] = {}, ["inventory"] = {}}, ["y"] = 3, ["z"] = 7, ["name"] = "default:stone"}, {["x"] = 7, ["meta"] = {["fields"] = {}, ["inventory"] = {}}, ["y"] = 3, ["z"] = 8, ["name"] = "default:stone"}, {["x"] = 7, ["meta"] = {["fields"] = {}, ["inventory"] = {}}, ["y"] = 3, ["z"] = 9, ["name"] = "default:stone"}, {["x"] = 7, ["meta"] = {["fields"] = {}, ["inventory"] = {}}, ["param2"] = 3, ["y"] = 3, ["param1"] = 136, ["z"] = 10, ["name"] = "stairs:stair_stone"}, {["x"] = 7, ["meta"] = {["fields"] = {}, ["inventory"] = {}}, ["param2"] = 3, ["y"] = 3, ["param1"] = 136, ["z"] = 11, ["name"] = "stairs:stair_stone"}, {["x"] = 7, ["meta"] = {["fields"] = {}, ["inventory"] = {}}, ["y"] = 3, ["z"] = 12, ["name"] = "default:stone"}, {["x"] = 7, ["meta"] = {["fields"] = {}, ["inventory"] = {}}, ["y"] = 3, ["z"] = 13, ["name"] = "default:stone"}, {["x"] = 7, ["meta"] = {["fields"] = {}, ["inventory"] = {}}, ["y"] = 3, ["z"] = 14, ["name"] = "default:stone"}, {["x"] = 7, ["meta"] = {["fields"] = {}, ["inventory"] = {}}, ["y"] = 3, ["z"] = 15, ["name"] = "darkage:desert_stone_with_iron"}, {["x"] = 7, ["meta"] = {["fields"] = {}, ["inventory"] = {}}, ["y"] = 4, ["z"] = 6, ["name"] = "darkage:desert_stone_with_iron"}, {["x"] = 7, ["meta"] = {["fields"] = {}, ["inventory"] = {}}, ["param2"] = 3, ["y"] = 4, ["param1"] = 153, ["z"] = 7, ["name"] = "homedecor:armchair_red"}, {["x"] = 7, ["meta"] = {["fields"] = {}, ["inventory"] = {}}, ["param2"] = 3, ["y"] = 4, ["param1"] = 153, ["z"] = 14, ["name"] = "homedecor:shower_tray"}, {["x"] = 7, ["meta"] = {["fields"] = {}, ["inventory"] = {}}, ["y"] = 4, ["z"] = 15, ["name"] = "darkage:desert_stone_with_iron"}, {["x"] = 7, ["meta"] = {["fields"] = {}, ["inventory"] = {}}, ["y"] = 5, ["z"] = 6, ["name"] = "darkage:desert_stone_with_iron"}, {["x"] = 7, ["meta"] = {["fields"] = {}, ["inventory"] = {}}, ["y"] = 5, ["z"] = 15, ["name"] = "darkage:desert_stone_with_iron"}, {["x"] = 7, ["meta"] = {["fields"] = {}, ["inventory"] = {}}, ["y"] = 6, ["z"] = 6, ["name"] = "darkage:desert_stone_with_iron"}, {["x"] = 7, ["meta"] = {["fields"] = {}, ["inventory"] = {}}, ["param2"] = 3, ["y"] = 6, ["param1"] = 187, ["z"] = 14, ["name"] = "homedecor:shower_head"}, {["x"] = 7, ["meta"] = {["fields"] = {}, ["inventory"] = {}}, ["y"] = 6, ["z"] = 15, ["name"] = "darkage:desert_stone_with_iron"}, {["x"] = 7, ["meta"] = {["fields"] = {}, ["inventory"] = {}}, ["y"] = 7, ["z"] = 6, ["name"] = "darkage:desert_stone_with_iron"}, {["x"] = 7, ["meta"] = {["fields"] = {}, ["inventory"] = {}}, ["y"] = 7, ["z"] = 7, ["name"] = "default:stone"}, {["x"] = 7, ["meta"] = {["fields"] = {}, ["inventory"] = {}}, ["y"] = 7, ["z"] = 8, ["name"] = "default:stone"}, {["x"] = 7, ["meta"] = {["fields"] = {}, ["inventory"] = {}}, ["y"] = 7, ["z"] = 9, ["name"] = "default:stone"}, {["x"] = 7, ["meta"] = {["fields"] = {}, ["inventory"] = {}}, ["y"] = 7, ["z"] = 10, ["name"] = "default:stone"}, {["x"] = 7, ["meta"] = {["fields"] = {}, ["inventory"] = {}}, ["y"] = 7, ["z"] = 11, ["name"] = "default:stone"}, {["x"] = 7, ["meta"] = {["fields"] = {}, ["inventory"] = {}}, ["y"] = 7, ["z"] = 12, ["name"] = "default:stone"}, {["x"] = 7, ["meta"] = {["fields"] = {}, ["inventory"] = {}}, ["y"] = 7, ["z"] = 13, ["name"] = "default:stone"}, {["x"] = 7, ["meta"] = {["fields"] = {}, ["inventory"] = {}}, ["y"] = 7, ["z"] = 14, ["name"] = "default:stone"}, {["x"] = 7, ["meta"] = {["fields"] = {}, ["inventory"] = {}}, ["y"] = 7, ["z"] = 15, ["name"] = "darkage:desert_stone_with_iron"}, {["x"] = 7, ["meta"] = {["fields"] = {}, ["inventory"] = {}}, ["y"] = 8, ["z"] = 6, ["name"] = "darkage:desert_stone_with_iron"}, {["x"] = 7, ["meta"] = {["fields"] = {}, ["inventory"] = {}}, ["y"] = 8, ["z"] = 7, ["name"] = "default:dirt_with_grass"}, {["x"] = 7, ["meta"] = {["fields"] = {}, ["inventory"] = {}}, ["y"] = 8, ["z"] = 8, ["name"] = "default:dirt_with_grass"}, {["x"] = 7, ["meta"] = {["fields"] = {}, ["inventory"] = {}}, ["y"] = 8, ["z"] = 9, ["name"] = "default:dirt_with_grass"}, {["x"] = 7, ["meta"] = {["fields"] = {}, ["inventory"] = {}}, ["param2"] = 3, ["y"] = 8, ["param1"] = 140, ["z"] = 10, ["name"] = "stairs:stair_stone"}, {["x"] = 7, ["meta"] = {["fields"] = {}, ["inventory"] = {}}, ["param2"] = 3, ["y"] = 8, ["param1"] = 140, ["z"] = 11, ["name"] = "stairs:stair_stone"}, {["x"] = 7, ["meta"] = {["fields"] = {}, ["inventory"] = {}}, ["y"] = 8, ["z"] = 12, ["name"] = "default:dirt_with_grass"}, {["x"] = 7, ["meta"] = {["fields"] = {}, ["inventory"] = {}}, ["y"] = 8, ["z"] = 13, ["name"] = "default:dirt_with_grass"}, {["x"] = 7, ["meta"] = {["fields"] = {}, ["inventory"] = {}}, ["y"] = 8, ["z"] = 14, ["name"] = "default:dirt_with_grass"}, {["x"] = 7, ["meta"] = {["fields"] = {}, ["inventory"] = {}}, ["y"] = 8, ["z"] = 15, ["name"] = "darkage:desert_stone_with_iron"}, {["x"] = 7, ["meta"] = {["fields"] = {}, ["inventory"] = {}}, ["y"] = 9, ["z"] = 4, ["name"] = "darkage:desert_stone_with_iron"}, {["x"] = 7, ["meta"] = {["fields"] = {}, ["inventory"] = {}}, ["y"] = 9, ["z"] = 5, ["name"] = "darkage:desert_stone_with_iron"}, {["x"] = 7, ["meta"] = {["fields"] = {}, ["inventory"] = {}}, ["y"] = 9, ["z"] = 6, ["name"] = "darkage:desert_stone_with_iron"}, {["x"] = 7, ["meta"] = {["fields"] = {}, ["inventory"] = {}}, ["y"] = 9, ["z"] = 15, ["name"] = "darkage:desert_stone_with_iron"}, {["x"] = 7, ["meta"] = {["fields"] = {}, ["inventory"] = {}}, ["y"] = 9, ["z"] = 16, ["name"] = "darkage:desert_stone_with_iron"}, {["x"] = 7, ["meta"] = {["fields"] = {}, ["inventory"] = {}}, ["y"] = 9, ["z"] = 17, ["name"] = "darkage:desert_stone_with_iron"}, {["x"] = 7, ["meta"] = {["fields"] = {}, ["inventory"] = {}}, ["y"] = 10, ["z"] = 4, ["name"] = "darkage:desert_stone_with_iron"}, {["x"] = 7, ["meta"] = {["fields"] = {}, ["inventory"] = {}}, ["y"] = 10, ["z"] = 5, ["name"] = "darkage:desert_stone_with_iron"}, {["x"] = 7, ["meta"] = {["fields"] = {}, ["inventory"] = {}}, ["y"] = 10, ["z"] = 16, ["name"] = "darkage:desert_stone_with_iron"}, {["x"] = 7, ["meta"] = {["fields"] = {}, ["inventory"] = {}}, ["y"] = 10, ["z"] = 17, ["name"] = "darkage:desert_stone_with_iron"}, {["x"] = 7, ["meta"] = {["fields"] = {}, ["inventory"] = {}}, ["param2"] = 1, ["y"] = 11, ["z"] = 4, ["name"] = "default:torch"}, {["x"] = 7, ["meta"] = {["fields"] = {}, ["inventory"] = {}}, ["param2"] = 1, ["y"] = 11, ["z"] = 17, ["name"] = "default:torch"}, {["x"] = 7, ["meta"] = {["fields"] = {}, ["inventory"] = {}}, ["param2"] = 4, ["y"] = 22, ["param1"] = 15, ["z"] = 9, ["name"] = "default:torch"}, {["x"] = 7, ["meta"] = {["fields"] = {}, ["inventory"] = {}}, ["y"] = 22, ["z"] = 10, ["name"] = "wool:green"}, {["x"] = 7, ["meta"] = {["fields"] = {}, ["inventory"] = {}}, ["y"] = 22, ["z"] = 11, ["name"] = "wool:green"}, {["x"] = 7, ["meta"] = {["fields"] = {}, ["inventory"] = {}}, ["param2"] = 5, ["y"] = 22, ["param1"] = 15, ["z"] = 12, ["name"] = "default:torch"}, {["x"] = 7, ["meta"] = {["fields"] = {}, ["inventory"] = {}}, ["param2"] = 2, ["y"] = 27, ["param1"] = 15, ["z"] = 1, ["name"] = "default:torch"}, {["x"] = 7, ["meta"] = {["fields"] = {}, ["inventory"] = {}}, ["y"] = 27, ["z"] = 2, ["name"] = "wool:green"}, {["x"] = 7, ["meta"] = {["fields"] = {}, ["inventory"] = {}}, ["y"] = 27, ["z"] = 3, ["name"] = "wool:green"}, {["x"] = 7, ["meta"] = {["fields"] = {}, ["inventory"] = {}}, ["y"] = 27, ["z"] = 4, ["name"] = "wool:green"}, {["x"] = 7, ["meta"] = {["fields"] = {}, ["inventory"] = {}}, ["y"] = 27, ["z"] = 5, ["name"] = "wool:green"}, {["x"] = 7, ["meta"] = {["fields"] = {}, ["inventory"] = {}}, ["y"] = 27, ["z"] = 6, ["name"] = "wool:green"}, {["x"] = 7, ["meta"] = {["fields"] = {}, ["inventory"] = {}}, ["param2"] = 2, ["y"] = 27, ["param1"] = 15, ["z"] = 7, ["name"] = "default:torch"}, {["x"] = 7, ["meta"] = {["fields"] = {}, ["inventory"] = {}}, ["param2"] = 2, ["y"] = 27, ["param1"] = 15, ["z"] = 14, ["name"] = "default:torch"}, {["x"] = 7, ["meta"] = {["fields"] = {}, ["inventory"] = {}}, ["y"] = 27, ["z"] = 15, ["name"] = "wool:green"}, {["x"] = 7, ["meta"] = {["fields"] = {}, ["inventory"] = {}}, ["y"] = 27, ["z"] = 16, ["name"] = "wool:green"}, {["x"] = 7, ["meta"] = {["fields"] = {}, ["inventory"] = {}}, ["y"] = 27, ["z"] = 17, ["name"] = "wool:green"}, {["x"] = 7, ["meta"] = {["fields"] = {}, ["inventory"] = {}}, ["y"] = 27, ["z"] = 18, ["name"] = "wool:green"}, {["x"] = 7, ["meta"] = {["fields"] = {}, ["inventory"] = {}}, ["y"] = 27, ["z"] = 19, ["name"] = "wool:green"}, {["x"] = 7, ["meta"] = {["fields"] = {}, ["inventory"] = {}}, ["param2"] = 2, ["y"] = 27, ["param1"] = 15, ["z"] = 20, ["name"] = "default:torch"}, {["x"] = 7, ["meta"] = {["fields"] = {}, ["inventory"] = {}}, ["param2"] = 2, ["y"] = 34, ["param1"] = 15, ["z"] = 2, ["name"] = "default:torch"}, {["x"] = 7, ["meta"] = {["fields"] = {}, ["inventory"] = {}}, ["y"] = 34, ["z"] = 3, ["name"] = "wool:white"}, {["x"] = 7, ["meta"] = {["fields"] = {}, ["inventory"] = {}}, ["y"] = 34, ["z"] = 4, ["name"] = "wool:white"}, {["x"] = 7, ["meta"] = {["fields"] = {}, ["inventory"] = {}}, ["y"] = 34, ["z"] = 5, ["name"] = "wool:white"}, {["x"] = 7, ["meta"] = {["fields"] = {}, ["inventory"] = {}}, ["param2"] = 2, ["y"] = 34, ["param1"] = 15, ["z"] = 6, ["name"] = "default:torch"}, {["x"] = 7, ["meta"] = {["fields"] = {}, ["inventory"] = {}}, ["param2"] = 4, ["y"] = 34, ["param1"] = 15, ["z"] = 9, ["name"] = "default:torch"}, {["x"] = 7, ["meta"] = {["fields"] = {}, ["inventory"] = {}}, ["y"] = 34, ["z"] = 10, ["name"] = "wool:yellow"}, {["x"] = 7, ["meta"] = {["fields"] = {}, ["inventory"] = {}}, ["y"] = 34, ["z"] = 11, ["name"] = "wool:yellow"}, {["x"] = 7, ["meta"] = {["fields"] = {}, ["inventory"] = {}}, ["param2"] = 5, ["y"] = 34, ["param1"] = 15, ["z"] = 12, ["name"] = "default:torch"}, {["x"] = 7, ["meta"] = {["fields"] = {}, ["inventory"] = {}}, ["param2"] = 2, ["y"] = 34, ["param1"] = 15, ["z"] = 15, ["name"] = "default:torch"}, {["x"] = 7, ["meta"] = {["fields"] = {}, ["inventory"] = {}}, ["y"] = 34, ["z"] = 16, ["name"] = "wool:white"}, {["x"] = 7, ["meta"] = {["fields"] = {}, ["inventory"] = {}}, ["y"] = 34, ["z"] = 17, ["name"] = "wool:white"}, {["x"] = 7, ["meta"] = {["fields"] = {}, ["inventory"] = {}}, ["y"] = 34, ["z"] = 18, ["name"] = "wool:white"}, {["x"] = 7, ["meta"] = {["fields"] = {}, ["inventory"] = {}}, ["param2"] = 2, ["y"] = 34, ["param1"] = 15, ["z"] = 19, ["name"] = "default:torch"}, {["x"] = 8, ["meta"] = {["fields"] = {}, ["inventory"] = {}}, ["y"] = 0, ["z"] = 5, ["name"] = "darkage:desert_stone_with_iron"}, {["x"] = 8, ["meta"] = {["fields"] = {["src_totaltime"] = "0", ["formspec"] = "size[8,9]image[2,2;1,1;default_furnace_fire_bg.png]list[current_name;fuel;2,3;1,1;]list[current_name;src;2,1;1,1;]list[current_name;dst;5,1;2,2;]list[current_player;main;0,5;8,4;]", ["fuel_time"] = "0", ["fuel_totaltime"] = "0", ["src_time"] = "0", ["infotext"] = "Oven (stainless steel): Out of fuel"}, ["inventory"] = {["fuel"] = {""}, ["dst"] = {"", "", "", ""}, ["src"] = {""}}}, ["param2"] = 2, ["y"] = 0, ["param1"] = 187, ["z"] = 6, ["name"] = "homedecor:oven_steel"}, {["x"] = 8, ["meta"] = {["fields"] = {}, ["inventory"] = {}}, ["param2"] = 1, ["y"] = 0, ["z"] = 10, ["name"] = "fake_fire:fancy_fire"}, {["x"] = 8, ["meta"] = {["fields"] = {}, ["inventory"] = {}}, ["param2"] = 1, ["y"] = 0, ["z"] = 11, ["name"] = "fake_fire:fancy_fire"}, {["x"] = 8, ["meta"] = {["fields"] = {}, ["inventory"] = {}}, ["param2"] = 2, ["y"] = 0, ["param1"] = 187, ["z"] = 14, ["name"] = "homedecor:chair_red"}, {["x"] = 8, ["meta"] = {["fields"] = {}, ["inventory"] = {}}, ["y"] = 0, ["param1"] = 187, ["z"] = 15, ["name"] = "homedecor:table"}, {["x"] = 8, ["meta"] = {["fields"] = {}, ["inventory"] = {}}, ["y"] = 0, ["z"] = 16, ["name"] = "darkage:desert_stone_with_iron"}, {["x"] = 8, ["meta"] = {["fields"] = {}, ["inventory"] = {}}, ["y"] = 1, ["z"] = 5, ["name"] = "darkage:desert_stone_with_iron"}, {["x"] = 8, ["meta"] = {["fields"] = {}, ["inventory"] = {}}, ["y"] = 1, ["z"] = 10, ["name"] = "default:stone"}, {["x"] = 8, ["meta"] = {["fields"] = {}, ["inventory"] = {}}, ["y"] = 1, ["z"] = 11, ["name"] = "default:stone"}, {["x"] = 8, ["meta"] = {["fields"] = {}, ["inventory"] = {}}, ["y"] = 1, ["param1"] = 204, ["z"] = 15, ["name"] = "computer:monitor_on"}, {["x"] = 8, ["meta"] = {["fields"] = {}, ["inventory"] = {}}, ["y"] = 1, ["z"] = 16, ["name"] = "darkage:desert_stone_with_iron"}, {["x"] = 8, ["meta"] = {["fields"] = {}, ["inventory"] = {}}, ["y"] = 2, ["z"] = 5, ["name"] = "darkage:desert_stone_with_iron"}, {["x"] = 8, ["meta"] = {["fields"] = {}, ["inventory"] = {}}, ["param2"] = 5, ["y"] = 2, ["z"] = 6, ["name"] = "default:torch"}, {["x"] = 8, ["meta"] = {["fields"] = {}, ["inventory"] = {}}, ["param2"] = 3, ["y"] = 2, ["param1"] = 170, ["z"] = 10, ["name"] = "stairs:stair_stone"}, {["x"] = 8, ["meta"] = {["fields"] = {}, ["inventory"] = {}}, ["param2"] = 3, ["y"] = 2, ["param1"] = 170, ["z"] = 11, ["name"] = "stairs:stair_stone"}, {["x"] = 8, ["meta"] = {["fields"] = {}, ["inventory"] = {}}, ["param2"] = 4, ["y"] = 2, ["z"] = 15, ["name"] = "default:torch"}, {["x"] = 8, ["meta"] = {["fields"] = {}, ["inventory"] = {}}, ["y"] = 2, ["z"] = 16, ["name"] = "darkage:desert_stone_with_iron"}, {["x"] = 8, ["meta"] = {["fields"] = {}, ["inventory"] = {}}, ["y"] = 3, ["z"] = 5, ["name"] = "darkage:desert_stone_with_iron"}, {["x"] = 8, ["meta"] = {["fields"] = {}, ["inventory"] = {}}, ["y"] = 3, ["z"] = 6, ["name"] = "default:stone"}, {["x"] = 8, ["meta"] = {["fields"] = {}, ["inventory"] = {}}, ["y"] = 3, ["z"] = 7, ["name"] = "default:stone"}, {["x"] = 8, ["meta"] = {["fields"] = {}, ["inventory"] = {}}, ["y"] = 3, ["z"] = 8, ["name"] = "default:stone"}, {["x"] = 8, ["meta"] = {["fields"] = {}, ["inventory"] = {}}, ["y"] = 3, ["z"] = 9, ["name"] = "default:stone"}, {["x"] = 8, ["meta"] = {["fields"] = {}, ["inventory"] = {}}, ["y"] = 3, ["z"] = 12, ["name"] = "default:stone"}, {["x"] = 8, ["meta"] = {["fields"] = {}, ["inventory"] = {}}, ["y"] = 3, ["z"] = 13, ["name"] = "default:stone"}, {["x"] = 8, ["meta"] = {["fields"] = {}, ["inventory"] = {}}, ["y"] = 3, ["z"] = 14, ["name"] = "default:stone"}, {["x"] = 8, ["meta"] = {["fields"] = {}, ["inventory"] = {}}, ["y"] = 3, ["z"] = 15, ["name"] = "default:stone"}, {["x"] = 8, ["meta"] = {["fields"] = {}, ["inventory"] = {}}, ["y"] = 3, ["z"] = 16, ["name"] = "darkage:desert_stone_with_iron"}, {["x"] = 8, ["meta"] = {["fields"] = {}, ["inventory"] = {}}, ["y"] = 4, ["z"] = 5, ["name"] = "darkage:desert_stone_with_iron"}, {["x"] = 8, ["meta"] = {["fields"] = {["infotext"] = "One-drawer Nightstand", ["formspec"] = "size[8,6]bgcolor[#080808BB;true]background[5,5;1,1;gui_formbg.png;true]listcolors[#00000069;#5A5A5A;#141318;#30434C;#FFF]list[context;main;0,0;8,1;]list[current_player;main;0,2;8,4;]"}, ["inventory"] = {["main"] = {"", "", "", "", "", "", "", ""}}}, ["param2"] = 2, ["y"] = 4, ["param1"] = 187, ["z"] = 6, ["name"] = "homedecor:nightstand_oak_one_drawer"}, {["x"] = 8, ["meta"] = {["fields"] = {["infotext"] = "Two-drawer Nightstand", ["formspec"] = "size[8,7]bgcolor[#080808BB;true]background[5,5;1,1;gui_formbg.png;true]listcolors[#00000069;#5A5A5A;#141318;#30434C;#FFF]list[context;main;0,0;8,2;]list[current_player;main;0,3;8,4;]"}, ["inventory"] = {["main"] = {"", "", "", "", "", "", "", "", "", "", "", "", "", "", "", ""}}}, ["y"] = 4, ["param1"] = 187, ["z"] = 15, ["name"] = "homedecor:nightstand_oak_two_drawers"}, {["x"] = 8, ["meta"] = {["fields"] = {}, ["inventory"] = {}}, ["y"] = 4, ["z"] = 16, ["name"] = "darkage:desert_stone_with_iron"}, {["x"] = 8, ["meta"] = {["fields"] = {}, ["inventory"] = {}}, ["y"] = 5, ["z"] = 5, ["name"] = "darkage:desert_stone_with_iron"}, {["x"] = 8, ["meta"] = {["fields"] = {}, ["inventory"] = {}}, ["param2"] = 2, ["y"] = 5, ["param1"] = 204, ["z"] = 6, ["name"] = "homedecor:table_lamp_red_off"}, {["x"] = 8, ["meta"] = {["fields"] = {}, ["inventory"] = {}}, ["y"] = 5, ["z"] = 16, ["name"] = "darkage:desert_stone_with_iron"}, {["x"] = 8, ["meta"] = {["fields"] = {}, ["inventory"] = {}}, ["y"] = 6, ["z"] = 5, ["name"] = "darkage:desert_stone_with_iron"}, {["x"] = 8, ["meta"] = {["fields"] = {}, ["inventory"] = {}}, ["param2"] = 5, ["y"] = 6, ["z"] = 6, ["name"] = "default:torch"}, {["x"] = 8, ["meta"] = {["fields"] = {}, ["inventory"] = {}}, ["param2"] = 4, ["y"] = 6, ["z"] = 15, ["name"] = "default:torch"}, {["x"] = 8, ["meta"] = {["fields"] = {}, ["inventory"] = {}}, ["y"] = 6, ["z"] = 16, ["name"] = "darkage:desert_stone_with_iron"}, {["x"] = 8, ["meta"] = {["fields"] = {}, ["inventory"] = {}}, ["y"] = 7, ["z"] = 5, ["name"] = "darkage:desert_stone_with_iron"}, {["x"] = 8, ["meta"] = {["fields"] = {}, ["inventory"] = {}}, ["y"] = 7, ["z"] = 6, ["name"] = "default:stone"}, {["x"] = 8, ["meta"] = {["fields"] = {}, ["inventory"] = {}}, ["y"] = 7, ["z"] = 7, ["name"] = "default:stone"}, {["x"] = 8, ["meta"] = {["fields"] = {}, ["inventory"] = {}}, ["y"] = 7, ["z"] = 8, ["name"] = "default:stone"}, {["x"] = 8, ["meta"] = {["fields"] = {}, ["inventory"] = {}}, ["y"] = 7, ["z"] = 9, ["name"] = "default:stone"}, {["x"] = 8, ["meta"] = {["fields"] = {}, ["inventory"] = {}}, ["param2"] = 3, ["y"] = 7, ["param1"] = 138, ["z"] = 10, ["name"] = "stairs:stair_stone"}, {["x"] = 8, ["meta"] = {["fields"] = {}, ["inventory"] = {}}, ["param2"] = 3, ["y"] = 7, ["param1"] = 138, ["z"] = 11, ["name"] = "stairs:stair_stone"}, {["x"] = 8, ["meta"] = {["fields"] = {}, ["inventory"] = {}}, ["y"] = 7, ["z"] = 12, ["name"] = "default:stone"}, {["x"] = 8, ["meta"] = {["fields"] = {}, ["inventory"] = {}}, ["y"] = 7, ["z"] = 13, ["name"] = "default:stone"}, {["x"] = 8, ["meta"] = {["fields"] = {}, ["inventory"] = {}}, ["y"] = 7, ["z"] = 14, ["name"] = "default:stone"}, {["x"] = 8, ["meta"] = {["fields"] = {}, ["inventory"] = {}}, ["y"] = 7, ["z"] = 15, ["name"] = "default:stone"}, {["x"] = 8, ["meta"] = {["fields"] = {}, ["inventory"] = {}}, ["y"] = 7, ["z"] = 16, ["name"] = "darkage:desert_stone_with_iron"}, {["x"] = 8, ["meta"] = {["fields"] = {}, ["inventory"] = {}}, ["y"] = 8, ["z"] = 5, ["name"] = "darkage:desert_stone_with_iron"}, {["x"] = 8, ["meta"] = {["fields"] = {}, ["inventory"] = {}}, ["y"] = 8, ["z"] = 6, ["name"] = "default:dirt_with_grass"}, {["x"] = 8, ["meta"] = {["fields"] = {}, ["inventory"] = {}}, ["y"] = 8, ["z"] = 7, ["name"] = "default:dirt_with_grass"}, {["x"] = 8, ["meta"] = {["fields"] = {}, ["inventory"] = {}}, ["y"] = 8, ["z"] = 8, ["name"] = "default:dirt_with_grass"}, {["x"] = 8, ["meta"] = {["fields"] = {}, ["inventory"] = {}}, ["y"] = 8, ["z"] = 9, ["name"] = "default:dirt_with_grass"}, {["x"] = 8, ["meta"] = {["fields"] = {}, ["inventory"] = {}}, ["y"] = 8, ["z"] = 12, ["name"] = "default:dirt_with_grass"}, {["x"] = 8, ["meta"] = {["fields"] = {}, ["inventory"] = {}}, ["y"] = 8, ["z"] = 13, ["name"] = "default:dirt_with_grass"}, {["x"] = 8, ["meta"] = {["fields"] = {}, ["inventory"] = {}}, ["y"] = 8, ["z"] = 14, ["name"] = "default:dirt_with_grass"}, {["x"] = 8, ["meta"] = {["fields"] = {}, ["inventory"] = {}}, ["y"] = 8, ["z"] = 15, ["name"] = "default:dirt_with_grass"}, {["x"] = 8, ["meta"] = {["fields"] = {}, ["inventory"] = {}}, ["y"] = 8, ["z"] = 16, ["name"] = "darkage:desert_stone_with_iron"}, {["x"] = 8, ["meta"] = {["fields"] = {}, ["inventory"] = {}}, ["y"] = 9, ["z"] = 4, ["name"] = "darkage:desert_stone_with_iron"}, {["x"] = 8, ["meta"] = {["fields"] = {}, ["inventory"] = {}}, ["y"] = 9, ["z"] = 5, ["name"] = "darkage:desert_stone_with_iron"}, {["x"] = 8, ["meta"] = {["fields"] = {}, ["inventory"] = {}}, ["y"] = 9, ["param1"] = 140, ["z"] = 6, ["name"] = "default:junglegrass"}, {["x"] = 8, ["meta"] = {["fields"] = {}, ["inventory"] = {}}, ["y"] = 9, ["param1"] = 140, ["z"] = 15, ["name"] = "default:junglegrass"}, {["x"] = 8, ["meta"] = {["fields"] = {}, ["inventory"] = {}}, ["y"] = 9, ["z"] = 16, ["name"] = "darkage:desert_stone_with_iron"}, {["x"] = 8, ["meta"] = {["fields"] = {}, ["inventory"] = {}}, ["y"] = 9, ["z"] = 17, ["name"] = "darkage:desert_stone_with_iron"}, {["x"] = 8, ["meta"] = {["fields"] = {}, ["inventory"] = {}}, ["y"] = 10, ["z"] = 4, ["name"] = "darkage:desert_stone_with_iron"}, {["x"] = 8, ["meta"] = {["fields"] = {}, ["inventory"] = {}}, ["y"] = 10, ["z"] = 17, ["name"] = "darkage:desert_stone_with_iron"}, {["x"] = 8, ["meta"] = {["fields"] = {}, ["inventory"] = {}}, ["param2"] = 2, ["y"] = 21, ["z"] = 10, ["name"] = "default:torch"}, {["x"] = 8, ["meta"] = {["fields"] = {}, ["inventory"] = {}}, ["param2"] = 2, ["y"] = 21, ["z"] = 11, ["name"] = "default:torch"}, {["x"] = 8, ["meta"] = {["fields"] = {}, ["inventory"] = {}}, ["param2"] = 4, ["y"] = 22, ["z"] = 9, ["name"] = "default:torch"}, {["x"] = 8, ["meta"] = {["fields"] = {}, ["inventory"] = {}}, ["y"] = 22, ["z"] = 10, ["name"] = "wool:green"}, {["x"] = 8, ["meta"] = {["fields"] = {}, ["inventory"] = {}}, ["y"] = 22, ["z"] = 11, ["name"] = "wool:green"}, {["x"] = 8, ["meta"] = {["fields"] = {}, ["inventory"] = {}}, ["param2"] = 5, ["y"] = 22, ["z"] = 12, ["name"] = "default:torch"}, {["x"] = 8, ["meta"] = {["fields"] = {}, ["inventory"] = {}}, ["param2"] = 2, ["y"] = 27, ["param1"] = 15, ["z"] = 0, ["name"] = "default:torch"}, {["x"] = 8, ["meta"] = {["fields"] = {}, ["inventory"] = {}}, ["y"] = 27, ["z"] = 1, ["name"] = "wool:green"}, {["x"] = 8, ["meta"] = {["fields"] = {}, ["inventory"] = {}}, ["y"] = 27, ["z"] = 2, ["name"] = "wool:green"}, {["x"] = 8, ["meta"] = {["fields"] = {}, ["inventory"] = {}}, ["y"] = 27, ["z"] = 3, ["name"] = "wool:green"}, {["x"] = 8, ["meta"] = {["fields"] = {}, ["inventory"] = {}}, ["y"] = 27, ["z"] = 4, ["name"] = "wool:green"}, {["x"] = 8, ["meta"] = {["fields"] = {}, ["inventory"] = {}}, ["y"] = 27, ["z"] = 5, ["name"] = "wool:green"}, {["x"] = 8, ["meta"] = {["fields"] = {}, ["inventory"] = {}}, ["y"] = 27, ["z"] = 6, ["name"] = "wool:green"}, {["x"] = 8, ["meta"] = {["fields"] = {}, ["inventory"] = {}}, ["y"] = 27, ["z"] = 7, ["name"] = "wool:green"}, {["x"] = 8, ["meta"] = {["fields"] = {}, ["inventory"] = {}}, ["param2"] = 2, ["y"] = 27, ["param1"] = 15, ["z"] = 8, ["name"] = "default:torch"}, {["x"] = 8, ["meta"] = {["fields"] = {}, ["inventory"] = {}}, ["param2"] = 2, ["y"] = 27, ["z"] = 9, ["name"] = "default:torch"}, {["x"] = 8, ["meta"] = {["fields"] = {}, ["inventory"] = {}}, ["param2"] = 2, ["y"] = 27, ["z"] = 12, ["name"] = "default:torch"}, {["x"] = 8, ["meta"] = {["fields"] = {}, ["inventory"] = {}}, ["param2"] = 2, ["y"] = 27, ["param1"] = 15, ["z"] = 13, ["name"] = "default:torch"}, {["x"] = 8, ["meta"] = {["fields"] = {}, ["inventory"] = {}}, ["y"] = 27, ["z"] = 14, ["name"] = "wool:green"}, {["x"] = 8, ["meta"] = {["fields"] = {}, ["inventory"] = {}}, ["y"] = 27, ["z"] = 15, ["name"] = "wool:green"}, {["x"] = 8, ["meta"] = {["fields"] = {}, ["inventory"] = {}}, ["y"] = 27, ["z"] = 16, ["name"] = "wool:green"}, {["x"] = 8, ["meta"] = {["fields"] = {}, ["inventory"] = {}}, ["y"] = 27, ["z"] = 17, ["name"] = "wool:green"}, {["x"] = 8, ["meta"] = {["fields"] = {}, ["inventory"] = {}}, ["y"] = 27, ["z"] = 18, ["name"] = "wool:green"}, {["x"] = 8, ["meta"] = {["fields"] = {}, ["inventory"] = {}}, ["y"] = 27, ["z"] = 19, ["name"] = "wool:green"}, {["x"] = 8, ["meta"] = {["fields"] = {}, ["inventory"] = {}}, ["y"] = 27, ["z"] = 20, ["name"] = "wool:green"}, {["x"] = 8, ["meta"] = {["fields"] = {}, ["inventory"] = {}}, ["y"] = 33, ["z"] = 9, ["name"] = "default:torch"}, {["x"] = 8, ["meta"] = {["fields"] = {}, ["inventory"] = {}}, ["y"] = 33, ["z"] = 10, ["name"] = "wool:dark_green"}, {["x"] = 8, ["meta"] = {["fields"] = {}, ["inventory"] = {}}, ["y"] = 33, ["z"] = 11, ["name"] = "wool:dark_green"}, {["x"] = 8, ["meta"] = {["fields"] = {}, ["inventory"] = {}}, ["y"] = 33, ["z"] = 12, ["name"] = "default:torch"}, {["x"] = 8, ["meta"] = {["fields"] = {}, ["inventory"] = {}}, ["param2"] = 2, ["y"] = 34, ["param1"] = 15, ["z"] = 1, ["name"] = "default:torch"}, {["x"] = 8, ["meta"] = {["fields"] = {}, ["inventory"] = {}}, ["y"] = 34, ["z"] = 2, ["name"] = "wool:white"}, {["x"] = 8, ["meta"] = {["fields"] = {}, ["inventory"] = {}}, ["y"] = 34, ["z"] = 3, ["name"] = "wool:white"}, {["x"] = 8, ["meta"] = {["fields"] = {}, ["inventory"] = {}}, ["y"] = 34, ["z"] = 4, ["name"] = "wool:white"}, {["x"] = 8, ["meta"] = {["fields"] = {}, ["inventory"] = {}}, ["y"] = 34, ["z"] = 5, ["name"] = "wool:white"}, {["x"] = 8, ["meta"] = {["fields"] = {}, ["inventory"] = {}}, ["y"] = 34, ["z"] = 6, ["name"] = "wool:white"}, {["x"] = 8, ["meta"] = {["fields"] = {}, ["inventory"] = {}}, ["param2"] = 2, ["y"] = 34, ["param1"] = 15, ["z"] = 7, ["name"] = "default:torch"}, {["x"] = 8, ["meta"] = {["fields"] = {}, ["inventory"] = {}}, ["param2"] = 2, ["y"] = 34, ["param1"] = 15, ["z"] = 8, ["name"] = "default:torch"}, {["x"] = 8, ["meta"] = {["fields"] = {}, ["inventory"] = {}}, ["y"] = 34, ["z"] = 9, ["name"] = "wool:yellow"}, {["x"] = 8, ["meta"] = {["fields"] = {}, ["inventory"] = {}}, ["y"] = 34, ["z"] = 10, ["name"] = "wool:yellow"}, {["x"] = 8, ["meta"] = {["fields"] = {}, ["inventory"] = {}}, ["y"] = 34, ["z"] = 11, ["name"] = "wool:yellow"}, {["x"] = 8, ["meta"] = {["fields"] = {}, ["inventory"] = {}}, ["y"] = 34, ["z"] = 12, ["name"] = "wool:yellow"}, {["x"] = 8, ["meta"] = {["fields"] = {}, ["inventory"] = {}}, ["param2"] = 2, ["y"] = 34, ["param1"] = 15, ["z"] = 13, ["name"] = "default:torch"}, {["x"] = 8, ["meta"] = {["fields"] = {}, ["inventory"] = {}}, ["param2"] = 2, ["y"] = 34, ["param1"] = 15, ["z"] = 14, ["name"] = "default:torch"}, {["x"] = 8, ["meta"] = {["fields"] = {}, ["inventory"] = {}}, ["y"] = 34, ["z"] = 15, ["name"] = "wool:white"}, {["x"] = 8, ["meta"] = {["fields"] = {}, ["inventory"] = {}}, ["y"] = 34, ["z"] = 16, ["name"] = "wool:white"}, {["x"] = 8, ["meta"] = {["fields"] = {}, ["inventory"] = {}}, ["y"] = 34, ["z"] = 17, ["name"] = "wool:white"}, {["x"] = 8, ["meta"] = {["fields"] = {}, ["inventory"] = {}}, ["y"] = 34, ["z"] = 18, ["name"] = "wool:white"}, {["x"] = 8, ["meta"] = {["fields"] = {}, ["inventory"] = {}}, ["y"] = 34, ["z"] = 19, ["name"] = "wool:white"}, {["x"] = 8, ["meta"] = {["fields"] = {}, ["inventory"] = {}}, ["param2"] = 2, ["y"] = 34, ["param1"] = 15, ["z"] = 20, ["name"] = "default:torch"}, {["x"] = 9, ["meta"] = {["fields"] = {}, ["inventory"] = {}}, ["y"] = 0, ["z"] = 5, ["name"] = "darkage:desert_stone_with_iron"}, {["x"] = 9, ["meta"] = {["fields"] = {["infotext"] = "Kitchen Cabinet", ["formspec"] = "size[8,8]bgcolor[#080808BB;true]background[5,5;1,1;gui_formbg.png;true]listcolors[#00000069;#5A5A5A;#141318;#30434C;#FFF]list[context;main;0,0;8,3;]list[current_player;main;0,4;8,4;]"}, ["inventory"] = {["main"] = {"", "", "", "", "", "", "", "", "", "", "", "", "", "", "", "", "", "", "", "", "", "", "", ""}}}, ["param2"] = 2, ["y"] = 0, ["param1"] = 170, ["z"] = 6, ["name"] = "homedecor:kitchen_cabinet_marble"}, {["x"] = 9, ["meta"] = {["fields"] = {}, ["inventory"] = {}}, ["y"] = 0, ["z"] = 10, ["name"] = "default:stone"}, {["x"] = 9, ["meta"] = {["fields"] = {}, ["inventory"] = {}}, ["y"] = 0, ["z"] = 11, ["name"] = "default:stone"}, {["x"] = 9, ["meta"] = {["fields"] = {}, ["inventory"] = {}}, ["y"] = 0, ["param1"] = 170, ["z"] = 15, ["name"] = "homedecor:table"}, {["x"] = 9, ["meta"] = {["fields"] = {}, ["inventory"] = {}}, ["y"] = 0, ["z"] = 16, ["name"] = "darkage:desert_stone_with_iron"}, {["x"] = 9, ["meta"] = {["fields"] = {}, ["inventory"] = {}}, ["y"] = 1, ["param1"] = 170, ["z"] = 5, ["name"] = "building_blocks:woodglass"}, {["x"] = 9, ["meta"] = {["fields"] = {}, ["inventory"] = {}}, ["param2"] = 3, ["y"] = 1, ["param1"] = 170, ["z"] = 10, ["name"] = "stairs:stair_stone"}, {["x"] = 9, ["meta"] = {["fields"] = {}, ["inventory"] = {}}, ["param2"] = 3, ["y"] = 1, ["param1"] = 170, ["z"] = 11, ["name"] = "stairs:stair_stone"}, {["x"] = 9, ["meta"] = {["fields"] = {}, ["inventory"] = {}}, ["y"] = 1, ["param1"] = 187, ["z"] = 15, ["name"] = "computer:printer"}, {["x"] = 9, ["meta"] = {["fields"] = {}, ["inventory"] = {}}, ["y"] = 1, ["param1"] = 170, ["z"] = 16, ["name"] = "building_blocks:woodglass"}, {["x"] = 9, ["meta"] = {["fields"] = {}, ["inventory"] = {}}, ["y"] = 2, ["z"] = 5, ["name"] = "darkage:desert_stone_with_iron"}, {["x"] = 9, ["meta"] = {["fields"] = {}, ["inventory"] = {}}, ["y"] = 2, ["z"] = 16, ["name"] = "darkage:desert_stone_with_iron"}, {["x"] = 9, ["meta"] = {["fields"] = {}, ["inventory"] = {}}, ["y"] = 3, ["z"] = 5, ["name"] = "darkage:desert_stone_with_iron"}, {["x"] = 9, ["meta"] = {["fields"] = {}, ["inventory"] = {}}, ["y"] = 3, ["z"] = 6, ["name"] = "default:stone"}, {["x"] = 9, ["meta"] = {["fields"] = {}, ["inventory"] = {}}, ["y"] = 3, ["z"] = 7, ["name"] = "default:stone"}, {["x"] = 9, ["meta"] = {["fields"] = {}, ["inventory"] = {}}, ["y"] = 3, ["z"] = 8, ["name"] = "default:stone"}, {["x"] = 9, ["meta"] = {["fields"] = {}, ["inventory"] = {}}, ["y"] = 3, ["z"] = 9, ["name"] = "default:stone"}, {["x"] = 9, ["meta"] = {["fields"] = {}, ["inventory"] = {}}, ["y"] = 3, ["z"] = 12, ["name"] = "default:stone"}, {["x"] = 9, ["meta"] = {["fields"] = {}, ["inventory"] = {}}, ["y"] = 3, ["z"] = 13, ["name"] = "default:stone"}, {["x"] = 9, ["meta"] = {["fields"] = {}, ["inventory"] = {}}, ["y"] = 3, ["z"] = 14, ["name"] = "default:stone"}, {["x"] = 9, ["meta"] = {["fields"] = {}, ["inventory"] = {}}, ["y"] = 3, ["z"] = 15, ["name"] = "default:stone"}, {["x"] = 9, ["meta"] = {["fields"] = {}, ["inventory"] = {}}, ["y"] = 3, ["z"] = 16, ["name"] = "darkage:desert_stone_with_iron"}, {["x"] = 9, ["meta"] = {["fields"] = {}, ["inventory"] = {}}, ["y"] = 4, ["z"] = 5, ["name"] = "darkage:desert_stone_with_iron"}, {["x"] = 9, ["meta"] = {["fields"] = {}, ["inventory"] = {}}, ["y"] = 4, ["param1"] = 170, ["z"] = 15, ["name"] = "homedecor:sink"}, {["x"] = 9, ["meta"] = {["fields"] = {}, ["inventory"] = {}}, ["y"] = 4, ["z"] = 16, ["name"] = "darkage:desert_stone_with_iron"}, {["x"] = 9, ["meta"] = {["fields"] = {}, ["inventory"] = {}}, ["y"] = 5, ["param1"] = 170, ["z"] = 5, ["name"] = "building_blocks:woodglass"}, {["x"] = 9, ["meta"] = {["fields"] = {}, ["inventory"] = {}}, ["y"] = 5, ["param1"] = 170, ["z"] = 16, ["name"] = "building_blocks:woodglass"}, {["x"] = 9, ["meta"] = {["fields"] = {}, ["inventory"] = {}}, ["y"] = 6, ["z"] = 5, ["name"] = "darkage:desert_stone_with_iron"}, {["x"] = 9, ["meta"] = {["fields"] = {}, ["inventory"] = {}}, ["param2"] = 3, ["y"] = 6, ["param1"] = 136, ["z"] = 10, ["name"] = "stairs:stair_stone"}, {["x"] = 9, ["meta"] = {["fields"] = {}, ["inventory"] = {}}, ["param2"] = 3, ["y"] = 6, ["param1"] = 136, ["z"] = 11, ["name"] = "stairs:stair_stone"}, {["x"] = 9, ["meta"] = {["fields"] = {}, ["inventory"] = {}}, ["y"] = 6, ["z"] = 16, ["name"] = "darkage:desert_stone_with_iron"}, {["x"] = 9, ["meta"] = {["fields"] = {}, ["inventory"] = {}}, ["y"] = 7, ["z"] = 5, ["name"] = "darkage:desert_stone_with_iron"}, {["x"] = 9, ["meta"] = {["fields"] = {}, ["inventory"] = {}}, ["y"] = 7, ["z"] = 6, ["name"] = "default:stone"}, {["x"] = 9, ["meta"] = {["fields"] = {}, ["inventory"] = {}}, ["y"] = 7, ["z"] = 7, ["name"] = "default:stone"}, {["x"] = 9, ["meta"] = {["fields"] = {}, ["inventory"] = {}}, ["y"] = 7, ["z"] = 8, ["name"] = "default:stone"}, {["x"] = 9, ["meta"] = {["fields"] = {}, ["inventory"] = {}}, ["y"] = 7, ["z"] = 9, ["name"] = "default:stone"}, {["x"] = 9, ["meta"] = {["fields"] = {}, ["inventory"] = {}}, ["y"] = 7, ["z"] = 12, ["name"] = "default:stone"}, {["x"] = 9, ["meta"] = {["fields"] = {}, ["inventory"] = {}}, ["y"] = 7, ["z"] = 13, ["name"] = "default:stone"}, {["x"] = 9, ["meta"] = {["fields"] = {}, ["inventory"] = {}}, ["y"] = 7, ["z"] = 14, ["name"] = "default:stone"}, {["x"] = 9, ["meta"] = {["fields"] = {}, ["inventory"] = {}}, ["y"] = 7, ["z"] = 15, ["name"] = "default:stone"}, {["x"] = 9, ["meta"] = {["fields"] = {}, ["inventory"] = {}}, ["y"] = 7, ["z"] = 16, ["name"] = "darkage:desert_stone_with_iron"}, {["x"] = 9, ["meta"] = {["fields"] = {}, ["inventory"] = {}}, ["y"] = 8, ["z"] = 5, ["name"] = "darkage:desert_stone_with_iron"}, {["x"] = 9, ["meta"] = {["fields"] = {}, ["inventory"] = {}}, ["y"] = 8, ["z"] = 6, ["name"] = "default:dirt"}, {["x"] = 9, ["meta"] = {["fields"] = {}, ["inventory"] = {}}, ["y"] = 8, ["z"] = 7, ["name"] = "default:dirt_with_grass"}, {["x"] = 9, ["meta"] = {["fields"] = {}, ["inventory"] = {}}, ["y"] = 8, ["z"] = 8, ["name"] = "default:dirt_with_grass"}, {["x"] = 9, ["meta"] = {["fields"] = {}, ["inventory"] = {}}, ["y"] = 8, ["z"] = 9, ["name"] = "default:dirt_with_grass"}, {["x"] = 9, ["meta"] = {["fields"] = {}, ["inventory"] = {}}, ["y"] = 8, ["z"] = 12, ["name"] = "default:dirt_with_grass"}, {["x"] = 9, ["meta"] = {["fields"] = {}, ["inventory"] = {}}, ["y"] = 8, ["z"] = 13, ["name"] = "default:dirt_with_grass"}, {["x"] = 9, ["meta"] = {["fields"] = {}, ["inventory"] = {}}, ["y"] = 8, ["z"] = 14, ["name"] = "default:dirt_with_grass"}, {["x"] = 9, ["meta"] = {["fields"] = {}, ["inventory"] = {}}, ["y"] = 8, ["z"] = 15, ["name"] = "default:dirt_with_grass"}, {["x"] = 9, ["meta"] = {["fields"] = {}, ["inventory"] = {}}, ["y"] = 8, ["z"] = 16, ["name"] = "darkage:desert_stone_with_iron"}, {["x"] = 9, ["meta"] = {["fields"] = {}, ["inventory"] = {}}, ["y"] = 9, ["z"] = 4, ["name"] = "darkage:desert_stone_with_iron"}, {["x"] = 9, ["meta"] = {["fields"] = {}, ["inventory"] = {}}, ["y"] = 9, ["z"] = 5, ["name"] = "darkage:desert_stone_with_iron"}, {["x"] = 9, ["meta"] = {["fields"] = {}, ["inventory"] = {}}, ["y"] = 9, ["param1"] = 155, ["z"] = 6, ["name"] = "homedecor:expansion_placeholder"}, {["x"] = 9, ["meta"] = {["fields"] = {}, ["inventory"] = {}}, ["param2"] = 2, ["y"] = 9, ["param1"] = 172, ["z"] = 7, ["name"] = "homedecor:deckchair"}, {["x"] = 9, ["meta"] = {["fields"] = {}, ["inventory"] = {}}, ["y"] = 9, ["param1"] = 172, ["z"] = 14, ["name"] = "homedecor:deckchair"}, {["x"] = 9, ["meta"] = {["fields"] = {}, ["inventory"] = {}}, ["y"] = 9, ["param1"] = 155, ["z"] = 15, ["name"] = "homedecor:expansion_placeholder"}, {["x"] = 9, ["meta"] = {["fields"] = {}, ["inventory"] = {}}, ["y"] = 9, ["z"] = 16, ["name"] = "darkage:desert_stone_with_iron"}, {["x"] = 9, ["meta"] = {["fields"] = {}, ["inventory"] = {}}, ["y"] = 9, ["z"] = 17, ["name"] = "darkage:desert_stone_with_iron"}, {["x"] = 9, ["meta"] = {["fields"] = {}, ["inventory"] = {}}, ["y"] = 10, ["z"] = 4, ["name"] = "darkage:desert_stone_with_iron"}, {["x"] = 9, ["meta"] = {["fields"] = {}, ["inventory"] = {}}, ["y"] = 10, ["z"] = 10, ["name"] = "wool:dark_green"}, {["x"] = 9, ["meta"] = {["fields"] = {}, ["inventory"] = {}}, ["y"] = 10, ["z"] = 11, ["name"] = "wool:dark_green"}, {["x"] = 9, ["meta"] = {["fields"] = {}, ["inventory"] = {}}, ["y"] = 10, ["z"] = 17, ["name"] = "darkage:desert_stone_with_iron"}, {["x"] = 9, ["meta"] = {["fields"] = {}, ["inventory"] = {}}, ["y"] = 11, ["z"] = 10, ["name"] = "wool:dark_green"}, {["x"] = 9, ["meta"] = {["fields"] = {}, ["inventory"] = {}}, ["y"] = 11, ["z"] = 11, ["name"] = "wool:dark_green"}, {["x"] = 9, ["meta"] = {["fields"] = {}, ["inventory"] = {}}, ["y"] = 12, ["z"] = 10, ["name"] = "wool:dark_green"}, {["x"] = 9, ["meta"] = {["fields"] = {}, ["inventory"] = {}}, ["y"] = 12, ["z"] = 11, ["name"] = "wool:dark_green"}, {["x"] = 9, ["meta"] = {["fields"] = {}, ["inventory"] = {}}, ["y"] = 13, ["z"] = 10, ["name"] = "wool:dark_green"}, {["x"] = 9, ["meta"] = {["fields"] = {}, ["inventory"] = {}}, ["y"] = 13, ["z"] = 11, ["name"] = "wool:dark_green"}, {["x"] = 9, ["meta"] = {["fields"] = {}, ["inventory"] = {}}, ["y"] = 14, ["z"] = 10, ["name"] = "wool:dark_green"}, {["x"] = 9, ["meta"] = {["fields"] = {}, ["inventory"] = {}}, ["y"] = 14, ["z"] = 11, ["name"] = "wool:dark_green"}, {["x"] = 9, ["meta"] = {["fields"] = {}, ["inventory"] = {}}, ["y"] = 15, ["z"] = 10, ["name"] = "wool:dark_green"}, {["x"] = 9, ["meta"] = {["fields"] = {}, ["inventory"] = {}}, ["y"] = 15, ["z"] = 11, ["name"] = "wool:dark_green"}, {["x"] = 9, ["meta"] = {["fields"] = {}, ["inventory"] = {}}, ["y"] = 16, ["z"] = 10, ["name"] = "wool:dark_green"}, {["x"] = 9, ["meta"] = {["fields"] = {}, ["inventory"] = {}}, ["y"] = 16, ["z"] = 11, ["name"] = "wool:dark_green"}, {["x"] = 9, ["meta"] = {["fields"] = {}, ["inventory"] = {}}, ["y"] = 17, ["z"] = 10, ["name"] = "wool:dark_green"}, {["x"] = 9, ["meta"] = {["fields"] = {}, ["inventory"] = {}}, ["y"] = 17, ["z"] = 11, ["name"] = "wool:dark_green"}, {["x"] = 9, ["meta"] = {["fields"] = {}, ["inventory"] = {}}, ["y"] = 18, ["z"] = 10, ["name"] = "wool:dark_green"}, {["x"] = 9, ["meta"] = {["fields"] = {}, ["inventory"] = {}}, ["y"] = 18, ["z"] = 11, ["name"] = "wool:dark_green"}, {["x"] = 9, ["meta"] = {["fields"] = {}, ["inventory"] = {}}, ["y"] = 19, ["z"] = 10, ["name"] = "wool:dark_green"}, {["x"] = 9, ["meta"] = {["fields"] = {}, ["inventory"] = {}}, ["y"] = 19, ["z"] = 11, ["name"] = "wool:dark_green"}, {["x"] = 9, ["meta"] = {["fields"] = {}, ["inventory"] = {}}, ["y"] = 20, ["z"] = 10, ["name"] = "wool:dark_green"}, {["x"] = 9, ["meta"] = {["fields"] = {}, ["inventory"] = {}}, ["y"] = 20, ["z"] = 11, ["name"] = "wool:dark_green"}, {["x"] = 9, ["meta"] = {["fields"] = {}, ["inventory"] = {}}, ["y"] = 21, ["z"] = 10, ["name"] = "wool:dark_green"}, {["x"] = 9, ["meta"] = {["fields"] = {}, ["inventory"] = {}}, ["y"] = 21, ["z"] = 11, ["name"] = "wool:dark_green"}, {["x"] = 9, ["meta"] = {["fields"] = {}, ["inventory"] = {}}, ["y"] = 22, ["z"] = 10, ["name"] = "wool:dark_green"}, {["x"] = 9, ["meta"] = {["fields"] = {}, ["inventory"] = {}}, ["y"] = 22, ["z"] = 11, ["name"] = "wool:dark_green"}, {["x"] = 9, ["meta"] = {["fields"] = {}, ["inventory"] = {}}, ["y"] = 23, ["z"] = 10, ["name"] = "wool:dark_green"}, {["x"] = 9, ["meta"] = {["fields"] = {}, ["inventory"] = {}}, ["y"] = 23, ["z"] = 11, ["name"] = "wool:dark_green"}, {["x"] = 9, ["meta"] = {["fields"] = {}, ["inventory"] = {}}, ["y"] = 24, ["z"] = 10, ["name"] = "wool:dark_green"}, {["x"] = 9, ["meta"] = {["fields"] = {}, ["inventory"] = {}}, ["y"] = 24, ["z"] = 11, ["name"] = "wool:dark_green"}, {["x"] = 9, ["meta"] = {["fields"] = {}, ["inventory"] = {}}, ["y"] = 25, ["z"] = 10, ["name"] = "wool:dark_green"}, {["x"] = 9, ["meta"] = {["fields"] = {}, ["inventory"] = {}}, ["y"] = 25, ["z"] = 11, ["name"] = "wool:dark_green"}, {["x"] = 9, ["meta"] = {["fields"] = {}, ["inventory"] = {}}, ["param2"] = 4, ["y"] = 26, ["z"] = 9, ["name"] = "default:torch"}, {["x"] = 9, ["meta"] = {["fields"] = {}, ["inventory"] = {}}, ["y"] = 26, ["z"] = 10, ["name"] = "wool:dark_green"}, {["x"] = 9, ["meta"] = {["fields"] = {}, ["inventory"] = {}}, ["y"] = 26, ["z"] = 11, ["name"] = "wool:dark_green"}, {["x"] = 9, ["meta"] = {["fields"] = {}, ["inventory"] = {}}, ["param2"] = 5, ["y"] = 26, ["z"] = 12, ["name"] = "default:torch"}, {["x"] = 9, ["meta"] = {["fields"] = {}, ["inventory"] = {}}, ["y"] = 27, ["z"] = 0, ["name"] = "wool:green"}, {["x"] = 9, ["meta"] = {["fields"] = {}, ["inventory"] = {}}, ["y"] = 27, ["z"] = 1, ["name"] = "wool:green"}, {["x"] = 9, ["meta"] = {["fields"] = {}, ["inventory"] = {}}, ["y"] = 27, ["z"] = 2, ["name"] = "wool:green"}, {["x"] = 9, ["meta"] = {["fields"] = {}, ["inventory"] = {}}, ["y"] = 27, ["z"] = 3, ["name"] = "wool:green"}, {["x"] = 9, ["meta"] = {["fields"] = {}, ["inventory"] = {}}, ["y"] = 27, ["z"] = 4, ["name"] = "wool:green"}, {["x"] = 9, ["meta"] = {["fields"] = {}, ["inventory"] = {}}, ["y"] = 27, ["z"] = 5, ["name"] = "wool:green"}, {["x"] = 9, ["meta"] = {["fields"] = {}, ["inventory"] = {}}, ["y"] = 27, ["z"] = 6, ["name"] = "wool:green"}, {["x"] = 9, ["meta"] = {["fields"] = {}, ["inventory"] = {}}, ["y"] = 27, ["z"] = 7, ["name"] = "wool:green"}, {["x"] = 9, ["meta"] = {["fields"] = {}, ["inventory"] = {}}, ["y"] = 27, ["z"] = 8, ["name"] = "wool:green"}, {["x"] = 9, ["meta"] = {["fields"] = {}, ["inventory"] = {}}, ["y"] = 27, ["z"] = 9, ["name"] = "wool:green"}, {["x"] = 9, ["meta"] = {["fields"] = {}, ["inventory"] = {}}, ["y"] = 27, ["z"] = 10, ["name"] = "wool:dark_green"}, {["x"] = 9, ["meta"] = {["fields"] = {}, ["inventory"] = {}}, ["y"] = 27, ["z"] = 11, ["name"] = "wool:dark_green"}, {["x"] = 9, ["meta"] = {["fields"] = {}, ["inventory"] = {}}, ["y"] = 27, ["z"] = 12, ["name"] = "wool:green"}, {["x"] = 9, ["meta"] = {["fields"] = {}, ["inventory"] = {}}, ["y"] = 27, ["z"] = 13, ["name"] = "wool:green"}, {["x"] = 9, ["meta"] = {["fields"] = {}, ["inventory"] = {}}, ["y"] = 27, ["z"] = 14, ["name"] = "wool:green"}, {["x"] = 9, ["meta"] = {["fields"] = {}, ["inventory"] = {}}, ["y"] = 27, ["z"] = 15, ["name"] = "wool:green"}, {["x"] = 9, ["meta"] = {["fields"] = {}, ["inventory"] = {}}, ["y"] = 27, ["z"] = 16, ["name"] = "wool:green"}, {["x"] = 9, ["meta"] = {["fields"] = {}, ["inventory"] = {}}, ["y"] = 27, ["z"] = 17, ["name"] = "wool:green"}, {["x"] = 9, ["meta"] = {["fields"] = {}, ["inventory"] = {}}, ["y"] = 27, ["z"] = 18, ["name"] = "wool:green"}, {["x"] = 9, ["meta"] = {["fields"] = {}, ["inventory"] = {}}, ["y"] = 27, ["z"] = 19, ["name"] = "wool:green"}, {["x"] = 9, ["meta"] = {["fields"] = {}, ["inventory"] = {}}, ["y"] = 27, ["z"] = 20, ["name"] = "wool:green"}, {["x"] = 9, ["meta"] = {["fields"] = {}, ["inventory"] = {}}, ["y"] = 28, ["z"] = 10, ["name"] = "wool:dark_green"}, {["x"] = 9, ["meta"] = {["fields"] = {}, ["inventory"] = {}}, ["y"] = 28, ["z"] = 11, ["name"] = "wool:dark_green"}, {["x"] = 9, ["meta"] = {["fields"] = {}, ["inventory"] = {}}, ["y"] = 29, ["z"] = 10, ["name"] = "wool:dark_green"}, {["x"] = 9, ["meta"] = {["fields"] = {}, ["inventory"] = {}}, ["y"] = 29, ["z"] = 11, ["name"] = "wool:dark_green"}, {["x"] = 9, ["meta"] = {["fields"] = {}, ["inventory"] = {}}, ["y"] = 30, ["z"] = 10, ["name"] = "wool:dark_green"}, {["x"] = 9, ["meta"] = {["fields"] = {}, ["inventory"] = {}}, ["y"] = 30, ["z"] = 11, ["name"] = "wool:dark_green"}, {["x"] = 9, ["meta"] = {["fields"] = {}, ["inventory"] = {}}, ["y"] = 31, ["z"] = 10, ["name"] = "wool:dark_green"}, {["x"] = 9, ["meta"] = {["fields"] = {}, ["inventory"] = {}}, ["y"] = 31, ["z"] = 11, ["name"] = "wool:dark_green"}, {["x"] = 9, ["meta"] = {["fields"] = {}, ["inventory"] = {}}, ["y"] = 32, ["z"] = 10, ["name"] = "wool:dark_green"}, {["x"] = 9, ["meta"] = {["fields"] = {}, ["inventory"] = {}}, ["y"] = 32, ["z"] = 11, ["name"] = "wool:dark_green"}, {["x"] = 9, ["meta"] = {["fields"] = {}, ["inventory"] = {}}, ["y"] = 33, ["z"] = 9, ["name"] = "wool:dark_green"}, {["x"] = 9, ["meta"] = {["fields"] = {}, ["inventory"] = {}}, ["y"] = 33, ["z"] = 10, ["name"] = "wool:dark_green"}, {["x"] = 9, ["meta"] = {["fields"] = {}, ["inventory"] = {}}, ["y"] = 33, ["z"] = 11, ["name"] = "wool:dark_green"}, {["x"] = 9, ["meta"] = {["fields"] = {}, ["inventory"] = {}}, ["y"] = 33, ["z"] = 12, ["name"] = "wool:dark_green"}, {["x"] = 9, ["meta"] = {["fields"] = {}, ["inventory"] = {}}, ["y"] = 34, ["z"] = 1, ["name"] = "wool:white"}, {["x"] = 9, ["meta"] = {["fields"] = {}, ["inventory"] = {}}, ["y"] = 34, ["z"] = 2, ["name"] = "wool:white"}, {["x"] = 9, ["meta"] = {["fields"] = {}, ["inventory"] = {}}, ["y"] = 34, ["z"] = 3, ["name"] = "wool:white"}, {["x"] = 9, ["meta"] = {["fields"] = {}, ["inventory"] = {}}, ["y"] = 34, ["z"] = 4, ["name"] = "wool:white"}, {["x"] = 9, ["meta"] = {["fields"] = {}, ["inventory"] = {}}, ["y"] = 34, ["z"] = 5, ["name"] = "wool:white"}, {["x"] = 9, ["meta"] = {["fields"] = {}, ["inventory"] = {}}, ["y"] = 34, ["z"] = 6, ["name"] = "wool:white"}, {["x"] = 9, ["meta"] = {["fields"] = {}, ["inventory"] = {}}, ["y"] = 34, ["z"] = 7, ["name"] = "wool:white"}, {["x"] = 9, ["meta"] = {["fields"] = {}, ["inventory"] = {}}, ["y"] = 34, ["z"] = 8, ["name"] = "wool:yellow"}, {["x"] = 9, ["meta"] = {["fields"] = {}, ["inventory"] = {}}, ["y"] = 34, ["z"] = 9, ["name"] = "wool:yellow"}, {["x"] = 9, ["meta"] = {["fields"] = {}, ["inventory"] = {}}, ["y"] = 34, ["z"] = 10, ["name"] = "wool:yellow"}, {["x"] = 9, ["meta"] = {["fields"] = {}, ["inventory"] = {}}, ["y"] = 34, ["z"] = 11, ["name"] = "wool:yellow"}, {["x"] = 9, ["meta"] = {["fields"] = {}, ["inventory"] = {}}, ["y"] = 34, ["z"] = 12, ["name"] = "wool:yellow"}, {["x"] = 9, ["meta"] = {["fields"] = {}, ["inventory"] = {}}, ["y"] = 34, ["z"] = 13, ["name"] = "wool:yellow"}, {["x"] = 9, ["meta"] = {["fields"] = {}, ["inventory"] = {}}, ["y"] = 34, ["z"] = 14, ["name"] = "wool:white"}, {["x"] = 9, ["meta"] = {["fields"] = {}, ["inventory"] = {}}, ["y"] = 34, ["z"] = 15, ["name"] = "wool:white"}, {["x"] = 9, ["meta"] = {["fields"] = {}, ["inventory"] = {}}, ["y"] = 34, ["z"] = 16, ["name"] = "wool:white"}, {["x"] = 9, ["meta"] = {["fields"] = {}, ["inventory"] = {}}, ["y"] = 34, ["z"] = 17, ["name"] = "wool:white"}, {["x"] = 9, ["meta"] = {["fields"] = {}, ["inventory"] = {}}, ["y"] = 34, ["z"] = 18, ["name"] = "wool:white"}, {["x"] = 9, ["meta"] = {["fields"] = {}, ["inventory"] = {}}, ["y"] = 34, ["z"] = 19, ["name"] = "wool:white"}, {["x"] = 9, ["meta"] = {["fields"] = {}, ["inventory"] = {}}, ["y"] = 34, ["z"] = 20, ["name"] = "wool:white"}, {["x"] = 10, ["meta"] = {["fields"] = {}, ["inventory"] = {}}, ["y"] = 0, ["z"] = 5, ["name"] = "darkage:desert_stone_with_iron"}, {["x"] = 10, ["meta"] = {["fields"] = {["infotext"] = "Under-sink cabinet", ["formspec"] = "size[8,7]bgcolor[#080808BB;true]background[5,5;1,1;gui_formbg.png;true]listcolors[#00000069;#5A5A5A;#141318;#30434C;#FFF]list[context;main;0,0;8,2;]list[current_player;main;0,3;8,4;]"}, ["inventory"] = {["main"] = {"", "", "", "", "", "", "", "", "", "", "", "", "", "", "", ""}}}, ["param2"] = 2, ["y"] = 0, ["param1"] = 170, ["z"] = 6, ["name"] = "homedecor:kitchen_cabinet_with_sink"}, {["x"] = 10, ["meta"] = {["fields"] = {}, ["inventory"] = {}}, ["param2"] = 3, ["y"] = 0, ["param1"] = 170, ["z"] = 10, ["name"] = "stairs:stair_stone"}, {["x"] = 10, ["meta"] = {["fields"] = {}, ["inventory"] = {}}, ["param2"] = 3, ["y"] = 0, ["param1"] = 170, ["z"] = 11, ["name"] = "stairs:stair_stone"}, {["x"] = 10, ["meta"] = {["fields"] = {}, ["inventory"] = {}}, ["param2"] = 2, ["y"] = 0, ["param1"] = 153, ["z"] = 14, ["name"] = "homedecor:chair_red"}, {["x"] = 10, ["meta"] = {["fields"] = {}, ["inventory"] = {}}, ["y"] = 0, ["param1"] = 170, ["z"] = 15, ["name"] = "homedecor:table"}, {["x"] = 10, ["meta"] = {["fields"] = {}, ["inventory"] = {}}, ["y"] = 0, ["z"] = 16, ["name"] = "darkage:desert_stone_with_iron"}, {["x"] = 10, ["meta"] = {["fields"] = {}, ["inventory"] = {}}, ["y"] = 1, ["param1"] = 170, ["z"] = 5, ["name"] = "building_blocks:woodglass"}, {["x"] = 10, ["meta"] = {["fields"] = {}, ["inventory"] = {}}, ["y"] = 1, ["param1"] = 187, ["z"] = 15, ["name"] = "homedecor:cutlery_set"}, {["x"] = 10, ["meta"] = {["fields"] = {}, ["inventory"] = {}}, ["y"] = 1, ["param1"] = 170, ["z"] = 16, ["name"] = "building_blocks:woodglass"}, {["x"] = 10, ["meta"] = {["fields"] = {}, ["inventory"] = {}}, ["y"] = 2, ["z"] = 5, ["name"] = "darkage:desert_stone_with_iron"}, {["x"] = 10, ["meta"] = {["fields"] = {}, ["inventory"] = {}}, ["y"] = 2, ["z"] = 16, ["name"] = "darkage:desert_stone_with_iron"}, {["x"] = 10, ["meta"] = {["fields"] = {}, ["inventory"] = {}}, ["y"] = 3, ["z"] = 5, ["name"] = "darkage:desert_stone_with_iron"}, {["x"] = 10, ["meta"] = {["fields"] = {}, ["inventory"] = {}}, ["y"] = 3, ["z"] = 6, ["name"] = "default:stone"}, {["x"] = 10, ["meta"] = {["fields"] = {}, ["inventory"] = {}}, ["y"] = 3, ["z"] = 7, ["name"] = "default:stone"}, {["x"] = 10, ["meta"] = {["fields"] = {}, ["inventory"] = {}}, ["y"] = 3, ["z"] = 8, ["name"] = "default:stone"}, {["x"] = 10, ["meta"] = {["fields"] = {}, ["inventory"] = {}}, ["y"] = 3, ["z"] = 9, ["name"] = "default:stone"}, {["x"] = 10, ["meta"] = {["fields"] = {}, ["inventory"] = {}}, ["y"] = 3, ["z"] = 12, ["name"] = "default:stone"}, {["x"] = 10, ["meta"] = {["fields"] = {}, ["inventory"] = {}}, ["y"] = 3, ["z"] = 13, ["name"] = "default:stone"}, {["x"] = 10, ["meta"] = {["fields"] = {}, ["inventory"] = {}}, ["y"] = 3, ["z"] = 14, ["name"] = "default:stone"}, {["x"] = 10, ["meta"] = {["fields"] = {}, ["inventory"] = {}}, ["y"] = 3, ["z"] = 15, ["name"] = "default:stone"}, {["x"] = 10, ["meta"] = {["fields"] = {}, ["inventory"] = {}}, ["y"] = 3, ["z"] = 16, ["name"] = "darkage:desert_stone_with_iron"}, {["x"] = 10, ["meta"] = {["fields"] = {}, ["inventory"] = {}}, ["y"] = 4, ["z"] = 5, ["name"] = "darkage:desert_stone_with_iron"}, {["x"] = 10, ["meta"] = {["fields"] = {}, ["inventory"] = {}}, ["param2"] = 2, ["y"] = 4, ["param1"] = 153, ["z"] = 7, ["name"] = "homedecor:bed_red_kingsize"}, {["x"] = 10, ["meta"] = {["fields"] = {}, ["inventory"] = {}}, ["y"] = 4, ["param1"] = 170, ["z"] = 15, ["name"] = "homedecor:sink"}, {["x"] = 10, ["meta"] = {["fields"] = {}, ["inventory"] = {}}, ["y"] = 4, ["z"] = 16, ["name"] = "darkage:desert_stone_with_iron"}, {["x"] = 10, ["meta"] = {["fields"] = {}, ["inventory"] = {}}, ["y"] = 5, ["param1"] = 170, ["z"] = 5, ["name"] = "building_blocks:woodglass"}, {["x"] = 10, ["meta"] = {["fields"] = {}, ["inventory"] = {}}, ["param2"] = 3, ["y"] = 5, ["param1"] = 119, ["z"] = 10, ["name"] = "stairs:stair_stone"}, {["x"] = 10, ["meta"] = {["fields"] = {}, ["inventory"] = {}}, ["param2"] = 3, ["y"] = 5, ["param1"] = 119, ["z"] = 11, ["name"] = "stairs:stair_stone"}, {["x"] = 10, ["meta"] = {["fields"] = {}, ["inventory"] = {}}, ["y"] = 5, ["param1"] = 170, ["z"] = 16, ["name"] = "building_blocks:woodglass"}, {["x"] = 10, ["meta"] = {["fields"] = {}, ["inventory"] = {}}, ["y"] = 6, ["z"] = 5, ["name"] = "darkage:desert_stone_with_iron"}, {["x"] = 10, ["meta"] = {["fields"] = {}, ["inventory"] = {}}, ["y"] = 6, ["z"] = 16, ["name"] = "darkage:desert_stone_with_iron"}, {["x"] = 10, ["meta"] = {["fields"] = {}, ["inventory"] = {}}, ["y"] = 7, ["z"] = 5, ["name"] = "darkage:desert_stone_with_iron"}, {["x"] = 10, ["meta"] = {["fields"] = {}, ["inventory"] = {}}, ["y"] = 7, ["z"] = 6, ["name"] = "default:stone"}, {["x"] = 10, ["meta"] = {["fields"] = {}, ["inventory"] = {}}, ["y"] = 7, ["z"] = 7, ["name"] = "default:stone"}, {["x"] = 10, ["meta"] = {["fields"] = {}, ["inventory"] = {}}, ["y"] = 7, ["z"] = 8, ["name"] = "default:stone"}, {["x"] = 10, ["meta"] = {["fields"] = {}, ["inventory"] = {}}, ["y"] = 7, ["z"] = 9, ["name"] = "default:stone"}, {["x"] = 10, ["meta"] = {["fields"] = {}, ["inventory"] = {}}, ["y"] = 7, ["z"] = 12, ["name"] = "default:stone"}, {["x"] = 10, ["meta"] = {["fields"] = {}, ["inventory"] = {}}, ["y"] = 7, ["z"] = 13, ["name"] = "default:stone"}, {["x"] = 10, ["meta"] = {["fields"] = {}, ["inventory"] = {}}, ["y"] = 7, ["z"] = 14, ["name"] = "default:stone"}, {["x"] = 10, ["meta"] = {["fields"] = {}, ["inventory"] = {}}, ["y"] = 7, ["z"] = 15, ["name"] = "default:stone"}, {["x"] = 10, ["meta"] = {["fields"] = {}, ["inventory"] = {}}, ["y"] = 7, ["z"] = 16, ["name"] = "darkage:desert_stone_with_iron"}, {["x"] = 10, ["meta"] = {["fields"] = {}, ["inventory"] = {}}, ["y"] = 8, ["z"] = 5, ["name"] = "darkage:desert_stone_with_iron"}, {["x"] = 10, ["meta"] = {["fields"] = {}, ["inventory"] = {}}, ["y"] = 8, ["z"] = 6, ["name"] = "default:dirt_with_grass"}, {["x"] = 10, ["meta"] = {["fields"] = {}, ["inventory"] = {}}, ["y"] = 8, ["z"] = 7, ["name"] = "default:dirt_with_grass"}, {["x"] = 10, ["meta"] = {["fields"] = {}, ["inventory"] = {}}, ["y"] = 8, ["z"] = 8, ["name"] = "default:dirt_with_grass"}, {["x"] = 10, ["meta"] = {["fields"] = {}, ["inventory"] = {}}, ["y"] = 8, ["z"] = 9, ["name"] = "default:dirt_with_grass"}, {["x"] = 10, ["meta"] = {["fields"] = {}, ["inventory"] = {}}, ["y"] = 8, ["z"] = 12, ["name"] = "default:dirt_with_grass"}, {["x"] = 10, ["meta"] = {["fields"] = {}, ["inventory"] = {}}, ["y"] = 8, ["z"] = 13, ["name"] = "default:dirt_with_grass"}, {["x"] = 10, ["meta"] = {["fields"] = {}, ["inventory"] = {}}, ["y"] = 8, ["z"] = 14, ["name"] = "default:dirt"}, {["x"] = 10, ["meta"] = {["fields"] = {}, ["inventory"] = {}}, ["y"] = 8, ["z"] = 15, ["name"] = "default:dirt_with_grass"}, {["x"] = 10, ["meta"] = {["fields"] = {}, ["inventory"] = {}}, ["y"] = 8, ["z"] = 16, ["name"] = "darkage:desert_stone_with_iron"}, {["x"] = 10, ["meta"] = {["fields"] = {}, ["inventory"] = {}}, ["y"] = 9, ["z"] = 4, ["name"] = "darkage:desert_stone_with_iron"}, {["x"] = 10, ["meta"] = {["fields"] = {}, ["inventory"] = {}}, ["y"] = 9, ["z"] = 5, ["name"] = "darkage:desert_stone_with_iron"}, {["x"] = 10, ["meta"] = {["fields"] = {}, ["inventory"] = {}}, ["y"] = 9, ["param1"] = 171, ["z"] = 6, ["name"] = "homedecor:expansion_placeholder"}, {["x"] = 10, ["meta"] = {["fields"] = {}, ["inventory"] = {}}, ["param2"] = 2, ["y"] = 9, ["param1"] = 188, ["z"] = 7, ["name"] = "homedecor:deckchair"}, {["x"] = 10, ["meta"] = {["fields"] = {}, ["inventory"] = {}}, ["param2"] = 4, ["y"] = 9, ["z"] = 9, ["name"] = "default:torch"}, {["x"] = 10, ["meta"] = {["fields"] = {}, ["inventory"] = {}}, ["y"] = 9, ["z"] = 10, ["name"] = "wool:dark_green"}, {["x"] = 10, ["meta"] = {["fields"] = {}, ["inventory"] = {}}, ["y"] = 9, ["z"] = 11, ["name"] = "wool:dark_green"}, {["x"] = 10, ["meta"] = {["fields"] = {}, ["inventory"] = {}}, ["param2"] = 5, ["y"] = 9, ["z"] = 12, ["name"] = "default:torch"}, {["x"] = 10, ["meta"] = {["fields"] = {}, ["inventory"] = {}}, ["y"] = 9, ["param1"] = 188, ["z"] = 14, ["name"] = "homedecor:deckchair"}, {["x"] = 10, ["meta"] = {["fields"] = {}, ["inventory"] = {}}, ["y"] = 9, ["param1"] = 171, ["z"] = 15, ["name"] = "homedecor:expansion_placeholder"}, {["x"] = 10, ["meta"] = {["fields"] = {}, ["inventory"] = {}}, ["y"] = 9, ["z"] = 16, ["name"] = "darkage:desert_stone_with_iron"}, {["x"] = 10, ["meta"] = {["fields"] = {}, ["inventory"] = {}}, ["y"] = 9, ["z"] = 17, ["name"] = "darkage:desert_stone_with_iron"}, {["x"] = 10, ["meta"] = {["fields"] = {}, ["inventory"] = {}}, ["y"] = 10, ["z"] = 4, ["name"] = "darkage:desert_stone_with_iron"}, {["x"] = 10, ["meta"] = {["fields"] = {}, ["inventory"] = {}}, ["y"] = 10, ["z"] = 10, ["name"] = "wool:dark_green"}, {["x"] = 10, ["meta"] = {["fields"] = {}, ["inventory"] = {}}, ["y"] = 10, ["z"] = 11, ["name"] = "wool:dark_green"}, {["x"] = 10, ["meta"] = {["fields"] = {}, ["inventory"] = {}}, ["y"] = 10, ["z"] = 17, ["name"] = "darkage:desert_stone_with_iron"}, {["x"] = 10, ["meta"] = {["fields"] = {}, ["inventory"] = {}}, ["y"] = 11, ["z"] = 10, ["name"] = "wool:dark_green"}, {["x"] = 10, ["meta"] = {["fields"] = {}, ["inventory"] = {}}, ["y"] = 11, ["z"] = 11, ["name"] = "wool:dark_green"}, {["x"] = 10, ["meta"] = {["fields"] = {}, ["inventory"] = {}}, ["y"] = 12, ["z"] = 10, ["name"] = "wool:dark_green"}, {["x"] = 10, ["meta"] = {["fields"] = {}, ["inventory"] = {}}, ["y"] = 12, ["z"] = 11, ["name"] = "wool:dark_green"}, {["x"] = 10, ["meta"] = {["fields"] = {}, ["inventory"] = {}}, ["y"] = 13, ["z"] = 10, ["name"] = "wool:dark_green"}, {["x"] = 10, ["meta"] = {["fields"] = {}, ["inventory"] = {}}, ["y"] = 13, ["z"] = 11, ["name"] = "wool:dark_green"}, {["x"] = 10, ["meta"] = {["fields"] = {}, ["inventory"] = {}}, ["y"] = 14, ["z"] = 10, ["name"] = "wool:dark_green"}, {["x"] = 10, ["meta"] = {["fields"] = {}, ["inventory"] = {}}, ["y"] = 14, ["z"] = 11, ["name"] = "wool:dark_green"}, {["x"] = 10, ["meta"] = {["fields"] = {}, ["inventory"] = {}}, ["y"] = 15, ["z"] = 10, ["name"] = "wool:dark_green"}, {["x"] = 10, ["meta"] = {["fields"] = {}, ["inventory"] = {}}, ["y"] = 15, ["z"] = 11, ["name"] = "wool:dark_green"}, {["x"] = 10, ["meta"] = {["fields"] = {}, ["inventory"] = {}}, ["y"] = 16, ["z"] = 10, ["name"] = "wool:dark_green"}, {["x"] = 10, ["meta"] = {["fields"] = {}, ["inventory"] = {}}, ["y"] = 16, ["z"] = 11, ["name"] = "wool:dark_green"}, {["x"] = 10, ["meta"] = {["fields"] = {}, ["inventory"] = {}}, ["y"] = 17, ["z"] = 10, ["name"] = "wool:dark_green"}, {["x"] = 10, ["meta"] = {["fields"] = {}, ["inventory"] = {}}, ["y"] = 17, ["z"] = 11, ["name"] = "wool:dark_green"}, {["x"] = 10, ["meta"] = {["fields"] = {}, ["inventory"] = {}}, ["y"] = 18, ["z"] = 10, ["name"] = "wool:dark_green"}, {["x"] = 10, ["meta"] = {["fields"] = {}, ["inventory"] = {}}, ["y"] = 18, ["z"] = 11, ["name"] = "wool:dark_green"}, {["x"] = 10, ["meta"] = {["fields"] = {}, ["inventory"] = {}}, ["y"] = 19, ["z"] = 10, ["name"] = "wool:dark_green"}, {["x"] = 10, ["meta"] = {["fields"] = {}, ["inventory"] = {}}, ["y"] = 19, ["z"] = 11, ["name"] = "wool:dark_green"}, {["x"] = 10, ["meta"] = {["fields"] = {}, ["inventory"] = {}}, ["y"] = 20, ["z"] = 10, ["name"] = "wool:dark_green"}, {["x"] = 10, ["meta"] = {["fields"] = {}, ["inventory"] = {}}, ["y"] = 20, ["z"] = 11, ["name"] = "wool:dark_green"}, {["x"] = 10, ["meta"] = {["fields"] = {}, ["inventory"] = {}}, ["y"] = 21, ["z"] = 10, ["name"] = "wool:dark_green"}, {["x"] = 10, ["meta"] = {["fields"] = {}, ["inventory"] = {}}, ["y"] = 21, ["z"] = 11, ["name"] = "wool:dark_green"}, {["x"] = 10, ["meta"] = {["fields"] = {}, ["inventory"] = {}}, ["y"] = 22, ["z"] = 10, ["name"] = "wool:dark_green"}, {["x"] = 10, ["meta"] = {["fields"] = {}, ["inventory"] = {}}, ["y"] = 22, ["z"] = 11, ["name"] = "wool:dark_green"}, {["x"] = 10, ["meta"] = {["fields"] = {}, ["inventory"] = {}}, ["y"] = 23, ["z"] = 10, ["name"] = "wool:dark_green"}, {["x"] = 10, ["meta"] = {["fields"] = {}, ["inventory"] = {}}, ["y"] = 23, ["z"] = 11, ["name"] = "wool:dark_green"}, {["x"] = 10, ["meta"] = {["fields"] = {}, ["inventory"] = {}}, ["y"] = 24, ["z"] = 10, ["name"] = "wool:dark_green"}, {["x"] = 10, ["meta"] = {["fields"] = {}, ["inventory"] = {}}, ["y"] = 24, ["z"] = 11, ["name"] = "wool:dark_green"}, {["x"] = 10, ["meta"] = {["fields"] = {}, ["inventory"] = {}}, ["y"] = 25, ["z"] = 10, ["name"] = "wool:dark_green"}, {["x"] = 10, ["meta"] = {["fields"] = {}, ["inventory"] = {}}, ["y"] = 25, ["z"] = 11, ["name"] = "wool:dark_green"}, {["x"] = 10, ["meta"] = {["fields"] = {}, ["inventory"] = {}}, ["param2"] = 4, ["y"] = 26, ["z"] = 9, ["name"] = "default:torch"}, {["x"] = 10, ["meta"] = {["fields"] = {}, ["inventory"] = {}}, ["y"] = 26, ["z"] = 10, ["name"] = "wool:dark_green"}, {["x"] = 10, ["meta"] = {["fields"] = {}, ["inventory"] = {}}, ["y"] = 26, ["z"] = 11, ["name"] = "wool:dark_green"}, {["x"] = 10, ["meta"] = {["fields"] = {}, ["inventory"] = {}}, ["param2"] = 5, ["y"] = 26, ["z"] = 12, ["name"] = "default:torch"}, {["x"] = 10, ["meta"] = {["fields"] = {}, ["inventory"] = {}}, ["y"] = 27, ["z"] = 0, ["name"] = "wool:green"}, {["x"] = 10, ["meta"] = {["fields"] = {}, ["inventory"] = {}}, ["y"] = 27, ["z"] = 1, ["name"] = "wool:green"}, {["x"] = 10, ["meta"] = {["fields"] = {}, ["inventory"] = {}}, ["y"] = 27, ["z"] = 2, ["name"] = "wool:green"}, {["x"] = 10, ["meta"] = {["fields"] = {}, ["inventory"] = {}}, ["y"] = 27, ["z"] = 3, ["name"] = "wool:green"}, {["x"] = 10, ["meta"] = {["fields"] = {}, ["inventory"] = {}}, ["y"] = 27, ["z"] = 4, ["name"] = "wool:green"}, {["x"] = 10, ["meta"] = {["fields"] = {}, ["inventory"] = {}}, ["y"] = 27, ["z"] = 5, ["name"] = "wool:green"}, {["x"] = 10, ["meta"] = {["fields"] = {}, ["inventory"] = {}}, ["y"] = 27, ["z"] = 6, ["name"] = "wool:green"}, {["x"] = 10, ["meta"] = {["fields"] = {}, ["inventory"] = {}}, ["y"] = 27, ["z"] = 7, ["name"] = "wool:green"}, {["x"] = 10, ["meta"] = {["fields"] = {}, ["inventory"] = {}}, ["y"] = 27, ["z"] = 8, ["name"] = "wool:green"}, {["x"] = 10, ["meta"] = {["fields"] = {}, ["inventory"] = {}}, ["y"] = 27, ["z"] = 9, ["name"] = "wool:green"}, {["x"] = 10, ["meta"] = {["fields"] = {}, ["inventory"] = {}}, ["y"] = 27, ["z"] = 10, ["name"] = "wool:dark_green"}, {["x"] = 10, ["meta"] = {["fields"] = {}, ["inventory"] = {}}, ["y"] = 27, ["z"] = 11, ["name"] = "wool:dark_green"}, {["x"] = 10, ["meta"] = {["fields"] = {}, ["inventory"] = {}}, ["y"] = 27, ["z"] = 12, ["name"] = "wool:green"}, {["x"] = 10, ["meta"] = {["fields"] = {}, ["inventory"] = {}}, ["y"] = 27, ["z"] = 13, ["name"] = "wool:green"}, {["x"] = 10, ["meta"] = {["fields"] = {}, ["inventory"] = {}}, ["y"] = 27, ["z"] = 14, ["name"] = "wool:green"}, {["x"] = 10, ["meta"] = {["fields"] = {}, ["inventory"] = {}}, ["y"] = 27, ["z"] = 15, ["name"] = "wool:green"}, {["x"] = 10, ["meta"] = {["fields"] = {}, ["inventory"] = {}}, ["y"] = 27, ["z"] = 16, ["name"] = "wool:green"}, {["x"] = 10, ["meta"] = {["fields"] = {}, ["inventory"] = {}}, ["y"] = 27, ["z"] = 17, ["name"] = "wool:green"}, {["x"] = 10, ["meta"] = {["fields"] = {}, ["inventory"] = {}}, ["y"] = 27, ["z"] = 18, ["name"] = "wool:green"}, {["x"] = 10, ["meta"] = {["fields"] = {}, ["inventory"] = {}}, ["y"] = 27, ["z"] = 19, ["name"] = "wool:green"}, {["x"] = 10, ["meta"] = {["fields"] = {}, ["inventory"] = {}}, ["y"] = 27, ["z"] = 20, ["name"] = "wool:green"}, {["x"] = 10, ["meta"] = {["fields"] = {}, ["inventory"] = {}}, ["y"] = 28, ["z"] = 10, ["name"] = "wool:dark_green"}, {["x"] = 10, ["meta"] = {["fields"] = {}, ["inventory"] = {}}, ["y"] = 28, ["z"] = 11, ["name"] = "wool:dark_green"}, {["x"] = 10, ["meta"] = {["fields"] = {}, ["inventory"] = {}}, ["y"] = 29, ["z"] = 10, ["name"] = "wool:dark_green"}, {["x"] = 10, ["meta"] = {["fields"] = {}, ["inventory"] = {}}, ["y"] = 29, ["z"] = 11, ["name"] = "wool:dark_green"}, {["x"] = 10, ["meta"] = {["fields"] = {}, ["inventory"] = {}}, ["y"] = 30, ["z"] = 10, ["name"] = "wool:dark_green"}, {["x"] = 10, ["meta"] = {["fields"] = {}, ["inventory"] = {}}, ["y"] = 30, ["z"] = 11, ["name"] = "wool:dark_green"}, {["x"] = 10, ["meta"] = {["fields"] = {}, ["inventory"] = {}}, ["y"] = 31, ["z"] = 10, ["name"] = "wool:dark_green"}, {["x"] = 10, ["meta"] = {["fields"] = {}, ["inventory"] = {}}, ["y"] = 31, ["z"] = 11, ["name"] = "wool:dark_green"}, {["x"] = 10, ["meta"] = {["fields"] = {}, ["inventory"] = {}}, ["y"] = 32, ["z"] = 10, ["name"] = "wool:dark_green"}, {["x"] = 10, ["meta"] = {["fields"] = {}, ["inventory"] = {}}, ["y"] = 32, ["z"] = 11, ["name"] = "wool:dark_green"}, {["x"] = 10, ["meta"] = {["fields"] = {}, ["inventory"] = {}}, ["y"] = 33, ["z"] = 9, ["name"] = "wool:dark_green"}, {["x"] = 10, ["meta"] = {["fields"] = {}, ["inventory"] = {}}, ["y"] = 33, ["z"] = 10, ["name"] = "wool:dark_green"}, {["x"] = 10, ["meta"] = {["fields"] = {}, ["inventory"] = {}}, ["y"] = 33, ["z"] = 11, ["name"] = "wool:dark_green"}, {["x"] = 10, ["meta"] = {["fields"] = {}, ["inventory"] = {}}, ["y"] = 33, ["z"] = 12, ["name"] = "wool:dark_green"}, {["x"] = 10, ["meta"] = {["fields"] = {}, ["inventory"] = {}}, ["y"] = 34, ["z"] = 1, ["name"] = "wool:white"}, {["x"] = 10, ["meta"] = {["fields"] = {}, ["inventory"] = {}}, ["y"] = 34, ["z"] = 2, ["name"] = "wool:white"}, {["x"] = 10, ["meta"] = {["fields"] = {}, ["inventory"] = {}}, ["y"] = 34, ["z"] = 3, ["name"] = "wool:white"}, {["x"] = 10, ["meta"] = {["fields"] = {}, ["inventory"] = {}}, ["y"] = 34, ["z"] = 4, ["name"] = "wool:white"}, {["x"] = 10, ["meta"] = {["fields"] = {}, ["inventory"] = {}}, ["y"] = 34, ["z"] = 5, ["name"] = "wool:white"}, {["x"] = 10, ["meta"] = {["fields"] = {}, ["inventory"] = {}}, ["y"] = 34, ["z"] = 6, ["name"] = "wool:white"}, {["x"] = 10, ["meta"] = {["fields"] = {}, ["inventory"] = {}}, ["y"] = 34, ["z"] = 7, ["name"] = "wool:white"}, {["x"] = 10, ["meta"] = {["fields"] = {}, ["inventory"] = {}}, ["y"] = 34, ["z"] = 8, ["name"] = "wool:yellow"}, {["x"] = 10, ["meta"] = {["fields"] = {}, ["inventory"] = {}}, ["y"] = 34, ["z"] = 9, ["name"] = "wool:yellow"}, {["x"] = 10, ["meta"] = {["fields"] = {}, ["inventory"] = {}}, ["y"] = 34, ["z"] = 10, ["name"] = "wool:yellow"}, {["x"] = 10, ["meta"] = {["fields"] = {}, ["inventory"] = {}}, ["y"] = 34, ["z"] = 11, ["name"] = "wool:yellow"}, {["x"] = 10, ["meta"] = {["fields"] = {}, ["inventory"] = {}}, ["y"] = 34, ["z"] = 12, ["name"] = "wool:yellow"}, {["x"] = 10, ["meta"] = {["fields"] = {}, ["inventory"] = {}}, ["y"] = 34, ["z"] = 13, ["name"] = "wool:yellow"}, {["x"] = 10, ["meta"] = {["fields"] = {}, ["inventory"] = {}}, ["y"] = 34, ["z"] = 14, ["name"] = "wool:white"}, {["x"] = 10, ["meta"] = {["fields"] = {}, ["inventory"] = {}}, ["y"] = 34, ["z"] = 15, ["name"] = "wool:white"}, {["x"] = 10, ["meta"] = {["fields"] = {}, ["inventory"] = {}}, ["y"] = 34, ["z"] = 16, ["name"] = "wool:white"}, {["x"] = 10, ["meta"] = {["fields"] = {}, ["inventory"] = {}}, ["y"] = 34, ["z"] = 17, ["name"] = "wool:white"}, {["x"] = 10, ["meta"] = {["fields"] = {}, ["inventory"] = {}}, ["y"] = 34, ["z"] = 18, ["name"] = "wool:white"}, {["x"] = 10, ["meta"] = {["fields"] = {}, ["inventory"] = {}}, ["y"] = 34, ["z"] = 19, ["name"] = "wool:white"}, {["x"] = 10, ["meta"] = {["fields"] = {}, ["inventory"] = {}}, ["y"] = 34, ["z"] = 20, ["name"] = "wool:white"}, {["x"] = 11, ["meta"] = {["fields"] = {}, ["inventory"] = {}}, ["y"] = 0, ["param1"] = 124, ["z"] = 4, ["name"] = "flowers:geranium"}, {["x"] = 11, ["meta"] = {["fields"] = {}, ["inventory"] = {}}, ["y"] = 0, ["z"] = 5, ["name"] = "darkage:desert_stone_with_iron"}, {["x"] = 11, ["meta"] = {["fields"] = {["infotext"] = "Refrigerator", ["formspec"] = "size[10,10]bgcolor[#080808BB;true]background[5,5;1,1;gui_formbg.png;true]listcolors[#00000069;#5A5A5A;#141318;#30434C;#FFF]list[context;main;0,0;10,5;]list[current_player;main;1,6;8,4;]"}, ["inventory"] = {["main"] = {"", "", "", "", "", "", "", "", "", "", "", "", "", "", "", "", "", "", "", "", "", "", "", "", "", "", "", "", "", "", "", "", "", "", "", "", "", "", "", "", "", "", "", "", "", "", "", "", "", ""}}}, ["param2"] = 2, ["y"] = 0, ["param1"] = 187, ["z"] = 6, ["name"] = "homedecor:refrigerator_white"}, {["x"] = 11, ["meta"] = {["fields"] = {}, ["inventory"] = {}}, ["param2"] = 2, ["y"] = 0, ["param1"] = 170, ["z"] = 14, ["name"] = "homedecor:chair_red"}, {["x"] = 11, ["meta"] = {["fields"] = {}, ["inventory"] = {}}, ["y"] = 0, ["param1"] = 187, ["z"] = 15, ["name"] = "homedecor:table"}, {["x"] = 11, ["meta"] = {["fields"] = {},