5:return {{["x"] = 0, ["meta"] = {["fields"] = {}, ["inventory"] = {}}, ["y"] = 0, ["param1"] = 142, ["z"] = 5, ["name"] = "my_door_wood:wood_black"}, {["x"] = 0, ["meta"] = {["fields"] = {}, ["inventory"] = {}}, ["y"] = 1, ["param1"] = 158, ["z"] = 5, ["name"] = "my_door_wood:wood_black"}, {["x"] = 0, ["meta"] = {["fields"] = {}, ["inventory"] = {}}, ["y"] = 2, ["param1"] = 158, ["z"] = 4, ["name"] = "my_door_wood:wood_black"}, {["x"] = 0, ["meta"] = {["fields"] = {}, ["inventory"] = {}}, ["y"] = 2, ["param1"] = 174, ["z"] = 5, ["name"] = "my_door_wood:wood_black"}, {["x"] = 0, ["meta"] = {["fields"] = {}, ["inventory"] = {}}, ["y"] = 3, ["param1"] = 110, ["z"] = 0, ["name"] = "my_door_wood:wood_black"}, {["x"] = 0, ["meta"] = {["fields"] = {}, ["inventory"] = {}}, ["y"] = 3, ["param1"] = 126, ["z"] = 1, ["name"] = "my_door_wood:wood_black"}, {["x"] = 0, ["meta"] = {["fields"] = {}, ["inventory"] = {}}, ["y"] = 3, ["param1"] = 142, ["z"] = 2, ["name"] = "my_door_wood:wood_black"}, {["x"] = 0, ["meta"] = {["fields"] = {}, ["inventory"] = {}}, ["y"] = 3, ["param1"] = 158, ["z"] = 3, ["name"] = "my_door_wood:wood_black"}, {["x"] = 0, ["meta"] = {["fields"] = {}, ["inventory"] = {}}, ["y"] = 3, ["param1"] = 174, ["z"] = 4, ["name"] = "my_door_wood:wood_black"}, {["x"] = 0, ["meta"] = {["fields"] = {}, ["inventory"] = {}}, ["y"] = 3, ["param1"] = 190, ["z"] = 5, ["name"] = "my_door_wood:wood_black"}, {["x"] = 1, ["meta"] = {["fields"] = {}, ["inventory"] = {}}, ["y"] = 2, ["param1"] = 125, ["z"] = 1, ["name"] = "my_door_wood:wood_black"}, {["x"] = 1, ["meta"] = {["fields"] = {}, ["inventory"] = {}}, ["y"] = 2, ["param1"] = 141, ["z"] = 2, ["name"] = "my_door_wood:wood_black"}, {["x"] = 1, ["meta"] = {["fields"] = {}, ["inventory"] = {}}, ["y"] = 2, ["param1"] = 157, ["z"] = 3, ["name"] = "my_door_wood:wood_black"}, {["x"] = 1, ["meta"] = {["fields"] = {}, ["inventory"] = {}}, ["y"] = 2, ["param1"] = 173, ["z"] = 4, ["name"] = "my_door_wood:wood_black"}, {["x"] = 1, ["meta"] = {["fields"] = {}, ["inventory"] = {}}, ["y"] = 2, ["param1"] = 190, ["z"] = 5, ["name"] = "my_door_wood:wood_black"}, {["x"] = 1, ["meta"] = {["fields"] = {}, ["inventory"] = {}}, ["y"] = 3, ["param1"] = 126, ["z"] = 0, ["name"] = "my_door_wood:wood_black"}, {["x"] = 1, ["meta"] = {["fields"] = {}, ["inventory"] = {}}, ["param2"] = 2, ["y"] = 3, ["param1"] = 173, ["z"] = 3, ["name"] = "mesecons_extrawires:corner_on"}, {["x"] = 1, ["meta"] = {["fields"] = {}, ["inventory"] = {}}, ["param2"] = 3, ["y"] = 3, ["param1"] = 189, ["z"] = 4, ["name"] = "mesecons_insulated:insulated_on"}, {["x"] = 1, ["meta"] = {["fields"] = {}, ["inventory"] = {}}, ["y"] = 3, ["z"] = 5, ["name"] = "mesecons_lightstone:lightstone_red_on"}, {["x"] = 1, ["meta"] = {["fields"] = {}, ["inventory"] = {}}, ["y"] = 4, ["param1"] = 126, ["z"] = 1, ["name"] = "my_door_wood:wood_black"}, {["x"] = 1, ["meta"] = {["fields"] = {}, ["inventory"] = {}}, ["y"] = 4, ["param1"] = 142, ["z"] = 2, ["name"] = "my_door_wood:wood_black"}, {["x"] = 1, ["meta"] = {["fields"] = {}, ["inventory"] = {}}, ["y"] = 4, ["param1"] = 158, ["z"] = 3, ["name"] = "my_door_wood:wood_black"}, {["x"] = 1, ["meta"] = {["fields"] = {}, ["inventory"] = {}}, ["y"] = 4, ["param1"] = 174, ["z"] = 4, ["name"] = "my_door_wood:wood_black"}, {["x"] = 1, ["meta"] = {["fields"] = {}, ["inventory"] = {}}, ["y"] = 4, ["param1"] = 190, ["z"] = 5, ["name"] = "my_door_wood:wood_black"}, {["x"] = 2, ["meta"] = {["fields"] = {}, ["inventory"] = {}}, ["y"] = 2, ["param1"] = 109, ["z"] = 1, ["name"] = "my_door_wood:wood_black"}, {["x"] = 2, ["meta"] = {["fields"] = {}, ["inventory"] = {}}, ["y"] = 2, ["param1"] = 124, ["z"] = 2, ["name"] = "my_door_wood:wood_black"}, {["x"] = 2, ["meta"] = {["fields"] = {}, ["inventory"] = {}}, ["y"] = 2, ["param1"] = 140, ["z"] = 3, ["name"] = "my_door_wood:wood_black"}, {["x"] = 2, ["meta"] = {["fields"] = {}, ["inventory"] = {}}, ["y"] = 2, ["param1"] = 157, ["z"] = 4, ["name"] = "my_door_wood:wood_black"}, {["x"] = 2, ["meta"] = {["fields"] = {}, ["inventory"] = {}}, ["y"] = 2, ["param1"] = 174, ["z"] = 5, ["name"] = "my_door_wood:wood_black"}, {["x"] = 2, ["meta"] = {["fields"] = {}, ["inventory"] = {}}, ["y"] = 3, ["param1"] = 110, ["z"] = 0, ["name"] = "my_door_wood:wood_black"}, {["x"] = 2, ["meta"] = {["fields"] = {}, ["inventory"] = {}}, ["y"] = 3, ["param1"] = 141, ["z"] = 2, ["name"] = "digilines:wire_std_11000000"}, {["x"] = 2, ["meta"] = {["fields"] = {["real_portstates"] = "1", ["code"] = "if event.type==\"digiline\" then\
  if event.channel==\"on\" then\
    if event.msg==1 then port.a=true end\
    if event.msg==2 then port.b=true end\
    if event.msg==3 then port.c=true end\
  else\
    if event.msg==1 then port.a=false end\
    if event.msg==2 then port.b=false end\
    if event.msg==3 then port.c=false end\
  end    \
end", ["formspec"] = "size[12,10]background[-0.2,-0.25;12.4,10.75;jeija_luac_background.png]textarea[0.2,0.2;12.2,9.5;code;;if event.type==\"digiline\" then\
  if event.channel==\"on\" then\
    if event.msg==1 then port.a=true end\
    if event.msg==2 then port.b=true end\
    if event.msg==3 then port.c=true end\
  else\
    if event.msg==1 then port.a=false end\
    if event.msg==2 then port.b=false end\
    if event.msg==3 then port.c=false end\
  end    \
end]image_button[4.75,8.75;2.5,1;jeija_luac_runbutton.png;program;]image_button_exit[11.72,-0.25;0.425,0.4;jeija_close_window.png;exit;]label[0.1,9;]", ["ignore_offevents"] = "return {[\"A\"] = true}", ["lc_memory"] = "return {}", ["luac_id"] = "3565"}, ["inventory"] = {}}, ["y"] = 3, ["param1"] = 157, ["z"] = 3, ["name"] = "mesecons_luacontroller:luacontroller0001"}, {["x"] = 2, ["meta"] = {["fields"] = {}, ["inventory"] = {}}, ["param2"] = 3, ["y"] = 3, ["param1"] = 173, ["z"] = 4, ["name"] = "mesecons_insulated:insulated_off"}, {["x"] = 2, ["meta"] = {["fields"] = {}, ["inventory"] = {}}, ["y"] = 3, ["z"] = 5, ["name"] = "mesecons_lightstone:lightstone_red_off"}, {["x"] = 2, ["meta"] = {["fields"] = {}, ["inventory"] = {}}, ["y"] = 4, ["param1"] = 110, ["z"] = 1, ["name"] = "my_door_wood:wood_black"}, {["x"] = 2, ["meta"] = {["fields"] = {}, ["inventory"] = {}}, ["y"] = 4, ["param1"] = 126, ["z"] = 2, ["name"] = "my_door_wood:wood_black"}, {["x"] = 2, ["meta"] = {["fields"] = {}, ["inventory"] = {}}, ["y"] = 4, ["param1"] = 142, ["z"] = 3, ["name"] = "my_door_wood:wood_black"}, {["x"] = 2, ["meta"] = {["fields"] = {}, ["inventory"] = {}}, ["y"] = 4, ["param1"] = 158, ["z"] = 4, ["name"] = "my_door_wood:wood_black"}, {["x"] = 2, ["meta"] = {["fields"] = {}, ["inventory"] = {}}, ["y"] = 4, ["param1"] = 174, ["z"] = 5, ["name"] = "my_door_wood:wood_black"}, {["x"] = 3, ["meta"] = {["fields"] = {}, ["inventory"] = {}}, ["y"] = 2, ["param1"] = 93, ["z"] = 1, ["name"] = "my_door_wood:wood_black"}, {["x"] = 3, ["meta"] = {["fields"] = {}, ["inventory"] = {}}, ["y"] = 2, ["param1"] = 108, ["z"] = 2, ["name"] = "my_door_wood:wood_black"}, {["x"] = 3, ["meta"] = {["fields"] = {}, ["inventory"] = {}}, ["y"] = 2, ["param1"] = 124, ["z"] = 3, ["name"] = "my_door_wood:wood_black"}, {["x"] = 3, ["meta"] = {["fields"] = {}, ["inventory"] = {}}, ["y"] = 2, ["param1"] = 141, ["z"] = 4, ["name"] = "my_door_wood:wood_black"}, {["x"] = 3, ["meta"] = {["fields"] = {}, ["inventory"] = {}}, ["y"] = 2, ["param1"] = 158, ["z"] = 5, ["name"] = "my_door_wood:wood_black"}, {["x"] = 3, ["meta"] = {["fields"] = {}, ["inventory"] = {}}, ["y"] = 3, ["param1"] = 94, ["z"] = 0, ["name"] = "my_door_wood:wood_black"}, {["x"] = 3, ["meta"] = {["fields"] = {}, ["inventory"] = {}}, ["y"] = 3, ["param1"] = 125, ["z"] = 2, ["name"] = "digilines:wire_std_10100000"}, {["x"] = 3, ["meta"] = {["fields"] = {}, ["inventory"] = {}}, ["param2"] = 1, ["y"] = 3, ["param1"] = 141, ["z"] = 3, ["name"] = "mesecons_extrawires:corner_off"}, {["x"] = 3, ["meta"] = {["fields"] = {}, ["inventory"] = {}}, ["param2"] = 3, ["y"] = 3, ["param1"] = 157, ["z"] = 4, ["name"] = "mesecons_insulated:insulated_off"}, {["x"] = 3, ["meta"] = {["fields"] = {}, ["inventory"] = {}}, ["y"] = 3, ["z"] = 5, ["name"] = "mesecons_lightstone:lightstone_red_off"}, {["x"] = 3, ["meta"] = {["fields"] = {}, ["inventory"] = {}}, ["y"] = 4, ["param1"] = 94, ["z"] = 1, ["name"] = "my_door_wood:wood_black"}, {["x"] = 3, ["meta"] = {["fields"] = {}, ["inventory"] = {}}, ["y"] = 4, ["param1"] = 110, ["z"] = 2, ["name"] = "my_door_wood:wood_black"}, {["x"] = 3, ["meta"] = {["fields"] = {}, ["inventory"] = {}}, ["y"] = 4, ["param1"] = 126, ["z"] = 3, ["name"] = "my_door_wood:wood_black"}, {["x"] = 3, ["meta"] = {["fields"] = {}, ["inventory"] = {}}, ["y"] = 4, ["param1"] = 142, ["z"] = 4, ["name"] = "my_door_wood:wood_black"}, {["x"] = 3, ["meta"] = {["fields"] = {}, ["inventory"] = {}}, ["y"] = 4, ["param1"] = 158, ["z"] = 5, ["name"] = "my_door_wood:wood_black"}, {["x"] = 4, ["meta"] = {["fields"] = {}, ["inventory"] = {}}, ["y"] = 2, ["param1"] = 77, ["z"] = 1, ["name"] = "my_door_wood:wood_black"}, {["x"] = 4, ["meta"] = {["fields"] = {}, ["inventory"] = {}}, ["y"] = 2, ["param1"] = 92, ["z"] = 2, ["name"] = "my_door_wood:wood_black"}, {["x"] = 4, ["meta"] = {["fields"] = {}, ["inventory"] = {}}, ["y"] = 2, ["param1"] = 108, ["z"] = 3, ["name"] = "my_door_wood:wood_black"}, {["x"] = 4, ["meta"] = {["fields"] = {}, ["inventory"] = {}}, ["y"] = 2, ["param1"] = 125, ["z"] = 4, ["name"] = "my_door_wood:wood_black"}, {["x"] = 4, ["meta"] = {["fields"] = {}, ["inventory"] = {}}, ["y"] = 2, ["param1"] = 142, ["z"] = 5, ["name"] = "my_door_wood:wood_black"}, {["x"] = 4, ["meta"] = {["fields"] = {}, ["inventory"] = {}}, ["y"] = 3, ["param1"] = 78, ["z"] = 0, ["name"] = "my_door_wood:wood_black"}, {["x"] = 4, ["meta"] = {["fields"] = {}, ["inventory"] = {}}, ["y"] = 3, ["param1"] = 109, ["z"] = 2, ["name"] = "digilines:wire_std_10100000"}, {["x"] = 4, ["meta"] = {["fields"] = {}, ["inventory"] = {}}, ["param2"] = 2, ["y"] = 3, ["param1"] = 125, ["z"] = 3, ["name"] = "mesecons_extrawires:corner_off"}, {["x"] = 4, ["meta"] = {["fields"] = {}, ["inventory"] = {}}, ["param2"] = 3, ["y"] = 3, ["param1"] = 141, ["z"] = 4, ["name"] = "mesecons_insulated:insulated_off"}, {["x"] = 4, ["meta"] = {["fields"] = {}, ["inventory"] = {}}, ["y"] = 3, ["z"] = 5, ["name"] = "mesecons_lightstone:lightstone_red_off"}, {["x"] = 4, ["meta"] = {["fields"] = {}, ["inventory"] = {}}, ["y"] = 4, ["param1"] = 78, ["z"] = 1, ["name"] = "my_door_wood:wood_black"}, {["x"] = 4, ["meta"] = {["fields"] = {}, ["inventory"] = {}}, ["y"] = 4, ["param1"] = 94, ["z"] = 2, ["name"] = "my_door_wood:wood_black"}, {["x"] = 4, ["meta"] = {["fields"] = {}, ["inventory"] = {}}, ["y"] = 4, ["param1"] = 110, ["z"] = 3, ["name"] = "my_door_wood:wood_black"}, {["x"] = 4, ["meta"] = {["fields"] = {}, ["inventory"] = {}}, ["y"] = 4, ["param1"] = 126, ["z"] = 4, ["name"] = "my_door_wood:wood_black"}, {["x"] = 4, ["meta"] = {["fields"] = {}, ["inventory"] = {}}, ["y"] = 4, ["param1"] = 142, ["z"] = 5, ["name"] = "my_door_wood:wood_black"}, {["x"] = 5, ["meta"] = {["fields"] = {}, ["inventory"] = {}}, ["y"] = 2, ["param1"] = 61, ["z"] = 1, ["name"] = "my_door_wood:wood_black"}, {["x"] = 5, ["meta"] = {["fields"] = {}, ["inventory"] = {}}, ["y"] = 2, ["param1"] = 76, ["z"] = 2, ["name"] = "my_door_wood:wood_black"}, {["x"] = 5, ["meta"] = {["fields"] = {}, ["inventory"] = {}}, ["y"] = 2, ["param1"] = 92, ["z"] = 3, ["name"] = "my_door_wood:wood_black"}, {["x"] = 5, ["meta"] = {["fields"] = {}, ["inventory"] = {}}, ["y"] = 2, ["param1"] = 109, ["z"] = 4, ["name"] = "my_door_wood:wood_black"}, {["x"] = 5, ["meta"] = {["fields"] = {}, ["inventory"] = {}}, ["y"] = 2, ["param1"] = 126, ["z"] = 5, ["name"] = "my_door_wood:wood_black"}, {["x"] = 5, ["meta"] = {["fields"] = {}, ["inventory"] = {}}, ["y"] = 3, ["param1"] = 62, ["z"] = 0, ["name"] = "my_door_wood:wood_black"}, {["x"] = 5, ["meta"] = {["fields"] = {["real_portstates"] = "1", ["code"] = "interrupt(0.15)\
if event.type==\"program\" then\
  mem.x = 1\
  mem.dx = 1\
end\
digiline_send(\"off\",mem.x)\
mem.x=mem.x+mem.dx\
if mem.x<2 or mem.x>7 then mem.dx=-mem.dx end\
digiline_send(\"on\",mem.x)", ["formspec"] = "size[12,10]background[-0.2,-0.25;12.4,10.75;jeija_luac_background.png]textarea[0.2,0.2;12.2,9.5;code;;interrupt(0.15)\
if event.type==\"program\" then\
  mem.x = 1\
  mem.dx = 1\
end\
digiline_send(\"off\"\\,mem.x)\
mem.x=mem.x+mem.dx\
if mem.x<2 or mem.x>7 then mem.dx=-mem.dx end\
digiline_send(\"on\"\\,mem.x)]image_button[4.75,8.75;2.5,1;jeija_luac_runbutton.png;program;]image_button_exit[11.72,-0.25;0.425,0.4;jeija_close_window.png;exit;]label[0.1,9;]", ["lc_memory"] = "return {[\"x\"] = 1, [\"dx\"] = 1}", ["luac_id"] = "811"}, ["inventory"] = {}}, ["y"] = 3, ["param1"] = 77, ["z"] = 1, ["name"] = "mesecons_luacontroller:luacontroller0000"}, {["x"] = 5, ["meta"] = {["fields"] = {}, ["inventory"] = {}}, ["y"] = 3, ["param1"] = 93, ["z"] = 2, ["name"] = "digilines:wire_std_11110000"}, {["x"] = 5, ["meta"] = {["fields"] = {["real_portstates"] = "1", ["code"] = "if event.type==\"digiline\" then\
  if event.channel==\"on\" then\
    if event.msg==4 then port.a=true end\
    if event.msg==5 then port.b=true end\
    if event.msg==6 then port.c=true end\
  else\
    if event.msg==4 then port.a=false end\
    if event.msg==5 then port.b=false end\
    if event.msg==6 then port.c=false end\
  end    \
end", ["formspec"] = "size[12,10]background[-0.2,-0.25;12.4,10.75;jeija_luac_background.png]textarea[0.2,0.2;12.2,9.5;code;;if event.type==\"digiline\" then\
  if event.channel==\"on\" then\
    if event.msg==4 then port.a=true end\
    if event.msg==5 then port.b=true end\
    if event.msg==6 then port.c=true end\
  else\
    if event.msg==4 then port.a=false end\
    if event.msg==5 then port.b=false end\
    if event.msg==6 then port.c=false end\
  end    \
end]image_button[4.75,8.75;2.5,1;jeija_luac_runbutton.png;program;]image_button_exit[11.72,-0.25;0.425,0.4;jeija_close_window.png;exit;]label[0.1,9;]", ["ignore_offevents"] = "return {}", ["lc_memory"] = "return {}", ["luac_id"] = "47708"}, ["inventory"] = {}}, ["y"] = 3, ["param1"] = 109, ["z"] = 3, ["name"] = "mesecons_luacontroller:luacontroller0000"}, {["x"] = 5, ["meta"] = {["fields"] = {}, ["inventory"] = {}}, ["param2"] = 3, ["y"] = 3, ["param1"] = 125, ["z"] = 4, ["name"] = "mesecons_insulated:insulated_off"}, {["x"] = 5, ["meta"] = {["fields"] = {}, ["inventory"] = {}}, ["y"] = 3, ["z"] = 5, ["name"] = "mesecons_lightstone:lightstone_red_off"}, {["x"] = 5, ["meta"] = {["fields"] = {}, ["inventory"] = {}}, ["y"] = 4, ["param1"] = 62, ["z"] = 1, ["name"] = "my_door_wood:wood_black"}, {["x"] = 5, ["meta"] = {["fields"] = {}, ["inventory"] = {}}, ["y"] = 4, ["param1"] = 78, ["z"] = 2, ["name"] = "my_door_wood:wood_black"}, {["x"] = 5, ["meta"] = {["fields"] = {}, ["inventory"] = {}}, ["y"] = 4, ["param1"] = 94, ["z"] = 3, ["name"] = "my_door_wood:wood_black"}, {["x"] = 5, ["meta"] = {["fields"] = {}, ["inventory"] = {}}, ["y"] = 4, ["param1"] = 110, ["z"] = 4, ["name"] = "my_door_wood:wood_black"}, {["x"] = 5, ["meta"] = {["fields"] = {}, ["inventory"] = {}}, ["y"] = 4, ["param1"] = 126, ["z"] = 5, ["name"] = "my_door_wood:wood_black"}, {["x"] = 6, ["meta"] = {["fields"] = {}, ["inventory"] = {}}, ["y"] = 2, ["param1"] = 45, ["z"] = 1, ["name"] = "my_door_wood:wood_black"}, {["x"] = 6, ["meta"] = {["fields"] = {}, ["inventory"] = {}}, ["y"] = 2, ["param1"] = 60, ["z"] = 2, ["name"] = "my_door_wood:wood_black"}, {["x"] = 6, ["meta"] = {["fields"] = {}, ["inventory"] = {}}, ["y"] = 2, ["param1"] = 76, ["z"] = 3, ["name"] = "my_door_wood:wood_black"}, {["x"] = 6, ["meta"] = {["fields"] = {}, ["inventory"] = {}}, ["y"] = 2, ["param1"] = 93, ["z"] = 4, ["name"] = "my_door_wood:wood_black"}, {["x"] = 6, ["meta"] = {["fields"] = {}, ["inventory"] = {}}, ["y"] = 2, ["param1"] = 110, ["z"] = 5, ["name"] = "my_door_wood:wood_black"}, {["x"] = 6, ["meta"] = {["fields"] = {}, ["inventory"] = {}}, ["y"] = 3, ["param1"] = 46, ["z"] = 0, ["name"] = "my_door_wood:wood_black"}, {["x"] = 6, ["meta"] = {["fields"] = {}, ["inventory"] = {}}, ["y"] = 3, ["param1"] = 77, ["z"] = 2, ["name"] = "digilines:wire_std_10100000"}, {["x"] = 6, ["meta"] = {["fields"] = {}, ["inventory"] = {}}, ["param2"] = 1, ["y"] = 3, ["param1"] = 93, ["z"] = 3, ["name"] = "mesecons_extrawires:corner_off"}, {["x"] = 6, ["meta"] = {["fields"] = {}, ["inventory"] = {}}, ["param2"] = 3, ["y"] = 3, ["param1"] = 109, ["z"] = 4, ["name"] = "mesecons_insulated:insulated_off"}, {["x"] = 6, ["meta"] = {["fields"] = {}, ["inventory"] = {}}, ["y"] = 3, ["z"] = 5, ["name"] = "mesecons_lightstone:lightstone_red_off"}, {["x"] = 6, ["meta"] = {["fields"] = {}, ["inventory"] = {}}, ["y"] = 4, ["param1"] = 46, ["z"] = 1, ["name"] = "my_door_wood:wood_black"}, {["x"] = 6, ["meta"] = {["fields"] = {}, ["inventory"] = {}}, ["y"] = 4, ["param1"] = 62, ["z"] = 2, ["name"] = "my_door_wood:wood_black"}, {["x"] = 6, ["meta"] = {["fields"] = {}, ["inventory"] = {}}, ["y"] = 4, ["param1"] = 78, ["z"] = 3, ["name"] = "my_door_wood:wood_black"}, {["x"] = 6, ["meta"] = {["fields"] = {}, ["inventory"] = {}}, ["y"] = 4, ["param1"] = 94, ["z"] = 4, ["name"] = "my_door_wood:wood_black"}, {["x"] = 6, ["meta"] = {["fields"] = {}, ["inventory"] = {}}, ["y"] = 4, ["param1"] = 110, ["z"] = 5, ["name"] = "my_door_wood:wood_black"}, {["x"] = 7, ["meta"] = {["fields"] = {}, ["inventory"] = {}}, ["y"] = 2, ["param1"] = 29, ["z"] = 1, ["name"] = "my_door_wood:wood_black"}, {["x"] = 7, ["meta"] = {["fields"] = {}, ["inventory"] = {}}, ["y"] = 2, ["param1"] = 44, ["z"] = 2, ["name"] = "my_door_wood:wood_black"}, {["x"] = 7, ["meta"] = {["fields"] = {}, ["inventory"] = {}}, ["y"] = 2, ["param1"] = 60, ["z"] = 3, ["name"] = "my_door_wood:wood_black"}, {["x"] = 7, ["meta"] = {["fields"] = {}, ["inventory"] = {}}, ["y"] = 2, ["param1"] = 77, ["z"] = 4, ["name"] = "my_door_wood:wood_black"}, {["x"] = 7, ["meta"] = {["fields"] = {}, ["inventory"] = {}}, ["y"] = 2, ["param1"] = 94, ["z"] = 5, ["name"] = "my_door_wood:wood_black"}, {["x"] = 7, ["meta"] = {["fields"] = {}, ["inventory"] = {}}, ["y"] = 3, ["param1"] = 30, ["z"] = 0, ["name"] = "my_door_wood:wood_black"}, {["x"] = 7, ["meta"] = {["fields"] = {}, ["inventory"] = {}}, ["y"] = 3, ["param1"] = 61, ["z"] = 2, ["name"] = "digilines:wire_std_10100000"}, {["x"] = 7, ["meta"] = {["fields"] = {}, ["inventory"] = {}}, ["param2"] = 2, ["y"] = 3, ["param1"] = 77, ["z"] = 3, ["name"] = "mesecons_extrawires:corner_off"}, {["x"] = 7, ["meta"] = {["fields"] = {}, ["inventory"] = {}}, ["param2"] = 3, ["y"] = 3, ["param1"] = 93, ["z"] = 4, ["name"] = "mesecons_insulated:insulated_off"}, {["x"] = 7, ["meta"] = {["fields"] = {}, ["inventory"] = {}}, ["y"] = 3, ["z"] = 5, ["name"] = "mesecons_lightstone:lightstone_red_off"}, {["x"] = 7, ["meta"] = {["fields"] = {}, ["inventory"] = {}}, ["y"] = 4, ["param1"] = 30, ["z"] = 1, ["name"] = "my_door_wood:wood_black"}, {["x"] = 7, ["meta"] = {["fields"] = {}, ["inventory"] = {}}, ["y"] = 4, ["param1"] = 46, ["z"] = 2, ["name"] = "my_door_wood:wood_black"}, {["x"] = 7, ["meta"] = {["fields"] = {}, ["inventory"] = {}}, ["y"] = 4, ["param1"] = 62, ["z"] = 3, ["name"] = "my_door_wood:wood_black"}, {["x"] = 7, ["meta"] = {["fields"] = {}, ["inventory"] = {}}, ["y"] = 4, ["param1"] = 78, ["z"] = 4, ["name"] = "my_door_wood:wood_black"}, {["x"] = 7, ["meta"] = {["fields"] = {}, ["inventory"] = {}}, ["y"] = 4, ["param1"] = 94, ["z"] = 5, ["name"] = "my_door_wood:wood_black"}, {["x"] = 8, ["meta"] = {["fields"] = {}, ["inventory"] = {}}, ["y"] = 2, ["param1"] = 13, ["z"] = 1, ["name"] = "my_door_wood:wood_black"}, {["x"] = 8, ["meta"] = {["fields"] = {}, ["inventory"] = {}}, ["y"] = 2, ["param1"] = 29, ["z"] = 2, ["name"] = "my_door_wood:wood_black"}, {["x"] = 8, ["meta"] = {["fields"] = {}, ["inventory"] = {}}, ["y"] = 2, ["param1"] = 45, ["z"] = 3, ["name"] = "my_door_wood:wood_black"}, {["x"] = 8, ["meta"] = {["fields"] = {}, ["inventory"] = {}}, ["y"] = 2, ["param1"] = 61, ["z"] = 4, ["name"] = "my_door_wood:wood_black"}, {["x"] = 8, ["meta"] = {["fields"] = {}, ["inventory"] = {}}, ["y"] = 2, ["param1"] = 78, ["z"] = 5, ["name"] = "my_door_wood:wood_black"}, {["x"] = 8, ["meta"] = {["fields"] = {}, ["inventory"] = {}}, ["y"] = 3, ["param1"] = 14, ["z"] = 0, ["name"] = "my_door_wood:wood_black"}, {["x"] = 8, ["meta"] = {["fields"] = {}, ["inventory"] = {}}, ["y"] = 3, ["param1"] = 45, ["z"] = 2, ["name"] = "digilines:wire_std_01100000"}, {["x"] = 8, ["meta"] = {["fields"] = {["real_portstates"] = "1", ["code"] = "if event.type==\"digiline\" then\
  if event.channel==\"on\" then\
    if event.msg==7 then port.a=true end\
    if event.msg==8 then port.b=true end\
  else\
    if event.msg==7 then port.a=false end\
    if event.msg==8 then port.b=false end\
  end    \
end", ["formspec"] = "size[12,10]background[-0.2,-0.25;12.4,10.75;jeija_luac_background.png]textarea[0.2,0.2;12.2,9.5;code;;if event.type==\"digiline\" then\
  if event.channel==\"on\" then\
    if event.msg==7 then port.a=true end\
    if event.msg==8 then port.b=true end\
  else\
    if event.msg==7 then port.a=false end\
    if event.msg==8 then port.b=false end\
  end    \
end]image_button[4.75,8.75;2.5,1;jeija_luac_runbutton.png;program;]image_button_exit[11.72,-0.25;0.425,0.4;jeija_close_window.png;exit;]label[0.1,9;]", ["ignore_offevents"] = "return {[\"C\"] = true}", ["lc_memory"] = "return {}", ["luac_id"] = "50522"}, ["inventory"] = {}}, ["y"] = 3, ["param1"] = 61, ["z"] = 3, ["name"] = "mesecons_luacontroller:luacontroller0000"}, {["x"] = 8, ["meta"] = {["fields"] = {}, ["inventory"] = {}}, ["param2"] = 3, ["y"] = 3, ["param1"] = 77, ["z"] = 4, ["name"] = "mesecons_insulated:insulated_off"}, {["x"] = 8, ["meta"] = {["fields"] = {}, ["inventory"] = {}}, ["y"] = 3, ["z"] = 5, ["name"] = "mesecons_lightstone:lightstone_red_off"}, {["x"] = 8, ["meta"] = {["fields"] = {}, ["inventory"] = {}}, ["y"] = 4, ["param1"] = 14, ["z"] = 1, ["name"] = "my_door_wood:wood_black"}, {["x"] = 8, ["meta"] = {["fields"] = {}, ["inventory"] = {}}, ["y"] = 4, ["param1"] = 30, ["z"] = 2, ["name"] = "my_door_wood:wood_black"}, {["x"] = 8, ["meta"] = {["fields"] = {}, ["inventory"] = {}}, ["y"] = 4, ["param1"] = 46, ["z"] = 3, ["name"] = "my_door_wood:wood_black"}, {["x"] = 8, ["meta"] = {["fields"] = {}, ["inventory"] = {}}, ["y"] = 4, ["param1"] = 62, ["z"] = 4, ["name"] = "my_door_wood:wood_black"}, {["x"] = 8, ["meta"] = {["fields"] = {}, ["inventory"] = {}}, ["y"] = 4, ["param1"] = 78, ["z"] = 5, ["name"] = "my_door_wood:wood_black"}, {["x"] = 9, ["meta"] = {["fields"] = {}, ["inventory"] = {}}, ["y"] = 0, ["param1"] = 30, ["z"] = 5, ["name"] = "my_door_wood:wood_black"}, {["x"] = 9, ["meta"] = {["fields"] = {}, ["inventory"] = {}}, ["y"] = 1, ["param1"] = 46, ["z"] = 5, ["name"] = "my_door_wood:wood_black"}, {["x"] = 9, ["meta"] = {["fields"] = {}, ["inventory"] = {}}, ["y"] = 2, ["param1"] = 62, ["z"] = 5, ["name"] = "my_door_wood:wood_black"}, {["x"] = 9, ["meta"] = {["fields"] = {}, ["inventory"] = {}}, ["y"] = 3, ["param1"] = 14, ["z"] = 1, ["name"] = "my_door_wood:wood_black"}, {["x"] = 9, ["meta"] = {["fields"] = {}, ["inventory"] = {}}, ["y"] = 3, ["param1"] = 30, ["z"] = 2, ["name"] = "my_door_wood:wood_black"}, {["x"] = 9, ["meta"] = {["fields"] = {}, ["inventory"] = {}}, ["y"] = 3, ["param1"] = 46, ["z"] = 3, ["name"] = "my_door_wood:wood_black"}, {["x"] = 9, ["meta"] = {["fields"] = {}, ["inventory"] = {}}, ["y"] = 3, ["param1"] = 62, ["z"] = 4, ["name"] = "my_door_wood:wood_black"}, {["x"] = 9, ["meta"] = {["fields"] = {}, ["inventory"] = {}}, ["y"] = 3, ["param1"] = 46, ["z"] = 5, ["name"] = "my_door_wood:wood_black"}}