5:return {{["x"] = 0, ["meta"] = {["fields"] = {}, ["inventory"] = {}}, ["y"] = 0, ["z"] = 0, ["name"] = "rainbow:stoneblock_white"}, {["x"] = 0, ["meta"] = {["fields"] = {}, ["inventory"] = {}}, ["y"] = 0, ["param1"] = 221, ["z"] = 1, ["name"] = "default:water_source"}, {["x"] = 0, ["meta"] = {["fields"] = {}, ["inventory"] = {}}, ["y"] = 0, ["param1"] = 221, ["z"] = 2, ["name"] = "default:water_source"}, {["x"] = 0, ["meta"] = {["fields"] = {}, ["inventory"] = {}}, ["y"] = 0, ["param1"] = 221, ["z"] = 3, ["name"] = "default:water_source"}, {["x"] = 0, ["meta"] = {["fields"] = {}, ["inventory"] = {}}, ["y"] = 0, ["z"] = 4, ["name"] = "rainbow:wood_white"}, {["x"] = 0, ["meta"] = {["fields"] = {}, ["inventory"] = {}}, ["y"] = 0, ["param1"] = 221, ["z"] = 5, ["name"] = "default:water_source"}, {["x"] = 0, ["meta"] = {["fields"] = {}, ["inventory"] = {}}, ["y"] = 0, ["param1"] = 221, ["z"] = 6, ["name"] = "default:water_source"}, {["x"] = 0, ["meta"] = {["fields"] = {}, ["inventory"] = {}}, ["y"] = 0, ["param1"] = 221, ["z"] = 7, ["name"] = "default:water_source"}, {["x"] = 0, ["meta"] = {["fields"] = {}, ["inventory"] = {}}, ["y"] = 0, ["param1"] = 221, ["z"] = 8, ["name"] = "default:water_source"}, {["x"] = 0, ["meta"] = {["fields"] = {}, ["inventory"] = {}}, ["y"] = 1, ["param1"] = 223, ["z"] = 0, ["name"] = "xdecor:potted_dandelion_white"}, {["x"] = 0, ["meta"] = {["fields"] = {}, ["inventory"] = {}}, ["y"] = 1, ["param1"] = 223, ["z"] = 1, ["name"] = "xdecor:potted_dandelion_white"}, {["x"] = 1, ["meta"] = {["fields"] = {}, ["inventory"] = {}}, ["y"] = 0, ["z"] = 0, ["name"] = "rainbow:stoneblock_white"}, {["x"] = 1, ["meta"] = {["fields"] = {}, ["inventory"] = {}}, ["y"] = 0, ["param1"] = 205, ["z"] = 1, ["name"] = "default:water_source"}, {["x"] = 1, ["meta"] = {["fields"] = {}, ["inventory"] = {}}, ["y"] = 0, ["param1"] = 205, ["z"] = 2, ["name"] = "default:water_source"}, {["x"] = 1, ["meta"] = {["fields"] = {}, ["inventory"] = {}}, ["y"] = 0, ["param1"] = 205, ["z"] = 3, ["name"] = "default:water_source"}, {["x"] = 1, ["meta"] = {["fields"] = {}, ["inventory"] = {}}, ["y"] = 0, ["z"] = 4, ["name"] = "rainbow:wood_white"}, {["x"] = 1, ["meta"] = {["fields"] = {}, ["inventory"] = {}}, ["y"] = 0, ["param1"] = 205, ["z"] = 5, ["name"] = "default:water_source"}, {["x"] = 1, ["meta"] = {["fields"] = {}, ["inventory"] = {}}, ["y"] = 0, ["param1"] = 205, ["z"] = 6, ["name"] = "default:water_source"}, {["x"] = 1, ["meta"] = {["fields"] = {}, ["inventory"] = {}}, ["y"] = 0, ["param1"] = 205, ["z"] = 7, ["name"] = "default:water_source"}, {["x"] = 1, ["meta"] = {["fields"] = {}, ["inventory"] = {}}, ["y"] = 0, ["param1"] = 205, ["z"] = 8, ["name"] = "default:water_source"}, {["x"] = 1, ["meta"] = {["fields"] = {["infotext"] = "library ", ["text"] = "library", ["__signslib_new_format"] = "1", ["formspec"] = "size[6,4]textarea[0,-0.3;6.5,3;text;;${text}]button_exit[2,3.4;2,1;ok;Write]background[-0.5,-0.5;7,5;bg_signs_lib.jpg]"}, ["inventory"] = {}}, ["param2"] = 2, ["y"] = 2, ["param1"] = 175, ["z"] = 3, ["name"] = "default:sign_wall_wood"}, {["x"] = 1, ["meta"] = {["fields"] = {}, ["inventory"] = {}}, ["param2"] = 3, ["y"] = 4, ["z"] = 4, ["name"] = "xdecor:desertstone_tile"}, {["x"] = 1, ["meta"] = {["fields"] = {}, ["inventory"] = {}}, ["param2"] = 3, ["y"] = 5, ["z"] = 4, ["name"] = "xdecor:desertstone_tile"}, {["x"] = 2, ["meta"] = {["fields"] = {}, ["inventory"] = {}}, ["y"] = 0, ["z"] = 0, ["name"] = "rainbow:wood_white"}, {["x"] = 2, ["meta"] = {["fields"] = {}, ["inventory"] = {}}, ["y"] = 0, ["z"] = 1, ["name"] = "rainbow:wood_white"}, {["x"] = 2, ["meta"] = {["fields"] = {}, ["inventory"] = {}}, ["y"] = 0, ["z"] = 2, ["name"] = "rainbow:wood_white"}, {["x"] = 2, ["meta"] = {["fields"] = {}, ["inventory"] = {}}, ["y"] = 0, ["z"] = 3, ["name"] = "rainbow:wood_white"}, {["x"] = 2, ["meta"] = {["fields"] = {}, ["inventory"] = {}}, ["y"] = 0, ["z"] = 4, ["name"] = "rainbow:wood_white"}, {["x"] = 2, ["meta"] = {["fields"] = {}, ["inventory"] = {}}, ["y"] = 0, ["z"] = 5, ["name"] = "rainbow:wood_white"}, {["x"] = 2, ["meta"] = {["fields"] = {}, ["inventory"] = {}}, ["y"] = 0, ["z"] = 6, ["name"] = "rainbow:wood_blue"}, {["x"] = 2, ["meta"] = {["fields"] = {}, ["inventory"] = {}}, ["y"] = 0, ["z"] = 7, ["name"] = "rainbow:wood_white"}, {["x"] = 2, ["meta"] = {["fields"] = {}, ["inventory"] = {}}, ["y"] = 0, ["z"] = 8, ["name"] = "rainbow:wood_white"}, {["x"] = 2, ["meta"] = {["fields"] = {}, ["inventory"] = {}}, ["param2"] = 2, ["y"] = 1, ["z"] = 0, ["name"] = "xdecor:desertstone_tile"}, {["x"] = 2, ["meta"] = {["fields"] = {}, ["inventory"] = {}}, ["param2"] = 2, ["y"] = 1, ["z"] = 1, ["name"] = "xdecor:desertstone_tile"}, {["x"] = 2, ["meta"] = {["fields"] = {}, ["inventory"] = {}}, ["param2"] = 2, ["y"] = 1, ["z"] = 2, ["name"] = "xdecor:desertstone_tile"}, {["x"] = 2, ["meta"] = {["fields"] = {}, ["inventory"] = {}}, ["param2"] = 2, ["y"] = 1, ["z"] = 3, ["name"] = "xdecor:desertstone_tile"}, {["x"] = 2, ["meta"] = {["fields"] = {["infotext"] = "Owned by fgh", ["state"] = "0", ["doors_owner"] = "fgh"}, ["inventory"] = {}}, ["param2"] = 1, ["y"] = 1, ["param1"] = 172, ["z"] = 4, ["name"] = "my_default_doors:door4_locked_a"}, {["x"] = 2, ["meta"] = {["fields"] = {}, ["inventory"] = {}}, ["param2"] = 1, ["y"] = 1, ["z"] = 5, ["name"] = "xdecor:desertstone_tile"}, {["x"] = 2, ["meta"] = {["fields"] = {}, ["inventory"] = {}}, ["param2"] = 1, ["y"] = 1, ["z"] = 6, ["name"] = "xdecor:desertstone_tile"}, {["x"] = 2, ["meta"] = {["fields"] = {}, ["inventory"] = {}}, ["y"] = 1, ["z"] = 7, ["name"] = "xdecor:desertstone_tile"}, {["x"] = 2, ["meta"] = {["fields"] = {}, ["inventory"] = {}}, ["y"] = 1, ["z"] = 8, ["name"] = "xdecor:desertstone_tile"}, {["x"] = 2, ["meta"] = {["fields"] = {}, ["inventory"] = {}}, ["param2"] = 3, ["y"] = 2, ["z"] = 0, ["name"] = "xdecor:desertstone_tile"}, {["x"] = 2, ["meta"] = {["fields"] = {}, ["inventory"] = {}}, ["param2"] = 3, ["y"] = 2, ["z"] = 1, ["name"] = "xdecor:desertstone_tile"}, {["x"] = 2, ["meta"] = {["fields"] = {}, ["inventory"] = {}}, ["param2"] = 3, ["y"] = 2, ["z"] = 2, ["name"] = "xdecor:desertstone_tile"}, {["x"] = 2, ["meta"] = {["fields"] = {}, ["inventory"] = {}}, ["param2"] = 3, ["y"] = 2, ["z"] = 3, ["name"] = "xdecor:desertstone_tile"}, {["x"] = 2, ["meta"] = {["fields"] = {}, ["inventory"] = {}}, ["param2"] = 1, ["y"] = 2, ["param1"] = 156, ["z"] = 4, ["name"] = "doors:hidden"}, {["x"] = 2, ["meta"] = {["fields"] = {}, ["inventory"] = {}}, ["param2"] = 1, ["y"] = 2, ["z"] = 5, ["name"] = "xdecor:desertstone_tile"}, {["x"] = 2, ["meta"] = {["fields"] = {}, ["inventory"] = {}}, ["param2"] = 3, ["y"] = 2, ["z"] = 6, ["name"] = "xdecor:desertstone_tile"}, {["x"] = 2, ["meta"] = {["fields"] = {}, ["inventory"] = {}}, ["param2"] = 3, ["y"] = 2, ["z"] = 7, ["name"] = "xdecor:desertstone_tile"}, {["x"] = 2, ["meta"] = {["fields"] = {}, ["inventory"] = {}}, ["param2"] = 3, ["y"] = 2, ["z"] = 8, ["name"] = "xdecor:desertstone_tile"}, {["x"] = 2, ["meta"] = {["fields"] = {}, ["inventory"] = {}}, ["param2"] = 3, ["y"] = 3, ["z"] = 1, ["name"] = "xdecor:desertstone_tile"}, {["x"] = 2, ["meta"] = {["fields"] = {}, ["inventory"] = {}}, ["param2"] = 3, ["y"] = 3, ["z"] = 2, ["name"] = "xdecor:desertstone_tile"}, {["x"] = 2, ["meta"] = {["fields"] = {}, ["inventory"] = {}}, ["param2"] = 2, ["y"] = 3, ["z"] = 3, ["name"] = "xdecor:desertstone_tile"}, {["x"] = 2, ["meta"] = {["fields"] = {}, ["inventory"] = {}}, ["y"] = 3, ["z"] = 4, ["name"] = "xdecor:desertstone_tile"}, {["x"] = 2, ["meta"] = {["fields"] = {}, ["inventory"] = {}}, ["y"] = 3, ["z"] = 5, ["name"] = "xdecor:desertstone_tile"}, {["x"] = 2, ["meta"] = {["fields"] = {}, ["inventory"] = {}}, ["param2"] = 3, ["y"] = 3, ["z"] = 6, ["name"] = "xdecor:desertstone_tile"}, {["x"] = 2, ["meta"] = {["fields"] = {}, ["inventory"] = {}}, ["param2"] = 3, ["y"] = 3, ["z"] = 7, ["name"] = "xdecor:desertstone_tile"}, {["x"] = 2, ["meta"] = {["fields"] = {}, ["inventory"] = {}}, ["param2"] = 3, ["y"] = 4, ["z"] = 2, ["name"] = "xdecor:desertstone_tile"}, {["x"] = 2, ["meta"] = {["fields"] = {}, ["inventory"] = {}}, ["param2"] = 3, ["y"] = 4, ["z"] = 3, ["name"] = "xdecor:desertstone_tile"}, {["x"] = 2, ["meta"] = {["fields"] = {}, ["inventory"] = {}}, ["param2"] = 3, ["y"] = 4, ["z"] = 4, ["name"] = "xdecor:desertstone_tile"}, {["x"] = 2, ["meta"] = {["fields"] = {}, ["inventory"] = {}}, ["param2"] = 3, ["y"] = 4, ["z"] = 5, ["name"] = "xdecor:desertstone_tile"}, {["x"] = 2, ["meta"] = {["fields"] = {}, ["inventory"] = {}}, ["param2"] = 3, ["y"] = 5, ["z"] = 3, ["name"] = "xdecor:desertstone_tile"}, {["x"] = 2, ["meta"] = {["fields"] = {}, ["inventory"] = {}}, ["param2"] = 3, ["y"] = 5, ["z"] = 4, ["name"] = "xdecor:desertstone_tile"}, {["x"] = 2, ["meta"] = {["fields"] = {}, ["inventory"] = {}}, ["param2"] = 3, ["y"] = 5, ["z"] = 5, ["name"] = "xdecor:desertstone_tile"}, {["x"] = 2, ["meta"] = {["fields"] = {}, ["inventory"] = {}}, ["param2"] = 3, ["y"] = 6, ["z"] = 4, ["name"] = "xdecor:desertstone_tile"}, {["x"] = 3, ["meta"] = {["fields"] = {}, ["inventory"] = {}}, ["y"] = 0, ["z"] = 0, ["name"] = "rainbow:wood_white"}, {["x"] = 3, ["meta"] = {["fields"] = {}, ["inventory"] = {}}, ["y"] = 0, ["z"] = 1, ["name"] = "rainbow:wood_white"}, {["x"] = 3, ["meta"] = {["fields"] = {}, ["inventory"] = {}}, ["y"] = 0, ["z"] = 2, ["name"] = "rainbow:wood_white"}, {["x"] = 3, ["meta"] = {["fields"] = {}, ["inventory"] = {}}, ["y"] = 0, ["z"] = 3, ["name"] = "rainbow:wood_white"}, {["x"] = 3, ["meta"] = {["fields"] = {}, ["inventory"] = {}}, ["y"] = 0, ["z"] = 5, ["name"] = "rainbow:wood_white"}, {["x"] = 3, ["meta"] = {["fields"] = {}, ["inventory"] = {}}, ["y"] = 0, ["z"] = 6, ["name"] = "rainbow:wood_white"}, {["x"] = 3, ["meta"] = {["fields"] = {}, ["inventory"] = {}}, ["y"] = 0, ["z"] = 7, ["name"] = "rainbow:wood_white"}, {["x"] = 3, ["meta"] = {["fields"] = {}, ["inventory"] = {}}, ["y"] = 0, ["z"] = 8, ["name"] = "rainbow:wood_white"}, {["x"] = 3, ["meta"] = {["fields"] = {}, ["inventory"] = {}}, ["param2"] = 3, ["y"] = 1, ["z"] = 0, ["name"] = "xdecor:desertstone_tile"}, {["x"] = 3, ["meta"] = {["fields"] = {["infotext"] = "Empty Shelf", ["formspec"] = " size[8,8]\
\9\9list[context;main;0,0;8,3;]\
\9\9list[current_player;main;0,4;8,4;]\
\9\9listring[current_player;main]\
\9\9listring[context;main]\" image[0,4;1,1;gui_hb_bg.png]image[1,4;1,1;gui_hb_bg.png]image[2,4;1,1;gui_hb_bg.png]image[3,4;1,1;gui_hb_bg.png]image[4,4;1,1;gui_hb_bg.png]image[5,4;1,1;gui_hb_bg.png]image[6,4;1,1;gui_hb_bg.png]image[7,4;1,1;gui_hb_bg.png]bgcolor[#080808BB;true]background[5,5;1,1;gui_formbg.png;true]listcolors[#00000069;#5A5A5A;#141318;#30434C;#FFF]"}, ["inventory"] = {["main"] = {"", "", "", "", "", "", "", "", "", "", "", "", "", "", "", "", "", "", "", "", "", "", "", ""}}}, ["y"] = 1, ["z"] = 2, ["name"] = "xdecor:empty_shelf"}, {["x"] = 3, ["meta"] = {["fields"] = {["infotext"] = "Empty Shelf", ["formspec"] = " size[8,8]\
\9\9list[context;main;0,0;8,3;]\
\9\9list[current_player;main;0,4;8,4;]\
\9\9listring[current_player;main]\
\9\9listring[context;main]\" image[0,4;1,1;gui_hb_bg.png]image[1,4;1,1;gui_hb_bg.png]image[2,4;1,1;gui_hb_bg.png]image[3,4;1,1;gui_hb_bg.png]image[4,4;1,1;gui_hb_bg.png]image[5,4;1,1;gui_hb_bg.png]image[6,4;1,1;gui_hb_bg.png]image[7,4;1,1;gui_hb_bg.png]bgcolor[#080808BB;true]background[5,5;1,1;gui_formbg.png;true]listcolors[#00000069;#5A5A5A;#141318;#30434C;#FFF]"}, ["inventory"] = {["main"] = {"", "", "", "", "", "", "", "", "", "", "", "", "", "", "", "", "", "", "", "", "", "", "", ""}}}, ["param2"] = 2, ["y"] = 1, ["z"] = 6, ["name"] = "xdecor:empty_shelf"}, {["x"] = 3, ["meta"] = {["fields"] = {}, ["inventory"] = {}}, ["param2"] = 2, ["y"] = 1, ["z"] = 8, ["name"] = "xdecor:desertstone_tile"}, {["x"] = 3, ["meta"] = {["fields"] = {}, ["inventory"] = {}}, ["param2"] = 3, ["y"] = 2, ["z"] = 0, ["name"] = "xdecor:desertstone_tile"}, {["x"] = 3, ["meta"] = {["fields"] = {}, ["inventory"] = {}}, ["param2"] = 3, ["y"] = 2, ["z"] = 8, ["name"] = "xdecor:desertstone_tile"}, {["x"] = 3, ["meta"] = {["fields"] = {}, ["inventory"] = {}}, ["y"] = 3, ["param1"] = 111, ["z"] = 1, ["name"] = "xdecor:woodframed_glass"}, {["x"] = 3, ["meta"] = {["fields"] = {}, ["inventory"] = {}}, ["y"] = 3, ["param1"] = 111, ["z"] = 7, ["name"] = "xdecor:woodframed_glass"}, {["x"] = 3, ["meta"] = {["fields"] = {}, ["inventory"] = {}}, ["param2"] = 3, ["y"] = 4, ["z"] = 2, ["name"] = "xdecor:desertstone_tile"}, {["x"] = 3, ["meta"] = {["fields"] = {}, ["inventory"] = {}}, ["param2"] = 1, ["y"] = 4, ["z"] = 6, ["name"] = "xdecor:desertstone_tile"}, {["x"] = 3, ["meta"] = {["fields"] = {}, ["inventory"] = {}}, ["param2"] = 3, ["y"] = 5, ["z"] = 3, ["name"] = "xdecor:desertstone_tile"}, {["x"] = 3, ["meta"] = {["fields"] = {}, ["inventory"] = {}}, ["param2"] = 3, ["y"] = 5, ["z"] = 5, ["name"] = "xdecor:desertstone_tile"}, {["x"] = 3, ["meta"] = {["fields"] = {}, ["inventory"] = {}}, ["param2"] = 3, ["y"] = 6, ["z"] = 4, ["name"] = "xdecor:desertstone_tile"}, {["x"] = 3, ["meta"] = {["fields"] = {["infotext"] = "erik's Mailbox", ["owner"] = "erik"}, ["inventory"] = {["drop"] = {""}, ["mailbox"] = {"", "", "", "", "", "", "", "", "", "", "", "", "", "", "", "", "", "", "", "", "", "", "", ""}}}, ["param2"] = 3, ["y"] = 7, ["z"] = 4, ["name"] = "xdecor:mailbox"}, {["x"] = 4, ["meta"] = {["fields"] = {}, ["inventory"] = {}}, ["y"] = 0, ["z"] = 0, ["name"] = "rainbow:wood_white"}, {["x"] = 4, ["meta"] = {["fields"] = {}, ["inventory"] = {}}, ["y"] = 0, ["z"] = 1, ["name"] = "rainbow:wood_white"}, {["x"] = 4, ["meta"] = {["fields"] = {}, ["inventory"] = {}}, ["y"] = 0, ["z"] = 2, ["name"] = "rainbow:wood_white"}, {["x"] = 4, ["meta"] = {["fields"] = {}, ["inventory"] = {}}, ["y"] = 0, ["z"] = 3, ["name"] = "rainbow:wood_white"}, {["x"] = 4, ["meta"] = {["fields"] = {}, ["inventory"] = {}}, ["y"] = 0, ["z"] = 4, ["name"] = "rainbow:wood_white"}, {["x"] = 4, ["meta"] = {["fields"] = {}, ["inventory"] = {}}, ["y"] = 0, ["z"] = 5, ["name"] = "rainbow:wood_white"}, {["x"] = 4, ["meta"] = {["fields"] = {}, ["inventory"] = {}}, ["y"] = 0, ["z"] = 6, ["name"] = "rainbow:wood_white"}, {["x"] = 4, ["meta"] = {["fields"] = {}, ["inventory"] = {}}, ["y"] = 0, ["z"] = 7, ["name"] = "rainbow:wood_white"}, {["x"] = 4, ["meta"] = {["fields"] = {}, ["inventory"] = {}}, ["y"] = 0, ["z"] = 8, ["name"] = "rainbow:wood_white"}, {["x"] = 4, ["meta"] = {["fields"] = {}, ["inventory"] = {}}, ["param2"] = 3, ["y"] = 1, ["z"] = 0, ["name"] = "xdecor:desertstone_tile"}, {["x"] = 4, ["meta"] = {["fields"] = {}, ["inventory"] = {}}, ["param2"] = 2, ["y"] = 1, ["param1"] = 61, ["z"] = 1, ["name"] = "xdecor:chair"}, {["x"] = 4, ["meta"] = {["fields"] = {["infotext"] = "Empty Shelf", ["formspec"] = " size[8,8]\
\9\9list[context;main;0,0;8,3;]\
\9\9list[current_player;main;0,4;8,4;]\
\9\9listring[current_player;main]\
\9\9listring[context;main]\" image[0,4;1,1;gui_hb_bg.png]image[1,4;1,1;gui_hb_bg.png]image[2,4;1,1;gui_hb_bg.png]image[3,4;1,1;gui_hb_bg.png]image[4,4;1,1;gui_hb_bg.png]image[5,4;1,1;gui_hb_bg.png]image[6,4;1,1;gui_hb_bg.png]image[7,4;1,1;gui_hb_bg.png]bgcolor[#080808BB;true]background[5,5;1,1;gui_formbg.png;true]listcolors[#00000069;#5A5A5A;#141318;#30434C;#FFF]"}, ["inventory"] = {["main"] = {"", "", "", "", "", "", "", "", "", "", "", "", "", "", "", "", "", "", "", "", "", "", "", ""}}}, ["y"] = 1, ["z"] = 2, ["name"] = "xdecor:empty_shelf"}, {["x"] = 4, ["meta"] = {["fields"] = {["infotext"] = "Empty Shelf", ["formspec"] = " size[8,8]\
\9\9list[context;main;0,0;8,3;]\
\9\9list[current_player;main;0,4;8,4;]\
\9\9listring[current_player;main]\
\9\9listring[context;main]\" image[0,4;1,1;gui_hb_bg.png]image[1,4;1,1;gui_hb_bg.png]image[2,4;1,1;gui_hb_bg.png]image[3,4;1,1;gui_hb_bg.png]image[4,4;1,1;gui_hb_bg.png]image[5,4;1,1;gui_hb_bg.png]image[6,4;1,1;gui_hb_bg.png]image[7,4;1,1;gui_hb_bg.png]bgcolor[#080808BB;true]background[5,5;1,1;gui_formbg.png;true]listcolors[#00000069;#5A5A5A;#141318;#30434C;#FFF]"}, ["inventory"] = {["main"] = {"", "", "", "", "", "", "", "", "", "", "", "", "", "", "", "", "", "", "", "", "", "", "", ""}}}, ["param2"] = 2, ["y"] = 1, ["z"] = 6, ["name"] = "xdecor:empty_shelf"}, {["x"] = 4, ["meta"] = {["fields"] = {}, ["inventory"] = {}}, ["y"] = 1, ["param1"] = 61, ["z"] = 7, ["name"] = "xdecor:chair"}, {["x"] = 4, ["meta"] = {["fields"] = {}, ["inventory"] = {}}, ["param2"] = 1, ["y"] = 1, ["z"] = 8, ["name"] = "xdecor:desertstone_tile"}, {["x"] = 4, ["meta"] = {["fields"] = {}, ["inventory"] = {}}, ["param2"] = 3, ["y"] = 2, ["z"] = 0, ["name"] = "xdecor:desertstone_tile"}, {["x"] = 4, ["meta"] = {["fields"] = {}, ["inventory"] = {}}, ["param2"] = 3, ["y"] = 2, ["z"] = 8, ["name"] = "xdecor:desertstone_tile"}, {["x"] = 4, ["meta"] = {["fields"] = {}, ["inventory"] = {}}, ["y"] = 3, ["param1"] = 95, ["z"] = 1, ["name"] = "xdecor:woodframed_glass"}, {["x"] = 4, ["meta"] = {["fields"] = {}, ["inventory"] = {}}, ["y"] = 3, ["param1"] = 95, ["z"] = 7, ["name"] = "xdecor:woodframed_glass"}, {["x"] = 4, ["meta"] = {["fields"] = {}, ["inventory"] = {}}, ["param2"] = 3, ["y"] = 4, ["z"] = 2, ["name"] = "xdecor:desertstone_tile"}, {["x"] = 4, ["meta"] = {["fields"] = {}, ["inventory"] = {}}, ["param2"] = 3, ["y"] = 4, ["z"] = 6, ["name"] = "xdecor:desertstone_tile"}, {["x"] = 4, ["meta"] = {["fields"] = {}, ["inventory"] = {}}, ["param2"] = 3, ["y"] = 5, ["z"] = 3, ["name"] = "xdecor:desertstone_tile"}, {["x"] = 4, ["meta"] = {["fields"] = {}, ["inventory"] = {}}, ["param2"] = 1, ["y"] = 5, ["z"] = 5, ["name"] = "xdecor:desertstone_tile"}, {["x"] = 4, ["meta"] = {["fields"] = {}, ["inventory"] = {}}, ["param2"] = 3, ["y"] = 6, ["z"] = 4, ["name"] = "xdecor:desertstone_tile"}, {["x"] = 5, ["meta"] = {["fields"] = {}, ["inventory"] = {}}, ["y"] = 0, ["z"] = 0, ["name"] = "rainbow:wood_white"}, {["x"] = 5, ["meta"] = {["fields"] = {}, ["inventory"] = {}}, ["y"] = 0, ["z"] = 1, ["name"] = "rainbow:wood_white"}, {["x"] = 5, ["meta"] = {["fields"] = {}, ["inventory"] = {}}, ["y"] = 0, ["z"] = 2, ["name"] = "rainbow:wood_white"}, {["x"] = 5, ["meta"] = {["fields"] = {}, ["inventory"] = {}}, ["y"] = 0, ["z"] = 3, ["name"] = "rainbow:wood_white"}, {["x"] = 5, ["meta"] = {["fields"] = {}, ["inventory"] = {}}, ["y"] = 0, ["z"] = 4, ["name"] = "rainbow:wood_white"}, {["x"] = 5, ["meta"] = {["fields"] = {}, ["inventory"] = {}}, ["y"] = 0, ["z"] = 5, ["name"] = "rainbow:wood_white"}, {["x"] = 5, ["meta"] = {["fields"] = {}, ["inventory"] = {}}, ["y"] = 0, ["z"] = 6, ["name"] = "rainbow:wood_white"}, {["x"] = 5, ["meta"] = {["fields"] = {}, ["inventory"] = {}}, ["y"] = 0, ["z"] = 7, ["name"] = "rainbow:wood_white"}, {["x"] = 5, ["meta"] = {["fields"] = {}, ["inventory"] = {}}, ["y"] = 0, ["z"] = 8, ["name"] = "rainbow:wood_white"}, {["x"] = 5, ["meta"] = {["fields"] = {}, ["inventory"] = {}}, ["param2"] = 3, ["y"] = 1, ["z"] = 0, ["name"] = "xdecor:desertstone_tile"}, {["x"] = 5, ["meta"] = {["fields"] = {["infotext"] = "Empty Shelf", ["formspec"] = " size[8,8]\
\9\9list[context;main;0,0;8,3;]\
\9\9list[current_player;main;0,4;8,4;]\
\9\9listring[current_player;main]\
\9\9listring[context;main]\" image[0,4;1,1;gui_hb_bg.png]image[1,4;1,1;gui_hb_bg.png]image[2,4;1,1;gui_hb_bg.png]image[3,4;1,1;gui_hb_bg.png]image[4,4;1,1;gui_hb_bg.png]image[5,4;1,1;gui_hb_bg.png]image[6,4;1,1;gui_hb_bg.png]image[7,4;1,1;gui_hb_bg.png]bgcolor[#080808BB;true]background[5,5;1,1;gui_formbg.png;true]listcolors[#00000069;#5A5A5A;#141318;#30434C;#FFF]"}, ["inventory"] = {["main"] = {"", "", "", "", "", "", "", "", "", "", "", "", "", "", "", "", "", "", "", "", "", "", "", ""}}}, ["y"] = 1, ["z"] = 2, ["name"] = "xdecor:empty_shelf"}, {["x"] = 5, ["meta"] = {["fields"] = {["infotext"] = "Empty Shelf", ["formspec"] = " size[8,8]\
\9\9list[context;main;0,0;8,3;]\
\9\9list[current_player;main;0,4;8,4;]\
\9\9listring[current_player;main]\
\9\9listring[context;main]\" image[0,4;1,1;gui_hb_bg.png]image[1,4;1,1;gui_hb_bg.png]image[2,4;1,1;gui_hb_bg.png]image[3,4;1,1;gui_hb_bg.png]image[4,4;1,1;gui_hb_bg.png]image[5,4;1,1;gui_hb_bg.png]image[6,4;1,1;gui_hb_bg.png]image[7,4;1,1;gui_hb_bg.png]bgcolor[#080808BB;true]background[5,5;1,1;gui_formbg.png;true]listcolors[#00000069;#5A5A5A;#141318;#30434C;#FFF]"}, ["inventory"] = {["main"] = {"", "", "", "", "", "", "", "", "", "", "", "", "", "", "", "", "", "", "", "", "", "", "", ""}}}, ["param2"] = 2, ["y"] = 1, ["z"] = 6, ["name"] = "xdecor:empty_shelf"}, {["x"] = 5, ["meta"] = {["fields"] = {}, ["inventory"] = {}}, ["param2"] = 1, ["y"] = 1, ["z"] = 8, ["name"] = "xdecor:desertstone_tile"}, {["x"] = 5, ["meta"] = {["fields"] = {}, ["inventory"] = {}}, ["y"] = 2, ["z"] = 0, ["name"] = "xdecor:desertstone_tile"}, {["x"] = 5, ["meta"] = {["fields"] = {}, ["inventory"] = {}}, ["param2"] = 3, ["y"] = 2, ["z"] = 8, ["name"] = "xdecor:desertstone_tile"}, {["x"] = 5, ["meta"] = {["fields"] = {}, ["inventory"] = {}}, ["y"] = 3, ["param1"] = 79, ["z"] = 1, ["name"] = "xdecor:woodframed_glass"}, {["x"] = 5, ["meta"] = {["fields"] = {}, ["inventory"] = {}}, ["y"] = 3, ["param1"] = 79, ["z"] = 7, ["name"] = "xdecor:woodframed_glass"}, {["x"] = 5, ["meta"] = {["fields"] = {}, ["inventory"] = {}}, ["param2"] = 3, ["y"] = 4, ["z"] = 2, ["name"] = "xdecor:desertstone_tile"}, {["x"] = 5, ["meta"] = {["fields"] = {}, ["inventory"] = {}}, ["param2"] = 3, ["y"] = 4, ["z"] = 6, ["name"] = "xdecor:desertstone_tile"}, {["x"] = 5, ["meta"] = {["fields"] = {}, ["inventory"] = {}}, ["param2"] = 3, ["y"] = 5, ["z"] = 3, ["name"] = "xdecor:desertstone_tile"}, {["x"] = 5, ["meta"] = {["fields"] = {}, ["inventory"] = {}}, ["param2"] = 3, ["y"] = 5, ["z"] = 5, ["name"] = "xdecor:desertstone_tile"}, {["x"] = 5, ["meta"] = {["fields"] = {}, ["inventory"] = {}}, ["param2"] = 1, ["y"] = 6, ["z"] = 4, ["name"] = "xdecor:desertstone_tile"}, {["x"] = 6, ["meta"] = {["fields"] = {}, ["inventory"] = {}}, ["y"] = 0, ["z"] = 0, ["name"] = "rainbow:wood_white"}, {["x"] = 6, ["meta"] = {["fields"] = {}, ["inventory"] = {}}, ["y"] = 0, ["z"] = 2, ["name"] = "rainbow:wood_white"}, {["x"] = 6, ["meta"] = {["fields"] = {}, ["inventory"] = {}}, ["y"] = 0, ["z"] = 3, ["name"] = "rainbow:wood_white"}, {["x"] = 6, ["meta"] = {["fields"] = {}, ["inventory"] = {}}, ["y"] = 0, ["z"] = 4, ["name"] = "rainbow:wood_white"}, {["x"] = 6, ["meta"] = {["fields"] = {}, ["inventory"] = {}}, ["y"] = 0, ["z"] = 5, ["name"] = "rainbow:wood_white"}, {["x"] = 6, ["meta"] = {["fields"] = {}, ["inventory"] = {}}, ["y"] = 0, ["z"] = 6, ["name"] = "rainbow:wood_white"}, {["x"] = 6, ["meta"] = {["fields"] = {}, ["inventory"] = {}}, ["y"] = 0, ["z"] = 7, ["name"] = "rainbow:wood_white"}, {["x"] = 6, ["meta"] = {["fields"] = {}, ["inventory"] = {}}, ["y"] = 0, ["z"] = 8, ["name"] = "rainbow:wood_white"}, {["x"] = 6, ["meta"] = {["fields"] = {}, ["inventory"] = {}}, ["param2"] = 3, ["y"] = 1, ["z"] = 0, ["name"] = "xdecor:desertstone_tile"}, {["x"] = 6, ["meta"] = {["fields"] = {["state"] = "2"}, ["inventory"] = {}}, ["param2"] = 1, ["y"] = 1, ["param1"] = 78, ["z"] = 2, ["name"] = "my_hidden_doors:hidden_doorbookshelf_b"}, {["x"] = 6, ["meta"] = {["fields"] = {["state"] = "2"}, ["inventory"] = {}}, ["param2"] = 1, ["y"] = 1, ["param1"] = 93, ["z"] = 3, ["name"] = "my_hidden_doors:hidden_doorbookshelf_b"}, {["x"] = 6, ["meta"] = {["fields"] = {["state"] = "2"}, ["inventory"] = {}}, ["param2"] = 1, ["y"] = 1, ["param1"] = 93, ["z"] = 5, ["name"] = "my_hidden_doors:hidden_doorbookshelf_b"}, {["x"] = 6, ["meta"] = {["fields"] = {["state"] = "0"}, ["inventory"] = {}}, ["param2"] = 1, ["y"] = 1, ["param1"] = 78, ["z"] = 6, ["name"] = "my_hidden_doors:hidden_doorbookshelf_a"}, {["x"] = 6, ["meta"] = {["fields"] = {["state"] = "0"}, ["inventory"] = {}}, ["param2"] = 1, ["y"] = 1, ["param1"] = 63, ["z"] = 7, ["name"] = "my_hidden_doors:hidden_doorbookshelf_a"}, {["x"] = 6, ["meta"] = {["fields"] = {}, ["inventory"] = {}}, ["y"] = 1, ["z"] = 8, ["name"] = "xdecor:desertstone_tile"}, {["x"] = 6, ["meta"] = {["fields"] = {}, ["inventory"] = {}}, ["y"] = 2, ["z"] = 0, ["name"] = "xdecor:desertstone_tile"}, {["x"] = 6, ["meta"] = {["fields"] = {}, ["inventory"] = {}}, ["y"] = 2, ["param1"] = 62, ["z"] = 2, ["name"] = "doors:hidden"}, {["x"] = 6, ["meta"] = {["fields"] = {}, ["inventory"] = {}}, ["y"] = 2, ["param1"] = 77, ["z"] = 3, ["name"] = "doors:hidden"}, {["x"] = 6, ["meta"] = {["fields"] = {}, ["inventory"] = {}}, ["y"] = 2, ["param1"] = 77, ["z"] = 5, ["name"] = "doors:hidden"}, {["x"] = 6, ["meta"] = {["fields"] = {}, ["inventory"] = {}}, ["param2"] = 1, ["y"] = 2, ["param1"] = 62, ["z"] = 6, ["name"] = "doors:hidden"}, {["x"] = 6, ["meta"] = {["fields"] = {}, ["inventory"] = {}}, ["param2"] = 1, ["y"] = 2, ["param1"] = 47, ["z"] = 7, ["name"] = "doors:hidden"}, {["x"] = 6, ["meta"] = {["fields"] = {}, ["inventory"] = {}}, ["param2"] = 3, ["y"] = 2, ["z"] = 8, ["name"] = "xdecor:desertstone_tile"}, {["x"] = 6, ["meta"] = {["fields"] = {}, ["inventory"] = {}}, ["y"] = 3, ["param1"] = 95, ["z"] = 1, ["name"] = "xdecor:woodframed_glass"}, {["x"] = 6, ["meta"] = {["fields"] = {}, ["inventory"] = {}}, ["y"] = 3, ["param1"] = 63, ["z"] = 7, ["name"] = "xdecor:woodframed_glass"}, {["x"] = 6, ["meta"] = {["fields"] = {}, ["inventory"] = {}}, ["param2"] = 3, ["y"] = 4, ["z"] = 2, ["name"] = "xdecor:desertstone_tile"}, {["x"] = 6, ["meta"] = {["fields"] = {}, ["inventory"] = {}}, ["param2"] = 3, ["y"] = 4, ["z"] = 6, ["name"] = "xdecor:desertstone_tile"}, {["x"] = 6, ["meta"] = {["fields"] = {}, ["inventory"] = {}}, ["param2"] = 3, ["y"] = 5, ["z"] = 3, ["name"] = "xdecor:desertstone_tile"}, {["x"] = 6, ["meta"] = {["fields"] = {}, ["inventory"] = {}}, ["param2"] = 3, ["y"] = 5, ["z"] = 5, ["name"] = "xdecor:desertstone_tile"}, {["x"] = 6, ["meta"] = {["fields"] = {}, ["inventory"] = {}}, ["param2"] = 1, ["y"] = 6, ["z"] = 4, ["name"] = "xdecor:desertstone_tile"}, {["x"] = 7, ["meta"] = {["fields"] = {}, ["inventory"] = {}}, ["y"] = 0, ["z"] = 0, ["name"] = "rainbow:wood_white"}, {["x"] = 7, ["meta"] = {["fields"] = {}, ["inventory"] = {}}, ["y"] = 0, ["z"] = 1, ["name"] = "rainbow:wood_white"}, {["x"] = 7, ["meta"] = {["fields"] = {}, ["inventory"] = {}}, ["y"] = 0, ["z"] = 2, ["name"] = "rainbow:wood_white"}, {["x"] = 7, ["meta"] = {["fields"] = {}, ["inventory"] = {}}, ["y"] = 0, ["z"] = 3, ["name"] = "rainbow:wood_white"}, {["x"] = 7, ["meta"] = {["fields"] = {}, ["inventory"] = {}}, ["y"] = 0, ["z"] = 4, ["name"] = "rainbow:wood_white"}, {["x"] = 7, ["meta"] = {["fields"] = {}, ["inventory"] = {}}, ["y"] = 0, ["z"] = 5, ["name"] = "rainbow:wood_white"}, {["x"] = 7, ["meta"] = {["fields"] = {}, ["inventory"] = {}}, ["y"] = 0, ["z"] = 6, ["name"] = "rainbow:wood_white"}, {["x"] = 7, ["meta"] = {["fields"] = {}, ["inventory"] = {}}, ["y"] = 0, ["z"] = 7, ["name"] = "rainbow:wood_white"}, {["x"] = 7, ["meta"] = {["fields"] = {}, ["inventory"] = {}}, ["y"] = 0, ["z"] = 8, ["name"] = "rainbow:wood_white"}, {["x"] = 7, ["meta"] = {["fields"] = {}, ["inventory"] = {}}, ["param2"] = 3, ["y"] = 1, ["z"] = 0, ["name"] = "xdecor:desertstone_tile"}, {["x"] = 7, ["meta"] = {["fields"] = {["formspec"] = "size[8,7;]bgcolor[#080808BB;true]background[5,5;1,1;gui_formbg.png;true]listcolors[#00000069;#5A5A5A;#141318;#30434C;#FFF]list[context;books;0,0.3;8,2;]list[current_player;main;0,2.85;8,1;]list[current_player;main;0,4.08;8,3;8]listring[context;books]listring[current_player;main]image[0,2.85;1,1;gui_hb_bg.png]image[1,2.85;1,1;gui_hb_bg.png]image[2,2.85;1,1;gui_hb_bg.png]image[3,2.85;1,1;gui_hb_bg.png]image[4,2.85;1,1;gui_hb_bg.png]image[5,2.85;1,1;gui_hb_bg.png]image[6,2.85;1,1;gui_hb_bg.png]image[7,2.85;1,1;gui_hb_bg.png]image[0,0.3;1,1;default_bookshelf_slot.png]image[1,0.3;1,1;default_bookshelf_slot.png]image[2,0.3;1,1;default_bookshelf_slot.png]image[3,0.3;1,1;default_bookshelf_slot.png]image[4,0.3;1,1;default_bookshelf_slot.png]image[5,0.3;1,1;default_bookshelf_slot.png]image[6,0.3;1,1;default_bookshelf_slot.png]image[7,0.3;1,1;default_bookshelf_slot.png]image[0,1.3;1,1;default_bookshelf_slot.png]image[1,1.3;1,1;default_bookshelf_slot.png]image[2,1.3;1,1;default_bookshelf_slot.png]image[3,1.3;1,1;default_bookshelf_slot.png]image[4,1.3;1,1;default_bookshelf_slot.png]image[5,1.3;1,1;default_bookshelf_slot.png]image[6,1.3;1,1;default_bookshelf_slot.png]image[7,1.3;1,1;default_bookshelf_slot.png]"}, ["inventory"] = {["books"] = {"", "", "", "", "", "", "", "", "", "", "", "", "", "", "", ""}}}, ["y"] = 1, ["z"] = 2, ["name"] = "default:bookshelf"}, {["x"] = 7, ["meta"] = {["fields"] = {["formspec"] = "size[8,7;]bgcolor[#080808BB;true]background[5,5;1,1;gui_formbg.png;true]listcolors[#00000069;#5A5A5A;#141318;#30434C;#FFF]list[context;books;0,0.3;8,2;]list[current_player;main;0,2.85;8,1;]list[current_player;main;0,4.08;8,3;8]listring[context;books]listring[current_player;main]image[0,2.85;1,1;gui_hb_bg.png]image[1,2.85;1,1;gui_hb_bg.png]image[2,2.85;1,1;gui_hb_bg.png]image[3,2.85;1,1;gui_hb_bg.png]image[4,2.85;1,1;gui_hb_bg.png]image[5,2.85;1,1;gui_hb_bg.png]image[6,2.85;1,1;gui_hb_bg.png]image[7,2.85;1,1;gui_hb_bg.png]image[0,0.3;1,1;default_bookshelf_slot.png]image[1,0.3;1,1;default_bookshelf_slot.png]image[2,0.3;1,1;default_bookshelf_slot.png]image[3,0.3;1,1;default_bookshelf_slot.png]image[4,0.3;1,1;default_bookshelf_slot.png]image[5,0.3;1,1;default_bookshelf_slot.png]image[6,0.3;1,1;default_bookshelf_slot.png]image[7,0.3;1,1;default_bookshelf_slot.png]image[0,1.3;1,1;default_bookshelf_slot.png]image[1,1.3;1,1;default_bookshelf_slot.png]image[2,1.3;1,1;default_bookshelf_slot.png]image[3,1.3;1,1;default_bookshelf_slot.png]image[4,1.3;1,1;default_bookshelf_slot.png]image[5,1.3;1,1;default_bookshelf_slot.png]image[6,1.3;1,1;default_bookshelf_slot.png]image[7,1.3;1,1;default_bookshelf_slot.png]"}, ["inventory"] = {["books"] = {"", "", "", "", "", "", "", "", "", "", "", "", "", "", "", ""}}}, ["y"] = 1, ["z"] = 6, ["name"] = "default:bookshelf"}, {["x"] = 7, ["meta"] = {["fields"] = {}, ["inventory"] = {}}, ["y"] = 1, ["z"] = 8, ["name"] = "xdecor:desertstone_tile"}, {["x"] = 7, ["meta"] = {["fields"] = {}, ["inventory"] = {}}, ["param2"] = 1, ["y"] = 2, ["z"] = 0, ["name"] = "xdecor:desertstone_tile"}, {["x"] = 7, ["meta"] = {["fields"] = {["formspec"] = "size[8,7;]bgcolor[#080808BB;true]background[5,5;1,1;gui_formbg.png;true]listcolors[#00000069;#5A5A5A;#141318;#30434C;#FFF]list[context;books;0,0.3;8,2;]list[current_player;main;0,2.85;8,1;]list[current_player;main;0,4.08;8,3;8]listring[context;books]listring[current_player;main]image[0,2.85;1,1;gui_hb_bg.png]image[1,2.85;1,1;gui_hb_bg.png]image[2,2.85;1,1;gui_hb_bg.png]image[3,2.85;1,1;gui_hb_bg.png]image[4,2.85;1,1;gui_hb_bg.png]image[5,2.85;1,1;gui_hb_bg.png]image[6,2.85;1,1;gui_hb_bg.png]image[7,2.85;1,1;gui_hb_bg.png]image[0,0.3;1,1;default_bookshelf_slot.png]image[1,0.3;1,1;default_bookshelf_slot.png]image[2,0.3;1,1;default_bookshelf_slot.png]image[3,0.3;1,1;default_bookshelf_slot.png]image[4,0.3;1,1;default_bookshelf_slot.png]image[5,0.3;1,1;default_bookshelf_slot.png]image[6,0.3;1,1;default_bookshelf_slot.png]image[7,0.3;1,1;default_bookshelf_slot.png]image[0,1.3;1,1;default_bookshelf_slot.png]image[1,1.3;1,1;default_bookshelf_slot.png]image[2,1.3;1,1;default_bookshelf_slot.png]image[3,1.3;1,1;default_bookshelf_slot.png]image[4,1.3;1,1;default_bookshelf_slot.png]image[5,1.3;1,1;default_bookshelf_slot.png]image[6,1.3;1,1;default_bookshelf_slot.png]image[7,1.3;1,1;default_bookshelf_slot.png]"}, ["inventory"] = {["books"] = {"", "", "", "", "", "", "", "", "", "", "", "", "", "", "", ""}}}, ["y"] = 2, ["z"] = 2, ["name"] = "default:bookshelf"}, {["x"] = 7, ["meta"] = {["fields"] = {["formspec"] = "size[8,7;]bgcolor[#080808BB;true]background[5,5;1,1;gui_formbg.png;true]listcolors[#00000069;#5A5A5A;#141318;#30434C;#FFF]list[context;books;0,0.3;8,2;]list[current_player;main;0,2.85;8,1;]list[current_player;main;0,4.08;8,3;8]listring[context;books]listring[current_player;main]image[0,2.85;1,1;gui_hb_bg.png]image[1,2.85;1,1;gui_hb_bg.png]image[2,2.85;1,1;gui_hb_bg.png]image[3,2.85;1,1;gui_hb_bg.png]image[4,2.85;1,1;gui_hb_bg.png]image[5,2.85;1,1;gui_hb_bg.png]image[6,2.85;1,1;gui_hb_bg.png]image[7,2.85;1,1;gui_hb_bg.png]image[0,0.3;1,1;default_bookshelf_slot.png]image[1,0.3;1,1;default_bookshelf_slot.png]image[2,0.3;1,1;default_bookshelf_slot.png]image[3,0.3;1,1;default_bookshelf_slot.png]image[4,0.3;1,1;default_bookshelf_slot.png]image[5,0.3;1,1;default_bookshelf_slot.png]image[6,0.3;1,1;default_bookshelf_slot.png]image[7,0.3;1,1;default_bookshelf_slot.png]image[0,1.3;1,1;default_bookshelf_slot.png]image[1,1.3;1,1;default_bookshelf_slot.png]image[2,1.3;1,1;default_bookshelf_slot.png]image[3,1.3;1,1;default_bookshelf_slot.png]image[4,1.3;1,1;default_bookshelf_slot.png]image[5,1.3;1,1;default_bookshelf_slot.png]image[6,1.3;1,1;default_bookshelf_slot.png]image[7,1.3;1,1;default_bookshelf_slot.png]"}, ["inventory"] = {["books"] = {"", "", "", "", "", "", "", "", "", "", "", "", "", "", "", ""}}}, ["y"] = 2, ["z"] = 6, ["name"] = "default:bookshelf"}, {["x"] = 7, ["meta"] = {["fields"] = {}, ["inventory"] = {}}, ["y"] = 2, ["z"] = 8, ["name"] = "xdecor:desertstone_tile"}, {["x"] = 7, ["meta"] = {["fields"] = {}, ["inventory"] = {}}, ["y"] = 3, ["param1"] = 79, ["z"] = 1, ["name"] = "xdecor:woodframed_glass"}, {["x"] = 7, ["meta"] = {["fields"] = {}, ["inventory"] = {}}, ["y"] = 3, ["param1"] = 47, ["z"] = 7, ["name"] = "xdecor:woodframed_glass"}, {["x"] = 7, ["meta"] = {["fields"] = {}, ["inventory"] = {}}, ["param2"] = 3, ["y"] = 4, ["z"] = 2, ["name"] = "xdecor:desertstone_tile"}, {["x"] = 7, ["meta"] = {["fields"] = {}, ["inventory"] = {}}, ["param2"] = 3, ["y"] = 4, ["z"] = 6, ["name"] = "xdecor:desertstone_tile"}, {["x"] = 7, ["meta"] = {["fields"] = {}, ["inventory"] = {}}, ["param2"] = 3, ["y"] = 5, ["z"] = 3, ["name"] = "xdecor:desertstone_tile"}, {["x"] = 7, ["meta"] = {["fields"] = {}, ["inventory"] = {}}, ["param2"] = 3, ["y"] = 5, ["z"] = 5, ["name"] = "xdecor:desertstone_tile"}, {["x"] = 7, ["meta"] = {["fields"] = {}, ["inventory"] = {}}, ["param2"] = 1, ["y"] = 6, ["z"] = 4, ["name"] = "xdecor:desertstone_tile"}, {["x"] = 8, ["meta"] = {["fields"] = {}, ["inventory"] = {}}, ["y"] = 0, ["z"] = 0, ["name"] = "rainbow:wood_white"}, {["x"] = 8, ["meta"] = {["fields"] = {}, ["inventory"] = {}}, ["y"] = 0, ["z"] = 1, ["name"] = "rainbow:wood_white"}, {["x"] = 8, ["meta"] = {["fields"] = {}, ["inventory"] = {}}, ["y"] = 0, ["z"] = 2, ["name"] = "rainbow:wood_white"}, {["x"] = 8, ["meta"] = {["fields"] = {}, ["inventory"] = {}}, ["y"] = 0, ["z"] = 3, ["name"] = "rainbow:wood_white"}, {["x"] = 8, ["meta"] = {["fields"] = {}, ["inventory"] = {}}, ["y"] = 0, ["z"] = 4, ["name"] = "rainbow:wood_white"}, {["x"] = 8, ["meta"] = {["fields"] = {}, ["inventory"] = {}}, ["y"] = 0, ["z"] = 5, ["name"] = "rainbow:wood_white"}, {["x"] = 8, ["meta"] = {["fields"] = {}, ["inventory"] = {}}, ["y"] = 0, ["z"] = 6, ["name"] = "rainbow:wood_white"}, {["x"] = 8, ["meta"] = {["fields"] = {}, ["inventory"] = {}}, ["y"] = 0, ["z"] = 7, ["name"] = "rainbow:wood_white"}, {["x"] = 8, ["meta"] = {["fields"] = {}, ["inventory"] = {}}, ["y"] = 0, ["z"] = 8, ["name"] = "rainbow:wood_white"}, {["x"] = 8, ["meta"] = {["fields"] = {}, ["inventory"] = {}}, ["param2"] = 3, ["y"] = 1, ["z"] = 0, ["name"] = "xdecor:desertstone_tile"}, {["x"] = 8, ["meta"] = {["fields"] = {["formspec"] = "size[8,7;]bgcolor[#080808BB;true]background[5,5;1,1;gui_formbg.png;true]listcolors[#00000069;#5A5A5A;#141318;#30434C;#FFF]list[context;books;0,0.3;8,2;]list[current_player;main;0,2.85;8,1;]list[current_player;main;0,4.08;8,3;8]listring[context;books]listring[current_player;main]image[0,2.85;1,1;gui_hb_bg.png]image[1,2.85;1,1;gui_hb_bg.png]image[2,2.85;1,1;gui_hb_bg.png]image[3,2.85;1,1;gui_hb_bg.png]image[4,2.85;1,1;gui_hb_bg.png]image[5,2.85;1,1;gui_hb_bg.png]image[6,2.85;1,1;gui_hb_bg.png]image[7,2.85;1,1;gui_hb_bg.png]image[0,0.3;1,1;default_bookshelf_slot.png]image[1,0.3;1,1;default_bookshelf_slot.png]image[2,0.3;1,1;default_bookshelf_slot.png]image[3,0.3;1,1;default_bookshelf_slot.png]image[4,0.3;1,1;default_bookshelf_slot.png]image[5,0.3;1,1;default_bookshelf_slot.png]image[6,0.3;1,1;default_bookshelf_slot.png]image[7,0.3;1,1;default_bookshelf_slot.png]image[0,1.3;1,1;default_bookshelf_slot.png]image[1,1.3;1,1;default_bookshelf_slot.png]image[2,1.3;1,1;default_bookshelf_slot.png]image[3,1.3;1,1;default_bookshelf_slot.png]image[4,1.3;1,1;default_bookshelf_slot.png]image[5,1.3;1,1;default_bookshelf_slot.png]image[6,1.3;1,1;default_bookshelf_slot.png]image[7,1.3;1,1;default_bookshelf_slot.png]"}, ["inventory"] = {["books"] = {"", "", "", "", "", "", "", "", "", "", "", "", "", "", "", ""}}}, ["y"] = 1, ["z"] = 2, ["name"] = "default:bookshelf"}, {["x"] = 8, ["meta"] = {["fields"] = {["formspec"] = "size[8,7;]bgcolor[#080808BB;true]background[5,5;1,1;gui_formbg.png;true]listcolors[#00000069;#5A5A5A;#141318;#30434C;#FFF]list[context;books;0,0.3;8,2;]list[current_player;main;0,2.85;8,1;]list[current_player;main;0,4.08;8,3;8]listring[context;books]listring[current_player;main]image[0,2.85;1,1;gui_hb_bg.png]image[1,2.85;1,1;gui_hb_bg.png]image[2,2.85;1,1;gui_hb_bg.png]image[3,2.85;1,1;gui_hb_bg.png]image[4,2.85;1,1;gui_hb_bg.png]image[5,2.85;1,1;gui_hb_bg.png]image[6,2.85;1,1;gui_hb_bg.png]image[7,2.85;1,1;gui_hb_bg.png]image[0,0.3;1,1;default_bookshelf_slot.png]image[1,0.3;1,1;default_bookshelf_slot.png]image[2,0.3;1,1;default_bookshelf_slot.png]image[3,0.3;1,1;default_bookshelf_slot.png]image[4,0.3;1,1;default_bookshelf_slot.png]image[5,0.3;1,1;default_bookshelf_slot.png]image[6,0.3;1,1;default_bookshelf_slot.png]image[7,0.3;1,1;default_bookshelf_slot.png]image[0,1.3;1,1;default_bookshelf_slot.png]image[1,1.3;1,1;default_bookshelf_slot.png]image[2,1.3;1,1;default_bookshelf_slot.png]image[3,1.3;1,1;default_bookshelf_slot.png]image[4,1.3;1,1;default_bookshelf_slot.png]image[5,1.3;1,1;default_bookshelf_slot.png]image[6,1.3;1,1;default_bookshelf_slot.png]image[7,1.3;1,1;default_bookshelf_slot.png]"}, ["inventory"] = {["books"] = {"", "", "", "", "", "", "", "", "", "", "", "", "", "", "", ""}}}, ["param2"] = 2, ["y"] = 1, ["z"] = 4, ["name"] = "default:bookshelf"}, {["x"] = 8, ["meta"] = {["fields"] = {["formspec"] = "size[8,7;]bgcolor[#080808BB;true]background[5,5;1,1;gui_formbg.png;true]listcolors[#00000069;#5A5A5A;#141318;#30434C;#FFF]list[context;books;0,0.3;8,2;]list[current_player;main;0,2.85;8,1;]list[current_player;main;0,4.08;8,3;8]listring[context;books]listring[current_player;main]image[0,2.85;1,1;gui_hb_bg.png]image[1,2.85;1,1;gui_hb_bg.png]image[2,2.85;1,1;gui_hb_bg.png]image[3,2.85;1,1;gui_hb_bg.png]image[4,2.85;1,1;gui_hb_bg.png]image[5,2.85;1,1;gui_hb_bg.png]image[6,2.85;1,1;gui_hb_bg.png]image[7,2.85;1,1;gui_hb_bg.png]image[0,0.3;1,1;default_bookshelf_slot.png]image[1,0.3;1,1;default_bookshelf_slot.png]image[2,0.3;1,1;default_bookshelf_slot.png]image[3,0.3;1,1;default_bookshelf_slot.png]image[4,0.3;1,1;default_bookshelf_slot.png]image[5,0.3;1,1;default_bookshelf_slot.png]image[6,0.3;1,1;default_bookshelf_slot.png]image[7,0.3;1,1;default_bookshelf_slot.png]image[0,1.3;1,1;default_bookshelf_slot.png]image[1,1.3;1,1;default_bookshelf_slot.png]image[2,1.3;1,1;default_bookshelf_slot.png]image[3,1.3;1,1;default_bookshelf_slot.png]image[4,1.3;1,1;default_bookshelf_slot.png]image[5,1.3;1,1;default_bookshelf_slot.png]image[6,1.3;1,1;default_bookshelf_slot.png]image[7,1.3;1,1;default_bookshelf_slot.png]"}, ["inventory"] = {["books"] = {"", "", "", "", "", "", "", "", "", "", "", "", "", "", "", ""}}}, ["y"] = 1, ["z"] = 6, ["name"] = "default:bookshelf"}, {["x"] = 8, ["meta"] = {["fields"] = {}, ["inventory"] = {}}, ["y"] = 1, ["z"] = 8, ["name"] = "xdecor:desertstone_tile"}, {["x"] = 8, ["meta"] = {["fields"] = {}, ["inventory"] = {}}, ["param2"] = 1, ["y"] = 2, ["z"] = 0, ["name"] = "xdecor:desertstone_tile"}, {["x"] = 8, ["meta"] = {["fields"] = {["formspec"] = "size[8,7;]bgcolor[#080808BB;true]background[5,5;1,1;gui_formbg.png;true]listcolors[#00000069;#5A5A5A;#141318;#30434C;#FFF]list[context;books;0,0.3;8,2;]list[current_player;main;0,2.85;8,1;]list[current_player;main;0,4.08;8,3;8]listring[context;books]listring[current_player;main]image[0,2.85;1,1;gui_hb_bg.png]image[1,2.85;1,1;gui_hb_bg.png]image[2,2.85;1,1;gui_hb_bg.png]image[3,2.85;1,1;gui_hb_bg.png]image[4,2.85;1,1;gui_hb_bg.png]image[5,2.85;1,1;gui_hb_bg.png]image[6,2.85;1,1;gui_hb_bg.png]image[7,2.85;1,1;gui_hb_bg.png]image[0,0.3;1,1;default_bookshelf_slot.png]image[1,0.3;1,1;default_bookshelf_slot.png]image[2,0.3;1,1;default_bookshelf_slot.png]image[3,0.3;1,1;default_bookshelf_slot.png]image[4,0.3;1,1;default_bookshelf_slot.png]image[5,0.3;1,1;default_bookshelf_slot.png]image[6,0.3;1,1;default_bookshelf_slot.png]image[7,0.3;1,1;default_bookshelf_slot.png]image[0,1.3;1,1;default_bookshelf_slot.png]image[1,1.3;1,1;default_bookshelf_slot.png]image[2,1.3;1,1;default_bookshelf_slot.png]image[3,1.3;1,1;default_bookshelf_slot.png]image[4,1.3;1,1;default_bookshelf_slot.png]image[5,1.3;1,1;default_bookshelf_slot.png]image[6,1.3;1,1;default_bookshelf_slot.png]image[7,1.3;1,1;default_bookshelf_slot.png]"}, ["inventory"] = {["books"] = {"", "", "", "", "", "", "", "", "", "", "", "", "", "", "", ""}}}, ["y"] = 2, ["z"] = 2, ["name"] = "default:bookshelf"}, {["x"] = 8, ["meta"] = {["fields"] = {["formspec"] = "size[8,7;]bgcolor[#080808BB;true]background[5,5;1,1;gui_formbg.png;true]listcolors[#00000069;#5A5A5A;#141318;#30434C;#FFF]list[context;books;0,0.3;8,2;]list[current_player;main;0,2.85;8,1;]list[current_player;main;0,4.08;8,3;8]listring[context;books]listring[current_player;main]image[0,2.85;1,1;gui_hb_bg.png]image[1,2.85;1,1;gui_hb_bg.png]image[2,2.85;1,1;gui_hb_bg.png]image[3,2.85;1,1;gui_hb_bg.png]image[4,2.85;1,1;gui_hb_bg.png]image[5,2.85;1,1;gui_hb_bg.png]image[6,2.85;1,1;gui_hb_bg.png]image[7,2.85;1,1;gui_hb_bg.png]image[0,0.3;1,1;default_bookshelf_slot.png]image[1,0.3;1,1;default_bookshelf_slot.png]image[2,0.3;1,1;default_bookshelf_slot.png]image[3,0.3;1,1;default_bookshelf_slot.png]image[4,0.3;1,1;default_bookshelf_slot.png]image[5,0.3;1,1;default_bookshelf_slot.png]image[6,0.3;1,1;default_bookshelf_slot.png]image[7,0.3;1,1;default_bookshelf_slot.png]image[0,1.3;1,1;default_bookshelf_slot.png]image[1,1.3;1,1;default_bookshelf_slot.png]image[2,1.3;1,1;default_bookshelf_slot.png]image[3,1.3;1,1;default_bookshelf_slot.png]image[4,1.3;1,1;default_bookshelf_slot.png]image[5,1.3;1,1;default_bookshelf_slot.png]image[6,1.3;1,1;default_bookshelf_slot.png]image[7,1.3;1,1;default_bookshelf_slot.png]"}, ["inventory"] = {["books"] = {"", "", "", "", "", "", "", "", "", "", "", "", "", "", "", ""}}}, ["param2"] = 2, ["y"] = 2, ["z"] = 4, ["name"] = "default:bookshelf"}, {["x"] = 8, ["meta"] = {["fields"] = {["formspec"] = "size[8,7;]bgcolor[#080808BB;true]background[5,5;1,1;gui_formbg.png;true]listcolors[#00000069;#5A5A5A;#141318;#30434C;#FFF]list[context;books;0,0.3;8,2;]list[current_player;main;0,2.85;8,1;]list[current_player;main;0,4.08;8,3;8]listring[context;books]listring[current_player;main]image[0,2.85;1,1;gui_hb_bg.png]image[1,2.85;1,1;gui_hb_bg.png]image[2,2.85;1,1;gui_hb_bg.png]image[3,2.85;1,1;gui_hb_bg.png]image[4,2.85;1,1;gui_hb_bg.png]image[5,2.85;1,1;gui_hb_bg.png]image[6,2.85;1,1;gui_hb_bg.png]image[7,2.85;1,1;gui_hb_bg.png]image[0,0.3;1,1;default_bookshelf_slot.png]image[1,0.3;1,1;default_bookshelf_slot.png]image[2,0.3;1,1;default_bookshelf_slot.png]image[3,0.3;1,1;default_bookshelf_slot.png]image[4,0.3;1,1;default_bookshelf_slot.png]image[5,0.3;1,1;default_bookshelf_slot.png]image[6,0.3;1,1;default_bookshelf_slot.png]image[7,0.3;1,1;default_bookshelf_slot.png]image[0,1.3;1,1;default_bookshelf_slot.png]image[1,1.3;1,1;default_bookshelf_slot.png]image[2,1.3;1,1;default_bookshelf_slot.png]image[3,1.3;1,1;default_bookshelf_slot.png]image[4,1.3;1,1;default_bookshelf_slot.png]image[5,1.3;1,1;default_bookshelf_slot.png]image[6,1.3;1,1;default_bookshelf_slot.png]image[7,1.3;1,1;default_bookshelf_slot.png]"}, ["inventory"] = {["books"] = {"", "", "", "", "", "", "", "", "", "", "", "", "", "", "", ""}}}, ["y"] = 2, ["z"] = 6, ["name"] = "default:bookshelf"}, {["x"] = 8, ["meta"] = {["fields"] = {}, ["inventory"] = {}}, ["param2"] = 2, ["y"] = 2, ["z"] = 8, ["name"] = "xdecor:desertstone_tile"}, {["x"] = 8, ["meta"] = {["fields"] = {}, ["inventory"] = {}}, ["y"] = 3, ["param1"] = 63, ["z"] = 1, ["name"] = "xdecor:woodframed_glass"}, {["x"] = 8, ["meta"] = {["fields"] = {}, ["inventory"] = {}}, ["y"] = 3, ["param1"] = 31, ["z"] = 7, ["name"] = "xdecor:woodframed_glass"}, {["x"] = 8, ["meta"] = {["fields"] = {}, ["inventory"] = {}}, ["param2"] = 3, ["y"] = 4, ["z"] = 2, ["name"] = "xdecor:desertstone_tile"}, {["x"] = 8, ["meta"] = {["fields"] = {}, ["inventory"] = {}}, ["param2"] = 3, ["y"] = 4, ["z"] = 6, ["name"] = "xdecor:desertstone_tile"}, {["x"] = 8, ["meta"] = {["fields"] = {}, ["inventory"] = {}}, ["param2"] = 3, ["y"] = 5, ["z"] = 3, ["name"] = "xdecor:desertstone_tile"}, {["x"] = 8, ["meta"] = {["fields"] = {}, ["inventory"] = {}}, ["param2"] = 3, ["y"] = 5, ["z"] = 5, ["name"] = "xdecor:desertstone_tile"}, {["x"] = 8, ["meta"] = {["fields"] = {}, ["inventory"] = {}}, ["param2"] = 3, ["y"] = 6, ["z"] = 4, ["name"] = "xdecor:desertstone_tile"}, {["x"] = 9, ["meta"] = {["fields"] = {}, ["inventory"] = {}}, ["y"] = 0, ["z"] = 0, ["name"] = "rainbow:wood_white"}, {["x"] = 9, ["meta"] = {["fields"] = {}, ["inventory"] = {}}, ["y"] = 0, ["z"] = 1, ["name"] = "rainbow:wood_white"}, {["x"] = 9, ["meta"] = {["fields"] = {}, ["inventory"] = {}}, ["y"] = 0, ["z"] = 2, ["name"] = "rainbow:wood_white"}, {["x"] = 9, ["meta"] = {["fields"] = {}, ["inventory"] = {}}, ["y"] = 0, ["z"] = 3, ["name"] = "rainbow:wood_white"}, {["x"] = 9, ["meta"] = {["fields"] = {}, ["inventory"] = {}}, ["y"] = 0, ["z"] = 4, ["name"] = "rainbow:wood_white"}, {["x"] = 9, ["meta"] = {["fields"] = {}, ["inventory"] = {}}, ["y"] = 0, ["z"] = 5, ["name"] = "rainbow:wood_white"}, {["x"] = 9, ["meta"] = {["fields"] = {}, ["inventory"] = {}}, ["y"] = 0, ["z"] = 6, ["name"] = "rainbow:wood_white"}, {["x"] = 9, ["meta"] = {["fields"] = {}, ["inventory"] = {}}, ["y"] = 0, ["z"] = 7, ["name"] = "rainbow:wood_white"}, {["x"] = 9, ["meta"] = {["fields"] = {}, ["inventory"] = {}}, ["y"] = 0, ["z"] = 8, ["name"] = "rainbow:wood_white"}, {["x"] = 9, ["meta"] = {["fields"] = {}, ["inventory"] = {}}, ["param2"] = 3, ["y"] = 1, ["z"] = 0, ["name"] = "xdecor:desertstone_tile"}, {["x"] = 9, ["meta"] = {["fields"] = {["formspec"] = "size[8,7;]bgcolor[#080808BB;true]background[5,5;1,1;gui_formbg.png;true]listcolors[#00000069;#5A5A5A;#141318;#30434C;#FFF]list[context;books;0,0.3;8,2;]list[current_player;main;0,2.85;8,1;]list[current_player;main;0,4.08;8,3;8]listring[context;books]listring[current_player;main]image[0,2.85;1,1;gui_hb_bg.png]image[1,2.85;1,1;gui_hb_bg.png]image[2,2.85;1,1;gui_hb_bg.png]image[3,2.85;1,1;gui_hb_bg.png]image[4,2.85;1,1;gui_hb_bg.png]image[5,2.85;1,1;gui_hb_bg.png]image[6,2.85;1,1;gui_hb_bg.png]image[7,2.85;1,1;gui_hb_bg.png]image[0,0.3;1,1;default_bookshelf_slot.png]image[1,0.3;1,1;default_bookshelf_slot.png]image[2,0.3;1,1;default_bookshelf_slot.png]image[3,0.3;1,1;default_bookshelf_slot.png]image[4,0.3;1,1;default_bookshelf_slot.png]image[5,0.3;1,1;default_bookshelf_slot.png]image[6,0.3;1,1;default_bookshelf_slot.png]image[7,0.3;1,1;default_bookshelf_slot.png]image[0,1.3;1,1;default_bookshelf_slot.png]image[1,1.3;1,1;default_bookshelf_slot.png]image[2,1.3;1,1;default_bookshelf_slot.png]image[3,1.3;1,1;default_bookshelf_slot.png]image[4,1.3;1,1;default_bookshelf_slot.png]image[5,1.3;1,1;default_bookshelf_slot.png]image[6,1.3;1,1;default_bookshelf_slot.png]image[7,1.3;1,1;default_bookshelf_slot.png]"}, ["inventory"] = {["books"] = {"", "", "", "", "", "", "", "", "", "", "", "", "", "", "", ""}}}, ["y"] = 1, ["z"] = 2, ["name"] = "default:bookshelf"}, {["x"] = 9, ["meta"] = {["fields"] = {["formspec"] = "size[8,7;]bgcolor[#080808BB;true]background[5,5;1,1;gui_formbg.png;true]listcolors[#00000069;#5A5A5A;#141318;#30434C;#FFF]list[context;books;0,0.3;8,2;]list[current_player;main;0,2.85;8,1;]list[current_player;main;0,4.08;8,3;8]listring[context;books]listring[current_player;main]image[0,2.85;1,1;gui_hb_bg.png]image[1,2.85;1,1;gui_hb_bg.png]image[2,2.85;1,1;gui_hb_bg.png]image[3,2.85;1,1;gui_hb_bg.png]image[4,2.85;1,1;gui_hb_bg.png]image[5,2.85;1,1;gui_hb_bg.png]image[6,2.85;1,1;gui_hb_bg.png]image[7,2.85;1,1;gui_hb_bg.png]image[0,0.3;1,1;default_bookshelf_slot.png]image[1,0.3;1,1;default_bookshelf_slot.png]image[2,0.3;1,1;default_bookshelf_slot.png]image[3,0.3;1,1;default_bookshelf_slot.png]image[4,0.3;1,1;default_bookshelf_slot.png]image[5,0.3;1,1;default_bookshelf_slot.png]image[6,0.3;1,1;default_bookshelf_slot.png]image[7,0.3;1,1;default_bookshelf_slot.png]image[0,1.3;1,1;default_bookshelf_slot.png]image[1,1.3;1,1;default_bookshelf_slot.png]image[2,1.3;1,1;default_bookshelf_slot.png]image[3,1.3;1,1;default_bookshelf_slot.png]image[4,1.3;1,1;default_bookshelf_slot.png]image[5,1.3;1,1;default_bookshelf_slot.png]image[6,1.3;1,1;default_bookshelf_slot.png]image[7,1.3;1,1;default_bookshelf_slot.png]"}, ["inventory"] = {["books"] = {"", "", "", "", "", "", "", "", "", "", "", "", "", "", "", ""}}}, ["y"] = 1, ["z"] = 4, ["name"] = "default:bookshelf"}, {["x"] = 9, ["meta"] = {["fields"] = {["formspec"] = "size[8,7;]bgcolor[#080808BB;true]background[5,5;1,1;gui_formbg.png;true]listcolors[#00000069;#5A5A5A;#141318;#30434C;#FFF]list[context;books;0,0.3;8,2;]list[current_player;main;0,2.85;8,1;]list[current_player;main;0,4.08;8,3;8]listring[context;books]listring[current_player;main]image[0,2.85;1,1;gui_hb_bg.png]image[1,2.85;1,1;gui_hb_bg.png]image[2,2.85;1,1;gui_hb_bg.png]image[3,2.85;1,1;gui_hb_bg.png]image[4,2.85;1,1;gui_hb_bg.png]image[5,2.85;1,1;gui_hb_bg.png]image[6,2.85;1,1;gui_hb_bg.png]image[7,2.85;1,1;gui_hb_bg.png]image[0,0.3;1,1;default_bookshelf_slot.png]image[1,0.3;1,1;default_bookshelf_slot.png]image[2,0.3;1,1;default_bookshelf_slot.png]image[3,0.3;1,1;default_bookshelf_slot.png]image[4,0.3;1,1;default_bookshelf_slot.png]image[5,0.3;1,1;default_bookshelf_slot.png]image[6,0.3;1,1;default_bookshelf_slot.png]image[7,0.3;1,1;default_bookshelf_slot.png]image[0,1.3;1,1;default_bookshelf_slot.png]image[1,1.3;1,1;default_bookshelf_slot.png]image[2,1.3;1,1;default_bookshelf_slot.png]image[3,1.3;1,1;default_bookshelf_slot.png]image[4,1.3;1,1;default_bookshelf_slot.png]image[5,1.3;1,1;default_bookshelf_slot.png]image[6,1.3;1,1;default_bookshelf_slot.png]image[7,1.3;1,1;default_bookshelf_slot.png]"}, ["inventory"] = {["books"] = {"", "", "", "", "", "", "", "", "", "", "", "", "", "", "", ""}}}, ["y"] = 1, ["z"] = 6, ["name"] = "default:bookshelf"}, {["x"] = 9, ["meta"] = {["fields"] = {}, ["inventory"] = {}}, ["param2"] = 1, ["y"] = 1, ["z"] = 8, ["name"] = "xdecor:desertstone_tile"}, {["x"] = 9, ["meta"] = {["fields"] = {}, ["inventory"] = {}}, ["param2"] = 1, ["y"] = 2, ["z"] = 0, ["name"] = "xdecor:desertstone_tile"}, {["x"] = 9, ["meta"] = {["fields"] = {["formspec"] = "size[8,7;]bgcolor[#080808BB;true]background[5,5;1,1;gui_formbg.png;true]listcolors[#00000069;#5A5A5A;#141318;#30434C;#FFF]list[context;books;0,0.3;8,2;]list[current_player;main;0,2.85;8,1;]list[current_player;main;0,4.08;8,3;8]listring[context;books]listring[current_player;main]image[0,2.85;1,1;gui_hb_bg.png]image[1,2.85;1,1;gui_hb_bg.png]image[2,2.85;1,1;gui_hb_bg.png]image[3,2.85;1,1;gui_hb_bg.png]image[4,2.85;1,1;gui_hb_bg.png]image[5,2.85;1,1;gui_hb_bg.png]image[6,2.85;1,1;gui_hb_bg.png]image[7,2.85;1,1;gui_hb_bg.png]image[0,0.3;1,1;default_bookshelf_slot.png]image[1,0.3;1,1;default_bookshelf_slot.png]image[2,0.3;1,1;default_bookshelf_slot.png]image[3,0.3;1,1;default_bookshelf_slot.png]image[4,0.3;1,1;default_bookshelf_slot.png]image[5,0.3;1,1;default_bookshelf_slot.png]image[6,0.3;1,1;default_bookshelf_slot.png]image[7,0.3;1,1;default_bookshelf_slot.png]image[0,1.3;1,1;default_bookshelf_slot.png]image[1,1.3;1,1;default_bookshelf_slot.png]image[2,1.3;1,1;default_bookshelf_slot.png]image[3,1.3;1,1;default_bookshelf_slot.png]image[4,1.3;1,1;default_bookshelf_slot.png]image[5,1.3;1,1;default_bookshelf_slot.png]image[6,1.3;1,1;default_bookshelf_slot.png]image[7,1.3;1,1;default_bookshelf_slot.png]"}, ["inventory"] = {["books"] = {"", "", "", "", "", "", "", "", "", "", "", "", "", "", "", ""}}}, ["y"] = 2, ["z"] = 2, ["name"] = "default:bookshelf"}, {["x"] = 9, ["meta"] = {["fields"] = {["formspec"] = "size[8,7;]bgcolor[#080808BB;true]background[5,5;1,1;gui_formbg.png;true]listcolors[#00000069;#5A5A5A;#141318;#30434C;#FFF]list[context;books;0,0.3;8,2;]list[current_player;main;0,2.85;8,1;]list[current_player;main;0,4.08;8,3;8]listring[context;books]listring[current_player;main]image[0,2.85;1,1;gui_hb_bg.png]image[1,2.85;1,1;gui_hb_bg.png]image[2,2.85;1,1;gui_hb_bg.png]image[3,2.85;1,1;gui_hb_bg.png]image[4,2.85;1,1;gui_hb_bg.png]image[5,2.85;1,1;gui_hb_bg.png]image[6,2.85;1,1;gui_hb_bg.png]image[7,2.85;1,1;gui_hb_bg.png]image[0,0.3;1,1;default_bookshelf_slot.png]image[1,0.3;1,1;default_bookshelf_slot.png]image[2,0.3;1,1;default_bookshelf_slot.png]image[3,0.3;1,1;default_bookshelf_slot.png]image[4,0.3;1,1;default_bookshelf_slot.png]image[5,0.3;1,1;default_bookshelf_slot.png]image[6,0.3;1,1;default_bookshelf_slot.png]image[7,0.3;1,1;default_bookshelf_slot.png]image[0,1.3;1,1;default_bookshelf_slot.png]image[1,1.3;1,1;default_bookshelf_slot.png]image[2,1.3;1,1;default_bookshelf_slot.png]image[3,1.3;1,1;default_bookshelf_slot.png]image[4,1.3;1,1;default_bookshelf_slot.png]image[5,1.3;1,1;default_bookshelf_slot.png]image[6,1.3;1,1;default_bookshelf_slot.png]image[7,1.3;1,1;default_bookshelf_slot.png]"}, ["inventory"] = {["books"] = {"", "", "", "", "", "", "", "", "", "", "", "", "", "", "", ""}}}, ["y"] = 2, ["z"] = 4, ["name"] = "default:bookshelf"}, {["x"] = 9, ["meta"] = {["fields"] = {["formspec"] = "size[8,7;]bgcolor[#080808BB;true]background[5,5;1,1;gui_formbg.png;true]listcolors[#00000069;#5A5A5A;#141318;#30434C;#FFF]list[context;books;0,0.3;8,2;]list[current_player;main;0,2.85;8,1;]list[current_player;main;0,4.08;8,3;8]listring[context;books]listring[current_player;main]image[0,2.85;1,1;gui_hb_bg.png]image[1,2.85;1,1;gui_hb_bg.png]image[2,2.85;1,1;gui_hb_bg.png]image[3,2.85;1,1;gui_hb_bg.png]image[4,2.85;1,1;gui_hb_bg.png]image[5,2.85;1,1;gui_hb_bg.png]image[6,2.85;1,1;gui_hb_bg.png]image[7,2.85;1,1;gui_hb_bg.png]image[0,0.3;1,1;default_bookshelf_slot.png]image[1,0.3;1,1;default_bookshelf_slot.png]image[2,0.3;1,1;default_bookshelf_slot.png]image[3,0.3;1,1;default_bookshelf_slot.png]image[4,0.3;1,1;default_bookshelf_slot.png]image[5,0.3;1,1;default_bookshelf_slot.png]image[6,0.3;1,1;default_bookshelf_slot.png]image[7,0.3;1,1;default_bookshelf_slot.png]image[0,1.3;1,1;default_bookshelf_slot.png]image[1,1.3;1,1;default_bookshelf_slot.png]image[2,1.3;1,1;default_bookshelf_slot.png]image[3,1.3;1,1;default_bookshelf_slot.png]image[4,1.3;1,1;default_bookshelf_slot.png]image[5,1.3;1,1;default_bookshelf_slot.png]image[6,1.3;1,1;default_bookshelf_slot.png]image[7,1.3;1,1;default_bookshelf_slot.png]"}, ["inventory"] = {["books"] = {"", "", "", "", "", "", "", "", "", "", "", "", "", "", "", ""}}}, ["y"] = 2, ["z"] = 6, ["name"] = "default:bookshelf"}, {["x"] = 9, ["meta"] = {["fields"] = {}, ["inventory"] = {}}, ["param2"] = 2, ["y"] = 2, ["z"] = 8, ["name"] = "xdecor:desertstone_tile"}, {["x"] = 9, ["meta"] = {["fields"] = {}, ["inventory"] = {}}, ["y"] = 3, ["param1"] = 47, ["z"] = 1, ["name"] = "xdecor:woodframed_glass"}, {["x"] = 9, ["meta"] = {["fields"] = {}, ["inventory"] = {}}, ["y"] = 3, ["param1"] = 15, ["z"] = 7, ["name"] = "xdecor:woodframed_glass"}, {["x"] = 9, ["meta"] = {["fields"] = {}, ["inventory"] = {}}, ["param2"] = 1, ["y"] = 4, ["z"] = 2, ["name"] = "xdecor:desertstone_tile"}, {["x"] = 9, ["meta"] = {["fields"] = {}, ["inventory"] = {}}, ["param2"] = 3, ["y"] = 4, ["z"] = 6, ["name"] = "xdecor:desertstone_tile"}, {["x"] = 9, ["meta"] = {["fields"] = {}, ["inventory"] = {}}, ["param2"] = 3, ["y"] = 5, ["z"] = 3, ["name"] = "xdecor:desertstone_tile"}, {["x"] = 9, ["meta"] = {["fields"] = {}, ["inventory"] = {}}, ["param2"] = 2, ["y"] = 5, ["z"] = 5, ["name"] = "xdecor:desertstone_tile"}, {["x"] = 9, ["meta"] = {["fields"] = {}, ["inventory"] = {}}, ["param2"] = 3, ["y"] = 6, ["z"] = 4, ["name"] = "xdecor:desertstone_tile"}, {["x"] = 10, ["meta"] = {["fields"] = {}, ["inventory"] = {}}, ["y"] = 0, ["z"] = 0, ["name"] = "rainbow:wood_white"}, {["x"] = 10, ["meta"] = {["fields"] = {}, ["inventory"] = {}}, ["y"] = 0, ["z"] = 1, ["name"] = "rainbow:wood_white"}, {["x"] = 10, ["meta"] = {["fields"] = {}, ["inventory"] = {}}, ["y"] = 0, ["z"] = 2, ["name"] = "rainbow:wood_white"}, {["x"] = 10, ["meta"] = {["fields"] = {}, ["inventory"] = {}}, ["y"] = 0, ["z"] = 3, ["name"] = "rainbow:wood_white"}, {["x"] = 10, ["meta"] = {["fields"] = {}, ["inventory"] = {}}, ["y"] = 0, ["z"] = 4, ["name"] = "rainbow:wood_white"}, {["x"] = 10, ["meta"] = {["fields"] = {}, ["inventory"] = {}}, ["y"] = 0, ["z"] = 5, ["name"] = "rainbow:wood_white"}, {["x"] = 10, ["meta"] = {["fields"] = {}, ["inventory"] = {}}, ["y"] = 0, ["z"] = 6, ["name"] = "rainbow:wood_white"}, {["x"] = 10, ["meta"] = {["fields"] = {}, ["inventory"] = {}}, ["y"] = 0, ["z"] = 7, ["name"] = "rainbow:wood_white"}, {["x"] = 10, ["meta"] = {["fields"] = {}, ["inventory"] = {}}, ["y"] = 0, ["z"] = 8, ["name"] = "rainbow:wood_white"}, {["x"] = 10, ["meta"] = {["fields"] = {}, ["inventory"] = {}}, ["param2"] = 3, ["y"] = 1, ["z"] = 0, ["name"] = "xdecor:desertstone_tile"}, {["x"] = 10, ["meta"] = {["fields"] = {["formspec"] = "size[8,7;]bgcolor[#080808BB;true]background[5,5;1,1;gui_formbg.png;true]listcolors[#00000069;#5A5A5A;#141318;#30434C;#FFF]list[context;books;0,0.3;8,2;]list[current_player;main;0,2.85;8,1;]list[current_player;main;0,4.08;8,3;8]listring[context;books]listring[current_player;main]image[0,2.85;1,1;gui_hb_bg.png]image[1,2.85;1,1;gui_hb_bg.png]image[2,2.85;1,1;gui_hb_bg.png]image[3,2.85;1,1;gui_hb_bg.png]image[4,2.85;1,1;gui_hb_bg.png]image[5,2.85;1,1;gui_hb_bg.png]image[6,2.85;1,1;gui_hb_bg.png]image[7,2.85;1,1;gui_hb_bg.png]image[0,0.3;1,1;default_bookshelf_slot.png]image[1,0.3;1,1;default_bookshelf_slot.png]image[2,0.3;1,1;default_bookshelf_slot.png]image[3,0.3;1,1;default_bookshelf_slot.png]image[4,0.3;1,1;default_bookshelf_slot.png]image[5,0.3;1,1;default_bookshelf_slot.png]image[6,0.3;1,1;default_bookshelf_slot.png]image[7,0.3;1,1;default_bookshelf_slot.png]image[0,1.3;1,1;default_bookshelf_slot.png]image[1,1.3;1,1;default_bookshelf_slot.png]image[2,1.3;1,1;default_bookshelf_slot.png]image[3,1.3;1,1;default_bookshelf_slot.png]image[4,1.3;1,1;default_bookshelf_slot.png]image[5,1.3;1,1;default_bookshelf_slot.png]image[6,1.3;1,1;default_bookshelf_slot.png]image[7,1.3;1,1;default_bookshelf_slot.png]"}, ["inventory"] = {["books"] = {"", "", "", "", "", "", "", "", "", "", "", "", "", "", "", ""}}}, ["y"] = 1, ["z"] = 2, ["name"] = "default:bookshelf"}, {["x"] = 10, ["meta"] = {["fields"] = {["formspec"] = "size[8,7;]bgcolor[#080808BB;true]background[5,5;1,1;gui_formbg.png;true]listcolors[#00000069;#5A5A5A;#141318;#30434C;#FFF]list[context;books;0,0.3;8,2;]list[current_player;main;0,2.85;8,1;]list[current_player;main;0,4.08;8,3;8]listring[context;books]listring[current_player;main]image[0,2.85;1,1;gui_hb_bg.png]image[1,2.85;1,1;gui_hb_bg.png]image[2,2.85;1,1;gui_hb_bg.png]image[3,2.85;1,1;gui_hb_bg.png]image[4,2.85;1,1;gui_hb_bg.png]image[5,2.85;1,1;gui_hb_bg.png]image[6,2.85;1,1;gui_hb_bg.png]image[7,2.85;1,1;gui_hb_bg.png]image[0,0.3;1,1;default_bookshelf_slot.png]image[1,0.3;1,1;default_bookshelf_slot.png]image[2,0.3;1,1;default_bookshelf_slot.png]image[3,0.3;1,1;default_bookshelf_slot.png]image[4,0.3;1,1;default_bookshelf_slot.png]image[5,0.3;1,1;default_bookshelf_slot.png]image[6,0.3;1,1;default_bookshelf_slot.png]image[7,0.3;1,1;default_bookshelf_slot.png]image[0,1.3;1,1;default_bookshelf_slot.png]image[1,1.3;1,1;default_bookshelf_slot.png]image[2,1.3;1,1;default_bookshelf_slot.png]image[3,1.3;1,1;default_bookshelf_slot.png]image[4,1.3;1,1;default_bookshelf_slot.png]image[5,1.3;1,1;default_bookshelf_slot.png]image[6,1.3;1,1;default_bookshelf_slot.png]image[7,1.3;1,1;default_bookshelf_slot.png]"}, ["inventory"] = {["books"] = {"", "", "", "", "", "", "", "", "", "", "", "", "", "", "", ""}}}, ["y"] = 1, ["z"] = 4, ["name"] = "default:bookshelf"}, {["x"] = 10, ["meta"] = {["fields"] = {["formspec"] = "size[8,7;]bgcolor[#080808BB;true]background[5,5;1,1;gui_formbg.png;true]listcolors[#00000069;#5A5A5A;#141318;#30434C;#FFF]list[context;books;0,0.3;8,2;]list[current_player;main;0,2.85;8,1;]list[current_player;main;0,4.08;8,3;8]listring[context;books]listring[current_player;main]image[0,2.85;1,1;gui_hb_bg.png]image[1,2.85;1,1;gui_hb_bg.png]image[2,2.85;1,1;gui_hb_bg.png]image[3,2.85;1,1;gui_hb_bg.png]image[4,2.85;1,1;gui_hb_bg.png]image[5,2.85;1,1;gui_hb_bg.png]image[6,2.85;1,1;gui_hb_bg.png]image[7,2.85;1,1;gui_hb_bg.png]image[0,0.3;1,1;default_bookshelf_slot.png]image[1,0.3;1,1;default_bookshelf_slot.png]image[2,0.3;1,1;default_bookshelf_slot.png]image[3,0.3;1,1;default_bookshelf_slot.png]image[4,0.3;1,1;default_bookshelf_slot.png]image[5,0.3;1,1;default_bookshelf_slot.png]image[6,0.3;1,1;default_bookshelf_slot.png]image[7,0.3;1,1;default_bookshelf_slot.png]image[0,1.3;1,1;default_bookshelf_slot.png]image[1,1.3;1,1;default_bookshelf_slot.png]image[2,1.3;1,1;default_bookshelf_slot.png]image[3,1.3;1,1;default_bookshelf_slot.png]image[4,1.3;1,1;default_bookshelf_slot.png]image[5,1.3;1,1;default_bookshelf_slot.png]image[6,1.3;1,1;default_bookshelf_slot.png]image[7,1.3;1,1;default_bookshelf_slot.png]"}, ["inventory"] = {["books"] = {"", "", "", "", "", "", "", "", "", "", "", "", "", "", "", ""}}}, ["y"] = 1, ["z"] = 6, ["name"] = "default:bookshelf"}, {["x"] = 10, ["meta"] = {["fields"] = {}, ["inventory"] = {}}, ["param2"] = 1, ["y"] = 1, ["z"] = 8, ["name"] = "xdecor:desertstone_tile"}, {["x"] = 10, ["meta"] = {["fields"] = {}, ["inventory"] = {}}, ["param2"] = 1, ["y"] = 2, ["z"] = 0, ["name"] = "xdecor:desertstone_tile"}, {["x"] = 10, ["meta"] = {["fields"] = {["formspec"] = "size[8,7;]bgcolor[#080808BB;true]background[5,5;1,1;gui_formbg.png;true]listcolors[#00000069;#5A5A5A;#141318;#30434C;#FFF]list[context;books;0,0.3;8,2;]list[current_player;main;0,2.85;8,1;]list[current_player;main;0,4.08;8,3;8]listring[context;books]listring[current_player;main]image[0,2.85;1,1;gui_hb_bg.png]image[1,2.85;1,1;gui_hb_bg.png]image[2,2.85;1,1;gui_hb_bg.png]image[3,2.85;1,1;gui_hb_bg.png]image[4,2.85;1,1;gui_hb_bg.png]image[5,2.85;1,1;gui_hb_bg.png]image[6,2.85;1,1;gui_hb_bg.png]image[7,2.85;1,1;gui_hb_bg.png]image[0,0.3;1,1;default_bookshelf_slot.png]image[1,0.3;1,1;default_bookshelf_slot.png]image[2,0.3;1,1;default_bookshelf_slot.png]image[3,0.3;1,1;default_bookshelf_slot.png]image[4,0.3;1,1;default_bookshelf_slot.png]image[5,0.3;1,1;default_bookshelf_slot.png]image[6,0.3;1,1;default_bookshelf_slot.png]image[7,0.3;1,1;default_bookshelf_slot.png]image[0,1.3;1,1;default_bookshelf_slot.png]image[1,1.3;1,1;default_bookshelf_slot.png]image[2,1.3;1,1;default_bookshelf_slot.png]image[3,1.3;1,1;default_bookshelf_slot.png]image[4,1.3;1,1;default_bookshelf_slot.png]image[5,1.3;1,1;default_bookshelf_slot.png]image[6,1.3;1,1;default_bookshelf_slot.png]image[7,1.3;1,1;default_bookshelf_slot.png]"}, ["inventory"] = {["books"] = {"", "", "", "", "", "", "", "", "", "", "", "", "", "", "", ""}}}, ["y"] = 2, ["z"] = 2, ["name"] = "default:bookshelf"}, {["x"] = 10, ["meta"] = {["fields"] = {["formspec"] = "size[8,7;]bgcolor[#080808BB;true]background[5,5;1,1;gui_formbg.png;true]listcolors[#00000069;#5A5A5A;#141318;#30434C;#FFF]list[context;books;0,0.3;8,2;]list[current_player;main;0,2.85;8,1;]list[current_player;main;0,4.08;8,3;8]listring[context;books]listring[current_player;main]image[0,2.85;1,1;gui_hb_bg.png]image[1,2.85;1,1;gui_hb_bg.png]image[2,2.85;1,1;gui_hb_bg.png]image[3,2.85;1,1;gui_hb_bg.png]image[4,2.85;1,1;gui_hb_bg.png]image[5,2.85;1,1;gui_hb_bg.png]image[6,2.85;1,1;gui_hb_bg.png]image[7,2.85;1,1;gui_hb_bg.png]image[0,0.3;1,1;default_bookshelf_slot.png]image[1,0.3;1,1;default_bookshelf_slot.png]image[2,0.3;1,1;default_bookshelf_slot.png]image[3,0.3;1,1;default_bookshelf_slot.png]image[4,0.3;1,1;default_bookshelf_slot.png]image[5,0.3;1,1;default_bookshelf_slot.png]image[6,0.3;1,1;default_bookshelf_slot.png]image[7,0.3;1,1;default_bookshelf_slot.png]image[0,1.3;1,1;default_bookshelf_slot.png]image[1,1.3;1,1;default_bookshelf_slot.png]image[2,1.3;1,1;default_bookshelf_slot.png]image[3,1.3;1,1;default_bookshelf_slot.png]image[4,1.3;1,1;default_bookshelf_slot.png]image[5,1.3;1,1;default_bookshelf_slot.png]image[6,1.3;1,1;default_bookshelf_slot.png]image[7,1.3;1,1;default_bookshelf_slot.png]"}, ["inventory"] = {["books"] = {"", "", "", "", "", "", "", "", "", "", "", "", "", "", "", ""}}}, ["y"] = 2, ["z"] = 4, ["name"] = "default:bookshelf"}, {["x"] = 10, ["meta"] = {["fields"] = {["formspec"] = "size[8,7;]bgcolor[#080808BB;true]background[5,5;1,1;gui_formbg.png;true]listcolors[#00000069;#5A5A5A;#141318;#30434C;#FFF]list[context;books;0,0.3;8,2;]list[current_player;main;0,2.85;8,1;]list[current_player;main;0,4.08;8,3;8]listring[context;books]listring[current_player;main]image[0,2.85;1,1;gui_hb_bg.png]image[1,2.85;1,1;gui_hb_bg.png]image[2,2.85;1,1;gui_hb_bg.png]image[3,2.85;1,1;gui_hb_bg.png]image[4,2.85;1,1;gui_hb_bg.png]image[5,2.85;1,1;gui_hb_bg.png]image[6,2.85;1,1;gui_hb_bg.png]image[7,2.85;1,1;gui_hb_bg.png]image[0,0.3;1,1;default_bookshelf_slot.png]image[1,0.3;1,1;default_bookshelf_slot.png]image[2,0.3;1,1;default_bookshelf_slot.png]image[3,0.3;1,1;default_bookshelf_slot.png]image[4,0.3;1,1;default_bookshelf_slot.png]image[5,0.3;1,1;default_bookshelf_slot.png]image[6,0.3;1,1;default_bookshelf_slot.png]image[7,0.3;1,1;default_bookshelf_slot.png]image[0,1.3;1,1;default_bookshelf_slot.png]image[1,1.3;1,1;default_bookshelf_slot.png]image[2,1.3;1,1;default_bookshelf_slot.png]image[3,1.3;1,1;default_bookshelf_slot.png]image[4,1.3;1,1;default_bookshelf_slot.png]image[5,1.3;1,1;default_bookshelf_slot.png]image[6,1.3;1,1;default_bookshelf_slot.png]image[7,1.3;1,1;default_bookshelf_slot.png]"}, ["inventory"] = {["books"] = {"", "", "", "", "", "", "", "", "", "", "", "", "", "", "", ""}}}, ["y"] = 2, ["z"] = 6, ["name"] = "default:bookshelf"}, {["x"] = 10, ["meta"] = {["fields"] = {}, ["inventory"] = {}}, ["param2"] = 1, ["y"] = 2, ["z"] = 8, ["name"] = "xdecor:desertstone_tile"}, {["x"] = 10, ["meta"] = {["fields"] = {}, ["inventory"] = {}}, ["y"] = 3, ["param1"] = 31, ["z"] = 1, ["name"] = "xdecor:woodframed_glass"}, {["x"] = 10, ["meta"] = {["fields"] = {}, ["inventory"] = {}}, ["y"] = 3, ["param1"] = 15, ["z"] = 7, ["name"] = "xdecor:woodframed_glass"}, {["x"] = 10, ["meta"] = {["fields"] = {}, ["inventory"] = {}}, ["param2"] = 1, ["y"] = 4, ["z"] = 2, ["name"] = "xdecor:desertstone_tile"}, {["x"] = 10, ["meta"] = {["fields"] = {}, ["inventory"] = {}}, ["param2"] = 3, ["y"] = 4, ["z"] = 6, ["name"] = "xdecor:desertstone_tile"}, {["x"] = 10, ["meta"] = {["fields"] = {}, ["inventory"] = {}}, ["param2"] = 3, ["y"] = 5, ["z"] = 3, ["name"] = "xdecor:desertstone_tile"}, {["x"] = 10, ["meta"] = {["fields"] = {}, ["inventory"] = {}}, ["param2"] = 2, ["y"] = 5, ["z"] = 5, ["name"] = "xdecor:desertstone_tile"}, {["x"] = 10, ["meta"] = {["fields"] = {}, ["inventory"] = {}}, ["param2"] = 3, ["y"] = 6, ["z"] = 4, ["name"] = "xdecor:desertstone_tile"}, {["x"] = 11, ["meta"] = {["fields"] = {}, ["inventory"] = {}}, ["y"] = 0, ["z"] = 0, ["name"] = "rainbow:wood_white"}, {["x"] = 11, ["meta"] = {["fields"] = {}, ["inventory"] = {}}, ["y"] = 0, ["z"] = 1, ["name"] = "rainbow:wood_white"}, {["x"] = 11, ["meta"] = {["fields"] = {}, ["inventory"] = {}}, ["y"] = 0, ["z"] = 2, ["name"] = "rainbow:wood_white"}, {["x"] = 11, ["meta"] = {["fields"] = {}, ["inventory"] = {}}, ["y"] = 0, ["z"] = 3, ["name"] = "rainbow:wood_white"}, {["x"] = 11, ["meta"] = {["fields"] = {}, ["inventory"] = {}}, ["y"] = 0, ["z"] = 4, ["name"] = "rainbow:wood_white"}, {["x"] = 11, ["meta"] = {["fields"] = {}, ["inventory"] = {}}, ["y"] = 0, ["z"] = 5, ["name"] = "rainbow:wood_white"}, {["x"] = 11, ["meta"] = {["fields"] = {}, ["inventory"] = {}}, ["y"] = 0, ["z"] = 6, ["name"] = "rainbow:wood_white"}, {["x"] = 11, ["meta"] = {["fields"] = {}, ["inventory"] = {}}, ["y"] = 0, ["z"] = 7, ["name"] = "rainbow:wood_white"}, {["x"] = 11, ["meta"] = {["fields"] = {}, ["inventory"] = {}}, ["y"] = 0, ["z"] = 8, ["name"] = "rainbow:wood_white"}, {["x"] = 11, ["meta"] = {["fields"] = {}, ["inventory"] = {}}, ["param2"] = 3, ["y"] = 1, ["z"] = 0, ["name"] = "xdecor:desertstone_tile"}, {["x"] = 11, ["meta"] = {["fields"] = {["formspec"] = "size[8,7;]bgcolor[#080808BB;true]background[5,5;1,1;gui_formbg.png;true]listcolors[#00000069;#5A5A5A;#141318;#30434C;#FFF]list[context;books;0,0.3;8,2;]list[current_player;main;0,2.85;8,1;]list[current_player;main;0,4.08;8,3;8]listring[context;books]listring[current_player;main]image[0,2.85;1,1;gui_hb_bg.png]image[1,2.85;1,1;gui_hb_bg.png]image[2,2.85;1,1;gui_hb_bg.png]image[3,2.85;1,1;gui_hb_bg.png]image[4,2.85;1,1;gui_hb_bg.png]image[5,2.85;1,1;gui_hb_bg.png]image[6,2.85;1,1;gui_hb_bg.png]image[7,2.85;1,1;gui_hb_bg.png]image[0,0.3;1,1;default_bookshelf_slot.png]image[1,0.3;1,1;default_bookshelf_slot.png]image[2,0.3;1,1;default_bookshelf_slot.png]image[3,0.3;1,1;default_bookshelf_slot.png]image[4,0.3;1,1;default_bookshelf_slot.png]image[5,0.3;1,1;default_bookshelf_slot.png]image[6,0.3;1,1;default_bookshelf_slot.png]image[7,0.3;1,1;default_bookshelf_slot.png]image[0,1.3;1,1;default_bookshelf_slot.png]image[1,1.3;1,1;default_bookshelf_slot.png]image[2,1.3;1,1;default_bookshelf_slot.png]image[3,1.3;1,1;default_bookshelf_slot.png]image[4,1.3;1,1;default_bookshelf_slot.png]image[5,1.3;1,1;default_bookshelf_slot.png]image[6,1.3;1,1;default_bookshelf_slot.png]image[7,1.3;1,1;default_bookshelf_slot.png]"}, ["inventory"] = {["books"] = {"", "", "", "", "", "", "", "", "", "", "", "", "", "", "", ""}}}, ["y"] = 1, ["z"] = 2, ["name"] = "default:bookshelf"}, {["x"] = 11, ["meta"] = {["fields"] = {["formspec"] = "size[8,7;]bgcolor[#080808BB;true]background[5,5;1,1;gui_formbg.png;true]listcolors[#00000069;#5A5A5A;#141318;#30434C;#FFF]list[context;books;0,0.3;8,2;]list[current_player;main;0,2.85;8,1;]list[current_player;main;0,4.08;8,3;8]listring[context;books]listring[current_player;main]image[0,2.85;1,1;gui_hb_bg.png]image[1,2.85;1,1;gui_hb_bg.png]image[2,2.85;1,1;gui_hb_bg.png]image[3,2.85;1,1;gui_hb_bg.png]image[4,2.85;1,1;gui_hb_bg.png]image[5,2.85;1,1;gui_hb_bg.png]image[6,2.85;1,1;gui_hb_bg.png]image[7,2.85;1,1;gui_hb_bg.png]image[0,0.3;1,1;default_bookshelf_slot.png]image[1,0.3;1,1;default_bookshelf_slot.png]image[2,0.3;1,1;default_bookshelf_slot.png]image[3,0.3;1,1;default_bookshelf_slot.png]image[4,0.3;1,1;default_bookshelf_slot.png]image[5,0.3;1,1;default_bookshelf_slot.png]image[6,0.3;1,1;default_bookshelf_slot.png]image[7,0.3;1,1;default_bookshelf_slot.png]image[0,1.3;1,1;default_bookshelf_slot.png]image[1,1.3;1,1;default_bookshelf_slot.png]image[2,1.3;1,1;default_bookshelf_slot.png]image[3,1.3;1,1;default_bookshelf_slot.png]image[4,1.3;1,1;default_bookshelf_slot.png]image[5,1.3;1,1;default_bookshelf_slot.png]image[6,1.3;1,1;default_bookshelf_slot.png]image[7,1.3;1,1;default_bookshelf_slot.png]"}, ["inventory"] = {["books"] = {"", "", "", "", "", "", "", "", "", "", "", "", "", "", "", ""}}}, ["y"] = 1, ["z"] = 4, ["name"] = "default:bookshelf"}, {["x"] = 11, ["meta"] = {["fields"] = {["formspec"] = "size[8,7;]bgcolor[#080808BB;true]background[5,5;1,1;gui_formbg.png;true]listcolors[#00000069;#5A5A5A;#141318;#30434C;#FFF]list[context;books;0,0.3;8,2;]list[current_player;main;0,2.85;8,1;]list[current_player;main;0,4.08;8,3;8]listring[context;books]listring[current_player;main]image[0,2.85;1,1;gui_hb_bg.png]image[1,2.85;1,1;gui_hb_bg.png]image[2,2.85;1,1;gui_hb_bg.png]image[3,2.85;1,1;gui_hb_bg.png]image[4,2.85;1,1;gui_hb_bg.png]image[5,2.85;1,1;gui_hb_bg.png]image[6,2.85;1,1;gui_hb_bg.png]image[7,2.85;1,1;gui_hb_bg.png]image[0,0.3;1,1;default_bookshelf_slot.png]image[1,0.3;1,1;default_bookshelf_slot.png]image[2,0.3;1,1;default_bookshelf_slot.png]image[3,0.3;1,1;default_bookshelf_slot.png]image[4,0.3;1,1;default_bookshelf_slot.png]image[5,0.3;1,1;default_bookshelf_slot.png]image[6,0.3;1,1;default_bookshelf_slot.png]image[7,0.3;1,1;default_bookshelf_slot.png]image[0,1.3;1,1;default_bookshelf_slot.png]image[1,1.3;1,1;default_bookshelf_slot.png]image[2,1.3;1,1;default_bookshelf_slot.png]image[3,1.3;1,1;default_bookshelf_slot.png]image[4,1.3;1,1;default_bookshelf_slot.png]image[5,1.3;1,1;default_bookshelf_slot.png]image[6,1.3;1,1;default_bookshelf_slot.png]image[7,1.3;1,1;default_bookshelf_slot.png]"}, ["inventory"] = {["books"] = {"", "", "", "", "", "", "", "", "", "", "", "", "", "", "", ""}}}, ["y"] = 1, ["z"] = 6, ["name"] = "default:bookshelf"}, {["x"] = 11, ["meta"] = {["fields"] = {}, ["inventory"] = {}}, ["param2"] = 1, ["y"] = 1, ["z"] = 8, ["name"] = "xdecor:desertstone_tile"}, {["x"] = 11, ["meta"] = {["fields"] = {}, ["inventory"] = {}}, ["param2"] = 1, ["y"] = 2, ["z"] = 0, ["name"] = "xdecor:desertstone_tile"}, {["x"] = 11, ["meta"] = {["fields"] = {["formspec"] = "size[8,7;]bgcolor[#080808BB;true]background[5,5;1,1;gui_formbg.png;true]listcolors[#00000069;#5A5A5A;#141318;#30434C;#FFF]list[context;books;0,0.3;8,2;]list[current_player;main;0,2.85;8,1;]list[current_player;main;0,4.08;8,3;8]listring[context;books]listring[current_player;main]image[0,2.85;1,1;gui_hb_bg.png]image[1,2.85;1,1;gui_hb_bg.png]image[2,2.85;1,1;gui_hb_bg.png]image[3,2.85;1,1;gui_hb_bg.png]image[4,2.85;1,1;gui_hb_bg.png]image[5,2.85;1,1;gui_hb_bg.png]image[6,2.85;1,1;gui_hb_bg.png]image[7,2.85;1,1;gui_hb_bg.png]image[0,0.3;1,1;default_bookshelf_slot.png]image[1,0.3;1,1;default_bookshelf_slot.png]image[2,0.3;1,1;default_bookshelf_slot.png]image[3,0.3;1,1;default_bookshelf_slot.png]image[4,0.3;1,1;default_bookshelf_slot.png]image[5,0.3;1,1;default_bookshelf_slot.png]image[6,0.3;1,1;default_bookshelf_slot.png]image[7,0.3;1,1;default_bookshelf_slot.png]image[0,1.3;1,1;default_bookshelf_slot.png]image[1,1.3;1,1;default_bookshelf_slot.png]image[2,1.3;1,1;default_bookshelf_slot.png]image[3,1.3;1,1;default_bookshelf_slot.png]image[4,1.3;1,1;default_bookshelf_slot.png]image[5,1.3;1,1;default_bookshelf_slot.png]image[6,1.3;1,1;default_bookshelf_slot.png]image[7,1.3;1,1;default_bookshelf_slot.png]"}, ["inventory"] = {["books"] = {"", "", "", "", "", "", "", "", "", "", "", "", "", "", "", ""}}}, ["y"] = 2, ["z"] = 2, ["name"] = "default:bookshelf"}, {["x"] = 11, ["meta"] = {["fields"] = {["formspec"] = "size[8,7;]bgcolor[#080808BB;true]background[5,5;1,1;gui_formbg.png;true]listcolors[#00000069;#5A5A5A;#141318;#30434C;#FFF]list[context;books;0,0.3;8,2;]list[current_player;main;0,2.85;8,1;]list[current_player;main;0,4.08;8,3;8]listring[context;books]listring[current_player;main]image[0,2.85;1,1;gui_hb_bg.png]image[1,2.85;1,1;gui_hb_bg.png]image[2,2.85;1,1;gui_hb_bg.png]image[3,2.85;1,1;gui_hb_bg.png]image[4,2.85;1,1;gui_hb_bg.png]image[5,2.85;1,1;gui_hb_bg.png]image[6,2.85;1,1;gui_hb_bg.png]image[7,2.85;1,1;gui_hb_bg.png]image[0,0.3;1,1;default_bookshelf_slot.png]image[1,0.3;1,1;default_bookshelf_slot.png]image[2,0.3;1,1;default_bookshelf_slot.png]image[3,0.3;1,1;default_bookshelf_slot.png]image[4,0.3;1,1;default_bookshelf_slot.png]image[5,0.3;1,1;default_bookshelf_slot.png]image[6,0.3;1,1;default_bookshelf_slot.png]image[7,0.3;1,1;default_bookshelf_slot.png]image[0,1.3;1,1;default_bookshelf_slot.png]image[1,1.3;1,1;default_bookshelf_slot.png]image[2,1.3;1,1;default_bookshelf_slot.png]image[3,1.3;1,1;default_bookshelf_slot.png]image[4,1.3;1,1;default_bookshelf_slot.png]image[5,1.3;1,1;default_bookshelf_slot.png]image[6,1.3;1,1;default_bookshelf_slot.png]image[7,1.3;1,1;default_bookshelf_slot.png]"}, ["inventory"] = {["books"] = {"", "", "", "", "", "", "", "", "", "", "", "", "", "", "", ""}}}, ["y"] = 2, ["z"] = 4, ["name"] = "default:bookshelf"}, {["x"] = 11, ["meta"] = {["fields"] = {["formspec"] = "size[8,7;]bgcolor[#080808BB;true]background[5,5;1,1;gui_formbg.png;true]listcolors[#00000069;#5A5A5A;#141318;#30434C;#FFF]list[context;books;0,0.3;8,2;]list[current_player;main;0,2.85;8,1;]list[current_player;main;0,4.08;8,3;8]listring[context;books]listring[current_player;main]image[0,2.85;1,1;gui_hb_bg.png]image[1,2.85;1,1;gui_hb_bg.png]image[2,2.85;1,1;gui_hb_bg.png]image[3,2.85;1,1;gui_hb_bg.png]image[4,2.85;1,1;gui_hb_bg.png]image[5,2.85;1,1;gui_hb_bg.png]image[6,2.85;1,1;gui_hb_bg.png]image[7,2.85;1,1;gui_hb_bg.png]image[0,0.3;1,1;default_bookshelf_slot.png]image[1,0.3;1,1;default_bookshelf_slot.png]image[2,0.3;1,1;default_bookshelf_slot.png]image[3,0.3;1,1;default_bookshelf_slot.png]image[4,0.3;1,1;default_bookshelf_slot.png]image[5,0.3;1,1;default_bookshelf_slot.png]image[6,0.3;1,1;default_bookshelf_slot.png]image[7,0.3;1,1;default_bookshelf_slot.png]image[0,1.3;1,1;default_bookshelf_slot.png]image[1,1.3;1,1;default_bookshelf_slot.png]image[2,1.3;1,1;default_bookshelf_slot.png]image[3,1.3;1,1;default_bookshelf_slot.png]image[4,1.3;1,1;default_bookshelf_slot.png]image[5,1.3;1,1;default_bookshelf_slot.png]image[6,1.3;1,1;default_bookshelf_slot.png]image[7,1.3;1,1;default_bookshelf_slot.png]"}, ["inventory"] = {["books"] = {"", "", "", "", "", "", "", "", "", "", "", "", "", "", "", ""}}}, ["y"] = 2, ["z"] = 6, ["name"] = "default:bookshelf"}, {["x"] = 11, ["meta"] = {["fields"] = {}, ["inventory"] = {}}, ["param2"] = 1, ["y"] = 2, ["z"] = 8, ["name"] = "xdecor:desertstone_tile"}, {["x"] = 11, ["meta"] = {["fields"] = {}, ["inventory"] = {}}, ["y"] = 3, ["param1"] = 15, ["z"] = 1, ["name"] = "xdecor:woodframed_glass"}, {["x"] = 11, ["meta"] = {["fields"] = {}, ["inventory"] = {}}, ["y"] = 3, ["param1"] = 15, ["z"] = 7, ["name"] = "xdecor:woodframed_glass"}, {["x"] = 11, ["meta"] = {["fields"] = {}, ["inventory"] = {}}, ["param2"] = 1, ["y"] = 4, ["z"] = 2, ["name"] = "xdecor:desertstone_tile"}, {["x"] = 11, ["meta"] = {["fields"] = {}, ["inventory"] = {}}, ["param2"] = 2, ["y"] = 4, ["z"] = 6, ["name"] = "xdecor:desertstone_tile"}, {["x"] = 11, ["meta"] = {["fields"] = {}, ["inventory"] = {}}, ["param2"] = 3, ["y"] = 5, ["z"] = 3, ["name"] = "xdecor:desertstone_tile"}, {["x"] = 11, ["meta"] = {["fields"] = {}, ["inventory"] = {}}, ["param2"] = 2, ["y"] = 5, ["z"] = 5, ["name"] = "xdecor:desertstone_tile"}, {["x"] = 11, ["meta"] = {["fields"] = {}, ["inventory"] = {}}, ["param2"] = 3, ["y"] = 6, ["z"] = 4, ["name"] = "xdecor:desertstone_tile"}, {["x"] = 12, ["meta"] = {["fields"] = {}, ["inventory"] = {}}, ["y"] = 0, ["z"] = 0, ["name"] = "rainbow:wood_white"}, {["x"] = 12, ["meta"] = {["fields"] = {}, ["inventory"] = {}}, ["y"] = 0, ["z"] = 1, ["name"] = "rainbow:wood_white"}, {["x"] = 12, ["meta"] = {["fields"] = {}, ["inventory"] = {}}, ["y"] = 0, ["z"] = 2, ["name"] = "rainbow:wood_white"}, {["x"] = 12, ["meta"] = {["fields"] = {}, ["inventory"] = {}}, ["y"] = 0, ["z"] = 3, ["name"] = "rainbow:wood_white"}, {["x"] = 12, ["meta"] = {["fields"] = {}, ["inventory"] = {}}, ["y"] = 0, ["z"] = 4, ["name"] = "rainbow:wood_white"}, {["x"] = 12, ["meta"] = {["fields"] = {}, ["inventory"] = {}}, ["y"] = 0, ["z"] = 5, ["name"] = "rainbow:wood_white"}, {["x"] = 12, ["meta"] = {["fields"] = {}, ["inventory"] = {}}, ["y"] = 0, ["z"] = 6, ["name"] = "rainbow:wood_white"}, {["x"] = 12, ["meta"] = {["fields"] = {}, ["inventory"] = {}}, ["y"] = 0, ["z"] = 7, ["name"] = "rainbow:wood_white"}, {["x"] = 12, ["meta"] = {["fields"] = {}, ["inventory"] = {}}, ["y"] = 0, ["z"] = 8, ["name"] = "rainbow:wood_white"}, {["x"] = 12, ["meta"] = {["fields"] = {}, ["inventory"] = {}}, ["param2"] = 3, ["y"] = 1, ["z"] = 0, ["name"] = "xdecor:desertstone_tile"}, {["x"] = 12, ["meta"] = {["fields"] = {["formspec"] = "size[8,7;]bgcolor[#080808BB;true]background[5,5;1,1;gui_formbg.png;true]listcolors[#00000069;#5A5A5A;#141318;#30434C;#FFF]list[context;books;0,0.3;8,2;]list[current_player;main;0,2.85;8,1;]list[current_player;main;0,4.08;8,3;8]listring[context;books]listring[current_player;main]image[0,2.85;1,1;gui_hb_bg.png]image[1,2.85;1,1;gui_hb_bg.png]image[2,2.85;1,1;gui_hb_bg.png]image[3,2.85;1,1;gui_hb_bg.png]image[4,2.85;1,1;gui_hb_bg.png]image[5,2.85;1,1;gui_hb_bg.png]image[6,2.85;1,1;gui_hb_bg.png]image[7,2.85;1,1;gui_hb_bg.png]image[0,0.3;1,1;default_bookshelf_slot.png]image[1,0.3;1,1;default_bookshelf_slot.png]image[2,0.3;1,1;default_bookshelf_slot.png]image[3,0.3;1,1;default_bookshelf_slot.png]image[4,0.3;1,1;default_bookshelf_slot.png]image[5,0.3;1,1;default_bookshelf_slot.png]image[6,0.3;1,1;default_bookshelf_slot.png]image[7,0.3;1,1;default_bookshelf_slot.png]image[0,1.3;1,1;default_bookshelf_slot.png]image[1,1.3;1,1;default_bookshelf_slot.png]image[2,1.3;1,1;default_bookshelf_slot.png]image[3,1.3;1,1;default_bookshelf_slot.png]image[4,1.3;1,1;default_bookshelf_slot.png]image[5,1.3;1,1;default_bookshelf_slot.png]image[6,1.3;1,1;default_bookshelf_slot.png]image[7,1.3;1,1;default_bookshelf_slot.png]"}, ["inventory"] = {["books"] = {"", "", "", "", "", "", "", "", "", "", "", "", "", "", "", ""}}}, ["y"] = 1, ["z"] = 2, ["name"] = "default:bookshelf"}, {["x"] = 12, ["meta"] = {["fields"] = {["formspec"] = "size[8,7;]bgcolor[#080808BB;true]background[5,5;1,1;gui_formbg.png;true]listcolors[#00000069;#5A5A5A;#141318;#30434C;#FFF]list[context;books;0,0.3;8,2;]list[current_player;main;0,2.85;8,1;]list[current_player;main;0,4.08;8,3;8]listring[context;books]listring[current_player;main]image[0,2.85;1,1;gui_hb_bg.png]image[1,2.85;1,1;gui_hb_bg.png]image[2,2.85;1,1;gui_hb_bg.png]image[3,2.85;1,1;gui_hb_bg.png]image[4,2.85;1,1;gui_hb_bg.png]image[5,2.85;1,1;gui_hb_bg.png]image[6,2.85;1,1;gui_hb_bg.png]image[7,2.85;1,1;gui_hb_bg.png]image[0,0.3;1,1;default_bookshelf_slot.png]image[1,0.3;1,1;default_bookshelf_slot.png]image[2,0.3;1,1;default_bookshelf_slot.png]image[3,0.3;1,1;default_bookshelf_slot.png]image[4,0.3;1,1;default_bookshelf_slot.png]image[5,0.3;1,1;default_bookshelf_slot.png]image[6,0.3;1,1;default_bookshelf_slot.png]image[7,0.3;1,1;default_bookshelf_slot.png]image[0,1.3;1,1;default_bookshelf_slot.png]image[1,1.3;1,1;default_bookshelf_slot.png]image[2,1.3;1,1;default_bookshelf_slot.png]image[3,1.3;1,1;default_bookshelf_slot.png]image[4,1.3;1,1;default_bookshelf_slot.png]image[5,1.3;1,1;default_bookshelf_slot.png]image[6,1.3;1,1;default_bookshelf_slot.png]image[7,1.3;1,1;default_bookshelf_slot.png]"}, ["inventory"] = {["books"] = {"", "", "", "", "", "", "", "", "", "", "", "", "", "", "", ""}}}, ["y"] = 1, ["z"] = 4, ["name"] = "default:bookshelf"}, {["x"] = 12, ["meta"] = {["fields"] = {["formspec"] = "size[8,7;]bgcolor[#080808BB;true]background[5,5;1,1;gui_formbg.png;true]listcolors[#00000069;#5A5A5A;#141318;#30434C;#FFF]list[context;books;0,0.3;8,2;]list[current_player;main;0,2.85;8,1;]list[current_player;main;0,4.08;8,3;8]listring[context;books]listring[current_player;main]image[0,2.85;1,1;gui_hb_bg.png]image[1,2.85;1,1;gui_hb_bg.png]image[2,2.85;1,1;gui_hb_bg.png]image[3,2.85;1,1;gui_hb_bg.png]image[4,2.85;1,1;gui_hb_bg.png]image[5,2.85;1,1;gui_hb_bg.png]image[6,2.85;1,1;gui_hb_bg.png]image[7,2.85;1,1;gui_hb_bg.png]image[0,0.3;1,1;default_bookshelf_slot.png]image[1,0.3;1,1;default_bookshelf_slot.png]image[2,0.3;1,1;default_bookshelf_slot.png]image[3,0.3;1,1;default_bookshelf_slot.png]image[4,0.3;1,1;default_bookshelf_slot.png]image[5,0.3;1,1;default_bookshelf_slot.png]image[6,0.3;1,1;default_bookshelf_slot.png]image[7,0.3;1,1;default_bookshelf_slot.png]image[0,1.3;1,1;default_bookshelf_slot.png]image[1,1.3;1,1;default_bookshelf_slot.png]image[2,1.3;1,1;default_bookshelf_slot.png]image[3,1.3;1,1;default_bookshelf_slot.png]image[4,1.3;1,1;default_bookshelf_slot.png]image[5,1.3;1,1;default_bookshelf_slot.png]image[6,1.3;1,1;default_bookshelf_slot.png]image[7,1.3;1,1;default_bookshelf_slot.png]"}, ["inventory"] = {["books"] = {"", "", "", "", "", "", "", "", "", "", "", "", "", "", "", ""}}}, ["y"] = 1, ["z"] = 6, ["name"] = "default:bookshelf"}, {["x"] = 12, ["meta"] = {["fields"] = {}, ["inventory"] = {}}, ["param2"] = 1, ["y"] = 1, ["z"] = 8, ["name"] = "xdecor:desertstone_tile"}, {["x"] = 12, ["meta"] = {["fields"] = {}, ["inventory"] = {}}, ["param2"] = 1, ["y"] = 2, ["z"] = 0, ["name"] = "xdecor:desertstone_tile"}, {["x"] = 12, ["meta"] = {["fields"] = {["formspec"] = "size[8,7;]bgcolor[#080808BB;true]background[5,5;1,1;gui_formbg.png;true]listcolors[#00000069;#5A5A5A;#141318;#30434C;#FFF]list[context;books;0,0.3;8,2;]list[current_player;main;0,2.85;8,1;]list[current_player;main;0,4.08;8,3;8]listring[context;books]listring[current_player;main]image[0,2.85;1,1;gui_hb_bg.png]image[1,2.85;1,1;gui_hb_bg.png]image[2,2.85;1,1;gui_hb_bg.png]image[3,2.85;1,1;gui_hb_bg.png]image[4,2.85;1,1;gui_hb_bg.png]image[5,2.85;1,1;gui_hb_bg.png]image[6,2.85;1,1;gui_hb_bg.png]image[7,2.85;1,1;gui_hb_bg.png]image[0,0.3;1,1;default_bookshelf_slot.png]image[1,0.3;1,1;default_bookshelf_slot.png]image[2,0.3;1,1;default_bookshelf_slot.png]image[3,0.3;1,1;default_bookshelf_slot.png]image[4,0.3;1,1;default_bookshelf_slot.png]image[5,0.3;1,1;default_bookshelf_slot.png]image[6,0.3;1,1;default_bookshelf_slot.png]image[7,0.3;1,1;default_bookshelf_slot.png]image[0,1.3;1,1;default_bookshelf_slot.png]image[1,1.3;1,1;default_bookshelf_slot.png]image[2,1.3;1,1;default_bookshelf_slot.png]image[3,1.3;1,1;default_bookshelf_slot.png]image[4,1.3;1,1;default_bookshelf_slot.png]image[5,1.3;1,1;default_bookshelf_slot.png]image[6,1.3;1,1;default_bookshelf_slot.png]image[7,1.3;1,1;default_bookshelf_slot.png]"}, ["inventory"] = {["books"] = {"", "", "", "", "", "", "", "", "", "", "", "", "", "", "", ""}}}, ["y"] = 2, ["z"] = 2, ["name"] = "default:bookshelf"}, {["x"] = 12, ["meta"] = {["fields"] = {["formspec"] = "size[8,7;]bgcolor[#080808BB;true]background[5,5;1,1;gui_formbg.png;true]listcolors[#00000069;#5A5A5A;#141318;#30434C;#FFF]list[context;books;0,0.3;8,2;]list[current_player;main;0,2.85;8,1;]list[current_player;main;0,4.08;8,3;8]listring[context;books]listring[current_player;main]image[0,2.85;1,1;gui_hb_bg.png]image[1,2.85;1,1;gui_hb_bg.png]image[2,2.85;1,1;gui_hb_bg.png]image[3,2.85;1,1;gui_hb_bg.png]image[4,2.85;1,1;gui_hb_bg.png]image[5,2.85;1,1;gui_hb_bg.png]image[6,2.85;1,1;gui_hb_bg.png]image[7,2.85;1,1;gui_hb_bg.png]image[0,0.3;1,1;default_bookshelf_slot.png]image[1,0.3;1,1;default_bookshelf_slot.png]image[2,0.3;1,1;default_bookshelf_slot.png]image[3,0.3;1,1;default_bookshelf_slot.png]image[4,0.3;1,1;default_bookshelf_slot.png]image[5,0.3;1,1;default_bookshelf_slot.png]image[6,0.3;1,1;default_bookshelf_slot.png]image[7,0.3;1,1;default_bookshelf_slot.png]image[0,1.3;1,1;default_bookshelf_slot.png]image[1,1.3;1,1;default_bookshelf_slot.png]image[2,1.3;1,1;default_bookshelf_slot.png]image[3,1.3;1,1;default_bookshelf_slot.png]image[4,1.3;1,1;default_bookshelf_slot.png]image[5,1.3;1,1;default_bookshelf_slot.png]image[6,1.3;1,1;default_bookshelf_slot.png]image[7,1.3;1,1;default_bookshelf_slot.png]"}, ["inventory"] = {["books"] = {"", "", "", "", "", "", "", "", "", "", "", "", "", "", "", ""}}}, ["y"] = 2, ["z"] = 4, ["name"] = "default:bookshelf"}, {["x"] = 12, ["meta"] = {["fields"] = {["formspec"] = "size[8,7;]bgcolor[#080808BB;true]background[5,5;1,1;gui_formbg.png;true]listcolors[#00000069;#5A5A5A;#141318;#30434C;#FFF]list[context;books;0,0.3;8,2;]list[current_player;main;0,2.85;8,1;]list[current_player;main;0,4.08;8,3;8]listring[context;books]listring[current_player;main]image[0,2.85;1,1;gui_hb_bg.png]image[1,2.85;1,1;gui_hb_bg.png]image[2,2.85;1,1;gui_hb_bg.png]image[3,2.85;1,1;gui_hb_bg.png]image[4,2.85;1,1;gui_hb_bg.png]image[5,2.85;1,1;gui_hb_bg.png]image[6,2.85;1,1;gui_hb_bg.png]image[7,2.85;1,1;gui_hb_bg.png]image[0,0.3;1,1;default_bookshelf_slot.png]image[1,0.3;1,1;default_bookshelf_slot.png]image[2,0.3;1,1;default_bookshelf_slot.png]image[3,0.3;1,1;default_bookshelf_slot.png]image[4,0.3;1,1;default_bookshelf_slot.png]image[5,0.3;1,1;default_bookshelf_slot.png]image[6,0.3;1,1;default_bookshelf_slot.png]image[7,0.3;1,1;default_bookshelf_slot.png]image[0,1.3;1,1;default_bookshelf_slot.png]image[1,1.3;1,1;default_bookshelf_slot.png]image[2,1.3;1,1;default_bookshelf_slot.png]image[3,1.3;1,1;default_bookshelf_slot.png]image[4,1.3;1,1;default_bookshelf_slot.png]image[5,1.3;1,1;default_bookshelf_slot.png]image[6,1.3;1,1;default_bookshelf_slot.png]image[7,1.3;1,1;default_bookshelf_slot.png]"}, ["inventory"] = {["books"] = {"", "", "", "", "", "", "", "", "", "", "", "", "", "", "", ""}}}, ["y"] = 2, ["z"] = 6, ["name"] = "default:bookshelf"}, {["x"] = 12, ["meta"] = {["fields"] = {}, ["inventory"] = {}}, ["param2"] = 1, ["y"] = 2, ["z"] = 8, ["name"] = "xdecor:desertstone_tile"}, {["x"] = 12, ["meta"] = {["fields"] = {}, ["inventory"] = {}}, ["y"] = 3, ["param1"] = 15, ["z"] = 1, ["name"] = "xdecor:woodframed_glass"}, {["x"] = 12, ["meta"] = {["fields"] = {}, ["inventory"] = {}}, ["y"] = 3, ["param1"] = 15, ["z"] = 7, ["name"] = "xdecor:woodframed_glass"}, {["x"] = 12, ["meta"] = {["fields"] = {}, ["inventory"] = {}}, ["param2"] = 1, ["y"] = 4, ["z"] = 2, ["name"] = "xdecor:desertstone_tile"}, {["x"] = 12, ["meta"] = {["fields"] = {}, ["inventory"] = {}}, ["param2"] = 1, ["y"] = 4, ["z"] = 6, ["name"] = "xdecor:desertstone_tile"}, {["x"] = 12, ["meta"] = {["fields"] = {}, ["inventory"] = {}}, ["param2"] = 3, ["y"] = 5, ["z"] = 3, ["name"] = "xdecor:desertstone_tile"}, {["x"] = 12, ["meta"] = {["fields"] = {}, ["inventory"] = {}}, ["param2"] = 2, ["y"] = 5, ["z"] = 5, ["name"] = "xdecor:desertstone_tile"}, {["x"] = 12, ["meta"] = {["fields"] = {}, ["inventory"] = {}}, ["param2"] = 3, ["y"] = 6, ["z"] = 4, ["name"] = "xdecor:desertstone_tile"}, {["x"] = 13, ["meta"] = {["fields"] = {}, ["inventory"] = {}}, ["y"] = 0, ["z"] = 0, ["name"] = "rainbow:wood_white"}, {["x"] = 13, ["meta"] = {["fields"] = {}, ["inventory"] = {}}, ["y"] = 0, ["z"] = 1, ["name"] = "rainbow:wood_white"}, {["x"] = 13, ["meta"] = {["fields"] = {}, ["inventory"] = {}}, ["y"] = 0, ["z"] = 2, ["name"] = "rainbow:wood_white"}, {["x"] = 13, ["meta"] = {["fields"] = {}, ["inventory"] = {}}, ["y"] = 0, ["z"] = 3, ["name"] = "rainbow:wood_white"}, {["x"] = 13, ["meta"] = {["fields"] = {}, ["inventory"] = {}}, ["y"] = 0, ["z"] = 4, ["name"] = "rainbow:wood_white"}, {["x"] = 13, ["meta"] = {["fields"] = {}, ["inventory"] = {}}, ["y"] = 0, ["z"] = 5, ["name"] = "rainbow:wood_white"}, {["x"] = 13, ["meta"] = {["fields"] = {}, ["inventory"] = {}}, ["y"] = 0, ["z"] = 6, ["name"] = "rainbow:wood_white"}, {["x"] = 13, ["meta"] = {["fields"] = {}, ["inventory"] = {}}, ["y"] = 0, ["z"] = 7, ["name"] = "rainbow:wood_white"}, {["x"] = 13, ["meta"] = {["fields"] = {}, ["inventory"] = {}}, ["y"] = 0, ["z"] = 8, ["name"] = "rainbow:wood_white"}, {["x"] = 13, ["meta"] = {["fields"] = {}, ["inventory"] = {}}, ["param2"] = 3, ["y"] = 1, ["z"] = 0, ["name"] = "xdecor:desertstone_tile"}, {["x"] = 13, ["meta"] = {["fields"] = {["formspec"] = "size[8,7;]bgcolor[#080808BB;true]background[5,5;1,1;gui_formbg.png;true]listcolors[#00000069;#5A5A5A;#141318;#30434C;#FFF]list[context;books;0,0.3;8,2;]list[current_player;main;0,2.85;8,1;]list[current_player;main;0,4.08;8,3;8]listring[context;books]listring[current_player;main]image[0,2.85;1,1;gui_hb_bg.png]image[1,2.85;1,1;gui_hb_bg.png]image[2,2.85;1,1;gui_hb_bg.png]image[3,2.85;1,1;gui_hb_bg.png]image[4,2.85;1,1;gui_hb_bg.png]image[5,2.85;1,1;gui_hb_bg.png]image[6,2.85;1,1;gui_hb_bg.png]image[7,2.85;1,1;gui_hb_bg.png]image[0,0.3;1,1;default_bookshelf_slot.png]image[1,0.3;1,1;default_bookshelf_slot.png]image[2,0.3;1,1;default_bookshelf_slot.png]image[3,0.3;1,1;default_bookshelf_slot.png]image[4,0.3;1,1;default_bookshelf_slot.png]image[5,0.3;1,1;default_bookshelf_slot.png]image[6,0.3;1,1;default_bookshelf_slot.png]image[7,0.3;1,1;default_bookshelf_slot.png]image[0,1.3;1,1;default_bookshelf_slot.png]image[1,1.3;1,1;default_bookshelf_slot.png]image[2,1.3;1,1;default_bookshelf_slot.png]image[3,1.3;1,1;default_bookshelf_slot.png]image[4,1.3;1,1;default_bookshelf_slot.png]image[5,1.3;1,1;default_bookshelf_slot.png]image[6,1.3;1,1;default_bookshelf_slot.png]image[7,1.3;1,1;default_bookshelf_slot.png]"}, ["inventory"] = {["books"] = {"", "", "", "", "", "", "", "", "", "", "", "", "", "", "", ""}}}, ["y"] = 1, ["z"] = 2, ["name"] = "default:bookshelf"}, {["x"] = 13, ["meta"] = {["fields"] = {["formspec"] = "size[8,7;]bgcolor[#080808BB;true]background[5,5;1,1;gui_formbg.png;true]listcolors[#00000069;#5A5A5A;#141318;#30434C;#FFF]list[context;books;0,0.3;8,2;]list[current_player;main;0,2.85;8,1;]list[current_player;main;0,4.08;8,3;8]listring[context;books]listring[current_player;main]image[0,2.85;1,1;gui_hb_bg.png]image[1,2.85;1,1;gui_hb_bg.png]image[2,2.85;1,1;gui_hb_bg.png]image[3,2.85;1,1;gui_hb_bg.png]image[4,2.85;1,1;gui_hb_bg.png]image[5,2.85;1,1;gui_hb_bg.png]image[6,2.85;1,1;gui_hb_bg.png]image[7,2.85;1,1;gui_hb_bg.png]image[0,0.3;1,1;default_bookshelf_slot.png]image[1,0.3;1,1;default_bookshelf_slot.png]image[2,0.3;1,1;default_bookshelf_slot.png]image[3,0.3;1,1;default_bookshelf_slot.png]image[4,0.3;1,1;default_bookshelf_slot.png]image[5,0.3;1,1;default_bookshelf_slot.png]image[6,0.3;1,1;default_bookshelf_slot.png]image[7,0.3;1,1;default_bookshelf_slot.png]image[0,1.3;1,1;default_bookshelf_slot.png]image[1,1.3;1,1;default_bookshelf_slot.png]image[2,1.3;1,1;default_bookshelf_slot.png]image[3,1.3;1,1;default_bookshelf_slot.png]image[4,1.3;1,1;default_bookshelf_slot.png]image[5,1.3;1,1;default_bookshelf_slot.png]image[6,1.3;1,1;default_bookshelf_slot.png]image[7,1.3;1,1;default_bookshelf_slot.png]"}, ["inventory"] = {["books"] = {"", "", "", "", "", "", "", "", "", "", "", "", "", "", "", ""}}}, ["y"] = 1, ["z"] = 4, ["name"] = "default:bookshelf"}, {["x"] = 13, ["meta"] = {["fields"] = {["formspec"] = "size[8,7;]bgcolor[#080808BB;true]background[5,5;1,1;gui_formbg.png;true]listcolors[#00000069;#5A5A5A;#141318;#30434C;#FFF]list[context;books;0,0.3;8,2;]list[current_player;main;0,2.85;8,1;]list[current_player;main;0,4.08;8,3;8]listring[context;books]listring[current_player;main]image[0,2.85;1,1;gui_hb_bg.png]image[1,2.85;1,1;gui_hb_bg.png]image[2,2.85;1,1;gui_hb_bg.png]image[3,2.85;1,1;gui_hb_bg.png]image[4,2.85;1,1;gui_hb_bg.png]image[5,2.85;1,1;gui_hb_bg.png]image[6,2.85;1,1;gui_hb_bg.png]image[7,2.85;1,1;gui_hb_bg.png]image[0,0.3;1,1;default_bookshelf_slot.png]image[1,0.3;1,1;default_bookshelf_slot.png]image[2,0.3;1,1;default_bookshelf_slot.png]image[3,0.3;1,1;default_bookshelf_slot.png]image[4,0.3;1,1;default_bookshelf_slot.png]image[5,0.3;1,1;default_bookshelf_slot.png]image[6,0.3;1,1;default_bookshelf_slot.png]image[7,0.3;1,1;default_bookshelf_slot.png]image[0,1.3;1,1;default_bookshelf_slot.png]image[1,1.3;1,1;default_bookshelf_slot.png]image[2,1.3;1,1;default_bookshelf_slot.png]image[3,1.3;1,1;default_bookshelf_slot.png]image[4,1.3;1,1;default_bookshelf_slot.png]image[5,1.3;1,1;default_bookshelf_slot.png]image[6,1.3;1,1;default_bookshelf_slot.png]image[7,1.3;1,1;default_bookshelf_slot.png]"}, ["inventory"] = {["books"] = {"", "", "", "", "", "", "", "", "", "", "", "", "", "", "", ""}}}, ["y"] = 1, ["z"] = 6, ["name"] = "default:bookshelf"}, {["x"] = 13, ["meta"] = {["fields"] = {}, ["inventory"] = {}}, ["param2"] = 1, ["y"] = 1, ["z"] = 8, ["name"] = "xdecor:desertstone_tile"}, {["x"] = 13, ["meta"] = {["fields"] = {}, ["inventory"] = {}}, ["param2"] = 1, ["y"] = 2, ["z"] = 0, ["name"] = "xdecor:desertstone_tile"}, {["x"] = 13, ["meta"] = {["fields"] = {["formspec"] = "size[8,7;]bgcolor[#080808BB;true]background[5,5;1,1;gui_formbg.png;true]listcolors[#00000069;#5A5A5A;#141318;#30434C;#FFF]list[context;books;0,0.3;8,2;]list[current_player;main;0,2.85;8,1;]list[current_player;main;0,4.08;8,3;8]listring[context;books]listring[current_player;main]image[0,2.85;1,1;gui_hb_bg.png]image[1,2.85;1,1;gui_hb_bg.png]image[2,2.85;1,1;gui_hb_bg.png]image[3,2.85;1,1;gui_hb_bg.png]image[4,2.85;1,1;gui_hb_bg.png]image[5,2.85;1,1;gui_hb_bg.png]image[6,2.85;1,1;gui_hb_bg.png]image[7,2.85;1,1;gui_hb_bg.png]image[0,0.3;1,1;default_bookshelf_slot.png]image[1,0.3;1,1;default_bookshelf_slot.png]image[2,0.3;1,1;default_bookshelf_slot.png]image[3,0.3;1,1;default_bookshelf_slot.png]image[4,0.3;1,1;default_bookshelf_slot.png]image[5,0.3;1,1;default_bookshelf_slot.png]image[6,0.3;1,1;default_bookshelf_slot.png]image[7,0.3;1,1;default_bookshelf_slot.png]image[0,1.3;1,1;default_bookshelf_slot.png]image[1,1.3;1,1;default_bookshelf_slot.png]image[2,1.3;1,1;default_bookshelf_slot.png]image[3,1.3;1,1;default_bookshelf_slot.png]image[4,1.3;1,1;default_bookshelf_slot.png]image[5,1.3;1,1;default_bookshelf_slot.png]image[6,1.3;1,1;default_bookshelf_slot.png]image[7,1.3;1,1;default_bookshelf_slot.png]"}, ["inventory"] = {["books"] = {"", "", "", "", "", "", "", "", "", "", "", "", "", "", "", ""}}}, ["y"] = 2, ["z"] = 2, ["name"] = "default:bookshelf"}, {["x"] = 13, ["meta"] = {["fields"] = {["formspec"] = "size[8,7;]bgcolor[#080808BB;true]background[5,5;1,1;gui_formbg.png;true]listcolors[#00000069;#5A5A5A;#141318;#30434C;#FFF]list[context;books;0,0.3;8,2;]list[current_player;main;0,2.85;8,1;]list[current_player;main;0,4.08;8,3;8]listring[context;books]listring[current_player;main]image[0,2.85;1,1;gui_hb_bg.png]image[1,2.85;1,1;gui_hb_bg.png]image[2,2.85;1,1;gui_hb_bg.png]image[3,2.85;1,1;gui_hb_bg.png]image[4,2.85;1,1;gui_hb_bg.png]image[5,2.85;1,1;gui_hb_bg.png]image[6,2.85;1,1;gui_hb_bg.png]image[7,2.85;1,1;gui_hb_bg.png]image[0,0.3;1,1;default_bookshelf_slot.png]image[1,0.3;1,1;default_bookshelf_slot.png]image[2,0.3;1,1;default_bookshelf_slot.png]image[3,0.3;1,1;default_bookshelf_slot.png]image[4,0.3;1,1;default_bookshelf_slot.png]image[5,0.3;1,1;default_bookshelf_slot.png]image[6,0.3;1,1;default_bookshelf_slot.png]image[7,0.3;1,1;default_bookshelf_slot.png]image[0,1.3;1,1;default_bookshelf_slot.png]image[1,1.3;1,1;default_bookshelf_slot.png]image[2,1.3;1,1;default_bookshelf_slot.png]image[3,1.3;1,1;default_bookshelf_slot.png]image[4,1.3;1,1;default_bookshelf_slot.png]image[5,1.3;1,1;default_bookshelf_slot.png]image[6,1.3;1,1;default_bookshelf_slot.png]image[7,1.3;1,1;default_bookshelf_slot.png]"}, ["inventory"] = {["books"] = {"", "", "", "", "", "", "", "", "", "", "", "", "", "", "", ""}}}, ["y"] = 2, ["z"] = 4, ["name"] = "default:bookshelf"}, {["x"] = 13, ["meta"] = {["fields"] = {["formspec"] = "size[8,7;]bgcolor[#080808BB;true]background[5,5;1,1;gui_formbg.png;true]listcolors[#00000069;#5A5A5A;#141318;#30434C;#FFF]list[context;books;0,0.3;8,2;]list[current_player;main;0,2.85;8,1;]list[current_player;main;0,4.08;8,3;8]listring[context;books]listring[current_player;main]image[0,2.85;1,1;gui_hb_bg.png]image[1,2.85;1,1;gui_hb_bg.png]image[2,2.85;1,1;gui_hb_bg.png]image[3,2.85;1,1;gui_hb_bg.png]image[4,2.85;1,1;gui_hb_bg.png]image[5,2.85;1,1;gui_hb_bg.png]image[6,2.85;1,1;gui_hb_bg.png]image[7,2.85;1,1;gui_hb_bg.png]image[0,0.3;1,1;default_bookshelf_slot.png]image[1,0.3;1,1;default_bookshelf_slot.png]image[2,0.3;1,1;default_bookshelf_slot.png]image[3,0.3;1,1;default_bookshelf_slot.png]image[4,0.3;1,1;default_bookshelf_slot.png]image[5,0.3;1,1;default_bookshelf_slot.png]image[6,0.3;1,1;default_bookshelf_slot.png]image[7,0.3;1,1;default_bookshelf_slot.png]image[0,1.3;1,1;default_bookshelf_slot.png]image[1,1.3;1,1;default_bookshelf_slot.png]image[2,1.3;1,1;default_bookshelf_slot.png]image[3,1.3;1,1;default_bookshelf_slot.png]image[4,1.3;1,1;default_bookshelf_slot.png]image[5,1.3;1,1;default_bookshelf_slot.png]image[6,1.3;1,1;default_bookshelf_slot.png]image[7,1.3;1,1;default_bookshelf_slot.png]"}, ["inventory"] = {["books"] = {"", "", "", "", "", "", "", "", "", "", "", "", "", "", "", ""}}},