5:return {{["x"] = 0, ["y"] = 0, ["z"] = 2, ["name"] = "mcl_core:stone"}, {["x"] = 0, ["y"] = 0, ["z"] = 16, ["name"] = "mcl_core:stone"}, {["x"] = 0, ["y"] = 0, ["z"] = 17, ["name"] = "mcl_core:stone"}, {["x"] = 0, ["y"] = 0, ["z"] = 18, ["name"] = "mcl_core:stone"}, {["x"] = 0, ["y"] = 0, ["z"] = 19, ["name"] = "mcl_core:stone"}, {["x"] = 0, ["y"] = 0, ["z"] = 20, ["name"] = "mcl_core:stone"}, {["x"] = 0, ["y"] = 0, ["z"] = 21, ["name"] = "mcl_core:stone"}, {["x"] = 0, ["y"] = 1, ["z"] = 1, ["name"] = "mcl_core:wood"}, {["x"] = 0, ["y"] = 1, ["z"] = 2, ["name"] = "mcl_core:stone"}, {["x"] = 0, ["y"] = 1, ["z"] = 3, ["name"] = "mcl_core:wood"}, {["x"] = 0, ["y"] = 1, ["z"] = 4, ["name"] = "mcl_core:wood"}, {["x"] = 0, ["y"] = 1, ["z"] = 5, ["name"] = "mcl_core:wood"}, {["x"] = 0, ["y"] = 1, ["z"] = 6, ["name"] = "mcl_core:wood"}, {["x"] = 0, ["y"] = 1, ["z"] = 7, ["name"] = "mcl_core:wood"}, {["x"] = 0, ["y"] = 1, ["z"] = 8, ["name"] = "mcl_core:wood"}, {["x"] = 0, ["y"] = 1, ["z"] = 9, ["name"] = "mcl_core:wood"}, {["x"] = 0, ["y"] = 1, ["z"] = 10, ["name"] = "mcl_core:wood"}, {["x"] = 0, ["y"] = 1, ["z"] = 11, ["name"] = "mcl_core:wood"}, {["x"] = 0, ["y"] = 1, ["z"] = 12, ["name"] = "mcl_core:wood"}, {["x"] = 0, ["y"] = 1, ["z"] = 13, ["name"] = "mcl_core:wood"}, {["x"] = 0, ["y"] = 1, ["z"] = 14, ["name"] = "mcl_core:wood"}, {["x"] = 0, ["y"] = 1, ["z"] = 15, ["name"] = "mcl_core:wood"}, {["x"] = 0, ["y"] = 1, ["z"] = 16, ["name"] = "mcl_core:stone"}, {["x"] = 0, ["y"] = 1, ["z"] = 17, ["name"] = "mcl_core:stone"}, {["x"] = 0, ["y"] = 1, ["z"] = 18, ["name"] = "mcl_core:stone"}, {["x"] = 0, ["y"] = 1, ["z"] = 19, ["name"] = "mcl_core:stone"}, {["x"] = 0, ["y"] = 1, ["z"] = 20, ["name"] = "mcl_core:stone"}, {["x"] = 0, ["y"] = 1, ["z"] = 21, ["name"] = "mcl_core:stone"}, {["x"] = 0, ["y"] = 2, ["z"] = 2, ["name"] = "mcl_core:stone"}, {["x"] = 0, ["y"] = 2, ["z"] = 16, ["name"] = "mcl_core:stone"}, {["x"] = 0, ["y"] = 2, ["z"] = 17, ["name"] = "mcl_core:stone"}, {["x"] = 0, ["y"] = 2, ["z"] = 18, ["name"] = "mcl_core:stone"}, {["x"] = 0, ["y"] = 2, ["z"] = 19, ["name"] = "mcl_core:stone"}, {["x"] = 0, ["y"] = 2, ["z"] = 20, ["name"] = "mcl_core:stone"}, {["x"] = 0, ["y"] = 2, ["z"] = 21, ["name"] = "mcl_core:stone"}, {["x"] = 0, ["y"] = 3, ["z"] = 2, ["name"] = "mcl_core:stone"}, {["x"] = 0, ["param2"] = 4, ["y"] = 3, ["param1"] = 238, ["z"] = 15, ["name"] = "mcl_torches:torch_wall"}, {["x"] = 0, ["y"] = 3, ["z"] = 16, ["name"] = "mcl_core:stone"}, {["x"] = 0, ["y"] = 3, ["z"] = 17, ["name"] = "mcl_core:stone"}, {["x"] = 0, ["y"] = 3, ["z"] = 18, ["name"] = "mcl_core:stone"}, {["x"] = 0, ["y"] = 3, ["z"] = 19, ["name"] = "mcl_core:stone"}, {["x"] = 0, ["y"] = 3, ["z"] = 20, ["name"] = "mcl_core:stone"}, {["x"] = 0, ["y"] = 3, ["z"] = 21, ["name"] = "mcl_core:stone"}, {["x"] = 0, ["param2"] = 2, ["y"] = 4, ["param1"] = 238, ["z"] = 0, ["name"] = "mcl_torches:torch_wall"}, {["x"] = 0, ["y"] = 4, ["z"] = 2, ["name"] = "mcl_core:stone"}, {["x"] = 0, ["param2"] = 2, ["y"] = 4, ["param1"] = 238, ["z"] = 3, ["name"] = "mcl_torches:torch_wall"}, {["x"] = 0, ["param2"] = 2, ["y"] = 4, ["param1"] = 238, ["z"] = 7, ["name"] = "mcl_torches:torch_wall"}, {["x"] = 0, ["y"] = 4, ["z"] = 8, ["name"] = "mcl_core:granite"}, {["x"] = 0, ["y"] = 4, ["z"] = 9, ["name"] = "mcl_core:stone"}, {["x"] = 0, ["y"] = 4, ["z"] = 10, ["name"] = "mcl_core:stone"}, {["x"] = 0, ["y"] = 4, ["z"] = 11, ["name"] = "mcl_core:stone"}, {["x"] = 0, ["y"] = 4, ["z"] = 12, ["name"] = "mcl_core:stone"}, {["x"] = 0, ["y"] = 4, ["z"] = 16, ["name"] = "mcl_core:stone"}, {["x"] = 0, ["y"] = 4, ["z"] = 17, ["name"] = "mcl_core:stone"}, {["x"] = 0, ["y"] = 4, ["z"] = 18, ["name"] = "mcl_core:stone"}, {["x"] = 0, ["y"] = 4, ["z"] = 19, ["name"] = "mcl_core:stone"}, {["x"] = 0, ["y"] = 4, ["z"] = 20, ["name"] = "mcl_core:stone"}, {["x"] = 0, ["y"] = 4, ["z"] = 21, ["name"] = "mcl_core:stone"}, {["x"] = 0, ["y"] = 5, ["z"] = 0, ["name"] = "mcl_core:stone"}, {["x"] = 0, ["y"] = 5, ["z"] = 1, ["name"] = "mcl_core:stone"}, {["x"] = 0, ["y"] = 5, ["z"] = 2, ["name"] = "mcl_core:stone"}, {["x"] = 0, ["y"] = 5, ["z"] = 3, ["name"] = "mcl_core:stone"}, {["x"] = 0, ["y"] = 5, ["z"] = 4, ["name"] = "mcl_core:stone"}, {["x"] = 0, ["y"] = 5, ["z"] = 5, ["name"] = "mcl_core:stone"}, {["x"] = 0, ["y"] = 5, ["z"] = 6, ["name"] = "mcl_core:stone"}, {["x"] = 0, ["y"] = 5, ["z"] = 7, ["name"] = "mcl_core:stone"}, {["x"] = 0, ["y"] = 5, ["z"] = 8, ["name"] = "mcl_core:stone"}, {["x"] = 0, ["y"] = 5, ["z"] = 9, ["name"] = "mcl_core:stone"}, {["x"] = 0, ["y"] = 5, ["z"] = 10, ["name"] = "mcl_core:stone"}, {["x"] = 0, ["y"] = 5, ["z"] = 11, ["name"] = "mcl_core:stone"}, {["x"] = 0, ["y"] = 5, ["z"] = 12, ["name"] = "mcl_core:stone"}, {["x"] = 0, ["y"] = 5, ["z"] = 16, ["name"] = "mcl_core:stone"}, {["x"] = 0, ["y"] = 5, ["z"] = 17, ["name"] = "mcl_core:stone"}, {["x"] = 0, ["y"] = 5, ["z"] = 18, ["name"] = "mcl_core:stone"}, {["x"] = 0, ["y"] = 5, ["z"] = 19, ["name"] = "mcl_core:stone"}, {["x"] = 0, ["y"] = 5, ["z"] = 20, ["name"] = "mcl_core:stone"}, {["x"] = 0, ["y"] = 5, ["z"] = 21, ["name"] = "mcl_core:stone"}, {["x"] = 0, ["y"] = 6, ["z"] = 0, ["name"] = "mcl_core:stone"}, {["x"] = 0, ["y"] = 6, ["z"] = 1, ["name"] = "mcl_core:stone"}, {["x"] = 0, ["y"] = 6, ["z"] = 2, ["name"] = "mcl_core:stone"}, {["x"] = 0, ["y"] = 6, ["z"] = 3, ["name"] = "mcl_core:stone"}, {["x"] = 0, ["y"] = 6, ["z"] = 4, ["name"] = "mcl_core:stone"}, {["x"] = 0, ["y"] = 6, ["z"] = 5, ["name"] = "mcl_core:stone"}, {["x"] = 0, ["y"] = 6, ["z"] = 6, ["name"] = "mcl_core:stone"}, {["x"] = 0, ["y"] = 6, ["z"] = 7, ["name"] = "mcl_core:stone"}, {["x"] = 0, ["y"] = 6, ["z"] = 8, ["name"] = "mcl_core:stone"}, {["x"] = 0, ["y"] = 6, ["z"] = 9, ["name"] = "mcl_core:stone"}, {["x"] = 0, ["y"] = 6, ["z"] = 10, ["name"] = "mcl_core:stone"}, {["x"] = 0, ["y"] = 6, ["z"] = 11, ["name"] = "mcl_core:stone"}, {["x"] = 0, ["y"] = 6, ["z"] = 12, ["name"] = "mcl_core:stone"}, {["x"] = 0, ["y"] = 6, ["z"] = 16, ["name"] = "mcl_core:stone"}, {["x"] = 0, ["y"] = 6, ["z"] = 17, ["name"] = "mcl_core:stone"}, {["x"] = 0, ["y"] = 6, ["z"] = 18, ["name"] = "mcl_core:stone"}, {["x"] = 0, ["y"] = 6, ["z"] = 19, ["name"] = "mcl_core:stone"}, {["x"] = 0, ["y"] = 6, ["z"] = 20, ["name"] = "mcl_core:stone"}, {["x"] = 0, ["y"] = 6, ["z"] = 21, ["name"] = "mcl_core:stone"}, {["x"] = 0, ["y"] = 7, ["z"] = 0, ["name"] = "mcl_core:stone"}, {["x"] = 0, ["y"] = 7, ["z"] = 1, ["name"] = "mcl_core:stone"}, {["x"] = 0, ["y"] = 7, ["z"] = 2, ["name"] = "mcl_core:stone"}, {["x"] = 0, ["y"] = 7, ["z"] = 3, ["name"] = "mcl_core:stone"}, {["x"] = 0, ["y"] = 7, ["z"] = 4, ["name"] = "mcl_core:stone"}, {["x"] = 0, ["y"] = 7, ["z"] = 5, ["name"] = "mcl_core:stone"}, {["x"] = 0, ["y"] = 7, ["z"] = 6, ["name"] = "mcl_core:stone"}, {["x"] = 0, ["y"] = 7, ["z"] = 7, ["name"] = "mcl_core:stone"}, {["x"] = 0, ["y"] = 7, ["z"] = 8, ["name"] = "mcl_core:stone"}, {["x"] = 0, ["y"] = 7, ["z"] = 9, ["name"] = "mcl_core:stone"}, {["x"] = 0, ["y"] = 7, ["z"] = 10, ["name"] = "mcl_core:stone"}, {["x"] = 0, ["y"] = 7, ["z"] = 11, ["name"] = "mcl_core:stone"}, {["x"] = 0, ["y"] = 7, ["z"] = 12, ["name"] = "mcl_core:stone"}, {["x"] = 0, ["y"] = 7, ["z"] = 13, ["name"] = "mcl_core:stone"}, {["x"] = 0, ["y"] = 7, ["z"] = 14, ["name"] = "mcl_core:stone"}, {["x"] = 0, ["y"] = 7, ["z"] = 15, ["name"] = "mcl_core:stone"}, {["x"] = 0, ["y"] = 7, ["z"] = 16, ["name"] = "mcl_core:stone"}, {["x"] = 0, ["y"] = 7, ["z"] = 17, ["name"] = "mcl_core:stone"}, {["x"] = 0, ["y"] = 7, ["z"] = 18, ["name"] = "mcl_core:stone"}, {["x"] = 0, ["y"] = 7, ["z"] = 19, ["name"] = "mcl_core:stone"}, {["x"] = 0, ["y"] = 7, ["z"] = 20, ["name"] = "mcl_core:stone"}, {["x"] = 0, ["y"] = 7, ["z"] = 21, ["name"] = "mcl_core:stone"}, {["x"] = 0, ["y"] = 8, ["z"] = 0, ["name"] = "mcl_core:stone"}, {["x"] = 0, ["y"] = 8, ["z"] = 1, ["name"] = "mcl_core:stone"}, {["x"] = 0, ["y"] = 8, ["z"] = 2, ["name"] = "mcl_core:stone"}, {["x"] = 0, ["y"] = 8, ["z"] = 3, ["name"] = "mcl_core:stone"}, {["x"] = 0, ["y"] = 8, ["z"] = 4, ["name"] = "mcl_core:stone"}, {["x"] = 0, ["y"] = 8, ["z"] = 5, ["name"] = "mcl_core:stone"}, {["x"] = 0, ["y"] = 8, ["z"] = 6, ["name"] = "mcl_core:stone"}, {["x"] = 0, ["y"] = 8, ["z"] = 7, ["name"] = "mcl_core:stone"}, {["x"] = 0, ["y"] = 8, ["z"] = 8, ["name"] = "mcl_core:stone"}, {["x"] = 0, ["y"] = 8, ["z"] = 9, ["name"] = "mcl_core:stone"}, {["x"] = 0, ["y"] = 8, ["z"] = 10, ["name"] = "mcl_core:stone"}, {["x"] = 0, ["y"] = 8, ["z"] = 11, ["name"] = "mcl_core:stone"}, {["x"] = 0, ["y"] = 8, ["z"] = 12, ["name"] = "mcl_core:stone"}, {["x"] = 0, ["y"] = 8, ["z"] = 13, ["name"] = "mcl_core:stone"}, {["x"] = 0, ["y"] = 8, ["z"] = 14, ["name"] = "mcl_core:stone"}, {["x"] = 0, ["y"] = 8, ["z"] = 15, ["name"] = "mcl_core:stone"}, {["x"] = 0, ["y"] = 8, ["z"] = 16, ["name"] = "mcl_core:stone"}, {["x"] = 0, ["y"] = 8, ["z"] = 17, ["name"] = "mcl_core:stone"}, {["x"] = 0, ["y"] = 8, ["z"] = 18, ["name"] = "mcl_core:stone"}, {["x"] = 0, ["y"] = 8, ["z"] = 19, ["name"] = "mcl_core:stone"}, {["x"] = 0, ["y"] = 8, ["z"] = 20, ["name"] = "mcl_core:stone"}, {["x"] = 0, ["y"] = 8, ["z"] = 21, ["name"] = "mcl_core:stone"}, {["x"] = 0, ["y"] = 9, ["z"] = 0, ["name"] = "mcl_core:stone"}, {["x"] = 0, ["y"] = 9, ["z"] = 1, ["name"] = "mcl_core:stone"}, {["x"] = 0, ["y"] = 9, ["z"] = 2, ["name"] = "mcl_core:stone"}, {["x"] = 0, ["y"] = 9, ["z"] = 3, ["name"] = "mcl_core:stone"}, {["x"] = 0, ["y"] = 9, ["z"] = 4, ["name"] = "mcl_core:stone"}, {["x"] = 0, ["y"] = 9, ["z"] = 5, ["name"] = "mcl_core:stone"}, {["x"] = 0, ["y"] = 9, ["z"] = 6, ["name"] = "mcl_core:stone"}, {["x"] = 0, ["y"] = 9, ["z"] = 7, ["name"] = "mcl_core:stone"}, {["x"] = 0, ["y"] = 9, ["z"] = 8, ["name"] = "mcl_core:stone"}, {["x"] = 0, ["y"] = 9, ["z"] = 9, ["name"] = "mcl_core:stone"}, {["x"] = 0, ["y"] = 9, ["z"] = 10, ["name"] = "mcl_core:stone"}, {["x"] = 0, ["y"] = 9, ["z"] = 11, ["name"] = "mcl_core:stone"}, {["x"] = 0, ["y"] = 9, ["z"] = 12, ["name"] = "mcl_core:stone"}, {["x"] = 0, ["y"] = 9, ["z"] = 13, ["name"] = "mcl_core:stone"}, {["x"] = 0, ["y"] = 9, ["z"] = 14, ["name"] = "mcl_core:stone"}, {["x"] = 0, ["y"] = 9, ["z"] = 15, ["name"] = "mcl_core:stone"}, {["x"] = 0, ["y"] = 9, ["z"] = 16, ["name"] = "mcl_core:stone"}, {["x"] = 0, ["y"] = 9, ["z"] = 17, ["name"] = "mcl_core:stone"}, {["x"] = 0, ["y"] = 9, ["z"] = 18, ["name"] = "mcl_core:stone"}, {["x"] = 0, ["y"] = 9, ["z"] = 19, ["name"] = "mcl_core:stone"}, {["x"] = 0, ["y"] = 9, ["z"] = 20, ["name"] = "mcl_core:stone"}, {["x"] = 0, ["y"] = 9, ["z"] = 21, ["name"] = "mcl_core:stone"}, {["x"] = 0, ["y"] = 10, ["z"] = 0, ["name"] = "mcl_core:stone"}, {["x"] = 0, ["y"] = 10, ["z"] = 1, ["name"] = "mcl_core:stone"}, {["x"] = 0, ["y"] = 10, ["z"] = 2, ["name"] = "mcl_core:stone"}, {["x"] = 0, ["y"] = 10, ["z"] = 3, ["name"] = "mcl_core:stone"}, {["x"] = 0, ["y"] = 10, ["z"] = 4, ["name"] = "mcl_core:stone"}, {["x"] = 0, ["y"] = 10, ["z"] = 5, ["name"] = "mcl_core:stone"}, {["x"] = 0, ["y"] = 10, ["z"] = 6, ["name"] = "mcl_core:stone"}, {["x"] = 0, ["y"] = 10, ["z"] = 7, ["name"] = "mcl_core:stone"}, {["x"] = 0, ["y"] = 10, ["z"] = 8, ["name"] = "mcl_core:stone"}, {["x"] = 0, ["y"] = 10, ["z"] = 9, ["name"] = "mcl_core:stone"}, {["x"] = 0, ["y"] = 10, ["z"] = 10, ["name"] = "mcl_core:stone"}, {["x"] = 0, ["y"] = 10, ["z"] = 11, ["name"] = "mcl_core:stone"}, {["x"] = 0, ["y"] = 10, ["param1"] = 238, ["z"] = 12, ["name"] = "mcl_nether:glowstone"}, {["x"] = 0, ["y"] = 10, ["z"] = 13, ["name"] = "mcl_core:stone"}, {["x"] = 0, ["y"] = 10, ["z"] = 14, ["name"] = "mcl_core:stone"}, {["x"] = 0, ["y"] = 10, ["z"] = 15, ["name"] = "mcl_core:stone"}, {["x"] = 0, ["y"] = 10, ["z"] = 16, ["name"] = "mcl_core:stone"}, {["x"] = 0, ["y"] = 10, ["z"] = 17, ["name"] = "mcl_core:stone"}, {["x"] = 0, ["y"] = 10, ["z"] = 18, ["name"] = "mcl_core:stone"}, {["x"] = 0, ["y"] = 10, ["z"] = 19, ["name"] = "mcl_core:stone"}, {["x"] = 0, ["y"] = 10, ["z"] = 20, ["name"] = "mcl_core:stone"}, {["x"] = 0, ["y"] = 10, ["z"] = 21, ["name"] = "mcl_core:stone"}, {["x"] = 0, ["y"] = 11, ["z"] = 0, ["name"] = "mcl_core:stone"}, {["x"] = 0, ["y"] = 11, ["z"] = 1, ["name"] = "mcl_core:stone"}, {["x"] = 0, ["y"] = 11, ["z"] = 2, ["name"] = "mcl_core:stone"}, {["x"] = 0, ["y"] = 11, ["z"] = 3, ["name"] = "mcl_core:stone"}, {["x"] = 0, ["y"] = 11, ["z"] = 4, ["name"] = "mcl_core:stone"}, {["x"] = 0, ["y"] = 11, ["z"] = 5, ["name"] = "mcl_core:stone"}, {["x"] = 0, ["y"] = 11, ["z"] = 6, ["name"] = "mcl_core:stone"}, {["x"] = 0, ["y"] = 11, ["z"] = 7, ["name"] = "mcl_core:stone"}, {["x"] = 0, ["y"] = 11, ["z"] = 8, ["name"] = "mcl_core:stone"}, {["x"] = 0, ["y"] = 11, ["z"] = 9, ["name"] = "mcl_core:stone"}, {["x"] = 0, ["y"] = 11, ["z"] = 10, ["name"] = "mcl_core:stone"}, {["x"] = 0, ["y"] = 11, ["z"] = 11, ["name"] = "mcl_core:stone"}, {["x"] = 0, ["y"] = 11, ["z"] = 12, ["name"] = "mcl_core:stone"}, {["x"] = 0, ["y"] = 11, ["z"] = 13, ["name"] = "mcl_core:stone"}, {["x"] = 0, ["y"] = 11, ["z"] = 14, ["name"] = "mcl_core:stone"}, {["x"] = 0, ["y"] = 11, ["z"] = 15, ["name"] = "mcl_core:stone"}, {["x"] = 0, ["y"] = 11, ["z"] = 16, ["name"] = "mcl_core:stone"}, {["x"] = 0, ["y"] = 11, ["z"] = 17, ["name"] = "mcl_core:stone"}, {["x"] = 0, ["y"] = 11, ["z"] = 18, ["name"] = "mcl_core:stone"}, {["x"] = 0, ["y"] = 11, ["z"] = 19, ["name"] = "mcl_core:stone"}, {["x"] = 0, ["y"] = 11, ["z"] = 20, ["name"] = "mcl_core:stone"}, {["x"] = 0, ["y"] = 11, ["z"] = 21, ["name"] = "mcl_core:stone"}, {["x"] = 0, ["y"] = 12, ["z"] = 0, ["name"] = "mcl_core:stone"}, {["x"] = 0, ["y"] = 12, ["z"] = 1, ["name"] = "mcl_core:stone"}, {["x"] = 0, ["y"] = 12, ["z"] = 2, ["name"] = "mcl_core:stone"}, {["x"] = 0, ["y"] = 12, ["z"] = 3, ["name"] = "mcl_core:stone"}, {["x"] = 0, ["y"] = 12, ["z"] = 4, ["name"] = "mcl_core:stone"}, {["x"] = 0, ["y"] = 12, ["z"] = 5, ["name"] = "mcl_core:stone"}, {["x"] = 0, ["y"] = 12, ["z"] = 6, ["name"] = "mcl_core:stone"}, {["x"] = 0, ["y"] = 12, ["z"] = 7, ["name"] = "mcl_core:stone"}, {["x"] = 0, ["y"] = 12, ["z"] = 8, ["name"] = "mcl_core:stone"}, {["x"] = 0, ["y"] = 12, ["z"] = 9, ["name"] = "mcl_core:stone"}, {["x"] = 0, ["y"] = 12, ["z"] = 10, ["name"] = "mcl_core:stone"}, {["x"] = 0, ["y"] = 12, ["z"] = 11, ["name"] = "mcl_core:cobble"}, {["x"] = 0, ["y"] = 12, ["z"] = 12, ["name"] = "mcl_core:stone"}, {["x"] = 0, ["y"] = 12, ["z"] = 13, ["name"] = "mcl_core:stone"}, {["x"] = 0, ["y"] = 12, ["z"] = 14, ["name"] = "mcl_core:stone"}, {["x"] = 0, ["y"] = 12, ["z"] = 15, ["name"] = "mcl_core:stone"}, {["x"] = 0, ["y"] = 12, ["z"] = 16, ["name"] = "mcl_core:stone"}, {["x"] = 0, ["y"] = 12, ["z"] = 17, ["name"] = "mcl_core:stone"}, {["x"] = 0, ["y"] = 12, ["z"] = 18, ["name"] = "mcl_core:stone"}, {["x"] = 0, ["y"] = 12, ["z"] = 19, ["name"] = "mcl_core:stone"}, {["x"] = 0, ["y"] = 12, ["z"] = 20, ["name"] = "mcl_core:stone"}, {["x"] = 0, ["y"] = 12, ["z"] = 21, ["name"] = "mcl_core:stone"}, {["x"] = 0, ["y"] = 13, ["z"] = 0, ["name"] = "mcl_core:stone"}, {["x"] = 0, ["y"] = 13, ["z"] = 1, ["name"] = "mcl_core:stone"}, {["x"] = 0, ["y"] = 13, ["z"] = 2, ["name"] = "mcl_core:stone"}, {["x"] = 0, ["y"] = 13, ["z"] = 3, ["name"] = "mcl_core:stone"}, {["x"] = 0, ["y"] = 13, ["z"] = 4, ["name"] = "mcl_core:stone"}, {["x"] = 0, ["y"] = 13, ["z"] = 5, ["name"] = "mcl_core:stone"}, {["x"] = 0, ["y"] = 13, ["z"] = 6, ["name"] = "mcl_core:stone"}, {["x"] = 0, ["y"] = 13, ["z"] = 7, ["name"] = "mcl_core:stone"}, {["x"] = 0, ["y"] = 13, ["z"] = 8, ["name"] = "mcl_core:stone"}, {["x"] = 0, ["y"] = 13, ["z"] = 9, ["name"] = "mcl_core:stone"}, {["x"] = 0, ["y"] = 13, ["z"] = 10, ["name"] = "mcl_core:stone"}, {["x"] = 0, ["y"] = 13, ["z"] = 11, ["name"] = "mcl_core:diorite"}, {["x"] = 0, ["y"] = 13, ["z"] = 12, ["name"] = "mcl_core:stone"}, {["x"] = 0, ["y"] = 13, ["z"] = 13, ["name"] = "mcl_core:stone"}, {["x"] = 0, ["y"] = 13, ["z"] = 14, ["name"] = "mcl_core:stone"}, {["x"] = 0, ["y"] = 13, ["z"] = 15, ["name"] = "mcl_core:stone"}, {["x"] = 0, ["y"] = 13, ["z"] = 16, ["name"] = "mcl_core:stone"}, {["x"] = 0, ["y"] = 13, ["z"] = 17, ["name"] = "mcl_core:stone"}, {["x"] = 0, ["y"] = 13, ["z"] = 18, ["name"] = "mcl_core:stone"}, {["x"] = 0, ["y"] = 13, ["z"] = 19, ["name"] = "mcl_core:stone"}, {["x"] = 0, ["y"] = 13, ["z"] = 20, ["name"] = "mcl_core:stone"}, {["x"] = 0, ["y"] = 13, ["z"] = 21, ["name"] = "mcl_core:stone"}, {["x"] = 0, ["y"] = 14, ["z"] = 0, ["name"] = "mcl_core:stone"}, {["x"] = 0, ["y"] = 14, ["z"] = 1, ["name"] = "mcl_core:stone"}, {["x"] = 0, ["y"] = 14, ["z"] = 2, ["name"] = "mcl_core:stone"}, {["x"] = 0, ["y"] = 14, ["z"] = 3, ["name"] = "mcl_core:stone"}, {["x"] = 0, ["y"] = 14, ["z"] = 4, ["name"] = "mcl_core:stone"}, {["x"] = 0, ["y"] = 14, ["z"] = 5, ["name"] = "mcl_core:stone"}, {["x"] = 0, ["y"] = 14, ["z"] = 6, ["name"] = "mcl_core:stone"}, {["x"] = 0, ["y"] = 14, ["z"] = 7, ["name"] = "mcl_core:stone"}, {["x"] = 0, ["y"] = 14, ["z"] = 8, ["name"] = "mcl_core:stone"}, {["x"] = 0, ["y"] = 14, ["z"] = 9, ["name"] = "mcl_core:stone"}, {["x"] = 0, ["y"] = 14, ["z"] = 10, ["name"] = "mcl_core:stone"}, {["x"] = 0, ["y"] = 14, ["z"] = 11, ["name"] = "mcl_core:diorite"}, {["x"] = 0, ["y"] = 14, ["z"] = 12, ["name"] = "mcl_core:stone"}, {["x"] = 0, ["y"] = 14, ["z"] = 13, ["name"] = "mcl_core:stone"}, {["x"] = 0, ["y"] = 14, ["z"] = 14, ["name"] = "mcl_core:stone"}, {["x"] = 0, ["y"] = 14, ["z"] = 15, ["name"] = "mcl_core:stone"}, {["x"] = 0, ["y"] = 14, ["z"] = 16, ["name"] = "mcl_core:stone"}, {["x"] = 0, ["y"] = 14, ["z"] = 17, ["name"] = "mcl_core:stone"}, {["x"] = 0, ["y"] = 14, ["z"] = 18, ["name"] = "mcl_core:stone"}, {["x"] = 0, ["y"] = 14, ["z"] = 19, ["name"] = "mcl_core:stone"}, {["x"] = 0, ["y"] = 14, ["z"] = 20, ["name"] = "mcl_core:stone"}, {["x"] = 0, ["y"] = 14, ["z"] = 21, ["name"] = "mcl_core:stone"}, {["x"] = 0, ["y"] = 15, ["z"] = 0, ["name"] = "mcl_core:stone"}, {["x"] = 0, ["y"] = 15, ["z"] = 1, ["name"] = "mcl_core:stone"}, {["x"] = 0, ["y"] = 15, ["z"] = 2, ["name"] = "mcl_core:stone"}, {["x"] = 0, ["y"] = 15, ["z"] = 3, ["name"] = "mcl_core:stone"}, {["x"] = 0, ["y"] = 15, ["z"] = 4, ["name"] = "mcl_core:stone"}, {["x"] = 0, ["y"] = 15, ["z"] = 5, ["name"] = "mcl_core:stone"}, {["x"] = 0, ["y"] = 15, ["z"] = 6, ["name"] = "mcl_core:stone"}, {["x"] = 0, ["y"] = 15, ["z"] = 7, ["name"] = "mcl_core:stone"}, {["x"] = 0, ["y"] = 15, ["z"] = 8, ["name"] = "mcl_core:stone"}, {["x"] = 0, ["y"] = 15, ["z"] = 9, ["name"] = "mcl_core:stone"}, {["x"] = 0, ["y"] = 15, ["z"] = 10, ["name"] = "mcl_core:stone"}, {["x"] = 0, ["y"] = 15, ["z"] = 11, ["name"] = "mcl_core:diorite"}, {["x"] = 0, ["y"] = 15, ["z"] = 12, ["name"] = "mcl_core:stone"}, {["x"] = 0, ["y"] = 15, ["z"] = 13, ["name"] = "mcl_core:stone"}, {["x"] = 0, ["y"] = 15, ["z"] = 14, ["name"] = "mcl_core:stone"}, {["x"] = 0, ["y"] = 15, ["z"] = 15, ["name"] = "mcl_core:stone"}, {["x"] = 0, ["y"] = 15, ["z"] = 16, ["name"] = "mcl_core:stone"}, {["x"] = 0, ["y"] = 15, ["z"] = 17, ["name"] = "mcl_core:stone"}, {["x"] = 0, ["y"] = 15, ["z"] = 18, ["name"] = "mcl_core:stone"}, {["x"] = 0, ["y"] = 15, ["z"] = 19, ["name"] = "mcl_core:stone"}, {["x"] = 0, ["y"] = 15, ["z"] = 20, ["name"] = "mcl_core:stone"}, {["x"] = 0, ["y"] = 15, ["z"] = 21, ["name"] = "mcl_core:stone"}, {["x"] = 0, ["y"] = 16, ["z"] = 0, ["name"] = "mcl_core:stone"}, {["x"] = 0, ["y"] = 16, ["z"] = 1, ["name"] = "mcl_core:stone"}, {["x"] = 0, ["y"] = 16, ["z"] = 2, ["name"] = "mcl_core:stone"}, {["x"] = 0, ["y"] = 16, ["z"] = 3, ["name"] = "mcl_core:stone"}, {["x"] = 0, ["y"] = 16, ["z"] = 4, ["name"] = "mcl_core:stone"}, {["x"] = 0, ["y"] = 16, ["z"] = 5, ["name"] = "mcl_core:stone"}, {["x"] = 0, ["y"] = 16, ["z"] = 6, ["name"] = "mcl_core:stone"}, {["x"] = 0, ["y"] = 16, ["z"] = 7, ["name"] = "mcl_core:stone"}, {["x"] = 0, ["y"] = 16, ["z"] = 8, ["name"] = "mcl_core:stone"}, {["x"] = 0, ["y"] = 16, ["z"] = 9, ["name"] = "mcl_core:stone"}, {["x"] = 0, ["y"] = 16, ["z"] = 10, ["name"] = "mcl_core:stone"}, {["x"] = 0, ["y"] = 16, ["z"] = 11, ["name"] = "mcl_core:stone"}, {["x"] = 0, ["y"] = 16, ["z"] = 12, ["name"] = "mcl_core:stone"}, {["x"] = 0, ["y"] = 16, ["z"] = 13, ["name"] = "mcl_core:stone"}, {["x"] = 0, ["y"] = 16, ["z"] = 14, ["name"] = "mcl_core:stone"}, {["x"] = 0, ["y"] = 16, ["z"] = 15, ["name"] = "mcl_core:stone"}, {["x"] = 0, ["y"] = 16, ["z"] = 16, ["name"] = "mcl_core:stone"}, {["x"] = 0, ["y"] = 16, ["z"] = 17, ["name"] = "mcl_core:stone"}, {["x"] = 0, ["y"] = 16, ["z"] = 18, ["name"] = "mcl_core:stone"}, {["x"] = 0, ["y"] = 16, ["z"] = 19, ["name"] = "mcl_core:stone"}, {["x"] = 0, ["y"] = 16, ["z"] = 20, ["name"] = "mcl_core:stone"}, {["x"] = 0, ["y"] = 16, ["z"] = 21, ["name"] = "mcl_core:stone"}, {["x"] = 0, ["y"] = 17, ["z"] = 0, ["name"] = "mcl_core:stone"}, {["x"] = 0, ["y"] = 17, ["z"] = 1, ["name"] = "mcl_core:stone"}, {["x"] = 0, ["y"] = 17, ["z"] = 2, ["name"] = "mcl_core:stone"}, {["x"] = 0, ["y"] = 17, ["z"] = 3, ["name"] = "mcl_core:stone"}, {["x"] = 0, ["y"] = 17, ["z"] = 4, ["name"] = "mcl_core:stone"}, {["x"] = 0, ["y"] = 17, ["z"] = 5, ["name"] = "mcl_core:stone"}, {["x"] = 0, ["y"] = 17, ["z"] = 6, ["name"] = "mcl_core:stone"}, {["x"] = 0, ["y"] = 17, ["z"] = 7, ["name"] = "mcl_core:stone"}, {["x"] = 0, ["y"] = 17, ["z"] = 8, ["name"] = "mcl_core:stone"}, {["x"] = 0, ["y"] = 17, ["z"] = 9, ["name"] = "mcl_core:stone"}, {["x"] = 0, ["y"] = 17, ["z"] = 10, ["name"] = "mcl_core:stone"}, {["x"] = 0, ["y"] = 17, ["z"] = 11, ["name"] = "mcl_core:stone"}, {["x"] = 0, ["y"] = 17, ["z"] = 12, ["name"] = "mcl_core:stone"}, {["x"] = 0, ["y"] = 17, ["z"] = 13, ["name"] = "mcl_core:stone"}, {["x"] = 0, ["y"] = 17, ["z"] = 14, ["name"] = "mcl_core:stone"}, {["x"] = 0, ["y"] = 17, ["z"] = 15, ["name"] = "mcl_core:stone"}, {["x"] = 0, ["y"] = 17, ["z"] = 16, ["name"] = "mcl_core:stone"}, {["x"] = 0, ["y"] = 17, ["z"] = 17, ["name"] = "mcl_core:stone"}, {["x"] = 0, ["y"] = 17, ["z"] = 18, ["name"] = "mcl_core:stone"}, {["x"] = 0, ["y"] = 17, ["z"] = 19, ["name"] = "mcl_core:stone"}, {["x"] = 0, ["y"] = 17, ["z"] = 20, ["name"] = "mcl_core:stone"}, {["x"] = 0, ["y"] = 17, ["z"] = 21, ["name"] = "mcl_core:stone"}, {["x"] = 0, ["y"] = 18, ["z"] = 0, ["name"] = "mcl_core:dirt"}, {["x"] = 0, ["y"] = 18, ["z"] = 1, ["name"] = "mcl_core:dirt"}, {["x"] = 0, ["y"] = 18, ["z"] = 2, ["name"] = "mcl_core:dirt"}, {["x"] = 0, ["y"] = 18, ["z"] = 3, ["name"] = "mcl_core:dirt_with_grass"}, {["x"] = 0, ["y"] = 18, ["z"] = 4, ["name"] = "mcl_core:dirt"}, {["x"] = 0, ["y"] = 18, ["z"] = 5, ["name"] = "mcl_core:dirt"}, {["x"] = 0, ["y"] = 18, ["z"] = 6, ["name"] = "mcl_core:dirt"}, {["x"] = 0, ["y"] = 18, ["z"] = 7, ["name"] = "mcl_core:dirt"}, {["x"] = 0, ["y"] = 18, ["z"] = 8, ["name"] = "mcl_core:dirt"}, {["x"] = 0, ["y"] = 18, ["z"] = 9, ["name"] = "mcl_core:dirt"}, {["x"] = 0, ["y"] = 18, ["z"] = 10, ["name"] = "mcl_core:dirt"}, {["x"] = 0, ["y"] = 18, ["z"] = 11, ["name"] = "mcl_core:dirt"}, {["x"] = 0, ["y"] = 18, ["z"] = 12, ["name"] = "mcl_core:dirt"}, {["x"] = 0, ["y"] = 18, ["z"] = 13, ["name"] = "mcl_core:dirt"}, {["x"] = 0, ["y"] = 18, ["z"] = 14, ["name"] = "mcl_core:dirt"}, {["x"] = 0, ["y"] = 18, ["z"] = 15, ["name"] = "mcl_core:dirt"}, {["x"] = 0, ["y"] = 18, ["z"] = 16, ["name"] = "mcl_core:dirt"}, {["x"] = 0, ["y"] = 18, ["z"] = 17, ["name"] = "mcl_core:dirt"}, {["x"] = 0, ["y"] = 18, ["z"] = 18, ["name"] = "mcl_core:dirt"}, {["x"] = 0, ["y"] = 18, ["z"] = 19, ["name"] = "mcl_core:dirt"}, {["x"] = 0, ["y"] = 18, ["z"] = 20, ["name"] = "mcl_core:dirt"}, {["x"] = 0, ["y"] = 18, ["z"] = 21, ["name"] = "mcl_core:dirt"}, {["x"] = 0, ["y"] = 19, ["z"] = 0, ["name"] = "mcl_core:dirt_with_grass"}, {["x"] = 0, ["y"] = 19, ["z"] = 1, ["name"] = "mcl_core:dirt_with_grass"}, {["x"] = 0, ["y"] = 19, ["z"] = 2, ["name"] = "mcl_core:dirt_with_grass"}, {["x"] = 0, ["y"] = 19, ["z"] = 4, ["name"] = "mcl_core:dirt_with_grass"}, {["x"] = 0, ["y"] = 19, ["z"] = 5, ["name"] = "mcl_core:dirt_with_grass"}, {["x"] = 0, ["y"] = 19, ["z"] = 6, ["name"] = "mcl_core:dirt_with_grass"}, {["x"] = 0, ["y"] = 19, ["z"] = 7, ["name"] = "mcl_core:dirt_with_grass"}, {["x"] = 0, ["y"] = 19, ["z"] = 8, ["name"] = "mcl_core:dirt_with_grass"}, {["x"] = 0, ["y"] = 19, ["z"] = 9, ["name"] = "mcl_core:dirt"}, {["x"] = 0, ["y"] = 19, ["z"] = 10, ["name"] = "mcl_core:dirt_with_grass"}, {["x"] = 0, ["y"] = 19, ["z"] = 11, ["name"] = "mcl_core:dirt_with_grass"}, {["x"] = 0, ["y"] = 19, ["z"] = 12, ["name"] = "mcl_core:dirt_with_grass"}, {["x"] = 0, ["y"] = 19, ["z"] = 13, ["name"] = "mcl_core:dirt_with_grass"}, {["x"] = 0, ["y"] = 19, ["z"] = 14, ["name"] = "mcl_core:dirt_with_grass"}, {["x"] = 0, ["y"] = 19, ["z"] = 15, ["name"] = "mcl_core:dirt_with_grass"}, {["x"] = 0, ["y"] = 19, ["z"] = 16, ["name"] = "mcl_core:dirt_with_grass"}, {["x"] = 0, ["y"] = 19, ["z"] = 17, ["name"] = "mcl_core:dirt_with_grass"}, {["x"] = 0, ["y"] = 19, ["z"] = 18, ["name"] = "mcl_core:dirt_with_grass"}, {["x"] = 0, ["y"] = 19, ["z"] = 19, ["name"] = "mcl_core:dirt_with_grass"}, {["x"] = 0, ["y"] = 19, ["z"] = 20, ["name"] = "mcl_core:dirt_with_grass"}, {["x"] = 0, ["y"] = 19, ["z"] = 21, ["name"] = "mcl_core:dirt_with_grass"}, {["x"] = 0, ["y"] = 20, ["param1"] = 15, ["z"] = 8, ["name"] = "mcl_flowers:tallgrass"}, {["x"] = 0, ["y"] = 20, ["z"] = 9, ["name"] = "mcl_core:dirt_with_grass"}, {["x"] = 1, ["y"] = 0, ["z"] = 0, ["name"] = "mcl_core:stone"}, {["x"] = 1, ["y"] = 0, ["z"] = 1, ["name"] = "mcl_core:stone"}, {["x"] = 1, ["y"] = 0, ["z"] = 2, ["name"] = "mcl_core:stone"}, {["x"] = 1, ["y"] = 0, ["z"] = 3, ["name"] = "mcl_core:stone"}, {["x"] = 1, ["y"] = 0, ["z"] = 4, ["name"] = "mcl_core:stone"}, {["x"] = 1, ["y"] = 0, ["z"] = 5, ["name"] = "mcl_core:stone"}, {["x"] = 1, ["y"] = 0, ["z"] = 6, ["name"] = "mcl_core:stone"}, {["x"] = 1, ["y"] = 0, ["z"] = 7, ["name"] = "mcl_core:stone"}, {["x"] = 1, ["param2"] = 2, ["y"] = 0, ["param1"] = 238, ["z"] = 14, ["name"] = "mcl_torches:torch_wall"}, {["x"] = 1, ["y"] = 0, ["z"] = 15, ["name"] = "mcl_core:stone"}, {["x"] = 1, ["y"] = 0, ["z"] = 16, ["name"] = "mcl_core:dirt"}, {["x"] = 1, ["y"] = 0, ["z"] = 17, ["name"] = "mcl_core:stone"}, {["x"] = 1, ["y"] = 0, ["z"] = 18, ["name"] = "mcl_core:stone"}, {["x"] = 1, ["y"] = 0, ["z"] = 19, ["name"] = "mcl_core:stone"}, {["x"] = 1, ["y"] = 0, ["z"] = 20, ["name"] = "mcl_core:stone"}, {["x"] = 1, ["y"] = 0, ["z"] = 21, ["name"] = "mcl_core:stone"}, {["x"] = 1, ["y"] = 1, ["z"] = 0, ["name"] = "mcl_core:stone"}, {["x"] = 1, ["y"] = 1, ["z"] = 1, ["name"] = "mcl_core:stone"}, {["x"] = 1, ["y"] = 1, ["z"] = 2, ["name"] = "mcl_core:stone"}, {["x"] = 1, ["y"] = 1, ["z"] = 3, ["name"] = "mcl_core:stone"}, {["x"] = 1, ["y"] = 1, ["z"] = 4, ["name"] = "mcl_core:stone"}, {["x"] = 1, ["y"] = 1, ["z"] = 5, ["name"] = "mcl_core:stone"}, {["x"] = 1, ["y"] = 1, ["z"] = 6, ["name"] = "mcl_core:stone"}, {["x"] = 1, ["y"] = 1, ["z"] = 7, ["name"] = "mcl_core:stone"}, {["x"] = 1, ["y"] = 1, ["z"] = 8, ["name"] = "mcl_core:wood"}, {["x"] = 1, ["y"] = 1, ["z"] = 9, ["name"] = "mcl_core:wood"}, {["x"] = 1, ["y"] = 1, ["z"] = 10, ["name"] = "mcl_core:wood"}, {["x"] = 1, ["y"] = 1, ["z"] = 11, ["name"] = "mcl_core:wood"}, {["x"] = 1, ["y"] = 1, ["z"] = 12, ["name"] = "mcl_core:wood"}, {["x"] = 1, ["y"] = 1, ["z"] = 13, ["name"] = "mcl_core:wood"}, {["x"] = 1, ["y"] = 1, ["z"] = 14, ["name"] = "mcl_core:wood"}, {["x"] = 1, ["y"] = 1, ["z"] = 15, ["name"] = "mcl_core:stone"}, {["x"] = 1, ["y"] = 1, ["z"] = 16, ["name"] = "mcl_core:stone"}, {["x"] = 1, ["y"] = 1, ["z"] = 17, ["name"] = "mcl_core:stone"}, {["x"] = 1, ["y"] = 1, ["z"] = 18, ["name"] = "mcl_core:stone"}, {["x"] = 1, ["y"] = 1, ["z"] = 19, ["name"] = "mcl_core:stone"}, {["x"] = 1, ["y"] = 1, ["z"] = 20, ["name"] = "mcl_core:stone"}, {["x"] = 1, ["y"] = 1, ["z"] = 21, ["name"] = "mcl_core:stone"}, {["x"] = 1, ["y"] = 2, ["z"] = 0, ["name"] = "mcl_core:stone"}, {["x"] = 1, ["y"] = 2, ["z"] = 1, ["name"] = "mcl_core:stone"}, {["x"] = 1, ["y"] = 2, ["z"] = 2, ["name"] = "mcl_core:stone"}, {["x"] = 1, ["y"] = 2, ["z"] = 3, ["name"] = "mcl_core:stone"}, {["x"] = 1, ["y"] = 2, ["z"] = 4, ["name"] = "mcl_core:stone"}, {["x"] = 1, ["y"] = 2, ["z"] = 5, ["name"] = "mcl_core:stone"}, {["x"] = 1, ["y"] = 2, ["z"] = 6, ["name"] = "mcl_core:stone"}, {["x"] = 1, ["y"] = 2, ["z"] = 7, ["name"] = "mcl_core:stone"}, {["x"] = 1, ["y"] = 2, ["z"] = 15, ["name"] = "mcl_core:stone"}, {["x"] = 1, ["y"] = 2, ["z"] = 16, ["name"] = "mcl_core:stone"}, {["x"] = 1, ["y"] = 2, ["z"] = 17, ["name"] = "mcl_core:stone"}, {["x"] = 1, ["y"] = 2, ["z"] = 18, ["name"] = "mcl_core:stone"}, {["x"] = 1, ["y"] = 2, ["z"] = 19, ["name"] = "mcl_core:stone"}, {["x"] = 1, ["y"] = 2, ["z"] = 20, ["name"] = "mcl_core:stone"}, {["x"] = 1, ["y"] = 2, ["z"] = 21, ["name"] = "mcl_core:stone"}, {["x"] = 1, ["y"] = 3, ["z"] = 0, ["name"] = "mcl_core:stone"}, {["x"] = 1, ["y"] = 3, ["z"] = 1, ["name"] = "mcl_core:stone"}, {["x"] = 1, ["y"] = 3, ["z"] = 2, ["name"] = "mcl_core:stone"}, {["x"] = 1, ["y"] = 3, ["z"] = 3, ["name"] = "mcl_core:stone"}, {["x"] = 1, ["y"] = 3, ["z"] = 4, ["name"] = "mcl_core:stone"}, {["x"] = 1, ["y"] = 3, ["z"] = 5, ["name"] = "mcl_core:stone"}, {["x"] = 1, ["y"] = 3, ["z"] = 6, ["name"] = "mcl_core:stone"}, {["x"] = 1, ["y"] = 3, ["z"] = 7, ["name"] = "mcl_core:stone"}, {["x"] = 1, ["y"] = 3, ["z"] = 15, ["name"] = "mcl_core:stone"}, {["x"] = 1, ["y"] = 3, ["z"] = 16, ["name"] = "mcl_core:stone"}, {["x"] = 1, ["y"] = 3, ["z"] = 17, ["name"] = "mcl_core:stone"}, {["x"] = 1, ["y"] = 3, ["z"] = 18, ["name"] = "mcl_core:stone"}, {["x"] = 1, ["y"] = 3, ["z"] = 19, ["name"] = "mcl_core:stone"}, {["x"] = 1, ["y"] = 3, ["z"] = 20, ["name"] = "mcl_core:stone"}, {["x"] = 1, ["y"] = 3, ["z"] = 21, ["name"] = "mcl_core:stone"}, {["x"] = 1, ["y"] = 4, ["z"] = 0, ["name"] = "mcl_core:stone"}, {["x"] = 1, ["y"] = 4, ["z"] = 1, ["name"] = "mcl_core:stone"}, {["x"] = 1, ["y"] = 4, ["z"] = 2, ["name"] = "mcl_core:stone"}, {["x"] = 1, ["y"] = 4, ["z"] = 3, ["name"] = "mcl_core:stone"}, {["x"] = 1, ["y"] = 4, ["z"] = 4, ["name"] = "mcl_core:stone"}, {["x"] = 1, ["y"] = 4, ["z"] = 5, ["name"] = "mcl_core:stone"}, {["x"] = 1, ["y"] = 4, ["z"] = 6, ["name"] = "mcl_core:stone"}, {["x"] = 1, ["y"] = 4, ["z"] = 7, ["name"] = "mcl_core:stone"}, {["x"] = 1, ["y"] = 4, ["z"] = 8, ["name"] = "mcl_core:stone"}, {["x"] = 1, ["y"] = 4, ["z"] = 9, ["name"] = "mcl_core:stone"}, {["x"] = 1, ["y"] = 4, ["z"] = 10, ["name"] = "mcl_core:stone"}, {["x"] = 1, ["y"] = 4, ["z"] = 11, ["name"] = "mcl_core:stone"}, {["x"] = 1, ["y"] = 4, ["z"] = 12, ["name"] = "mcl_core:stone"}, {["x"] = 1, ["y"] = 4, ["z"] = 15, ["name"] = "mcl_core:gravel"}, {["x"] = 1, ["y"] = 4, ["z"] = 16, ["name"] = "mcl_core:stone"}, {["x"] = 1, ["y"] = 4, ["z"] = 17, ["name"] = "mcl_core:stone"}, {["x"] = 1, ["y"] = 4, ["z"] = 18, ["name"] = "mcl_core:stone"}, {["x"] = 1, ["y"] = 4, ["z"] = 19, ["name"] = "mcl_core:stone"}, {["x"] = 1, ["y"] = 4, ["z"] = 20, ["name"] = "mcl_core:stone"}, {["x"] = 1, ["y"] = 4, ["z"] = 21, ["name"] = "mcl_core:stone"}, {["x"] = 1, ["y"] = 5, ["z"] = 0, ["name"] = "mcl_core:stone"}, {["x"] = 1, ["y"] = 5, ["z"] = 1, ["name"] = "mcl_core:stone"}, {["x"] = 1, ["y"] = 5, ["z"] = 2, ["name"] = "mcl_core:stone"}, {["x"] = 1, ["y"] = 5, ["z"] = 3, ["name"] = "mcl_core:stone"}, {["x"] = 1, ["y"] = 5, ["z"] = 4, ["name"] = "mcl_core:stone"}, {["x"] = 1, ["y"] = 5, ["z"] = 5, ["name"] = "mcl_core:stone"}, {["x"] = 1, ["y"] = 5, ["z"] = 6, ["name"] = "mcl_core:stone"}, {["x"] = 1, ["y"] = 5, ["z"] = 7, ["name"] = "mcl_core:stone"}, {["x"] = 1, ["y"] = 5, ["z"] = 8, ["name"] = "mcl_core:stone"}, {["x"] = 1, ["y"] = 5, ["z"] = 9, ["name"] = "mcl_core:stone"}, {["x"] = 1, ["y"] = 5, ["z"] = 10, ["name"] = "mcl_core:stone"}, {["x"] = 1, ["y"] = 5, ["z"] = 11, ["name"] = "mcl_core:stone"}, {["x"] = 1, ["y"] = 5, ["z"] = 12, ["name"] = "mcl_core:stone"}, {["x"] = 1, ["y"] = 5, ["z"] = 15, ["name"] = "mcl_core:gravel"}, {["x"] = 1, ["y"] = 5, ["z"] = 16, ["name"] = "mcl_core:stone"}, {["x"] = 1, ["y"] = 5, ["z"] = 17, ["name"] = "mcl_core:stone"}, {["x"] = 1, ["y"] = 5, ["z"] = 18, ["name"] = "mcl_core:stone"}, {["x"] = 1, ["y"] = 5, ["z"] = 19, ["name"] = "mcl_core:stone"}, {["x"] = 1, ["y"] = 5, ["z"] = 20, ["name"] = "mcl_core:stone"}, {["x"] = 1, ["y"] = 5, ["z"] = 21, ["name"] = "mcl_core:stone"}, {["x"] = 1, ["y"] = 6, ["z"] = 0, ["name"] = "mcl_core:stone"}, {["x"] = 1, ["y"] = 6, ["z"] = 1, ["name"] = "mcl_core:stone"}, {["x"] = 1, ["y"] = 6, ["z"] = 2, ["name"] = "mcl_core:stone"}, {["x"] = 1, ["y"] = 6, ["z"] = 3, ["name"] = "mcl_core:stone"}, {["x"] = 1, ["y"] = 6, ["z"] = 4, ["name"] = "mcl_core:stone"}, {["x"] = 1, ["y"] = 6, ["z"] = 5, ["name"] = "mcl_core:stone"}, {["x"] = 1, ["y"] = 6, ["z"] = 6, ["name"] = "mcl_core:stone"}, {["x"] = 1, ["y"] = 6, ["z"] = 7, ["name"] = "mcl_core:stone"}, {["x"] = 1, ["y"] = 6, ["z"] = 8, ["name"] = "mcl_core:stone"}, {["x"] = 1, ["y"] = 6, ["z"] = 9, ["name"] = "mcl_core:stone"}, {["x"] = 1, ["y"] = 6, ["z"] = 10, ["name"] = "mcl_core:stone"}, {["x"] = 1, ["y"] = 6, ["z"] = 11, ["name"] = "mcl_core:stone"}, {["x"] = 1, ["y"] = 6, ["z"] = 12, ["name"] = "mcl_core:stone"}, {["x"] = 1, ["y"] = 6, ["z"] = 13, ["name"] = "mcl_core:cobble"}, {["x"] = 1, ["y"] = 6, ["z"] = 14, ["name"] = "mcl_core:cobble"}, {["x"] = 1, ["y"] = 6, ["z"] = 15, ["name"] = "mcl_core:cobble"}, {["x"] = 1, ["y"] = 6, ["z"] = 16, ["name"] = "mcl_core:stone"}, {["x"] = 1, ["y"] = 6, ["z"] = 17, ["name"] = "mcl_core:stone"}, {["x"] = 1, ["y"] = 6, ["z"] = 18, ["name"] = "mcl_core:stone"}, {["x"] = 1, ["y"] = 6, ["z"] = 19, ["name"] = "mcl_core:stone"}, {["x"] = 1, ["y"] = 6, ["z"] = 20, ["name"] = "mcl_core:stone"}, {["x"] = 1, ["y"] = 6, ["z"] = 21, ["name"] = "mcl_core:stone"}, {["x"] = 1, ["y"] = 7, ["z"] = 0, ["name"] = "mcl_core:stone"}, {["x"] = 1, ["y"] = 7, ["z"] = 1, ["name"] = "mcl_core:stone"}, {["x"] = 1, ["y"] = 7, ["z"] = 2, ["name"] = "mcl_core:stone"}, {["x"] = 1, ["y"] = 7, ["z"] = 3, ["name"] = "mcl_core:stone"}, {["x"] = 1, ["y"] = 7, ["z"] = 4, ["name"] = "mcl_core:stone"}, {["x"] = 1, ["y"] = 7, ["z"] = 5, ["name"] = "mcl_core:stone"}, {["x"] = 1, ["y"] = 7, ["z"] = 6, ["name"] = "mcl_core:stone"}, {["x"] = 1, ["y"] = 7, ["z"] = 7, ["name"] = "mcl_core:stone"}, {["x"] = 1, ["y"] = 7, ["z"] = 8, ["name"] = "mcl_core:dirt"}, {["x"] = 1, ["y"] = 7, ["z"] = 9, ["name"] = "mcl_core:dirt"}, {["x"] = 1, ["y"] = 7, ["z"] = 10, ["name"] = "mcl_core:dirt"}, {["x"] = 1, ["y"] = 7, ["z"] = 11, ["name"] = "mcl_core:dirt"}, {["x"] = 1, ["y"] = 7, ["z"] = 12, ["name"] = "mcl_core:dirt"}, {["x"] = 1, ["y"] = 7, ["z"] = 13, ["name"] = "mcl_core:sand"}, {["x"] = 1, ["y"] = 7, ["z"] = 14, ["name"] = "mcl_core:sand"}, {["x"] = 1, ["y"] = 7, ["z"] = 15, ["name"] = "mcl_core:stone"}, {["x"] = 1, ["y"] = 7, ["z"] = 16, ["name"] = "mcl_core:stone"}, {["x"] = 1, ["y"] = 7, ["z"] = 17, ["name"] = "mcl_core:stone"}, {["x"] = 1, ["y"] = 7, ["z"] = 18, ["name"] = "mcl_core:stone"}, {["x"] = 1, ["y"] = 7, ["z"] = 19, ["name"] = "mcl_core:stone"}, {["x"] = 1, ["y"] = 7, ["z"] = 20, ["name"] = "mcl_core:stone"}, {["x"] = 1, ["y"] = 7, ["z"] = 21, ["name"] = "mcl_core:stone"}, {["x"] = 1, ["y"] = 8, ["z"] = 0, ["name"] = "mcl_core:stone"}, {["x"] = 1, ["y"] = 8, ["z"] = 1, ["name"] = "mcl_core:stone"}, {["x"] = 1, ["y"] = 8, ["z"] = 2, ["name"] = "mcl_core:stone"}, {["x"] = 1, ["y"] = 8, ["z"] = 3, ["name"] = "mcl_core:stone"}, {["x"] = 1, ["y"] = 8, ["z"] = 4, ["name"] = "mcl_core:stone"}, {["x"] = 1, ["y"] = 8, ["z"] = 5, ["name"] = "mcl_core:stone"}, {["x"] = 1, ["y"] = 8, ["z"] = 6, ["name"] = "mcl_core:stone"}, {["x"] = 1, ["y"] = 8, ["z"] = 7, ["name"] = "mcl_core:stone"}, {["x"] = 1, ["y"] = 8, ["param1"] = 153, ["z"] = 8, ["name"] = "mcl_flowers:rose_bush"}, {["x"] = 1, ["y"] = 8, ["param1"] = 136, ["z"] = 9, ["name"] = "mcl_flowers:sunflower"}, {["x"] = 1, ["y"] = 8, ["param1"] = 153, ["z"] = 10, ["name"] = "mcl_flowers:tulip_white"}, {["x"] = 1, ["y"] = 8, ["param1"] = 170, ["z"] = 11, ["name"] = "mcl_flowers:tulip_red"}, {["x"] = 1, ["y"] = 8, ["param1"] = 187, ["z"] = 12, ["name"] = "mcl_flowers:sunflower"}, {["x"] = 1, ["y"] = 8, ["param1"] = 153, ["z"] = 14, ["name"] = "mcl_core:cactus"}, {["x"] = 1, ["y"] = 8, ["z"] = 15, ["name"] = "mcl_core:stone"}, {["x"] = 1, ["y"] = 8, ["z"] = 16, ["name"] = "mcl_core:stone"}, {["x"] = 1, ["y"] = 8, ["z"] = 17, ["name"] = "mcl_core:stone"}, {["x"] = 1, ["y"] = 8, ["z"] = 18, ["name"] = "mcl_core:stone"}, {["x"] = 1, ["y"] = 8, ["z"] = 19, ["name"] = "mcl_core:stone"}, {["x"] = 1, ["y"] = 8, ["z"] = 20, ["name"] = "mcl_core:stone"}, {["x"] = 1, ["y"] = 8, ["z"] = 21, ["name"] = "mcl_core:stone"}, {["x"] = 1, ["y"] = 9, ["z"] = 0, ["name"] = "mcl_core:stone"}, {["x"] = 1, ["y"] = 9, ["z"] = 1, ["name"] = "mcl_core:stone"}, {["x"] = 1, ["y"] = 9, ["z"] = 2, ["name"] = "mcl_core:stone"}, {["x"] = 1, ["y"] = 9, ["z"] = 3, ["name"] = "mcl_core:stone"}, {["x"] = 1, ["y"] = 9, ["z"] = 4, ["name"] = "mcl_core:stone"}, {["x"] = 1, ["y"] = 9, ["z"] = 5, ["name"] = "mcl_core:stone"}, {["x"] = 1, ["y"] = 9, ["z"] = 6, ["name"] = "mcl_core:stone"}, {["x"] = 1, ["y"] = 9, ["z"] = 7, ["name"] = "mcl_core:stone"}, {["x"] = 1, ["y"] = 9, ["param1"] = 170, ["z"] = 8, ["name"] = "mcl_flowers:rose_bush_top"}, {["x"] = 1, ["y"] = 9, ["param1"] = 153, ["z"] = 9, ["name"] = "mcl_flowers:sunflower_top"}, {["x"] = 1, ["y"] = 9, ["param1"] = 204, ["z"] = 12, ["name"] = "mcl_flowers:sunflower_top"}, {["x"] = 1, ["y"] = 9, ["param1"] = 170, ["z"] = 14, ["name"] = "mcl_core:cactus"}, {["x"] = 1, ["y"] = 9, ["z"] = 15, ["name"] = "mcl_core:stone"}, {["x"] = 1, ["y"] = 9, ["z"] = 16, ["name"] = "mcl_core:stone"}, {["x"] = 1, ["y"] = 9, ["z"] = 17, ["name"] = "mcl_core:stone"}, {["x"] = 1, ["y"] = 9, ["z"] = 18, ["name"] = "mcl_core:stone"}, {["x"] = 1, ["y"] = 9, ["z"] = 19, ["name"] = "mcl_core:stone"}, {["x"] = 1, ["y"] = 9, ["z"] = 20, ["name"] = "mcl_core:stone"}, {["x"] = 1, ["y"] = 9, ["z"] = 21, ["name"] = "mcl_core:stone"}, {["x"] = 1, ["y"] = 10, ["z"] = 0, ["name"] = "mcl_core:stone"}, {["x"] = 1, ["y"] = 10, ["z"] = 1, ["name"] = "mcl_core:stone"}, {["x"] = 1, ["y"] = 10, ["z"] = 2, ["name"] = "mcl_core:stone"}, {["x"] = 1, ["y"] = 10, ["z"] = 3, ["name"] = "mcl_core:stone"}, {["x"] = 1, ["y"] = 10, ["z"] = 4, ["name"] = "mcl_core:stone"}, {["x"] = 1, ["y"] = 10, ["z"] = 5, ["name"] = "mcl_core:stone"}, {["x"] = 1, ["y"] = 10, ["z"] = 6, ["name"] = "mcl_core:stone"}, {["x"] = 1, ["y"] = 10, ["z"] = 7, ["name"] = "mcl_core:stone"}, {["x"] = 1, ["y"] = 10, ["param1"] = 187, ["z"] = 14, ["name"] = "mcl_core:cactus"}, {["x"] = 1, ["y"] = 10, ["z"] = 15, ["name"] = "mcl_core:stone"}, {["x"] = 1, ["y"] = 10, ["z"] = 16, ["name"] = "mcl_core:stone"}, {["x"] = 1, ["y"] = 10, ["z"] = 17, ["name"] = "mcl_core:stone"}, {["x"] = 1, ["y"] = 10, ["z"] = 18, ["name"] = "mcl_core:stone"}, {["x"] = 1, ["y"] = 10, ["z"] = 19, ["name"] = "mcl_core:stone"}, {["x"] = 1, ["y"] = 10, ["z"] = 20, ["name"] = "mcl_core:stone"}, {["x"] = 1, ["y"] = 10, ["z"] = 21, ["name"] = "mcl_core:stone"}, {["x"] = 1, ["y"] = 11, ["z"] = 0, ["name"] = "mcl_core:stone"}, {["x"] = 1, ["y"] = 11, ["z"] = 1, ["name"] = "mcl_core:stone"}, {["x"] = 1, ["y"] = 11, ["z"] = 2, ["name"] = "mcl_core:stone"}, {["x"] = 1, ["y"] = 11, ["z"] = 3, ["name"] = "mcl_core:stone"}, {["x"] = 1, ["y"] = 11, ["z"] = 4, ["name"] = "mcl_core:stone"}, {["x"] = 1, ["y"] = 11, ["z"] = 5, ["name"] = "mcl_core:stone"}, {["x"] = 1, ["y"] = 11, ["z"] = 6, ["name"] = "mcl_core:stone"}, {["x"] = 1, ["y"] = 11, ["z"] = 7, ["name"] = "mcl_core:stone"}, {["x"] = 1, ["y"] = 11, ["z"] = 8, ["name"] = "mcl_core:stone"}, {["x"] = 1, ["y"] = 11, ["z"] = 9, ["name"] = "mcl_core:stone"}, {["x"] = 1, ["y"] = 11, ["z"] = 10, ["name"] = "mcl_core:stone"}, {["x"] = 1, ["y"] = 11, ["z"] = 11, ["name"] = "mcl_core:stone"}, {["x"] = 1, ["y"] = 11, ["z"] = 12, ["name"] = "mcl_core:stone"}, {["x"] = 1, ["y"] = 11, ["z"] = 13, ["name"] = "mcl_core:stone"}, {["x"] = 1, ["y"] = 11, ["z"] = 14, ["name"] = "mcl_core:stone"}, {["x"] = 1, ["y"] = 11, ["z"] = 15, ["name"] = "mcl_core:stone"}, {["x"] = 1, ["y"] = 11, ["z"] = 16, ["name"] = "mcl_core:stone"}, {["x"] = 1, ["y"] = 11, ["z"] = 17, ["name"] = "mcl_core:stone"}, {["x"] = 1, ["y"] = 11, ["z"] = 18, ["name"] = "mcl_core:stone"}, {["x"] = 1, ["y"] = 11, ["z"] = 19, ["name"] = "mcl_core:stone"}, {["x"] = 1, ["y"] = 11, ["z"] = 20, ["name"] = "mcl_core:stone"}, {["x"] = 1, ["y"] = 11, ["z"] = 21, ["name"] = "mcl_core:stone"}, {["x"] = 1, ["y"] = 12, ["z"] = 0, ["name"] = "mcl_core:stone"}, {["x"] = 1, ["y"] = 12, ["z"] = 1, ["name"] = "mcl_core:stone"}, {["x"] = 1, ["y"] = 12, ["z"] = 2, ["name"] = "mcl_core:stone"}, {["x"] = 1, ["y"] = 12, ["z"] = 3, ["name"] = "mcl_core:stone"}, {["x"] = 1, ["y"] = 12, ["z"] = 4, ["name"] = "mcl_core:stone"}, {["x"] = 1, ["y"] = 12, ["z"] = 5, ["name"] = "mcl_core:stone"}, {["x"] = 1, ["y"] = 12, ["z"] = 6, ["name"] = "mcl_core:stone"}, {["x"] = 1, ["y"] = 12, ["z"] = 7, ["name"] = "mcl_core:stone"}, {["x"] = 1, ["y"] = 12, ["z"] = 8, ["name"] = "mcl_core:stone"}, {["x"] = 1, ["y"] = 12, ["z"] = 9, ["name"] = "mcl_core:stone"}, {["x"] = 1, ["y"] = 12, ["z"] = 10, ["name"] = "mcl_core:stone"}, {["x"] = 1, ["y"] = 12, ["z"] = 11, ["name"] = "mcl_core:cobble"}, {["x"] = 1, ["y"] = 12, ["z"] = 12, ["name"] = "mcl_core:stone"}, {["x"] = 1, ["y"] = 12, ["z"] = 13, ["name"] = "mcl_core:stone"}, {["x"] = 1, ["y"] = 12, ["z"] = 14, ["name"] = "mcl_core:stone"}, {["x"] = 1, ["y"] = 12, ["z"] = 15, ["name"] = "mcl_core:stone"}, {["x"] = 1, ["y"] = 12, ["z"] = 16, ["name"] = "mcl_core:stone"}, {["x"] = 1, ["y"] = 12, ["z"] = 17, ["name"] = "mcl_core:stone"}, {["x"] = 1, ["y"] = 12, ["z"] = 18, ["name"] = "mcl_core:stone"}, {["x"] = 1, ["y"] = 12, ["z"] = 19, ["name"] = "mcl_core:stone"}, {["x"] = 1, ["y"] = 12, ["z"] = 20, ["name"] = "mcl_core:stone"}, {["x"] = 1, ["y"] = 12, ["z"] = 21, ["name"] = "mcl_core:stone"}, {["x"] = 1, ["y"] = 13, ["z"] = 0, ["name"] = "mcl_core:stone"}, {["x"] = 1, ["y"] = 13, ["z"] = 1, ["name"] = "mcl_core:stone"}, {["x"] = 1, ["y"] = 13, ["z"] = 2, ["name"] = "mcl_core:stone"}, {["x"] = 1, ["y"] = 13, ["z"] = 3, ["name"] = "mcl_core:stone"}, {["x"] = 1, ["y"] = 13, ["z"] = 4, ["name"] = "mcl_core:stone"}, {["x"] = 1, ["y"] = 13, ["z"] = 5, ["name"] = "mcl_core:stone"}, {["x"] = 1, ["y"] = 13, ["z"] = 6, ["name"] = "mcl_core:stone"}, {["x"] = 1, ["y"] = 13, ["z"] = 7, ["name"] = "mcl_core:stone"}, {["x"] = 1, ["y"] = 13, ["z"] = 8, ["name"] = "mcl_core:stone"}, {["x"] = 1, ["y"] = 13, ["z"] = 9, ["name"] = "mcl_core:stone"}, {["x"] = 1, ["y"] = 13, ["z"] = 10, ["name"] = "mcl_core:stone"}, {["x"] = 1, ["y"] = 13, ["z"] = 11, ["name"] = "mcl_core:cobble"}, {["x"] = 1, ["y"] = 13, ["z"] = 12, ["name"] = "mcl_core:stone"}, {["x"] = 1, ["y"] = 13, ["z"] = 13, ["name"] = "mcl_core:stone"}, {["x"] = 1, ["y"] = 13, ["z"] = 14, ["name"] = "mcl_core:stone"}, {["x"] = 1, ["y"] = 13, ["z"] = 15, ["name"] = "mcl_core:stone"}, {["x"] = 1, ["y"] = 13, ["z"] = 16, ["name"] = "mcl_core:stone"}, {["x"] = 1, ["y"] = 13, ["z"] = 17, ["name"] = "mcl_core:stone"}, {["x"] = 1, ["y"] = 13, ["z"] = 18, ["name"] = "mcl_core:stone"}, {["x"] = 1, ["y"] = 13, ["z"] = 19, ["name"] = "mcl_core:stone"}, {["x"] = 1, ["y"] = 13, ["z"] = 20, ["name"] = "mcl_core:stone"}, {["x"] = 1, ["y"] = 13, ["z"] = 21, ["name"] = "mcl_core:stone"}, {["x"] = 1, ["y"] = 14, ["z"] = 0, ["name"] = "mcl_core:stone"}, {["x"] = 1, ["y"] = 14, ["z"] = 1, ["name"] = "mcl_core:stone"}, {["x"] = 1, ["y"] = 14, ["z"] = 2, ["name"] = "mcl_core:stone"}, {["x"] = 1, ["y"] = 14, ["z"] = 3, ["name"] = "mcl_core:stone"}, {["x"] = 1, ["y"] = 14, ["z"] = 4, ["name"] = "mcl_core:stone"}, {["x"] = 1, ["y"] = 14, ["z"] = 5, ["name"] = "mcl_core:stone"}, {["x"] = 1, ["y"] = 14, ["z"] = 6, ["name"] = "mcl_core:stone"}, {["x"] = 1, ["y"] = 14, ["z"] = 7, ["name"] = "mcl_core:stone"}, {["x"] = 1, ["y"] = 14, ["z"] = 8, ["name"] = "mcl_core:stone"}, {["x"] = 1, ["y"] = 14, ["z"] = 9, ["name"] = "mcl_core:stone"}, {["x"] = 1, ["y"] = 14, ["z"] = 10, ["name"] = "mcl_core:stone"}, {["x"] = 1, ["y"] = 14, ["z"] = 11, ["name"] = "mcl_core:cobble"}, {["x"] = 1, ["y"] = 14, ["z"] = 12, ["name"] = "mcl_core:stone"}, {["x"] = 1, ["y"] = 14, ["z"] = 13, ["name"] = "mcl_core:stone"}, {["x"] = 1, ["y"] = 14, ["z"] = 14, ["name"] = "mcl_core:stone"}, {["x"] = 1, ["y"] = 14, ["z"] = 15, ["name"] = "mcl_core:stone"}, {["x"] = 1, ["y"] = 14, ["z"] = 16, ["name"] = "mcl_core:stone"}, {["x"] = 1, ["y"] = 14, ["z"] = 17, ["name"] = "mcl_core:stone"}, {["x"] = 1, ["y"] = 14, ["z"] = 18, ["name"] = "mcl_core:stone"}, {["x"] = 1, ["y"] = 14, ["z"] = 19, ["name"] = "mcl_core:stone"}, {["x"] = 1, ["y"] = 14, ["z"] = 20, ["name"] = "mcl_core:stone"}, {["x"] = 1, ["y"] = 14, ["z"] = 21, ["name"] = "mcl_core:stone"}, {["x"] = 1, ["y"] = 15, ["z"] = 0, ["name"] = "mcl_core:stone"}, {["x"] = 1, ["y"] = 15, ["z"] = 1, ["name"] = "mcl_core:stone"}, {["x"] = 1, ["y"] = 15, ["z"] = 2, ["name"] = "mcl_core:stone"}, {["x"] = 1, ["y"] = 15, ["z"] = 3, ["name"] = "mcl_core:stone"}, {["x"] = 1, ["y"] = 15, ["z"] = 4, ["name"] = "mcl_core:stone"}, {["x"] = 1, ["y"] = 15, ["z"] = 5, ["name"] = "mcl_core:stone"}, {["x"] = 1, ["y"] = 15, ["z"] = 6, ["name"] = "mcl_core:stone"}, {["x"] = 1, ["y"] = 15, ["z"] = 7, ["name"] = "mcl_core:stone"}, {["x"] = 1, ["y"] = 15, ["z"] = 8, ["name"] = "mcl_core:stone"}, {["x"] = 1, ["y"] = 15, ["z"] = 9, ["name"] = "mcl_core:stone"}, {["x"] = 1, ["y"] = 15, ["z"] = 10, ["name"] = "mcl_core:stone"}, {["x"] = 1, ["y"] = 15, ["z"] = 11, ["name"] = "mcl_core:cobble"}, {["x"] = 1, ["y"] = 15, ["z"] = 12, ["name"] = "mcl_core:stone"}, {["x"] = 1, ["y"] = 15, ["z"] = 13, ["name"] = "mcl_core:stone"}, {["x"] = 1, ["y"] = 15, ["z"] = 14, ["name"] = "mcl_core:stone"}, {["x"] = 1, ["y"] = 15, ["z"] = 15, ["name"] = "mcl_core:stone"}, {["x"] = 1, ["y"] = 15, ["z"] = 16, ["name"] = "mcl_core:stone"}, {["x"] = 1, ["y"] = 15, ["z"] = 17, ["name"] = "mcl_core:stone"}, {["x"] = 1, ["y"] = 15, ["z"] = 18, ["name"] = "mcl_core:stone"}, {["x"] = 1, ["y"] = 15, ["z"] = 19, ["name"] = "mcl_core:stone"}, {["x"] = 1, ["y"] = 15, ["z"] = 20, ["name"] = "mcl_core:stone"}, {["x"] = 1, ["y"] = 15, ["z"] = 21, ["name"] = "mcl_core:stone"}, {["x"] = 1, ["y"] = 16, ["z"] = 0, ["name"] = "mcl_core:stone"}, {["x"] = 1, ["y"] = 16, ["z"] = 1, ["name"] = "mcl_core:stone"}, {["x"] = 1, ["y"] = 16, ["z"] = 2, ["name"] = "mcl_core:stone"}, {["x"] = 1, ["y"] = 16, ["z"] = 3, ["name"] = "mcl_core:stone"}, {["x"] = 1, ["y"] = 16, ["z"] = 4, ["name"] = "mcl_core:stone"}, {["x"] = 1, ["y"] = 16, ["z"] = 5, ["name"] = "mcl_core:stone"}, {["x"] = 1, ["y"] = 16, ["z"] = 6, ["name"] = "mcl_core:stone"}, {["x"] = 1, ["y"] = 16, ["z"] = 7, ["name"] = "mcl_core:stone"}, {["x"] = 1, ["y"] = 16, ["z"] = 8, ["name"] = "mcl_core:stone"}, {["x"] = 1, ["y"] = 16, ["z"] = 9, ["name"] = "mcl_core:stone"}, {["x"] = 1, ["y"] = 16, ["z"] = 10, ["name"] = "mcl_core:stone"}, {["x"] = 1, ["y"] = 16, ["z"] = 11, ["name"] = "mcl_core:cobble"}, {["x"] = 1, ["y"] = 16, ["z"] = 12, ["name"] = "mcl_core:stone"}, {["x"] = 1, ["y"] = 16, ["z"] = 13, ["name"] = "mcl_core:stone"}, {["x"] = 1, ["y"] = 16, ["z"] = 14, ["name"] = "mcl_core:stone"}, {["x"] = 1, ["y"] = 16, ["z"] = 15, ["name"] = "mcl_core:stone"}, {["x"] = 1, ["y"] = 16, ["z"] = 16, ["name"] = "mcl_core:stone"}, {["x"] = 1, ["y"] = 16, ["z"] = 17, ["name"] = "mcl_core:stone"}, {["x"] = 1, ["y"] = 16, ["z"] = 18, ["name"] = "mcl_core:stone"}, {["x"] = 1, ["y"] = 16, ["z"] = 19, ["name"] = "mcl_core:stone"}, {["x"] = 1, ["y"] = 16, ["z"] = 20, ["name"] = "mcl_core:stone"}, {["x"] = 1, ["y"] = 16, ["z"] = 21, ["name"] = "mcl_core:stone"}, {["x"] = 1, ["y"] = 17, ["z"] = 0, ["name"] = "mcl_core:stone"}, {["x"] = 1, ["y"] = 17, ["z"] = 1, ["name"] = "mcl_core:stone"}, {["x"] = 1, ["y"] = 17, ["z"] = 2, ["name"] = "mcl_core:stone"}, {["x"] = 1, ["y"] = 17, ["z"] = 3, ["name"] = "mcl_core:stone"}, {["x"] = 1, ["y"] = 17, ["z"] = 4, ["name"] = "mcl_core:stone"}, {["x"] = 1, ["y"] = 17, ["z"] = 5, ["name"] = "mcl_core:stone"}, {["x"] = 1, ["y"] = 17, ["z"] = 6, ["name"] = "mcl_core:stone"}, {["x"] = 1, ["y"] = 17, ["z"] = 7, ["name"] = "mcl_core:stone"}, {["x"] = 1, ["y"] = 17, ["z"] = 8, ["name"] = "mcl_core:stone"}, {["x"] = 1, ["y"] = 17, ["z"] = 9, ["name"] = "mcl_core:stone"}, {["x"] = 1, ["y"] = 17, ["z"] = 10, ["name"] = "mcl_core:stone"}, {["x"] = 1, ["y"] = 17, ["z"] = 11, ["name"] = "mcl_core:stone"}, {["x"] = 1, ["y"] = 17, ["z"] = 12, ["name"] = "mcl_core:stone"}, {["x"] = 1, ["y"] = 17, ["z"] = 13, ["name"] = "mcl_core:stone"}, {["x"] = 1, ["y"] = 17, ["z"] = 14, ["name"] = "mcl_core:stone"}, {["x"] = 1, ["y"] = 17, ["z"] = 15, ["name"] = "mcl_core:stone"}, {["x"] = 1, ["y"] = 17, ["z"] = 16, ["name"] = "mcl_core:stone"}, {["x"] = 1, ["y"] = 17, ["z"] = 17, ["name"] = "mcl_core:stone"}, {["x"] = 1, ["y"] = 17, ["z"] = 18, ["name"] = "mcl_core:stone_with_coal"}, {["x"] = 1, ["y"] = 17, ["z"] = 19, ["name"] = "mcl_core:stone"}, {["x"] = 1, ["y"] = 17, ["z"] = 20, ["name"] = "mcl_core:stone"}, {["x"] = 1, ["y"] = 17, ["z"] = 21, ["name"] = "mcl_core:stone"}, {["x"] = 1, ["y"] = 18, ["z"] = 0, ["name"] = "mcl_core:dirt"}, {["x"] = 1, ["y"] = 18, ["z"] = 1, ["name"] = "mcl_core:dirt"}, {["x"] = 1, ["y"] = 18, ["z"] = 2, ["name"] = "mcl_core:dirt"}, {["x"] = 1, ["y"] = 18, ["z"] = 3, ["name"] = "mcl_core:dirt"}, {["x"] = 1, ["y"] = 18, ["z"] = 4, ["name"] = "mcl_core:dirt"}, {["x"] = 1, ["y"] = 18, ["z"] = 5, ["name"] = "mcl_core:dirt"}, {["x"] = 1, ["y"] = 18, ["z"] = 6, ["name"] = "mcl_core:dirt"}, {["x"] = 1, ["y"] = 18, ["z"] = 7, ["name"] = "mcl_core:dirt"}, {["x"] = 1, ["y"] = 18, ["z"] = 8, ["name"] = "mcl_core:dirt_with_grass"}, {["x"] = 1, ["y"] = 18, ["z"] = 9, ["name"] = "mcl_core:dirt_with_grass"}, {["x"] = 1, ["y"] = 18, ["z"] = 10, ["name"] = "mcl_core:dirt"}, {["x"] = 1, ["y"] = 18, ["z"] = 11, ["name"] = "mcl_core:dirt"}, {["x"] = 1, ["y"] = 18, ["z"] = 12, ["name"] = "mcl_core:dirt"}, {["x"] = 1, ["y"] = 18, ["z"] = 13, ["name"] = "mcl_core:dirt"}, {["x"] = 1, ["y"] = 18, ["z"] = 14, ["name"] = "mcl_core:dirt"}, {["x"] = 1, ["y"] = 18, ["z"] = 15, ["name"] = "mcl_core:dirt"}, {["x"] = 1, ["y"] = 18, ["z"] = 16, ["name"] = "mcl_core:dirt"}, {["x"] = 1, ["y"] = 18, ["z"] = 17, ["name"] = "mcl_core:dirt"}, {["x"] = 1, ["y"] = 18, ["z"] = 18, ["name"] = "mcl_core:dirt"}, {["x"] = 1, ["y"] = 18, ["z"] = 19, ["name"] = "mcl_core:dirt"}, {["x"] = 1, ["y"] = 18, ["z"] = 20, ["name"] = "mcl_core:dirt"}, {["x"] = 1, ["y"] = 18, ["z"] = 21, ["name"] = "mcl_core:dirt"}, {["x"] = 1, ["y"] = 19, ["z"] = 0, ["name"] = "mcl_core:dirt_with_grass"}, {["x"] = 1, ["y"] = 19, ["z"] = 1, ["name"] = "mcl_core:dirt_with_grass"}, {["x"] = 1, ["y"] = 19, ["z"] = 2, ["name"] = "mcl_core:dirt_with_grass"}, {["x"] = 1, ["y"] = 19, ["z"] = 3, ["name"] = "mcl_core:dirt_with_grass"}, {["x"] = 1, ["y"] = 19, ["z"] = 4, ["name"] = "mcl_core:dirt_with_grass"}, {["x"] = 1, ["y"] = 19, ["z"] = 5, ["name"] = "mcl_core:dirt_with_grass"}, {["x"] = 1, ["y"] = 19, ["z"] = 6, ["name"] = "mcl_core:dirt_with_grass"}, {["x"] = 1, ["y"] = 19, ["z"] = 7, ["name"] = "mcl_core:dirt_with_grass"}, {["x"] = 1, ["y"] = 19, ["z"] = 10, ["name"] = "mcl_core:dirt_with_grass"}, {["x"] = 1, ["y"] = 19, ["z"] = 11, ["name"] = "mcl_core:dirt_with_grass"}, {["x"] = 1, ["y"] = 19, ["z"] = 12, ["name"] = "mcl_core:dirt"}, {["x"] = 1, ["y"] = 19, ["z"] = 13, ["name"] = "mcl_core:dirt_with_grass"}, {["x"] = 1, ["y"] = 19, ["z"] = 14, ["name"] = "mcl_core:dirt_with_grass"}, {["x"] = 1, ["y"] = 19, ["z"] = 15, ["name"] = "mcl_core:dirt_with_grass"}, {["x"] = 1, ["y"] = 19, ["z"] = 16, ["name"] = "mcl_core:dirt_with_grass"}, {["x"] = 1, ["y"] = 19, ["z"] = 17, ["name"] = "mcl_core:dirt"}, {["x"] = 1, ["y"] = 19, ["z"] = 18, ["name"] = "mcl_core:dirt_with_grass"}, {["x"] = 1, ["y"] = 19, ["z"] = 19, ["name"] = "mcl_core:dirt_with_grass"}, {["x"] = 1, ["y"] = 19, ["z"] = 20, ["name"] = "mcl_core:dirt_with_grass"}, {["x"] = 1, ["y"] = 19, ["z"] = 21, ["name"] = "mcl_core:dirt_with_grass"}, {["x"] = 1, ["y"] = 20, ["param1"] = 15, ["z"] = 0, ["name"] = "mcl_flowers:tallgrass"}, {["x"] = 1, ["y"] = 20, ["param1"] = 15, ["z"] = 5, ["name"] = "mcl_flowers:tallgrass"}, {["x"] = 1, ["y"] = 20, ["param1"] = 15, ["z"] = 7, ["name"] = "mcl_flowers:tallgrass"}, {["x"] = 1, ["y"] = 20, ["z"] = 12, ["name"] = "mcl_core:dirt_with_grass"}, {["x"] = 1, ["y"] = 20, ["z"] = 17, ["name"] = "mcl_core:dirt_with_grass"}, {["x"] = 2, ["y"] = 0, ["z"] = 0, ["name"] = "mcl_core:stone"}, {["x"] = 2, ["y"] = 0, ["z"] = 1, ["name"] = "mcl_core:stone"}, {["x"] = 2, ["y"] = 0, ["z"] = 2, ["name"] = "mcl_core:stone"}, {["x"] = 2, ["y"] = 0, ["z"] = 3, ["name"] = "mcl_core:stone"}, {["x"] = 2, ["y"] = 0, ["z"] = 4, ["name"] = "mcl_core:stone"}, {["x"] = 2, ["y"] = 0, ["z"] = 5, ["name"] = "mcl_core:stone"}, {["x"] = 2, ["y"] = 0, ["z"] = 6, ["name"] = "mcl_core:stone"}, {["x"] = 2, ["y"] = 0, ["z"] = 7, ["name"] = "mcl_core:stone"}, {["x"] = 2, ["y"] = 0, ["z"] = 8, ["name"] = "mcl_core:stone"}, {["x"] = 2, ["y"] = 0, ["z"] = 9, ["name"] = "mcl_core:stone"}, {["x"] = 2, ["param2"] = 2, ["y"] = 0, ["param1"] = 238, ["z"] = 11, ["name"] = "mcl_torches:torch_wall"}, {["x"] = 2, ["param2"] = 4, ["y"] = 0, ["param1"] = 238, ["z"] = 12, ["name"] = "mcl_torches:torch_wall"}, {["x"] = 2, ["y"] = 0, ["z"] = 13, ["name"] = "mcl_core:stone"}, {["x"] = 2, ["y"] = 0, ["z"] = 14, ["name"] = "mcl_core:stone"}, {["x"] = 2, ["y"] = 0, ["z"] = 15, ["name"] = "mcl_core:stone"}, {["x"] = 2, ["y"] = 0, ["z"] = 16, ["name"] = "mcl_core:stone"}, {["x"] = 2, ["y"] = 0, ["z"] = 17, ["name"] = "mcl_core:stone"}, {["x"] = 2, ["y"] = 0, ["z"] = 18, ["name"] = "mcl_core:stone"}, {["x"] = 2, ["y"] = 0, ["z"] = 19, ["name"] = "mcl_core:stone"}, {["x"] = 2, ["y"] = 0, ["z"] = 20, ["name"] = "mcl_core:stone"}, {["x"] = 2, ["y"] = 0, ["z"] = 21, ["name"] = "mcl_core:stone"}, {["x"] = 2, ["y"] = 1, ["z"] = 0, ["name"] = "mcl_core:stone"}, {["x"] = 2, ["y"] = 1, ["z"] = 1, ["name"] = "mcl_core:stone"}, {["x"] = 2, ["y"] = 1, ["z"] = 2, ["name"] = "mcl_core:stone"}, {["x"] = 2, ["y"] = 1, ["z"] = 3, ["name"] = "mcl_core:stone"}, {["x"] = 2, ["y"] = 1, ["z"] = 4, ["name"] = "mcl_core:stone"}, {["x"] = 2, ["y"] = 1, ["z"] = 5, ["name"] = "mcl_core:stone"}, {["x"] = 2, ["y"] = 1, ["z"] = 6, ["name"] = "mcl_core:stone"}, {["x"] = 2, ["y"] = 1, ["z"] = 7, ["name"] = "mcl_core:stone"}, {["x"] = 2, ["y"] = 1, ["z"] = 8, ["name"] = "mcl_core:stone"}, {["x"] = 2, ["y"] = 1, ["z"] = 9, ["name"] = "mcl_core:stone"}, {["x"] = 2, ["y"] = 1, ["z"] = 10, ["name"] = "mcl_core:wood"}, {["x"] = 2, ["y"] = 1, ["z"] = 11, ["name"] = "mcl_core:wood"}, {["x"] = 2, ["y"] = 1, ["z"] = 12, ["name"] = "mcl_core:wood"}, {["x"] = 2, ["y"] = 1, ["z"] = 13, ["name"] = "mcl_core:stone"}, {["x"] = 2, ["y"] = 1, ["z"] = 14, ["name"] = "mcl_core:stone"}, {["x"] = 2, ["y"] = 1, ["z"] = 15, ["name"] = "mcl_core:stone"}, {["x"] = 2, ["y"] = 1, ["z"] = 16, ["name"] = "mcl_core:stone"}, {["x"] = 2, ["y"] = 1, ["z"] = 17, ["name"] = "mcl_core:stone"}, {["x"] = 2, ["y"] = 1, ["z"] = 18, ["name"] = "mcl_core:stone"}, {["x"] = 2, ["y"] = 1, ["z"] = 19, ["name"] = "mcl_core:stone"}, {["x"] = 2, ["y"] = 1, ["z"] = 20, ["name"] = "mcl_core:stone"}, {["x"] = 2, ["y"] = 1, ["z"] = 21, ["name"] = "mcl_core:stone"}, {["x"] = 2, ["y"] = 2, ["z"] = 0, ["name"] = "mcl_core:stone"}, {["x"] = 2, ["y"] = 2, ["z"] = 1, ["name"] = "mcl_core:stone"}, {["x"] = 2, ["y"] = 2, ["z"] = 2, ["name"] = "mcl_core:stone"}, {["x"] = 2, ["y"] = 2, ["z"] = 3, ["name"] = "mcl_core:stone"}, {["x"] = 2, ["y"] = 2, ["z"] = 4, ["name"] = "mcl_core:stone"}, {["x"] = 2, ["y"] = 2, ["z"] = 5, ["name"] = "mcl_core:stone"}, {["x"] = 2, ["y"] = 2, ["z"] = 6, ["name"] = "mcl_core:stone"}, {["x"] = 2, ["y"] = 2, ["z"] = 7, ["name"] = "mcl_core:stone"}, {["x"] = 2, ["y"] = 2, ["z"] = 8, ["name"] = "mcl_core:stone"}, {["x"] = 2, ["y"] = 2, ["z"] = 9, ["name"] = "mcl_core:stone"}, {["x"] = 2, ["y"] = 2, ["z"] = 13, ["name"] = "mcl_core:stone"}, {["x"] = 2, ["y"] = 2, ["z"] = 14, ["name"] = "mcl_core:stone"}, {["x"] = 2, ["y"] = 2, ["z"] = 15, ["name"] = "mcl_core:stone"}, {["x"] = 2, ["y"] = 2, ["z"] = 16, ["name"] = "mcl_core:stone"}, {["x"] = 2, ["y"] = 2, ["z"] = 17, ["name"] = "mcl_core:stone"}, {["x"] = 2, ["y"] = 2, ["z"] = 18, ["name"] = "mcl_core:stone"}, {["x"] = 2, ["y"] = 2, ["z"] = 19, ["name"] = "mcl_core:stone"}, {["x"] = 2, ["y"] = 2, ["z"] = 20, ["name"] = "mcl_core:stone"}, {["x"] = 2, ["y"] = 2, ["z"] = 21, ["name"] = "mcl_core:stone"}, {["x"] = 2, ["y"] = 3, ["z"] = 0, ["name"] = "mcl_core:stone"}, {["x"] = 2, ["y"] = 3, ["z"] = 1, ["name"] = "mcl_core:stone"}, {["x"] = 2, ["y"] = 3, ["z"] = 2, ["name"] = "mcl_core:stone"}, {["x"] = 2, ["y"] = 3, ["z"] = 3, ["name"] = "mcl_core:stone"}, {["x"] = 2, ["y"] = 3, ["z"] = 4, ["name"] = "mcl_core:stone"}, {["x"] = 2, ["y"] = 3, ["z"] = 5, ["name"] = "mcl_core:stone"}, {["x"] = 2, ["y"] = 3, ["z"] = 6, ["name"] = "mcl_core:stone"}, {["x"] = 2, ["y"] = 3, ["z"] = 7, ["name"] = "mcl_core:stone"}, {["x"] = 2, ["y"] = 3, ["z"] = 8, ["name"] = "mcl_core:stone"}, {["x"] = 2, ["y"] = 3, ["z"] = 9, ["name"] = "mcl_core:stone"}, {["x"] = 2, ["y"] = 3, ["z"] = 13, ["name"] = "mcl_core:stone"}, {["x"] = 2, ["y"] = 3, ["z"] = 14, ["name"] = "mcl_core:stone"}, {["x"] = 2, ["y"] = 3, ["z"] = 15, ["name"] = "mcl_core:stone"}, {["x"] = 2, ["y"] = 3, ["z"] = 16, ["name"] = "mcl_core:stone"}, {["x"] = 2, ["y"] = 3, ["z"] = 17, ["name"] = "mcl_core:stone"}, {["x"] = 2, ["y"] = 3, ["z"] = 18, ["name"] = "mcl_core:stone"}, {["x"] = 2, ["y"] = 3, ["z"] = 19, ["name"] = "mcl_core:stone"}, {["x"] = 2, ["y"] = 3, ["z"] = 20, ["name"] = "mcl_core:stone"}, {["x"] = 2, ["y"] = 3, ["z"] = 21, ["name"] = "mcl_core:stone"}, {["x"] = 2, ["y"] = 4, ["z"] = 0, ["name"] = "mcl_core:stone"}, {["x"] = 2, ["y"] = 4, ["z"] = 1, ["name"] = "mcl_core:stone"}, {["x"] = 2, ["y"] = 4, ["z"] = 2, ["name"] = "mcl_core:stone"}, {["x"] = 2, ["y"] = 4, ["z"] = 3, ["name"] = "mcl_core:stone"}, {["x"] = 2, ["y"] = 4, ["z"] = 4, ["name"] = "mcl_core:stone"}, {["x"] = 2, ["y"] = 4, ["z"] = 5, ["name"] = "mcl_core:stone"}, {["x"] = 2, ["y"] = 4, ["z"] = 6, ["name"] = "mcl_core:stone"}, {["x"] = 2, ["y"] = 4, ["z"] = 7, ["name"] = "mcl_core:stone"}, {["x"] = 2, ["y"] = 4, ["z"] = 8, ["name"] = "mcl_core:stone"}, {["x"] = 2, ["y"] = 4, ["z"] = 9, ["name"] = "mcl_core:stone"}, {["x"] = 2, ["y"] = 4, ["z"] = 10, ["name"] = "mcl_core:stone"}, {["x"] = 2, ["y"] = 4, ["z"] = 11, ["name"] = "mcl_core:stone"}, {["x"] = 2, ["y"] = 4, ["z"] = 12, ["name"] = "mcl_core:stone"}, {["x"] = 2, ["y"] = 4, ["z"] = 13, ["name"] = "mcl_core:gravel"}, {["x"] = 2, ["y"] = 4, ["z"] = 14, ["name"] = "mcl_core:gravel"}, {["x"] = 2, ["y"] = 4, ["z"] = 15, ["name"] = "mcl_core:gravel"}, {["x"] = 2, ["y"] = 4, ["z"] = 16, ["name"] = "mcl_core:stone"}, {["x"] = 2, ["y"] = 4, ["z"] = 17, ["name"] = "mcl_core:stone"}, {["x"] = 2, ["y"] = 4, ["z"] = 18, ["name"] = "mcl_core:stone"}, {["x"] = 2, ["y"] = 4, ["z"] = 19, ["name"] = "mcl_core:stone"}, {["x"] = 2, ["y"] = 4, ["z"] = 20, ["name"] = "mcl_core:stone"}, {["x"] = 2, ["y"] = 4, ["z"] = 21, ["name"] = "mcl_core:stone"}, {["x"] = 2, ["y"] = 5, ["z"] = 0, ["name"] = "mcl_core:stone"}, {["x"] = 2, ["y"] = 5, ["z"] = 1, ["name"] = "mcl_core:stone"}, {["x"] = 2, ["y"] = 5, ["z"] = 2, ["name"] = "mcl_core:stone"}, {["x"] = 2, ["y"] = 5, ["z"] = 3, ["name"] = "mcl_core:stone"}, {["x"] = 2, ["y"] = 5, ["z"] = 4, ["name"] = "mcl_core:stone"}, {["x"] = 2, ["y"] = 5, ["z"] = 5, ["name"] = "mcl_core:stone"}, {["x"] = 2, ["y"] = 5, ["z"] = 6, ["name"] = "mcl_core:stone"}, {["x"] = 2, ["y"] = 5, ["z"] = 7, ["name"] = "mcl_core:stone"}, {["x"] = 2, ["y"] = 5, ["z"] = 8, ["name"] = "mcl_core:stone"}, {["x"] = 2, ["y"] = 5, ["z"] = 9, ["name"] = "mcl_core:stone"}, {["x"] = 2, ["y"] = 5, ["z"] = 10, ["name"] = "mcl_core:stone"}, {["x"] = 2, ["y"] = 5, ["z"] = 11, ["name"] = "mcl_core:stone"}, {["x"] = 2, ["y"] = 5, ["z"] = 12, ["name"] = "mcl_core:stone"}, {["x"] = 2, ["y"] = 5, ["z"] = 13, ["name"] = "mcl_core:gravel"}, {["x"] = 2, ["y"] = 5, ["z"] = 14, ["name"] = "mcl_core:gravel"}, {["x"] = 2, ["y"] = 5, ["z"] = 15, ["name"] = "mcl_core:gravel"}, {["x"] = 2, ["y"] = 5, ["z"] = 16, ["name"] = "mcl_core:stone"}, {["x"] = 2, ["y"] = 5, ["z"] = 17, ["name"] = "mcl_core:stone"}, {["x"] = 2, ["y"] = 5, ["z"] = 18, ["name"] = "mcl_core:stone"}, {["x"] = 2, ["y"] = 5, ["z"] = 19, ["name"] = "mcl_core:stone"}, {["x"] = 2, ["y"] = 5, ["z"] = 20, ["name"] = "mcl_core:stone"}, {["x"] = 2, ["y"] = 5, ["z"] = 21, ["name"] = "mcl_core:stone"}, {["x"] = 2, ["y"] = 6, ["z"] = 0, ["name"] = "mcl_core:stone"}, {["x"] = 2, ["y"] = 6, ["z"] = 1, ["name"] = "mcl_core:stone"}, {["x"] = 2, ["y"] = 6, ["z"] = 2, ["name"] = "mcl_core:stone"}, {["x"] = 2, ["y"] = 6, ["z"] = 3, ["name"] = "mcl_core:stone"}, {["x"] = 2, ["y"] = 6, ["z"] = 4, ["name"] = "mcl_core:stone"}, {["x"] = 2, ["y"] = 6, ["z"] = 5, ["name"] = "mcl_core:stone"}, {["x"] = 2, ["y"] = 6, ["z"] = 6, ["name"] = "mcl_core:stone"}, {["x"] = 2, ["y"] = 6, ["z"] = 7, ["name"] = "mcl_core:stone"}, {["x"] = 2, ["y"] = 6, ["z"] = 8, ["name"] = "mcl_core:stone"}, {["x"] = 2, ["y"] = 6, ["z"] = 9, ["name"] = "mcl_core:stone"}, {["x"] = 2, ["y"] = 6, ["z"] = 10, ["name"] = "mcl_core:stone"}, {["x"] = 2, ["y"] = 6, ["z"] = 11, ["name"] = "mcl_core:stone"}, {["x"] = 2, ["y"] = 6, ["z"] = 12, ["name"] = "mcl_core:stone"}, {["x"] = 2, ["y"] = 6, ["z"] = 13, ["name"] = "mcl_core:gravel"}, {["x"] = 2, ["y"] = 6, ["z"] = 14, ["name"] = "mcl_core:cobble"}, {["x"] = 2, ["y"] = 6, ["z"] = 15, ["name"] = "mcl_core:gravel"}, {["x"] = 2, ["y"] = 6, ["z"] = 16, ["name"] = "mcl_core:stone"}, {["x"] = 2, ["y"] = 6, ["z"] = 17, ["name"] = "mcl_core:stone"}, {["x"] = 2, ["y"] = 6, ["z"] = 18, ["name"] = "mcl_core:stone"}, {["x"] = 2, ["y"] = 6, ["z"] = 19, ["name"] = "mcl_core:stone"}, {["x"] = 2, ["y"] = 6, ["z"] = 20, ["name"] = "mcl_core:stone"}, {["x"] = 2, ["y"] = 6, ["z"] = 21, ["name"] = "mcl_core:stone"}, {["x"] = 2, ["y"] = 7, ["z"] = 0, ["name"] = "mcl_core:stone"}, {["x"] = 2, ["y"] = 7, ["z"] = 1, ["name"] = "mcl_core:stone"}, {["x"] = 2, ["y"] = 7, ["z"] = 2, ["name"] = "mcl_core:stone"}, {["x"] = 2, ["y"] = 7, ["z"] = 3, ["name"] = "mcl_core:stone"}, {["x"] = 2, ["y"] = 7, ["z"] = 4, ["name"] = "mcl_core:stone"}, {["x"] = 2, ["y"] = 7, ["z"] = 5, ["name"] = "mcl_core:stone"}, {["x"] = 2, ["y"] = 7, ["z"] = 6, ["name"] = "mcl_core:stone"}, {["x"] = 2, ["y"] = 7, ["z"] = 7, ["name"] = "mcl_core:stone"}, {["x"] = 2, ["y"] = 7, ["z"] = 8, ["name"] = "mcl_core:dirt"}, {["x"] = 2, ["y"] = 7, ["z"] = 9, ["name"] = "mcl_core:dirt"}, {["x"] = 2, ["y"] = 7, ["z"] = 10, ["name"] = "mcl_core:dirt"}, {["x"] = 2, ["y"] = 7, ["z"] = 11, ["name"] = "mcl_core:dirt"}, {["x"] = 2, ["y"] = 7, ["z"] = 12, ["name"] = "mcl_core:dirt"}, {["x"] = 2, ["y"] = 7, ["z"] = 13, ["name"] = "mcl_core:dirt"}, {["x"] = 2, ["y"] = 7, ["z"] = 14, ["name"] = "mcl_core:sand"}, {["x"] = 2, ["y"] = 7, ["z"] = 15, ["name"] = "mcl_core:stone"}, {["x"] = 2, ["y"] = 7, ["z"] = 16, ["name"] = "mcl_core:stone"}, {["x"] = 2, ["y"] = 7, ["z"] = 17, ["name"] = "mcl_core:stone"}, {["x"] = 2, ["y"] = 7, ["z"] = 18, ["name"] = "mcl_core:stone"}, {["x"] = 2, ["y"] = 7, ["z"] = 19, ["name"] = "mcl_core:stone"}, {["x"] = 2, ["y"] = 7, ["z"] = 20, ["name"] = "mcl_core:stone"}, {["x"] = 2, ["y"] = 7, ["z"] = 21, ["name"] = "mcl_core:stone"}, {["x"] = 2, ["y"] = 8, ["z"] = 0, ["name"] = "mcl_core:stone"}, {["x"] = 2, ["y"] = 8, ["z"] = 1, ["name"] = "mcl_core:stone"}, {["x"] = 2, ["y"] = 8, ["z"] = 2, ["name"] = "mcl_core:stone"}, {["x"] = 2, ["y"] = 8, ["z"] = 3, ["name"] = "mcl_core:stone"}, {["x"] = 2, ["y"] = 8, ["z"] = 4, ["name"] = "mcl_core:stone"}, {["x"] = 2, ["y"] = 8, ["z"] = 5, ["name"] = "mcl_core:stone"}, {["x"] = 2, ["y"] = 8, ["z"] = 6, ["name"] = "mcl_core:stone"}, {["x"] = 2, ["y"] = 8, ["z"] = 7, ["name"] = "mcl_core:stone"}, {["x"] = 2, ["y"] = 8, ["param1"] = 170, ["z"] = 8, ["name"] = "mcl_flowers:rose_bush"}, {["x"] = 2, ["y"] = 8, ["param1"] = 153, ["z"] = 9, ["name"] = "mcl_flowers:rose_bush"}, {["x"] = 2, ["y"] = 8, ["param1"] = 136, ["z"] = 10, ["name"] = "mcl_flowers:sunflower"}, {["x"] = 2, ["y"] = 8, ["param1"] = 153, ["z"] = 11, ["name"] = "mcl_flowers:tulip_orange"}, {["x"] = 2, ["y"] = 8, ["param1"] = 170, ["z"] = 12, ["name"] = "mcl_flowers:tulip_white"}, {["x"] = 2, ["y"] = 8, ["param1"] = 153, ["z"] = 13, ["name"] = "mcl_flowers:tulip_red"}, {["x"] = 2, ["y"] = 8, ["z"] = 15, ["name"] = "mcl_core:stone"}, {["x"] = 2, ["y"] = 8, ["z"] = 16, ["name"] = "mcl_core:stone"}, {["x"] = 2, ["y"] = 8, ["z"] = 17, ["name"] = "mcl_core:stone"}, {["x"] = 2, ["y"] = 8, ["z"] = 18, ["name"] = "mcl_core:stone"}, {["x"] = 2, ["y"] = 8, ["z"] = 19, ["name"] = "mcl_core:stone"}, {["x"] = 2, ["y"] = 8, ["z"] = 20, ["name"] = "mcl_core:stone"}, {["x"] = 2, ["y"] = 8, ["z"] = 21, ["name"] = "mcl_core:stone"}, {["x"] = 2, ["y"] = 9, ["z"] = 0, ["name"] = "mcl_core:stone"}, {["x"] = 2, ["y"] = 9, ["z"] = 1, ["name"] = "mcl_core:stone"}, {["x"] = 2, ["y"] = 9, ["z"] = 2, ["name"] = "mcl_core:stone"}, {["x"] = 2, ["y"] = 9, ["z"] = 3, ["name"] = "mcl_core:stone"}, {["x"] = 2, ["y"] = 9, ["z"] = 4, ["name"] = "mcl_core:stone"}, {["x"] = 2, ["y"] = 9, ["z"] = 5, ["name"] = "mcl_core:stone"}, {["x"] = 2, ["y"] = 9, ["z"] = 6, ["name"] = "mcl_core:stone"}, {["x"] = 2, ["y"] = 9, ["z"] = 7, ["name"] = "mcl_core:stone"}, {["x"] = 2, ["y"] = 9, ["param1"] = 187, ["z"] = 8, ["name"] = "mcl_flowers:rose_bush_top"}, {["x"] = 2, ["y"] = 9, ["param1"] = 170, ["z"] = 9, ["name"] = "mcl_flowers:rose_bush_top"}, {["x"] = 2, ["y"] = 9, ["param1"] = 153, ["z"] = 10, ["name"] = "mcl_flowers:sunflower_top"}, {["x"] = 2, ["y"] = 9, ["z"] = 15, ["name"] = "mcl_core:stone"}, {["x"] = 2, ["y"] = 9, ["z"] = 16, ["name"] = "mcl_core:stone"}, {["x"] = 2, ["y"] = 9, ["z"] = 17, ["name"] = "mcl_core:stone"}, {["x"] = 2, ["y"] = 9, ["z"] = 18, ["name"] = "mcl_core:stone"}, {["x"] = 2, ["y"] = 9, ["z"] = 19, ["name"] = "mcl_core:stone"}, {["x"] = 2, ["y"] = 9, ["z"] = 20, ["name"] = "mcl_core:stone"}, {["x"] = 2, ["y"] = 9, ["z"] = 21, ["name"] = "mcl_core:stone"}, {["x"] = 2, ["y"] = 10, ["z"] = 0, ["name"] = "mcl_core:stone"}, {["x"] = 2, ["y"] = 10, ["z"] = 1, ["name"] = "mcl_core:stone"}, {["x"] = 2, ["y"] = 10, ["z"] = 2, ["name"] = "mcl_core:stone"}, {["x"] = 2, ["y"] = 10, ["z"] = 3, ["name"] = "mcl_core:stone"}, {["x"] = 2, ["y"] = 10, ["z"] = 4, ["name"] = "mcl_core:stone"}, {["x"] = 2, ["y"] = 10, ["z"] = 5, ["name"] = "mcl_core:stone"}, {["x"] = 2, ["y"] = 10, ["z"] = 6, ["name"] = "mcl_core:stone"}, {["x"] = 2, ["y"] = 10, ["z"] = 7, ["name"] = "mcl_core:stone"}, {["x"] = 2, ["y"] = 10, ["z"] = 15, ["name"] = "mcl_core:stone"}, {["x"] = 2, ["y"] = 10, ["z"] = 16, ["name"] = "mcl_core:stone"}, {["x"] = 2, ["y"] = 10, ["z"] = 17, ["name"] = "mcl_core:stone"}, {["x"] = 2, ["y"] = 10, ["z"] = 18, ["name"] = "mcl_core:stone"}, {["x"] = 2, ["y"] = 10, ["z"] = 19, ["name"] = "mcl_core:stone"}, {["x"] = 2, ["y"] = 10, ["z"] = 20, ["name"] = "mcl_core:stone"}, {["x"] = 2, ["y"] = 10, ["z"] = 21, ["name"] = "mcl_core:stone"}, {["x"] = 2, ["y"] = 11, ["z"] = 0, ["name"] = "mcl_core:stone"}, {["x"] = 2, ["y"] = 11, ["z"] = 1, ["name"] = "mcl_core:stone"}, {["x"] = 2, ["y"] = 11, ["z"] = 2, ["name"] = "mcl_core:stone"}, {["x"] = 2, ["y"] = 11, ["z"] = 3, ["name"] = "mcl_core:stone"}, {["x"] = 2, ["y"] = 11, ["z"] = 4, ["name"] = "mcl_core:stone"}, {["x"] = 2, ["y"] = 11, ["z"] = 5, ["name"] = "mcl_core:stone"}, {["x"] = 2, ["y"] = 11, ["z"] = 6, ["name"] = "mcl_core:stone"}, {["x"] = 2, ["y"] = 11, ["z"] = 7, ["name"] = "mcl_core:stone"}, {["x"] = 2, ["y"] = 11, ["z"] = 8, ["name"] = "mcl_core:stone"}, {["x"] = 2, ["y"] = 11, ["z"] = 9, ["name"] = "mcl_core:stone"}, {["x"] = 2, ["y"] = 11, ["z"] = 10, ["name"] = "mcl_core:stone"}, {["x"] = 2, ["y"] = 11, ["z"] = 11, ["name"] = "mcl_core:stone"}, {["x"] = 2, ["y"] = 11, ["z"] = 12, ["name"] = "mcl_core:stone"}, {["x"] = 2, ["y"] = 11, ["z"] = 13, ["name"] = "mcl_core:stone"}, {["x"] = 2, ["y"] = 11, ["z"] = 14, ["name"] = "mcl_core:stone"}, {["x"] = 2, ["y"] = 11, ["z"] = 15, ["name"] = "mcl_core:stone"}, {["x"] = 2, ["y"] = 11, ["z"] = 16, ["name"] = "mcl_core:stone"}, {["x"] = 2, ["y"] = 11, ["z"] = 17, ["name"] = "mcl_core:stone"}, {["x"] = 2, ["y"] = 11, ["z"] = 18, ["name"] = "mcl_core:stone"}, {["x"] = 2, ["y"] = 11, ["z"] = 19, ["name"] = "mcl_core:stone"}, {["x"] = 2, ["y"] = 11, ["z"] = 20, ["name"] = "mcl_core:stone"}, {["x"] = 2, ["y"] = 11, ["z"] = 21, ["name"] = "mcl_core:stone"}, {["x"] = 2, ["y"] = 12, ["z"] = 0, ["name"] = "mcl_core:stone"}, {["x"] = 2, ["y"] = 12, ["z"] = 1, ["name"] = "mcl_core:stone"}, {["x"] = 2, ["y"] = 12, ["z"] = 2, ["name"] = "mcl_core:stone"}, {["x"] = 2, ["y"] = 12, ["z"] = 3, ["name"] = "mcl_core:stone"}, {["x"] = 2, ["y"] = 12, ["z"] = 4, ["name"] = "mcl_core:stone"}, {["x"] = 2, ["y"] = 12, ["z"] = 5, ["name"] = "mcl_core:stone"}, {["x"] = 2, ["y"] = 12, ["z"] = 6, ["name"] = "mcl_core:stone"}, {["x"] = 2, ["y"] = 12, ["z"] = 7, ["name"] = "mcl_core:stone"}, {["x"] = 2, ["y"] = 12, ["z"] = 8, ["name"] = "mcl_core:stone"}, {["x"] = 2, ["y"] = 12, ["z"] = 9, ["name"] = "mcl_core:stone"}, {["x"] = 2, ["y"] = 12, ["z"] = 10, ["name"] = "mcl_core:stone"}, {["x"] = 2, ["y"] = 12, ["z"] = 11, ["name"] = "mcl_core:cobble"}, {["x"] = 2, ["y"] = 12, ["z"] = 12, ["name"] = "mcl_core:stone"}, {["x"] = 2, ["y"] = 12, ["z"] = 13, ["name"] = "mcl_core:stone"}, {["x"] = 2, ["y"] = 12, ["z"] = 14, ["name"] = "mcl_core:stone"}, {["x"] = 2, ["y"] = 12, ["z"] = 15, ["name"] = "mcl_core:stone"}, {["x"] = 2, ["y"] = 12, ["z"] = 16, ["name"] = "mcl_core:stone"}, {["x"] = 2, ["y"] = 12, ["z"] = 17, ["name"] = "mcl_core:stone"}, {["x"] = 2, ["y"] = 12, ["z"] = 18, ["name"] = "mcl_core:stone"}, {["x"] = 2, ["y"] = 12, ["z"] = 19, ["name"] = "mcl_core:stone"}, {["x"] = 2, ["y"] = 12, ["z"] = 20, ["name"] = "mcl_core:stone"}, {["x"] = 2, ["y"] = 12, ["z"] = 21, ["name"] = "mcl_core:stone"}, {["x"] = 2, ["y"] = 13, ["z"] = 0, ["name"] = "mcl_core:stone"}, {["x"] = 2, ["y"] = 13, ["z"] = 1, ["name"] = "mcl_core:stone"}, {["x"] = 2, ["y"] = 13, ["z"] = 2, ["name"] = "mcl_core:stone"}, {["x"] = 2, ["y"] = 13, ["z"] = 3, ["name"] = "mcl_core:stone"}, {["x"] = 2, ["y"] = 13, ["z"] = 4, ["name"] = "mcl_core:stone"}, {["x"] = 2, ["y"] = 13, ["z"] = 5, ["name"] = "mcl_core:stone"}, {["x"] = 2, ["y"] = 13, ["z"] = 6, ["name"] = "mcl_core:stone"}, {["x"] = 2, ["y"] = 13, ["z"] = 7, ["name"] = "mcl_core:stone"}, {["x"] = 2, ["y"] = 13, ["z"] = 8, ["name"] = "mcl_core:stone"}, {["x"] = 2, ["y"] = 13, ["z"] = 9, ["name"] = "mcl_core:stone"}, {["x"] = 2, ["y"] = 13, ["z"] = 10, ["name"] = "mcl_core:stone"}, {["x"] = 2, ["y"] = 13, ["z"] = 11, ["name"] = "mcl_core:stone"}, {["x"] = 2, ["y"] = 13, ["z"] = 12, ["name"] = "mcl_core:stone"}, {["x"] = 2, ["y"] = 13, ["z"] = 13, ["name"] = "mcl_core:stone"}, {["x"] = 2, ["y"] = 13, ["z"] = 14, ["name"] = "mcl_core:stone"}, {["x"] = 2, ["y"] = 13, ["z"] = 15, ["name"] = "mcl_core:stone"}, {["x"] = 2, ["y"] = 13, ["z"] = 16, ["name"] = "mcl_core:stone"}, {["x"] = 2, ["y"] = 13, ["z"] = 17, ["name"] = "mcl_core:stone"}, {["x"] = 2, ["y"] = 13, ["z"] = 18, ["name"] = "mcl_core:stone"}, {["x"] = 2, ["y"] = 13, ["z"] = 19, ["name"] = "mcl_core:stone"}, {["x"] = 2, ["y"] = 13, ["z"] = 20, ["name"] = "mcl_core:stone"}, {["x"] = 2, ["y"] = 13, ["z"] = 21, ["name"] = "mcl_core:stone"}, {["x"] = 2, ["y"] = 14, ["z"] = 0, ["name"] = "mcl_core:stone"}, {["x"] = 2, ["y"] = 14, ["z"] = 1, ["name"] = "mcl_core:stone"}, {["x"] = 2, ["y"] = 14, ["z"] = 2, ["name"] = "mcl_core:stone"}, {["x"] = 2, ["y"] = 14, ["z"] = 3, ["name"] = "mcl_core:stone"}, {["x"] = 2, ["y"] = 14, ["z"] = 4, ["name"] = "mcl_core:stone"}, {["x"] = 2, ["y"] = 14, ["z"] = 5, ["name"] = "mcl_core:stone"}, {["x"] = 2, ["y"] = 14, ["z"] = 6, ["name"] = "mcl_core:stone"}, {["x"] = 2, ["y"] = 14, ["z"] = 7, ["name"] = "mcl_core:stone"}, {["x"] = 2, ["y"] = 14, ["z"] = 8, ["name"] = "mcl_core:stone"}, {["x"] = 2, ["y"] = 14, ["z"] = 9, ["name"] = "mcl_core:stone"}, {["x"] = 2, ["y"] = 14, ["z"] = 10, ["name"] = "mcl_core:stone"}, {["x"] = 2, ["y"] = 14, ["z"] = 11, ["name"] = "mcl_core:stone"}, {["x"] = 2, ["y"] = 14, ["z"] = 12, ["name"] = "mcl_core:stone"}, {["x"] = 2, ["y"] = 14, ["z"] = 13, ["name"] = "mcl_core:stone"}, {["x"] = 2, ["y"] = 14, ["z"] = 14, ["name"] = "mcl_core:stone"}, {["x"] = 2, ["y"] = 14, ["z"] = 15, ["name"] = "mcl_core:stone"}, {["x"] = 2, ["y"] = 14, ["z"] = 16, ["name"] = "mcl_core:stone"}, {["x"] = 2, ["y"] = 14, ["z"] = 17, ["name"] = "mcl_core:stone"}, {["x"] = 2, ["y"] = 14, ["z"] = 18, ["name"] = "mcl_core:stone"}, {["x"] = 2, ["y"] = 14, ["z"] = 19, ["name"] = "mcl_core:stone"}, {["x"] = 2, ["y"] = 14, ["z"] = 20, ["name"] = "mcl_core:stone"}, {["x"] = 2, ["y"] = 14, ["z"] = 21, ["name"] = "mcl_core:stone"}, {["x"] = 2, ["y"] = 15, ["z"] = 0, ["name"] = "mcl_core:stone"}, {["x"] = 2, ["y"] = 15, ["z"] = 1, ["name"] = "mcl_core:stone"}, {["x"] = 2, ["y"] = 15, ["z"] = 2, ["name"] = "mcl_core:stone"}, {["x"] = 2, ["y"] = 15, ["z"] = 3, ["name"] = "mcl_core:stone"}, {["x"] = 2, ["y"] = 15, ["z"] = 4, ["name"] = "mcl_core:stone"}, {["x"] = 2, ["y"] = 15, ["z"] = 5, ["name"] = "mcl_core:stone"}, {["x"] = 2, ["y"] = 15, ["z"] = 6, ["name"] = "mcl_core:stone"}, {["x"] = 2, ["y"] = 15, ["z"] = 7, ["name"] = "mcl_core:stone"}, {["x"] = 2, ["y"] = 15, ["z"] = 8, ["name"] = "mcl_core:stone"}, {["x"] = 2, ["y"] = 15, ["z"] = 9, ["name"] = "mcl_core:stone"}, {["x"] = 2, ["y"] = 15, ["z"] = 10, ["name"] = "mcl_core:stone"}, {["x"] = 2, ["y"] = 15, ["z"] = 11, ["name"] = "mcl_core:stone"}, {["x"] = 2, ["y"] = 15, ["z"] = 12, ["name"] = "mcl_core:stone"}, {["x"] = 2, ["y"] = 15, ["z"] = 13, ["name"] = "mcl_core:stone"}, {["x"] = 2, ["y"] = 15, ["z"] = 14, ["name"] = "mcl_core:stone"}, {["x"] = 2, ["y"] = 15, ["z"] = 15, ["name"] = "mcl_core:stone"}, {["x"] = 2, ["y"] = 15, ["z"] = 16, ["name"] = "mcl_core:stone"}, {["x"] = 2, ["y"] = 15, ["z"] = 17, ["name"] = "mcl_core:stone"}, {["x"] = 2, ["y"] = 15, ["z"] = 18, ["name"] = "mcl_core:stone"}, {["x"] = 2, ["y"] = 15, ["z"] = 19, ["name"] = "mcl_core:stone"}, {["x"] = 2, ["y"] = 15, ["z"] = 20, ["name"] = "mcl_core:stone"}, {["x"] = 2, ["y"] = 15, ["z"] = 21, ["name"] = "mcl_core:stone"}, {["x"] = 2, ["y"] = 16, ["z"] = 0, ["name"] = "mcl_core:stone"}, {["x"] = 2, ["y"] = 16, ["z"] = 1, ["name"] = "mcl_core:stone"}, {["x"] = 2, ["y"] = 16, ["z"] = 2, ["name"] = "mcl_core:stone"}, {["x"] = 2, ["y"] = 16, ["z"] = 3, ["name"] = "mcl_core:stone"}, {["x"] = 2, ["y"] = 16, ["z"] = 4, ["name"] = "mcl_core:stone"}, {["x"] = 2, ["y"] = 16, ["z"] = 5, ["name"] = "mcl_core:stone"}, {["x"] = 2, ["y"] = 16, ["z"] = 6, ["name"] = "mcl_core:stone"}, {["x"] = 2, ["y"] = 16, ["z"] = 7, ["name"] = "mcl_core:stone"}, {["x"] = 2, ["y"] = 16, ["z"] = 8, ["name"] = "mcl_core:stone"}, {["x"] = 2, ["y"] = 16, ["z"] = 9, ["name"] = "mcl_core:stone"}, {["x"] = 2, ["y"] = 16, ["z"] = 10, ["name"] = "mcl_core:stone"}, {["x"] = 2, ["y"] = 16, ["z"] = 11, ["name"] = "mcl_core:stone"}, {["x"] = 2, ["y"] = 16, ["z"] = 12, ["name"] = "mcl_core:stone"}, {["x"] = 2, ["y"] = 16, ["z"] = 13, ["name"] = "mcl_core:stone"}, {["x"] = 2, ["y"] = 16, ["z"] = 14, ["name"] = "mcl_core:stone"}, {["x"] = 2, ["y"] = 16, ["z"] = 15, ["name"] = "mcl_core:stone"}, {["x"] = 2, ["y"] = 16, ["z"] = 16, ["name"] = "mcl_core:stone"}, {["x"] = 2, ["y"] = 16, ["z"] = 17, ["name"] = "mcl_core:stone"}, {["x"] = 2, ["y"] = 16, ["z"] = 18, ["name"] = "mcl_core:stone"}, {["x"] = 2, ["y"] = 16, ["z"] = 19, ["name"] = "mcl_core:stone"}, {["x"] = 2, ["y"] = 16, ["z"] = 20, ["name"] = "mcl_core:stone"}, {["x"] = 2, ["y"] = 16, ["z"] = 21, ["name"] = "mcl_core:stone"}, {["x"] = 2, ["y"] = 17, ["z"] = 0, ["name"] = "mcl_core:stone"}, {["x"] = 2, ["y"] = 17, ["z"] = 1, ["name"] = "mcl_core:stone"}, {["x"] = 2, ["y"] = 17, ["z"] = 2, ["name"] = "mcl_core:stone"}, {["x"] = 2, ["y"] = 17, ["z"] = 3, ["name"] = "mcl_core:stone"}, {["x"] = 2, ["y"] = 17, ["z"] = 4, ["name"] = "mcl_core:stone"}, {["x"] = 2, ["y"] = 17, ["z"] = 5, ["name"] = "mcl_core:stone"}, {["x"] = 2, ["y"] = 17, ["z"] = 6, ["name"] = "mcl_core:stone"}, {["x"] = 2, ["y"] = 17, ["z"] = 7, ["name"] = "mcl_core:stone"}, {["x"] = 2, ["y"] = 17, ["z"] = 8, ["name"] = "mcl_core:stone"}, {["x"] = 2, ["y"] = 17, ["z"] = 9, ["name"] = "mcl_core:stone"}, {["x"] = 2, ["y"] = 17, ["z"] = 10, ["name"] = "mcl_core:stone"}, {["x"] = 2, ["y"] = 17, ["z"] = 11, ["name"] = "mcl_core:stone"}, {["x"] = 2, ["y"] = 17, ["z"] = 12, ["name"] = "mcl_core:stone"}, {["x"] = 2, ["y"] = 17, ["z"] = 13, ["name"] = "mcl_core:stone"}, {["x"] = 2, ["y"] = 17, ["z"] = 14, ["name"] = "mcl_core:stone"}, {["x"] = 2, ["y"] = 17, ["z"] = 15, ["name"] = "mcl_core:stone"}, {["x"] = 2, ["y"] = 17, ["z"] = 16, ["name"] = "mcl_core:stone"}, {["x"] = 2, ["y"] = 17, ["z"] = 17, ["name"] = "mcl_core:stone"}, {["x"] = 2, ["y"] = 17, ["z"] = 18, ["name"] = "mcl_core:stone"}, {["x"] = 2, ["y"] = 17, ["z"] = 19, ["name"] = "mcl_core:stone"}, {["x"] = 2, ["y"] = 17, ["z"] = 20, ["name"] = "mcl_core:stone"}, {["x"] = 2, ["y"] = 17, ["z"] = 21, ["name"] = "mcl_core:stone"}, {["x"] = 2, ["y"] = 18, ["z"] = 0, ["name"] = "mcl_core:dirt_with_grass"}, {["x"] = 2, ["y"] = 18, ["z"] = 1, ["name"] = "mcl_core:dirt"}, {["x"] = 2, ["y"] = 18, ["z"] = 2, ["name"] = "mcl_core:dirt"}, {["x"] = 2, ["y"] = 18, ["z"] = 3, ["name"] = "mcl_core:dirt"}, {["x"] = 2, ["y"] = 18, ["z"] = 4, ["name"] = "mcl_core:dirt_with_grass"}, {["x"] = 2, ["y"] = 18, ["z"] = 5, ["name"] = "mcl_core:dirt"}, {["x"] = 2, ["y"] = 18, ["z"] = 6, ["name"] = "mcl_core:dirt"}, {["x"] = 2, ["y"] = 18, ["z"] = 7, ["name"] = "mcl_core:dirt"}, {["x"] = 2, ["y"] = 18, ["z"] = 8, ["name"] = "mcl_core:dirt"}, {["x"] = 2, ["y"] = 18, ["z"] = 9, ["name"] = "mcl_core:dirt"}, {["x"] = 2, ["y"] = 18, ["z"] = 10, ["name"] = "mcl_core:dirt"}, {["x"] = 2, ["y"] = 18, ["z"] = 11, ["name"] = "mcl_core:dirt"}, {["x"] = 2, ["y"] = 18, ["z"] = 12, ["name"] = "mcl_core:dirt"}, {["x"] = 2, ["y"] = 18, ["z"] = 13, ["name"] = "mcl_core:dirt"}, {["x"] = 2, ["y"] = 18, ["z"] = 14, ["name"] = "mcl_core:dirt"}, {["x"] = 2, ["y"] = 18, ["z"] = 15, ["name"] = "mcl_core:dirt"}, {["x"] = 2, ["y"] = 18, ["z"] = 16, ["name"] = "mcl_core:dirt_with_grass"}, {["x"] = 2, ["y"] = 18, ["z"] = 17, ["name"] = "mcl_core:dirt"}, {["x"] = 2, ["y"] = 18, ["z"] = 18, ["name"] = "mcl_core:dirt"}, {["x"] = 2, ["y"] = 18, ["z"] = 19, ["name"] = "mcl_core:dirt"}, {["x"] = 2, ["y"] = 18, ["z"] = 20, ["name"] = "mcl_core:dirt"}, {["x"] = 2, ["y"] = 18, ["z"] = 21, ["name"] = "mcl_core:dirt"}, {["x"] = 2, ["y"] = 19, ["z"] = 1, ["name"] = "mcl_core:dirt_with_grass"}, {["x"] = 2, ["y"] = 19, ["z"] = 2, ["name"] = "mcl_core:dirt"}, {["x"] = 2, ["y"] = 19, ["z"] = 3, ["name"] = "mcl_core:dirt_with_grass"}, {["x"] = 2, ["y"] = 19, ["z"] = 5, ["name"] = "mcl_core:dirt"}, {["x"] = 2, ["y"] = 19, ["z"] = 6, ["name"] = "mcl_core:dirt_with_grass"}, {["x"] = 2, ["y"] = 19, ["z"] = 7, ["name"] = "mcl_core:dirt_with_grass"}, {["x"] = 2, ["y"] = 19, ["z"] = 8, ["name"] = "mcl_core:dirt_with_grass"}, {["x"] = 2, ["y"] = 19, ["z"] = 9, ["name"] = "mcl_core:dirt_with_grass"}, {["x"] = 2, ["y"] = 19, ["z"] = 10, ["name"] = "mcl_core:dirt_with_grass"}, {["x"] = 2, ["y"] = 19, ["z"] = 11, ["name"] = "mcl_core:dirt_with_grass"}, {["x"] = 2, ["y"] = 19, ["z"] = 12, ["name"] = "mcl_core:dirt_with_grass"}, {["x"] = 2, ["y"] = 19, ["z"] = 13, ["name"] = "mcl_core:dirt_with_grass"}, {["x"] = 2, ["y"] = 19, ["z"] = 14, ["name"] = "mcl_core:dirt_with_grass"}, {["x"] = 2, ["y"] = 19, ["z"] = 15, ["name"] = "mcl_core:dirt_with_grass"}, {["x"] = 2, ["y"] = 19, ["z"] = 17, ["name"] = "mcl_core:dirt_with_grass"}, {["x"] = 2, ["y"] = 19, ["z"] = 18, ["name"] = "mcl_core:dirt_with_grass"}, {["x"] = 2, ["y"] = 19, ["z"] = 19, ["name"] = "mcl_core:dirt"}, {["x"] = 2, ["y"] = 19, ["z"] = 20, ["name"] = "mcl_core:dirt_with_grass"}, {["x"] = 2, ["y"] = 19, ["z"] = 21, ["name"] = "mcl_core:dirt_with_grass"}, {["x"] = 2, ["y"] = 20, ["param1"] = 15, ["z"] = 1, ["name"] = "mcl_flowers:tallgrass"}, {["x"] = 2, ["y"] = 20, ["z"] = 2, ["name"] = "mcl_core:dirt_with_grass"}, {["x"] = 2, ["y"] = 20, ["z"] = 5, ["name"] = "mcl_core:dirt_with_grass"}, {["x"] = 2, ["y"] = 20, ["z"] = 19, ["name"] = "mcl_core:dirt_with_grass"}, {["x"] = 3, ["y"] = 0, ["z"] = 0, ["name"] = "mcl_core:stone"}, {["x"] = 3, ["y"] = 0, ["z"] = 1, ["name"] = "mcl_core:stone"}, {["x"] = 3, ["y"] = 0, ["z"] = 2, ["name"] = "mcl_core:stone"}, {["x"] = 3, ["y"] = 0, ["z"] = 3, ["name"] = "mcl_core:stone"}, {["x"] = 3, ["y"] = 0, ["z"] = 4, ["name"] = "mcl_core:stone"}, {["x"] = 3, ["y"] = 0, ["z"] = 5, ["name"] = "mcl_core:stone"}, {["x"] = 3, ["y"] = 0, ["z"] = 6, ["name"] = "mcl_core:stone"}, {["x"] = 3, ["y"] = 0, ["z"] = 7, ["name"] = "mcl_core:stone"}, {["x"] = 3, ["y"] = 0, ["z"] = 8, ["name"] = "mcl_core:stone"}, {["x"] = 3, ["y"] = 0, ["z"] = 9, ["name"] = "mcl_core:stone"}, {["x"] = 3, ["y"] = 0, ["z"] = 10, ["name"] = "mcl_core:stone"}, {["x"] = 3, ["y"] = 0, ["z"] = 11, ["name"] = "mcl_core:stone"}, {["x"] = 3, ["y"] = 0, ["z"] = 12, ["name"] = "mcl_core:stone"}, {["x"] = 3, ["param2"] = 3, ["y"] = 0, ["param1"] = 136, ["z"] = 13, ["name"] = "mcl_core:ladder"}, {["x"] = 3, ["y"] = 0, ["z"] = 14, ["name"] = "mcl_core:stone"}, {["x"] = 3, ["y"] = 0, ["z"] = 15, ["name"] = "mcl_core:stone"}, {["x"] = 3, ["y"] = 0, ["z"] = 16, ["name"] = "mcl_core:stone"}, {["x"] = 3, ["y"] = 0, ["z"] = 17, ["name"] = "mcl_core:stone"}, {["x"] = 3, ["y"] = 0, ["z"] = 18, ["name"] = "mcl_core:stone"}, {["x"] = 3, ["y"] = 0, ["z"] = 19, ["name"] = "mcl_core:stone"}, {["x"] = 3, ["y"] = 0, ["z"] = 20, ["name"] = "mcl_core:stone"}, {["x"] = 3, ["y"] = 0, ["z"] = 21, ["name"] = "mcl_core:stone"}, {["x"] = 3, ["y"] = 1, ["z"] = 0, ["name"] = "mcl_core:stone"}, {["x"] = 3, ["y"] = 1, ["z"] = 1, ["name"] = "mcl_core:stone"}, {["x"] = 3, ["y"] = 1, ["z"] = 2, ["name"] = "mcl_core:stone"}, {["x"] = 3, ["y"] = 1, ["z"] = 3, ["name"] = "mcl_core:stone"}, {["x"] = 3, ["y"] = 1, ["z"] = 4, ["name"] = "mcl_core:stone"}, {["x"] = 3, ["y"] = 1, ["z"] = 5, ["name"] = "mcl_core:stone"}, {["x"] = 3, ["y"] = 1, ["z"] = 6, ["name"] = "mcl_core:stone"}, {["x"] = 3, ["y"] = 1, ["z"] = 7, ["name"] = "mcl_core:stone"}, {["x"] = 3, ["y"] = 1, ["z"] = 8, ["name"] = "mcl_core:stone"}, {["x"] = 3, ["y"] = 1, ["z"] = 9, ["name"] = "mcl_core:stone"}, {["x"] = 3, ["y"] = 1, ["z"] = 10, ["name"] = "mcl_core:stone"}, {["x"] = 3, ["y"] = 1, ["z"] = 11, ["name"] = "mcl_core:stone"}, {["x"] = 3, ["y"] = 1, ["z"] = 12, ["name"] = "mcl_core:stone"}, {["x"] = 3, ["param2"] = 3, ["y"] = 1, ["param1"] = 119, ["z"] = 13, ["name"] = "mcl_core:ladder"}, {["x"] = 3, ["y"] = 1, ["z"] = 14, ["name"] = "mcl_core:stone"}, {["x"] = 3, ["y"] = 1, ["z"] = 15, ["name"] = "mcl_core:stone"}, {["x"] = 3, ["y"] = 1, ["z"] = 16, ["name"] = "mcl_core:stone"}, {["x"] = 3, ["y"] = 1, ["z"] = 17, ["name"] = "mcl_core:stone"}, {["x"] = 3, ["y"] = 1, ["z"] = 18, ["name"] = "mcl_core:stone"}, {["x"] = 3, ["y"] = 1, ["z"] = 19, ["name"] = "mcl_core:stone"}, {["x"] = 3, ["y"] = 1, ["z"] = 20, ["name"] = "mcl_core:stone"}, {["x"] = 3, ["y"] = 1, ["z"] = 21, ["name"] = "mcl_core:stone"}, {["x"] = 3, ["y"] = 2, ["z"] = 0, ["name"] = "mcl_core:stone"}, {["x"] = 3, ["y"] = 2, ["z"] = 1, ["name"] = "mcl_core:stone"}, {["x"] = 3, ["y"] = 2, ["z"] = 2, ["name"] = "mcl_core:stone"}, {["x"] = 3, ["y"] = 2, ["z"] = 3, ["name"] = "mcl_core:stone"}, {["x"] = 3, ["y"] = 2, ["z"] = 4, ["name"] = "mcl_core:stone"}, {["x"] = 3, ["y"] = 2, ["z"] = 5, ["name"] = "mcl_core:stone"}, {["x"] = 3, ["y"] = 2, ["z"] = 6, ["name"] = "mcl_core:stone"}, {["x"] = 3, ["y"] = 2, ["z"] = 7, ["name"] = "mcl_core:stone"}, {["x"] = 3, ["y"] = 2, ["z"] = 8, ["name"] = "mcl_core:stone"}, {["x"] = 3, ["y"] = 2, ["z"] = 9, ["name"] = "mcl_core:stone"}, {["x"] = 3, ["y"] = 2, ["z"] = 10, ["name"] = "mcl_core:stone"}, {["x"] = 3, ["y"] = 2, ["z"] = 11, ["name"] = "mcl_core:sandstone"}, {["x"] = 3, ["y"] = 2, ["z"] = 12, ["name"] = "mcl_core:stone"}, {["x"] = 3, ["y"] = 2, ["z"] = 13, ["name"] = "mcl_core:diorite"}, {["x"] = 3, ["y"] = 2, ["z"] = 14, ["name"] = "mcl_core:stone"}, {["x"] = 3, ["y"] = 2, ["z"] = 15, ["name"] = "mcl_core:stone"}, {["x"] = 3, ["y"] = 2, ["z"] = 16, ["name"] = "mcl_core:stone"}, {["x"] = 3, ["y"] = 2, ["z"] = 17, ["name"] = "mcl_core:stone"}, {["x"] = 3, ["y"] = 2, ["z"] = 18, ["name"] = "mcl_core:stone"}, {["x"] = 3, ["y"] = 2, ["z"] = 19, ["name"] = "mcl_core:stone"}, {["x"] = 3, ["y"] = 2, ["z"] = 20, ["name"] = "mcl_core:stone"}, {["x"] = 3, ["y"] = 2, ["z"] = 21, ["name"] = "mcl_core:stone"}, {["x"] = 3, ["y"] = 3, ["z"] = 0, ["name"] = "mcl_core:stone"}, {["x"] = 3, ["y"] = 3, ["z"] = 1, ["name"] = "mcl_core:stone"}, {["x"] = 3, ["y"] = 3, ["z"] = 2, ["name"] = "mcl_core:stone"}, {["x"] = 3, ["y"] = 3, ["z"] = 3, ["name"] = "mcl_core:stone"}, {["x"] = 3, ["y"] = 3, ["z"] = 4, ["name"] = "mcl_core:stone"}, {["x"] = 3, ["y"] = 3, ["z"] = 5, ["name"] = "mcl_core:stone"}, {["x"] = 3, ["y"] = 3, ["z"] = 6, ["name"] = "mcl_core:stone"}, {["x"] = 3, ["y"] = 3, ["z"] = 7, ["name"] = "mcl_core:stone"}, {["x"] = 3, ["y"] = 3, ["z"] = 8, ["name"] = "mcl_core:stone"}, {["x"] = 3, ["y"] = 3, ["z"] = 9, ["name"] = "mcl_core:stone"}, {["x"] = 3, ["y"] = 3, ["z"] = 10, ["name"] = "mcl_core:stone"}, {["x"] = 3, ["y"] = 3, ["z"] = 11, ["name"] = "mcl_core:sandstone"}, {["x"] = 3, ["y"] = 3, ["z"] = 12, ["name"] = "mcl_core:stone"}, {["x"] = 3, ["y"] = 3, ["z"] = 13, ["name"] = "mcl_core:diorite"}, {["x"] = 3, ["y"] = 3, ["z"] = 14, ["name"] = "mcl_core:stone"}, {["x"] = 3, ["y"] = 3, ["z"] = 15, ["name"] = "mcl_core:stone"}, {["x"] = 3, ["y"] = 3, ["z"] = 16, ["name"] = "mcl_core:stone"}, {["x"] = 3, ["y"] = 3, ["z"] = 17, ["name"] = "mcl_core:stone"}, {["x"] = 3, ["y"] = 3, ["z"] = 18, ["name"] = "mcl_core:stone"}, {["x"] = 3, ["y"] = 3, ["z"] = 19, ["name"] = "mcl_core:stone"}, {["x"] = 3, ["y"] = 3, ["z"] = 20, ["name"] = "mcl_core:stone"}, {["x"] = 3, ["y"] = 3, ["z"] = 21, ["name"] = "mcl_core:stone"}, {["x"] = 3, ["y"] = 4, ["z"] = 0, ["name"] = "mcl_core:stone"}, {["x"] = 3, ["y"] = 4, ["z"] = 1, ["name"] = "mcl_core:stone"}, {["x"] = 3, ["y"] = 4, ["z"] = 2, ["name"] = "mcl_core:stone"}, {["x"] = 3, ["y"] = 4, ["z"] = 3, ["name"] = "mcl_core:stone"}, {["x"] = 3, ["y"] = 4, ["z"] = 4, ["name"] = "mcl_core:stone"}, {["x"] = 3, ["y"] = 4, ["z"] = 5, ["name"] = "mcl_core:stone"}, {["x"] = 3, ["y"] = 4, ["z"] = 6, ["name"] = "mcl_core:stone"}, {["x"] = 3, ["y"] = 4, ["z"] = 7, ["name"] = "mcl_core:stone"}, {["x"] = 3, ["y"] = 4, ["z"] = 8, ["name"] = "mcl_core:stone"}, {["x"] = 3, ["y"] = 4, ["z"] = 9, ["name"] = "mcl_core:stone"}, {["x"] = 3, ["y"] = 4, ["z"] = 10, ["name"] = "mcl_core:stone"}, {["x"] = 3, ["y"] = 4, ["z"] = 11, ["name"] = "mcl_core:stone"}, {["x"] = 3, ["y"] = 4, ["z"] = 12, ["name"] = "mcl_core:stone"}, {["x"] = 3, ["y"] = 4, ["z"] = 13, ["name"] = "mcl_core:stone"}, {["x"] = 3, ["y"] = 4, ["z"] = 14, ["name"] = "mcl_core:stone"}, {["x"] = 3, ["y"] = 4, ["z"] = 15, ["name"] = "mcl_core:stone"}, {["x"] = 3, ["y"] = 4, ["z"] = 16, ["name"] = "mcl_core:stone"}, {["x"] = 3, ["y"] = 4, ["z"] = 17, ["name"] = "mcl_core:stone"}, {["x"] = 3, ["y"] = 4, ["z"] = 18, ["name"] = "mcl_core:stone"}, {["x"] = 3, ["y"] = 4, ["z"] = 19, ["name"] = "mcl_core:stone"}, {["x"] = 3, ["y"] = 4, ["z"] = 20, ["name"] = "mcl_core:stone"}, {["x"] = 3, ["y"] = 4, ["z"] = 21, ["name"] = "mcl_core:stone"}, {["x"] = 3, ["y"] = 5, ["z"] = 0, ["name"] = "mcl_core:stone"}, {["x"] = 3, ["y"] = 5, ["z"] = 1, ["name"] = "mcl_core:stone"}, {["x"] = 3, ["y"] = 5, ["z"] = 2, ["name"] = "mcl_core:stone"}, {["x"] = 3, ["y"] = 5, ["z"] = 3, ["name"] = "mcl_core:stone"}, {["x"] = 3, ["y"] = 5, ["z"] = 4, ["name"] = "mcl_core:stone"}, {["x"] = 3, ["y"] = 5, ["z"] = 5, ["name"] = "mcl_core:stone"}, {["x"] = 3, ["y"] = 5, ["z"] = 6, ["name"] = "mcl_core:stone"}, {["x"] = 3, ["y"] = 5, ["z"] = 7, ["name"] = "mcl_core:stone"}, {["x"] = 3, ["y"] = 5, ["z"] = 8, ["name"] = "mcl_core:stone"}, {["x"] = 3, ["y"] = 5, ["z"] = 9, ["name"] = "mcl_core:stone"}, {["x"] = 3, ["y"] = 5, ["z"] = 10, ["name"] = "mcl_core:stone"}, {["x"] = 3, ["y"] = 5, ["z"] = 11, ["name"] = "mcl_core:stone"}, {["x"] = 3, ["y"] = 5, ["z"] = 12, ["name"] = "mcl_core:stone"}, {["x"] = 3, ["y"] = 5, ["z"] = 13, ["name"] = "mcl_core:stone"}, {["x"] = 3, ["y"] = 5, ["z"] = 14, ["name"] = "mcl_core:stone"}, {["x"] = 3, ["y"] = 5, ["z"] = 15, ["name"] = "mcl_core:stone"}, {["x"] = 3, ["y"] = 5, ["z"] = 16, ["name"] = "mcl_core:stone"}, {["x"] = 3, ["y"] = 5, ["z"] = 17, ["name"] = "mcl_core:stone"}, {["x"] = 3, ["y"] = 5, ["z"] = 18, ["name"] = "mcl_core:stone"}, {["x"] = 3, ["y"] = 5, ["z"] = 19, ["name"] = "mcl_core:stone"}, {["x"] = 3, ["y"] = 5, ["z"] = 20, ["name"] = "mcl_core:stone"}, {["x"] = 3, ["y"] = 5, ["z"] = 21, ["name"] = "mcl_core:stone"}, {["x"] = 3, ["y"] = 6, ["z"] = 0, ["name"] = "mcl_core:stone"}, {["x"] = 3, ["y"] = 6, ["z"] = 1, ["name"] = "mcl_core:stone"}, {["x"] = 3, ["y"] = 6, ["z"] = 2, ["name"] = "mcl_core:stone"}, {["x"] = 3, ["y"] = 6, ["z"] = 3, ["name"] = "mcl_core:stone"}, {["x"] = 3, ["y"] = 6, ["z"] = 4, ["name"] = "mcl_core:stone"}, {["x"] = 3, ["y"] = 6, ["z"] = 5, ["name"] = "mcl_core:stone"}, {["x"] = 3, ["y"] = 6, ["z"] = 6, ["name"] = "mcl_core:stone"}, {["x"] = 3, ["y"] = 6, ["z"] = 7, ["name"] = "mcl_core:stone"}, {["x"] = 3, ["y"] = 6, ["z"] = 8, ["name"] = "mcl_core:stone"}, {["x"] = 3, ["y"] = 6, ["z"] = 9, ["name"] = "mcl_core:stone"}, {["x"] = 3, ["y"] = 6, ["z"] = 10, ["name"] = "mcl_core:stone"}, {["x"] = 3, ["y"] = 6, ["z"] = 11, ["name"] = "mcl_core:stone"}, {["x"] = 3, ["y"] = 6, ["z"] = 12, ["name"] = "mcl_core:stone"}, {["x"] = 3, ["y"] = 6, ["z"] = 13, ["name"] = "mcl_core:stone"}, {["x"] = 3, ["y"] = 6, ["z"] = 14, ["name"] = "mcl_core:stone"}, {["x"] = 3, ["y"] = 6, ["z"] = 15, ["name"] = "mcl_core:stone"}, {["x"] = 3, ["y"] = 6, ["z"] = 16, ["name"] = "mcl_core:stone"}, {["x"] = 3, ["y"] = 6, ["z"] = 17, ["name"] = "mcl_core:stone"}, {["x"] = 3, ["y"] = 6, ["z"] = 18, ["name"] = "mcl_core:stone"}, {["x"] = 3, ["y"] = 6, ["z"] = 19, ["name"] = "mcl_core:stone"}, {["x"] = 3, ["y"] = 6, ["z"] = 20, ["name"] = "mcl_core:stone"}, {["x"] = 3, ["y"] = 6, ["z"] = 21, ["name"] = "mcl_core:stone"}, {["x"] = 3, ["y"] = 7, ["z"] = 0, ["name"] = "mcl_core:stone"}, {["x"] = 3, ["y"] = 7, ["z"] = 1, ["name"] = "mcl_core:stone"}, {["x"] = 3, ["y"] = 7, ["z"] = 2, ["name"] = "mcl_core:stone"}, {["x"] = 3, ["y"] = 7, ["z"] = 3, ["name"] = "mcl_core:stone"}, {["x"] = 3, ["y"] = 7, ["z"] = 4, ["name"] = "mcl_core:stone"}, {["x"] = 3, ["y"] = 7, ["z"] = 5, ["name"] = "mcl_core:stone"}, {["x"] = 3, ["y"] = 7, ["z"] = 6, ["name"] = "mcl_core:stone"}, {["x"] = 3, ["y"] = 7, ["z"] = 7, ["name"] = "mcl_core:stone"}, {["x"] = 3, ["y"] = 7, ["param1"] = 170, ["z"] = 8, ["name"] = "mcl_core:glass"}, {["x"] = 3, ["y"] = 7, ["param1"] = 153, ["z"] = 9, ["name"] = "mcl_core:glass"}, {["x"] = 3, ["y"] = 7, ["param1"] = 136, ["z"] = 10, ["name"] = "mcl_core:glass"}, {["x"] = 3, ["y"] = 7, ["param1"] = 119, ["z"] = 11, ["name"] = "mcl_core:glass"}, {["x"] = 3, ["y"] = 7, ["param1"] = 136, ["z"] = 12, ["name"] = "mcl_core:glass"}, {["x"] = 3, ["y"] = 7, ["param1"] = 153, ["z"] = 13, ["name"] = "mcl_core:glass"}, {["x"] = 3, ["y"] = 7, ["param1"] = 170, ["z"] = 14, ["name"] = "mcl_core:glass"}, {["x"] = 3, ["y"] = 7, ["z"] = 15, ["name"] = "mcl_core:stone"}, {["x"] = 3, ["y"] = 7, ["z"] = 16, ["name"] = "mcl_core:stone"}, {["x"] = 3, ["y"] = 7, ["z"] = 17, ["name"] = "mcl_core:stone"}, {["x"] = 3, ["y"] = 7, ["z"] = 18, ["name"] = "mcl_core:stone"}, {["x"] = 3, ["y"] = 7, ["z"] = 19, ["name"] = "mcl_core:stone"}, {["x"] = 3, ["y"] = 7, ["z"] = 20, ["name"] = "mcl_core:stone"}, {["x"] = 3, ["y"] = 7, ["z"] = 21, ["name"] = "mcl_core:stone"}, {["x"] = 3, ["y"] = 8, ["z"] = 0, ["name"] = "mcl_core:stone"}, {["x"] = 3, ["y"] = 8, ["z"] = 1, ["name"] = "mcl_core:stone"}, {["x"] = 3, ["y"] = 8, ["z"] = 2, ["name"] = "mcl_core:stone"}, {["x"] = 3, ["y"] = 8, ["z"] = 3, ["name"] = "mcl_core:stone"}, {["x"] = 3, ["y"] = 8, ["z"] = 4, ["name"] = "mcl_core:stone"}, {["x"] = 3, ["y"] = 8, ["z"] = 5, ["name"] = "mcl_core:stone"}, {["x"] = 3, ["y"] = 8, ["z"] = 6, ["name"] = "mcl_core:stone"}, {["x"] = 3, ["y"] = 8, ["z"] = 7, ["name"] = "mcl_core:stone"}, {["x"] = 3, ["y"] = 8, ["param1"] = 187, ["z"] = 8, ["name"] = "mcl_core:glass"}, {["x"] = 3, ["y"] = 8, ["param1"] = 170, ["z"] = 9, ["name"] = "mcl_core:glass"}, {["x"] = 3, ["y"] = 8, ["param1"] = 153, ["z"] = 10, ["name"] = "mcl_core:glass"}, {["x"] = 3, ["y"] = 8, ["param1"] = 136, ["z"] = 11, ["name"] = "mcl_core:glass"}, {["x"] = 3, ["y"] = 8, ["param1"] = 153, ["z"] = 12, ["name"] = "mcl_core:glass"}, {["x"] = 3, ["y"] = 8, ["param1"] = 170, ["z"] = 13, ["name"] = "mcl_core:glass"}, {["x"] = 3, ["y"] = 8, ["param1"] = 187, ["z"] = 14, ["name"] = "mcl_core:glass"}, {["x"] = 3, ["y"] = 8, ["z"] = 15, ["name"] = "mcl_core:stone"}, {["x"] = 3, ["y"] = 8, ["z"] = 16, ["name"] = "mcl_core:stone"}, {["x"] = 3, ["y"] = 8, ["z"] = 17, ["name"] = "mcl_core:stone"}, {["x"] = 3, ["y"] = 8, ["z"] = 18, ["name"] = "mcl_core:stone"}, {["x"] = 3, ["y"] = 8, ["z"] = 19, ["name"] = "mcl_core:stone"}, {["x"] = 3, ["y"] = 8, ["z"] = 20, ["name"] = "mcl_core:stone"}, {["x"] = 3, ["y"] = 8, ["z"] = 21, ["name"] = "mcl_core:stone"}, {["x"] = 3, ["y"] = 9, ["z"] = 0, ["name"] = "mcl_core:stone"}, {["x"] = 3, ["y"] = 9, ["z"] = 1, ["name"] = "mcl_core:stone"}, {["x"] = 3, ["y"] = 9, ["z"] = 2, ["name"] = "mcl_core:stone"}, {["x"] = 3, ["y"] = 9, ["z"] = 3, ["name"] = "mcl_core:stone"}, {["x"] = 3, ["y"] = 9, ["z"] = 4, ["name"] = "mcl_core:stone"}, {["x"] = 3, ["y"] = 9, ["z"] = 5, ["name"] = "mcl_core:stone"}, {["x"] = 3, ["y"] = 9, ["z"] = 6, ["name"] = "mcl_core:stone"}, {["x"] = 3, ["y"] = 9, ["z"] = 7, ["name"] = "mcl_core:stone"}, {["x"] = 3, ["y"] = 9, ["param1"] = 204, ["z"] = 8, ["name"] = "mcl_core:glass"}, {["x"] = 3, ["y"] = 9, ["param1"] = 187, ["z"] = 9, ["name"] = "mcl_core:glass"}, {["x"] = 3, ["y"] = 9, ["param1"] = 170, ["z"] = 10, ["name"] = "mcl_core:glass"}, {["x"] = 3, ["y"] = 9, ["param1"] = 153, ["z"] = 11, ["name"] = "mcl_core:glass"}, {["x"] = 3, ["y"] = 9, ["param1"] = 170, ["z"] = 12, ["name"] = "mcl_core:glass"}, {["x"] = 3, ["y"] = 9, ["param1"] = 187, ["z"] = 13, ["name"] = "mcl_core:glass"}, {["x"] = 3, ["y"] = 9, ["param1"] = 204, ["z"] = 14, ["name"] = "mcl_core:glass"}, {["x"] = 3, ["y"] = 9, ["z"] = 15, ["name"] = "mcl_core:stone"}, {["x"] = 3, ["y"] = 9, ["z"] = 16, ["name"] = "mcl_core:stone"}, {["x"] = 3, ["y"] = 9, ["z"] = 17, ["name"] = "mcl_core:stone"}, {["x"] = 3, ["y"] = 9, ["z"] = 18, ["name"] = "mcl_core:stone"}, {["x"] = 3, ["y"] = 9, ["z"] = 19, ["name"] = "mcl_core:stone"}, {["x"] = 3, ["y"] = 9, ["z"] = 20, ["name"] = "mcl_core:stone"}, {["x"] = 3, ["y"] = 9, ["z"] = 21, ["name"] = "mcl_core:stone"}, {["x"] = 3, ["y"] = 10, ["z"] = 0, ["name"] = "mcl_core:stone"}, {["x"] = 3, ["y"] = 10, ["z"] = 1, ["name"] = "mcl_core:stone"}, {["x"] = 3, ["y"] = 10, ["z"] = 2, ["name"] = "mcl_core:stone"}, {["x"] = 3, ["y"] = 10, ["z"] = 3, ["name"] = "mcl_core:stone"}, {["x"] = 3, ["y"] = 10, ["z"] = 4, ["name"] = "mcl_core:stone"}, {["x"] = 3, ["y"] = 10, ["z"] = 5, ["name"] = "mcl_core:stone"}, {["x"] = 3, ["y"] = 10, ["z"] = 6, ["name"] = "mcl_core:stone"}, {["x"] = 3, ["y"] = 10, ["z"] = 7, ["name"] = "mcl_core:stone"}, {["x"] = 3, ["y"] = 10, ["param1"] = 221, ["z"] = 8, ["name"] = "mcl_core:glass"}, {["x"] = 3, ["y"] = 10, ["param1"] = 204, ["z"] = 9, ["name"] = "mcl_core:glass"}, {["x"] = 3, ["y"] = 10, ["param1"] = 187, ["z"] = 10, ["name"] = "mcl_core:glass"}, {["x"] = 3, ["y"] = 10, ["param1"] = 170, ["z"] = 11, ["name"] = "mcl_core:glass"}, {["x"] = 3, ["y"] = 10, ["param1"] = 187, ["z"] = 12, ["name"] = "mcl_core:glass"}, {["x"] = 3, ["y"] = 10, ["param1"] = 204, ["z"] = 13, ["name"] = "mcl_core:glass"}, {["x"] = 3, ["y"] = 10, ["param1"] = 221, ["z"] = 14, ["name"] = "mcl_core:glass"}, {["x"] = 3, ["y"] = 10, ["z"] = 15, ["name"] = "mcl_core:stone"}, {["x"] = 3, ["y"] = 10, ["z"] = 16, ["name"] = "mcl_core:stone"}, {["x"] = 3, ["y"] = 10, ["z"] = 17, ["name"] = "mcl_core:stone"}, {["x"] = 3, ["y"] = 10, ["z"] = 18, ["name"] = "mcl_core:stone"}, {["x"] = 3, ["y"] = 10, ["z"] = 19, ["name"] = "mcl_core:stone"}, {["x"] = 3, ["y"] = 10, ["z"] = 20, ["name"] = "mcl_core:stone"}, {["x"] = 3, ["y"] = 10, ["z"] = 21, ["name"] = "mcl_core:stone"}, {["x"] = 3, ["y"] = 11, ["z"] = 0, ["name"] = "mcl_core:stone"}, {["x"] = 3, ["y"] = 11, ["z"] = 1, ["name"] = "mcl_core:stone"}, {["x"] = 3, ["y"] = 11, ["z"] = 2, ["name"] = "mcl_core:stone"}, {["x"] = 3, ["y"] = 11, ["z"] = 3, ["name"] = "mcl_core:stone"}, {["x"] = 3, ["y"] = 11, ["z"] = 4, ["name"] = "mcl_core:stone"}, {["x"] = 3, ["y"] = 11, ["z"] = 5, ["name"] = "mcl_core:stone"}, {["x"] = 3, ["y"] = 11, ["z"] = 6, ["name"] = "mcl_core:stone"}, {["x"] = 3, ["y"] = 11, ["z"] = 7, ["name"] = "mcl_core:stone"}, {["x"] = 3, ["y"] = 11, ["z"] = 8, ["name"] = "mcl_core:stone"}, {["x"] = 3, ["y"] = 11, ["z"] = 9, ["name"] = "mcl_core:stone"}, {["x"] = 3, ["y"] = 11, ["z"] = 10, ["name"] = "mcl_core:stone"}, {["x"] = 3, ["y"] = 11, ["z"] = 11, ["name"] = "mcl_core:stone"}, {["x"] = 3, ["y"] = 11, ["z"] = 12, ["name"] = "mcl_core:stone"}, {["x"] = 3, ["y"] = 11, ["z"] = 13, ["name"] = "mcl_core:stone"}, {["x"] = 3, ["y"] = 11, ["z"] = 14, ["name"] = "mcl_core:stone"}, {["x"] = 3, ["y"] = 11, ["z"] = 15, ["name"] = "mcl_core:stone"}, {["x"] = 3, ["y"] = 11, ["z"] = 16, ["name"] = "mcl_core:stone"}, {["x"] = 3, ["y"] = 11, ["z"] = 17, ["name"] = "mcl_core:stone"}, {["x"] = 3, ["y"] = 11, ["z"] = 18, ["name"] = "mcl_core:stone_with_coal"}, {["x"] = 3, ["y"] = 11, ["z"] = 19, ["name"] = "mcl_core:stone"}, {["x"] = 3, ["y"] = 11, ["z"] = 20, ["name"] = "mcl_core:stone"}, {["x"] = 3, ["y"] = 11, ["z"] = 21, ["name"] = "mcl_core:stone"}, {["x"] = 3, ["y"] = 12, ["z"] = 0, ["name"] = "mcl_core:stone"}, {["x"] = 3, ["y"] = 12, ["z"] = 1, ["name"] = "mcl_core:stone"}, {["x"] = 3, ["y"] = 12, ["z"] = 2, ["name"] = "mcl_core:stone"}, {["x"] = 3, ["y"] = 12, ["z"] = 3, ["name"] = "mcl_core:stone"}, {["x"] = 3, ["y"] = 12, ["z"] = 4, ["name"] = "mcl_core:wood"}, {["x"] = 3, ["y"] = 12, ["z"] = 5, ["name"] = "mcl_core:wood"}, {["x"] = 3, ["y"] = 12, ["z"] = 6, ["name"] = "mcl_core:wood"}, {["x"] = 3, ["y"] = 12, ["z"] = 7, ["name"] = "mcl_core:stone"}, {["x"] = 3, ["y"] = 12, ["z"] = 8, ["name"] = "mcl_core:stone"}, {["x"] = 3, ["y"] = 12, ["z"] = 9, ["name"] = "mcl_core:stone"}, {["x"] = 3, ["y"] = 12, ["z"] = 10, ["name"] = "mcl_core:stone"}, {["x"] = 3, ["y"] = 12, ["z"] = 11, ["name"] = "mcl_core:cobble"}, {["x"] = 3, ["y"] = 12, ["z"] = 12, ["name"] = "mcl_core:stone"}, {["x"] = 3, ["y"] = 12, ["z"] = 13, ["name"] = "mcl_core:stone"}, {["x"] = 3, ["y"] = 12, ["z"] = 14, ["name"] = "mcl_core:stone"}, {["x"] = 3, ["y"] = 12, ["z"] = 15, ["name"] = "mcl_core:stone"}, {["x"] = 3, ["y"] = 12, ["z"] = 16, ["name"] = "mcl_core:stone"}, {["x"] = 3, ["y"] = 12, ["z"] = 17, ["name"] = "mcl_core:stone_with_coal"}, {["x"] = 3, ["y"] = 12, ["z"] = 18, ["name"] = "mcl_core:stone_with_coal"}, {["x"] = 3, ["y"] = 12, ["z"] = 19, ["name"] = "mcl_core:stone"}, {["x"] = 3, ["y"] = 12, ["z"] = 20, ["name"] = "mcl_core:stone"}, {["x"] = 3, ["y"] = 12, ["z"] = 21, ["name"] = "mcl_core:stone"}, {["x"] = 3, ["y"] = 13, ["z"] = 0, ["name"] = "mcl_core:stone"}, {["x"] = 3, ["y"] = 13, ["z"] = 1, ["name"] = "mcl_core:stone"}, {["x"] = 3, ["y"] = 13, ["z"] = 2, ["name"] = "mcl_core:stone"}, {["x"] = 3, ["y"] = 13, ["z"] = 3, ["name"] = "mcl_core:stone"},