5:return {{["x"] = 0, ["meta"] = {["fields"] = {}, ["inventory"] = {}}, ["y"] = 9, ["param1"] = 15, ["z"] = 50, ["name"] = "rainbow:stoneblock_white"}, {["x"] = 0, ["meta"] = {["fields"] = {}, ["inventory"] = {}}, ["y"] = 9, ["param1"] = 15, ["z"] = 51, ["name"] = "rainbow:stoneblock_white"}, {["x"] = 0, ["meta"] = {["fields"] = {}, ["inventory"] = {}}, ["y"] = 9, ["param1"] = 15, ["z"] = 52, ["name"] = "rainbow:stoneblock_white"}, {["x"] = 0, ["meta"] = {["fields"] = {}, ["inventory"] = {}}, ["y"] = 9, ["param1"] = 15, ["z"] = 53, ["name"] = "rainbow:stoneblock_white"}, {["x"] = 0, ["meta"] = {["fields"] = {}, ["inventory"] = {}}, ["y"] = 9, ["param1"] = 15, ["z"] = 54, ["name"] = "rainbow:stoneblock_white"}, {["x"] = 0, ["meta"] = {["fields"] = {}, ["inventory"] = {}}, ["y"] = 9, ["param1"] = 15, ["z"] = 55, ["name"] = "rainbow:stoneblock_white"}, {["x"] = 0, ["meta"] = {["fields"] = {}, ["inventory"] = {}}, ["y"] = 9, ["param1"] = 15, ["z"] = 56, ["name"] = "rainbow:stoneblock_white"}, {["x"] = 0, ["meta"] = {["fields"] = {}, ["inventory"] = {}}, ["y"] = 9, ["param1"] = 15, ["z"] = 57, ["name"] = "rainbow:stoneblock_white"}, {["x"] = 0, ["meta"] = {["fields"] = {}, ["inventory"] = {}}, ["y"] = 9, ["param1"] = 15, ["z"] = 58, ["name"] = "rainbow:stoneblock_white"}, {["x"] = 0, ["meta"] = {["fields"] = {}, ["inventory"] = {}}, ["y"] = 9, ["param1"] = 15, ["z"] = 59, ["name"] = "rainbow:stoneblock_white"}, {["x"] = 0, ["meta"] = {["fields"] = {}, ["inventory"] = {}}, ["y"] = 9, ["param1"] = 15, ["z"] = 60, ["name"] = "rainbow:stoneblock_white"}, {["x"] = 0, ["meta"] = {["fields"] = {}, ["inventory"] = {}}, ["y"] = 9, ["param1"] = 15, ["z"] = 61, ["name"] = "rainbow:stoneblock_white"}, {["x"] = 0, ["meta"] = {["fields"] = {}, ["inventory"] = {}}, ["y"] = 9, ["param1"] = 15, ["z"] = 62, ["name"] = "rainbow:stoneblock_white"}, {["x"] = 0, ["meta"] = {["fields"] = {}, ["inventory"] = {}}, ["y"] = 9, ["param1"] = 15, ["z"] = 63, ["name"] = "rainbow:stoneblock_white"}, {["x"] = 0, ["meta"] = {["fields"] = {}, ["inventory"] = {}}, ["y"] = 9, ["param1"] = 15, ["z"] = 64, ["name"] = "rainbow:stoneblock_white"}, {["x"] = 0, ["meta"] = {["fields"] = {}, ["inventory"] = {}}, ["y"] = 10, ["param1"] = 15, ["z"] = 50, ["name"] = "rainbow:stoneblock_white"}, {["x"] = 0, ["meta"] = {["fields"] = {}, ["inventory"] = {}}, ["y"] = 10, ["param1"] = 15, ["z"] = 51, ["name"] = "rainbow:stoneblock_white"}, {["x"] = 0, ["meta"] = {["fields"] = {}, ["inventory"] = {}}, ["y"] = 10, ["param1"] = 15, ["z"] = 52, ["name"] = "rainbow:stoneblock_white"}, {["x"] = 0, ["meta"] = {["fields"] = {}, ["inventory"] = {}}, ["y"] = 10, ["param1"] = 15, ["z"] = 53, ["name"] = "rainbow:stoneblock_white"}, {["x"] = 0, ["meta"] = {["fields"] = {}, ["inventory"] = {}}, ["y"] = 10, ["param1"] = 15, ["z"] = 54, ["name"] = "rainbow:stoneblock_white"}, {["x"] = 0, ["meta"] = {["fields"] = {}, ["inventory"] = {}}, ["y"] = 10, ["param1"] = 15, ["z"] = 55, ["name"] = "rainbow:stoneblock_white"}, {["x"] = 0, ["meta"] = {["fields"] = {}, ["inventory"] = {}}, ["y"] = 10, ["param1"] = 15, ["z"] = 56, ["name"] = "rainbow:stoneblock_white"}, {["x"] = 0, ["meta"] = {["fields"] = {}, ["inventory"] = {}}, ["y"] = 10, ["param1"] = 15, ["z"] = 57, ["name"] = "rainbow:stoneblock_white"}, {["x"] = 0, ["meta"] = {["fields"] = {}, ["inventory"] = {}}, ["y"] = 10, ["param1"] = 15, ["z"] = 58, ["name"] = "rainbow:stoneblock_white"}, {["x"] = 0, ["meta"] = {["fields"] = {}, ["inventory"] = {}}, ["y"] = 10, ["param1"] = 15, ["z"] = 59, ["name"] = "rainbow:stoneblock_white"}, {["x"] = 0, ["meta"] = {["fields"] = {}, ["inventory"] = {}}, ["y"] = 10, ["param1"] = 15, ["z"] = 60, ["name"] = "rainbow:stoneblock_white"}, {["x"] = 0, ["meta"] = {["fields"] = {}, ["inventory"] = {}}, ["y"] = 10, ["param1"] = 15, ["z"] = 61, ["name"] = "rainbow:stoneblock_white"}, {["x"] = 0, ["meta"] = {["fields"] = {}, ["inventory"] = {}}, ["y"] = 10, ["param1"] = 15, ["z"] = 62, ["name"] = "rainbow:stoneblock_white"}, {["x"] = 0, ["meta"] = {["fields"] = {}, ["inventory"] = {}}, ["y"] = 10, ["param1"] = 15, ["z"] = 63, ["name"] = "rainbow:stoneblock_white"}, {["x"] = 0, ["meta"] = {["fields"] = {}, ["inventory"] = {}}, ["y"] = 10, ["param1"] = 15, ["z"] = 64, ["name"] = "rainbow:stoneblock_white"}, {["x"] = 0, ["meta"] = {["fields"] = {}, ["inventory"] = {}}, ["y"] = 11, ["param1"] = 15, ["z"] = 50, ["name"] = "rainbow:stoneblock_white"}, {["x"] = 0, ["meta"] = {["fields"] = {}, ["inventory"] = {}}, ["y"] = 11, ["param1"] = 15, ["z"] = 51, ["name"] = "rainbow:stoneblock_white"}, {["x"] = 0, ["meta"] = {["fields"] = {}, ["inventory"] = {}}, ["y"] = 11, ["param1"] = 15, ["z"] = 52, ["name"] = "rainbow:stoneblock_white"}, {["x"] = 0, ["meta"] = {["fields"] = {}, ["inventory"] = {}}, ["y"] = 11, ["param1"] = 15, ["z"] = 53, ["name"] = "rainbow:stoneblock_white"}, {["x"] = 0, ["meta"] = {["fields"] = {}, ["inventory"] = {}}, ["y"] = 11, ["param1"] = 15, ["z"] = 54, ["name"] = "rainbow:stoneblock_white"}, {["x"] = 0, ["meta"] = {["fields"] = {}, ["inventory"] = {}}, ["y"] = 11, ["param1"] = 15, ["z"] = 55, ["name"] = "rainbow:stoneblock_white"}, {["x"] = 0, ["meta"] = {["fields"] = {}, ["inventory"] = {}}, ["y"] = 11, ["param1"] = 15, ["z"] = 56, ["name"] = "rainbow:stoneblock_white"}, {["x"] = 0, ["meta"] = {["fields"] = {}, ["inventory"] = {}}, ["y"] = 11, ["param1"] = 15, ["z"] = 57, ["name"] = "rainbow:stoneblock_white"}, {["x"] = 0, ["meta"] = {["fields"] = {}, ["inventory"] = {}}, ["y"] = 11, ["param1"] = 15, ["z"] = 58, ["name"] = "rainbow:stoneblock_white"}, {["x"] = 0, ["meta"] = {["fields"] = {}, ["inventory"] = {}}, ["y"] = 11, ["param1"] = 15, ["z"] = 59, ["name"] = "rainbow:stoneblock_white"}, {["x"] = 0, ["meta"] = {["fields"] = {}, ["inventory"] = {}}, ["y"] = 11, ["param1"] = 15, ["z"] = 60, ["name"] = "rainbow:stoneblock_white"}, {["x"] = 0, ["meta"] = {["fields"] = {}, ["inventory"] = {}}, ["y"] = 11, ["param1"] = 15, ["z"] = 61, ["name"] = "rainbow:stoneblock_white"}, {["x"] = 0, ["meta"] = {["fields"] = {}, ["inventory"] = {}}, ["y"] = 11, ["param1"] = 15, ["z"] = 62, ["name"] = "rainbow:stoneblock_white"}, {["x"] = 0, ["meta"] = {["fields"] = {}, ["inventory"] = {}}, ["y"] = 11, ["param1"] = 15, ["z"] = 63, ["name"] = "rainbow:stoneblock_white"}, {["x"] = 0, ["meta"] = {["fields"] = {}, ["inventory"] = {}}, ["y"] = 11, ["param1"] = 15, ["z"] = 64, ["name"] = "rainbow:stoneblock_white"}, {["x"] = 0, ["meta"] = {["fields"] = {}, ["inventory"] = {}}, ["y"] = 12, ["param1"] = 15, ["z"] = 50, ["name"] = "rainbow:stoneblock_white"}, {["x"] = 0, ["meta"] = {["fields"] = {}, ["inventory"] = {}}, ["y"] = 12, ["param1"] = 15, ["z"] = 51, ["name"] = "rainbow:stoneblock_white"}, {["x"] = 0, ["meta"] = {["fields"] = {}, ["inventory"] = {}}, ["y"] = 12, ["param1"] = 15, ["z"] = 52, ["name"] = "rainbow:stoneblock_white"}, {["x"] = 0, ["meta"] = {["fields"] = {}, ["inventory"] = {}}, ["y"] = 12, ["param1"] = 15, ["z"] = 53, ["name"] = "rainbow:stoneblock_white"}, {["x"] = 0, ["meta"] = {["fields"] = {}, ["inventory"] = {}}, ["y"] = 12, ["param1"] = 15, ["z"] = 54, ["name"] = "rainbow:stoneblock_white"}, {["x"] = 0, ["meta"] = {["fields"] = {}, ["inventory"] = {}}, ["y"] = 12, ["param1"] = 15, ["z"] = 55, ["name"] = "rainbow:stoneblock_white"}, {["x"] = 0, ["meta"] = {["fields"] = {}, ["inventory"] = {}}, ["y"] = 12, ["param1"] = 15, ["z"] = 56, ["name"] = "rainbow:stoneblock_white"}, {["x"] = 0, ["meta"] = {["fields"] = {}, ["inventory"] = {}}, ["y"] = 12, ["param1"] = 15, ["z"] = 57, ["name"] = "rainbow:stoneblock_white"}, {["x"] = 0, ["meta"] = {["fields"] = {}, ["inventory"] = {}}, ["y"] = 12, ["param1"] = 15, ["z"] = 58, ["name"] = "rainbow:stoneblock_white"}, {["x"] = 0, ["meta"] = {["fields"] = {}, ["inventory"] = {}}, ["y"] = 12, ["param1"] = 15, ["z"] = 59, ["name"] = "rainbow:stoneblock_white"}, {["x"] = 0, ["meta"] = {["fields"] = {}, ["inventory"] = {}}, ["y"] = 12, ["param1"] = 15, ["z"] = 60, ["name"] = "rainbow:stoneblock_white"}, {["x"] = 0, ["meta"] = {["fields"] = {}, ["inventory"] = {}}, ["y"] = 12, ["param1"] = 15, ["z"] = 61, ["name"] = "rainbow:stoneblock_white"}, {["x"] = 0, ["meta"] = {["fields"] = {}, ["inventory"] = {}}, ["y"] = 12, ["param1"] = 15, ["z"] = 62, ["name"] = "rainbow:stoneblock_white"}, {["x"] = 0, ["meta"] = {["fields"] = {}, ["inventory"] = {}}, ["y"] = 12, ["param1"] = 15, ["z"] = 63, ["name"] = "rainbow:stoneblock_white"}, {["x"] = 0, ["meta"] = {["fields"] = {}, ["inventory"] = {}}, ["y"] = 12, ["param1"] = 15, ["z"] = 64, ["name"] = "rainbow:stoneblock_white"}, {["x"] = 0, ["meta"] = {["fields"] = {}, ["inventory"] = {}}, ["y"] = 13, ["param1"] = 15, ["z"] = 50, ["name"] = "rainbow:stoneblock_white"}, {["x"] = 0, ["meta"] = {["fields"] = {}, ["inventory"] = {}}, ["y"] = 13, ["param1"] = 15, ["z"] = 51, ["name"] = "rainbow:stoneblock_white"}, {["x"] = 0, ["meta"] = {["fields"] = {}, ["inventory"] = {}}, ["y"] = 13, ["param1"] = 15, ["z"] = 52, ["name"] = "rainbow:stoneblock_white"}, {["x"] = 0, ["meta"] = {["fields"] = {}, ["inventory"] = {}}, ["y"] = 13, ["param1"] = 15, ["z"] = 53, ["name"] = "rainbow:stoneblock_white"}, {["x"] = 0, ["meta"] = {["fields"] = {}, ["inventory"] = {}}, ["y"] = 13, ["param1"] = 15, ["z"] = 54, ["name"] = "rainbow:stoneblock_white"}, {["x"] = 0, ["meta"] = {["fields"] = {}, ["inventory"] = {}}, ["y"] = 13, ["param1"] = 15, ["z"] = 55, ["name"] = "rainbow:stoneblock_white"}, {["x"] = 0, ["meta"] = {["fields"] = {}, ["inventory"] = {}}, ["y"] = 13, ["param1"] = 15, ["z"] = 56, ["name"] = "rainbow:stoneblock_white"}, {["x"] = 0, ["meta"] = {["fields"] = {}, ["inventory"] = {}}, ["y"] = 13, ["param1"] = 15, ["z"] = 57, ["name"] = "rainbow:stoneblock_white"}, {["x"] = 0, ["meta"] = {["fields"] = {}, ["inventory"] = {}}, ["y"] = 13, ["param1"] = 15, ["z"] = 58, ["name"] = "rainbow:stoneblock_white"}, {["x"] = 0, ["meta"] = {["fields"] = {}, ["inventory"] = {}}, ["y"] = 13, ["param1"] = 15, ["z"] = 59, ["name"] = "rainbow:stoneblock_white"}, {["x"] = 0, ["meta"] = {["fields"] = {}, ["inventory"] = {}}, ["y"] = 13, ["param1"] = 15, ["z"] = 60, ["name"] = "rainbow:stoneblock_white"}, {["x"] = 0, ["meta"] = {["fields"] = {}, ["inventory"] = {}}, ["y"] = 13, ["param1"] = 15, ["z"] = 61, ["name"] = "rainbow:stoneblock_white"}, {["x"] = 0, ["meta"] = {["fields"] = {}, ["inventory"] = {}}, ["y"] = 13, ["param1"] = 15, ["z"] = 62, ["name"] = "rainbow:stoneblock_white"}, {["x"] = 0, ["meta"] = {["fields"] = {}, ["inventory"] = {}}, ["y"] = 13, ["param1"] = 15, ["z"] = 63, ["name"] = "rainbow:stoneblock_white"}, {["x"] = 0, ["meta"] = {["fields"] = {}, ["inventory"] = {}}, ["y"] = 13, ["param1"] = 15, ["z"] = 64, ["name"] = "rainbow:stoneblock_white"}, {["x"] = 0, ["meta"] = {["fields"] = {}, ["inventory"] = {}}, ["y"] = 14, ["param1"] = 15, ["z"] = 50, ["name"] = "rainbow:stoneblock_white"}, {["x"] = 0, ["meta"] = {["fields"] = {}, ["inventory"] = {}}, ["y"] = 14, ["param1"] = 15, ["z"] = 51, ["name"] = "rainbow:stoneblock_white"}, {["x"] = 0, ["meta"] = {["fields"] = {}, ["inventory"] = {}}, ["y"] = 14, ["param1"] = 15, ["z"] = 52, ["name"] = "rainbow:stoneblock_white"}, {["x"] = 0, ["meta"] = {["fields"] = {}, ["inventory"] = {}}, ["y"] = 14, ["param1"] = 15, ["z"] = 53, ["name"] = "rainbow:stoneblock_white"}, {["x"] = 0, ["meta"] = {["fields"] = {}, ["inventory"] = {}}, ["y"] = 14, ["param1"] = 15, ["z"] = 54, ["name"] = "rainbow:stoneblock_white"}, {["x"] = 0, ["meta"] = {["fields"] = {}, ["inventory"] = {}}, ["y"] = 14, ["param1"] = 15, ["z"] = 55, ["name"] = "rainbow:stoneblock_white"}, {["x"] = 0, ["meta"] = {["fields"] = {}, ["inventory"] = {}}, ["y"] = 14, ["param1"] = 15, ["z"] = 56, ["name"] = "rainbow:stoneblock_white"}, {["x"] = 0, ["meta"] = {["fields"] = {}, ["inventory"] = {}}, ["y"] = 14, ["param1"] = 15, ["z"] = 57, ["name"] = "rainbow:stoneblock_white"}, {["x"] = 0, ["meta"] = {["fields"] = {}, ["inventory"] = {}}, ["y"] = 14, ["param1"] = 15, ["z"] = 58, ["name"] = "rainbow:stoneblock_white"}, {["x"] = 0, ["meta"] = {["fields"] = {}, ["inventory"] = {}}, ["y"] = 14, ["param1"] = 15, ["z"] = 59, ["name"] = "rainbow:stoneblock_white"}, {["x"] = 0, ["meta"] = {["fields"] = {}, ["inventory"] = {}}, ["y"] = 14, ["param1"] = 15, ["z"] = 60, ["name"] = "rainbow:stoneblock_white"}, {["x"] = 0, ["meta"] = {["fields"] = {}, ["inventory"] = {}}, ["y"] = 14, ["param1"] = 15, ["z"] = 61, ["name"] = "rainbow:stoneblock_white"}, {["x"] = 0, ["meta"] = {["fields"] = {}, ["inventory"] = {}}, ["y"] = 14, ["param1"] = 15, ["z"] = 62, ["name"] = "rainbow:stoneblock_white"}, {["x"] = 0, ["meta"] = {["fields"] = {}, ["inventory"] = {}}, ["y"] = 14, ["param1"] = 15, ["z"] = 63, ["name"] = "rainbow:stoneblock_white"}, {["x"] = 0, ["meta"] = {["fields"] = {}, ["inventory"] = {}}, ["y"] = 14, ["param1"] = 15, ["z"] = 64, ["name"] = "rainbow:stoneblock_white"}, {["x"] = 0, ["meta"] = {["fields"] = {}, ["inventory"] = {}}, ["y"] = 15, ["param1"] = 15, ["z"] = 50, ["name"] = "rainbow:stoneblock_white"}, {["x"] = 0, ["meta"] = {["fields"] = {}, ["inventory"] = {}}, ["y"] = 15, ["param1"] = 15, ["z"] = 51, ["name"] = "rainbow:stoneblock_white"}, {["x"] = 0, ["meta"] = {["fields"] = {}, ["inventory"] = {}}, ["y"] = 15, ["param1"] = 15, ["z"] = 52, ["name"] = "rainbow:stoneblock_white"}, {["x"] = 0, ["meta"] = {["fields"] = {}, ["inventory"] = {}}, ["y"] = 15, ["param1"] = 15, ["z"] = 53, ["name"] = "rainbow:stoneblock_white"}, {["x"] = 0, ["meta"] = {["fields"] = {}, ["inventory"] = {}}, ["y"] = 15, ["param1"] = 15, ["z"] = 54, ["name"] = "rainbow:stoneblock_white"}, {["x"] = 0, ["meta"] = {["fields"] = {}, ["inventory"] = {}}, ["y"] = 15, ["param1"] = 15, ["z"] = 55, ["name"] = "rainbow:stoneblock_white"}, {["x"] = 0, ["meta"] = {["fields"] = {}, ["inventory"] = {}}, ["y"] = 15, ["param1"] = 15, ["z"] = 56, ["name"] = "rainbow:stoneblock_white"}, {["x"] = 0, ["meta"] = {["fields"] = {}, ["inventory"] = {}}, ["y"] = 15, ["param1"] = 15, ["z"] = 57, ["name"] = "rainbow:stoneblock_white"}, {["x"] = 0, ["meta"] = {["fields"] = {}, ["inventory"] = {}}, ["y"] = 15, ["param1"] = 15, ["z"] = 58, ["name"] = "rainbow:stoneblock_white"}, {["x"] = 0, ["meta"] = {["fields"] = {}, ["inventory"] = {}}, ["y"] = 15, ["param1"] = 15, ["z"] = 59, ["name"] = "rainbow:stoneblock_white"}, {["x"] = 0, ["meta"] = {["fields"] = {}, ["inventory"] = {}}, ["y"] = 15, ["param1"] = 15, ["z"] = 60, ["name"] = "rainbow:stoneblock_white"}, {["x"] = 0, ["meta"] = {["fields"] = {}, ["inventory"] = {}}, ["y"] = 15, ["param1"] = 15, ["z"] = 61, ["name"] = "rainbow:stoneblock_white"}, {["x"] = 0, ["meta"] = {["fields"] = {}, ["inventory"] = {}}, ["y"] = 15, ["param1"] = 15, ["z"] = 62, ["name"] = "rainbow:stoneblock_white"}, {["x"] = 0, ["meta"] = {["fields"] = {}, ["inventory"] = {}}, ["y"] = 15, ["param1"] = 15, ["z"] = 63, ["name"] = "rainbow:stoneblock_white"}, {["x"] = 0, ["meta"] = {["fields"] = {}, ["inventory"] = {}}, ["y"] = 15, ["param1"] = 15, ["z"] = 64, ["name"] = "rainbow:stoneblock_white"}, {["x"] = 1, ["meta"] = {["fields"] = {}, ["inventory"] = {}}, ["y"] = 7, ["param1"] = 15, ["z"] = 50, ["name"] = "rainbow:stoneblock_white"}, {["x"] = 1, ["meta"] = {["fields"] = {}, ["inventory"] = {}}, ["y"] = 7, ["param1"] = 15, ["z"] = 51, ["name"] = "rainbow:stoneblock_white"}, {["x"] = 1, ["meta"] = {["fields"] = {}, ["inventory"] = {}}, ["y"] = 7, ["param1"] = 15, ["z"] = 52, ["name"] = "rainbow:stoneblock_white"}, {["x"] = 1, ["meta"] = {["fields"] = {}, ["inventory"] = {}}, ["y"] = 7, ["param1"] = 15, ["z"] = 53, ["name"] = "rainbow:stoneblock_white"}, {["x"] = 1, ["meta"] = {["fields"] = {}, ["inventory"] = {}}, ["y"] = 7, ["param1"] = 15, ["z"] = 54, ["name"] = "rainbow:stoneblock_white"}, {["x"] = 1, ["meta"] = {["fields"] = {}, ["inventory"] = {}}, ["y"] = 7, ["param1"] = 15, ["z"] = 55, ["name"] = "rainbow:stoneblock_white"}, {["x"] = 1, ["meta"] = {["fields"] = {}, ["inventory"] = {}}, ["y"] = 7, ["param1"] = 15, ["z"] = 56, ["name"] = "rainbow:stoneblock_white"}, {["x"] = 1, ["meta"] = {["fields"] = {}, ["inventory"] = {}}, ["y"] = 7, ["param1"] = 15, ["z"] = 57, ["name"] = "rainbow:stoneblock_white"}, {["x"] = 1, ["meta"] = {["fields"] = {}, ["inventory"] = {}}, ["y"] = 7, ["param1"] = 15, ["z"] = 58, ["name"] = "rainbow:stoneblock_white"}, {["x"] = 1, ["meta"] = {["fields"] = {}, ["inventory"] = {}}, ["y"] = 7, ["param1"] = 15, ["z"] = 59, ["name"] = "rainbow:stoneblock_white"}, {["x"] = 1, ["meta"] = {["fields"] = {}, ["inventory"] = {}}, ["y"] = 7, ["param1"] = 15, ["z"] = 60, ["name"] = "rainbow:stoneblock_white"}, {["x"] = 1, ["meta"] = {["fields"] = {}, ["inventory"] = {}}, ["y"] = 7, ["param1"] = 15, ["z"] = 61, ["name"] = "rainbow:stoneblock_white"}, {["x"] = 1, ["meta"] = {["fields"] = {}, ["inventory"] = {}}, ["y"] = 7, ["param1"] = 15, ["z"] = 62, ["name"] = "rainbow:stoneblock_white"}, {["x"] = 1, ["meta"] = {["fields"] = {}, ["inventory"] = {}}, ["y"] = 7, ["param1"] = 15, ["z"] = 63, ["name"] = "rainbow:stoneblock_white"}, {["x"] = 1, ["meta"] = {["fields"] = {}, ["inventory"] = {}}, ["y"] = 7, ["param1"] = 15, ["z"] = 64, ["name"] = "rainbow:stoneblock_white"}, {["x"] = 1, ["meta"] = {["fields"] = {}, ["inventory"] = {}}, ["y"] = 8, ["param1"] = 15, ["z"] = 50, ["name"] = "rainbow:stoneblock_white"}, {["x"] = 1, ["meta"] = {["fields"] = {}, ["inventory"] = {}}, ["y"] = 8, ["param1"] = 15, ["z"] = 51, ["name"] = "rainbow:stoneblock_white"}, {["x"] = 1, ["meta"] = {["fields"] = {}, ["inventory"] = {}}, ["y"] = 8, ["param1"] = 15, ["z"] = 52, ["name"] = "rainbow:stoneblock_white"}, {["x"] = 1, ["meta"] = {["fields"] = {}, ["inventory"] = {}}, ["y"] = 8, ["param1"] = 15, ["z"] = 53, ["name"] = "rainbow:stoneblock_white"}, {["x"] = 1, ["meta"] = {["fields"] = {}, ["inventory"] = {}}, ["y"] = 8, ["param1"] = 15, ["z"] = 54, ["name"] = "rainbow:stoneblock_white"}, {["x"] = 1, ["meta"] = {["fields"] = {}, ["inventory"] = {}}, ["y"] = 8, ["param1"] = 15, ["z"] = 55, ["name"] = "rainbow:stoneblock_white"}, {["x"] = 1, ["meta"] = {["fields"] = {}, ["inventory"] = {}}, ["y"] = 8, ["param1"] = 15, ["z"] = 56, ["name"] = "rainbow:stoneblock_white"}, {["x"] = 1, ["meta"] = {["fields"] = {}, ["inventory"] = {}}, ["y"] = 8, ["param1"] = 15, ["z"] = 57, ["name"] = "rainbow:stoneblock_white"}, {["x"] = 1, ["meta"] = {["fields"] = {}, ["inventory"] = {}}, ["y"] = 8, ["param1"] = 15, ["z"] = 58, ["name"] = "rainbow:stoneblock_white"}, {["x"] = 1, ["meta"] = {["fields"] = {}, ["inventory"] = {}}, ["y"] = 8, ["param1"] = 15, ["z"] = 59, ["name"] = "rainbow:stoneblock_white"}, {["x"] = 1, ["meta"] = {["fields"] = {}, ["inventory"] = {}}, ["y"] = 8, ["param1"] = 15, ["z"] = 60, ["name"] = "rainbow:stoneblock_white"}, {["x"] = 1, ["meta"] = {["fields"] = {}, ["inventory"] = {}}, ["y"] = 8, ["param1"] = 15, ["z"] = 61, ["name"] = "rainbow:stoneblock_white"}, {["x"] = 1, ["meta"] = {["fields"] = {}, ["inventory"] = {}}, ["y"] = 8, ["param1"] = 15, ["z"] = 62, ["name"] = "rainbow:stoneblock_white"}, {["x"] = 1, ["meta"] = {["fields"] = {}, ["inventory"] = {}}, ["y"] = 8, ["param1"] = 15, ["z"] = 63, ["name"] = "rainbow:stoneblock_white"}, {["x"] = 1, ["meta"] = {["fields"] = {}, ["inventory"] = {}}, ["y"] = 8, ["param1"] = 15, ["z"] = 64, ["name"] = "rainbow:stoneblock_white"}, {["x"] = 1, ["meta"] = {["fields"] = {}, ["inventory"] = {}}, ["y"] = 9, ["param1"] = 11, ["z"] = 52, ["name"] = "rainbow:stoneblock_white"}, {["x"] = 1, ["meta"] = {["fields"] = {}, ["inventory"] = {}}, ["y"] = 9, ["param1"] = 11, ["z"] = 62, ["name"] = "rainbow:stoneblock_white"}, {["x"] = 1, ["meta"] = {["fields"] = {}, ["inventory"] = {}}, ["y"] = 10, ["param1"] = 11, ["z"] = 52, ["name"] = "rainbow:stoneblock_white"}, {["x"] = 1, ["meta"] = {["fields"] = {}, ["inventory"] = {}}, ["y"] = 10, ["param1"] = 11, ["z"] = 62, ["name"] = "rainbow:stoneblock_white"}, {["x"] = 1, ["meta"] = {["fields"] = {}, ["inventory"] = {}}, ["y"] = 11, ["param1"] = 11, ["z"] = 52, ["name"] = "rainbow:stoneblock_white"}, {["x"] = 1, ["meta"] = {["fields"] = {}, ["inventory"] = {}}, ["y"] = 11, ["param1"] = 11, ["z"] = 62, ["name"] = "rainbow:stoneblock_white"}, {["x"] = 1, ["meta"] = {["fields"] = {}, ["inventory"] = {}}, ["y"] = 12, ["param1"] = 11, ["z"] = 52, ["name"] = "rainbow:stoneblock_white"}, {["x"] = 1, ["meta"] = {["fields"] = {}, ["inventory"] = {}}, ["y"] = 12, ["param1"] = 11, ["z"] = 62, ["name"] = "rainbow:stoneblock_white"}, {["x"] = 1, ["meta"] = {["fields"] = {}, ["inventory"] = {}}, ["y"] = 13, ["param1"] = 11, ["z"] = 52, ["name"] = "rainbow:stoneblock_white"}, {["x"] = 1, ["meta"] = {["fields"] = {}, ["inventory"] = {}}, ["y"] = 13, ["param1"] = 11, ["z"] = 62, ["name"] = "rainbow:stoneblock_white"}, {["x"] = 1, ["meta"] = {["fields"] = {}, ["inventory"] = {}}, ["y"] = 14, ["param1"] = 11, ["z"] = 52, ["name"] = "rainbow:stoneblock_white"}, {["x"] = 1, ["meta"] = {["fields"] = {}, ["inventory"] = {}}, ["y"] = 14, ["param1"] = 11, ["z"] = 62, ["name"] = "rainbow:stoneblock_white"}, {["x"] = 1, ["meta"] = {["fields"] = {}, ["inventory"] = {}}, ["y"] = 15, ["param1"] = 11, ["z"] = 52, ["name"] = "rainbow:stoneblock_white"}, {["x"] = 1, ["meta"] = {["fields"] = {}, ["inventory"] = {}}, ["y"] = 15, ["param1"] = 11, ["z"] = 62, ["name"] = "rainbow:stoneblock_white"}, {["x"] = 1, ["meta"] = {["fields"] = {}, ["inventory"] = {}}, ["y"] = 16, ["param1"] = 15, ["z"] = 50, ["name"] = "rainbow:stoneblock_white"}, {["x"] = 1, ["meta"] = {["fields"] = {}, ["inventory"] = {}}, ["y"] = 16, ["param1"] = 15, ["z"] = 51, ["name"] = "rainbow:stoneblock_white"}, {["x"] = 1, ["meta"] = {["fields"] = {}, ["inventory"] = {}}, ["y"] = 16, ["param1"] = 15, ["z"] = 52, ["name"] = "rainbow:stoneblock_white"}, {["x"] = 1, ["meta"] = {["fields"] = {}, ["inventory"] = {}}, ["y"] = 16, ["param1"] = 15, ["z"] = 53, ["name"] = "rainbow:stoneblock_white"}, {["x"] = 1, ["meta"] = {["fields"] = {}, ["inventory"] = {}}, ["y"] = 16, ["param1"] = 15, ["z"] = 54, ["name"] = "rainbow:stoneblock_white"}, {["x"] = 1, ["meta"] = {["fields"] = {}, ["inventory"] = {}}, ["y"] = 16, ["param1"] = 15, ["z"] = 55, ["name"] = "rainbow:stoneblock_white"}, {["x"] = 1, ["meta"] = {["fields"] = {}, ["inventory"] = {}}, ["y"] = 16, ["param1"] = 15, ["z"] = 56, ["name"] = "rainbow:stoneblock_white"}, {["x"] = 1, ["meta"] = {["fields"] = {}, ["inventory"] = {}}, ["y"] = 16, ["param1"] = 15, ["z"] = 57, ["name"] = "rainbow:stoneblock_white"}, {["x"] = 1, ["meta"] = {["fields"] = {}, ["inventory"] = {}}, ["y"] = 16, ["param1"] = 15, ["z"] = 58, ["name"] = "rainbow:stoneblock_white"}, {["x"] = 1, ["meta"] = {["fields"] = {}, ["inventory"] = {}}, ["y"] = 16, ["param1"] = 15, ["z"] = 59, ["name"] = "rainbow:stoneblock_white"}, {["x"] = 1, ["meta"] = {["fields"] = {}, ["inventory"] = {}}, ["y"] = 16, ["param1"] = 15, ["z"] = 60, ["name"] = "rainbow:stoneblock_white"}, {["x"] = 1, ["meta"] = {["fields"] = {}, ["inventory"] = {}}, ["y"] = 16, ["param1"] = 15, ["z"] = 61, ["name"] = "rainbow:stoneblock_white"}, {["x"] = 1, ["meta"] = {["fields"] = {}, ["inventory"] = {}}, ["y"] = 16, ["param1"] = 15, ["z"] = 62, ["name"] = "rainbow:stoneblock_white"}, {["x"] = 1, ["meta"] = {["fields"] = {}, ["inventory"] = {}}, ["y"] = 16, ["param1"] = 15, ["z"] = 63, ["name"] = "rainbow:stoneblock_white"}, {["x"] = 1, ["meta"] = {["fields"] = {}, ["inventory"] = {}}, ["y"] = 16, ["param1"] = 15, ["z"] = 64, ["name"] = "rainbow:stoneblock_white"}, {["x"] = 1, ["meta"] = {["fields"] = {}, ["inventory"] = {}}, ["y"] = 17, ["param1"] = 15, ["z"] = 50, ["name"] = "rainbow:stoneblock_white"}, {["x"] = 1, ["meta"] = {["fields"] = {}, ["inventory"] = {}}, ["y"] = 17, ["param1"] = 15, ["z"] = 51, ["name"] = "rainbow:stoneblock_white"}, {["x"] = 1, ["meta"] = {["fields"] = {}, ["inventory"] = {}}, ["y"] = 17, ["param1"] = 15, ["z"] = 52, ["name"] = "rainbow:stoneblock_white"}, {["x"] = 1, ["meta"] = {["fields"] = {}, ["inventory"] = {}}, ["y"] = 17, ["param1"] = 15, ["z"] = 53, ["name"] = "rainbow:stoneblock_white"}, {["x"] = 1, ["meta"] = {["fields"] = {}, ["inventory"] = {}}, ["y"] = 17, ["param1"] = 15, ["z"] = 54, ["name"] = "rainbow:stoneblock_white"}, {["x"] = 1, ["meta"] = {["fields"] = {}, ["inventory"] = {}}, ["y"] = 17, ["param1"] = 15, ["z"] = 55, ["name"] = "rainbow:stoneblock_white"}, {["x"] = 1, ["meta"] = {["fields"] = {}, ["inventory"] = {}}, ["y"] = 17, ["param1"] = 15, ["z"] = 56, ["name"] = "rainbow:stoneblock_white"}, {["x"] = 1, ["meta"] = {["fields"] = {}, ["inventory"] = {}}, ["y"] = 17, ["param1"] = 15, ["z"] = 57, ["name"] = "rainbow:stoneblock_white"}, {["x"] = 1, ["meta"] = {["fields"] = {}, ["inventory"] = {}}, ["y"] = 17, ["param1"] = 15, ["z"] = 58, ["name"] = "rainbow:stoneblock_white"}, {["x"] = 1, ["meta"] = {["fields"] = {}, ["inventory"] = {}}, ["y"] = 17, ["param1"] = 15, ["z"] = 59, ["name"] = "rainbow:stoneblock_white"}, {["x"] = 1, ["meta"] = {["fields"] = {}, ["inventory"] = {}}, ["y"] = 17, ["param1"] = 15, ["z"] = 60, ["name"] = "rainbow:stoneblock_white"}, {["x"] = 1, ["meta"] = {["fields"] = {}, ["inventory"] = {}}, ["y"] = 17, ["param1"] = 15, ["z"] = 61, ["name"] = "rainbow:stoneblock_white"}, {["x"] = 1, ["meta"] = {["fields"] = {}, ["inventory"] = {}}, ["y"] = 17, ["param1"] = 15, ["z"] = 62, ["name"] = "rainbow:stoneblock_white"}, {["x"] = 1, ["meta"] = {["fields"] = {}, ["inventory"] = {}}, ["y"] = 17, ["param1"] = 15, ["z"] = 63, ["name"] = "rainbow:stoneblock_white"}, {["x"] = 1, ["meta"] = {["fields"] = {}, ["inventory"] = {}}, ["y"] = 17, ["param1"] = 15, ["z"] = 64, ["name"] = "rainbow:stoneblock_white"}, {["x"] = 2, ["meta"] = {["fields"] = {}, ["inventory"] = {}}, ["y"] = 5, ["param1"] = 15, ["z"] = 50, ["name"] = "rainbow:stoneblock_white"}, {["x"] = 2, ["meta"] = {["fields"] = {}, ["inventory"] = {}}, ["y"] = 5, ["param1"] = 15, ["z"] = 51, ["name"] = "rainbow:stoneblock_white"}, {["x"] = 2, ["meta"] = {["fields"] = {}, ["inventory"] = {}}, ["y"] = 5, ["param1"] = 15, ["z"] = 52, ["name"] = "rainbow:stoneblock_white"}, {["x"] = 2, ["meta"] = {["fields"] = {}, ["inventory"] = {}}, ["y"] = 5, ["param1"] = 15, ["z"] = 53, ["name"] = "rainbow:stoneblock_white"}, {["x"] = 2, ["meta"] = {["fields"] = {}, ["inventory"] = {}}, ["y"] = 5, ["param1"] = 15, ["z"] = 54, ["name"] = "rainbow:stoneblock_white"}, {["x"] = 2, ["meta"] = {["fields"] = {}, ["inventory"] = {}}, ["y"] = 5, ["param1"] = 15, ["z"] = 55, ["name"] = "rainbow:stoneblock_white"}, {["x"] = 2, ["meta"] = {["fields"] = {}, ["inventory"] = {}}, ["y"] = 5, ["param1"] = 15, ["z"] = 56, ["name"] = "rainbow:stoneblock_white"}, {["x"] = 2, ["meta"] = {["fields"] = {}, ["inventory"] = {}}, ["y"] = 5, ["param1"] = 15, ["z"] = 57, ["name"] = "rainbow:stoneblock_white"}, {["x"] = 2, ["meta"] = {["fields"] = {}, ["inventory"] = {}}, ["y"] = 5, ["param1"] = 15, ["z"] = 58, ["name"] = "rainbow:stoneblock_white"}, {["x"] = 2, ["meta"] = {["fields"] = {}, ["inventory"] = {}}, ["y"] = 5, ["param1"] = 15, ["z"] = 59, ["name"] = "rainbow:stoneblock_white"}, {["x"] = 2, ["meta"] = {["fields"] = {}, ["inventory"] = {}}, ["y"] = 5, ["param1"] = 15, ["z"] = 60, ["name"] = "rainbow:stoneblock_white"}, {["x"] = 2, ["meta"] = {["fields"] = {}, ["inventory"] = {}}, ["y"] = 5, ["param1"] = 15, ["z"] = 61, ["name"] = "rainbow:stoneblock_white"}, {["x"] = 2, ["meta"] = {["fields"] = {}, ["inventory"] = {}}, ["y"] = 5, ["param1"] = 15, ["z"] = 62, ["name"] = "rainbow:stoneblock_white"}, {["x"] = 2, ["meta"] = {["fields"] = {}, ["inventory"] = {}}, ["y"] = 5, ["param1"] = 15, ["z"] = 63, ["name"] = "rainbow:stoneblock_white"}, {["x"] = 2, ["meta"] = {["fields"] = {}, ["inventory"] = {}}, ["y"] = 5, ["param1"] = 15, ["z"] = 64, ["name"] = "rainbow:stoneblock_white"}, {["x"] = 2, ["meta"] = {["fields"] = {}, ["inventory"] = {}}, ["y"] = 6, ["param1"] = 15, ["z"] = 50, ["name"] = "rainbow:stoneblock_white"}, {["x"] = 2, ["meta"] = {["fields"] = {}, ["inventory"] = {}}, ["y"] = 6, ["param1"] = 15, ["z"] = 51, ["name"] = "rainbow:stoneblock_white"}, {["x"] = 2, ["meta"] = {["fields"] = {}, ["inventory"] = {}}, ["y"] = 6, ["param1"] = 15, ["z"] = 52, ["name"] = "rainbow:stoneblock_white"}, {["x"] = 2, ["meta"] = {["fields"] = {}, ["inventory"] = {}}, ["y"] = 6, ["param1"] = 15, ["z"] = 53, ["name"] = "rainbow:stoneblock_white"}, {["x"] = 2, ["meta"] = {["fields"] = {}, ["inventory"] = {}}, ["y"] = 6, ["param1"] = 15, ["z"] = 54, ["name"] = "rainbow:stoneblock_white"}, {["x"] = 2, ["meta"] = {["fields"] = {}, ["inventory"] = {}}, ["y"] = 6, ["param1"] = 15, ["z"] = 55, ["name"] = "rainbow:stoneblock_white"}, {["x"] = 2, ["meta"] = {["fields"] = {}, ["inventory"] = {}}, ["y"] = 6, ["param1"] = 15, ["z"] = 56, ["name"] = "rainbow:stoneblock_white"}, {["x"] = 2, ["meta"] = {["fields"] = {}, ["inventory"] = {}}, ["y"] = 6, ["param1"] = 15, ["z"] = 57, ["name"] = "rainbow:stoneblock_white"}, {["x"] = 2, ["meta"] = {["fields"] = {}, ["inventory"] = {}}, ["y"] = 6, ["param1"] = 15, ["z"] = 58, ["name"] = "rainbow:stoneblock_white"}, {["x"] = 2, ["meta"] = {["fields"] = {}, ["inventory"] = {}}, ["y"] = 6, ["param1"] = 15, ["z"] = 59, ["name"] = "rainbow:stoneblock_white"}, {["x"] = 2, ["meta"] = {["fields"] = {}, ["inventory"] = {}}, ["y"] = 6, ["param1"] = 15, ["z"] = 60, ["name"] = "rainbow:stoneblock_white"}, {["x"] = 2, ["meta"] = {["fields"] = {}, ["inventory"] = {}}, ["y"] = 6, ["param1"] = 15, ["z"] = 61, ["name"] = "rainbow:stoneblock_white"}, {["x"] = 2, ["meta"] = {["fields"] = {}, ["inventory"] = {}}, ["y"] = 6, ["param1"] = 15, ["z"] = 62, ["name"] = "rainbow:stoneblock_white"}, {["x"] = 2, ["meta"] = {["fields"] = {}, ["inventory"] = {}}, ["y"] = 6, ["param1"] = 15, ["z"] = 63, ["name"] = "rainbow:stoneblock_white"}, {["x"] = 2, ["meta"] = {["fields"] = {}, ["inventory"] = {}}, ["y"] = 6, ["param1"] = 15, ["z"] = 64, ["name"] = "rainbow:stoneblock_white"}, {["x"] = 2, ["meta"] = {["fields"] = {}, ["inventory"] = {}}, ["y"] = 7, ["param1"] = 11, ["z"] = 52, ["name"] = "rainbow:stoneblock_white"}, {["x"] = 2, ["meta"] = {["fields"] = {}, ["inventory"] = {}}, ["y"] = 7, ["param1"] = 10, ["z"] = 62, ["name"] = "rainbow:stoneblock_white"}, {["x"] = 2, ["meta"] = {["fields"] = {}, ["inventory"] = {}}, ["y"] = 8, ["param1"] = 11, ["z"] = 52, ["name"] = "rainbow:stoneblock_white"}, {["x"] = 2, ["meta"] = {["fields"] = {}, ["inventory"] = {}}, ["y"] = 8, ["param1"] = 10, ["z"] = 62, ["name"] = "rainbow:stoneblock_white"}, {["x"] = 2, ["meta"] = {["fields"] = {}, ["inventory"] = {}}, ["y"] = 9, ["param1"] = 15, ["z"] = 48, ["name"] = "rainbow:stoneblock_white"}, {["x"] = 2, ["meta"] = {["fields"] = {}, ["inventory"] = {}}, ["y"] = 9, ["param1"] = 15, ["z"] = 49, ["name"] = "rainbow:stoneblock_white"}, {["x"] = 2, ["meta"] = {["fields"] = {}, ["inventory"] = {}}, ["y"] = 9, ["param1"] = 13, ["z"] = 50, ["name"] = "rainbow:stoneblock_white"}, {["x"] = 2, ["meta"] = {["fields"] = {}, ["inventory"] = {}}, ["y"] = 9, ["param1"] = 12, ["z"] = 51, ["name"] = "rainbow:stoneblock_white"}, {["x"] = 2, ["meta"] = {["fields"] = {}, ["inventory"] = {}}, ["y"] = 9, ["param1"] = 11, ["z"] = 52, ["name"] = "rainbow:stoneblock_white"}, {["x"] = 2, ["meta"] = {["fields"] = {}, ["inventory"] = {}}, ["y"] = 9, ["param1"] = 27, ["z"] = 62, ["name"] = "rainbow:stoneblock_white"}, {["x"] = 2, ["meta"] = {["fields"] = {}, ["inventory"] = {}}, ["y"] = 9, ["param1"] = 28, ["z"] = 63, ["name"] = "rainbow:stoneblock_white"}, {["x"] = 2, ["meta"] = {["fields"] = {}, ["inventory"] = {}}, ["y"] = 9, ["param1"] = 29, ["z"] = 64, ["name"] = "rainbow:stoneblock_white"}, {["x"] = 2, ["meta"] = {["fields"] = {}, ["inventory"] = {}}, ["y"] = 9, ["param1"] = 31, ["z"] = 65, ["name"] = "rainbow:stoneblock_white"}, {["x"] = 2, ["meta"] = {["fields"] = {}, ["inventory"] = {}}, ["y"] = 9, ["param1"] = 47, ["z"] = 66, ["name"] = "rainbow:stoneblock_white"}, {["x"] = 2, ["meta"] = {["fields"] = {}, ["inventory"] = {}}, ["y"] = 10, ["param1"] = 15, ["z"] = 48, ["name"] = "rainbow:stoneblock_white"}, {["x"] = 2, ["meta"] = {["fields"] = {}, ["inventory"] = {}}, ["y"] = 10, ["param1"] = 15, ["z"] = 49, ["name"] = "rainbow:stoneblock_white"}, {["x"] = 2, ["meta"] = {["fields"] = {}, ["inventory"] = {}}, ["y"] = 10, ["param1"] = 13, ["z"] = 50, ["name"] = "rainbow:stoneblock_white"}, {["x"] = 2, ["meta"] = {["fields"] = {}, ["inventory"] = {}}, ["y"] = 10, ["param1"] = 12, ["z"] = 51, ["name"] = "rainbow:stoneblock_white"}, {["x"] = 2, ["meta"] = {["fields"] = {}, ["inventory"] = {}}, ["y"] = 10, ["param1"] = 11, ["z"] = 52, ["name"] = "rainbow:stoneblock_white"}, {["x"] = 2, ["meta"] = {["fields"] = {}, ["inventory"] = {}}, ["y"] = 10, ["param1"] = 43, ["z"] = 62, ["name"] = "rainbow:stoneblock_white"}, {["x"] = 2, ["meta"] = {["fields"] = {}, ["inventory"] = {}}, ["y"] = 10, ["param1"] = 44, ["z"] = 63, ["name"] = "rainbow:stoneblock_white"}, {["x"] = 2, ["meta"] = {["fields"] = {}, ["inventory"] = {}}, ["y"] = 10, ["param1"] = 45, ["z"] = 64, ["name"] = "rainbow:stoneblock_white"}, {["x"] = 2, ["meta"] = {["fields"] = {}, ["inventory"] = {}}, ["y"] = 10, ["param1"] = 47, ["z"] = 65, ["name"] = "rainbow:stoneblock_white"}, {["x"] = 2, ["meta"] = {["fields"] = {}, ["inventory"] = {}}, ["y"] = 10, ["param1"] = 63, ["z"] = 66, ["name"] = "rainbow:stoneblock_white"}, {["x"] = 2, ["meta"] = {["fields"] = {}, ["inventory"] = {}}, ["y"] = 11, ["param1"] = 15, ["z"] = 48, ["name"] = "rainbow:stoneblock_white"}, {["x"] = 2, ["meta"] = {["fields"] = {}, ["inventory"] = {}}, ["y"] = 11, ["param1"] = 15, ["z"] = 49, ["name"] = "rainbow:stoneblock_white"}, {["x"] = 2, ["meta"] = {["fields"] = {}, ["inventory"] = {}}, ["y"] = 11, ["param1"] = 13, ["z"] = 50, ["name"] = "rainbow:stoneblock_white"}, {["x"] = 2, ["meta"] = {["fields"] = {}, ["inventory"] = {}}, ["y"] = 11, ["param1"] = 12, ["z"] = 51, ["name"] = "rainbow:stoneblock_white"}, {["x"] = 2, ["meta"] = {["fields"] = {}, ["inventory"] = {}}, ["y"] = 11, ["param1"] = 11, ["z"] = 52, ["name"] = "rainbow:stoneblock_white"}, {["x"] = 2, ["meta"] = {["fields"] = {}, ["inventory"] = {}}, ["y"] = 11, ["param1"] = 59, ["z"] = 62, ["name"] = "rainbow:stoneblock_white"}, {["x"] = 2, ["meta"] = {["fields"] = {}, ["inventory"] = {}}, ["y"] = 11, ["param1"] = 60, ["z"] = 63, ["name"] = "rainbow:stoneblock_white"}, {["x"] = 2, ["meta"] = {["fields"] = {}, ["inventory"] = {}}, ["y"] = 11, ["param1"] = 61, ["z"] = 64, ["name"] = "rainbow:stoneblock_white"}, {["x"] = 2, ["meta"] = {["fields"] = {}, ["inventory"] = {}}, ["y"] = 11, ["param1"] = 63, ["z"] = 65, ["name"] = "rainbow:stoneblock_white"}, {["x"] = 2, ["meta"] = {["fields"] = {}, ["inventory"] = {}}, ["y"] = 11, ["param1"] = 79, ["z"] = 66, ["name"] = "rainbow:stoneblock_white"}, {["x"] = 2, ["meta"] = {["fields"] = {}, ["inventory"] = {}}, ["y"] = 12, ["param1"] = 15, ["z"] = 48, ["name"] = "rainbow:stoneblock_white"}, {["x"] = 2, ["meta"] = {["fields"] = {}, ["inventory"] = {}}, ["y"] = 12, ["param1"] = 15, ["z"] = 49, ["name"] = "rainbow:stoneblock_white"}, {["x"] = 2, ["meta"] = {["fields"] = {}, ["inventory"] = {}}, ["y"] = 12, ["param1"] = 13, ["z"] = 50, ["name"] = "rainbow:stoneblock_white"}, {["x"] = 2, ["meta"] = {["fields"] = {}, ["inventory"] = {}}, ["y"] = 12, ["param1"] = 12, ["z"] = 51, ["name"] = "rainbow:stoneblock_white"}, {["x"] = 2, ["meta"] = {["fields"] = {}, ["inventory"] = {}}, ["y"] = 12, ["param1"] = 11, ["z"] = 52, ["name"] = "rainbow:stoneblock_white"}, {["x"] = 2, ["meta"] = {["fields"] = {}, ["inventory"] = {}}, ["y"] = 12, ["param1"] = 75, ["z"] = 62, ["name"] = "rainbow:stoneblock_white"}, {["x"] = 2, ["meta"] = {["fields"] = {}, ["inventory"] = {}}, ["y"] = 12, ["param1"] = 76, ["z"] = 63, ["name"] = "rainbow:stoneblock_white"}, {["x"] = 2, ["meta"] = {["fields"] = {}, ["inventory"] = {}}, ["y"] = 12, ["param1"] = 77, ["z"] = 64, ["name"] = "rainbow:stoneblock_white"}, {["x"] = 2, ["meta"] = {["fields"] = {}, ["inventory"] = {}}, ["y"] = 12, ["param1"] = 79, ["z"] = 65, ["name"] = "rainbow:stoneblock_white"}, {["x"] = 2, ["meta"] = {["fields"] = {}, ["inventory"] = {}}, ["y"] = 12, ["param1"] = 79, ["z"] = 66, ["name"] = "rainbow:stoneblock_white"}, {["x"] = 2, ["meta"] = {["fields"] = {}, ["inventory"] = {}}, ["y"] = 13, ["param1"] = 15, ["z"] = 48, ["name"] = "rainbow:stoneblock_white"}, {["x"] = 2, ["meta"] = {["fields"] = {}, ["inventory"] = {}}, ["y"] = 13, ["param1"] = 15, ["z"] = 49, ["name"] = "rainbow:stoneblock_white"}, {["x"] = 2, ["meta"] = {["fields"] = {}, ["inventory"] = {}}, ["y"] = 13, ["param1"] = 13, ["z"] = 50, ["name"] = "rainbow:stoneblock_white"}, {["x"] = 2, ["meta"] = {["fields"] = {}, ["inventory"] = {}}, ["y"] = 13, ["param1"] = 12, ["z"] = 51, ["name"] = "rainbow:stoneblock_white"}, {["x"] = 2, ["meta"] = {["fields"] = {}, ["inventory"] = {}}, ["y"] = 13, ["param1"] = 11, ["z"] = 52, ["name"] = "rainbow:stoneblock_white"}, {["x"] = 2, ["meta"] = {["fields"] = {}, ["inventory"] = {}}, ["y"] = 13, ["param1"] = 59, ["z"] = 62, ["name"] = "rainbow:stoneblock_white"}, {["x"] = 2, ["meta"] = {["fields"] = {}, ["inventory"] = {}}, ["y"] = 13, ["param1"] = 60, ["z"] = 63, ["name"] = "rainbow:stoneblock_white"}, {["x"] = 2, ["meta"] = {["fields"] = {}, ["inventory"] = {}}, ["y"] = 13, ["param1"] = 61, ["z"] = 64, ["name"] = "rainbow:stoneblock_white"}, {["x"] = 2, ["meta"] = {["fields"] = {}, ["inventory"] = {}}, ["y"] = 13, ["param1"] = 63, ["z"] = 65, ["name"] = "rainbow:stoneblock_white"}, {["x"] = 2, ["meta"] = {["fields"] = {}, ["inventory"] = {}}, ["y"] = 13, ["param1"] = 63, ["z"] = 66, ["name"] = "rainbow:stoneblock_white"}, {["x"] = 2, ["meta"] = {["fields"] = {}, ["inventory"] = {}}, ["y"] = 14, ["param1"] = 15, ["z"] = 48, ["name"] = "rainbow:stoneblock_white"}, {["x"] = 2, ["meta"] = {["fields"] = {}, ["inventory"] = {}}, ["y"] = 14, ["param1"] = 15, ["z"] = 49, ["name"] = "rainbow:stoneblock_white"}, {["x"] = 2, ["meta"] = {["fields"] = {}, ["inventory"] = {}}, ["y"] = 14, ["param1"] = 13, ["z"] = 50, ["name"] = "rainbow:stoneblock_white"}, {["x"] = 2, ["meta"] = {["fields"] = {}, ["inventory"] = {}}, ["y"] = 14, ["param1"] = 12, ["z"] = 51, ["name"] = "rainbow:stoneblock_white"}, {["x"] = 2, ["meta"] = {["fields"] = {}, ["inventory"] = {}}, ["y"] = 14, ["param1"] = 11, ["z"] = 52, ["name"] = "rainbow:stoneblock_white"}, {["x"] = 2, ["meta"] = {["fields"] = {}, ["inventory"] = {}}, ["y"] = 14, ["param1"] = 43, ["z"] = 62, ["name"] = "rainbow:stoneblock_white"}, {["x"] = 2, ["meta"] = {["fields"] = {}, ["inventory"] = {}}, ["y"] = 14, ["param1"] = 44, ["z"] = 63, ["name"] = "rainbow:stoneblock_white"}, {["x"] = 2, ["meta"] = {["fields"] = {}, ["inventory"] = {}}, ["y"] = 14, ["param1"] = 45, ["z"] = 64, ["name"] = "rainbow:stoneblock_white"}, {["x"] = 2, ["meta"] = {["fields"] = {}, ["inventory"] = {}}, ["y"] = 14, ["param1"] = 47, ["z"] = 65, ["name"] = "rainbow:stoneblock_white"}, {["x"] = 2, ["meta"] = {["fields"] = {}, ["inventory"] = {}}, ["y"] = 14, ["param1"] = 47, ["z"] = 66, ["name"] = "rainbow:stoneblock_white"}, {["x"] = 2, ["meta"] = {["fields"] = {}, ["inventory"] = {}}, ["y"] = 15, ["param1"] = 15, ["z"] = 48, ["name"] = "rainbow:stoneblock_white"}, {["x"] = 2, ["meta"] = {["fields"] = {}, ["inventory"] = {}}, ["y"] = 15, ["param1"] = 15, ["z"] = 49, ["name"] = "rainbow:stoneblock_white"}, {["x"] = 2, ["meta"] = {["fields"] = {}, ["inventory"] = {}}, ["y"] = 15, ["param1"] = 13, ["z"] = 50, ["name"] = "rainbow:stoneblock_white"}, {["x"] = 2, ["meta"] = {["fields"] = {}, ["inventory"] = {}}, ["y"] = 15, ["param1"] = 12, ["z"] = 51, ["name"] = "rainbow:stoneblock_white"}, {["x"] = 2, ["meta"] = {["fields"] = {}, ["inventory"] = {}}, ["y"] = 15, ["param1"] = 11, ["z"] = 52, ["name"] = "rainbow:stoneblock_white"}, {["x"] = 2, ["meta"] = {["fields"] = {}, ["inventory"] = {}}, ["y"] = 15, ["param1"] = 27, ["z"] = 62, ["name"] = "rainbow:stoneblock_white"}, {["x"] = 2, ["meta"] = {["fields"] = {}, ["inventory"] = {}}, ["y"] = 15, ["param1"] = 28, ["z"] = 63, ["name"] = "rainbow:stoneblock_white"}, {["x"] = 2, ["meta"] = {["fields"] = {}, ["inventory"] = {}}, ["y"] = 15, ["param1"] = 29, ["z"] = 64, ["name"] = "rainbow:stoneblock_white"}, {["x"] = 2, ["meta"] = {["fields"] = {}, ["inventory"] = {}}, ["y"] = 15, ["param1"] = 31, ["z"] = 65, ["name"] = "rainbow:stoneblock_white"}, {["x"] = 2, ["meta"] = {["fields"] = {}, ["inventory"] = {}}, ["y"] = 15, ["param1"] = 31, ["z"] = 66, ["name"] = "rainbow:stoneblock_white"}, {["x"] = 2, ["meta"] = {["fields"] = {}, ["inventory"] = {}}, ["y"] = 16, ["param1"] = 11, ["z"] = 52, ["name"] = "rainbow:stoneblock_white"}, {["x"] = 2, ["meta"] = {["fields"] = {}, ["inventory"] = {}}, ["y"] = 16, ["param1"] = 11, ["z"] = 62, ["name"] = "rainbow:stoneblock_white"}, {["x"] = 2, ["meta"] = {["fields"] = {}, ["inventory"] = {}}, ["y"] = 17, ["param1"] = 11, ["z"] = 52, ["name"] = "rainbow:stoneblock_white"}, {["x"] = 2, ["meta"] = {["fields"] = {}, ["inventory"] = {}}, ["y"] = 17, ["param1"] = 11, ["z"] = 62, ["name"] = "rainbow:stoneblock_white"}, {["x"] = 2, ["meta"] = {["fields"] = {}, ["inventory"] = {}}, ["y"] = 18, ["param1"] = 15, ["z"] = 50, ["name"] = "rainbow:stoneblock_white"}, {["x"] = 2, ["meta"] = {["fields"] = {}, ["inventory"] = {}}, ["y"] = 18, ["param1"] = 15, ["z"] = 51, ["name"] = "rainbow:stoneblock_white"}, {["x"] = 2, ["meta"] = {["fields"] = {}, ["inventory"] = {}}, ["y"] = 18, ["param1"] = 15, ["z"] = 52, ["name"] = "rainbow:stoneblock_white"}, {["x"] = 2, ["meta"] = {["fields"] = {}, ["inventory"] = {}}, ["y"] = 18, ["param1"] = 15, ["z"] = 53, ["name"] = "rainbow:stoneblock_white"}, {["x"] = 2, ["meta"] = {["fields"] = {}, ["inventory"] = {}}, ["y"] = 18, ["param1"] = 15, ["z"] = 54, ["name"] = "rainbow:stoneblock_white"}, {["x"] = 2, ["meta"] = {["fields"] = {}, ["inventory"] = {}}, ["y"] = 18, ["param1"] = 15, ["z"] = 55, ["name"] = "rainbow:stoneblock_white"}, {["x"] = 2, ["meta"] = {["fields"] = {}, ["inventory"] = {}}, ["y"] = 18, ["param1"] = 15, ["z"] = 56, ["name"] = "rainbow:stoneblock_white"}, {["x"] = 2, ["meta"] = {["fields"] = {}, ["inventory"] = {}}, ["y"] = 18, ["param1"] = 15, ["z"] = 57, ["name"] = "rainbow:stoneblock_white"}, {["x"] = 2, ["meta"] = {["fields"] = {}, ["inventory"] = {}}, ["y"] = 18, ["param1"] = 15, ["z"] = 58, ["name"] = "rainbow:stoneblock_white"}, {["x"] = 2, ["meta"] = {["fields"] = {}, ["inventory"] = {}}, ["y"] = 18, ["param1"] = 15, ["z"] = 59, ["name"] = "rainbow:stoneblock_white"}, {["x"] = 2, ["meta"] = {["fields"] = {}, ["inventory"] = {}}, ["y"] = 18, ["param1"] = 15, ["z"] = 60, ["name"] = "rainbow:stoneblock_white"}, {["x"] = 2, ["meta"] = {["fields"] = {}, ["inventory"] = {}}, ["y"] = 18, ["param1"] = 15, ["z"] = 61, ["name"] = "rainbow:stoneblock_white"}, {["x"] = 2, ["meta"] = {["fields"] = {}, ["inventory"] = {}}, ["y"] = 18, ["param1"] = 15, ["z"] = 62, ["name"] = "rainbow:stoneblock_white"}, {["x"] = 2, ["meta"] = {["fields"] = {}, ["inventory"] = {}}, ["y"] = 18, ["param1"] = 15, ["z"] = 63, ["name"] = "rainbow:stoneblock_white"}, {["x"] = 2, ["meta"] = {["fields"] = {}, ["inventory"] = {}}, ["y"] = 18, ["param1"] = 15, ["z"] = 64, ["name"] = "rainbow:stoneblock_white"}, {["x"] = 2, ["meta"] = {["fields"] = {}, ["inventory"] = {}}, ["y"] = 19, ["param1"] = 15, ["z"] = 50, ["name"] = "rainbow:stoneblock_white"}, {["x"] = 2, ["meta"] = {["fields"] = {}, ["inventory"] = {}}, ["y"] = 19, ["param1"] = 15, ["z"] = 51, ["name"] = "rainbow:stoneblock_white"}, {["x"] = 2, ["meta"] = {["fields"] = {}, ["inventory"] = {}}, ["y"] = 19, ["param1"] = 15, ["z"] = 52, ["name"] = "rainbow:stoneblock_white"}, {["x"] = 2, ["meta"] = {["fields"] = {}, ["inventory"] = {}}, ["y"] = 19, ["param1"] = 15, ["z"] = 53, ["name"] = "rainbow:stoneblock_white"}, {["x"] = 2, ["meta"] = {["fields"] = {}, ["inventory"] = {}}, ["y"] = 19, ["param1"] = 15, ["z"] = 54, ["name"] = "rainbow:stoneblock_white"}, {["x"] = 2, ["meta"] = {["fields"] = {}, ["inventory"] = {}}, ["y"] = 19, ["param1"] = 15, ["z"] = 55, ["name"] = "rainbow:stoneblock_white"}, {["x"] = 2, ["meta"] = {["fields"] = {}, ["inventory"] = {}}, ["y"] = 19, ["param1"] = 15, ["z"] = 56, ["name"] = "rainbow:stoneblock_white"}, {["x"] = 2, ["meta"] = {["fields"] = {}, ["inventory"] = {}}, ["y"] = 19, ["param1"] = 15, ["z"] = 57, ["name"] = "rainbow:stoneblock_white"}, {["x"] = 2, ["meta"] = {["fields"] = {}, ["inventory"] = {}}, ["y"] = 19, ["param1"] = 15, ["z"] = 58, ["name"] = "rainbow:stoneblock_white"}, {["x"] = 2, ["meta"] = {["fields"] = {}, ["inventory"] = {}}, ["y"] = 19, ["param1"] = 15, ["z"] = 59, ["name"] = "rainbow:stoneblock_white"}, {["x"] = 2, ["meta"] = {["fields"] = {}, ["inventory"] = {}}, ["y"] = 19, ["param1"] = 15, ["z"] = 60, ["name"] = "rainbow:stoneblock_white"}, {["x"] = 2, ["meta"] = {["fields"] = {}, ["inventory"] = {}}, ["y"] = 19, ["param1"] = 15, ["z"] = 61, ["name"] = "rainbow:stoneblock_white"}, {["x"] = 2, ["meta"] = {["fields"] = {}, ["inventory"] = {}}, ["y"] = 19, ["param1"] = 15, ["z"] = 62, ["name"] = "rainbow:stoneblock_white"}, {["x"] = 2, ["meta"] = {["fields"] = {}, ["inventory"] = {}}, ["y"] = 19, ["param1"] = 15, ["z"] = 63, ["name"] = "rainbow:stoneblock_white"}, {["x"] = 2, ["meta"] = {["fields"] = {}, ["inventory"] = {}}, ["y"] = 19, ["param1"] = 15, ["z"] = 64, ["name"] = "rainbow:stoneblock_white"}, {["x"] = 3, ["meta"] = {["fields"] = {}, ["inventory"] = {}}, ["y"] = 4, ["param1"] = 15, ["z"] = 50, ["name"] = "rainbow:stoneblock_white"}, {["x"] = 3, ["meta"] = {["fields"] = {}, ["inventory"] = {}}, ["y"] = 4, ["param1"] = 15, ["z"] = 51, ["name"] = "rainbow:stoneblock_white"}, {["x"] = 3, ["meta"] = {["fields"] = {}, ["inventory"] = {}}, ["y"] = 4, ["param1"] = 15, ["z"] = 52, ["name"] = "rainbow:stoneblock_white"}, {["x"] = 3, ["meta"] = {["fields"] = {}, ["inventory"] = {}}, ["y"] = 4, ["param1"] = 15, ["z"] = 53, ["name"] = "rainbow:stoneblock_white"}, {["x"] = 3, ["meta"] = {["fields"] = {}, ["inventory"] = {}}, ["y"] = 4, ["param1"] = 15, ["z"] = 54, ["name"] = "rainbow:stoneblock_white"}, {["x"] = 3, ["meta"] = {["fields"] = {}, ["inventory"] = {}}, ["y"] = 4, ["param1"] = 15, ["z"] = 55, ["name"] = "rainbow:stoneblock_white"}, {["x"] = 3, ["meta"] = {["fields"] = {}, ["inventory"] = {}}, ["y"] = 4, ["param1"] = 15, ["z"] = 56, ["name"] = "rainbow:stoneblock_white"}, {["x"] = 3, ["meta"] = {["fields"] = {}, ["inventory"] = {}}, ["y"] = 4, ["param1"] = 15, ["z"] = 57, ["name"] = "rainbow:stoneblock_white"}, {["x"] = 3, ["meta"] = {["fields"] = {}, ["inventory"] = {}}, ["y"] = 4, ["param1"] = 15, ["z"] = 58, ["name"] = "rainbow:stoneblock_white"}, {["x"] = 3, ["meta"] = {["fields"] = {}, ["inventory"] = {}}, ["y"] = 4, ["param1"] = 15, ["z"] = 59, ["name"] = "rainbow:stoneblock_white"}, {["x"] = 3, ["meta"] = {["fields"] = {}, ["inventory"] = {}}, ["y"] = 4, ["param1"] = 15, ["z"] = 60, ["name"] = "rainbow:stoneblock_white"}, {["x"] = 3, ["meta"] = {["fields"] = {}, ["inventory"] = {}}, ["y"] = 4, ["param1"] = 15, ["z"] = 61, ["name"] = "rainbow:stoneblock_white"}, {["x"] = 3, ["meta"] = {["fields"] = {}, ["inventory"] = {}}, ["y"] = 4, ["param1"] = 15, ["z"] = 62, ["name"] = "rainbow:stoneblock_white"}, {["x"] = 3, ["meta"] = {["fields"] = {}, ["inventory"] = {}}, ["y"] = 4, ["param1"] = 15, ["z"] = 63, ["name"] = "rainbow:stoneblock_white"}, {["x"] = 3, ["meta"] = {["fields"] = {}, ["inventory"] = {}}, ["y"] = 4, ["param1"] = 15, ["z"] = 64, ["name"] = "rainbow:stoneblock_white"}, {["x"] = 3, ["meta"] = {["fields"] = {}, ["inventory"] = {}}, ["y"] = 5, ["param1"] = 11, ["z"] = 52, ["name"] = "rainbow:stoneblock_white"}, {["x"] = 3, ["meta"] = {["fields"] = {}, ["inventory"] = {}}, ["y"] = 5, ["param1"] = 9, ["z"] = 62, ["name"] = "rainbow:stoneblock_white"}, {["x"] = 3, ["meta"] = {["fields"] = {}, ["inventory"] = {}}, ["y"] = 6, ["param1"] = 11, ["z"] = 52, ["name"] = "rainbow:stoneblock_white"}, {["x"] = 3, ["meta"] = {["fields"] = {}, ["inventory"] = {}}, ["y"] = 6, ["param1"] = 9, ["z"] = 62, ["name"] = "rainbow:stoneblock_white"}, {["x"] = 3, ["meta"] = {["fields"] = {}, ["inventory"] = {}}, ["y"] = 7, ["param1"] = 15, ["z"] = 48, ["name"] = "rainbow:stoneblock_white"}, {["x"] = 3, ["meta"] = {["fields"] = {}, ["inventory"] = {}}, ["y"] = 7, ["param1"] = 15, ["z"] = 49, ["name"] = "rainbow:stoneblock_white"}, {["x"] = 3, ["meta"] = {["fields"] = {}, ["inventory"] = {}}, ["y"] = 7, ["param1"] = 13, ["z"] = 50, ["name"] = "rainbow:stoneblock_white"}, {["x"] = 3, ["meta"] = {["fields"] = {}, ["inventory"] = {}}, ["y"] = 7, ["param1"] = 12, ["z"] = 51, ["name"] = "rainbow:stoneblock_white"}, {["x"] = 3, ["meta"] = {["fields"] = {}, ["inventory"] = {}}, ["y"] = 7, ["param1"] = 11, ["z"] = 52, ["name"] = "rainbow:stoneblock_white"}, {["x"] = 3, ["meta"] = {["fields"] = {}, ["inventory"] = {}}, ["y"] = 7, ["param1"] = 11, ["z"] = 62, ["name"] = "rainbow:stoneblock_white"}, {["x"] = 3, ["meta"] = {["fields"] = {}, ["inventory"] = {}}, ["y"] = 7, ["param1"] = 12, ["z"] = 63, ["name"] = "rainbow:stoneblock_white"}, {["x"] = 3, ["meta"] = {["fields"] = {}, ["inventory"] = {}}, ["y"] = 7, ["param1"] = 13, ["z"] = 64, ["name"] = "rainbow:stoneblock_white"}, {["x"] = 3, ["meta"] = {["fields"] = {}, ["inventory"] = {}}, ["y"] = 7, ["param1"] = 15, ["z"] = 65, ["name"] = "rainbow:stoneblock_white"}, {["x"] = 3, ["meta"] = {["fields"] = {}, ["inventory"] = {}}, ["y"] = 7, ["param1"] = 31, ["z"] = 66, ["name"] = "rainbow:stoneblock_white"}, {["x"] = 3, ["meta"] = {["fields"] = {}, ["inventory"] = {}}, ["y"] = 8, ["param1"] = 15, ["z"] = 48, ["name"] = "rainbow:stoneblock_white"}, {["x"] = 3, ["meta"] = {["fields"] = {}, ["inventory"] = {}}, ["y"] = 8, ["param1"] = 15, ["z"] = 49, ["name"] = "rainbow:stoneblock_white"}, {["x"] = 3, ["meta"] = {["fields"] = {}, ["inventory"] = {}}, ["y"] = 8, ["param1"] = 13, ["z"] = 50, ["name"] = "rainbow:stoneblock_white"}, {["x"] = 3, ["meta"] = {["fields"] = {}, ["inventory"] = {}}, ["y"] = 8, ["param1"] = 12, ["z"] = 51, ["name"] = "rainbow:stoneblock_white"}, {["x"] = 3, ["meta"] = {["fields"] = {}, ["inventory"] = {}}, ["y"] = 8, ["param1"] = 11, ["z"] = 52, ["name"] = "rainbow:stoneblock_white"}, {["x"] = 3, ["meta"] = {["fields"] = {}, ["inventory"] = {}}, ["y"] = 8, ["param1"] = 27, ["z"] = 62, ["name"] = "rainbow:stoneblock_white"}, {["x"] = 3, ["meta"] = {["fields"] = {}, ["inventory"] = {}}, ["y"] = 8, ["param1"] = 28, ["z"] = 63, ["name"] = "rainbow:stoneblock_white"}, {["x"] = 3, ["meta"] = {["fields"] = {}, ["inventory"] = {}}, ["y"] = 8, ["param1"] = 29, ["z"] = 64, ["name"] = "rainbow:stoneblock_white"}, {["x"] = 3, ["meta"] = {["fields"] = {}, ["inventory"] = {}}, ["y"] = 8, ["param1"] = 31, ["z"] = 65, ["name"] = "rainbow:stoneblock_white"}, {["x"] = 3, ["meta"] = {["fields"] = {}, ["inventory"] = {}}, ["y"] = 8, ["param1"] = 47, ["z"] = 66, ["name"] = "rainbow:stoneblock_white"}, {["x"] = 3, ["meta"] = {["fields"] = {}, ["inventory"] = {}}, ["y"] = 9, ["param1"] = 15, ["z"] = 46, ["name"] = "rainbow:stoneblock_white"}, {["x"] = 3, ["meta"] = {["fields"] = {}, ["inventory"] = {}}, ["y"] = 9, ["param1"] = 15, ["z"] = 47, ["name"] = "rainbow:stoneblock_white"}, {["x"] = 3, ["meta"] = {["fields"] = {}, ["inventory"] = {}}, ["y"] = 9, ["param1"] = 15, ["z"] = 48, ["name"] = "rainbow:stoneblock_white"}, {["x"] = 3, ["meta"] = {["fields"] = {}, ["inventory"] = {}}, ["y"] = 9, ["param1"] = 15, ["z"] = 49, ["name"] = "rainbow:stoneblock_white"}, {["x"] = 3, ["meta"] = {["fields"] = {}, ["inventory"] = {}}, ["y"] = 9, ["param1"] = 13, ["z"] = 50, ["name"] = "rainbow:stoneblock_white"}, {["x"] = 3, ["meta"] = {["fields"] = {}, ["inventory"] = {}}, ["y"] = 9, ["param1"] = 12, ["z"] = 51, ["name"] = "rainbow:stoneblock_white"}, {["x"] = 3, ["meta"] = {["fields"] = {}, ["inventory"] = {}}, ["y"] = 9, ["param1"] = 11, ["z"] = 52, ["name"] = "rainbow:stoneblock_white"}, {["x"] = 3, ["meta"] = {["fields"] = {}, ["inventory"] = {}}, ["y"] = 9, ["param1"] = 43, ["z"] = 62, ["name"] = "rainbow:stoneblock_white"}, {["x"] = 3, ["meta"] = {["fields"] = {}, ["inventory"] = {}}, ["y"] = 9, ["param1"] = 44, ["z"] = 63, ["name"] = "rainbow:stoneblock_white"}, {["x"] = 3, ["meta"] = {["fields"] = {}, ["inventory"] = {}}, ["y"] = 9, ["param1"] = 45, ["z"] = 64, ["name"] = "rainbow:stoneblock_white"}, {["x"] = 3, ["meta"] = {["fields"] = {}, ["inventory"] = {}}, ["y"] = 9, ["param1"] = 47, ["z"] = 65, ["name"] = "rainbow:stoneblock_white"}, {["x"] = 3, ["meta"] = {["fields"] = {}, ["inventory"] = {}}, ["y"] = 9, ["param1"] = 63, ["z"] = 66, ["name"] = "rainbow:stoneblock_white"}, {["x"] = 3, ["meta"] = {["fields"] = {}, ["inventory"] = {}}, ["y"] = 10, ["param1"] = 15, ["z"] = 46, ["name"] = "rainbow:stoneblock_white"}, {["x"] = 3, ["meta"] = {["fields"] = {}, ["inventory"] = {}}, ["y"] = 10, ["param1"] = 15, ["z"] = 47, ["name"] = "rainbow:stoneblock_white"}, {["x"] = 3, ["meta"] = {["fields"] = {}, ["inventory"] = {}}, ["y"] = 10, ["param1"] = 15, ["z"] = 67, ["name"] = "rainbow:stoneblock_white"}, {["x"] = 3, ["meta"] = {["fields"] = {}, ["inventory"] = {}}, ["y"] = 10, ["param1"] = 15, ["z"] = 68, ["name"] = "rainbow:stoneblock_white"}, {["x"] = 3, ["meta"] = {["fields"] = {}, ["inventory"] = {}}, ["y"] = 11, ["param1"] = 15, ["z"] = 46, ["name"] = "rainbow:stoneblock_white"}, {["x"] = 3, ["meta"] = {["fields"] = {}, ["inventory"] = {}}, ["y"] = 11, ["param1"] = 15, ["z"] = 47, ["name"] = "rainbow:stoneblock_white"}, {["x"] = 3, ["meta"] = {["fields"] = {}, ["inventory"] = {}}, ["y"] = 11, ["param1"] = 15, ["z"] = 67, ["name"] = "rainbow:stoneblock_white"}, {["x"] = 3, ["meta"] = {["fields"] = {}, ["inventory"] = {}}, ["y"] = 11, ["param1"] = 15, ["z"] = 68, ["name"] = "rainbow:stoneblock_white"}, {["x"] = 3, ["meta"] = {["fields"] = {}, ["inventory"] = {}}, ["y"] = 12, ["param1"] = 15, ["z"] = 46, ["name"] = "rainbow:stoneblock_white"}, {["x"] = 3, ["meta"] = {["fields"] = {}, ["inventory"] = {}}, ["y"] = 12, ["param1"] = 15, ["z"] = 47, ["name"] = "rainbow:stoneblock_white"}, {["x"] = 3, ["meta"] = {["fields"] = {}, ["inventory"] = {}}, ["y"] = 12, ["param1"] = 15, ["z"] = 67, ["name"] = "rainbow:stoneblock_white"}, {["x"] = 3, ["meta"] = {["fields"] = {}, ["inventory"] = {}}, ["y"] = 12, ["param1"] = 15, ["z"] = 68, ["name"] = "rainbow:stoneblock_white"}, {["x"] = 3, ["meta"] = {["fields"] = {}, ["inventory"] = {}}, ["y"] = 13, ["param1"] = 15, ["z"] = 46, ["name"] = "rainbow:stoneblock_white"}, {["x"] = 3, ["meta"] = {["fields"] = {}, ["inventory"] = {}}, ["y"] = 13, ["param1"] = 15, ["z"] = 47, ["name"] = "rainbow:stoneblock_white"}, {["x"] = 3, ["meta"] = {["fields"] = {}, ["inventory"] = {}}, ["y"] = 13, ["param1"] = 15, ["z"] = 67, ["name"] = "rainbow:stoneblock_white"}, {["x"] = 3, ["meta"] = {["fields"] = {}, ["inventory"] = {}}, ["y"] = 13, ["param1"] = 15, ["z"] = 68, ["name"] = "rainbow:stoneblock_white"}, {["x"] = 3, ["meta"] = {["fields"] = {}, ["inventory"] = {}}, ["y"] = 14, ["param1"] = 15, ["z"] = 46, ["name"] = "rainbow:stoneblock_white"}, {["x"] = 3, ["meta"] = {["fields"] = {}, ["inventory"] = {}}, ["y"] = 14, ["param1"] = 15, ["z"] = 47, ["name"] = "rainbow:stoneblock_white"}, {["x"] = 3, ["meta"] = {["fields"] = {}, ["inventory"] = {}}, ["y"] = 14, ["param1"] = 15, ["z"] = 67, ["name"] = "rainbow:stoneblock_white"}, {["x"] = 3, ["meta"] = {["fields"] = {}, ["inventory"] = {}}, ["y"] = 14, ["param1"] = 15, ["z"] = 68, ["name"] = "rainbow:stoneblock_white"}, {["x"] = 3, ["meta"] = {["fields"] = {}, ["inventory"] = {}}, ["y"] = 15, ["param1"] = 15, ["z"] = 46, ["name"] = "rainbow:stoneblock_white"}, {["x"] = 3, ["meta"] = {["fields"] = {}, ["inventory"] = {}}, ["y"] = 15, ["param1"] = 15, ["z"] = 47, ["name"] = "rainbow:stoneblock_white"}, {["x"] = 3, ["meta"] = {["fields"] = {}, ["inventory"] = {}}, ["y"] = 15, ["param1"] = 15, ["z"] = 48, ["name"] = "rainbow:stoneblock_white"}, {["x"] = 3, ["meta"] = {["fields"] = {}, ["inventory"] = {}}, ["y"] = 15, ["param1"] = 15, ["z"] = 49, ["name"] = "rainbow:stoneblock_white"}, {["x"] = 3, ["meta"] = {["fields"] = {}, ["inventory"] = {}}, ["y"] = 15, ["param1"] = 13, ["z"] = 50, ["name"] = "rainbow:stoneblock_white"}, {["x"] = 3, ["meta"] = {["fields"] = {}, ["inventory"] = {}}, ["y"] = 15, ["param1"] = 12, ["z"] = 51, ["name"] = "rainbow:stoneblock_white"}, {["x"] = 3, ["meta"] = {["fields"] = {}, ["inventory"] = {}}, ["y"] = 15, ["param1"] = 11, ["z"] = 52, ["name"] = "rainbow:stoneblock_white"}, {["x"] = 3, ["meta"] = {["fields"] = {}, ["inventory"] = {}}, ["y"] = 15, ["param1"] = 43, ["z"] = 62, ["name"] = "rainbow:stoneblock_white"}, {["x"] = 3, ["meta"] = {["fields"] = {}, ["inventory"] = {}}, ["y"] = 15, ["param1"] = 44, ["z"] = 63, ["name"] = "rainbow:stoneblock_white"}, {["x"] = 3, ["meta"] = {["fields"] = {}, ["inventory"] = {}}, ["y"] = 15, ["param1"] = 45, ["z"] = 64, ["name"] = "rainbow:stoneblock_white"}, {["x"] = 3, ["meta"] = {["fields"] = {}, ["inventory"] = {}}, ["y"] = 15, ["param1"] = 47, ["z"] = 65, ["name"] = "rainbow:stoneblock_white"}, {["x"] = 3, ["meta"] = {["fields"] = {}, ["inventory"] = {}}, ["y"] = 15, ["param1"] = 47, ["z"] = 66, ["name"] = "rainbow:stoneblock_white"}, {["x"] = 3, ["meta"] = {["fields"] = {}, ["inventory"] = {}}, ["y"] = 16, ["param1"] = 15, ["z"] = 48, ["name"] = "rainbow:stoneblock_white"}, {["x"] = 3, ["meta"] = {["fields"] = {}, ["inventory"] = {}}, ["y"] = 16, ["param1"] = 15, ["z"] = 49, ["name"] = "rainbow:stoneblock_white"}, {["x"] = 3, ["meta"] = {["fields"] = {}, ["inventory"] = {}}, ["y"] = 16, ["param1"] = 13, ["z"] = 50, ["name"] = "rainbow:stoneblock_white"}, {["x"] = 3, ["meta"] = {["fields"] = {}, ["inventory"] = {}}, ["y"] = 16, ["param1"] = 12, ["z"] = 51, ["name"] = "rainbow:stoneblock_white"}, {["x"] = 3, ["meta"] = {["fields"] = {}, ["inventory"] = {}}, ["y"] = 16, ["param1"] = 11, ["z"] = 52, ["name"] = "rainbow:stoneblock_white"}, {["x"] = 3, ["meta"] = {["fields"] = {}, ["inventory"] = {}}, ["y"] = 16, ["param1"] = 27, ["z"] = 62, ["name"] = "rainbow:stoneblock_white"}, {["x"] = 3, ["meta"] = {["fields"] = {}, ["inventory"] = {}}, ["y"] = 16, ["param1"] = 28, ["z"] = 63, ["name"] = "rainbow:stoneblock_white"}, {["x"] = 3, ["meta"] = {["fields"] = {}, ["inventory"] = {}}, ["y"] = 16, ["param1"] = 29, ["z"] = 64, ["name"] = "rainbow:stoneblock_white"}, {["x"] = 3, ["meta"] = {["fields"] = {}, ["inventory"] = {}}, ["y"] = 16, ["param1"] = 31, ["z"] = 65, ["name"] = "rainbow:stoneblock_white"}, {["x"] = 3, ["meta"] = {["fields"] = {}, ["inventory"] = {}}, ["y"] = 16, ["param1"] = 31, ["z"] = 66, ["name"] = "rainbow:stoneblock_white"}, {["x"] = 3, ["meta"] = {["fields"] = {}, ["inventory"] = {}}, ["y"] = 17, ["param1"] = 15, ["z"] = 48, ["name"] = "rainbow:stoneblock_white"}, {["x"] = 3, ["meta"] = {["fields"] = {}, ["inventory"] = {}}, ["y"] = 17, ["param1"] = 15, ["z"] = 49, ["name"] = "rainbow:stoneblock_white"}, {["x"] = 3, ["meta"] = {["fields"] = {}, ["inventory"] = {}}, ["y"] = 17, ["param1"] = 13, ["z"] = 50, ["name"] = "rainbow:stoneblock_white"}, {["x"] = 3, ["meta"] = {["fields"] = {}, ["inventory"] = {}}, ["y"] = 17, ["param1"] = 12, ["z"] = 51, ["name"] = "rainbow:stoneblock_white"}, {["x"] = 3, ["meta"] = {["fields"] = {}, ["inventory"] = {}}, ["y"] = 17, ["param1"] = 11, ["z"] = 52, ["name"] = "rainbow:stoneblock_white"}, {["x"] = 3, ["meta"] = {["fields"] = {}, ["inventory"] = {}}, ["y"] = 17, ["param1"] = 11, ["z"] = 62, ["name"] = "rainbow:stoneblock_white"}, {["x"] = 3, ["meta"] = {["fields"] = {}, ["inventory"] = {}}, ["y"] = 17, ["param1"] = 12, ["z"] = 63, ["name"] = "rainbow:stoneblock_white"}, {["x"] = 3, ["meta"] = {["fields"] = {}, ["inventory"] = {}}, ["y"] = 17, ["param1"] = 13, ["z"] = 64, ["name"] = "rainbow:stoneblock_white"}, {["x"] = 3, ["meta"] = {["fields"] = {}, ["inventory"] = {}}, ["y"] = 17, ["param1"] = 15, ["z"] = 65, ["name"] = "rainbow:stoneblock_white"}, {["x"] = 3, ["meta"] = {["fields"] = {}, ["inventory"] = {}}, ["y"] = 17, ["param1"] = 15, ["z"] = 66, ["name"] = "rainbow:stoneblock_white"}, {["x"] = 3, ["meta"] = {["fields"] = {}, ["inventory"] = {}}, ["y"] = 18, ["param1"] = 11, ["z"] = 52, ["name"] = "rainbow:stoneblock_white"}, {["x"] = 3, ["meta"] = {["fields"] = {}, ["inventory"] = {}}, ["y"] = 18, ["param1"] = 11, ["z"] = 62, ["name"] = "rainbow:stoneblock_white"}, {["x"] = 3, ["meta"] = {["fields"] = {}, ["inventory"] = {}}, ["y"] = 19, ["param1"] = 11, ["z"] = 52, ["name"] = "rainbow:stoneblock_white"}, {["x"] = 3, ["meta"] = {["fields"] = {}, ["inventory"] = {}}, ["y"] = 19, ["param1"] = 11, ["z"] = 62, ["name"] = "rainbow:stoneblock_white"}, {["x"] = 3, ["meta"] = {["fields"] = {}, ["inventory"] = {}}, ["y"] = 20, ["param1"] = 15, ["z"] = 50, ["name"] = "rainbow:stoneblock_white"}, {["x"] = 3, ["meta"] = {["fields"] = {}, ["inventory"] = {}}, ["y"] = 20, ["param1"] = 15, ["z"] = 51, ["name"] = "rainbow:stoneblock_white"}, {["x"] = 3, ["meta"] = {["fields"] = {}, ["inventory"] = {}}, ["y"] = 20, ["param1"] = 15, ["z"] = 52, ["name"] = "rainbow:stoneblock_white"}, {["x"] = 3, ["meta"] = {["fields"] = {}, ["inventory"] = {}}, ["y"] = 20, ["param1"] = 15, ["z"] = 53, ["name"] = "rainbow:stoneblock_white"}, {["x"] = 3, ["meta"] = {["fields"] = {}, ["inventory"] = {}}, ["y"] = 20, ["param1"] = 15, ["z"] = 54, ["name"] = "rainbow:stoneblock_white"}, {["x"] = 3, ["meta"] = {["fields"] = {}, ["inventory"] = {}}, ["y"] = 20, ["param1"] = 15, ["z"] = 55, ["name"] = "rainbow:stoneblock_white"}, {["x"] = 3, ["meta"] = {["fields"] = {}, ["inventory"] = {}}, ["y"] = 20, ["param1"] = 15, ["z"] = 56, ["name"] = "rainbow:stoneblock_white"}, {["x"] = 3, ["meta"] = {["fields"] = {}, ["inventory"] = {}}, ["y"] = 20, ["param1"] = 15, ["z"] = 57, ["name"] = "rainbow:stoneblock_white"}, {["x"] = 3, ["meta"] = {["fields"] = {}, ["inventory"] = {}}, ["y"] = 20, ["param1"] = 15, ["z"] = 58, ["name"] = "rainbow:stoneblock_white"}, {["x"] = 3, ["meta"] = {["fields"] = {}, ["inventory"] = {}}, ["y"] = 20, ["param1"] = 15, ["z"] = 59, ["name"] = "rainbow:stoneblock_white"}, {["x"] = 3, ["meta"] = {["fields"] = {}, ["inventory"] = {}}, ["y"] = 20, ["param1"] = 15, ["z"] = 60, ["name"] = "rainbow:stoneblock_white"}, {["x"] = 3, ["meta"] = {["fields"] = {}, ["inventory"] = {}}, ["y"] = 20, ["param1"] = 15, ["z"] = 61, ["name"] = "rainbow:stoneblock_white"}, {["x"] = 3, ["meta"] = {["fields"] = {}, ["inventory"] = {}}, ["y"] = 20, ["param1"] = 15, ["z"] = 62, ["name"] = "rainbow:stoneblock_white"}, {["x"] = 3, ["meta"] = {["fields"] = {}, ["inventory"] = {}}, ["y"] = 20, ["param1"] = 15, ["z"] = 63, ["name"] = "rainbow:stoneblock_white"}, {["x"] = 3, ["meta"] = {["fields"] = {}, ["inventory"] = {}}, ["y"] = 20, ["param1"] = 15, ["z"] = 64, ["name"] = "rainbow:stoneblock_white"}, {["x"] = 4, ["meta"] = {["fields"] = {}, ["inventory"] = {}}, ["y"] = 3, ["param1"] = 15, ["z"] = 50, ["name"] = "rainbow:stoneblock_white"}, {["x"] = 4, ["meta"] = {["fields"] = {}, ["inventory"] = {}}, ["y"] = 3, ["param1"] = 15, ["z"] = 51, ["name"] = "rainbow:stoneblock_white"}, {["x"] = 4, ["meta"] = {["fields"] = {}, ["inventory"] = {}}, ["y"] = 3, ["param1"] = 15, ["z"] = 52, ["name"] = "rainbow:stoneblock_white"}, {["x"] = 4, ["meta"] = {["fields"] = {}, ["inventory"] = {}}, ["y"] = 3, ["param1"] = 15, ["z"] = 53, ["name"] = "rainbow:stoneblock_white"}, {["x"] = 4, ["meta"] = {["fields"] = {}, ["inventory"] = {}}, ["y"] = 3, ["param1"] = 15, ["z"] = 54, ["name"] = "rainbow:stoneblock_white"}, {["x"] = 4, ["meta"] = {["fields"] = {}, ["inventory"] = {}}, ["y"] = 3, ["param1"] = 15, ["z"] = 55, ["name"] = "rainbow:stoneblock_white"}, {["x"] = 4, ["meta"] = {["fields"] = {}, ["inventory"] = {}}, ["y"] = 3, ["param1"] = 15, ["z"] = 56, ["name"] = "rainbow:stoneblock_white"}, {["x"] = 4, ["meta"] = {["fields"] = {}, ["inventory"] = {}}, ["y"] = 3, ["param1"] = 15, ["z"] = 57, ["name"] = "rainbow:stoneblock_white"}, {["x"] = 4, ["meta"] = {["fields"] = {}, ["inventory"] = {}}, ["y"] = 3, ["param1"] = 15, ["z"] = 58, ["name"] = "rainbow:stoneblock_white"}, {["x"] = 4, ["meta"] = {["fields"] = {}, ["inventory"] = {}}, ["y"] = 3, ["param1"] = 15, ["z"] = 59, ["name"] = "rainbow:stoneblock_white"}, {["x"] = 4, ["meta"] = {["fields"] = {}, ["inventory"] = {}}, ["y"] = 3, ["param1"] = 15, ["z"] = 60, ["name"] = "rainbow:stoneblock_white"}, {["x"] = 4, ["meta"] = {["fields"] = {}, ["inventory"] = {}}, ["y"] = 3, ["param1"] = 15, ["z"] = 61, ["name"] = "rainbow:stoneblock_white"}, {["x"] = 4, ["meta"] = {["fields"] = {}, ["inventory"] = {}}, ["y"] = 3, ["param1"] = 15, ["z"] = 62, ["name"] = "rainbow:stoneblock_white"}, {["x"] = 4, ["meta"] = {["fields"] = {}, ["inventory"] = {}}, ["y"] = 3, ["param1"] = 15, ["z"] = 63, ["name"] = "rainbow:stoneblock_white"}, {["x"] = 4, ["meta"] = {["fields"] = {}, ["inventory"] = {}}, ["y"] = 3, ["param1"] = 15, ["z"] = 64, ["name"] = "rainbow:stoneblock_white"}, {["x"] = 4, ["meta"] = {["fields"] = {}, ["inventory"] = {}}, ["y"] = 4, ["param1"] = 11, ["z"] = 52, ["name"] = "rainbow:stoneblock_white"}, {["x"] = 4, ["meta"] = {["fields"] = {}, ["inventory"] = {}}, ["y"] = 4, ["param1"] = 8, ["z"] = 62, ["name"] = "rainbow:stoneblock_white"}, {["x"] = 4, ["meta"] = {["fields"] = {}, ["inventory"] = {}}, ["y"] = 5, ["param1"] = 11, ["z"] = 52, ["name"] = "rainbow:stoneblock_white"}, {["x"] = 4, ["meta"] = {["fields"] = {}, ["inventory"] = {}}, ["y"] = 5, ["param1"] = 8, ["z"] = 62, ["name"] = "rainbow:stoneblock_white"}, {["x"] = 4, ["meta"] = {["fields"] = {}, ["inventory"] = {}}, ["y"] = 6, ["param1"] = 15, ["z"] = 48, ["name"] = "rainbow:stoneblock_white"}, {["x"] = 4, ["meta"] = {["fields"] = {}, ["inventory"] = {}}, ["y"] = 6, ["param1"] = 15, ["z"] = 49, ["name"] = "rainbow:stoneblock_white"}, {["x"] = 4, ["meta"] = {["fields"] = {}, ["inventory"] = {}}, ["y"] = 6, ["param1"] = 13, ["z"] = 50, ["name"] = "rainbow:stoneblock_white"}, {["x"] = 4, ["meta"] = {["fields"] = {}, ["inventory"] = {}}, ["y"] = 6, ["param1"] = 12, ["z"] = 51, ["name"] = "rainbow:stoneblock_white"}, {["x"] = 4, ["meta"] = {["fields"] = {}, ["inventory"] = {}}, ["y"] = 6, ["param1"] = 11, ["z"] = 52, ["name"] = "rainbow:stoneblock_white"}, {["x"] = 4, ["meta"] = {["fields"] = {}, ["inventory"] = {}}, ["y"] = 6, ["param1"] = 11, ["z"] = 62, ["name"] = "rainbow:stoneblock_white"}, {["x"] = 4, ["meta"] = {["fields"] = {}, ["inventory"] = {}}, ["y"] = 6, ["param1"] = 12, ["z"] = 63, ["name"] = "rainbow:stoneblock_white"}, {["x"] = 4, ["meta"] = {["fields"] = {}, ["inventory"] = {}}, ["y"] = 6, ["param1"] = 13, ["z"] = 64, ["name"] = "rainbow:stoneblock_white"}, {["x"] = 4, ["meta"] = {["fields"] = {}, ["inventory"] = {}}, ["y"] = 6, ["param1"] = 15, ["z"] = 65, ["name"] = "rainbow:stoneblock_white"}, {["x"] = 4, ["meta"] = {["fields"] = {}, ["inventory"] = {}}, ["y"] = 6, ["param1"] = 31, ["z"] = 66, ["name"] = "rainbow:stoneblock_white"}, {["x"] = 4, ["meta"] = {["fields"] = {}, ["inventory"] = {}}, ["y"] = 7, ["param1"] = 15, ["z"] = 46, ["name"] = "rainbow:stoneblock_white"}, {["x"] = 4, ["meta"] = {["fields"] = {}, ["inventory"] = {}}, ["y"] = 7, ["param1"] = 15, ["z"] = 47, ["name"] = "rainbow:stoneblock_white"}, {["x"] = 4, ["meta"] = {["fields"] = {}, ["inventory"] = {}}, ["y"] = 7, ["param1"] = 15, ["z"] = 67, ["name"] = "rainbow:stoneblock_white"}, {["x"] = 4, ["meta"] = {["fields"] = {}, ["inventory"] = {}}, ["y"] = 7, ["param1"] = 15, ["z"] = 68, ["name"] = "rainbow:stoneblock_white"}, {["x"] = 4, ["meta"] = {["fields"] = {}, ["inventory"] = {}}, ["y"] = 8, ["param1"] = 15, ["z"] = 46, ["name"] = "rainbow:stoneblock_white"}, {["x"] = 4, ["meta"] = {["fields"] = {}, ["inventory"] = {}}, ["y"] = 8, ["param1"] = 15, ["z"] = 47, ["name"] = "rainbow:stoneblock_white"}, {["x"] = 4, ["meta"] = {["fields"] = {}, ["inventory"] = {}}, ["y"] = 8, ["param1"] = 15, ["z"] = 67, ["name"] = "rainbow:stoneblock_white"}, {["x"] = 4, ["meta"] = {["fields"] = {}, ["inventory"] = {}}, ["y"] = 8, ["param1"] = 15, ["z"] = 68, ["name"] = "rainbow:stoneblock_white"}, {["x"] = 4, ["meta"] = {["fields"] = {}, ["inventory"] = {}}, ["y"] = 9, ["param1"] = 15, ["z"] = 46, ["name"] = "rainbow:stoneblock_white"}, {["x"] = 4, ["meta"] = {["fields"] = {}, ["inventory"] = {}}, ["y"] = 9, ["param1"] = 15, ["z"] = 47, ["name"] = "rainbow:stoneblock_white"}, {["x"] = 4, ["meta"] = {["fields"] = {}, ["inventory"] = {}}, ["y"] = 9, ["param1"] = 15, ["z"] = 67, ["name"] = "rainbow:stoneblock_white"}, {["x"] = 4, ["meta"] = {["fields"] = {}, ["inventory"] = {}}, ["y"] = 9, ["param1"] = 15, ["z"] = 68, ["name"] = "rainbow:stoneblock_white"}, {["x"] = 4, ["meta"] = {["fields"] = {}, ["inventory"] = {}}, ["y"] = 10, ["param1"] = 15, ["z"] = 44, ["name"] = "rainbow:stoneblock_white"}, {["x"] = 4, ["meta"] = {["fields"] = {}, ["inventory"] = {}}, ["y"] = 10, ["param1"] = 15, ["z"] = 45, ["name"] = "rainbow:stoneblock_white"}, {["x"] = 4, ["meta"] = {["fields"] = {}, ["inventory"] = {}}, ["y"] = 10, ["param1"] = 15, ["z"] = 69, ["name"] = "rainbow:stoneblock_white"}, {["x"] = 4, ["meta"] = {["fields"] = {}, ["inventory"] = {}}, ["y"] = 10, ["param1"] = 15, ["z"] = 70, ["name"] = "rainbow:stoneblock_white"}, {["x"] = 4, ["meta"] = {["fields"] = {}, ["inventory"] = {}}, ["y"] = 11, ["param1"] = 15, ["z"] = 44, ["name"] = "rainbow:stoneblock_white"}, {["x"] = 4, ["meta"] = {["fields"] = {}, ["inventory"] = {}}, ["y"] = 11, ["param1"] = 15, ["z"] = 45, ["name"] = "rainbow:stoneblock_white"}, {["x"] = 4, ["meta"] = {["fields"] = {}, ["inventory"] = {}}, ["y"] = 11, ["param1"] = 15, ["z"] = 69, ["name"] = "rainbow:stoneblock_white"}, {["x"] = 4, ["meta"] = {["fields"] = {}, ["inventory"] = {}}, ["y"] = 11, ["param1"] = 15, ["z"] = 70, ["name"] = "rainbow:stoneblock_white"}, {["x"] = 4, ["meta"] = {["fields"] = {}, ["inventory"] = {}}, ["y"] = 12, ["param1"] = 15, ["z"] = 44, ["name"] = "rainbow:stoneblock_white"}, {["x"] = 4, ["meta"] = {["fields"] = {}, ["inventory"] = {}}, ["y"] = 12, ["param1"] = 15, ["z"] = 45, ["name"] = "rainbow:stoneblock_white"}, {["x"] = 4, ["meta"] = {["fields"] = {}, ["inventory"] = {}}, ["y"] = 12, ["param1"] = 15, ["z"] = 69, ["name"] = "rainbow:stoneblock_white"}, {["x"] = 4, ["meta"] = {["fields"] = {}, ["inventory"] = {}}, ["y"] = 12, ["param1"] = 15, ["z"] = 70, ["name"] = "rainbow:stoneblock_white"}, {["x"] = 4, ["meta"] = {["fields"] = {}, ["inventory"] = {}}, ["y"] = 13, ["param1"] = 15, ["z"] = 44, ["name"] = "rainbow:stoneblock_white"}, {["x"] = 4, ["meta"] = {["fields"] = {}, ["inventory"] = {}}, ["y"] = 13, ["param1"] = 15, ["z"] = 45, ["name"] = "rainbow:stoneblock_white"}, {["x"] = 4, ["meta"] = {["fields"] = {}, ["inventory"] = {}}, ["y"] = 13, ["param1"] = 15, ["z"] = 69, ["name"] = "rainbow:stoneblock_white"}, {["x"] = 4, ["meta"] = {["fields"] = {}, ["inventory"] = {}}, ["y"] = 13, ["param1"] = 15, ["z"] = 70, ["name"] = "rainbow:stoneblock_white"}, {["x"] = 4, ["meta"] = {["fields"] = {}, ["inventory"] = {}}, ["y"] = 14, ["param1"] = 15, ["z"] = 44, ["name"] = "rainbow:stoneblock_white"}, {["x"] = 4, ["meta"] = {["fields"] = {}, ["inventory"] = {}}, ["y"] = 14, ["param1"] = 15, ["z"] = 45, ["name"] = "rainbow:stoneblock_white"}, {["x"] = 4, ["meta"] = {["fields"] = {}, ["inventory"] = {}}, ["y"] = 14, ["param1"] = 15, ["z"] = 69, ["name"] = "rainbow:stoneblock_white"}, {["x"] = 4, ["meta"] = {["fields"] = {}, ["inventory"] = {}}, ["y"] = 14, ["param1"] = 15, ["z"] = 70, ["name"] = "rainbow:stoneblock_white"}, {["x"] = 4, ["meta"] = {["fields"] = {}, ["inventory"] = {}}, ["y"] = 15, ["param1"] = 15, ["z"] = 46, ["name"] = "rainbow:stoneblock_white"}, {["x"] = 4, ["meta"] = {["fields"] = {}, ["inventory"] = {}}, ["y"] = 15, ["param1"] = 15, ["z"] = 47, ["name"] = "rainbow:stoneblock_white"}, {["x"] = 4, ["meta"] = {["fields"] = {}, ["inventory"] = {}}, ["y"] = 15, ["param1"] = 15, ["z"] = 67, ["name"] = "rainbow:stoneblock_white"}, {["x"] = 4, ["meta"] = {["fields"] = {}, ["inventory"] = {}}, ["y"] = 15, ["param1"] = 15, ["z"] = 68, ["name"] = "rainbow:stoneblock_white"}, {["x"] = 4, ["meta"] = {["fields"] = {}, ["inventory"] = {}}, ["y"] = 16, ["param1"] = 15, ["z"] = 46, ["name"] = "rainbow:stoneblock_white"}, {["x"] = 4, ["meta"] = {["fields"] = {}, ["inventory"] = {}}, ["y"] = 16, ["param1"] = 15, ["z"] = 47, ["name"] = "rainbow:stoneblock_white"}, {["x"] = 4, ["meta"] = {["fields"] = {}, ["inventory"] = {}}, ["y"] = 16, ["param1"] = 15, ["z"] = 67, ["name"] = "rainbow:stoneblock_white"}, {["x"] = 4, ["meta"] = {["fields"] = {}, ["inventory"] = {}}, ["y"] = 16, ["param1"] = 15, ["z"] = 68, ["name"] = "rainbow:stoneblock_white"}, {["x"] = 4, ["meta"] = {["fields"] = {}, ["inventory"] = {}}, ["y"] = 17, ["param1"] = 15, ["z"] = 46, ["name"] = "rainbow:stoneblock_white"}, {["x"] = 4, ["meta"] = {["fields"] = {}, ["inventory"] = {}}, ["y"] = 17, ["param1"] = 15, ["z"] = 47, ["name"] = "rainbow:stoneblock_white"}, {["x"] = 4, ["meta"] = {["fields"] = {}, ["inventory"] = {}}, ["y"] = 17, ["param1"] = 15, ["z"] = 67, ["name"] = "rainbow:stoneblock_white"}, {["x"] = 4, ["meta"] = {["fields"] = {}, ["inventory"] = {}}, ["y"] = 17, ["param1"] = 15, ["z"] = 68, ["name"] = "rainbow:stoneblock_white"}, {["x"] = 4, ["meta"] = {["fields"] = {}, ["inventory"] = {}}, ["y"] = 18, ["param1"] = 15, ["z"] = 48, ["name"] = "rainbow:stoneblock_white"}, {["x"] = 4, ["meta"] = {["fields"] = {}, ["inventory"] = {}}, ["y"] = 18, ["param1"] = 15, ["z"] = 49, ["name"] = "rainbow:stoneblock_white"}, {["x"] = 4, ["meta"] = {["fields"] = {}, ["inventory"] = {}}, ["y"] = 18, ["param1"] = 13, ["z"] = 50, ["name"] = "rainbow:stoneblock_white"}, {["x"] = 4, ["meta"] = {["fields"] = {}, ["inventory"] = {}}, ["y"] = 18, ["param1"] = 12, ["z"] = 51, ["name"] = "rainbow:stoneblock_white"}, {["x"] = 4, ["meta"] = {["fields"] = {}, ["inventory"] = {}}, ["y"] = 18, ["param1"] = 11, ["z"] = 52, ["name"] = "rainbow:stoneblock_white"}, {["x"] = 4, ["meta"] = {["fields"] = {}, ["inventory"] = {}}, ["y"] = 18, ["param1"] = 11, ["z"] = 62, ["name"] = "rainbow:stoneblock_white"}, {["x"] = 4, ["meta"] = {["fields"] = {}, ["inventory"] = {}}, ["y"] = 18, ["param1"] = 12, ["z"] = 63, ["name"] = "rainbow:stoneblock_white"}, {["x"] = 4, ["meta"] = {["fields"] = {}, ["inventory"] = {}}, ["y"] = 18, ["param1"] = 13, ["z"] = 64, ["name"] = "rainbow:stoneblock_white"}, {["x"] = 4, ["meta"] = {["fields"] = {}, ["inventory"] = {}}, ["y"] = 18, ["param1"] = 15, ["z"] = 65, ["name"] = "rainbow:stoneblock_white"}, {["x"] = 4, ["meta"] = {["fields"] = {}, ["inventory"] = {}}, ["y"] = 18, ["param1"] = 15, ["z"] = 66, ["name"] = "rainbow:stoneblock_white"}, {["x"] = 4, ["meta"] = {["fields"] = {}, ["inventory"] = {}}, ["y"] = 19, ["param1"] = 11, ["z"] = 52, ["name"] = "rainbow:stoneblock_white"}, {["x"] = 4, ["meta"] = {["fields"] = {}, ["inventory"] = {}}, ["y"] = 19, ["param1"] = 11, ["z"] = 62, ["name"] = "rainbow:stoneblock_white"}, {["x"] = 4, ["meta"] = {["fields"] = {}, ["inventory"] = {}}, ["y"] = 20, ["param1"] = 11, ["z"] = 52, ["name"] = "rainbow:stoneblock_white"}, {["x"] = 4, ["meta"] = {["fields"] = {}, ["inventory"] = {}}, ["y"] = 20, ["param1"] = 11, ["z"] = 62, ["name"] = "rainbow:stoneblock_white"}, {["x"] = 4, ["meta"] = {["fields"] = {}, ["inventory"] = {}}, ["y"] = 21, ["param1"] = 15, ["z"] = 50, ["name"] = "rainbow:stoneblock_white"}, {["x"] = 4, ["meta"] = {["fields"] = {}, ["inventory"] = {}}, ["y"] = 21, ["param1"] = 15, ["z"] = 51, ["name"] = "rainbow:stoneblock_white"}, {["x"] = 4, ["meta"] = {["fields"] = {}, ["inventory"] = {}}, ["y"] = 21, ["param1"] = 15, ["z"] = 52, ["name"] = "rainbow:stoneblock_white"}, {["x"] = 4, ["meta"] = {["fields"] = {}, ["inventory"] = {}}, ["y"] = 21, ["param1"] = 15, ["z"] = 53, ["name"] = "rainbow:stoneblock_white"}, {["x"] = 4, ["meta"] = {["fields"] = {}, ["inventory"] = {}}, ["y"] = 21, ["param1"] = 15, ["z"] = 54, ["name"] = "rainbow:stoneblock_white"}, {["x"] = 4, ["meta"] = {["fields"] = {}, ["inventory"] = {}}, ["y"] = 21, ["param1"] = 15, ["z"] = 55, ["name"] = "rainbow:stoneblock_white"}, {["x"] = 4, ["meta"] = {["fields"] = {}, ["inventory"] = {}}, ["y"] = 21, ["param1"] = 15, ["z"] = 56, ["name"] = "rainbow:stoneblock_white"}, {["x"] = 4, ["meta"] = {["fields"] = {}, ["inventory"] = {}}, ["y"] = 21, ["param1"] = 15, ["z"] = 57, ["name"] = "rainbow:stoneblock_white"}, {["x"] = 4, ["meta"] = {["fields"] = {}, ["inventory"] = {}}, ["y"] = 21, ["param1"] = 15, ["z"] = 58, ["name"] = "rainbow:stoneblock_white"}, {["x"] = 4, ["meta"] = {["fields"] = {}, ["inventory"] = {}}, ["y"] = 21, ["param1"] = 15, ["z"] = 59, ["name"] = "rainbow:stoneblock_white"}, {["x"] = 4, ["meta"] = {["fields"] = {}, ["inventory"] = {}}, ["y"] = 21, ["param1"] = 15, ["z"] = 60, ["name"] = "rainbow:stoneblock_white"}, {["x"] = 4, ["meta"] = {["fields"] = {}, ["inventory"] = {}}, ["y"] = 21, ["param1"] = 15, ["z"] = 61, ["name"] = "rainbow:stoneblock_white"}, {["x"] = 4, ["meta"] = {["fields"] = {}, ["inventory"] = {}}, ["y"] = 21, ["param1"] = 15, ["z"] = 62, ["name"] = "rainbow:stoneblock_white"}, {["x"] = 4, ["meta"] = {["fields"] = {}, ["inventory"] = {}}, ["y"] = 21, ["param1"] = 15, ["z"] = 63, ["name"] = "rainbow:stoneblock_white"}, {["x"] = 4, ["meta"] = {["fields"] = {}, ["inventory"] = {}}, ["y"] = 21, ["param1"] = 15, ["z"] = 64, ["name"] = "rainbow:stoneblock_white"}, {["x"] = 5, ["meta"] = {["fields"] = {}, ["inventory"] = {}}, ["y"] = 2, ["param1"] = 15, ["z"] = 50, ["name"] = "rainbow:stoneblock_white"}, {["x"] = 5, ["meta"] = {["fields"] = {}, ["inventory"] = {}}, ["y"] = 2, ["param1"] = 15, ["z"] = 51, ["name"] = "rainbow:stoneblock_white"}, {["x"] = 5, ["meta"] = {["fields"] = {}, ["inventory"] = {}}, ["y"] = 2, ["param1"] = 15, ["z"] = 52, ["name"] = "rainbow:stoneblock_white"}, {["x"] = 5, ["meta"] = {["fields"] = {}, ["inventory"] = {}}, ["y"] = 2, ["param1"] = 15, ["z"] = 53, ["name"] = "rainbow:stoneblock_white"}, {["x"] = 5, ["meta"] = {["fields"] = {}, ["inventory"] = {}}, ["y"] = 2, ["param1"] = 15, ["z"] = 54, ["name"] = "rainbow:stoneblock_white"}, {["x"] = 5, ["meta"] = {["fields"] = {}, ["inventory"] = {}}, ["y"] = 2, ["param1"] = 15, ["z"] = 55, ["name"] = "rainbow:stoneblock_white"}, {["x"] = 5, ["meta"] = {["fields"] = {}, ["inventory"] = {}}, ["y"] = 2, ["param1"] = 15, ["z"] = 56, ["name"] = "rainbow:stoneblock_white"}, {["x"] = 5, ["meta"] = {["fields"] = {}, ["inventory"] = {}}, ["y"] = 2, ["param1"] = 15, ["z"] = 57, ["name"] = "rainbow:stoneblock_white"}, {["x"] = 5, ["meta"] = {["fields"] = {}, ["inventory"] = {}}, ["y"] = 2, ["param1"] = 15, ["z"] = 58, ["name"] = "rainbow:stoneblock_white"}, {["x"] = 5, ["meta"] = {["fields"] = {}, ["inventory"] = {}}, ["y"] = 2, ["param1"] = 15, ["z"] = 59, ["name"] = "rainbow:stoneblock_white"}, {["x"] = 5, ["meta"] = {["fields"] = {}, ["inventory"] = {}}, ["y"] = 2, ["param1"] = 15, ["z"] = 60, ["name"] = "rainbow:stoneblock_white"}, {["x"] = 5, ["meta"] = {["fields"] = {}, ["inventory"] = {}}, ["y"] = 2, ["param1"] = 15, ["z"] = 61, ["name"] = "rainbow:stoneblock_white"}, {["x"] = 5, ["meta"] = {["fields"] = {}, ["inventory"] = {}}, ["y"] = 2, ["param1"] = 15, ["z"] = 62, ["name"] = "rainbow:stoneblock_white"}, {["x"] = 5, ["meta"] = {["fields"] = {}, ["inventory"] = {}}, ["y"] = 2, ["param1"] = 15, ["z"] = 63, ["name"] = "rainbow:stoneblock_white"}, {["x"] = 5, ["meta"] = {["fields"] = {}, ["inventory"] = {}}, ["y"] = 2, ["param1"] = 15, ["z"] = 64, ["name"] = "rainbow:stoneblock_white"}, {["x"] = 5, ["meta"] = {["fields"] = {}, ["inventory"] = {}}, ["y"] = 3, ["param1"] = 11, ["z"] = 52, ["name"] = "rainbow:stoneblock_white"}, {["x"] = 5, ["meta"] = {["fields"] = {}, ["inventory"] = {}}, ["y"] = 3, ["param1"] = 8, ["z"] = 62, ["name"] = "rainbow:stoneblock_white"}, {["x"] = 5, ["meta"] = {["fields"] = {}, ["inventory"] = {}}, ["y"] = 4, ["param1"] = 11, ["z"] = 52, ["name"] = "rainbow:stoneblock_white"}, {["x"] = 5, ["meta"] = {["fields"] = {}, ["inventory"] = {}}, ["y"] = 4, ["param1"] = 8, ["z"] = 62, ["name"] = "rainbow:stoneblock_white"}, {["x"] = 5, ["meta"] = {["fields"] = {}, ["inventory"] = {}}, ["y"] = 5, ["param1"] = 15, ["z"] = 48, ["name"] = "rainbow:stoneblock_white"}, {["x"] = 5, ["meta"] = {["fields"] = {}, ["inventory"] = {}}, ["y"] = 5, ["param1"] = 15, ["z"] = 49, ["name"] = "rainbow:stoneblock_white"}, {["x"] = 5, ["meta"] = {["fields"] = {}, ["inventory"] = {}}, ["y"] = 5, ["param1"] = 13, ["z"] = 50, ["name"] = "rainbow:stoneblock_white"}, {["x"] = 5, ["meta"] = {["fields"] = {}, ["inventory"] = {}}, ["y"] = 5, ["param1"] = 12, ["z"] = 51, ["name"] = "rainbow:stoneblock_white"}, {["x"] = 5, ["meta"] = {["fields"] = {}, ["inventory"] = {}}, ["y"] = 5, ["param1"] = 11, ["z"] = 52, ["name"] = "rainbow:stoneblock_white"}, {["x"] = 5, ["meta"] = {["fields"] = {}, ["inventory"] = {}}, ["y"] = 5, ["param1"] = 11, ["z"] = 62, ["name"] = "rainbow:stoneblock_white"}, {["x"] = 5, ["meta"] = {["fields"] = {}, ["inventory"] = {}}, ["y"] = 5, ["param1"] = 12, ["z"] = 63, ["name"] = "rainbow:stoneblock_white"}, {["x"] = 5, ["meta"] = {["fields"] = {}, ["inventory"] = {}}, ["y"] = 5, ["param1"] = 13, ["z"] = 64, ["name"] = "rainbow:stoneblock_white"}, {["x"] = 5, ["meta"] = {["fields"] = {}, ["inventory"] = {}}, ["y"] = 5, ["param1"] = 15, ["z"] = 65, ["name"] = "rainbow:stoneblock_white"}, {["x"] = 5, ["meta"] = {["fields"] = {}, ["inventory"] = {}}, ["y"] = 5, ["param1"] = 31, ["z"] = 66, ["name"] = "rainbow:stoneblock_white"}, {["x"] = 5, ["meta"] = {["fields"] = {}, ["inventory"] = {}}, ["y"] = 6, ["param1"] = 15, ["z"] = 46, ["name"] = "rainbow:stoneblock_white"}, {["x"] = 5, ["meta"] = {["fields"] = {}, ["inventory"] = {}}, ["y"] = 6, ["param1"] = 15, ["z"] = 47, ["name"] = "rainbow:stoneblock_white"}, {["x"] = 5, ["meta"] = {["fields"] = {}, ["inventory"] = {}}, ["y"] = 6, ["param1"] = 15, ["z"] = 67, ["name"] = "rainbow:stoneblock_white"}, {["x"] = 5, ["meta"] = {["fields"] = {}, ["inventory"] = {}}, ["y"] = 6, ["param1"] = 15, ["z"] = 68, ["name"] = "rainbow:stoneblock_white"}, {["x"] = 5, ["meta"] = {["fields"] = {}, ["inventory"] = {}}, ["y"] = 7, ["param1"] = 15, ["z"] = 46, ["name"] = "rainbow:stoneblock_white"}, {["x"] = 5, ["meta"] = {["fields"] = {}, ["inventory"] = {}}, ["y"] = 7, ["param1"] = 15, ["z"] = 47, ["name"] = "rainbow:stoneblock_white"}, {["x"] = 5, ["meta"] = {["fields"] = {}, ["inventory"] = {}}, ["y"] = 7, ["param1"] = 15, ["z"] = 67, ["name"] = "rainbow:stoneblock_white"}, {["x"] = 5, ["meta"] = {["fields"] = {}, ["inventory"] = {}}, ["y"] = 7, ["param1"] = 15, ["z"] = 68, ["name"] = "rainbow:stoneblock_white"}, {["x"] = 5, ["meta"] = {["fields"] = {}, ["inventory"] = {}}, ["y"] = 8, ["param1"] = 15, ["z"] = 44, ["name"] = "rainbow:stoneblock_white"}, {["x"] = 5, ["meta"] = {["fields"] = {}, ["inventory"] = {}}, ["y"] = 8, ["param1"] = 15, ["z"] = 45, ["name"] = "rainbow:stoneblock_white"}, {["x"] = 5, ["meta"] = {["fields"] = {}, ["inventory"] = {}}, ["y"] = 8, ["param1"] = 15, ["z"] = 69, ["name"] = "rainbow:stoneblock_white"}, {["x"] = 5, ["meta"] = {["fields"] = {}, ["inventory"] = {}}, ["y"] = 8, ["param1"] = 15, ["z"] = 70, ["name"] = "rainbow:stoneblock_white"}, {["x"] = 5, ["meta"] = {["fields"] = {}, ["inventory"] = {}}, ["y"] = 9, ["param1"] = 15, ["z"] = 44, ["name"] = "rainbow:stoneblock_white"}, {["x"] = 5, ["meta"] = {["fields"] = {}, ["inventory"] = {}}, ["y"] = 9, ["param1"] = 15, ["z"] = 45, ["name"] = "rainbow:stoneblock_white"}, {["x"] = 5, ["meta"] = {["fields"] = {}, ["inventory"] = {}}, ["y"] = 9, ["param1"] = 15, ["z"] = 69, ["name"] = "rainbow:stoneblock_white"}, {["x"] = 5, ["meta"] = {["fields"] = {}, ["inventory"] = {}}, ["y"] = 9, ["param1"] = 15, ["z"] = 70, ["name"] = "rainbow:stoneblock_white"}, {["x"] = 5, ["meta"] = {["fields"] = {}, ["inventory"] = {}}, ["y"] = 10, ["param1"] = 15, ["z"] = 42, ["name"] = "rainbow:stoneblock_white"}, {["x"] = 5, ["meta"] = {["fields"] = {}, ["inventory"] = {}}, ["y"] = 10, ["param1"] = 15, ["z"] = 43, ["name"] = "rainbow:stoneblock_white"}, {["x"] = 5, ["meta"] = {["fields"] = {}, ["inventory"] = {}}, ["y"] = 10, ["param1"] = 15, ["z"] = 71, ["name"] = "rainbow:stoneblock_white"}, {["x"] = 5, ["meta"] = {["fields"] = {}, ["inventory"] = {}}, ["y"] = 10, ["param1"] = 15, ["z"] = 72, ["name"] = "rainbow:stoneblock_white"}, {["x"] = 5, ["meta"] = {["fields"] = {}, ["inventory"] = {}}, ["y"] = 10, ["param1"] = 15, ["z"] = 78, ["name"] = "rainbow:stoneblock_white"}, {["x"] = 5, ["meta"] = {["fields"] = {}, ["inventory"] = {}}, ["y"] = 10, ["z"] = 79, ["name"] = "rainbow:stoneblock_red"}, {["x"] = 5, ["meta"] = {["fields"] = {}, ["inventory"] = {}}, ["y"] = 10, ["param1"] = 15, ["z"] = 80, ["name"] = "rainbow:stoneblock_white"}, {["x"] = 5, ["meta"] = {["fields"] = {}, ["inventory"] = {}}, ["y"] = 10, ["param1"] = 15, ["z"] = 81, ["name"] = "rainbow:stoneblock_white"}, {["x"] = 5, ["meta"] = {["fields"] = {}, ["inventory"] = {}}, ["y"] = 10, ["param1"] = 15, ["z"] = 82, ["name"] = "rainbow:stoneblock_white"}, {["x"] = 5, ["meta"] = {["fields"] = {}, ["inventory"] = {}}, ["y"] = 10, ["param1"] = 15, ["z"] = 83, ["name"] = "rainbow:stoneblock_white"}, {["x"] = 5, ["meta"] = {["fields"] = {}, ["inventory"] = {}}, ["y"] = 10, ["param1"] = 15, ["z"] = 84, ["name"] = "rainbow:stoneblock_white"}, {["x"] = 5, ["meta"] = {["fields"] = {}, ["inventory"] = {}}, ["y"] = 10, ["param1"] = 15, ["z"] = 85, ["name"] = "rainbow:stoneblock_white"}, {["x"] = 5, ["meta"] = {["fields"] = {}, ["inventory"] = {}}, ["y"] = 10, ["param1"] = 15, ["z"] = 86, ["name"] = "rainbow:stoneblock_white"}, {["x"] = 5, ["meta"] = {["fields"] = {}, ["inventory"] = {}}, ["y"] = 10, ["param1"] = 15, ["z"] = 87, ["name"] = "rainbow:stoneblock_white"}, {["x"] = 5, ["meta"] = {["fields"] = {}, ["inventory"] = {}}, ["y"] = 10, ["param1"] = 15, ["z"] = 88, ["name"] = "rainbow:stoneblock_white"}, {["x"] = 5, ["meta"] = {["fields"] = {}, ["inventory"] = {}}, ["y"] = 10, ["param1"] = 15, ["z"] = 89, ["name"] = "rainbow:stoneblock_white"}, {["x"] = 5, ["meta"] = {["fields"] = {}, ["inventory"] = {}}, ["y"] = 10, ["param1"] = 15, ["z"] = 90, ["name"] = "rainbow:stoneblock_white"}, {["x"] = 5, ["meta"] = {["fields"] = {}, ["inventory"] = {}}, ["y"] = 11, ["param1"] = 15, ["z"] = 42, ["name"] = "rainbow:stoneblock_white"}, {["x"] = 5, ["meta"] = {["fields"] = {}, ["inventory"] = {}}, ["y"] = 11, ["param1"] = 15, ["z"] = 43, ["name"] = "rainbow:stoneblock_white"}, {["x"] = 5, ["meta"] = {["fields"] = {}, ["inventory"] = {}}, ["y"] = 11, ["param1"] = 15, ["z"] = 71, ["name"] = "rainbow:stoneblock_white"}, {["x"] = 5, ["meta"] = {["fields"] = {}, ["inventory"] = {}}, ["y"] = 11, ["param1"] = 15, ["z"] = 72, ["name"] = "rainbow:stoneblock_white"}, {["x"] = 5, ["meta"] = {["fields"] = {}, ["inventory"] = {}}, ["y"] = 11, ["param1"] = 15, ["z"] = 78, ["name"] = "rainbow:stoneblock_white"}, {["x"] = 5, ["meta"] = {["fields"] = {}, ["inventory"] = {}}, ["y"] = 11, ["z"] = 79, ["name"] = "rainbow:stoneblock_red"}, {["x"] = 5, ["meta"] = {["fields"] = {}, ["inventory"] = {}}, ["y"] = 11, ["param1"] = 15, ["z"] = 80, ["name"] = "rainbow:stoneblock_white"}, {["x"] = 5, ["meta"] = {["fields"] = {}, ["inventory"] = {}}, ["y"] = 11, ["param1"] = 15, ["z"] = 81, ["name"] = "rainbow:stoneblock_white"}, {["x"] = 5, ["meta"] = {["fields"] = {}, ["inventory"] = {}}, ["y"] = 11, ["param1"] = 15, ["z"] = 82, ["name"] = "rainbow:stoneblock_white"}, {["x"] = 5, ["meta"] = {["fields"] = {}, ["inventory"] = {}}, ["y"] = 11, ["param1"] = 15, ["z"] = 83, ["name"] = "rainbow:stoneblock_white"}, {["x"] = 5, ["meta"] = {["fields"] = {}, ["inventory"] = {}}, ["y"] = 11, ["param1"] = 15, ["z"] = 84, ["name"] = "rainbow:stoneblock_white"}, {["x"] = 5, ["meta"] = {["fields"] = {}, ["inventory"] = {}}, ["y"] = 11, ["param1"] = 15, ["z"] = 85, ["name"] = "rainbow:stoneblock_white"}, {["x"] = 5, ["meta"] = {["fields"] = {}, ["inventory"] = {}}, ["y"] = 11, ["param1"] = 15, ["z"] = 86, ["name"] = "rainbow:stoneblock_white"}, {["x"] = 5, ["meta"] = {["fields"] = {}, ["inventory"] = {}}, ["y"] = 11, ["param1"] = 15, ["z"] = 87, ["name"] = "rainbow:stoneblock_white"}, {["x"] = 5, ["meta"] = {["fields"] = {}, ["inventory"] = {}}, ["y"] = 11, ["param1"] = 15, ["z"] = 88, ["name"] = "rainbow:stoneblock_white"}, {["x"] = 5, ["meta"] = {["fields"] = {}, ["inventory"] = {}}, ["y"] = 11, ["param1"] = 15, ["z"] = 89, ["name"] = "rainbow:stoneblock_white"}, {["x"] = 5, ["meta"] = {["fields"] = {}, ["inventory"] = {}}, ["y"] = 11, ["param1"] = 15, ["z"] = 90, ["name"] = "rainbow:stoneblock_white"}, {["x"] = 5, ["meta"] = {["fields"] = {}, ["inventory"] = {}}, ["y"] = 12, ["param1"] = 15, ["z"] = 42, ["name"] = "rainbow:stoneblock_white"}, {["x"] = 5, ["meta"] = {["fields"] = {}, ["inventory"] = {}}, ["y"] = 12, ["param1"] = 15, ["z"] = 43, ["name"] = "rainbow:stoneblock_white"}, {["x"] = 5, ["meta"] = {["fields"] = {}, ["inventory"] = {}}, ["y"] = 12, ["param1"] = 15, ["z"] = 71, ["name"] = "rainbow:stoneblock_white"}, {["x"] = 5, ["meta"] = {["fields"] = {}, ["inventory"] = {}}, ["y"] = 12, ["param1"] = 15, ["z"] = 72, ["name"] = "rainbow:stoneblock_white"}, {["x"] = 5, ["meta"] = {["fields"] = {}, ["inventory"] = {}}, ["y"] = 12, ["param1"] = 15, ["z"] = 78, ["name"] = "rainbow:stoneblock_white"}, {["x"] = 5, ["meta"] = {["fields"] = {}, ["inventory"] = {}}, ["y"] = 12, ["z"] = 79, ["name"] = "rainbow:stoneblock_red"}, {["x"] = 5, ["meta"] = {["fields"] = {}, ["inventory"] = {}}, ["y"] = 12, ["param1"] = 31, ["z"] = 80, ["name"] = "rainbow:stoneblock_white"}, {["x"] = 5, ["meta"] = {["fields"] = {}, ["inventory"] = {}}, ["y"] = 12, ["param1"] = 15, ["z"] = 81, ["name"] = "rainbow:stoneblock_white"}, {["x"] = 5, ["meta"] = {["fields"] = {}, ["inventory"] = {}}, ["y"] = 12, ["param1"] = 15, ["z"] = 82, ["name"] = "rainbow:stoneblock_white"}, {["x"] = 5, ["meta"] = {["fields"] = {}, ["inventory"] = {}}, ["y"] = 12, ["param1"] = 15, ["z"] = 83, ["name"] = "rainbow:stoneblock_white"}, {["x"] = 5, ["meta"] = {["fields"] = {}, ["inventory"] = {}}, ["y"] = 12, ["param1"] = 15, ["z"] = 84, ["name"] = "rainbow:stoneblock_white"}, {["x"] = 5, ["meta"] = {["fields"] = {}, ["inventory"] = {}}, ["y"] = 12, ["param1"] = 15, ["z"] = 85, ["name"] = "rainbow:stoneblock_white"}, {["x"] = 5, ["meta"] = {["fields"] = {}, ["inventory"] = {}}, ["y"] = 12, ["param1"] = 15, ["z"] = 86, ["name"] = "rainbow:stoneblock_white"}, {["x"] = 5, ["meta"] = {["fields"] = {}, ["inventory"] = {}}, ["y"] = 12, ["param1"] = 15, ["z"] = 87, ["name"] = "rainbow:stoneblock_white"}, {["x"] = 5, ["meta"] = {["fields"] = {}, ["inventory"] = {}}, ["y"] = 12, ["param1"] = 15, ["z"] = 88, ["name"] = "rainbow:stoneblock_white"}, {["x"] = 5, ["meta"] = {["fields"] = {}, ["inventory"] = {}}, ["y"] = 12, ["param1"] = 15, ["z"] = 89, ["name"] = "rainbow:stoneblock_white"}, {["x"] = 5, ["meta"] = {["fields"] = {}, ["inventory"] = {}}, ["y"] = 12, ["param1"] = 31, ["z"] = 90, ["name"] = "rainbow:stoneblock_white"}, {["x"] = 5, ["meta"] = {["fields"] = {}, ["inventory"] = {}}, ["y"] = 13, ["param1"] = 15, ["z"] = 42, ["name"] = "rainbow:stoneblock_white"}, {["x"] = 5, ["meta"] = {["fields"] = {}, ["inventory"] = {}}, ["y"] = 13, ["param1"] = 15, ["z"] = 43, ["name"] = "rainbow:stoneblock_white"}, {["x"] = 5, ["meta"] = {["fields"] = {}, ["inventory"] = {}}, ["y"] = 13, ["param1"] = 15, ["z"] = 71, ["name"] = "rainbow:stoneblock_white"}, {["x"] = 5, ["meta"] = {["fields"] = {}, ["inventory"] = {}}, ["y"] = 13, ["param1"] = 15, ["z"] = 72, ["name"] = "rainbow:stoneblock_white"}, {["x"] = 5, ["meta"] = {["fields"] = {}, ["inventory"] = {}}, ["y"] = 13, ["param1"] = 15, ["z"] = 78, ["name"] = "rainbow:stoneblock_white"}, {["x"] = 5, ["meta"] = {["fields"] = {}, ["inventory"] = {}}, ["y"] = 13, ["z"] = 79, ["name"] = "rainbow:stoneblock_red"}, {["x"] = 5, ["meta"] = {["fields"] = {}, ["inventory"] = {}}, ["y"] = 13, ["param1"] = 47, ["z"] = 80, ["name"] = "rainbow:stoneblock_white"}, {["x"] = 5, ["meta"] = {["fields"] = {}, ["inventory"] = {}}, ["y"] = 13, ["param1"] = 31, ["z"] = 81, ["name"] = "rainbow:stoneblock_white"}, {["x"] = 5, ["meta"] = {["fields"] = {}, ["inventory"] = {}}, ["y"] = 13, ["param1"] = 15, ["z"] = 82, ["name"] = "rainbow:stoneblock_white"}, {["x"] = 5, ["meta"] = {["fields"] = {}, ["inventory"] = {}}, ["y"] = 13, ["param1"] = 15, ["z"] = 83, ["name"] = "rainbow:stoneblock_white"}, {["x"] = 5, ["meta"] = {["fields"] = {}, ["inventory"] = {}}, ["y"] = 13, ["param1"] = 15, ["z"] = 84, ["name"] = "rainbow:stoneblock_white"}, {["x"] = 5, ["meta"] = {["fields"] = {}, ["inventory"] = {}}, ["y"] = 13, ["param1"] = 15, ["z"] = 85, ["name"] = "rainbow:stoneblock_white"}, {["x"] = 5, ["meta"] = {["fields"] = {}, ["inventory"] = {}}, ["y"] = 13, ["param1"] = 15, ["z"] = 86, ["name"] = "rainbow:stoneblock_white"}, {["x"] = 5, ["meta"] = {["fields"] = {}, ["inventory"] = {}}, ["y"] = 13, ["param1"] = 15, ["z"] = 87, ["name"] = "rainbow:stoneblock_white"}, {["x"] = 5, ["meta"] = {["fields"] = {}, ["inventory"] = {}}, ["y"] = 13, ["param1"] = 15, ["z"] = 88, ["name"] = "rainbow:stoneblock_white"}, {["x"] = 5, ["meta"] = {["fields"] = {}, ["inventory"] = {}}, ["y"] = 13, ["param1"] = 15, ["z"] = 89, ["name"] = "rainbow:stoneblock_white"}, {["x"] = 5, ["meta"] = {["fields"] = {}, ["inventory"] = {}}, ["y"] = 13, ["param1"] = 47, ["z"] = 90, ["name"] = "rainbow:stoneblock_white"}, {["x"] = 5, ["meta"] = {["fields"] = {}, ["inventory"] = {}}, ["y"] = 14, ["param1"] = 15, ["z"] = 42, ["name"] = "rainbow:stoneblock_white"}, {["x"] = 5, ["meta"] = {["fields"] = {}, ["inventory"] = {}}, ["y"] = 14, ["param1"] = 15, ["z"] = 43, ["name"] = "rainbow:stoneblock_white"}, {["x"] = 5, ["meta"] = {["fields"] = {}, ["inventory"] = {}}, ["y"] = 14, ["param1"] = 15, ["z"] = 71, ["name"] = "rainbow:stoneblock_white"}, {["x"] = 5, ["meta"] = {["fields"] = {}, ["inventory"] = {}}, ["y"] = 14, ["param1"] = 15, ["z"] = 72, ["name"] = "rainbow:stoneblock_white"}, {["x"] = 5, ["meta"] = {["fields"] = {}, ["inventory"] = {}}, ["y"] = 14, ["param1"] = 15, ["z"] = 78, ["name"] = "rainbow:stoneblock_white"}, {["x"] = 5, ["meta"] = {["fields"] = {}, ["inventory"] = {}}, ["y"] = 14, ["z"] = 79, ["name"] = "rainbow:stoneblock_red"}, {["x"] = 5, ["meta"] = {["fields"] = {}, ["inventory"] = {}}, ["y"] = 14, ["param1"] = 63, ["z"] = 80, ["name"] = "rainbow:stoneblock_white"}, {["x"] = 5, ["meta"] = {["fields"] = {}, ["inventory"] = {}}, ["y"] = 14, ["param1"] = 47, ["z"] = 81, ["name"] = "rainbow:stoneblock_white"}, {["x"] = 5, ["meta"] = {["fields"] = {}, ["inventory"] = {}}, ["y"] = 14, ["param1"] = 31, ["z"] = 82, ["name"] = "rainbow:stoneblock_white"}, {["x"] = 5, ["meta"] = {["fields"] = {}, ["inventory"] = {}}, ["y"] = 14, ["param1"] = 15, ["z"] = 83, ["name"] = "rainbow:stoneblock_white"}, {["x"] = 5, ["meta"] = {["fields"] = {}, ["inventory"] = {}}, ["y"] = 14, ["param1"] = 15, ["z"] = 84, ["name"] = "rainbow:stoneblock_white"}, {["x"] = 5, ["meta"] = {["fields"] = {}, ["inventory"] = {}}, ["y"] = 14, ["param1"] = 15, ["z"] = 85, ["name"] = "rainbow:stoneblock_white"}, {["x"] = 5, ["meta"] = {["fields"] = {}, ["inventory"] = {}}, ["y"] = 14, ["param1"] = 15, ["z"] = 86, ["name"] = "rainbow:stoneblock_white"}, {["x"] = 5, ["meta"] = {["fields"] = {}, ["inventory"] = {}}, ["y"] = 14, ["param1"] = 15, ["z"] = 87, ["name"] = "rainbow:stoneblock_white"}, {["x"] = 5, ["meta"] = {["fields"] = {}, ["inventory"] = {}}, ["y"] = 14, ["param1"] = 15, ["z"] = 88, ["name"] = "rainbow:stoneblock_white"}, {["x"] = 5, ["meta"] = {["fields"] = {}, ["inventory"] = {}}, ["y"] = 14, ["param1"] = 15, ["z"] = 89, ["name"] = "rainbow:stoneblock_white"}, {["x"] = 5, ["meta"] = {["fields"] = {}, ["inventory"] = {}}, ["y"] = 14, ["param1"] = 63, ["z"] = 90, ["name"] = "rainbow:stoneblock_white"}, {["x"] = 5, ["meta"] = {["fields"] = {}, ["inventory"] = {}}, ["y"] = 15, ["param1"] = 15, ["z"] = 44, ["name"] = "rainbow:stoneblock_white"}, {["x"] = 5, ["meta"] = {["fields"] = {}, ["inventory"] = {}}, ["y"] = 15, ["param1"] = 15, ["z"] = 45, ["name"] = "rainbow:stoneblock_white"}, {["x"] = 5, ["meta"] = {["fields"] = {}, ["inventory"] = {}}, ["y"] = 15, ["param1"] = 15, ["z"] = 69, ["name"] = "rainbow:stoneblock_white"}, {["x"] = 5, ["meta"] = {["fields"] = {}, ["inventory"] = {}}, ["y"] = 15, ["param1"] = 15, ["z"] = 70, ["name"] = "rainbow:stoneblock_white"}, {["x"] = 5, ["meta"] = {["fields"] = {}, ["inventory"] = {}}, ["y"] = 16, ["param1"] = 15, ["z"] = 44, ["name"] = "rainbow:stoneblock_white"}, {["x"] = 5, ["meta"] = {["fields"] = {}, ["inventory"] = {}}, ["y"] = 16, ["param1"] = 15, ["z"] = 45, ["name"] = "rainbow:stoneblock_white"}, {["x"] = 5, ["meta"] = {["fields"] = {}, ["inventory"] = {}}, ["y"] = 16, ["param1"] = 15, ["z"] = 69, ["name"] = "rainbow:stoneblock_white"}, {["x"] = 5, ["meta"] = {["fields"] = {}, ["inventory"] = {}}, ["y"] = 16, ["param1"] = 15, ["z"] = 70, ["name"] = "rainbow:stoneblock_white"}, {["x"] = 5, ["meta"] = {["fields"] = {}, ["inventory"] = {}}, ["y"] = 17, ["param1"] = 15, ["z"] = 46, ["name"] = "rainbow:stoneblock_white"}, {["x"] = 5, ["meta"] = {["fields"] = {}, ["inventory"] = {}}, ["y"] = 17, ["param1"] = 15, ["z"] = 47, ["name"] = "rainbow:stoneblock_white"}, {["x"] = 5, ["meta"] = {["fields"] = {}, ["inventory"] = {}}, ["y"] = 17, ["param1"] = 15, ["z"] = 67, ["name"] = "rainbow:stoneblock_white"}, {["x"] = 5, ["meta"] = {["fields"] = {}, ["inventory"] = {}}, ["y"] = 17, ["param1"] = 15, ["z"] = 68, ["name"] = "rainbow:stoneblock_white"}, {["x"] = 5, ["meta"] = {["fields"] = {}, ["inventory"] = {}}, ["y"] = 18, ["param1"] = 15, ["z"] = 46, ["name"] = "rainbow:stoneblock_white"}, {["x"] = 5, ["meta"] = {["fields"] = {}, ["inventory"] = {}}, ["y"] = 18, ["param1"] = 15, ["z"] = 47, ["name"] = "rainbow:stoneblock_white"}, {["x"] = 5, ["meta"] = {["fields"] = {}, ["inventory"] = {}}, ["y"] = 18, ["param1"] = 15, ["z"] = 67, ["name"] = "rainbow:stoneblock_white"}, {["x"] = 5, ["meta"] = {["fields"] = {}, ["inventory"] = {}}, ["y"] = 18, ["param1"] = 15, ["z"] = 68, ["name"] = "rainbow:stoneblock_white"}, {["x"] = 5, ["meta"] = {["fields"] = {}, ["inventory"] = {}}, ["y"] = 19, ["param1"] = 15, ["z"] = 48, ["name"] = "rainbow:stoneblock_white"}, {["x"] = 5, ["meta"] = {["fields"] = {}, ["inventory"] = {}}, ["y"] = 19, ["param1"] = 15, ["z"] = 49, ["name"] = "rainbow:stoneblock_white"}, {["x"] = 5, ["meta"] = {["fields"] = {}, ["inventory"] = {}}, ["y"] = 19, ["param1"] = 13, ["z"] = 50, ["name"] = "rainbow:stoneblock_white"}, {["x"] = 5, ["meta"] = {["fields"] = {}, ["inventory"] = {}}, ["y"] = 19, ["param1"] = 12, ["z"] = 51, ["name"] = "rainbow:stoneblock_white"}, {["x"] = 5, ["meta"] = {["fields"] = {}, ["inventory"] = {}}, ["y"] = 19, ["param1"] = 11, ["z"] = 52, ["name"] = "rainbow:stoneblock_white"}, {["x"] = 5, ["meta"] = {["fields"] = {}, ["inventory"] = {}}, ["y"] = 19, ["param1"] = 11, ["z"] = 62, ["name"] = "rainbow:stoneblock_white"}, {["x"] = 5, ["meta"] = {["fields"] = {}, ["inventory"] = {}}, ["y"] = 19, ["param1"] = 12, ["z"] = 63, ["name"] = "rainbow:stoneblock_white"}, {["x"] = 5, ["meta"] = {["fields"] = {}, ["inventory"] = {}}, ["y"] = 19, ["param1"] = 13, ["z"] = 64, ["name"] = "rainbow:stoneblock_white"}, {["x"] = 5, ["meta"] = {["fields"] = {}, ["inventory"] = {}}, ["y"] = 19, ["param1"] = 15, ["z"] = 65, ["name"] = "rainbow:stoneblock_white"}, {["x"] = 5, ["meta"] = {["fields"] = {}, ["inventory"] = {}}, ["y"] = 19, ["param1"] = 15, ["z"] = 66, ["name"] = "rainbow:stoneblock_white"}, {["x"] = 5, ["meta"] = {["fields"] = {}, ["inventory"] = {}}, ["y"] = 20, ["param1"] = 11, ["z"] = 52, ["name"] = "rainbow:stoneblock_white"}, {["x"] = 5, ["meta"] = {["fields"] = {}, ["inventory"] = {}}, ["y"] = 20, ["param1"] = 11, ["z"] = 62, ["name"] = "rainbow:stoneblock_white"}, {["x"] = 5, ["meta"] = {["fields"] = {}, ["inventory"] = {}}, ["y"] = 21, ["param1"] = 11, ["z"] = 52, ["name"] = "rainbow:stoneblock_white"}, {["x"] = 5, ["meta"] = {["fields"] = {}, ["inventory"] = {}}, ["y"] = 21, ["param1"] = 11, ["z"] = 62, ["name"] = "rainbow:stoneblock_white"}, {["x"] = 5, ["meta"] = {["fields"] = {}, ["inventory"] = {}},