5:return {{["x"] = 0, ["meta"] = {["fields"] = {}, ["inventory"] = {}}, ["y"] = 0, ["z"] = 0, ["name"] = "spell:Letter_E"}, {["x"] = 0, ["meta"] = {["fields"] = {}, ["inventory"] = {}}, ["param2"] = 5, ["y"] = 0, ["param1"] = 221, ["z"] = 1, ["name"] = "homedecor:curtain_white"}, {["x"] = 0, ["meta"] = {["fields"] = {}, ["inventory"] = {}}, ["y"] = 1, ["z"] = 0, ["name"] = "spell:Letter_P"}, {["x"] = 0, ["meta"] = {["fields"] = {}, ["inventory"] = {}}, ["param2"] = 5, ["y"] = 1, ["param1"] = 221, ["z"] = 1, ["name"] = "homedecor:curtain_white"}, {["x"] = 0, ["meta"] = {["fields"] = {}, ["inventory"] = {}}, ["y"] = 2, ["z"] = 0, ["name"] = "default:snowblock"}, {["x"] = 0, ["meta"] = {["fields"] = {}, ["inventory"] = {}}, ["param2"] = 5, ["y"] = 2, ["param1"] = 205, ["z"] = 1, ["name"] = "homedecor:curtain_white"}, {["x"] = 0, ["meta"] = {["fields"] = {}, ["inventory"] = {}}, ["param2"] = 1, ["y"] = 6, ["param1"] = 125, ["z"] = 34, ["name"] = "homedecor:fence_wrought_iron"}, {["x"] = 0, ["meta"] = {["fields"] = {}, ["inventory"] = {}}, ["param2"] = 1, ["y"] = 6, ["param1"] = 108, ["z"] = 35, ["name"] = "homedecor:fence_wrought_iron"}, {["x"] = 0, ["meta"] = {["fields"] = {}, ["inventory"] = {}}, ["param2"] = 2, ["y"] = 6, ["param1"] = 93, ["z"] = 36, ["name"] = "homedecor:fence_wrought_iron"}, {["x"] = 0, ["meta"] = {["fields"] = {}, ["inventory"] = {}}, ["param2"] = 1, ["y"] = 6, ["param1"] = 77, ["z"] = 37, ["name"] = "homedecor:fence_wrought_iron"}, {["x"] = 0, ["meta"] = {["fields"] = {}, ["inventory"] = {}}, ["param2"] = 1, ["y"] = 6, ["param1"] = 61, ["z"] = 38, ["name"] = "homedecor:fence_wrought_iron"}, {["x"] = 0, ["meta"] = {["fields"] = {}, ["inventory"] = {}}, ["param2"] = 1, ["y"] = 6, ["param1"] = 45, ["z"] = 39, ["name"] = "homedecor:fence_wrought_iron"}, {["x"] = 0, ["meta"] = {["fields"] = {}, ["inventory"] = {}}, ["param2"] = 1, ["y"] = 6, ["param1"] = 45, ["z"] = 40, ["name"] = "homedecor:fence_wrought_iron"}, {["x"] = 0, ["meta"] = {["fields"] = {}, ["inventory"] = {}}, ["param2"] = 1, ["y"] = 6, ["param1"] = 61, ["z"] = 41, ["name"] = "homedecor:fence_wrought_iron"}, {["x"] = 0, ["meta"] = {["fields"] = {}, ["inventory"] = {}}, ["param2"] = 1, ["y"] = 6, ["param1"] = 45, ["z"] = 42, ["name"] = "homedecor:fence_wrought_iron"}, {["x"] = 0, ["meta"] = {["fields"] = {}, ["inventory"] = {}}, ["param2"] = 1, ["y"] = 6, ["param1"] = 29, ["z"] = 43, ["name"] = "homedecor:fence_wrought_iron"}, {["x"] = 0, ["meta"] = {["fields"] = {}, ["inventory"] = {}}, ["param2"] = 1, ["y"] = 6, ["param1"] = 29, ["z"] = 44, ["name"] = "homedecor:fence_wrought_iron"}, {["x"] = 0, ["meta"] = {["fields"] = {}, ["inventory"] = {}}, ["param2"] = 1, ["y"] = 6, ["param1"] = 45, ["z"] = 45, ["name"] = "homedecor:fence_wrought_iron"}, {["x"] = 0, ["meta"] = {["fields"] = {}, ["inventory"] = {}}, ["param2"] = 1, ["y"] = 6, ["param1"] = 61, ["z"] = 46, ["name"] = "homedecor:fence_wrought_iron"}, {["x"] = 0, ["meta"] = {["fields"] = {}, ["inventory"] = {}}, ["param2"] = 1, ["y"] = 6, ["param1"] = 45, ["z"] = 47, ["name"] = "homedecor:fence_wrought_iron"}, {["x"] = 0, ["meta"] = {["fields"] = {}, ["inventory"] = {}}, ["param2"] = 1, ["y"] = 6, ["param1"] = 29, ["z"] = 48, ["name"] = "homedecor:fence_wrought_iron"}, {["x"] = 0, ["meta"] = {["fields"] = {}, ["inventory"] = {}}, ["param2"] = 1, ["y"] = 6, ["param1"] = 29, ["z"] = 49, ["name"] = "homedecor:fence_wrought_iron"}, {["x"] = 0, ["meta"] = {["fields"] = {}, ["inventory"] = {}}, ["param2"] = 1, ["y"] = 6, ["param1"] = 45, ["z"] = 50, ["name"] = "homedecor:fence_wrought_iron"}, {["x"] = 0, ["meta"] = {["fields"] = {}, ["inventory"] = {}}, ["param2"] = 1, ["y"] = 6, ["param1"] = 61, ["z"] = 51, ["name"] = "homedecor:fence_wrought_iron"}, {["x"] = 0, ["meta"] = {["fields"] = {}, ["inventory"] = {}}, ["param2"] = 1, ["y"] = 6, ["param1"] = 45, ["z"] = 52, ["name"] = "homedecor:fence_wrought_iron"}, {["x"] = 0, ["meta"] = {["fields"] = {}, ["inventory"] = {}}, ["param2"] = 1, ["y"] = 6, ["param1"] = 29, ["z"] = 53, ["name"] = "homedecor:fence_wrought_iron"}, {["x"] = 0, ["meta"] = {["fields"] = {}, ["inventory"] = {}}, ["param2"] = 1, ["y"] = 6, ["param1"] = 29, ["z"] = 54, ["name"] = "homedecor:fence_wrought_iron"}, {["x"] = 0, ["meta"] = {["fields"] = {}, ["inventory"] = {}}, ["param2"] = 1, ["y"] = 6, ["param1"] = 45, ["z"] = 55, ["name"] = "homedecor:fence_wrought_iron"}, {["x"] = 0, ["meta"] = {["fields"] = {}, ["inventory"] = {}}, ["param2"] = 1, ["y"] = 6, ["param1"] = 61, ["z"] = 56, ["name"] = "homedecor:fence_wrought_iron"}, {["x"] = 0, ["meta"] = {["fields"] = {}, ["inventory"] = {}}, ["param2"] = 1, ["y"] = 6, ["param1"] = 45, ["z"] = 57, ["name"] = "homedecor:fence_wrought_iron"}, {["x"] = 0, ["meta"] = {["fields"] = {}, ["inventory"] = {}}, ["param2"] = 1, ["y"] = 6, ["param1"] = 29, ["z"] = 58, ["name"] = "homedecor:fence_wrought_iron"}, {["x"] = 0, ["meta"] = {["fields"] = {}, ["inventory"] = {}}, ["param2"] = 2, ["y"] = 7, ["param1"] = 141, ["z"] = 34, ["name"] = "homedecor:fence_wrought_iron"}, {["x"] = 0, ["meta"] = {["fields"] = {}, ["inventory"] = {}}, ["param2"] = 2, ["y"] = 7, ["param1"] = 125, ["z"] = 35, ["name"] = "homedecor:fence_wrought_iron"}, {["x"] = 0, ["meta"] = {["fields"] = {}, ["inventory"] = {}}, ["param2"] = 2, ["y"] = 7, ["param1"] = 109, ["z"] = 36, ["name"] = "homedecor:fence_wrought_iron"}, {["x"] = 0, ["meta"] = {["fields"] = {}, ["inventory"] = {}}, ["param2"] = 2, ["y"] = 7, ["param1"] = 93, ["z"] = 37, ["name"] = "homedecor:fence_wrought_iron"}, {["x"] = 0, ["meta"] = {["fields"] = {}, ["inventory"] = {}}, ["param2"] = 1, ["y"] = 7, ["param1"] = 77, ["z"] = 38, ["name"] = "homedecor:fence_wrought_iron"}, {["x"] = 0, ["meta"] = {["fields"] = {}, ["inventory"] = {}}, ["y"] = 7, ["param1"] = 61, ["z"] = 39, ["name"] = "homedecor:fence_wrought_iron"}, {["x"] = 0, ["meta"] = {["fields"] = {}, ["inventory"] = {}}, ["param2"] = 2, ["y"] = 7, ["param1"] = 61, ["z"] = 40, ["name"] = "homedecor:fence_wrought_iron"}, {["x"] = 0, ["meta"] = {["fields"] = {}, ["inventory"] = {}}, ["param2"] = 2, ["y"] = 7, ["param1"] = 77, ["z"] = 41, ["name"] = "homedecor:fence_wrought_iron"}, {["x"] = 0, ["meta"] = {["fields"] = {}, ["inventory"] = {}}, ["param2"] = 2, ["y"] = 7, ["param1"] = 61, ["z"] = 42, ["name"] = "homedecor:fence_wrought_iron"}, {["x"] = 0, ["meta"] = {["fields"] = {}, ["inventory"] = {}}, ["param2"] = 1, ["y"] = 7, ["param1"] = 45, ["z"] = 43, ["name"] = "homedecor:fence_wrought_iron"}, {["x"] = 0, ["meta"] = {["fields"] = {}, ["inventory"] = {}}, ["y"] = 7, ["param1"] = 45, ["z"] = 44, ["name"] = "homedecor:fence_wrought_iron"}, {["x"] = 0, ["meta"] = {["fields"] = {}, ["inventory"] = {}}, ["param2"] = 1, ["y"] = 7, ["param1"] = 61, ["z"] = 45, ["name"] = "homedecor:fence_wrought_iron"}, {["x"] = 0, ["meta"] = {["fields"] = {}, ["inventory"] = {}}, ["param2"] = 1, ["y"] = 7, ["param1"] = 77, ["z"] = 46, ["name"] = "homedecor:fence_wrought_iron"}, {["x"] = 0, ["meta"] = {["fields"] = {}, ["inventory"] = {}}, ["param2"] = 1, ["y"] = 7, ["param1"] = 61, ["z"] = 47, ["name"] = "homedecor:fence_wrought_iron"}, {["x"] = 0, ["meta"] = {["fields"] = {}, ["inventory"] = {}}, ["param2"] = 2, ["y"] = 7, ["param1"] = 45, ["z"] = 48, ["name"] = "homedecor:fence_wrought_iron"}, {["x"] = 0, ["meta"] = {["fields"] = {}, ["inventory"] = {}}, ["param2"] = 2, ["y"] = 7, ["param1"] = 45, ["z"] = 49, ["name"] = "homedecor:fence_wrought_iron"}, {["x"] = 0, ["meta"] = {["fields"] = {}, ["inventory"] = {}}, ["param2"] = 2, ["y"] = 7, ["param1"] = 61, ["z"] = 50, ["name"] = "homedecor:fence_wrought_iron"}, {["x"] = 0, ["meta"] = {["fields"] = {}, ["inventory"] = {}}, ["param2"] = 1, ["y"] = 7, ["param1"] = 77, ["z"] = 51, ["name"] = "homedecor:fence_wrought_iron"}, {["x"] = 0, ["meta"] = {["fields"] = {}, ["inventory"] = {}}, ["y"] = 7, ["param1"] = 61, ["z"] = 52, ["name"] = "homedecor:fence_wrought_iron"}, {["x"] = 0, ["meta"] = {["fields"] = {}, ["inventory"] = {}}, ["y"] = 7, ["param1"] = 45, ["z"] = 53, ["name"] = "homedecor:fence_wrought_iron"}, {["x"] = 0, ["meta"] = {["fields"] = {}, ["inventory"] = {}}, ["y"] = 7, ["param1"] = 45, ["z"] = 54, ["name"] = "homedecor:fence_wrought_iron"}, {["x"] = 0, ["meta"] = {["fields"] = {}, ["inventory"] = {}}, ["y"] = 7, ["param1"] = 61, ["z"] = 55, ["name"] = "homedecor:fence_wrought_iron"}, {["x"] = 0, ["meta"] = {["fields"] = {}, ["inventory"] = {}}, ["param2"] = 1, ["y"] = 7, ["param1"] = 77, ["z"] = 56, ["name"] = "homedecor:fence_wrought_iron"}, {["x"] = 0, ["meta"] = {["fields"] = {}, ["inventory"] = {}}, ["param2"] = 1, ["y"] = 7, ["param1"] = 61, ["z"] = 57, ["name"] = "homedecor:fence_wrought_iron"}, {["x"] = 0, ["meta"] = {["fields"] = {}, ["inventory"] = {}}, ["param2"] = 1, ["y"] = 7, ["param1"] = 45, ["z"] = 58, ["name"] = "homedecor:fence_wrought_iron"}, {["x"] = 1, ["meta"] = {["fields"] = {}, ["inventory"] = {}}, ["y"] = 0, ["z"] = 0, ["name"] = "spell:Letter_X"}, {["x"] = 1, ["meta"] = {["fields"] = {}, ["inventory"] = {}}, ["param2"] = 5, ["y"] = 0, ["param1"] = 221, ["z"] = 1, ["name"] = "homedecor:curtain_white"}, {["x"] = 1, ["meta"] = {["fields"] = {}, ["inventory"] = {}}, ["y"] = 0, ["z"] = 28, ["name"] = "mesecons_lightstone:lightstone_red_off"}, {["x"] = 1, ["meta"] = {["fields"] = {}, ["inventory"] = {}}, ["y"] = 0, ["z"] = 29, ["name"] = "mesecons_lightstone:lightstone_red_off"}, {["x"] = 1, ["meta"] = {["fields"] = {}, ["inventory"] = {}}, ["y"] = 0, ["z"] = 30, ["name"] = "mesecons_lightstone:lightstone_red_off"}, {["x"] = 1, ["meta"] = {["fields"] = {}, ["inventory"] = {}}, ["y"] = 0, ["z"] = 31, ["name"] = "mesecons_lightstone:lightstone_red_off"}, {["x"] = 1, ["meta"] = {["fields"] = {}, ["inventory"] = {}}, ["y"] = 0, ["z"] = 32, ["name"] = "mesecons_lightstone:lightstone_red_off"}, {["x"] = 1, ["meta"] = {["fields"] = {}, ["inventory"] = {}}, ["y"] = 0, ["z"] = 33, ["name"] = "mesecons_lightstone:lightstone_red_off"}, {["x"] = 1, ["meta"] = {["fields"] = {}, ["inventory"] = {}}, ["y"] = 0, ["z"] = 59, ["name"] = "mesecons_lightstone:lightstone_red_off"}, {["x"] = 1, ["meta"] = {["fields"] = {}, ["inventory"] = {}}, ["y"] = 0, ["z"] = 60, ["name"] = "mesecons_lightstone:lightstone_red_off"}, {["x"] = 1, ["meta"] = {["fields"] = {}, ["inventory"] = {}}, ["y"] = 0, ["z"] = 61, ["name"] = "mesecons_lightstone:lightstone_red_off"}, {["x"] = 1, ["meta"] = {["fields"] = {}, ["inventory"] = {}}, ["y"] = 0, ["z"] = 62, ["name"] = "mesecons_lightstone:lightstone_red_off"}, {["x"] = 1, ["meta"] = {["fields"] = {}, ["inventory"] = {}}, ["y"] = 0, ["z"] = 63, ["name"] = "mesecons_lightstone:lightstone_red_off"}, {["x"] = 1, ["meta"] = {["fields"] = {}, ["inventory"] = {}}, ["y"] = 0, ["z"] = 64, ["name"] = "mesecons_lightstone:lightstone_red_off"}, {["x"] = 1, ["meta"] = {["fields"] = {}, ["inventory"] = {}}, ["y"] = 1, ["z"] = 0, ["name"] = "spell:Letter_L"}, {["x"] = 1, ["meta"] = {["fields"] = {}, ["inventory"] = {}}, ["param2"] = 5, ["y"] = 1, ["param1"] = 221, ["z"] = 1, ["name"] = "homedecor:curtain_white"}, {["x"] = 1, ["meta"] = {["fields"] = {}, ["inventory"] = {}}, ["y"] = 1, ["z"] = 28, ["name"] = "mesecons_lightstone:lightstone_red_off"}, {["x"] = 1, ["meta"] = {["fields"] = {}, ["inventory"] = {}}, ["y"] = 1, ["z"] = 29, ["name"] = "mesecons_lightstone:lightstone_red_off"}, {["x"] = 1, ["meta"] = {["fields"] = {}, ["inventory"] = {}}, ["y"] = 1, ["z"] = 30, ["name"] = "mesecons_lightstone:lightstone_red_off"}, {["x"] = 1, ["meta"] = {["fields"] = {}, ["inventory"] = {}}, ["y"] = 1, ["z"] = 31, ["name"] = "mesecons_lightstone:lightstone_red_off"}, {["x"] = 1, ["meta"] = {["fields"] = {}, ["inventory"] = {}}, ["y"] = 1, ["z"] = 32, ["name"] = "mesecons_lightstone:lightstone_red_off"}, {["x"] = 1, ["meta"] = {["fields"] = {}, ["inventory"] = {}}, ["y"] = 1, ["z"] = 33, ["name"] = "mesecons_lightstone:lightstone_red_off"}, {["x"] = 1, ["meta"] = {["fields"] = {}, ["inventory"] = {}}, ["y"] = 1, ["z"] = 59, ["name"] = "mesecons_lightstone:lightstone_red_off"}, {["x"] = 1, ["meta"] = {["fields"] = {}, ["inventory"] = {}}, ["y"] = 1, ["z"] = 60, ["name"] = "mesecons_lightstone:lightstone_red_off"}, {["x"] = 1, ["meta"] = {["fields"] = {}, ["inventory"] = {}}, ["y"] = 1, ["z"] = 61, ["name"] = "mesecons_lightstone:lightstone_red_off"}, {["x"] = 1, ["meta"] = {["fields"] = {}, ["inventory"] = {}}, ["y"] = 1, ["z"] = 62, ["name"] = "mesecons_lightstone:lightstone_red_off"}, {["x"] = 1, ["meta"] = {["fields"] = {}, ["inventory"] = {}}, ["y"] = 1, ["z"] = 63, ["name"] = "mesecons_lightstone:lightstone_red_off"}, {["x"] = 1, ["meta"] = {["fields"] = {}, ["inventory"] = {}}, ["y"] = 1, ["z"] = 64, ["name"] = "mesecons_lightstone:lightstone_red_off"}, {["x"] = 1, ["meta"] = {["fields"] = {}, ["inventory"] = {}}, ["y"] = 2, ["z"] = 0, ["name"] = "default:snowblock"}, {["x"] = 1, ["meta"] = {["fields"] = {}, ["inventory"] = {}}, ["param2"] = 5, ["y"] = 2, ["param1"] = 205, ["z"] = 1, ["name"] = "homedecor:curtain_white"}, {["x"] = 1, ["meta"] = {["fields"] = {}, ["inventory"] = {}}, ["y"] = 2, ["z"] = 28, ["name"] = "mesecons_lightstone:lightstone_red_off"}, {["x"] = 1, ["meta"] = {["fields"] = {}, ["inventory"] = {}}, ["y"] = 2, ["z"] = 29, ["name"] = "mesecons_lightstone:lightstone_red_off"}, {["x"] = 1, ["meta"] = {["fields"] = {}, ["inventory"] = {}}, ["y"] = 2, ["z"] = 30, ["name"] = "mesecons_lightstone:lightstone_red_off"}, {["x"] = 1, ["meta"] = {["fields"] = {}, ["inventory"] = {}}, ["y"] = 2, ["z"] = 31, ["name"] = "mesecons_lightstone:lightstone_red_off"}, {["x"] = 1, ["meta"] = {["fields"] = {}, ["inventory"] = {}}, ["y"] = 2, ["z"] = 32, ["name"] = "mesecons_lightstone:lightstone_red_off"}, {["x"] = 1, ["meta"] = {["fields"] = {}, ["inventory"] = {}}, ["y"] = 2, ["z"] = 33, ["name"] = "mesecons_lightstone:lightstone_red_off"}, {["x"] = 1, ["meta"] = {["fields"] = {}, ["inventory"] = {}}, ["y"] = 2, ["z"] = 59, ["name"] = "mesecons_lightstone:lightstone_red_off"}, {["x"] = 1, ["meta"] = {["fields"] = {}, ["inventory"] = {}}, ["y"] = 2, ["z"] = 60, ["name"] = "mesecons_lightstone:lightstone_red_off"}, {["x"] = 1, ["meta"] = {["fields"] = {}, ["inventory"] = {}}, ["y"] = 2, ["z"] = 61, ["name"] = "mesecons_lightstone:lightstone_red_off"}, {["x"] = 1, ["meta"] = {["fields"] = {}, ["inventory"] = {}}, ["y"] = 2, ["z"] = 62, ["name"] = "mesecons_lightstone:lightstone_red_off"}, {["x"] = 1, ["meta"] = {["fields"] = {}, ["inventory"] = {}}, ["y"] = 2, ["z"] = 63, ["name"] = "mesecons_lightstone:lightstone_red_off"}, {["x"] = 1, ["meta"] = {["fields"] = {}, ["inventory"] = {}}, ["y"] = 2, ["z"] = 64, ["name"] = "mesecons_lightstone:lightstone_red_off"}, {["x"] = 1, ["meta"] = {["fields"] = {}, ["inventory"] = {}}, ["y"] = 3, ["z"] = 28, ["name"] = "mesecons_lightstone:lightstone_red_off"}, {["x"] = 1, ["meta"] = {["fields"] = {}, ["inventory"] = {}}, ["y"] = 3, ["z"] = 29, ["name"] = "mesecons_lightstone:lightstone_red_off"}, {["x"] = 1, ["meta"] = {["fields"] = {}, ["inventory"] = {}}, ["y"] = 3, ["z"] = 30, ["name"] = "mesecons_lightstone:lightstone_red_off"}, {["x"] = 1, ["meta"] = {["fields"] = {}, ["inventory"] = {}}, ["y"] = 3, ["z"] = 31, ["name"] = "mesecons_lightstone:lightstone_red_off"}, {["x"] = 1, ["meta"] = {["fields"] = {}, ["inventory"] = {}}, ["y"] = 3, ["z"] = 32, ["name"] = "mesecons_lightstone:lightstone_red_off"}, {["x"] = 1, ["meta"] = {["fields"] = {}, ["inventory"] = {}}, ["y"] = 3, ["z"] = 33, ["name"] = "mesecons_lightstone:lightstone_red_off"}, {["x"] = 1, ["meta"] = {["fields"] = {}, ["inventory"] = {}}, ["y"] = 3, ["z"] = 59, ["name"] = "mesecons_lightstone:lightstone_red_off"}, {["x"] = 1, ["meta"] = {["fields"] = {}, ["inventory"] = {}}, ["y"] = 3, ["z"] = 60, ["name"] = "mesecons_lightstone:lightstone_red_off"}, {["x"] = 1, ["meta"] = {["fields"] = {}, ["inventory"] = {}}, ["y"] = 3, ["z"] = 61, ["name"] = "mesecons_lightstone:lightstone_red_off"}, {["x"] = 1, ["meta"] = {["fields"] = {}, ["inventory"] = {}}, ["y"] = 3, ["z"] = 62, ["name"] = "mesecons_lightstone:lightstone_red_off"}, {["x"] = 1, ["meta"] = {["fields"] = {}, ["inventory"] = {}}, ["y"] = 3, ["z"] = 63, ["name"] = "mesecons_lightstone:lightstone_red_off"}, {["x"] = 1, ["meta"] = {["fields"] = {}, ["inventory"] = {}}, ["y"] = 3, ["z"] = 64, ["name"] = "mesecons_lightstone:lightstone_red_off"}, {["x"] = 1, ["meta"] = {["fields"] = {}, ["inventory"] = {}}, ["y"] = 4, ["z"] = 28, ["name"] = "mesecons_lightstone:lightstone_red_off"}, {["x"] = 1, ["meta"] = {["fields"] = {}, ["inventory"] = {}}, ["y"] = 4, ["z"] = 29, ["name"] = "mesecons_lightstone:lightstone_red_off"}, {["x"] = 1, ["meta"] = {["fields"] = {}, ["inventory"] = {}}, ["y"] = 4, ["z"] = 30, ["name"] = "mesecons_lightstone:lightstone_red_off"}, {["x"] = 1, ["meta"] = {["fields"] = {}, ["inventory"] = {}}, ["y"] = 4, ["z"] = 31, ["name"] = "mesecons_lightstone:lightstone_red_off"}, {["x"] = 1, ["meta"] = {["fields"] = {}, ["inventory"] = {}}, ["y"] = 4, ["z"] = 32, ["name"] = "mesecons_lightstone:lightstone_red_off"}, {["x"] = 1, ["meta"] = {["fields"] = {}, ["inventory"] = {}}, ["y"] = 4, ["z"] = 33, ["name"] = "mesecons_lightstone:lightstone_red_off"}, {["x"] = 1, ["meta"] = {["fields"] = {}, ["inventory"] = {}}, ["y"] = 4, ["z"] = 59, ["name"] = "mesecons_lightstone:lightstone_red_off"}, {["x"] = 1, ["meta"] = {["fields"] = {}, ["inventory"] = {}}, ["y"] = 4, ["z"] = 60, ["name"] = "mesecons_lightstone:lightstone_red_off"}, {["x"] = 1, ["meta"] = {["fields"] = {}, ["inventory"] = {}}, ["y"] = 4, ["z"] = 61, ["name"] = "mesecons_lightstone:lightstone_red_off"}, {["x"] = 1, ["meta"] = {["fields"] = {}, ["inventory"] = {}}, ["y"] = 4, ["z"] = 62, ["name"] = "mesecons_lightstone:lightstone_red_off"}, {["x"] = 1, ["meta"] = {["fields"] = {}, ["inventory"] = {}}, ["y"] = 4, ["z"] = 63, ["name"] = "mesecons_lightstone:lightstone_red_off"}, {["x"] = 1, ["meta"] = {["fields"] = {}, ["inventory"] = {}}, ["y"] = 4, ["z"] = 64, ["name"] = "mesecons_lightstone:lightstone_red_off"}, {["x"] = 1, ["meta"] = {["fields"] = {}, ["inventory"] = {}}, ["y"] = 5, ["z"] = 28, ["name"] = "mesecons_lightstone:lightstone_red_off"}, {["x"] = 1, ["meta"] = {["fields"] = {}, ["inventory"] = {}}, ["y"] = 5, ["z"] = 29, ["name"] = "mesecons_lightstone:lightstone_red_off"}, {["x"] = 1, ["meta"] = {["fields"] = {}, ["inventory"] = {}}, ["y"] = 5, ["z"] = 30, ["name"] = "mesecons_lightstone:lightstone_red_off"}, {["x"] = 1, ["meta"] = {["fields"] = {}, ["inventory"] = {}}, ["y"] = 5, ["z"] = 31, ["name"] = "mesecons_lightstone:lightstone_red_off"}, {["x"] = 1, ["meta"] = {["fields"] = {}, ["inventory"] = {}}, ["y"] = 5, ["z"] = 32, ["name"] = "mesecons_lightstone:lightstone_red_off"}, {["x"] = 1, ["meta"] = {["fields"] = {}, ["inventory"] = {}}, ["y"] = 5, ["z"] = 33, ["name"] = "mesecons_lightstone:lightstone_red_off"}, {["x"] = 1, ["meta"] = {["fields"] = {}, ["inventory"] = {}}, ["y"] = 5, ["z"] = 36, ["name"] = "mesecons_lightstone:lightstone_green_off"}, {["x"] = 1, ["meta"] = {["fields"] = {}, ["inventory"] = {}}, ["y"] = 5, ["z"] = 41, ["name"] = "mesecons_lightstone:lightstone_green_off"}, {["x"] = 1, ["meta"] = {["fields"] = {}, ["inventory"] = {}}, ["y"] = 5, ["z"] = 46, ["name"] = "mesecons_lightstone:lightstone_green_off"}, {["x"] = 1, ["meta"] = {["fields"] = {}, ["inventory"] = {}}, ["y"] = 5, ["z"] = 51, ["name"] = "mesecons_lightstone:lightstone_green_off"}, {["x"] = 1, ["meta"] = {["fields"] = {}, ["inventory"] = {}}, ["y"] = 5, ["z"] = 56, ["name"] = "mesecons_lightstone:lightstone_green_off"}, {["x"] = 1, ["meta"] = {["fields"] = {}, ["inventory"] = {}}, ["y"] = 5, ["z"] = 59, ["name"] = "mesecons_lightstone:lightstone_red_off"}, {["x"] = 1, ["meta"] = {["fields"] = {}, ["inventory"] = {}}, ["y"] = 5, ["z"] = 60, ["name"] = "mesecons_lightstone:lightstone_red_off"}, {["x"] = 1, ["meta"] = {["fields"] = {}, ["inventory"] = {}}, ["y"] = 5, ["z"] = 61, ["name"] = "mesecons_lightstone:lightstone_red_off"}, {["x"] = 1, ["meta"] = {["fields"] = {}, ["inventory"] = {}}, ["y"] = 5, ["z"] = 62, ["name"] = "mesecons_lightstone:lightstone_red_off"}, {["x"] = 1, ["meta"] = {["fields"] = {}, ["inventory"] = {}}, ["y"] = 5, ["z"] = 63, ["name"] = "mesecons_lightstone:lightstone_red_off"}, {["x"] = 1, ["meta"] = {["fields"] = {}, ["inventory"] = {}}, ["y"] = 5, ["z"] = 64, ["name"] = "mesecons_lightstone:lightstone_red_off"}, {["x"] = 1, ["meta"] = {["fields"] = {}, ["inventory"] = {}}, ["y"] = 6, ["z"] = 28, ["name"] = "mesecons_lightstone:lightstone_red_off"}, {["x"] = 1, ["meta"] = {["fields"] = {}, ["inventory"] = {}}, ["y"] = 6, ["z"] = 29, ["name"] = "mesecons_lightstone:lightstone_red_off"}, {["x"] = 1, ["meta"] = {["fields"] = {}, ["inventory"] = {}}, ["y"] = 6, ["z"] = 30, ["name"] = "mesecons_lightstone:lightstone_red_off"}, {["x"] = 1, ["meta"] = {["fields"] = {}, ["inventory"] = {}}, ["y"] = 6, ["z"] = 31, ["name"] = "mesecons_lightstone:lightstone_red_off"}, {["x"] = 1, ["meta"] = {["fields"] = {}, ["inventory"] = {}}, ["y"] = 6, ["z"] = 32, ["name"] = "mesecons_lightstone:lightstone_red_off"}, {["x"] = 1, ["meta"] = {["fields"] = {}, ["inventory"] = {}}, ["y"] = 6, ["z"] = 33, ["name"] = "mesecons_lightstone:lightstone_red_off"}, {["x"] = 1, ["meta"] = {["fields"] = {}, ["inventory"] = {}}, ["y"] = 6, ["z"] = 34, ["name"] = "moreblocks:wood_tile_full"}, {["x"] = 1, ["meta"] = {["fields"] = {}, ["inventory"] = {}}, ["y"] = 6, ["z"] = 35, ["name"] = "moreblocks:wood_tile_full"}, {["x"] = 1, ["meta"] = {["fields"] = {}, ["inventory"] = {}}, ["y"] = 6, ["z"] = 36, ["name"] = "moreblocks:wood_tile_full"}, {["x"] = 1, ["meta"] = {["fields"] = {}, ["inventory"] = {}}, ["y"] = 6, ["z"] = 37, ["name"] = "moreblocks:wood_tile_full"}, {["x"] = 1, ["meta"] = {["fields"] = {}, ["inventory"] = {}}, ["y"] = 6, ["z"] = 38, ["name"] = "moreblocks:wood_tile_full"}, {["x"] = 1, ["meta"] = {["fields"] = {}, ["inventory"] = {}}, ["y"] = 6, ["z"] = 39, ["name"] = "moreblocks:wood_tile_full"}, {["x"] = 1, ["meta"] = {["fields"] = {}, ["inventory"] = {}}, ["y"] = 6, ["z"] = 40, ["name"] = "moreblocks:wood_tile_full"}, {["x"] = 1, ["meta"] = {["fields"] = {}, ["inventory"] = {}}, ["y"] = 6, ["z"] = 41, ["name"] = "moreblocks:wood_tile_full"}, {["x"] = 1, ["meta"] = {["fields"] = {}, ["inventory"] = {}}, ["y"] = 6, ["z"] = 42, ["name"] = "moreblocks:wood_tile_full"}, {["x"] = 1, ["meta"] = {["fields"] = {}, ["inventory"] = {}}, ["y"] = 6, ["z"] = 43, ["name"] = "moreblocks:wood_tile_full"}, {["x"] = 1, ["meta"] = {["fields"] = {}, ["inventory"] = {}}, ["y"] = 6, ["z"] = 44, ["name"] = "moreblocks:wood_tile_full"}, {["x"] = 1, ["meta"] = {["fields"] = {}, ["inventory"] = {}}, ["y"] = 6, ["z"] = 45, ["name"] = "moreblocks:wood_tile_full"}, {["x"] = 1, ["meta"] = {["fields"] = {}, ["inventory"] = {}}, ["y"] = 6, ["z"] = 46, ["name"] = "moreblocks:wood_tile_full"}, {["x"] = 1, ["meta"] = {["fields"] = {}, ["inventory"] = {}}, ["y"] = 6, ["z"] = 47, ["name"] = "moreblocks:wood_tile_full"}, {["x"] = 1, ["meta"] = {["fields"] = {}, ["inventory"] = {}}, ["y"] = 6, ["z"] = 48, ["name"] = "moreblocks:wood_tile_full"}, {["x"] = 1, ["meta"] = {["fields"] = {}, ["inventory"] = {}}, ["y"] = 6, ["z"] = 49, ["name"] = "moreblocks:wood_tile_full"}, {["x"] = 1, ["meta"] = {["fields"] = {}, ["inventory"] = {}}, ["y"] = 6, ["z"] = 50, ["name"] = "moreblocks:wood_tile_full"}, {["x"] = 1, ["meta"] = {["fields"] = {}, ["inventory"] = {}}, ["y"] = 6, ["z"] = 51, ["name"] = "moreblocks:wood_tile_full"}, {["x"] = 1, ["meta"] = {["fields"] = {}, ["inventory"] = {}}, ["y"] = 6, ["z"] = 52, ["name"] = "moreblocks:wood_tile_full"}, {["x"] = 1, ["meta"] = {["fields"] = {}, ["inventory"] = {}}, ["y"] = 6, ["z"] = 53, ["name"] = "moreblocks:wood_tile_full"}, {["x"] = 1, ["meta"] = {["fields"] = {}, ["inventory"] = {}}, ["y"] = 6, ["z"] = 54, ["name"] = "moreblocks:wood_tile_full"}, {["x"] = 1, ["meta"] = {["fields"] = {}, ["inventory"] = {}}, ["y"] = 6, ["z"] = 55, ["name"] = "moreblocks:wood_tile_full"}, {["x"] = 1, ["meta"] = {["fields"] = {}, ["inventory"] = {}}, ["y"] = 6, ["z"] = 56, ["name"] = "moreblocks:wood_tile_full"}, {["x"] = 1, ["meta"] = {["fields"] = {}, ["inventory"] = {}}, ["y"] = 6, ["z"] = 57, ["name"] = "moreblocks:wood_tile_full"}, {["x"] = 1, ["meta"] = {["fields"] = {}, ["inventory"] = {}}, ["y"] = 6, ["z"] = 58, ["name"] = "moreblocks:wood_tile_full"}, {["x"] = 1, ["meta"] = {["fields"] = {}, ["inventory"] = {}}, ["y"] = 6, ["z"] = 59, ["name"] = "mesecons_lightstone:lightstone_red_off"}, {["x"] = 1, ["meta"] = {["fields"] = {}, ["inventory"] = {}}, ["y"] = 6, ["z"] = 60, ["name"] = "mesecons_lightstone:lightstone_red_off"}, {["x"] = 1, ["meta"] = {["fields"] = {}, ["inventory"] = {}}, ["y"] = 6, ["z"] = 61, ["name"] = "mesecons_lightstone:lightstone_red_off"}, {["x"] = 1, ["meta"] = {["fields"] = {}, ["inventory"] = {}}, ["y"] = 6, ["z"] = 62, ["name"] = "mesecons_lightstone:lightstone_red_off"}, {["x"] = 1, ["meta"] = {["fields"] = {}, ["inventory"] = {}}, ["y"] = 6, ["z"] = 63, ["name"] = "mesecons_lightstone:lightstone_red_off"}, {["x"] = 1, ["meta"] = {["fields"] = {}, ["inventory"] = {}}, ["y"] = 6, ["z"] = 64, ["name"] = "mesecons_lightstone:lightstone_red_off"}, {["x"] = 1, ["meta"] = {["fields"] = {}, ["inventory"] = {}}, ["y"] = 7, ["z"] = 28, ["name"] = "mesecons_lightstone:lightstone_red_off"}, {["x"] = 1, ["meta"] = {["fields"] = {}, ["inventory"] = {}}, ["y"] = 7, ["z"] = 29, ["name"] = "mesecons_lightstone:lightstone_red_off"}, {["x"] = 1, ["meta"] = {["fields"] = {}, ["inventory"] = {}}, ["y"] = 7, ["z"] = 30, ["name"] = "mesecons_lightstone:lightstone_red_off"}, {["x"] = 1, ["meta"] = {["fields"] = {}, ["inventory"] = {}}, ["y"] = 7, ["z"] = 31, ["name"] = "mesecons_lightstone:lightstone_red_off"}, {["x"] = 1, ["meta"] = {["fields"] = {}, ["inventory"] = {}}, ["y"] = 7, ["z"] = 32, ["name"] = "mesecons_lightstone:lightstone_red_off"}, {["x"] = 1, ["meta"] = {["fields"] = {}, ["inventory"] = {}}, ["y"] = 7, ["z"] = 33, ["name"] = "mesecons_lightstone:lightstone_red_off"}, {["x"] = 1, ["meta"] = {["fields"] = {}, ["inventory"] = {}}, ["y"] = 7, ["z"] = 59, ["name"] = "mesecons_lightstone:lightstone_red_off"}, {["x"] = 1, ["meta"] = {["fields"] = {}, ["inventory"] = {}}, ["y"] = 7, ["z"] = 60, ["name"] = "mesecons_lightstone:lightstone_red_off"}, {["x"] = 1, ["meta"] = {["fields"] = {}, ["inventory"] = {}}, ["y"] = 7, ["z"] = 61, ["name"] = "mesecons_lightstone:lightstone_red_off"}, {["x"] = 1, ["meta"] = {["fields"] = {}, ["inventory"] = {}}, ["y"] = 7, ["z"] = 62, ["name"] = "mesecons_lightstone:lightstone_red_off"}, {["x"] = 1, ["meta"] = {["fields"] = {}, ["inventory"] = {}}, ["y"] = 7, ["z"] = 63, ["name"] = "mesecons_lightstone:lightstone_red_off"}, {["x"] = 1, ["meta"] = {["fields"] = {}, ["inventory"] = {}}, ["y"] = 7, ["z"] = 64, ["name"] = "mesecons_lightstone:lightstone_red_off"}, {["x"] = 1, ["meta"] = {["fields"] = {}, ["inventory"] = {}}, ["y"] = 8, ["z"] = 28, ["name"] = "mesecons_lightstone:lightstone_red_off"}, {["x"] = 1, ["meta"] = {["fields"] = {}, ["inventory"] = {}}, ["y"] = 8, ["z"] = 29, ["name"] = "mesecons_lightstone:lightstone_red_off"}, {["x"] = 1, ["meta"] = {["fields"] = {}, ["inventory"] = {}}, ["y"] = 8, ["z"] = 30, ["name"] = "mesecons_lightstone:lightstone_red_off"}, {["x"] = 1, ["meta"] = {["fields"] = {}, ["inventory"] = {}}, ["y"] = 8, ["z"] = 31, ["name"] = "mesecons_lightstone:lightstone_red_off"}, {["x"] = 1, ["meta"] = {["fields"] = {}, ["inventory"] = {}}, ["y"] = 8, ["z"] = 32, ["name"] = "mesecons_lightstone:lightstone_red_off"}, {["x"] = 1, ["meta"] = {["fields"] = {}, ["inventory"] = {}}, ["y"] = 8, ["z"] = 33, ["name"] = "mesecons_lightstone:lightstone_red_off"}, {["x"] = 1, ["meta"] = {["fields"] = {}, ["inventory"] = {}}, ["y"] = 8, ["z"] = 59, ["name"] = "mesecons_lightstone:lightstone_red_off"}, {["x"] = 1, ["meta"] = {["fields"] = {}, ["inventory"] = {}}, ["y"] = 8, ["z"] = 60, ["name"] = "mesecons_lightstone:lightstone_red_off"}, {["x"] = 1, ["meta"] = {["fields"] = {}, ["inventory"] = {}}, ["y"] = 8, ["z"] = 61, ["name"] = "mesecons_lightstone:lightstone_red_off"}, {["x"] = 1, ["meta"] = {["fields"] = {}, ["inventory"] = {}}, ["y"] = 8, ["z"] = 62, ["name"] = "mesecons_lightstone:lightstone_red_off"}, {["x"] = 1, ["meta"] = {["fields"] = {}, ["inventory"] = {}}, ["y"] = 8, ["z"] = 63, ["name"] = "mesecons_lightstone:lightstone_red_off"}, {["x"] = 1, ["meta"] = {["fields"] = {}, ["inventory"] = {}}, ["y"] = 8, ["z"] = 64, ["name"] = "mesecons_lightstone:lightstone_red_off"}, {["x"] = 1, ["meta"] = {["fields"] = {}, ["inventory"] = {}}, ["y"] = 9, ["z"] = 28, ["name"] = "mesecons_lightstone:lightstone_red_off"}, {["x"] = 1, ["meta"] = {["fields"] = {}, ["inventory"] = {}}, ["y"] = 9, ["z"] = 29, ["name"] = "mesecons_lightstone:lightstone_red_off"}, {["x"] = 1, ["meta"] = {["fields"] = {}, ["inventory"] = {}}, ["y"] = 9, ["z"] = 30, ["name"] = "mesecons_lightstone:lightstone_red_off"}, {["x"] = 1, ["meta"] = {["fields"] = {}, ["inventory"] = {}}, ["y"] = 9, ["z"] = 31, ["name"] = "mesecons_lightstone:lightstone_red_off"}, {["x"] = 1, ["meta"] = {["fields"] = {}, ["inventory"] = {}}, ["y"] = 9, ["z"] = 32, ["name"] = "mesecons_lightstone:lightstone_red_off"}, {["x"] = 1, ["meta"] = {["fields"] = {}, ["inventory"] = {}}, ["y"] = 9, ["z"] = 33, ["name"] = "mesecons_lightstone:lightstone_red_off"}, {["x"] = 1, ["meta"] = {["fields"] = {}, ["inventory"] = {}}, ["y"] = 9, ["z"] = 59, ["name"] = "mesecons_lightstone:lightstone_red_off"}, {["x"] = 1, ["meta"] = {["fields"] = {}, ["inventory"] = {}}, ["y"] = 9, ["z"] = 60, ["name"] = "mesecons_lightstone:lightstone_red_off"}, {["x"] = 1, ["meta"] = {["fields"] = {}, ["inventory"] = {}}, ["y"] = 9, ["z"] = 61, ["name"] = "mesecons_lightstone:lightstone_red_off"}, {["x"] = 1, ["meta"] = {["fields"] = {}, ["inventory"] = {}}, ["y"] = 9, ["z"] = 62, ["name"] = "mesecons_lightstone:lightstone_red_off"}, {["x"] = 1, ["meta"] = {["fields"] = {}, ["inventory"] = {}}, ["y"] = 9, ["z"] = 63, ["name"] = "mesecons_lightstone:lightstone_red_off"}, {["x"] = 1, ["meta"] = {["fields"] = {}, ["inventory"] = {}}, ["y"] = 9, ["z"] = 64, ["name"] = "mesecons_lightstone:lightstone_red_off"}, {["x"] = 1, ["meta"] = {["fields"] = {}, ["inventory"] = {}}, ["y"] = 10, ["z"] = 28, ["name"] = "mesecons_lightstone:lightstone_red_off"}, {["x"] = 1, ["meta"] = {["fields"] = {}, ["inventory"] = {}}, ["y"] = 10, ["z"] = 29, ["name"] = "mesecons_lightstone:lightstone_red_off"}, {["x"] = 1, ["meta"] = {["fields"] = {}, ["inventory"] = {}}, ["y"] = 10, ["z"] = 30, ["name"] = "mesecons_lightstone:lightstone_red_off"}, {["x"] = 1, ["meta"] = {["fields"] = {}, ["inventory"] = {}}, ["y"] = 10, ["z"] = 31, ["name"] = "mesecons_lightstone:lightstone_red_off"}, {["x"] = 1, ["meta"] = {["fields"] = {}, ["inventory"] = {}}, ["y"] = 10, ["z"] = 32, ["name"] = "mesecons_lightstone:lightstone_red_off"}, {["x"] = 1, ["meta"] = {["fields"] = {}, ["inventory"] = {}}, ["y"] = 10, ["z"] = 33, ["name"] = "mesecons_lightstone:lightstone_red_off"}, {["x"] = 1, ["meta"] = {["fields"] = {}, ["inventory"] = {}}, ["y"] = 10, ["z"] = 59, ["name"] = "mesecons_lightstone:lightstone_red_off"}, {["x"] = 1, ["meta"] = {["fields"] = {}, ["inventory"] = {}}, ["y"] = 10, ["z"] = 60, ["name"] = "mesecons_lightstone:lightstone_red_off"}, {["x"] = 1, ["meta"] = {["fields"] = {}, ["inventory"] = {}}, ["y"] = 10, ["z"] = 61, ["name"] = "mesecons_lightstone:lightstone_red_off"}, {["x"] = 1, ["meta"] = {["fields"] = {}, ["inventory"] = {}}, ["y"] = 10, ["z"] = 62, ["name"] = "mesecons_lightstone:lightstone_red_off"}, {["x"] = 1, ["meta"] = {["fields"] = {}, ["inventory"] = {}}, ["y"] = 10, ["z"] = 63, ["name"] = "mesecons_lightstone:lightstone_red_off"}, {["x"] = 1, ["meta"] = {["fields"] = {}, ["inventory"] = {}}, ["y"] = 10, ["z"] = 64, ["name"] = "mesecons_lightstone:lightstone_red_off"}, {["x"] = 1, ["meta"] = {["fields"] = {}, ["inventory"] = {}}, ["y"] = 11, ["z"] = 28, ["name"] = "mesecons_lightstone:lightstone_red_off"}, {["x"] = 1, ["meta"] = {["fields"] = {}, ["inventory"] = {}}, ["y"] = 11, ["z"] = 29, ["name"] = "mesecons_lightstone:lightstone_red_off"}, {["x"] = 1, ["meta"] = {["fields"] = {}, ["inventory"] = {}}, ["y"] = 11, ["z"] = 30, ["name"] = "mesecons_lightstone:lightstone_red_off"}, {["x"] = 1, ["meta"] = {["fields"] = {}, ["inventory"] = {}}, ["y"] = 11, ["z"] = 31, ["name"] = "mesecons_lightstone:lightstone_red_off"}, {["x"] = 1, ["meta"] = {["fields"] = {}, ["inventory"] = {}}, ["y"] = 11, ["z"] = 32, ["name"] = "mesecons_lightstone:lightstone_red_off"}, {["x"] = 1, ["meta"] = {["fields"] = {}, ["inventory"] = {}}, ["y"] = 11, ["z"] = 33, ["name"] = "mesecons_lightstone:lightstone_red_off"}, {["x"] = 1, ["meta"] = {["fields"] = {}, ["inventory"] = {}}, ["y"] = 11, ["z"] = 59, ["name"] = "mesecons_lightstone:lightstone_red_off"}, {["x"] = 1, ["meta"] = {["fields"] = {}, ["inventory"] = {}}, ["y"] = 11, ["z"] = 60, ["name"] = "mesecons_lightstone:lightstone_red_off"}, {["x"] = 1, ["meta"] = {["fields"] = {}, ["inventory"] = {}}, ["y"] = 11, ["z"] = 61, ["name"] = "mesecons_lightstone:lightstone_red_off"}, {["x"] = 1, ["meta"] = {["fields"] = {}, ["inventory"] = {}}, ["y"] = 11, ["z"] = 62, ["name"] = "mesecons_lightstone:lightstone_red_off"}, {["x"] = 1, ["meta"] = {["fields"] = {}, ["inventory"] = {}}, ["y"] = 11, ["z"] = 63, ["name"] = "mesecons_lightstone:lightstone_red_off"}, {["x"] = 1, ["meta"] = {["fields"] = {}, ["inventory"] = {}}, ["y"] = 11, ["z"] = 64, ["name"] = "mesecons_lightstone:lightstone_red_off"}, {["x"] = 1, ["meta"] = {["fields"] = {}, ["inventory"] = {}}, ["y"] = 12, ["z"] = 28, ["name"] = "mesecons_lightstone:lightstone_red_off"}, {["x"] = 1, ["meta"] = {["fields"] = {}, ["inventory"] = {}}, ["y"] = 12, ["z"] = 29, ["name"] = "mesecons_lightstone:lightstone_red_off"}, {["x"] = 1, ["meta"] = {["fields"] = {}, ["inventory"] = {}}, ["y"] = 12, ["z"] = 30, ["name"] = "mesecons_lightstone:lightstone_red_off"}, {["x"] = 1, ["meta"] = {["fields"] = {}, ["inventory"] = {}}, ["y"] = 12, ["z"] = 31, ["name"] = "mesecons_lightstone:lightstone_red_off"}, {["x"] = 1, ["meta"] = {["fields"] = {}, ["inventory"] = {}}, ["y"] = 12, ["z"] = 32, ["name"] = "mesecons_lightstone:lightstone_red_off"}, {["x"] = 1, ["meta"] = {["fields"] = {}, ["inventory"] = {}}, ["y"] = 12, ["z"] = 33, ["name"] = "mesecons_lightstone:lightstone_red_off"}, {["x"] = 1, ["meta"] = {["fields"] = {}, ["inventory"] = {}}, ["y"] = 12, ["z"] = 59, ["name"] = "mesecons_lightstone:lightstone_red_off"}, {["x"] = 1, ["meta"] = {["fields"] = {}, ["inventory"] = {}}, ["y"] = 12, ["z"] = 60, ["name"] = "mesecons_lightstone:lightstone_red_off"}, {["x"] = 1, ["meta"] = {["fields"] = {}, ["inventory"] = {}}, ["y"] = 12, ["z"] = 61, ["name"] = "mesecons_lightstone:lightstone_red_off"}, {["x"] = 1, ["meta"] = {["fields"] = {}, ["inventory"] = {}}, ["y"] = 12, ["z"] = 62, ["name"] = "mesecons_lightstone:lightstone_red_off"}, {["x"] = 1, ["meta"] = {["fields"] = {}, ["inventory"] = {}}, ["y"] = 12, ["z"] = 63, ["name"] = "mesecons_lightstone:lightstone_red_off"}, {["x"] = 1, ["meta"] = {["fields"] = {}, ["inventory"] = {}}, ["y"] = 12, ["z"] = 64, ["name"] = "mesecons_lightstone:lightstone_red_off"}, {["x"] = 1, ["meta"] = {["fields"] = {}, ["inventory"] = {}}, ["y"] = 13, ["z"] = 28, ["name"] = "mesecons_lightstone:lightstone_red_off"}, {["x"] = 1, ["meta"] = {["fields"] = {}, ["inventory"] = {}}, ["y"] = 13, ["z"] = 29, ["name"] = "mesecons_lightstone:lightstone_red_off"}, {["x"] = 1, ["meta"] = {["fields"] = {}, ["inventory"] = {}}, ["y"] = 13, ["z"] = 30, ["name"] = "mesecons_lightstone:lightstone_red_off"}, {["x"] = 1, ["meta"] = {["fields"] = {}, ["inventory"] = {}}, ["y"] = 13, ["z"] = 31, ["name"] = "mesecons_lightstone:lightstone_red_off"}, {["x"] = 1, ["meta"] = {["fields"] = {}, ["inventory"] = {}}, ["y"] = 13, ["z"] = 32, ["name"] = "mesecons_lightstone:lightstone_red_off"}, {["x"] = 1, ["meta"] = {["fields"] = {}, ["inventory"] = {}}, ["y"] = 13, ["z"] = 33, ["name"] = "mesecons_lightstone:lightstone_red_off"}, {["x"] = 1, ["meta"] = {["fields"] = {}, ["inventory"] = {}}, ["y"] = 13, ["z"] = 59, ["name"] = "mesecons_lightstone:lightstone_red_off"}, {["x"] = 1, ["meta"] = {["fields"] = {}, ["inventory"] = {}}, ["y"] = 13, ["z"] = 60, ["name"] = "mesecons_lightstone:lightstone_red_off"}, {["x"] = 1, ["meta"] = {["fields"] = {}, ["inventory"] = {}}, ["y"] = 13, ["z"] = 61, ["name"] = "mesecons_lightstone:lightstone_red_off"}, {["x"] = 1, ["meta"] = {["fields"] = {}, ["inventory"] = {}}, ["y"] = 13, ["z"] = 62, ["name"] = "mesecons_lightstone:lightstone_red_off"}, {["x"] = 1, ["meta"] = {["fields"] = {}, ["inventory"] = {}}, ["y"] = 13, ["z"] = 63, ["name"] = "mesecons_lightstone:lightstone_red_off"}, {["x"] = 1, ["meta"] = {["fields"] = {}, ["inventory"] = {}}, ["y"] = 13, ["z"] = 64, ["name"] = "mesecons_lightstone:lightstone_red_off"}, {["x"] = 1, ["meta"] = {["fields"] = {}, ["inventory"] = {}}, ["y"] = 25, ["param1"] = 77, ["z"] = 10, ["name"] = "homedecor:fence_wrought_iron"}, {["x"] = 1, ["meta"] = {["fields"] = {}, ["inventory"] = {}}, ["y"] = 25, ["param1"] = 93, ["z"] = 11, ["name"] = "homedecor:fence_wrought_iron"}, {["x"] = 1, ["meta"] = {["fields"] = {}, ["inventory"] = {}}, ["y"] = 25, ["param1"] = 109, ["z"] = 12, ["name"] = "homedecor:fence_wrought_iron"}, {["x"] = 1, ["meta"] = {["fields"] = {}, ["inventory"] = {}}, ["y"] = 25, ["param1"] = 125, ["z"] = 13, ["name"] = "homedecor:fence_wrought_iron"}, {["x"] = 1, ["meta"] = {["fields"] = {}, ["inventory"] = {}}, ["param2"] = 1, ["y"] = 25, ["param1"] = 125, ["z"] = 14, ["name"] = "homedecor:fence_wrought_iron"}, {["x"] = 1, ["meta"] = {["fields"] = {}, ["inventory"] = {}}, ["y"] = 25, ["param1"] = 109, ["z"] = 15, ["name"] = "homedecor:fence_wrought_iron"}, {["x"] = 1, ["meta"] = {["fields"] = {}, ["inventory"] = {}}, ["param2"] = 1, ["y"] = 25, ["param1"] = 93, ["z"] = 16, ["name"] = "homedecor:fence_wrought_iron"}, {["x"] = 1, ["meta"] = {["fields"] = {}, ["inventory"] = {}}, ["param2"] = 1, ["y"] = 25, ["param1"] = 77, ["z"] = 17, ["name"] = "homedecor:fence_wrought_iron"}, {["x"] = 1, ["meta"] = {["fields"] = {}, ["inventory"] = {}}, ["y"] = 26, ["param1"] = 93, ["z"] = 10, ["name"] = "homedecor:fence_wrought_iron"}, {["x"] = 1, ["meta"] = {["fields"] = {}, ["inventory"] = {}}, ["y"] = 26, ["param1"] = 109, ["z"] = 11, ["name"] = "homedecor:fence_wrought_iron"}, {["x"] = 1, ["meta"] = {["fields"] = {}, ["inventory"] = {}}, ["y"] = 26, ["param1"] = 125, ["z"] = 12, ["name"] = "homedecor:fence_wrought_iron"}, {["x"] = 1, ["meta"] = {["fields"] = {}, ["inventory"] = {}}, ["y"] = 26, ["param1"] = 141, ["z"] = 13, ["name"] = "homedecor:fence_wrought_iron"}, {["x"] = 1, ["meta"] = {["fields"] = {}, ["inventory"] = {}}, ["param2"] = 1, ["y"] = 26, ["param1"] = 141, ["z"] = 14, ["name"] = "homedecor:fence_wrought_iron"}, {["x"] = 1, ["meta"] = {["fields"] = {}, ["inventory"] = {}}, ["y"] = 26, ["param1"] = 125, ["z"] = 15, ["name"] = "homedecor:fence_wrought_iron"}, {["x"] = 1, ["meta"] = {["fields"] = {}, ["inventory"] = {}}, ["param2"] = 1, ["y"] = 26, ["param1"] = 109, ["z"] = 16, ["name"] = "homedecor:fence_wrought_iron"}, {["x"] = 1, ["meta"] = {["fields"] = {}, ["inventory"] = {}}, ["param2"] = 1, ["y"] = 26, ["param1"] = 93, ["z"] = 17, ["name"] = "homedecor:fence_wrought_iron"}, {["x"] = 2, ["meta"] = {["fields"] = {}, ["inventory"] = {}}, ["y"] = 0, ["z"] = 0, ["name"] = "spell:Letter_P"}, {["x"] = 2, ["meta"] = {["fields"] = {}, ["inventory"] = {}}, ["param2"] = 5, ["y"] = 0, ["param1"] = 221, ["z"] = 1, ["name"] = "homedecor:curtain_white"}, {["x"] = 2, ["meta"] = {["fields"] = {}, ["inventory"] = {}}, ["y"] = 0, ["z"] = 28, ["name"] = "mesecons_lightstone:lightstone_red_off"}, {["x"] = 2, ["meta"] = {["fields"] = {}, ["inventory"] = {}}, ["y"] = 0, ["param1"] = 187, ["z"] = 30, ["name"] = "stairs:stair_steelblock"}, {["x"] = 2, ["meta"] = {["fields"] = {}, ["inventory"] = {}}, ["y"] = 0, ["z"] = 33, ["name"] = "mesecons_lightstone:lightstone_red_off"}, {["x"] = 2, ["meta"] = {["fields"] = {}, ["inventory"] = {}}, ["y"] = 0, ["z"] = 34, ["name"] = "mesecons_lightstone:lightstone_yellow_off"}, {["x"] = 2, ["meta"] = {["fields"] = {}, ["inventory"] = {}}, ["y"] = 0, ["z"] = 35, ["name"] = "mesecons_lightstone:lightstone_yellow_off"}, {["x"] = 2, ["meta"] = {["fields"] = {}, ["inventory"] = {}}, ["y"] = 0, ["z"] = 36, ["name"] = "mesecons_lightstone:lightstone_yellow_off"}, {["x"] = 2, ["meta"] = {["fields"] = {}, ["inventory"] = {}}, ["y"] = 0, ["z"] = 37, ["name"] = "mesecons_lightstone:lightstone_yellow_off"}, {["x"] = 2, ["meta"] = {["fields"] = {}, ["inventory"] = {}}, ["y"] = 0, ["z"] = 38, ["name"] = "mesecons_lightstone:lightstone_yellow_off"}, {["x"] = 2, ["meta"] = {["fields"] = {}, ["inventory"] = {}}, ["y"] = 0, ["z"] = 39, ["name"] = "mesecons_lightstone:lightstone_yellow_off"}, {["x"] = 2, ["meta"] = {["fields"] = {}, ["inventory"] = {}}, ["y"] = 0, ["z"] = 40, ["name"] = "mesecons_lightstone:lightstone_yellow_off"}, {["x"] = 2, ["meta"] = {["fields"] = {}, ["inventory"] = {}}, ["y"] = 0, ["z"] = 41, ["name"] = "mesecons_lightstone:lightstone_yellow_off"}, {["x"] = 2, ["meta"] = {["fields"] = {}, ["inventory"] = {}}, ["y"] = 0, ["z"] = 42, ["name"] = "mesecons_lightstone:lightstone_yellow_off"}, {["x"] = 2, ["meta"] = {["fields"] = {}, ["inventory"] = {}}, ["y"] = 0, ["z"] = 43, ["name"] = "mesecons_lightstone:lightstone_yellow_off"}, {["x"] = 2, ["meta"] = {["fields"] = {}, ["inventory"] = {}}, ["y"] = 0, ["z"] = 44, ["name"] = "mesecons_lightstone:lightstone_yellow_off"}, {["x"] = 2, ["meta"] = {["fields"] = {}, ["inventory"] = {}}, ["y"] = 0, ["z"] = 45, ["name"] = "mesecons_lightstone:lightstone_yellow_off"}, {["x"] = 2, ["meta"] = {["fields"] = {}, ["inventory"] = {}}, ["y"] = 0, ["z"] = 46, ["name"] = "mesecons_lightstone:lightstone_yellow_off"}, {["x"] = 2, ["meta"] = {["fields"] = {}, ["inventory"] = {}}, ["y"] = 0, ["z"] = 47, ["name"] = "mesecons_lightstone:lightstone_yellow_off"}, {["x"] = 2, ["meta"] = {["fields"] = {}, ["inventory"] = {}}, ["y"] = 0, ["z"] = 48, ["name"] = "mesecons_lightstone:lightstone_yellow_off"}, {["x"] = 2, ["meta"] = {["fields"] = {}, ["inventory"] = {}}, ["y"] = 0, ["z"] = 49, ["name"] = "mesecons_lightstone:lightstone_yellow_off"}, {["x"] = 2, ["meta"] = {["fields"] = {}, ["inventory"] = {}}, ["y"] = 0, ["z"] = 50, ["name"] = "mesecons_lightstone:lightstone_yellow_off"}, {["x"] = 2, ["meta"] = {["fields"] = {}, ["inventory"] = {}}, ["y"] = 0, ["z"] = 51, ["name"] = "mesecons_lightstone:lightstone_yellow_off"}, {["x"] = 2, ["meta"] = {["fields"] = {}, ["inventory"] = {}}, ["y"] = 0, ["z"] = 52, ["name"] = "mesecons_lightstone:lightstone_yellow_off"}, {["x"] = 2, ["meta"] = {["fields"] = {}, ["inventory"] = {}}, ["y"] = 0, ["z"] = 53, ["name"] = "mesecons_lightstone:lightstone_yellow_off"}, {["x"] = 2, ["meta"] = {["fields"] = {}, ["inventory"] = {}}, ["y"] = 0, ["z"] = 54, ["name"] = "mesecons_lightstone:lightstone_yellow_off"}, {["x"] = 2, ["meta"] = {["fields"] = {}, ["inventory"] = {}}, ["y"] = 0, ["z"] = 55, ["name"] = "mesecons_lightstone:lightstone_yellow_off"}, {["x"] = 2, ["meta"] = {["fields"] = {}, ["inventory"] = {}}, ["y"] = 0, ["z"] = 56, ["name"] = "mesecons_lightstone:lightstone_yellow_off"}, {["x"] = 2, ["meta"] = {["fields"] = {}, ["inventory"] = {}}, ["y"] = 0, ["z"] = 57, ["name"] = "mesecons_lightstone:lightstone_yellow_off"}, {["x"] = 2, ["meta"] = {["fields"] = {}, ["inventory"] = {}}, ["y"] = 0, ["z"] = 58, ["name"] = "mesecons_lightstone:lightstone_yellow_off"}, {["x"] = 2, ["meta"] = {["fields"] = {}, ["inventory"] = {}}, ["y"] = 0, ["z"] = 59, ["name"] = "mesecons_lightstone:lightstone_red_off"}, {["x"] = 2, ["meta"] = {["fields"] = {}, ["inventory"] = {}}, ["y"] = 0, ["z"] = 60, ["name"] = "default:meselamp"}, {["x"] = 2, ["meta"] = {["fields"] = {}, ["inventory"] = {}}, ["y"] = 0, ["z"] = 61, ["name"] = "default:meselamp"}, {["x"] = 2, ["meta"] = {["fields"] = {}, ["inventory"] = {}}, ["y"] = 0, ["z"] = 62, ["name"] = "mesecons_lightstone:lightstone_red_off"}, {["x"] = 2, ["meta"] = {["fields"] = {}, ["inventory"] = {}}, ["y"] = 0, ["z"] = 63, ["name"] = "mesecons_lightstone:lightstone_red_off"}, {["x"] = 2, ["meta"] = {["fields"] = {}, ["inventory"] = {}}, ["y"] = 0, ["z"] = 64, ["name"] = "mesecons_lightstone:lightstone_red_off"}, {["x"] = 2, ["meta"] = {["fields"] = {}, ["inventory"] = {}}, ["y"] = 1, ["z"] = 0, ["name"] = "spell:Letter_A"}, {["x"] = 2, ["meta"] = {["fields"] = {}, ["inventory"] = {}}, ["param2"] = 5, ["y"] = 1, ["param1"] = 221, ["z"] = 1, ["name"] = "homedecor:curtain_white"}, {["x"] = 2, ["meta"] = {["fields"] = {}, ["inventory"] = {}}, ["y"] = 1, ["z"] = 28, ["name"] = "mesecons_lightstone:lightstone_red_off"}, {["x"] = 2, ["meta"] = {["fields"] = {}, ["inventory"] = {}}, ["y"] = 1, ["param1"] = 204, ["z"] = 31, ["name"] = "stairs:stair_steelblock"}, {["x"] = 2, ["meta"] = {["fields"] = {}, ["inventory"] = {}}, ["y"] = 1, ["z"] = 33, ["name"] = "mesecons_lightstone:lightstone_red_off"}, {["x"] = 2, ["meta"] = {["fields"] = {}, ["inventory"] = {}}, ["y"] = 1, ["z"] = 59, ["name"] = "mesecons_lightstone:lightstone_red_off"}, {["x"] = 2, ["meta"] = {["fields"] = {}, ["inventory"] = {}}, ["y"] = 1, ["z"] = 60, ["name"] = "default:meselamp"}, {["x"] = 2, ["meta"] = {["fields"] = {}, ["inventory"] = {}}, ["y"] = 1, ["z"] = 61, ["name"] = "default:meselamp"}, {["x"] = 2, ["meta"] = {["fields"] = {}, ["inventory"] = {}}, ["y"] = 1, ["z"] = 62, ["name"] = "mesecons_lightstone:lightstone_red_off"}, {["x"] = 2, ["meta"] = {["fields"] = {}, ["inventory"] = {}}, ["y"] = 1, ["z"] = 63, ["name"] = "mesecons_lightstone:lightstone_red_off"}, {["x"] = 2, ["meta"] = {["fields"] = {}, ["inventory"] = {}}, ["y"] = 1, ["z"] = 64, ["name"] = "mesecons_lightstone:lightstone_red_off"}, {["x"] = 2, ["meta"] = {["fields"] = {}, ["inventory"] = {}}, ["y"] = 2, ["z"] = 0, ["name"] = "default:snowblock"}, {["x"] = 2, ["meta"] = {["fields"] = {}, ["inventory"] = {}}, ["param2"] = 5, ["y"] = 2, ["param1"] = 205, ["z"] = 1, ["name"] = "homedecor:curtain_white"}, {["x"] = 2, ["meta"] = {["fields"] = {}, ["inventory"] = {}}, ["y"] = 2, ["z"] = 28, ["name"] = "mesecons_lightstone:lightstone_red_off"}, {["x"] = 2, ["meta"] = {["fields"] = {}, ["inventory"] = {}}, ["y"] = 2, ["param1"] = 187, ["z"] = 32, ["name"] = "stairs:stair_steelblock"}, {["x"] = 2, ["meta"] = {["fields"] = {}, ["inventory"] = {}}, ["y"] = 2, ["z"] = 33, ["name"] = "mesecons_lightstone:lightstone_red_off"}, {["x"] = 2, ["meta"] = {["fields"] = {}, ["inventory"] = {}}, ["y"] = 2, ["z"] = 59, ["name"] = "mesecons_lightstone:lightstone_red_off"}, {["x"] = 2, ["meta"] = {["fields"] = {}, ["inventory"] = {}}, ["y"] = 2, ["z"] = 60, ["name"] = "default:meselamp"}, {["x"] = 2, ["meta"] = {["fields"] = {}, ["inventory"] = {}}, ["y"] = 2, ["z"] = 61, ["name"] = "default:meselamp"}, {["x"] = 2, ["meta"] = {["fields"] = {}, ["inventory"] = {}}, ["y"] = 2, ["z"] = 62, ["name"] = "mesecons_lightstone:lightstone_red_off"}, {["x"] = 2, ["meta"] = {["fields"] = {}, ["inventory"] = {}}, ["y"] = 2, ["z"] = 63, ["name"] = "mesecons_lightstone:lightstone_red_off"}, {["x"] = 2, ["meta"] = {["fields"] = {}, ["inventory"] = {}}, ["y"] = 2, ["z"] = 64, ["name"] = "mesecons_lightstone:lightstone_red_off"}, {["x"] = 2, ["meta"] = {["fields"] = {}, ["inventory"] = {}}, ["y"] = 3, ["z"] = 28, ["name"] = "mesecons_lightstone:lightstone_red_off"}, {["x"] = 2, ["meta"] = {["fields"] = {}, ["inventory"] = {}}, ["y"] = 3, ["z"] = 33, ["name"] = "mesecons_lightstone:lightstone_red_off"}, {["x"] = 2, ["meta"] = {["fields"] = {}, ["inventory"] = {}}, ["y"] = 3, ["z"] = 59, ["name"] = "mesecons_lightstone:lightstone_red_off"}, {["x"] = 2, ["meta"] = {["fields"] = {}, ["inventory"] = {}}, ["y"] = 3, ["z"] = 60, ["name"] = "default:meselamp"}, {["x"] = 2, ["meta"] = {["fields"] = {}, ["inventory"] = {}}, ["y"] = 3, ["z"] = 61, ["name"] = "default:meselamp"}, {["x"] = 2, ["meta"] = {["fields"] = {}, ["inventory"] = {}}, ["y"] = 3, ["z"] = 62, ["name"] = "mesecons_lightstone:lightstone_red_off"}, {["x"] = 2, ["meta"] = {["fields"] = {}, ["inventory"] = {}}, ["y"] = 3, ["z"] = 63, ["name"] = "mesecons_lightstone:lightstone_red_off"}, {["x"] = 2, ["meta"] = {["fields"] = {}, ["inventory"] = {}}, ["y"] = 3, ["z"] = 64, ["name"] = "mesecons_lightstone:lightstone_red_off"}, {["x"] = 2, ["meta"] = {["fields"] = {}, ["inventory"] = {}}, ["y"] = 4, ["z"] = 28, ["name"] = "mesecons_lightstone:lightstone_red_off"}, {["x"] = 2, ["meta"] = {["fields"] = {}, ["inventory"] = {}}, ["y"] = 4, ["z"] = 33, ["name"] = "mesecons_lightstone:lightstone_red_off"}, {["x"] = 2, ["meta"] = {["fields"] = {}, ["inventory"] = {}}, ["y"] = 4, ["z"] = 36, ["name"] = "mesecons_lightstone:lightstone_green_off"}, {["x"] = 2, ["meta"] = {["fields"] = {}, ["inventory"] = {}}, ["y"] = 4, ["z"] = 41, ["name"] = "mesecons_lightstone:lightstone_green_off"}, {["x"] = 2, ["meta"] = {["fields"] = {}, ["inventory"] = {}}, ["y"] = 4, ["z"] = 46, ["name"] = "mesecons_lightstone:lightstone_green_off"}, {["x"] = 2, ["meta"] = {["fields"] = {}, ["inventory"] = {}}, ["y"] = 4, ["z"] = 51, ["name"] = "mesecons_lightstone:lightstone_green_off"}, {["x"] = 2, ["meta"] = {["fields"] = {}, ["inventory"] = {}}, ["y"] = 4, ["z"] = 56, ["name"] = "mesecons_lightstone:lightstone_green_off"}, {["x"] = 2, ["meta"] = {["fields"] = {}, ["inventory"] = {}}, ["y"] = 4, ["z"] = 59, ["name"] = "mesecons_lightstone:lightstone_red_off"}, {["x"] = 2, ["meta"] = {["fields"] = {}, ["inventory"] = {}}, ["y"] = 4, ["z"] = 60, ["name"] = "default:meselamp"}, {["x"] = 2, ["meta"] = {["fields"] = {}, ["inventory"] = {}}, ["y"] = 4, ["z"] = 61, ["name"] = "default:meselamp"}, {["x"] = 2, ["meta"] = {["fields"] = {}, ["inventory"] = {}}, ["y"] = 4, ["z"] = 62, ["name"] = "mesecons_lightstone:lightstone_red_off"}, {["x"] = 2, ["meta"] = {["fields"] = {}, ["inventory"] = {}}, ["y"] = 4, ["z"] = 63, ["name"] = "mesecons_lightstone:lightstone_red_off"}, {["x"] = 2, ["meta"] = {["fields"] = {}, ["inventory"] = {}}, ["y"] = 4, ["z"] = 64, ["name"] = "mesecons_lightstone:lightstone_red_off"}, {["x"] = 2, ["meta"] = {["fields"] = {}, ["inventory"] = {}}, ["y"] = 5, ["z"] = 28, ["name"] = "mesecons_lightstone:lightstone_red_off"}, {["x"] = 2, ["meta"] = {["fields"] = {}, ["inventory"] = {}}, ["y"] = 5, ["z"] = 29, ["name"] = "default:steelblock"}, {["x"] = 2, ["meta"] = {["fields"] = {}, ["inventory"] = {}}, ["y"] = 5, ["z"] = 33, ["name"] = "mesecons_lightstone:lightstone_red_off"}, {["x"] = 2, ["meta"] = {["fields"] = {}, ["inventory"] = {}}, ["y"] = 5, ["z"] = 36, ["name"] = "mesecons_lightstone:lightstone_green_off"}, {["x"] = 2, ["meta"] = {["fields"] = {}, ["inventory"] = {}}, ["y"] = 5, ["z"] = 41, ["name"] = "mesecons_lightstone:lightstone_green_off"}, {["x"] = 2, ["meta"] = {["fields"] = {}, ["inventory"] = {}}, ["y"] = 5, ["z"] = 46, ["name"] = "mesecons_lightstone:lightstone_green_off"}, {["x"] = 2, ["meta"] = {["fields"] = {}, ["inventory"] = {}}, ["y"] = 5, ["z"] = 51, ["name"] = "mesecons_lightstone:lightstone_green_off"}, {["x"] = 2, ["meta"] = {["fields"] = {}, ["inventory"] = {}}, ["y"] = 5, ["z"] = 56, ["name"] = "mesecons_lightstone:lightstone_green_off"}, {["x"] = 2, ["meta"] = {["fields"] = {}, ["inventory"] = {}}, ["y"] = 5, ["z"] = 59, ["name"] = "mesecons_lightstone:lightstone_red_off"}, {["x"] = 2, ["meta"] = {["fields"] = {}, ["inventory"] = {}}, ["y"] = 5, ["z"] = 60, ["name"] = "default:meselamp"}, {["x"] = 2, ["meta"] = {["fields"] = {}, ["inventory"] = {}}, ["y"] = 5, ["z"] = 61, ["name"] = "default:meselamp"}, {["x"] = 2, ["meta"] = {["fields"] = {}, ["inventory"] = {}}, ["y"] = 5, ["z"] = 62, ["name"] = "mesecons_lightstone:lightstone_red_off"}, {["x"] = 2, ["meta"] = {["fields"] = {}, ["inventory"] = {}}, ["y"] = 5, ["z"] = 63, ["name"] = "mesecons_lightstone:lightstone_red_off"}, {["x"] = 2, ["meta"] = {["fields"] = {}, ["inventory"] = {}}, ["y"] = 5, ["z"] = 64, ["name"] = "mesecons_lightstone:lightstone_red_off"}, {["x"] = 2, ["meta"] = {["fields"] = {}, ["inventory"] = {}}, ["y"] = 6, ["z"] = 28, ["name"] = "mesecons_lightstone:lightstone_red_off"}, {["x"] = 2, ["meta"] = {["fields"] = {}, ["inventory"] = {}}, ["y"] = 6, ["param1"] = 187, ["z"] = 30, ["name"] = "stairs:stair_steelblock"}, {["x"] = 2, ["meta"] = {["fields"] = {}, ["inventory"] = {}}, ["y"] = 6, ["param1"] = 187, ["z"] = 31, ["name"] = "stairs:slab_steelblock"}, {["x"] = 2, ["meta"] = {["fields"] = {}, ["inventory"] = {}}, ["y"] = 6, ["param1"] = 187, ["z"] = 32, ["name"] = "stairs:slab_steelblock"}, {["x"] = 2, ["meta"] = {["fields"] = {}, ["inventory"] = {}}, ["y"] = 6, ["z"] = 33, ["name"] = "mesecons_lightstone:lightstone_red_off"}, {["x"] = 2, ["meta"] = {["fields"] = {}, ["inventory"] = {}}, ["y"] = 6, ["z"] = 34, ["name"] = "moreblocks:wood_tile_full"}, {["x"] = 2, ["meta"] = {["fields"] = {}, ["inventory"] = {}}, ["y"] = 6, ["z"] = 35, ["name"] = "moreblocks:wood_tile_full"}, {["x"] = 2, ["meta"] = {["fields"] = {}, ["inventory"] = {}}, ["y"] = 6, ["z"] = 36, ["name"] = "moreblocks:wood_tile_full"}, {["x"] = 2, ["meta"] = {["fields"] = {}, ["inventory"] = {}}, ["y"] = 6, ["z"] = 37, ["name"] = "moreblocks:wood_tile_full"}, {["x"] = 2, ["meta"] = {["fields"] = {}, ["inventory"] = {}}, ["y"] = 6, ["z"] = 38, ["name"] = "moreblocks:wood_tile_full"}, {["x"] = 2, ["meta"] = {["fields"] = {}, ["inventory"] = {}}, ["y"] = 6, ["z"] = 39, ["name"] = "moreblocks:wood_tile_full"}, {["x"] = 2, ["meta"] = {["fields"] = {}, ["inventory"] = {}}, ["y"] = 6, ["z"] = 40, ["name"] = "moreblocks:wood_tile_full"}, {["x"] = 2, ["meta"] = {["fields"] = {}, ["inventory"] = {}}, ["y"] = 6, ["z"] = 41, ["name"] = "moreblocks:wood_tile_full"}, {["x"] = 2, ["meta"] = {["fields"] = {}, ["inventory"] = {}}, ["y"] = 6, ["z"] = 42, ["name"] = "moreblocks:wood_tile_full"}, {["x"] = 2, ["meta"] = {["fields"] = {}, ["inventory"] = {}}, ["y"] = 6, ["z"] = 43, ["name"] = "moreblocks:wood_tile_full"}, {["x"] = 2, ["meta"] = {["fields"] = {}, ["inventory"] = {}}, ["y"] = 6, ["z"] = 44, ["name"] = "moreblocks:wood_tile_full"}, {["x"] = 2, ["meta"] = {["fields"] = {}, ["inventory"] = {}}, ["y"] = 6, ["z"] = 45, ["name"] = "moreblocks:wood_tile_full"}, {["x"] = 2, ["meta"] = {["fields"] = {}, ["inventory"] = {}}, ["y"] = 6, ["z"] = 46, ["name"] = "moreblocks:wood_tile_full"}, {["x"] = 2, ["meta"] = {["fields"] = {}, ["inventory"] = {}}, ["y"] = 6, ["z"] = 47, ["name"] = "moreblocks:wood_tile_full"}, {["x"] = 2, ["meta"] = {["fields"] = {}, ["inventory"] = {}}, ["y"] = 6, ["z"] = 48, ["name"] = "moreblocks:wood_tile_full"}, {["x"] = 2, ["meta"] = {["fields"] = {}, ["inventory"] = {}}, ["y"] = 6, ["z"] = 49, ["name"] = "moreblocks:wood_tile_full"}, {["x"] = 2, ["meta"] = {["fields"] = {}, ["inventory"] = {}}, ["y"] = 6, ["z"] = 50, ["name"] = "moreblocks:wood_tile_full"}, {["x"] = 2, ["meta"] = {["fields"] = {}, ["inventory"] = {}}, ["y"] = 6, ["z"] = 51, ["name"] = "moreblocks:wood_tile_full"}, {["x"] = 2, ["meta"] = {["fields"] = {}, ["inventory"] = {}}, ["y"] = 6, ["z"] = 52, ["name"] = "moreblocks:wood_tile_full"}, {["x"] = 2, ["meta"] = {["fields"] = {}, ["inventory"] = {}}, ["y"] = 6, ["z"] = 53, ["name"] = "moreblocks:wood_tile_full"}, {["x"] = 2, ["meta"] = {["fields"] = {}, ["inventory"] = {}}, ["y"] = 6, ["z"] = 54, ["name"] = "moreblocks:wood_tile_full"}, {["x"] = 2, ["meta"] = {["fields"] = {}, ["inventory"] = {}}, ["y"] = 6, ["z"] = 55, ["name"] = "moreblocks:wood_tile_full"}, {["x"] = 2, ["meta"] = {["fields"] = {}, ["inventory"] = {}}, ["y"] = 6, ["z"] = 56, ["name"] = "moreblocks:wood_tile_full"}, {["x"] = 2, ["meta"] = {["fields"] = {}, ["inventory"] = {}}, ["y"] = 6, ["z"] = 57, ["name"] = "moreblocks:wood_tile_full"}, {["x"] = 2, ["meta"] = {["fields"] = {}, ["inventory"] = {}}, ["y"] = 6, ["z"] = 58, ["name"] = "moreblocks:wood_tile_full"}, {["x"] = 2, ["meta"] = {["fields"] = {}, ["inventory"] = {}}, ["y"] = 6, ["z"] = 59, ["name"] = "mesecons_lightstone:lightstone_red_off"}, {["x"] = 2, ["meta"] = {["fields"] = {}, ["inventory"] = {}}, ["y"] = 6, ["z"] = 60, ["name"] = "default:meselamp"}, {["x"] = 2, ["meta"] = {["fields"] = {}, ["inventory"] = {}}, ["y"] = 6, ["z"] = 61, ["name"] = "default:meselamp"}, {["x"] = 2, ["meta"] = {["fields"] = {}, ["inventory"] = {}}, ["y"] = 6, ["z"] = 62, ["name"] = "mesecons_lightstone:lightstone_red_off"}, {["x"] = 2, ["meta"] = {["fields"] = {}, ["inventory"] = {}}, ["y"] = 6, ["z"] = 63, ["name"] = "mesecons_lightstone:lightstone_red_off"}, {["x"] = 2, ["meta"] = {["fields"] = {}, ["inventory"] = {}}, ["y"] = 6, ["z"] = 64, ["name"] = "mesecons_lightstone:lightstone_red_off"}, {["x"] = 2, ["meta"] = {["fields"] = {}, ["inventory"] = {}}, ["y"] = 7, ["z"] = 28, ["name"] = "mesecons_lightstone:lightstone_red_off"}, {["x"] = 2, ["meta"] = {["fields"] = {}, ["inventory"] = {}}, ["y"] = 7, ["param1"] = 204, ["z"] = 31, ["name"] = "stairs:stair_steelblock"}, {["x"] = 2, ["meta"] = {["fields"] = {}, ["inventory"] = {}}, ["param2"] = 2, ["y"] = 7, ["param1"] = 173, ["z"] = 34, ["name"] = "stairs:stair_steelblock"}, {["x"] = 2, ["meta"] = {["fields"] = {}, ["inventory"] = {}}, ["y"] = 7, ["z"] = 59, ["name"] = "mesecons_lightstone:lightstone_red_off"}, {["x"] = 2, ["meta"] = {["fields"] = {}, ["inventory"] = {}}, ["y"] = 7, ["z"] = 60, ["name"] = "default:meselamp"}, {["x"] = 2, ["meta"] = {["fields"] = {}, ["inventory"] = {}}, ["y"] = 7, ["z"] = 61, ["name"] = "default:meselamp"}, {["x"] = 2, ["meta"] = {["fields"] = {}, ["inventory"] = {}}, ["y"] = 7, ["z"] = 62, ["name"] = "mesecons_lightstone:lightstone_red_off"}, {["x"] = 2, ["meta"] = {["fields"] = {}, ["inventory"] = {}}, ["y"] = 7, ["z"] = 63, ["name"] = "mesecons_lightstone:lightstone_red_off"}, {["x"] = 2, ["meta"] = {["fields"] = {}, ["inventory"] = {}}, ["y"] = 7, ["z"] = 64, ["name"] = "mesecons_lightstone:lightstone_red_off"}, {["x"] = 2, ["meta"] = {["fields"] = {}, ["inventory"] = {}}, ["y"] = 8, ["z"] = 28, ["name"] = "mesecons_lightstone:lightstone_red_off"}, {["x"] = 2, ["meta"] = {["fields"] = {}, ["inventory"] = {}}, ["y"] = 8, ["param1"] = 188, ["z"] = 32, ["name"] = "stairs:stair_steelblock"}, {["x"] = 2, ["meta"] = {["fields"] = {}, ["inventory"] = {}}, ["param2"] = 2, ["y"] = 8, ["param1"] = 173, ["z"] = 33, ["name"] = "stairs:stair_steelblock"}, {["x"] = 2, ["meta"] = {["fields"] = {}, ["inventory"] = {}}, ["y"] = 8, ["z"] = 59, ["name"] = "mesecons_lightstone:lightstone_red_off"}, {["x"] = 2, ["meta"] = {["fields"] = {}, ["inventory"] = {}}, ["y"] = 8, ["z"] = 60, ["name"] = "default:meselamp"}, {["x"] = 2, ["meta"] = {["fields"] = {}, ["inventory"] = {}}, ["y"] = 8, ["z"] = 61, ["name"] = "default:meselamp"}, {["x"] = 2, ["meta"] = {["fields"] = {}, ["inventory"] = {}}, ["y"] = 8, ["z"] = 62, ["name"] = "mesecons_lightstone:lightstone_red_off"}, {["x"] = 2, ["meta"] = {["fields"] = {}, ["inventory"] = {}}, ["y"] = 8, ["z"] = 63, ["name"] = "mesecons_lightstone:lightstone_red_off"}, {["x"] = 2, ["meta"] = {["fields"] = {}, ["inventory"] = {}}, ["y"] = 8, ["z"] = 64, ["name"] = "mesecons_lightstone:lightstone_red_off"}, {["x"] = 2, ["meta"] = {["fields"] = {}, ["inventory"] = {}}, ["y"] = 9, ["z"] = 28, ["name"] = "mesecons_lightstone:lightstone_red_off"}, {["x"] = 2, ["meta"] = {["fields"] = {}, ["inventory"] = {}}, ["y"] = 9, ["z"] = 59, ["name"] = "mesecons_lightstone:lightstone_red_off"}, {["x"] = 2, ["meta"] = {["fields"] = {}, ["inventory"] = {}}, ["y"] = 9, ["z"] = 60, ["name"] = "default:meselamp"}, {["x"] = 2, ["meta"] = {["fields"] = {}, ["inventory"] = {}}, ["y"] = 9, ["z"] = 61, ["name"] = "default:meselamp"}, {["x"] = 2, ["meta"] = {["fields"] = {}, ["inventory"] = {}}, ["y"] = 9, ["z"] = 62, ["name"] = "mesecons_lightstone:lightstone_red_off"}, {["x"] = 2, ["meta"] = {["fields"] = {}, ["inventory"] = {}}, ["y"] = 9, ["z"] = 63, ["name"] = "mesecons_lightstone:lightstone_red_off"}, {["x"] = 2, ["meta"] = {["fields"] = {}, ["inventory"] = {}}, ["y"] = 9, ["z"] = 64, ["name"] = "mesecons_lightstone:lightstone_red_off"}, {["x"] = 2, ["meta"] = {["fields"] = {}, ["inventory"] = {}}, ["y"] = 10, ["z"] = 28, ["name"] = "mesecons_lightstone:lightstone_red_off"}, {["x"] = 2, ["meta"] = {["fields"] = {}, ["inventory"] = {}}, ["y"] = 10, ["z"] = 29, ["name"] = "default:meselamp"}, {["x"] = 2, ["meta"] = {["fields"] = {}, ["inventory"] = {}}, ["y"] = 10, ["z"] = 59, ["name"] = "mesecons_lightstone:lightstone_red_off"}, {["x"] = 2, ["meta"] = {["fields"] = {}, ["inventory"] = {}}, ["y"] = 10, ["z"] = 60, ["name"] = "default:meselamp"}, {["x"] = 2, ["meta"] = {["fields"] = {}, ["inventory"] = {}}, ["y"] = 10, ["z"] = 61, ["name"] = "default:meselamp"}, {["x"] = 2, ["meta"] = {["fields"] = {}, ["inventory"] = {}}, ["y"] = 10, ["z"] = 62, ["name"] = "mesecons_lightstone:lightstone_red_off"}, {["x"] = 2, ["meta"] = {["fields"] = {}, ["inventory"] = {}}, ["y"] = 10, ["z"] = 63, ["name"] = "mesecons_lightstone:lightstone_red_off"}, {["x"] = 2, ["meta"] = {["fields"] = {}, ["inventory"] = {}}, ["y"] = 10, ["z"] = 64, ["name"] = "mesecons_lightstone:lightstone_red_off"}, {["x"] = 2, ["meta"] = {["fields"] = {}, ["inventory"] = {}}, ["y"] = 11, ["param1"] = 13, ["z"] = 28, ["name"] = "mesecons_lightstone:lightstone_red_off"}, {["x"] = 2, ["meta"] = {["fields"] = {}, ["inventory"] = {}}, ["y"] = 11, ["z"] = 29, ["name"] = "default:meselamp"}, {["x"] = 2, ["meta"] = {["fields"] = {}, ["inventory"] = {}}, ["y"] = 11, ["param1"] = 13, ["z"] = 33, ["name"] = "mesecons_lightstone:lightstone_red_off"}, {["x"] = 2, ["meta"] = {["fields"] = {}, ["inventory"] = {}}, ["y"] = 11, ["param1"] = 13, ["z"] = 59, ["name"] = "mesecons_lightstone:lightstone_red_off"}, {["x"] = 2, ["meta"] = {["fields"] = {}, ["inventory"] = {}}, ["y"] = 11, ["z"] = 60, ["name"] = "default:meselamp"}, {["x"] = 2, ["meta"] = {["fields"] = {}, ["inventory"] = {}}, ["y"] = 11, ["z"] = 61, ["name"] = "default:meselamp"}, {["x"] = 2, ["meta"] = {["fields"] = {}, ["inventory"] = {}}, ["y"] = 11, ["param1"] = 13, ["z"] = 62, ["name"] = "mesecons_lightstone:lightstone_red_off"}, {["x"] = 2, ["meta"] = {["fields"] = {}, ["inventory"] = {}}, ["y"] = 11, ["param1"] = 13, ["z"] = 63, ["name"] = "mesecons_lightstone:lightstone_red_off"}, {["x"] = 2, ["meta"] = {["fields"] = {}, ["inventory"] = {}}, ["y"] = 11, ["param1"] = 13, ["z"] = 64, ["name"] = "mesecons_lightstone:lightstone_red_off"}, {["x"] = 2, ["meta"] = {["fields"] = {}, ["inventory"] = {}}, ["y"] = 12, ["z"] = 28, ["name"] = "mesecons_lightstone:lightstone_red_off"}, {["x"] = 2, ["meta"] = {["fields"] = {}, ["inventory"] = {}}, ["y"] = 12, ["z"] = 29, ["name"] = "default:meselamp"}, {["x"] = 2, ["meta"] = {["fields"] = {}, ["inventory"] = {}}, ["y"] = 12, ["z"] = 33, ["name"] = "mesecons_lightstone:lightstone_red_off"}, {["x"] = 2, ["meta"] = {["fields"] = {}, ["inventory"] = {}}, ["y"] = 12, ["z"] = 59, ["name"] = "mesecons_lightstone:lightstone_red_off"}, {["x"] = 2, ["meta"] = {["fields"] = {}, ["inventory"] = {}}, ["y"] = 12, ["z"] = 60, ["name"] = "default:meselamp"}, {["x"] = 2, ["meta"] = {["fields"] = {}, ["inventory"] = {}}, ["y"] = 12, ["z"] = 61, ["name"] = "default:meselamp"}, {["x"] = 2, ["meta"] = {["fields"] = {}, ["inventory"] = {}}, ["y"] = 12, ["z"] = 62, ["name"] = "mesecons_lightstone:lightstone_red_off"}, {["x"] = 2, ["meta"] = {["fields"] = {}, ["inventory"] = {}}, ["y"] = 12, ["z"] = 63, ["name"] = "mesecons_lightstone:lightstone_red_off"}, {["x"] = 2, ["meta"] = {["fields"] = {}, ["inventory"] = {}}, ["y"] = 12, ["z"] = 64, ["name"] = "mesecons_lightstone:lightstone_red_off"}, {["x"] = 2, ["meta"] = {["fields"] = {}, ["inventory"] = {}}, ["y"] = 13, ["z"] = 28, ["name"] = "mesecons_lightstone:lightstone_red_off"}, {["x"] = 2, ["meta"] = {["fields"] = {}, ["inventory"] = {}}, ["y"] = 13, ["z"] = 29, ["name"] = "default:meselamp"}, {["x"] = 2, ["meta"] = {["fields"] = {}, ["inventory"] = {}}, ["y"] = 13, ["z"] = 30, ["name"] = "default:meselamp"}, {["x"] = 2, ["meta"] = {["fields"] = {}, ["inventory"] = {}}, ["y"] = 13, ["z"] = 31, ["name"] = "default:meselamp"}, {["x"] = 2, ["meta"] = {["fields"] = {}, ["inventory"] = {}}, ["y"] = 13, ["z"] = 32, ["name"] = "default:meselamp"}, {["x"] = 2, ["meta"] = {["fields"] = {}, ["inventory"] = {}}, ["y"] = 13, ["z"] = 33, ["name"] = "mesecons_lightstone:lightstone_red_off"}, {["x"] = 2, ["meta"] = {["fields"] = {}, ["inventory"] = {}}, ["y"] = 13, ["z"] = 59, ["name"] = "mesecons_lightstone:lightstone_red_off"}, {["x"] = 2, ["meta"] = {["fields"] = {}, ["inventory"] = {}}, ["y"] = 13, ["z"] = 60, ["name"] = "default:meselamp"}, {["x"] = 2, ["meta"] = {["fields"] = {}, ["inventory"] = {}}, ["y"] = 13, ["z"] = 61, ["name"] = "default:meselamp"}, {["x"] = 2, ["meta"] = {["fields"] = {}, ["inventory"] = {}}, ["y"] = 13, ["z"] = 62, ["name"] = "mesecons_lightstone:lightstone_red_off"}, {["x"] = 2, ["meta"] = {["fields"] = {}, ["inventory"] = {}}, ["y"] = 13, ["z"] = 63, ["name"] = "mesecons_lightstone:lightstone_red_off"}, {["x"] = 2, ["meta"] = {["fields"] = {}, ["inventory"] = {}}, ["y"] = 13, ["z"] = 64, ["name"] = "mesecons_lightstone:lightstone_red_off"}, {["x"] = 2, ["meta"] = {["fields"] = {}, ["inventory"] = {}}, ["y"] = 14, ["z"] = 28, ["name"] = "mesecons_lightstone:lightstone_red_off"}, {["x"] = 2, ["meta"] = {["fields"] = {}, ["inventory"] = {}}, ["y"] = 14, ["z"] = 29, ["name"] = "mesecons_lightstone:lightstone_red_off"}, {["x"] = 2, ["meta"] = {["fields"] = {}, ["inventory"] = {}}, ["y"] = 14, ["z"] = 30, ["name"] = "mesecons_lightstone:lightstone_red_off"}, {["x"] = 2, ["meta"] = {["fields"] = {}, ["inventory"] = {}}, ["y"] = 14, ["z"] = 31, ["name"] = "mesecons_lightstone:lightstone_red_off"}, {["x"] = 2, ["meta"] = {["fields"] = {}, ["inventory"] = {}}, ["y"] = 14, ["z"] = 32, ["name"] = "mesecons_lightstone:lightstone_red_off"}, {["x"] = 2, ["meta"] = {["fields"] = {}, ["inventory"] = {}}, ["y"] = 14, ["z"] = 33, ["name"] = "mesecons_lightstone:lightstone_red_off"}, {["x"] = 2, ["meta"] = {["fields"] = {}, ["inventory"] = {}}, ["y"] = 14, ["z"] = 59, ["name"] = "mesecons_lightstone:lightstone_red_off"}, {["x"] = 2, ["meta"] = {["fields"] = {}, ["inventory"] = {}}, ["y"] = 14, ["z"] = 60, ["name"] = "mesecons_lightstone:lightstone_red_off"}, {["x"] = 2, ["meta"] = {["fields"] = {}, ["inventory"] = {}}, ["y"] = 14, ["z"] = 61, ["name"] = "mesecons_lightstone:lightstone_red_off"}, {["x"] = 2, ["meta"] = {["fields"] = {}, ["inventory"] = {}}, ["y"] = 14, ["z"] = 62, ["name"] = "mesecons_lightstone:lightstone_red_off"}, {["x"] = 2, ["meta"] = {["fields"] = {}, ["inventory"] = {}}, ["y"] = 14, ["z"] = 63, ["name"] = "mesecons_lightstone:lightstone_red_off"}, {["x"] = 2, ["meta"] = {["fields"] = {}, ["inventory"] = {}}, ["y"] = 14, ["z"] = 64, ["name"] = "mesecons_lightstone:lightstone_red_off"}, {["x"] = 2, ["meta"] = {["fields"] = {}, ["inventory"] = {}}, ["y"] = 15, ["z"] = 28, ["name"] = "mesecons_lightstone:lightstone_red_off"}, {["x"] = 2, ["meta"] = {["fields"] = {}, ["inventory"] = {}}, ["y"] = 15, ["z"] = 29, ["name"] = "mesecons_lightstone:lightstone_red_off"}, {["x"] = 2, ["meta"] = {["fields"] = {}, ["inventory"] = {}}, ["y"] = 15, ["z"] = 30, ["name"] = "mesecons_lightstone:lightstone_red_off"}, {["x"] = 2, ["meta"] = {["fields"] = {}, ["inventory"] = {}}, ["y"] = 15, ["z"] = 31, ["name"] = "mesecons_lightstone:lightstone_red_off"}, {["x"] = 2, ["meta"] = {["fields"] = {}, ["inventory"] = {}}, ["y"] = 15, ["z"] = 32, ["name"] = "mesecons_lightstone:lightstone_red_off"}, {["x"] = 2, ["meta"] = {["fields"] = {}, ["inventory"] = {}}, ["y"] = 15, ["z"] = 33, ["name"] = "mesecons_lightstone:lightstone_red_off"}, {["x"] = 2, ["meta"] = {["fields"] = {}, ["inventory"] = {}}, ["y"] = 15, ["z"] = 59, ["name"] = "mesecons_lightstone:lightstone_red_off"}, {["x"] = 2, ["meta"] = {["fields"] = {}, ["inventory"] = {}}, ["y"] = 15, ["z"] = 60, ["name"] = "mesecons_lightstone:lightstone_red_off"}, {["x"] = 2, ["meta"] = {["fields"] = {}, ["inventory"] = {}}, ["y"] = 15, ["z"] = 61, ["name"] = "mesecons_lightstone:lightstone_red_off"}, {["x"] = 2, ["meta"] = {["fields"] = {}, ["inventory"] = {}}, ["y"] = 15, ["z"] = 62, ["name"] = "mesecons_lightstone:lightstone_red_off"}, {["x"] = 2, ["meta"] = {["fields"] = {}, ["inventory"] = {}}, ["y"] = 15, ["z"] = 63, ["name"] = "mesecons_lightstone:lightstone_red_off"}, {["x"] = 2, ["meta"] = {["fields"] = {}, ["inventory"] = {}}, ["y"] = 15, ["z"] = 64, ["name"] = "mesecons_lightstone:lightstone_red_off"}, {["x"] = 2, ["meta"] = {["fields"] = {}, ["inventory"] = {}}, ["y"] = 16, ["z"] = 28, ["name"] = "mesecons_lightstone:lightstone_red_off"}, {["x"] = 2, ["meta"] = {["fields"] = {}, ["inventory"] = {}}, ["y"] = 16, ["z"] = 29, ["name"] = "mesecons_lightstone:lightstone_red_off"}, {["x"] = 2, ["meta"] = {["fields"] = {}, ["inventory"] = {}}, ["y"] = 16, ["z"] = 30, ["name"] = "mesecons_lightstone:lightstone_red_off"}, {["x"] = 2, ["meta"] = {["fields"] = {}, ["inventory"] = {}}, ["y"] = 16, ["z"] = 31, ["name"] = "mesecons_lightstone:lightstone_red_off"}, {["x"] = 2, ["meta"] = {["fields"] = {}, ["inventory"] = {}}, ["y"] = 16, ["z"] = 32, ["name"] = "mesecons_lightstone:lightstone_red_off"}, {["x"] = 2, ["meta"] = {["fields"] = {}, ["inventory"] = {}}, ["y"] = 16, ["z"] = 33, ["name"] = "mesecons_lightstone:lightstone_red_off"}, {["x"] = 2, ["meta"] = {["fields"] = {}, ["inventory"] = {}}, ["y"] = 16, ["z"] = 59, ["name"] = "mesecons_lightstone:lightstone_red_off"}, {["x"] = 2, ["meta"] = {["fields"] = {}, ["inventory"] = {}}, ["y"] = 16, ["z"] = 60, ["name"] = "mesecons_lightstone:lightstone_red_off"}, {["x"] = 2, ["meta"] = {["fields"] = {}, ["inventory"] = {}}, ["y"] = 16, ["z"] = 61, ["name"] = "mesecons_lightstone:lightstone_red_off"}, {["x"] = 2, ["meta"] = {["fields"] = {}, ["inventory"] = {}}, ["y"] = 16, ["z"] = 62, ["name"] = "mesecons_lightstone:lightstone_red_off"}, {["x"] = 2, ["meta"] = {["fields"] = {}, ["inventory"] = {}}, ["y"] = 16, ["z"] = 63, ["name"] = "mesecons_lightstone:lightstone_red_off"}, {["x"] = 2, ["meta"] = {["fields"] = {}, ["inventory"] = {}}, ["y"] = 16, ["z"] = 64, ["name"] = "mesecons_lightstone:lightstone_red_off"}, {["x"] = 2, ["meta"] = {["fields"] = {}, ["inventory"] = {}}, ["y"] = 17, ["z"] = 28, ["name"] = "mesecons_lightstone:lightstone_red_off"}, {["x"] = 2, ["meta"] = {["fields"] = {}, ["inventory"] = {}}, ["y"] = 17, ["z"] = 29, ["name"] = "mesecons_lightstone:lightstone_red_off"}, {["x"] = 2, ["meta"] = {["fields"] = {}, ["inventory"] = {}}, ["y"] = 17, ["z"] = 30, ["name"] = "mesecons_lightstone:lightstone_red_off"}, {["x"] = 2, ["meta"] = {["fields"] = {}, ["inventory"] = {}}, ["y"] = 17, ["z"] = 31, ["name"] = "mesecons_lightstone:lightstone_red_off"}, {["x"] = 2, ["meta"] = {["fields"] = {}, ["inventory"] = {}}, ["y"] = 17, ["z"] = 32, ["name"] = "mesecons_lightstone:lightstone_red_off"}, {["x"] = 2, ["meta"] = {["fields"] = {}, ["inventory"] = {}}, ["y"] = 17, ["z"] = 33, ["name"] = "mesecons_lightstone:lightstone_red_off"}, {["x"] = 2, ["meta"] = {["fields"] = {}, ["inventory"] = {}}, ["y"] = 17, ["z"] = 59, ["name"] = "mesecons_lightstone:lightstone_red_off"}, {["x"] = 2, ["meta"] = {["fields"] = {}, ["inventory"] = {}}, ["y"] = 17, ["z"] = 60, ["name"] = "mesecons_lightstone:lightstone_red_off"}, {["x"] = 2, ["meta"] = {["fields"] = {}, ["inventory"] = {}}, ["y"] = 17, ["z"] = 61, ["name"] = "mesecons_lightstone:lightstone_red_off"}, {["x"] = 2, ["meta"] = {["fields"] = {}, ["inventory"] = {}}, ["y"] = 17, ["z"] = 62, ["name"] = "mesecons_lightstone:lightstone_red_off"}, {["x"] = 2, ["meta"] = {["fields"] = {}, ["inventory"] = {}}, ["y"] = 17, ["z"] = 63, ["name"] = "mesecons_lightstone:lightstone_red_off"}, {["x"] = 2, ["meta"] = {["fields"] = {}, ["inventory"] = {}}, ["y"] = 17, ["z"] = 64, ["name"] = "mesecons_lightstone:lightstone_red_off"}, {["x"] = 2, ["meta"] = {["fields"] = {}, ["inventory"] = {}}, ["y"] = 18, ["z"] = 28, ["name"] = "mesecons_lightstone:lightstone_red_off"}, {["x"] = 2, ["meta"] = {["fields"] = {}, ["inventory"] = {}}, ["y"] = 18, ["z"] = 29, ["name"] = "mesecons_lightstone:lightstone_red_off"}, {["x"] = 2, ["meta"] = {["fields"] = {}, ["inventory"] = {}}, ["y"] = 18, ["z"] = 30, ["name"] = "mesecons_lightstone:lightstone_red_off"}, {["x"] = 2, ["meta"] = {["fields"] = {}, ["inventory"] = {}}, ["y"] = 18, ["z"] = 31, ["name"] = "mesecons_lightstone:lightstone_red_off"}, {["x"] = 2, ["meta"] = {["fields"] = {}, ["inventory"] = {}}, ["y"] = 18, ["z"] = 32, ["name"] = "mesecons_lightstone:lightstone_red_off"}, {["x"] = 2, ["meta"] = {["fields"] = {}, ["inventory"] = {}}, ["y"] = 18, ["z"] = 33, ["name"] = "mesecons_lightstone:lightstone_red_off"}, {["x"] = 2, ["meta"] = {["fields"] = {}, ["inventory"] = {}}, ["y"] = 18, ["z"] = 59, ["name"] = "mesecons_lightstone:lightstone_red_off"}, {["x"] = 2, ["meta"] = {["fields"] = {}, ["inventory"] = {}}, ["y"] = 18, ["z"] = 60, ["name"] = "mesecons_lightstone:lightstone_red_off"}, {["x"] = 2, ["meta"] = {["fields"] = {}, ["inventory"] = {}}, ["y"] = 18, ["z"] = 61, ["name"] = "mesecons_lightstone:lightstone_red_off"}, {["x"] = 2, ["meta"] = {["fields"] = {}, ["inventory"] = {}}, ["y"] = 18, ["z"] = 62, ["name"] = "mesecons_lightstone:lightstone_red_off"}, {["x"] = 2, ["meta"] = {["fields"] = {}, ["inventory"] = {}}, ["y"] = 18, ["z"] = 63, ["name"] = "mesecons_lightstone:lightstone_red_off"}, {["x"] = 2, ["meta"] = {["fields"] = {}, ["inventory"] = {}}, ["y"] = 18, ["z"] = 64, ["name"] = "mesecons_lightstone:lightstone_red_off"}, {["x"] = 2, ["meta"] = {["fields"] = {}, ["inventory"] = {}}, ["y"] = 19, ["z"] = 28, ["name"] = "mesecons_lightstone:lightstone_red_off"}, {["x"] = 2, ["meta"] = {["fields"] = {}, ["inventory"] = {}}, ["y"] = 19, ["z"] = 29, ["name"] = "mesecons_lightstone:lightstone_red_off"}, {["x"] = 2, ["meta"] = {["fields"] = {}, ["inventory"] = {}}, ["y"] = 19, ["z"] = 30, ["name"] = "mesecons_lightstone:lightstone_red_off"}, {["x"] = 2, ["meta"] = {["fields"] = {}, ["inventory"] = {}}, ["y"] = 19, ["z"] = 31, ["name"] = "mesecons_lightstone:lightstone_red_off"}, {["x"] = 2, ["meta"] = {["fields"] = {}, ["inventory"] = {}}, ["y"] = 19, ["z"] = 32, ["name"] = "mesecons_lightstone:lightstone_red_off"}, {["x"] = 2, ["meta"] = {["fields"] = {}, ["inventory"] = {}}, ["y"] = 19, ["z"] = 33, ["name"] = "mesecons_lightstone:lightstone_red_off"}, {["x"] = 2, ["meta"] = {["fields"] = {}, ["inventory"] = {}}, ["y"] = 19, ["z"] = 59, ["name"] = "mesecons_lightstone:lightstone_red_off"}, {["x"] = 2, ["meta"] = {["fields"] = {}, ["inventory"] = {}}, ["y"] = 19, ["z"] = 60, ["name"] = "mesecons_lightstone:lightstone_red_off"}, {["x"] = 2, ["meta"] = {["fields"] = {}, ["inventory"] = {}}, ["y"] = 19, ["z"] = 61, ["name"] = "mesecons_lightstone:lightstone_red_off"}, {["x"] = 2, ["meta"] = {["fields"] = {}, ["inventory"] = {}}, ["y"] = 19, ["z"] = 62, ["name"] = "mesecons_lightstone:lightstone_red_off"}, {["x"] = 2, ["meta"] = {["fields"] = {}, ["inventory"] = {}}, ["y"] = 19, ["z"] = 63, ["name"] = "mesecons_lightstone:lightstone_red_off"}, {["x"] = 2, ["meta"] = {["fields"] = {}, ["inventory"] = {}}, ["y"] = 19, ["z"] = 64, ["name"] = "mesecons_lightstone:lightstone_red_off"}, {["x"] = 2, ["meta"] = {["fields"] = {}, ["inventory"] = {}}, ["param2"] = 1, ["y"] = 25, ["param1"] = 61, ["z"] = 8, ["name"] = "homedecor:fence_wrought_iron"}, {["x"] = 2, ["meta"] = {["fields"] = {}, ["inventory"] = {}}, ["y"] = 25, ["param1"] = 77, ["z"] = 9, ["name"] = "homedecor:fence_wrought_iron"}, {["x"] = 2, ["meta"] = {["fields"] = {}, ["inventory"] = {}}, ["y"] = 25, ["param1"] = 92, ["z"] = 10, ["name"] = "homedecor:fence_wrought_iron"}, {["x"] = 2, ["meta"] = {["fields"] = {}, ["inventory"] = {}}, ["y"] = 25, ["z"] = 11, ["name"] = "wool:dark_grey"}, {["x"] = 2, ["meta"] = {["fields"] = {}, ["inventory"] = {}}, ["y"] = 25, ["z"] = 12, ["name"] = "wool:dark_grey"}, {["x"] = 2, ["meta"] = {["fields"] = {}, ["inventory"] = {}}, ["y"] = 25, ["z"] = 13, ["name"] = "wool:dark_grey"}, {["x"] = 2, ["meta"] = {["fields"] = {}, ["inventory"] = {}}, ["y"] = 25, ["z"] = 14, ["name"] = "wool:dark_grey"}, {["x"] = 2, ["meta"] = {["fields"] = {}, ["inventory"] = {}}, ["y"] = 25, ["z"] = 15, ["name"] = "wool:dark_grey"}, {["x"] = 2, ["meta"] = {["fields"] = {}, ["inventory"] = {}}, ["y"] = 25, ["z"] = 16, ["name"] = "wool:dark_grey"}, {["x"] = 2, ["meta"] = {["fields"] = {}, ["inventory"] = {}}, ["param2"] = 1, ["y"] = 25, ["param1"] = 92, ["z"] = 17, ["name"] = "homedecor:fence_wrought_iron"}, {["x"] = 2, ["meta"] = {["fields"] = {}, ["inventory"] = {}}, ["param2"] = 1, ["y"] = 25, ["param1"] = 77, ["z"] = 18, ["name"] = "homedecor:fence_wrought_iron"}, {["x"] = 2, ["meta"] = {["fields"] = {}, ["inventory"] = {}}, ["param2"] = 1, ["y"] = 26, ["param1"] = 77, ["z"] = 8, ["name"] = "homedecor:fence_wrought_iron"}, {["x"] = 2, ["meta"] = {["fields"] = {}, ["inventory"] = {}}, ["y"] = 26, ["param1"] = 93, ["z"] = 9, ["name"] = "homedecor:fence_wrought_iron"}, {["x"] = 2, ["meta"] = {["fields"] = {}, ["inventory"] = {}}, ["y"] = 26, ["param1"] = 109, ["z"] = 10, ["name"] = "homedecor:fence_wrought_iron"}, {["x"] = 2, ["meta"] = {["fields"] = {}, ["inventory"] = {}}, ["param2"] = 1, ["y"] = 26, ["param1"] = 109, ["z"] = 17, ["name"] = "homedecor:fence_wrought_iron"}, {["x"] = 2, ["meta"] = {["fields"] = {}, ["inventory"] = {}}, ["param2"] = 1, ["y"] = 26, ["param1"] = 93, ["z"] = 18, ["name"] = "homedecor:fence_wrought_iron"}, {["x"] = 3, ["meta"] = {["fields"] = {}, ["inventory"] = {}}, ["y"] = 0, ["z"] = 0, ["name"] = "spell:Letter_R"}, {["x"] = 3, ["meta"] = {["fields"] = {}, ["inventory"] = {}}, ["param2"] = 5, ["y"] = 0, ["param1"] = 221, ["z"] = 1, ["name"] = "homedecor:curtain_white"}, {["x"] = 3, ["meta"] = {["fields"] = {}, ["inventory"] = {}}, ["y"] = 0, ["param1"] = 13, ["z"] = 28, ["name"] = "mesecons_lightstone:lightstone_red_off"}, {["x"] = 3, ["meta"] = {["fields"] = {}, ["inventory"] = {}}, ["y"] = 0, ["param1"] = 13, ["z"] = 33, ["name"] = "mesecons_lightstone:lightstone_red_off"}, {["x"] = 3, ["meta"] = {["fields"] = {}, ["inventory"] = {}}, ["y"] = 0, ["z"] = 34, ["name"] = "mesecons_lightstone:lightstone_yellow_off"}, {["x"] = 3, ["meta"] = {["fields"] = {}, ["inventory"] = {}}, ["y"] = 0, ["z"] = 35, ["name"] = "mesecons_lightstone:lightstone_yellow_off"}, {["x"] = 3, ["meta"] = {["fields"] = {}, ["inventory"] = {}}, ["y"] = 0, ["z"] = 36, ["name"] = "mesecons_lightstone:lightstone_yellow_off"}, {["x"] = 3, ["meta"] = {["fields"] = {}, ["inventory"] = {}}, ["y"] = 0, ["z"] = 37, ["name"] = "mesecons_lightstone:lightstone_yellow_off"}, {["x"] = 3, ["meta"] = {["fields"] = {}, ["inventory"] = {}}, ["y"] = 0, ["z"] = 38, ["name"] = "mesecons_lightstone:lightstone_yellow_off"}, {["x"] = 3, ["meta"] = {["fields"] = {}, ["inventory"] = {}}, ["y"] = 0, ["z"] = 39, ["name"] = "mesecons_lightstone:lightstone_yellow_off"}, {["x"] = 3, ["meta"] = {["fields"] = {}, ["inventory"] = {}}, ["y"] = 0, ["z"] = 40, ["name"] = "mesecons_lightstone:lightstone_yellow_off"}, {["x"] = 3, ["meta"] = {["fields"] = {}, ["inventory"] = {}}, ["y"] = 0, ["z"] = 41, ["name"] = "mesecons_lightstone:lightstone_yellow_off"}, {["x"] = 3, ["meta"] = {["fields"] = {}, ["inventory"] = {}}, ["y"] = 0, ["z"] = 42, ["name"] = "mesecons_lightstone:lightstone_yellow_off"}, {["x"] = 3, ["meta"] = {["fields"] = {}, ["inventory"] = {}}, ["y"] = 0, ["z"] = 43, ["name"] = "mesecons_lightstone:lightstone_yellow_off"}, {["x"] = 3, ["meta"] = {["fields"] = {}, ["inventory"] = {}}, ["y"] = 0, ["z"] = 44, ["name"] = "mesecons_lightstone:lightstone_yellow_off"}, {["x"] = 3, ["meta"] = {["fields"] = {}, ["inventory"] = {}}, ["y"] = 0, ["z"] = 45, ["name"] = "mesecons_lightstone:lightstone_yellow_off"}, {["x"] = 3, ["meta"] = {["fields"] = {}, ["inventory"] = {}}, ["y"] = 0, ["z"] = 46, ["name"] = "mesecons_lightstone:lightstone_yellow_off"}, {["x"] = 3, ["meta"] = {["fields"] = {}, ["inventory"] = {}}, ["y"] = 0, ["z"] = 47, ["name"] = "mesecons_lightstone:lightstone_yellow_off"}, {["x"] = 3, ["meta"] = {["fields"] = {}, ["inventory"] = {}}, ["y"] = 0, ["z"] = 48, ["name"] = "mesecons_lightstone:lightstone_yellow_off"}, {["x"] = 3, ["meta"] = {["fields"] = {}, ["inventory"] = {}}, ["y"] = 0, ["z"] = 49, ["name"] = "mesecons_lightstone:lightstone_yellow_off"}, {["x"] = 3, ["meta"] = {["fields"] = {}, ["inventory"] = {}}, ["y"] = 0, ["z"] = 50, ["name"] = "mesecons_lightstone:lightstone_yellow_off"}, {["x"] = 3, ["meta"] = {["fields"] = {}, ["inventory"] = {}}, ["y"] = 0, ["z"] = 51, ["name"] = "mesecons_lightstone:lightstone_yellow_off"}, {["x"] = 3, ["meta"] = {["fields"] = {}, ["inventory"] = {}}, ["y"] = 0, ["z"] = 52, ["name"] = "mesecons_lightstone:lightstone_yellow_off"}, {["x"] = 3, ["meta"] = {["fields"] = {}, ["inventory"] = {}}, ["y"] = 0, ["z"] = 53, ["name"] = "mesecons_lightstone:lightstone_yellow_off"}, {["x"] = 3, ["meta"] = {["fields"] = {}, ["inventory"] = {}}, ["y"] = 0, ["z"] = 54, ["name"] = "mesecons_lightstone:lightstone_yellow_off"}, {["x"] = 3, ["meta"] = {["fields"] = {}, ["inventory"] = {}}, ["y"] = 0, ["z"] = 55, ["name"] = "mesecons_lightstone:lightstone_yellow_off"}, {["x"] = 3, ["meta"] = {["fields"] = {}, ["inventory"] = {}}, ["y"] = 0, ["z"] = 56, ["name"] = "mesecons_lightstone:lightstone_yellow_off"}, {["x"] = 3, ["meta"] = {["fields"] = {}, ["inventory"] = {}}, ["y"] = 0, ["z"] = 57, ["name"] = "mesecons_lightstone:lightstone_yellow_off"}, {["x"] = 3, ["meta"] = {["fields"] = {}, ["inventory"] = {}}, ["y"] = 0, ["z"] = 58, ["name"] = "mesecons_lightstone:lightstone_yellow_off"}, {["x"] = 3, ["meta"] = {["fields"] = {}, ["inventory"] = {}}, ["y"] = 0, ["param1"] = 13, ["z"] = 59, ["name"] = "mesecons_lightstone:lightstone_red_off"}, {["x"] = 3, ["meta"] = {["fields"] = {}, ["inventory"] = {}}, ["y"] = 0, ["param1"] = 13, ["z"] = 64, ["name"] = "mesecons_lightstone:lightstone_red_off"}, {["x"] = 3, ["meta"] = {["fields"] = {}, ["inventory"] = {}}, ["y"] = 1, ["z"] = 0, ["name"] = "spell:Letter_N"}, {["x"] = 3, ["meta"] = {["fields"] = {}, ["inventory"] = {}}, ["param2"] = 5, ["y"] = 1, ["param1"] = 221, ["z"] = 1, ["name"] = "homedecor:curtain_white"}, {["x"] = 3, ["meta"] = {["fields"] = {}, ["inventory"] = {}}, ["y"] = 1, ["param1"] = 13, ["z"] = 28, ["name"] = "mesecons_lightstone:lightstone_red_off"}, {["x"] = 3, ["meta"] = {["fields"] = {}, ["inventory"] = {}}, ["y"] = 1, ["param1"] = 13, ["z"] = 33, ["name"] = "mesecons_lightstone:lightstone_red_off"}, {["x"] = 3, ["meta"] = {["fields"] = {}, ["inventory"] = {}}, ["y"] = 1, ["param1"] = 13, ["z"] = 34, ["name"] = "mesecons_lightstone:lightstone_red_off"}, {["x"] = 3, ["meta"] = {["fields"] = {}, ["inventory"] = {}}, ["y"] = 1, ["param1"] = 15, ["z"] = 35, ["name"] = "mesecons_lightstone:lightstone_red_off"}, {["x"] = 3, ["meta"] = {["fields"] = {}, ["inventory"] = {}}, ["y"] = 1, ["param1"] = 15, ["z"] = 36, ["name"] = "mesecons_lightstone:lightstone_red_off"}, {["x"] = 3, ["meta"] = {["fields"] = {}, ["inventory"] = {}}, ["y"] = 1, ["param1"] = 15, ["z"] = 37, ["name"] = "mesecons_lightstone:lightstone_red_off"}, {["x"] = 3, ["meta"] = {["fields"] = {}, ["inventory"] = {}}, ["y"] = 1, ["param1"] = 15, ["z"] = 38, ["name"] = "mesecons_lightstone:lightstone_red_off"}, {["x"] = 3, ["meta"] = {["fields"] = {}, ["inventory"] = {}}, ["y"] = 1, ["param1"] = 13, ["z"] = 39, ["name"] = "mesecons_lightstone:lightstone_red_off"}, {["x"] = 3, ["meta"] = {["fields"] = {}, ["inventory"] = {}}, ["y"] = 1, ["param1"] = 15, ["z"] = 40, ["name"] = "mesecons_lightstone:lightstone_red_off"}, {["x"] = 3, ["meta"] = {["fields"] = {}, ["inventory"] = {}}, ["y"] = 1, ["param1"] = 15, ["z"] = 41, ["name"] = "mesecons_lightstone:lightstone_red_off"}, {["x"] = 3, ["meta"] = {["fields"] = {}, ["inventory"] = {}}, ["y"] = 1, ["param1"] = 15, ["z"] = 42, ["name"] = "mesecons_lightstone:lightstone_red_off"}, {["x"] = 3, ["meta"] = {["fields"] = {}, ["inventory"] = {}}, ["y"] = 1, ["param1"] = 15, ["z"] = 43, ["name"] = "mesecons_lightstone:lightstone_red_off"}, {["x"] = 3, ["meta"] = {["fields"] = {}, ["inventory"] = {}}, ["y"] = 1, ["param1"] = 13, ["z"] = 44, ["name"] = "mesecons_lightstone:lightstone_red_off"}, {["x"] = 3, ["meta"] = {["fields"] = {}, ["inventory"] = {}}, ["y"] = 1, ["param1"] = 15, ["z"] = 45, ["name"] = "mesecons_lightstone:lightstone_red_off"}, {["x"] = 3, ["meta"] = {["fields"] = {}, ["inventory"] = {}}, ["y"] = 1, ["param1"] = 15, ["z"] = 46, ["name"] = "mesecons_lightstone:lightstone_red_off"}, {["x"] = 3, ["meta"] = {["fields"] = {}, ["inventory"] = {}}, ["y"] = 1, ["param1"] = 15, ["z"] = 47, ["name"] = "mesecons_lightstone:lightstone_red_off"}, {["x"] = 3, ["meta"] = {["fields"] = {}, ["inventory"] = {}}, ["y"] = 1, ["param1"] = 15, ["z"] = 48, ["name"] = "mesecons_lightstone:lightstone_red_off"}, {["x"] = 3, ["meta"] = {["fields"] = {}, ["inventory"] = {}}, ["y"] = 1, ["param1"] = 13, ["z"] = 49, ["name"] = "mesecons_lightstone:lightstone_red_off"}, {["x"] = 3, ["meta"] = {["fields"] = {}, ["inventory"] = {}}, ["y"] = 1, ["param1"] = 15, ["z"] = 50, ["name"] = "mesecons_lightstone:lightstone_red_off"}, {["x"] = 3, ["meta"] = {["fields"] = {}, ["inventory"] = {}}, ["y"] = 1, ["param1"] = 15, ["z"] = 51, ["name"] = "mesecons_lightstone:lightstone_red_off"}, {["x"] = 3, ["meta"] = {["fields"] = {}, ["inventory"] = {}}, ["y"] = 1, ["param1"] = 15, ["z"] = 52, ["name"] = "mesecons_lightstone:lightstone_red_off"}, {["x"] = 3, ["meta"] = {["fields"] = {}, ["inventory"] = {}}, ["y"] = 1, ["param1"] = 15, ["z"] = 53, ["name"] = "mesecons_lightstone:lightstone_red_off"}, {["x"] = 3, ["meta"] = {["fields"] = {}, ["inventory"] = {}}, ["y"] = 1, ["param1"] = 13, ["z"] = 54, ["name"] = "mesecons_lightstone:lightstone_red_off"}, {["x"] = 3, ["meta"] = {["fields"] = {}, ["inventory"] = {}}, ["y"] = 1, ["param1"] = 15, ["z"] = 55, ["name"] = "mesecons_lightstone:lightstone_red_off"}, {["x"] = 3, ["meta"] = {["fields"] = {}, ["inventory"] = {}}, ["y"] = 1, ["param1"] = 15, ["z"] = 56, ["name"] = "mesecons_lightstone:lightstone_red_off"}, {["x"] = 3, ["meta"] = {["fields"] = {}, ["inventory"] = {}}, ["y"] = 1, ["param1"] = 15, ["z"] = 57, ["name"] = "mesecons_lightstone:lightstone_red_off"}, {["x"] = 3, ["meta"] = {["fields"] = {}, ["inventory"] = {}}, ["y"] = 1, ["param1"] = 15, ["z"] = 58, ["name"] = "mesecons_lightstone:lightstone_red_off"}, {["x"] = 3, ["meta"] = {["fields"] = {}, ["inventory"] = {}}, ["y"] = 1, ["z"] = 59, ["name"] = "mesecons_lightstone:lightstone_red_off"}, {["x"] = 3, ["meta"] = {["fields"] = {}, ["inventory"] = {}}, ["y"] = 1, ["param1"] = 13, ["z"] = 64, ["name"] = "mesecons_lightstone:lightstone_red_off"}, {["x"] = 3, ["meta"] = {["fields"] = {}, ["inventory"] = {}}, ["y"] = 2, ["z"] = 0, ["name"] = "default:snowblock"}, {["x"] = 3, ["meta"] = {["fields"] = {}, ["inventory"] = {}}, ["param2"] = 5, ["y"] = 2, ["param1"] = 205, ["z"] = 1, ["name"] = "homedecor:curtain_white"}, {["x"] = 3, ["meta"] = {["fields"] = {}, ["inventory"] = {}}, ["y"] = 2, ["param1"] = 13, ["z"] = 28, ["name"] = "mesecons_lightstone:lightstone_red_off"}, {["x"] = 3, ["meta"] = {["fields"] = {}, ["inventory"] = {}}, ["y"] = 2, ["z"] = 32, ["name"] = "default:steelblock"}, {["x"] = 3, ["meta"] = {["fields"] = {}, ["inventory"] = {}}, ["y"] = 2, ["param1"] = 13, ["z"] = 33, ["name"] = "mesecons_lightstone:lightstone_red_off"}, {["x"] = 3, ["meta"] = {["fields"] = {}, ["inventory"] = {}}, ["y"] = 2, ["param1"] = 13, ["z"] = 34, ["name"] = "mesecons_lightstone:lightstone_red_off"}, {["x"] = 3, ["meta"] = {["fields"] = {}, ["inventory"] = {}}, ["y"] = 2, ["param1"] = 15, ["z"] = 35, ["name"] = "mesecons_lightstone:lightstone_red_off"}, {["x"] = 3, ["meta"] = {["fields"] = {}, ["inventory"] = {}}, ["y"] = 2, ["param1"] = 15, ["z"] = 36, ["name"] = "mesecons_lightstone:lightstone_red_off"}, {["x"] = 3, ["meta"] = {["fields"] = {}, ["inventory"] = {}}, ["y"] = 2, ["param1"] = 15, ["z"] = 37, ["name"] = "mesecons_lightstone:lightstone_red_off"}, {["x"] = 3, ["meta"] = {["fields"] = {}, ["inventory"] = {}}, ["y"] = 2, ["param1"] = 15, ["z"] = 38, ["name"] = "mesecons_lightstone:lightstone_red_off"}, {["x"] = 3, ["meta"] = {["fields"] = {}, ["inventory"] = {}}, ["y"] = 2, ["param1"] = 13, ["z"] = 39, ["name"] = "mesecons_lightstone:lightstone_red_off"}, {["x"] = 3, ["meta"] = {["fields"] = {}, ["inventory"] = {}}, ["y"] = 2, ["param1"] = 15, ["z"] = 40, ["name"] = "mesecons_lightstone:lightstone_red_off"}, {["x"] = 3, ["meta"] = {["fields"] = {}, ["inventory"] = {}}, ["y"] = 2, ["param1"] = 15, ["z"] = 41, ["name"] = "mesecons_lightstone:lightstone_red_off"}, {["x"] = 3, ["meta"] = {["fields"] = {}, ["inventory"] = {}}, ["y"] = 2, ["param1"] = 15, ["z"] = 42, ["name"] = "mesecons_lightstone:lightstone_red_off"}, {["x"] = 3, ["meta"] = {["fields"] = {}, ["inventory"] = {}}, ["y"] = 2, ["param1"] = 15, ["z"] = 43, ["name"] = "mesecons_lightstone:lightstone_red_off"}, {["x"] = 3, ["meta"] = {["fields"] = {}, ["inventory"] = {}}, ["y"] = 2, ["param1"] = 13, ["z"] = 44, ["name"] = "mesecons_lightstone:lightstone_red_off"}, {["x"] = 3, ["meta"] = {["fields"] = {}, ["inventory"] = {}}, ["y"] = 2, ["param1"] = 15, ["z"] = 45, ["name"] = "mesecons_lightstone:lightstone_red_off"}, {["x"] = 3, ["meta"] = {["fields"] = {}, ["inventory"] = {}}, ["y"] = 2, ["param1"] = 15, ["z"] = 46, ["name"] = "mesecons_lightstone:lightstone_red_off"}, {["x"] = 3, ["meta"] = {["fields"] = {}, ["inventory"] = {}}, ["y"] = 2, ["param1"] = 15, ["z"] = 47, ["name"] = "mesecons_lightstone:lightstone_red_off"}, {["x"] = 3, ["meta"] = {["fields"] = {}, ["inventory"] = {}}, ["y"] = 2, ["param1"] = 15, ["z"] = 48, ["name"] = "mesecons_lightstone:lightstone_red_off"}, {["x"] = 3, ["meta"] = {["fields"] = {}, ["inventory"] = {}}, ["y"] = 2, ["param1"] = 13, ["z"] = 49, ["name"] = "mesecons_lightstone:lightstone_red_off"}, {["x"] = 3, ["meta"] = {["fields"] = {}, ["inventory"] = {}}, ["y"] = 2, ["param1"] = 15, ["z"] = 50, ["name"] = "mesecons_lightstone:lightstone_red_off"}, {["x"] = 3, ["meta"] = {["fields"] = {}, ["inventory"] = {}}, ["y"] = 2, ["param1"] = 15, ["z"] = 51, ["name"] = "mesecons_lightstone:lightstone_red_off"}, {["x"] = 3, ["meta"] = {["fields"] = {}, ["inventory"] = {}}, ["y"] = 2, ["param1"] = 15, ["z"] = 52, ["name"] = "mesecons_lightstone:lightstone_red_off"}, {["x"] = 3, ["meta"] = {["fields"] = {}, ["inventory"] = {}}, ["y"] = 2, ["param1"] = 15, ["z"] = 53, ["name"] = "mesecons_lightstone:lightstone_red_off"}, {["x"] = 3, ["meta"] = {["fields"] = {}, ["inventory"] = {}}, ["y"] = 2, ["param1"] = 13, ["z"] = 54, ["name"] = "mesecons_lightstone:lightstone_red_off"}, {["x"] = 3, ["meta"] = {["fields"] = {}, ["inventory"] = {}}, ["y"] = 2, ["param1"] = 15, ["z"] = 55, ["name"] = "mesecons_lightstone:lightstone_red_off"}, {["x"] = 3, ["meta"] = {["fields"] = {}, ["inventory"] = {}}, ["y"] = 2, ["param1"] = 15, ["z"] = 56, ["name"] = "mesecons_lightstone:lightstone_red_off"}, {["x"] = 3, ["meta"] = {["fields"] = {}, ["inventory"] = {}}, ["y"] = 2, ["param1"] = 15, ["z"] = 57, ["name"] = "mesecons_lightstone:lightstone_red_off"}, {["x"] = 3, ["meta"] = {["fields"] = {}, ["inventory"] = {}}, ["y"] = 2, ["param1"] = 15, ["z"] = 58, ["name"] = "mesecons_lightstone:lightstone_red_off"}, {["x"] = 3, ["meta"] = {["fields"] = {}, ["inventory"] = {}}, ["y"] = 2, ["param1"] = 13, ["z"] = 59, ["name"] = "mesecons_lightstone:lightstone_red_off"}, {["x"] = 3, ["meta"] = {["fields"] = {}, ["inventory"] = {}}, ["y"] = 2, ["param1"] = 13, ["z"] = 64, ["name"] = "mesecons_lightstone:lightstone_red_off"}, {["x"] = 3, ["meta"] = {["fields"] = {}, ["inventory"] = {}}, ["y"] = 3, ["param1"] = 13, ["z"] = 28, ["name"] = "mesecons_lightstone:lightstone_red_off"}, {["x"] = 3, ["meta"] = {["fields"] = {}, ["inventory"] = {}}, ["param2"] = 2, ["y"] = 3, ["param1"] = 221, ["z"] = 31, ["name"] = "stairs:stair_steelblock"}, {["x"] = 3, ["meta"] = {["fields"] = {}, ["inventory"] = {}}, ["y"] = 3, ["param1"] = 13, ["z"] = 33, ["name"] = "mesecons_lightstone:lightstone_red_off"}, {["x"] = 3, ["meta"] = {["fields"] = {}, ["inventory"] = {}}, ["y"] = 3, ["param1"] = 13, ["z"] = 34, ["name"] = "mesecons_lightstone:lightstone_red_off"}, {["x"] = 3, ["meta"] = {["fields"] = {}, ["inventory"] = {}}, ["y"] = 3, ["param1"] = 15, ["z"] = 35, ["name"] = "mesecons_lightstone:lightstone_red_off"}, {["x"] = 3, ["meta"] = {["fields"] = {}, ["inventory"] = {}}, ["y"] = 3, ["param1"] = 15, ["z"] = 36, ["name"] = "mesecons_lightstone:lightstone_red_off"}, {["x"] = 3, ["meta"] = {["fields"] = {}, ["inventory"] = {}}, ["y"] = 3, ["param1"] = 15, ["z"] = 37, ["name"] = "mesecons_lightstone:lightstone_red_off"}, {["x"] = 3, ["meta"] = {["fields"] = {}, ["inventory"] = {}}, ["y"] = 3, ["param1"] = 15, ["z"] = 38, ["name"] = "mesecons_lightstone:lightstone_red_off"}, {["x"] = 3, ["meta"] = {["fields"] = {}, ["inventory"] = {}}, ["y"] = 3, ["param1"] = 13, ["z"] = 39, ["name"] = "mesecons_lightstone:lightstone_red_off"}, {["x"] = 3, ["meta"] = {["fields"] = {}, ["inventory"] = {}}, ["y"] = 3, ["param1"] = 15, ["z"] = 40, ["name"] = "mesecons_lightstone:lightstone_red_off"}, {["x"] = 3, ["meta"] = {["fields"] = {}, ["inventory"] = {}}, ["y"] = 3, ["param1"] = 15, ["z"] = 41, ["name"] = "mesecons_lightstone:lightstone_red_off"}, {["x"] = 3, ["meta"] = {["fields"] = {}, ["inventory"] = {}}, ["y"] = 3, ["param1"] = 15, ["z"] = 42, ["name"] = "mesecons_lightstone:lightstone_red_off"}, {["x"] = 3, ["meta"] = {["fields"] = {}, ["inventory"] = {}}, ["y"] = 3, ["param1"] = 15, ["z"] = 43, ["name"] = "mesecons_lightstone:lightstone_red_off"}, {["x"] = 3, ["meta"] = {["fields"] = {}, ["inventory"] = {}}, ["y"] = 3, ["param1"] = 13, ["z"] = 44, ["name"] = "mesecons_lightstone:lightstone_red_off"}, {["x"] = 3, ["meta"] = {["fields"] = {}, ["inventory"] = {}}, ["y"] = 3, ["param1"] = 15, ["z"] = 45, ["name"] = "mesecons_lightstone:lightstone_red_off"}, {["x"] = 3, ["meta"] = {["fields"] = {}, ["inventory"] = {}}, ["y"] = 3, ["param1"] = 15, ["z"] = 46, ["name"] = "mesecons_lightstone:lightstone_red_off"}, {["x"] = 3, ["meta"] = {["fields"] = {}, ["inventory"] = {}}, ["y"] = 3, ["param1"] = 15, ["z"] = 47, ["name"] = "mesecons_lightstone:lightstone_red_off"}, {["x"] = 3, ["meta"] = {["fields"] = {}, ["inventory"] = {}}, ["y"] = 3, ["param1"] = 15, ["z"] = 48, ["name"] = "mesecons_lightstone:lightstone_red_off"}, {["x"] = 3, ["meta"] = {["fields"] = {}, ["inventory"] = {}}, ["y"] = 3, ["param1"] = 13, ["z"] = 49, ["name"] = "mesecons_lightstone:lightstone_red_off"}, {["x"] = 3, ["meta"] = {["fields"] = {}, ["inventory"] = {}}, ["y"] = 3, ["param1"] = 15, ["z"] = 50, ["name"] = "mesecons_lightstone:lightstone_red_off"}, {["x"] = 3, ["meta"] = {["fields"] = {}, ["inventory"] = {}}, ["y"] = 3, ["param1"] = 15, ["z"] = 51, ["name"] = "mesecons_lightstone:lightstone_red_off"}, {["x"] = 3, ["meta"] = {["fields"] = {}, ["inventory"] = {}}, ["y"] = 3, ["param1"] = 15, ["z"] = 52, ["name"] = "mesecons_lightstone:lightstone_red_off"}, {["x"] = 3, ["meta"] = {["fields"] = {}, ["inventory"] = {}}, ["y"] = 3, ["param1"] = 15, ["z"] = 53, ["name"] = "mesecons_lightstone:lightstone_red_off"}, {["x"] = 3, ["meta"] = {["fields"] = {}, ["inventory"] = {}}, ["y"] = 3, ["param1"] = 13, ["z"] = 54, ["name"] = "mesecons_lightstone:lightstone_red_off"}, {["x"] = 3, ["meta"] = {["fields"] = {}, ["inventory"] = {}}, ["y"] = 3, ["param1"] = 15, ["z"] = 55, ["name"] = "mesecons_lightstone:lightstone_red_off"}, {["x"] = 3, ["meta"] = {["fields"] = {}, ["inventory"] = {}}, ["y"] = 3, ["param1"] = 15, ["z"] = 56, ["name"] = "mesecons_lightstone:lightstone_red_off"}, {["x"] = 3, ["meta"] = {["fields"] = {}, ["inventory"] = {}}, ["y"] = 3, ["param1"] = 15, ["z"] = 57, ["name"] = "mesecons_lightstone:lightstone_red_off"}, {["x"] = 3, ["meta"] = {["fields"] = {}, ["inventory"] = {}}, ["y"] = 3, ["param1"] = 15, ["z"] = 58, ["name"] = "mesecons_lightstone:lightstone_red_off"}, {["x"] = 3, ["meta"] = {["fields"] = {}, ["inventory"] = {}}, ["y"] = 3, ["param1"] = 13, ["z"] = 59, ["name"] = "mesecons_lightstone:lightstone_red_off"}, {["x"] = 3, ["meta"] = {["fields"] = {}, ["inventory"] = {}}, ["y"] = 3, ["param1"] = 13, ["z"] = 64, ["name"] = "mesecons_lightstone:lightstone_red_off"}, {["x"] = 3, ["meta"] = {["fields"] = {}, ["inventory"] = {}}, ["y"] = 4, ["param1"] = 13, ["z"] = 28, ["name"] = "mesecons_lightstone:lightstone_red_off"}, {["x"] = 3, ["meta"] = {["fields"] = {}, ["inventory"] = {}}, ["param2"] = 2, ["y"] = 4, ["param1"] = 221, ["z"] = 30, ["name"] = "stairs:stair_steelblock"}, {["x"] = 3, ["meta"] = {["fields"] = {}, ["inventory"] = {}}, ["y"] = 4, ["param1"] = 13, ["z"] = 33, ["name"] = "mesecons_lightstone:lightstone_red_off"}, {["x"] = 3, ["meta"] = {["fields"] = {}, ["inventory"] = {}}, ["y"] = 4, ["param1"] = 13, ["z"] = 34, ["name"] = "mesecons_lightstone:lightstone_red_off"}, {["x"] = 3, ["meta"] = {["fields"] = {}, ["inventory"] = {}}, ["y"] = 4, ["param1"] = 15, ["z"] = 35, ["name"] = "mesecons_lightstone:lightstone_red_off"}, {["x"] = 3, ["meta"] = {["fields"] = {}, ["inventory"] = {}}, ["y"] = 4, ["param1"] = 15, ["z"] = 36, ["name"] = "mesecons_lightstone:lightstone_red_off"}, {["x"] = 3, ["meta"] = {["fields"] = {}, ["inventory"] = {}}, ["y"] = 4, ["param1"] = 15, ["z"] = 37, ["name"] = "mesecons_lightstone:lightstone_red_off"}, {["x"] = 3, ["meta"] = {["fields"] = {}, ["inventory"] = {}}, ["y"] = 4, ["param1"] = 15, ["z"] = 38, ["name"] = "mesecons_lightstone:lightstone_red_off"}, {["x"] = 3, ["meta"] = {["fields"] = {}, ["inventory"] = {}}, ["y"] = 4, ["param1"] = 13, ["z"] = 39, ["name"] = "mesecons_lightstone:lightstone_red_off"}, {["x"] = 3, ["meta"] = {["fields"] = {}, ["inventory"] = {}}, ["y"] = 4, ["param1"] = 15, ["z"] = 40, ["name"] = "mesecons_lightstone:lightstone_red_off"}, {["x"] = 3, ["meta"] = {["fields"] = {}, ["inventory"] = {}}, ["y"] = 4, ["param1"] = 15, ["z"] = 41, ["name"] = "mesecons_lightstone:lightstone_red_off"}, {["x"] = 3, ["meta"] = {["fields"] = {}, ["inventory"] = {}}, ["y"] = 4, ["param1"] = 15, ["z"] = 42, ["name"] = "mesecons_lightstone:lightstone_red_off"}, {["x"] = 3, ["meta"] = {["fields"] = {}, ["inventory"] = {}}, ["y"] = 4, ["param1"] = 15, ["z"] = 43, ["name"] = "mesecons_lightstone:lightstone_red_off"}, {["x"] = 3, ["meta"] = {["fields"] = {}, ["inventory"] = {}}, ["y"] = 4, ["param1"] = 13, ["z"] = 44, ["name"] = "mesecons_lightstone:lightstone_red_off"}, {["x"] = 3, ["meta"] = {["fields"] = {}, ["inventory"] = {}}, ["y"] = 4, ["param1"] = 15, ["z"] = 45, ["name"] = "mesecons_lightstone:lightstone_red_off"}, {["x"] = 3, ["meta"] = {["fields"] = {}, ["inventory"] = {}}, ["y"] = 4, ["param1"] = 15, ["z"] = 46, ["name"] = "mesecons_lightstone:lightstone_red_off"}, {["x"] = 3, ["meta"] = {["fields"] = {}, ["inventory"] = {}}, ["y"] = 4, ["param1"] = 15, ["z"] = 47, ["name"] = "mesecons_lightstone:lightstone_red_off"}, {["x"] = 3, ["meta"] = {["fields"] = {}, ["inventory"] = {}}, ["y"] = 4, ["param1"] = 15, ["z"] = 48, ["name"] = "mesecons_lightstone:lightstone_red_off"}, {["x"] = 3, ["meta"] = {["fields"] = {}, ["inventory"] = {}}, ["y"] = 4, ["param1"] = 13, ["z"] = 49, ["name"] = "mesecons_lightstone:lightstone_red_off"}, {["x"] = 3, ["meta"] = {["fields"] = {}, ["inventory"] = {}}, ["y"] = 4, ["param1"] = 15, ["z"] = 50, ["name"] = "mesecons_lightstone:lightstone_red_off"}, {["x"] = 3, ["meta"] = {["fields"] = {}, ["inventory"] = {}}, ["y"] = 4, ["param1"] = 15, ["z"] = 51, ["name"] = "mesecons_lightstone:lightstone_red_off"}, {["x"] = 3, ["meta"] = {["fields"] = {}, ["inventory"] = {}}, ["y"] = 4, ["param1"] = 15, ["z"] = 52, ["name"] = "mesecons_lightstone:lightstone_red_off"}, {["x"] = 3, ["meta"] = {["fields"] = {}, ["inventory"] = {}}, ["y"] = 4, ["param1"] = 15, ["z"] = 53, ["name"] = "mesecons_lightstone:lightstone_red_off"},