5:return {{["x"] = 0, ["meta"] = {["fields"] = {}, ["inventory"] = {}}, ["y"] = 0, ["z"] = 0, ["name"] = "default:desert_cobble"}, {["x"] = 0, ["meta"] = {["fields"] = {}, ["inventory"] = {}}, ["y"] = 0, ["z"] = 1, ["name"] = "default:desert_stone"}, {["x"] = 0, ["meta"] = {["fields"] = {}, ["inventory"] = {}}, ["y"] = 0, ["z"] = 2, ["name"] = "default:desert_stone"}, {["x"] = 0, ["meta"] = {["fields"] = {}, ["inventory"] = {}}, ["y"] = 1, ["z"] = 0, ["name"] = "default:desert_stone"}, {["x"] = 0, ["meta"] = {["fields"] = {}, ["inventory"] = {}}, ["y"] = 1, ["z"] = 2, ["name"] = "default:desert_stone"}, {["x"] = 0, ["meta"] = {["fields"] = {}, ["inventory"] = {}}, ["y"] = 2, ["z"] = 0, ["name"] = "default:desert_stone"}, {["x"] = 0, ["meta"] = {["fields"] = {}, ["inventory"] = {}}, ["y"] = 2, ["z"] = 2, ["name"] = "default:desert_stone"}, {["x"] = 0, ["meta"] = {["fields"] = {}, ["inventory"] = {}}, ["param2"] = 1, ["y"] = 3, ["param1"] = 141, ["z"] = 0, ["name"] = "stairs:stair_desert_stone"}, {["x"] = 0, ["meta"] = {["fields"] = {}, ["inventory"] = {}}, ["param2"] = 1, ["y"] = 3, ["param1"] = 157, ["z"] = 1, ["name"] = "stairs:stair_desert_stone"}, {["x"] = 0, ["meta"] = {["fields"] = {}, ["inventory"] = {}}, ["param2"] = 1, ["y"] = 3, ["param1"] = 141, ["z"] = 2, ["name"] = "stairs:stair_desert_stone"}, {["x"] = 1, ["meta"] = {["fields"] = {}, ["inventory"] = {}}, ["y"] = 0, ["z"] = 0, ["name"] = "default:desert_stone"}, {["x"] = 1, ["meta"] = {["fields"] = {}, ["inventory"] = {}}, ["y"] = 0, ["z"] = 1, ["name"] = "default:desert_stone"}, {["x"] = 1, ["meta"] = {["fields"] = {}, ["inventory"] = {}}, ["y"] = 0, ["z"] = 2, ["name"] = "default:desert_stone"}, {["x"] = 1, ["meta"] = {["fields"] = {}, ["inventory"] = {}}, ["param2"] = 21, ["y"] = 3, ["param1"] = 157, ["z"] = 2, ["name"] = "stairs:stair_desert_stone"}, {["x"] = 1, ["meta"] = {["fields"] = {}, ["inventory"] = {}}, ["param2"] = 1, ["y"] = 4, ["param1"] = 141, ["z"] = 2, ["name"] = "stairs:stair_desert_stone"}, {["x"] = 2, ["meta"] = {["fields"] = {}, ["inventory"] = {}}, ["y"] = 0, ["z"] = 0, ["name"] = "default:desert_stone"}, {["x"] = 2, ["meta"] = {["fields"] = {}, ["inventory"] = {}}, ["y"] = 0, ["z"] = 1, ["name"] = "default:meselamp"}, {["x"] = 2, ["meta"] = {["fields"] = {["infotext"] = "Command Block\
(owned by Nigel)\
Commands: teleport @nearest 1304,30,772", ["owner"] = "Nigel", ["commands"] = "teleport @nearest 1304,30,772", ["formspec"] = "invsize[9,5;]textarea[0.5,0.5;8.5,4;commands;Commands;teleport @nearest 1304,30,772]label[1,3.8;@nearest, @farthest, and @random are replaced by the respective player names]button_exit[3.3,4.5;2,1;submit;Submit]"}, ["inventory"] = {}}, ["y"] = 0, ["z"] = 2, ["name"] = "mesecons_commandblock:commandblock_off"}, {["x"] = 2, ["meta"] = {["fields"] = {}, ["inventory"] = {}}, ["y"] = 1, ["param1"] = 221, ["z"] = 1, ["name"] = "mesecons_pressureplates:pressure_plate_stone_off"}, {["x"] = 2, ["meta"] = {["fields"] = {}, ["inventory"] = {}}, ["y"] = 1, ["z"] = 2, ["name"] = "default:desert_stone"}, {["x"] = 2, ["meta"] = {["fields"] = {["infotext"] = "Desert Village ", ["text"] = "Desert Village", ["__signslib_new_format"] = "1", ["formspec"] = "size[6,4]textarea[0,-0.3;6.5,3;text;;${text}]button_exit[2,3.4;2,1;ok;Write]background[-0.5,-0.5;7,5;bg_signs_lib.jpg]"}, ["inventory"] = {}}, ["y"] = 2, ["param1"] = 207, ["z"] = 1, ["name"] = "signs:sign_wall_white_black"}, {["x"] = 2, ["meta"] = {["fields"] = {}, ["inventory"] = {}}, ["y"] = 2, ["z"] = 2, ["name"] = "default:desert_stone"}, {["x"] = 2, ["meta"] = {["fields"] = {}, ["inventory"] = {}}, ["y"] = 4, ["z"] = 2, ["name"] = "default:desert_stone"}, {["x"] = 2, ["meta"] = {["fields"] = {}, ["inventory"] = {}}, ["y"] = 5, ["param1"] = 141, ["z"] = 2, ["name"] = "stairs:slab_desert_stone"}, {["x"] = 3, ["meta"] = {["fields"] = {}, ["inventory"] = {}}, ["y"] = 0, ["z"] = 0, ["name"] = "default:desert_stone"}, {["x"] = 3, ["meta"] = {["fields"] = {}, ["inventory"] = {}}, ["y"] = 0, ["z"] = 1, ["name"] = "default:desert_stone"}, {["x"] = 3, ["meta"] = {["fields"] = {}, ["inventory"] = {}}, ["y"] = 0, ["z"] = 2, ["name"] = "default:desert_stone"}, {["x"] = 3, ["meta"] = {["fields"] = {}, ["inventory"] = {}}, ["param2"] = 23, ["y"] = 3, ["param1"] = 157, ["z"] = 2, ["name"] = "stairs:stair_desert_stone"}, {["x"] = 3, ["meta"] = {["fields"] = {}, ["inventory"] = {}}, ["param2"] = 3, ["y"] = 4, ["param1"] = 141, ["z"] = 2, ["name"] = "stairs:stair_desert_stone"}, {["x"] = 4, ["meta"] = {["fields"] = {}, ["inventory"] = {}}, ["y"] = 0, ["z"] = 0, ["name"] = "default:desert_stone"}, {["x"] = 4, ["meta"] = {["fields"] = {}, ["inventory"] = {}}, ["y"] = 0, ["z"] = 1, ["name"] = "default:desert_stone"}, {["x"] = 4, ["meta"] = {["fields"] = {}, ["inventory"] = {}}, ["y"] = 0, ["param1"] = 124, ["z"] = 2, ["name"] = "default:cloud"}, {["x"] = 4, ["meta"] = {["fields"] = {}, ["inventory"] = {}}, ["y"] = 1, ["z"] = 0, ["name"] = "default:desert_stone"}, {["x"] = 4, ["meta"] = {["fields"] = {}, ["inventory"] = {}}, ["y"] = 1, ["z"] = 2, ["name"] = "default:desert_stone"}, {["x"] = 4, ["meta"] = {["fields"] = {}, ["inventory"] = {}}, ["y"] = 2, ["z"] = 0, ["name"] = "default:desert_stone"}, {["x"] = 4, ["meta"] = {["fields"] = {}, ["inventory"] = {}}, ["y"] = 2, ["z"] = 2, ["name"] = "default:desert_stone"}, {["x"] = 4, ["meta"] = {["fields"] = {}, ["inventory"] = {}}, ["param2"] = 3, ["y"] = 3, ["param1"] = 141, ["z"] = 0, ["name"] = "stairs:stair_desert_stone"}, {["x"] = 4, ["meta"] = {["fields"] = {}, ["inventory"] = {}}, ["param2"] = 3, ["y"] = 3, ["param1"] = 157, ["z"] = 1, ["name"] = "stairs:stair_desert_stone"}, {["x"] = 4, ["meta"] = {["fields"] = {}, ["inventory"] = {}}, ["param2"] = 3, ["y"] = 3, ["param1"] = 141, ["z"] = 2, ["name"] = "stairs:stair_desert_stone"}}