5:return {{["x"] = 0, ["meta"] = {["fields"] = {}, ["inventory"] = {}}, ["y"] = 0, ["z"] = 8, ["name"] = "darkage:stone_brick"}, {["x"] = 0, ["meta"] = {["fields"] = {}, ["inventory"] = {}}, ["param2"] = 20, ["y"] = 22, ["z"] = 2, ["name"] = "homedecor:glowlight_quarter_white"}, {["x"] = 0, ["meta"] = {["fields"] = {}, ["inventory"] = {}}, ["param2"] = 23, ["y"] = 22, ["z"] = 3, ["name"] = "homedecor:glowlight_quarter_white"}, {["x"] = 0, ["meta"] = {["fields"] = {}, ["inventory"] = {}}, ["param2"] = 23, ["y"] = 22, ["z"] = 4, ["name"] = "homedecor:glowlight_quarter_white"}, {["x"] = 0, ["meta"] = {["fields"] = {}, ["inventory"] = {}}, ["param2"] = 23, ["y"] = 22, ["z"] = 5, ["name"] = "homedecor:glowlight_quarter_white"}, {["x"] = 0, ["meta"] = {["fields"] = {}, ["inventory"] = {}}, ["param2"] = 23, ["y"] = 22, ["z"] = 6, ["name"] = "homedecor:glowlight_quarter_white"}, {["x"] = 0, ["meta"] = {["fields"] = {}, ["inventory"] = {}}, ["y"] = 23, ["z"] = 2, ["name"] = "darkage:stone_brick"}, {["x"] = 0, ["meta"] = {["fields"] = {}, ["inventory"] = {}}, ["y"] = 23, ["z"] = 3, ["name"] = "darkage:stone_brick"}, {["x"] = 0, ["meta"] = {["fields"] = {}, ["inventory"] = {}}, ["y"] = 23, ["z"] = 4, ["name"] = "darkage:stone_brick"}, {["x"] = 0, ["meta"] = {["fields"] = {}, ["inventory"] = {}}, ["y"] = 23, ["z"] = 5, ["name"] = "darkage:stone_brick"}, {["x"] = 0, ["meta"] = {["fields"] = {}, ["inventory"] = {}}, ["y"] = 23, ["z"] = 6, ["name"] = "darkage:stone_brick"}, {["x"] = 0, ["meta"] = {["fields"] = {}, ["inventory"] = {}}, ["param2"] = 2, ["y"] = 24, ["param1"] = 157, ["z"] = 0, ["name"] = "homedecor:fence_wrought_iron"}, {["x"] = 0, ["meta"] = {["fields"] = {}, ["inventory"] = {}}, ["param2"] = 1, ["y"] = 24, ["param1"] = 173, ["z"] = 1, ["name"] = "homedecor:fence_wrought_iron"}, {["x"] = 0, ["meta"] = {["fields"] = {}, ["inventory"] = {}}, ["param2"] = 2, ["y"] = 24, ["param1"] = 173, ["z"] = 7, ["name"] = "homedecor:fence_wrought_iron"}, {["x"] = 0, ["meta"] = {["fields"] = {}, ["inventory"] = {}}, ["param2"] = 2, ["y"] = 24, ["param1"] = 157, ["z"] = 8, ["name"] = "homedecor:fence_wrought_iron"}, {["x"] = 0, ["meta"] = {["fields"] = {}, ["inventory"] = {}}, ["param2"] = 22, ["y"] = 26, ["z"] = 3, ["name"] = "homedecor:glowlight_quarter_white"}, {["x"] = 0, ["meta"] = {["fields"] = {}, ["inventory"] = {}}, ["param2"] = 22, ["y"] = 26, ["z"] = 4, ["name"] = "homedecor:glowlight_quarter_white"}, {["x"] = 0, ["meta"] = {["fields"] = {}, ["inventory"] = {}}, ["param2"] = 23, ["y"] = 26, ["z"] = 5, ["name"] = "homedecor:glowlight_quarter_white"}, {["x"] = 0, ["meta"] = {["fields"] = {}, ["inventory"] = {}}, ["y"] = 27, ["param1"] = 205, ["z"] = 3, ["name"] = "stairs:slab_darkage_slate_cobble"}, {["x"] = 0, ["meta"] = {["fields"] = {}, ["inventory"] = {}}, ["y"] = 27, ["param1"] = 205, ["z"] = 4, ["name"] = "stairs:slab_darkage_slate_cobble"}, {["x"] = 0, ["meta"] = {["fields"] = {}, ["inventory"] = {}}, ["y"] = 27, ["param1"] = 205, ["z"] = 5, ["name"] = "stairs:slab_darkage_slate_cobble"}, {["x"] = 1, ["meta"] = {["fields"] = {}, ["inventory"] = {}}, ["y"] = 3, ["z"] = 3, ["name"] = "darkage:stone_brick"}, {["x"] = 1, ["meta"] = {["fields"] = {}, ["inventory"] = {}}, ["y"] = 3, ["param1"] = 11, ["z"] = 4, ["name"] = "darkage:stone_brick"}, {["x"] = 1, ["meta"] = {["fields"] = {}, ["inventory"] = {}}, ["y"] = 3, ["param1"] = 11, ["z"] = 5, ["name"] = "darkage:stone_brick"}, {["x"] = 1, ["meta"] = {["fields"] = {}, ["inventory"] = {}}, ["y"] = 4, ["param1"] = 12, ["z"] = 3, ["name"] = "darkage:stone_brick"}, {["x"] = 1, ["meta"] = {["fields"] = {}, ["inventory"] = {}}, ["y"] = 4, ["z"] = 4, ["name"] = "darkage:stone_brick"}, {["x"] = 1, ["meta"] = {["fields"] = {}, ["inventory"] = {}}, ["y"] = 4, ["param1"] = 12, ["z"] = 5, ["name"] = "darkage:stone_brick"}, {["x"] = 1, ["meta"] = {["fields"] = {}, ["inventory"] = {}}, ["y"] = 5, ["param1"] = 13, ["z"] = 3, ["name"] = "darkage:stone_brick"}, {["x"] = 1, ["meta"] = {["fields"] = {}, ["inventory"] = {}}, ["param2"] = 1, ["y"] = 5, ["param1"] = 171, ["z"] = 4, ["name"] = "castle:arrowslit_desertstonebrick_cross"}, {["x"] = 1, ["meta"] = {["fields"] = {}, ["inventory"] = {}}, ["y"] = 5, ["param1"] = 29, ["z"] = 5, ["name"] = "darkage:stone_brick"}, {["x"] = 1, ["meta"] = {["fields"] = {}, ["inventory"] = {}}, ["y"] = 6, ["param1"] = 15, ["z"] = 3, ["name"] = "darkage:stone_brick"}, {["x"] = 1, ["meta"] = {["fields"] = {}, ["inventory"] = {}}, ["y"] = 6, ["param1"] = 15, ["z"] = 4, ["name"] = "darkage:stone_brick"}, {["x"] = 1, ["meta"] = {["fields"] = {}, ["inventory"] = {}}, ["y"] = 6, ["param1"] = 15, ["z"] = 5, ["name"] = "darkage:stone_brick"}, {["x"] = 1, ["meta"] = {["fields"] = {}, ["inventory"] = {}}, ["y"] = 7, ["param1"] = 15, ["z"] = 3, ["name"] = "darkage:stone_brick"}, {["x"] = 1, ["meta"] = {["fields"] = {}, ["inventory"] = {}}, ["y"] = 7, ["param1"] = 15, ["z"] = 4, ["name"] = "darkage:stone_brick"}, {["x"] = 1, ["meta"] = {["fields"] = {}, ["inventory"] = {}}, ["y"] = 7, ["param1"] = 15, ["z"] = 5, ["name"] = "darkage:stone_brick"}, {["x"] = 1, ["meta"] = {["fields"] = {}, ["inventory"] = {}}, ["y"] = 8, ["param1"] = 15, ["z"] = 3, ["name"] = "darkage:stone_brick"}, {["x"] = 1, ["meta"] = {["fields"] = {}, ["inventory"] = {}}, ["y"] = 8, ["param1"] = 15, ["z"] = 4, ["name"] = "darkage:stone_brick"}, {["x"] = 1, ["meta"] = {["fields"] = {}, ["inventory"] = {}}, ["y"] = 8, ["param1"] = 15, ["z"] = 5, ["name"] = "darkage:stone_brick"}, {["x"] = 1, ["meta"] = {["fields"] = {}, ["inventory"] = {}}, ["y"] = 9, ["param1"] = 15, ["z"] = 3, ["name"] = "darkage:stone_brick"}, {["x"] = 1, ["meta"] = {["fields"] = {}, ["inventory"] = {}}, ["param2"] = 1, ["y"] = 9, ["param1"] = 171, ["z"] = 4, ["name"] = "castle:arrowslit_sandstone_cross"}, {["x"] = 1, ["meta"] = {["fields"] = {}, ["inventory"] = {}}, ["y"] = 9, ["param1"] = 15, ["z"] = 5, ["name"] = "darkage:stone_brick"}, {["x"] = 1, ["meta"] = {["fields"] = {}, ["inventory"] = {}}, ["y"] = 10, ["param1"] = 15, ["z"] = 3, ["name"] = "darkage:stone_brick"}, {["x"] = 1, ["meta"] = {["fields"] = {}, ["inventory"] = {}}, ["y"] = 10, ["param1"] = 15, ["z"] = 4, ["name"] = "darkage:stone_brick"}, {["x"] = 1, ["meta"] = {["fields"] = {}, ["inventory"] = {}}, ["y"] = 10, ["param1"] = 15, ["z"] = 5, ["name"] = "darkage:stone_brick"}, {["x"] = 1, ["meta"] = {["fields"] = {}, ["inventory"] = {}}, ["y"] = 11, ["param1"] = 15, ["z"] = 3, ["name"] = "darkage:stone_brick"}, {["x"] = 1, ["meta"] = {["fields"] = {}, ["inventory"] = {}}, ["y"] = 11, ["param1"] = 15, ["z"] = 4, ["name"] = "darkage:stone_brick"}, {["x"] = 1, ["meta"] = {["fields"] = {}, ["inventory"] = {}}, ["y"] = 11, ["param1"] = 15, ["z"] = 5, ["name"] = "darkage:stone_brick"}, {["x"] = 1, ["meta"] = {["fields"] = {}, ["inventory"] = {}}, ["y"] = 12, ["param1"] = 15, ["z"] = 3, ["name"] = "darkage:stone_brick"}, {["x"] = 1, ["meta"] = {["fields"] = {}, ["inventory"] = {}}, ["y"] = 12, ["param1"] = 15, ["z"] = 4, ["name"] = "darkage:stone_brick"}, {["x"] = 1, ["meta"] = {["fields"] = {}, ["inventory"] = {}}, ["y"] = 12, ["param1"] = 15, ["z"] = 5, ["name"] = "darkage:stone_brick"}, {["x"] = 1, ["meta"] = {["fields"] = {}, ["inventory"] = {}}, ["y"] = 13, ["param1"] = 15, ["z"] = 3, ["name"] = "darkage:stone_brick"}, {["x"] = 1, ["meta"] = {["fields"] = {}, ["inventory"] = {}}, ["param2"] = 1, ["y"] = 13, ["param1"] = 171, ["z"] = 4, ["name"] = "castle:arrowslit_desertstonebrick_cross"}, {["x"] = 1, ["meta"] = {["fields"] = {}, ["inventory"] = {}}, ["y"] = 13, ["param1"] = 15, ["z"] = 5, ["name"] = "darkage:stone_brick"}, {["x"] = 1, ["meta"] = {["fields"] = {}, ["inventory"] = {}}, ["y"] = 14, ["param1"] = 15, ["z"] = 3, ["name"] = "darkage:stone_brick"}, {["x"] = 1, ["meta"] = {["fields"] = {}, ["inventory"] = {}}, ["y"] = 14, ["param1"] = 15, ["z"] = 4, ["name"] = "darkage:stone_brick"}, {["x"] = 1, ["meta"] = {["fields"] = {}, ["inventory"] = {}}, ["y"] = 14, ["param1"] = 15, ["z"] = 5, ["name"] = "darkage:stone_brick"}, {["x"] = 1, ["meta"] = {["fields"] = {}, ["inventory"] = {}}, ["y"] = 15, ["param1"] = 15, ["z"] = 3, ["name"] = "darkage:stone_brick"}, {["x"] = 1, ["meta"] = {["fields"] = {}, ["inventory"] = {}}, ["y"] = 15, ["param1"] = 15, ["z"] = 4, ["name"] = "darkage:stone_brick"}, {["x"] = 1, ["meta"] = {["fields"] = {}, ["inventory"] = {}}, ["y"] = 15, ["param1"] = 15, ["z"] = 5, ["name"] = "darkage:stone_brick"}, {["x"] = 1, ["meta"] = {["fields"] = {}, ["inventory"] = {}}, ["y"] = 16, ["param1"] = 15, ["z"] = 3, ["name"] = "darkage:stone_brick"}, {["x"] = 1, ["meta"] = {["fields"] = {}, ["inventory"] = {}}, ["y"] = 16, ["param1"] = 15, ["z"] = 4, ["name"] = "darkage:stone_brick"}, {["x"] = 1, ["meta"] = {["fields"] = {}, ["inventory"] = {}}, ["y"] = 16, ["param1"] = 15, ["z"] = 5, ["name"] = "darkage:stone_brick"}, {["x"] = 1, ["meta"] = {["fields"] = {}, ["inventory"] = {}}, ["y"] = 17, ["param1"] = 15, ["z"] = 3, ["name"] = "darkage:stone_brick"}, {["x"] = 1, ["meta"] = {["fields"] = {}, ["inventory"] = {}}, ["param2"] = 1, ["y"] = 17, ["param1"] = 171, ["z"] = 4, ["name"] = "castle:arrowslit_sandstone_cross"}, {["x"] = 1, ["meta"] = {["fields"] = {}, ["inventory"] = {}}, ["y"] = 17, ["param1"] = 15, ["z"] = 5, ["name"] = "darkage:stone_brick"}, {["x"] = 1, ["meta"] = {["fields"] = {}, ["inventory"] = {}}, ["y"] = 18, ["param1"] = 15, ["z"] = 3, ["name"] = "darkage:stone_brick"}, {["x"] = 1, ["meta"] = {["fields"] = {}, ["inventory"] = {}}, ["y"] = 18, ["param1"] = 15, ["z"] = 4, ["name"] = "darkage:stone_brick"}, {["x"] = 1, ["meta"] = {["fields"] = {}, ["inventory"] = {}}, ["y"] = 18, ["param1"] = 15, ["z"] = 5, ["name"] = "darkage:stone_brick"}, {["x"] = 1, ["meta"] = {["fields"] = {}, ["inventory"] = {}}, ["y"] = 19, ["param1"] = 15, ["z"] = 3, ["name"] = "darkage:stone_brick"}, {["x"] = 1, ["meta"] = {["fields"] = {}, ["inventory"] = {}}, ["y"] = 19, ["param1"] = 15, ["z"] = 4, ["name"] = "darkage:stone_brick"}, {["x"] = 1, ["meta"] = {["fields"] = {}, ["inventory"] = {}}, ["y"] = 19, ["param1"] = 15, ["z"] = 5, ["name"] = "darkage:stone_brick"}, {["x"] = 1, ["meta"] = {["fields"] = {}, ["inventory"] = {}}, ["y"] = 20, ["param1"] = 15, ["z"] = 3, ["name"] = "darkage:stone_brick"}, {["x"] = 1, ["meta"] = {["fields"] = {}, ["inventory"] = {}}, ["y"] = 20, ["param1"] = 15, ["z"] = 4, ["name"] = "darkage:stone_brick"}, {["x"] = 1, ["meta"] = {["fields"] = {}, ["inventory"] = {}}, ["y"] = 20, ["param1"] = 15, ["z"] = 5, ["name"] = "darkage:stone_brick"}, {["x"] = 1, ["meta"] = {["fields"] = {}, ["inventory"] = {}}, ["y"] = 21, ["param1"] = 15, ["z"] = 3, ["name"] = "darkage:stone_brick"}, {["x"] = 1, ["meta"] = {["fields"] = {}, ["inventory"] = {}}, ["param2"] = 1, ["y"] = 21, ["param1"] = 187, ["z"] = 4, ["name"] = "castle:arrowslit_desertstonebrick_cross"}, {["x"] = 1, ["meta"] = {["fields"] = {}, ["inventory"] = {}}, ["y"] = 21, ["param1"] = 15, ["z"] = 5, ["name"] = "darkage:stone_brick"}, {["x"] = 1, ["meta"] = {["fields"] = {}, ["inventory"] = {}}, ["param2"] = 20, ["y"] = 22, ["z"] = 1, ["name"] = "homedecor:glowlight_quarter_white"}, {["x"] = 1, ["meta"] = {["fields"] = {}, ["inventory"] = {}}, ["param2"] = 20, ["y"] = 22, ["z"] = 2, ["name"] = "homedecor:glowlight_quarter_white"}, {["x"] = 1, ["meta"] = {["fields"] = {}, ["inventory"] = {}}, ["y"] = 22, ["param1"] = 15, ["z"] = 3, ["name"] = "darkage:stone_brick"}, {["x"] = 1, ["meta"] = {["fields"] = {}, ["inventory"] = {}}, ["y"] = 22, ["param1"] = 15, ["z"] = 4, ["name"] = "darkage:stone_brick"}, {["x"] = 1, ["meta"] = {["fields"] = {}, ["inventory"] = {}}, ["y"] = 22, ["param1"] = 15, ["z"] = 5, ["name"] = "darkage:stone_brick"}, {["x"] = 1, ["meta"] = {["fields"] = {}, ["inventory"] = {}}, ["param2"] = 23, ["y"] = 22, ["z"] = 6, ["name"] = "homedecor:glowlight_quarter_white"}, {["x"] = 1, ["meta"] = {["fields"] = {}, ["inventory"] = {}}, ["param2"] = 23, ["y"] = 22, ["z"] = 7, ["name"] = "homedecor:glowlight_quarter_white"}, {["x"] = 1, ["meta"] = {["fields"] = {}, ["inventory"] = {}}, ["y"] = 23, ["z"] = 1, ["name"] = "darkage:stone_brick"}, {["x"] = 1, ["meta"] = {["fields"] = {}, ["inventory"] = {}}, ["y"] = 23, ["z"] = 2, ["name"] = "darkage:stone_brick"}, {["x"] = 1, ["meta"] = {["fields"] = {}, ["inventory"] = {}}, ["y"] = 23, ["param1"] = 15, ["z"] = 3, ["name"] = "darkage:stone_brick"}, {["x"] = 1, ["meta"] = {["fields"] = {}, ["inventory"] = {}}, ["y"] = 23, ["param1"] = 15, ["z"] = 4, ["name"] = "darkage:stone_brick"}, {["x"] = 1, ["meta"] = {["fields"] = {}, ["inventory"] = {}}, ["y"] = 23, ["param1"] = 15, ["z"] = 5, ["name"] = "darkage:stone_brick"}, {["x"] = 1, ["meta"] = {["fields"] = {}, ["inventory"] = {}}, ["y"] = 23, ["z"] = 6, ["name"] = "darkage:stone_brick"}, {["x"] = 1, ["meta"] = {["fields"] = {}, ["inventory"] = {}}, ["y"] = 23, ["z"] = 7, ["name"] = "darkage:stone_brick"}, {["x"] = 1, ["meta"] = {["fields"] = {}, ["inventory"] = {}}, ["param2"] = 1, ["y"] = 24, ["param1"] = 173, ["z"] = 0, ["name"] = "homedecor:fence_wrought_iron"}, {["x"] = 1, ["meta"] = {["fields"] = {}, ["inventory"] = {}}, ["param2"] = 2, ["y"] = 24, ["param1"] = 172, ["z"] = 3, ["name"] = "castle:pillars_stonebrick_bottom"}, {["x"] = 1, ["meta"] = {["fields"] = {}, ["inventory"] = {}}, ["param2"] = 3, ["y"] = 24, ["param1"] = 172, ["z"] = 5, ["name"] = "castle:pillars_stonebrick_bottom"}, {["x"] = 1, ["meta"] = {["fields"] = {}, ["inventory"] = {}}, ["param2"] = 2, ["y"] = 24, ["param1"] = 173, ["z"] = 8, ["name"] = "homedecor:fence_wrought_iron"}, {["x"] = 1, ["meta"] = {["fields"] = {}, ["inventory"] = {}}, ["param2"] = 2, ["y"] = 25, ["param1"] = 188, ["z"] = 3, ["name"] = "castle:pillars_stonebrick_middle"}, {["x"] = 1, ["meta"] = {["fields"] = {}, ["inventory"] = {}}, ["param2"] = 3, ["y"] = 25, ["param1"] = 188, ["z"] = 5, ["name"] = "castle:pillars_stonebrick_middle"}, {["x"] = 1, ["meta"] = {["fields"] = {}, ["inventory"] = {}}, ["param2"] = 20, ["y"] = 26, ["z"] = 2, ["name"] = "homedecor:glowlight_quarter_white"}, {["x"] = 1, ["meta"] = {["fields"] = {}, ["inventory"] = {}}, ["param2"] = 2, ["y"] = 26, ["param1"] = 204, ["z"] = 3, ["name"] = "castle:pillars_stonebrick_top"}, {["x"] = 1, ["meta"] = {["fields"] = {}, ["inventory"] = {}}, ["param2"] = 3, ["y"] = 26, ["param1"] = 204, ["z"] = 5, ["name"] = "castle:pillars_stonebrick_top"}, {["x"] = 1, ["meta"] = {["fields"] = {}, ["inventory"] = {}}, ["param2"] = 23, ["y"] = 26, ["z"] = 6, ["name"] = "homedecor:glowlight_quarter_white"}, {["x"] = 1, ["meta"] = {["fields"] = {}, ["inventory"] = {}}, ["y"] = 27, ["param1"] = 205, ["z"] = 2, ["name"] = "stairs:slab_darkage_slate_cobble"}, {["x"] = 1, ["meta"] = {["fields"] = {}, ["inventory"] = {}}, ["y"] = 27, ["z"] = 3, ["name"] = "darkage:slate_cobble"}, {["x"] = 1, ["meta"] = {["fields"] = {}, ["inventory"] = {}}, ["y"] = 27, ["z"] = 4, ["name"] = "darkage:slate_cobble"}, {["x"] = 1, ["meta"] = {["fields"] = {}, ["inventory"] = {}}, ["y"] = 27, ["z"] = 5, ["name"] = "darkage:slate_cobble"}, {["x"] = 1, ["meta"] = {["fields"] = {}, ["inventory"] = {}}, ["y"] = 27, ["param1"] = 205, ["z"] = 6, ["name"] = "stairs:slab_darkage_slate_cobble"}, {["x"] = 2, ["meta"] = {["fields"] = {}, ["inventory"] = {}}, ["y"] = 2, ["z"] = 3, ["name"] = "darkage:stone_brick"}, {["x"] = 2, ["meta"] = {["fields"] = {}, ["inventory"] = {}}, ["y"] = 2, ["z"] = 4, ["name"] = "darkage:stone_brick"}, {["x"] = 2, ["meta"] = {["fields"] = {}, ["inventory"] = {}}, ["y"] = 2, ["z"] = 5, ["name"] = "darkage:stone_brick"}, {["x"] = 2, ["meta"] = {["fields"] = {}, ["inventory"] = {}}, ["y"] = 3, ["param1"] = 11, ["z"] = 2, ["name"] = "darkage:stone_brick"}, {["x"] = 2, ["meta"] = {["fields"] = {}, ["inventory"] = {}}, ["y"] = 3, ["param1"] = 170, ["z"] = 3, ["name"] = "stairs:slab_steelblock"}, {["x"] = 2, ["meta"] = {["fields"] = {}, ["inventory"] = {}}, ["y"] = 3, ["z"] = 4, ["name"] = "default:steelblock"}, {["x"] = 2, ["meta"] = {["fields"] = {}, ["inventory"] = {}}, ["y"] = 3, ["z"] = 6, ["name"] = "darkage:stone_brick"}, {["x"] = 2, ["meta"] = {["fields"] = {}, ["inventory"] = {}}, ["y"] = 4, ["param1"] = 12, ["z"] = 2, ["name"] = "darkage:stone_brick"}, {["x"] = 2, ["meta"] = {["fields"] = {}, ["inventory"] = {}}, ["y"] = 4, ["param1"] = 153, ["z"] = 5, ["name"] = "stairs:slab_steelblock"}, {["x"] = 2, ["meta"] = {["fields"] = {}, ["inventory"] = {}}, ["y"] = 4, ["param1"] = 28, ["z"] = 6, ["name"] = "darkage:stone_brick"}, {["x"] = 2, ["meta"] = {["fields"] = {}, ["inventory"] = {}}, ["y"] = 5, ["param1"] = 13, ["z"] = 2, ["name"] = "darkage:stone_brick"}, {["x"] = 2, ["meta"] = {["fields"] = {}, ["inventory"] = {}}, ["y"] = 5, ["param1"] = 45, ["z"] = 6, ["name"] = "darkage:stone_brick"}, {["x"] = 2, ["meta"] = {["fields"] = {}, ["inventory"] = {}}, ["y"] = 6, ["param1"] = 15, ["z"] = 2, ["name"] = "darkage:stone_brick"}, {["x"] = 2, ["meta"] = {["fields"] = {}, ["inventory"] = {}}, ["y"] = 6, ["param1"] = 31, ["z"] = 6, ["name"] = "darkage:stone_brick"}, {["x"] = 2, ["meta"] = {["fields"] = {}, ["inventory"] = {}}, ["y"] = 7, ["param1"] = 15, ["z"] = 2, ["name"] = "darkage:stone_brick"}, {["x"] = 2, ["meta"] = {["fields"] = {}, ["inventory"] = {}}, ["y"] = 7, ["param1"] = 170, ["z"] = 3, ["name"] = "stairs:slab_steelblock"}, {["x"] = 2, ["meta"] = {["fields"] = {}, ["inventory"] = {}}, ["y"] = 7, ["z"] = 4, ["name"] = "default:steelblock"}, {["x"] = 2, ["meta"] = {["fields"] = {}, ["inventory"] = {}}, ["y"] = 7, ["param1"] = 15, ["z"] = 6, ["name"] = "darkage:stone_brick"}, {["x"] = 2, ["meta"] = {["fields"] = {}, ["inventory"] = {}}, ["y"] = 8, ["param1"] = 15, ["z"] = 2, ["name"] = "darkage:stone_brick"}, {["x"] = 2, ["meta"] = {["fields"] = {}, ["inventory"] = {}}, ["y"] = 8, ["param1"] = 170, ["z"] = 5, ["name"] = "stairs:slab_steelblock"}, {["x"] = 2, ["meta"] = {["fields"] = {}, ["inventory"] = {}}, ["y"] = 8, ["param1"] = 15, ["z"] = 6, ["name"] = "darkage:stone_brick"}, {["x"] = 2, ["meta"] = {["fields"] = {}, ["inventory"] = {}}, ["y"] = 9, ["param1"] = 15, ["z"] = 2, ["name"] = "darkage:stone_brick"}, {["x"] = 2, ["meta"] = {["fields"] = {}, ["inventory"] = {}}, ["y"] = 9, ["param1"] = 15, ["z"] = 6, ["name"] = "darkage:stone_brick"}, {["x"] = 2, ["meta"] = {["fields"] = {}, ["inventory"] = {}}, ["y"] = 10, ["param1"] = 15, ["z"] = 2, ["name"] = "darkage:stone_brick"}, {["x"] = 2, ["meta"] = {["fields"] = {}, ["inventory"] = {}}, ["y"] = 10, ["param1"] = 15, ["z"] = 6, ["name"] = "darkage:stone_brick"}, {["x"] = 2, ["meta"] = {["fields"] = {}, ["inventory"] = {}}, ["y"] = 11, ["param1"] = 15, ["z"] = 2, ["name"] = "darkage:stone_brick"}, {["x"] = 2, ["meta"] = {["fields"] = {}, ["inventory"] = {}}, ["y"] = 11, ["param1"] = 170, ["z"] = 3, ["name"] = "stairs:slab_steelblock"}, {["x"] = 2, ["meta"] = {["fields"] = {}, ["inventory"] = {}}, ["y"] = 11, ["z"] = 4, ["name"] = "default:steelblock"}, {["x"] = 2, ["meta"] = {["fields"] = {}, ["inventory"] = {}}, ["y"] = 11, ["param1"] = 15, ["z"] = 6, ["name"] = "darkage:stone_brick"}, {["x"] = 2, ["meta"] = {["fields"] = {}, ["inventory"] = {}}, ["y"] = 12, ["param1"] = 15, ["z"] = 2, ["name"] = "darkage:stone_brick"}, {["x"] = 2, ["meta"] = {["fields"] = {}, ["inventory"] = {}}, ["y"] = 12, ["param1"] = 170, ["z"] = 5, ["name"] = "stairs:slab_steelblock"}, {["x"] = 2, ["meta"] = {["fields"] = {}, ["inventory"] = {}}, ["y"] = 12, ["param1"] = 15, ["z"] = 6, ["name"] = "darkage:stone_brick"}, {["x"] = 2, ["meta"] = {["fields"] = {}, ["inventory"] = {}}, ["y"] = 13, ["param1"] = 15, ["z"] = 2, ["name"] = "darkage:stone_brick"}, {["x"] = 2, ["meta"] = {["fields"] = {}, ["inventory"] = {}}, ["y"] = 13, ["param1"] = 15, ["z"] = 6, ["name"] = "darkage:stone_brick"}, {["x"] = 2, ["meta"] = {["fields"] = {}, ["inventory"] = {}}, ["y"] = 14, ["param1"] = 15, ["z"] = 2, ["name"] = "darkage:stone_brick"}, {["x"] = 2, ["meta"] = {["fields"] = {}, ["inventory"] = {}}, ["y"] = 14, ["param1"] = 15, ["z"] = 6, ["name"] = "darkage:stone_brick"}, {["x"] = 2, ["meta"] = {["fields"] = {}, ["inventory"] = {}}, ["y"] = 15, ["param1"] = 15, ["z"] = 2, ["name"] = "darkage:stone_brick"}, {["x"] = 2, ["meta"] = {["fields"] = {}, ["inventory"] = {}}, ["y"] = 15, ["param1"] = 170, ["z"] = 3, ["name"] = "stairs:slab_steelblock"}, {["x"] = 2, ["meta"] = {["fields"] = {}, ["inventory"] = {}}, ["y"] = 15, ["z"] = 4, ["name"] = "default:steelblock"}, {["x"] = 2, ["meta"] = {["fields"] = {}, ["inventory"] = {}}, ["y"] = 15, ["param1"] = 15, ["z"] = 6, ["name"] = "darkage:stone_brick"}, {["x"] = 2, ["meta"] = {["fields"] = {}, ["inventory"] = {}}, ["y"] = 16, ["param1"] = 15, ["z"] = 2, ["name"] = "darkage:stone_brick"}, {["x"] = 2, ["meta"] = {["fields"] = {}, ["inventory"] = {}}, ["y"] = 16, ["param1"] = 170, ["z"] = 5, ["name"] = "stairs:slab_steelblock"}, {["x"] = 2, ["meta"] = {["fields"] = {}, ["inventory"] = {}}, ["y"] = 16, ["param1"] = 15, ["z"] = 6, ["name"] = "darkage:stone_brick"}, {["x"] = 2, ["meta"] = {["fields"] = {}, ["inventory"] = {}}, ["y"] = 17, ["param1"] = 15, ["z"] = 2, ["name"] = "darkage:stone_brick"}, {["x"] = 2, ["meta"] = {["fields"] = {}, ["inventory"] = {}}, ["y"] = 17, ["param1"] = 15, ["z"] = 6, ["name"] = "darkage:stone_brick"}, {["x"] = 2, ["meta"] = {["fields"] = {}, ["inventory"] = {}}, ["y"] = 18, ["param1"] = 15, ["z"] = 2, ["name"] = "darkage:stone_brick"}, {["x"] = 2, ["meta"] = {["fields"] = {}, ["inventory"] = {}}, ["y"] = 18, ["param1"] = 15, ["z"] = 6, ["name"] = "darkage:stone_brick"}, {["x"] = 2, ["meta"] = {["fields"] = {}, ["inventory"] = {}}, ["y"] = 19, ["param1"] = 15, ["z"] = 2, ["name"] = "darkage:stone_brick"}, {["x"] = 2, ["meta"] = {["fields"] = {}, ["inventory"] = {}}, ["y"] = 19, ["param1"] = 170, ["z"] = 3, ["name"] = "stairs:slab_steelblock"}, {["x"] = 2, ["meta"] = {["fields"] = {}, ["inventory"] = {}}, ["y"] = 19, ["z"] = 4, ["name"] = "default:steelblock"}, {["x"] = 2, ["meta"] = {["fields"] = {}, ["inventory"] = {}}, ["y"] = 19, ["param1"] = 15, ["z"] = 6, ["name"] = "darkage:stone_brick"}, {["x"] = 2, ["meta"] = {["fields"] = {}, ["inventory"] = {}}, ["y"] = 20, ["param1"] = 15, ["z"] = 2, ["name"] = "darkage:stone_brick"}, {["x"] = 2, ["meta"] = {["fields"] = {}, ["inventory"] = {}}, ["y"] = 20, ["param1"] = 170, ["z"] = 5, ["name"] = "stairs:slab_steelblock"}, {["x"] = 2, ["meta"] = {["fields"] = {}, ["inventory"] = {}}, ["y"] = 20, ["param1"] = 15, ["z"] = 6, ["name"] = "darkage:stone_brick"}, {["x"] = 2, ["meta"] = {["fields"] = {}, ["inventory"] = {}}, ["y"] = 21, ["param1"] = 15, ["z"] = 2, ["name"] = "darkage:stone_brick"}, {["x"] = 2, ["meta"] = {["fields"] = {}, ["inventory"] = {}}, ["y"] = 21, ["param1"] = 15, ["z"] = 6, ["name"] = "darkage:stone_brick"}, {["x"] = 2, ["meta"] = {["fields"] = {}, ["inventory"] = {}}, ["param2"] = 20, ["y"] = 22, ["z"] = 0, ["name"] = "homedecor:glowlight_quarter_white"}, {["x"] = 2, ["meta"] = {["fields"] = {}, ["inventory"] = {}}, ["param2"] = 20, ["y"] = 22, ["z"] = 1, ["name"] = "homedecor:glowlight_quarter_white"}, {["x"] = 2, ["meta"] = {["fields"] = {}, ["inventory"] = {}}, ["y"] = 22, ["param1"] = 15, ["z"] = 2, ["name"] = "darkage:stone_brick"}, {["x"] = 2, ["meta"] = {["fields"] = {}, ["inventory"] = {}}, ["y"] = 22, ["param1"] = 15, ["z"] = 6, ["name"] = "darkage:stone_brick"}, {["x"] = 2, ["meta"] = {["fields"] = {}, ["inventory"] = {}}, ["param2"] = 23, ["y"] = 22, ["z"] = 7, ["name"] = "homedecor:glowlight_quarter_white"}, {["x"] = 2, ["meta"] = {["fields"] = {}, ["inventory"] = {}}, ["param2"] = 22, ["y"] = 22, ["z"] = 8, ["name"] = "homedecor:glowlight_quarter_white"}, {["x"] = 2, ["meta"] = {["fields"] = {}, ["inventory"] = {}}, ["y"] = 23, ["z"] = 0, ["name"] = "darkage:stone_brick"}, {["x"] = 2, ["meta"] = {["fields"] = {}, ["inventory"] = {}}, ["y"] = 23, ["z"] = 1, ["name"] = "darkage:stone_brick"}, {["x"] = 2, ["meta"] = {["fields"] = {}, ["inventory"] = {}}, ["y"] = 23, ["param1"] = 15, ["z"] = 2, ["name"] = "darkage:stone_brick"}, {["x"] = 2, ["meta"] = {["fields"] = {}, ["inventory"] = {}}, ["y"] = 23, ["z"] = 3, ["name"] = "default:steelblock"}, {["x"] = 2, ["meta"] = {["fields"] = {}, ["inventory"] = {}}, ["y"] = 23, ["z"] = 4, ["name"] = "default:steelblock"}, {["x"] = 2, ["meta"] = {["fields"] = {}, ["inventory"] = {}}, ["y"] = 23, ["z"] = 5, ["name"] = "default:steelblock"}, {["x"] = 2, ["meta"] = {["fields"] = {}, ["inventory"] = {}}, ["y"] = 23, ["param1"] = 15, ["z"] = 6, ["name"] = "darkage:stone_brick"}, {["x"] = 2, ["meta"] = {["fields"] = {}, ["inventory"] = {}}, ["y"] = 23, ["z"] = 7, ["name"] = "darkage:stone_brick"}, {["x"] = 2, ["meta"] = {["fields"] = {}, ["inventory"] = {}}, ["y"] = 23, ["z"] = 8, ["name"] = "darkage:stone_brick"}, {["x"] = 2, ["meta"] = {["fields"] = {}, ["inventory"] = {}}, ["param2"] = 23, ["y"] = 26, ["z"] = 1, ["name"] = "homedecor:glowlight_quarter_white"}, {["x"] = 2, ["meta"] = {["fields"] = {}, ["inventory"] = {}}, ["param2"] = 23, ["y"] = 26, ["z"] = 7, ["name"] = "homedecor:glowlight_quarter_white"}, {["x"] = 2, ["meta"] = {["fields"] = {}, ["inventory"] = {}}, ["y"] = 27, ["param1"] = 205, ["z"] = 1, ["name"] = "stairs:slab_darkage_slate_cobble"}, {["x"] = 2, ["meta"] = {["fields"] = {}, ["inventory"] = {}}, ["y"] = 27, ["z"] = 2, ["name"] = "darkage:slate_cobble"}, {["x"] = 2, ["meta"] = {["fields"] = {}, ["inventory"] = {}}, ["y"] = 27, ["param1"] = 188, ["z"] = 3, ["name"] = "stairs:slab_darkage_slate_cobble"}, {["x"] = 2, ["meta"] = {["fields"] = {}, ["inventory"] = {}}, ["y"] = 27, ["param1"] = 204, ["z"] = 4, ["name"] = "stairs:slab_darkage_slate_cobble"}, {["x"] = 2, ["meta"] = {["fields"] = {}, ["inventory"] = {}}, ["y"] = 27, ["z"] = 5, ["name"] = "darkage:slate_cobble"}, {["x"] = 2, ["meta"] = {["fields"] = {}, ["inventory"] = {}}, ["y"] = 27, ["z"] = 6, ["name"] = "darkage:slate_cobble"}, {["x"] = 2, ["meta"] = {["fields"] = {}, ["inventory"] = {}}, ["y"] = 27, ["param1"] = 205, ["z"] = 7, ["name"] = "stairs:slab_darkage_slate_cobble"}, {["x"] = 2, ["meta"] = {["fields"] = {}, ["inventory"] = {}}, ["y"] = 28, ["param1"] = 173, ["z"] = 3, ["name"] = "stairs:slab_darkage_slate_cobble"}, {["x"] = 2, ["meta"] = {["fields"] = {}, ["inventory"] = {}}, ["y"] = 28, ["param1"] = 189, ["z"] = 4, ["name"] = "stairs:slab_darkage_slate_cobble"}, {["x"] = 2, ["meta"] = {["fields"] = {}, ["inventory"] = {}}, ["y"] = 28, ["param1"] = 173, ["z"] = 5, ["name"] = "stairs:slab_darkage_slate_cobble"}, {["x"] = 3, ["meta"] = {["fields"] = {}, ["inventory"] = {}}, ["y"] = 1, ["z"] = 4, ["name"] = "darkage:stone_brick"}, {["x"] = 3, ["meta"] = {["fields"] = {}, ["inventory"] = {}}, ["y"] = 2, ["param1"] = 13, ["z"] = 0, ["name"] = "darkage:stone_brick"}, {["x"] = 3, ["meta"] = {["fields"] = {}, ["inventory"] = {}}, ["y"] = 2, ["param1"] = 13, ["z"] = 1, ["name"] = "darkage:stone_brick"}, {["x"] = 3, ["meta"] = {["fields"] = {}, ["inventory"] = {}}, ["y"] = 2, ["param1"] = 15, ["z"] = 2, ["name"] = "darkage:stone_brick"}, {["x"] = 3, ["meta"] = {["fields"] = {}, ["inventory"] = {}}, ["y"] = 2, ["param1"] = 15, ["z"] = 3, ["name"] = "darkage:stone_brick"}, {["x"] = 3, ["meta"] = {["fields"] = {}, ["inventory"] = {}}, ["y"] = 2, ["z"] = 4, ["name"] = "darkage:stone_brick"}, {["x"] = 3, ["meta"] = {["fields"] = {}, ["inventory"] = {}}, ["y"] = 2, ["z"] = 5, ["name"] = "darkage:stone_brick"}, {["x"] = 3, ["meta"] = {["fields"] = {}, ["inventory"] = {}}, ["y"] = 2, ["z"] = 6, ["name"] = "darkage:stone_brick"}, {["x"] = 3, ["meta"] = {["fields"] = {}, ["inventory"] = {}}, ["y"] = 3, ["param1"] = 15, ["z"] = 0, ["name"] = "darkage:stone_brick"}, {["x"] = 3, ["meta"] = {["fields"] = {}, ["inventory"] = {}}, ["y"] = 3, ["param1"] = 15, ["z"] = 1, ["name"] = "darkage:stone_brick"}, {["x"] = 3, ["meta"] = {["fields"] = {}, ["inventory"] = {}}, ["y"] = 3, ["param1"] = 170, ["z"] = 2, ["name"] = "stairs:slab_steelblock"}, {["x"] = 3, ["meta"] = {["fields"] = {}, ["inventory"] = {}}, ["y"] = 3, ["param1"] = 187, ["z"] = 3, ["name"] = "stairs:slab_steelblock"}, {["x"] = 3, ["meta"] = {["fields"] = {}, ["inventory"] = {}}, ["y"] = 3, ["z"] = 4, ["name"] = "default:steelblock"}, {["x"] = 3, ["meta"] = {["fields"] = {}, ["inventory"] = {}}, ["y"] = 3, ["param1"] = 27, ["z"] = 7, ["name"] = "darkage:stone_brick"}, {["x"] = 3, ["meta"] = {["fields"] = {}, ["inventory"] = {}}, ["y"] = 4, ["param1"] = 15, ["z"] = 0, ["name"] = "darkage:stone_brick"}, {["x"] = 3, ["meta"] = {["fields"] = {}, ["inventory"] = {}}, ["y"] = 4, ["param1"] = 15, ["z"] = 1, ["name"] = "darkage:stone_brick"}, {["x"] = 3, ["meta"] = {["fields"] = {}, ["inventory"] = {}}, ["y"] = 4, ["param1"] = 170, ["z"] = 5, ["name"] = "stairs:slab_steelblock"}, {["x"] = 3, ["meta"] = {["fields"] = {}, ["inventory"] = {}}, ["y"] = 4, ["param1"] = 153, ["z"] = 6, ["name"] = "stairs:slab_steelblock"}, {["x"] = 3, ["meta"] = {["fields"] = {}, ["inventory"] = {}}, ["y"] = 4, ["param1"] = 44, ["z"] = 7, ["name"] = "darkage:stone_brick"}, {["x"] = 3, ["meta"] = {["fields"] = {}, ["inventory"] = {}}, ["y"] = 5, ["param1"] = 15, ["z"] = 0, ["name"] = "darkage:stone_brick"}, {["x"] = 3, ["meta"] = {["fields"] = {}, ["inventory"] = {}}, ["y"] = 5, ["param1"] = 15, ["z"] = 1, ["name"] = "darkage:stone_brick"}, {["x"] = 3, ["meta"] = {["fields"] = {}, ["inventory"] = {}}, ["y"] = 5, ["param1"] = 61, ["z"] = 7, ["name"] = "darkage:stone_brick"}, {["x"] = 3, ["meta"] = {["fields"] = {}, ["inventory"] = {}}, ["y"] = 6, ["param1"] = 15, ["z"] = 0, ["name"] = "darkage:stone_brick"}, {["x"] = 3, ["meta"] = {["fields"] = {}, ["inventory"] = {}}, ["y"] = 6, ["param1"] = 15, ["z"] = 1, ["name"] = "darkage:stone_brick"}, {["x"] = 3, ["meta"] = {["fields"] = {}, ["inventory"] = {}}, ["y"] = 6, ["param1"] = 47, ["z"] = 7, ["name"] = "darkage:stone_brick"}, {["x"] = 3, ["meta"] = {["fields"] = {}, ["inventory"] = {}}, ["y"] = 7, ["param1"] = 15, ["z"] = 0, ["name"] = "darkage:stone_brick"}, {["x"] = 3, ["meta"] = {["fields"] = {}, ["inventory"] = {}}, ["y"] = 7, ["param1"] = 15, ["z"] = 1, ["name"] = "darkage:stone_brick"}, {["x"] = 3, ["meta"] = {["fields"] = {}, ["inventory"] = {}}, ["y"] = 7, ["param1"] = 170, ["z"] = 2, ["name"] = "stairs:slab_steelblock"}, {["x"] = 3, ["meta"] = {["fields"] = {}, ["inventory"] = {}}, ["y"] = 7, ["param1"] = 187, ["z"] = 3, ["name"] = "stairs:slab_steelblock"}, {["x"] = 3, ["meta"] = {["fields"] = {}, ["inventory"] = {}}, ["y"] = 7, ["z"] = 4, ["name"] = "default:steelblock"}, {["x"] = 3, ["meta"] = {["fields"] = {}, ["inventory"] = {}}, ["y"] = 7, ["param1"] = 31, ["z"] = 7, ["name"] = "darkage:stone_brick"}, {["x"] = 3, ["meta"] = {["fields"] = {}, ["inventory"] = {}}, ["y"] = 8, ["param1"] = 15, ["z"] = 0, ["name"] = "darkage:stone_brick"}, {["x"] = 3, ["meta"] = {["fields"] = {}, ["inventory"] = {}}, ["y"] = 8, ["param1"] = 15, ["z"] = 1, ["name"] = "darkage:stone_brick"}, {["x"] = 3, ["meta"] = {["fields"] = {}, ["inventory"] = {}}, ["y"] = 8, ["param1"] = 187, ["z"] = 5, ["name"] = "stairs:slab_steelblock"}, {["x"] = 3, ["meta"] = {["fields"] = {}, ["inventory"] = {}}, ["y"] = 8, ["param1"] = 170, ["z"] = 6, ["name"] = "stairs:slab_steelblock"}, {["x"] = 3, ["meta"] = {["fields"] = {}, ["inventory"] = {}}, ["y"] = 8, ["param1"] = 15, ["z"] = 7, ["name"] = "darkage:stone_brick"}, {["x"] = 3, ["meta"] = {["fields"] = {}, ["inventory"] = {}}, ["y"] = 9, ["param1"] = 15, ["z"] = 0, ["name"] = "darkage:stone_brick"}, {["x"] = 3, ["meta"] = {["fields"] = {}, ["inventory"] = {}}, ["y"] = 9, ["param1"] = 15, ["z"] = 1, ["name"] = "darkage:stone_brick"}, {["x"] = 3, ["meta"] = {["fields"] = {}, ["inventory"] = {}}, ["y"] = 9, ["param1"] = 15, ["z"] = 7, ["name"] = "darkage:stone_brick"}, {["x"] = 3, ["meta"] = {["fields"] = {}, ["inventory"] = {}}, ["y"] = 10, ["z"] = 0, ["name"] = "darkage:stone_brick"}, {["x"] = 3, ["meta"] = {["fields"] = {}, ["inventory"] = {}}, ["y"] = 10, ["param1"] = 15, ["z"] = 1, ["name"] = "darkage:stone_brick"}, {["x"] = 3, ["meta"] = {["fields"] = {}, ["inventory"] = {}}, ["y"] = 10, ["param1"] = 15, ["z"] = 7, ["name"] = "darkage:stone_brick"}, {["x"] = 3, ["meta"] = {["fields"] = {}, ["inventory"] = {}}, ["y"] = 11, ["z"] = 0, ["name"] = "darkage:stone_brick"}, {["x"] = 3, ["meta"] = {["fields"] = {}, ["inventory"] = {}}, ["y"] = 11, ["param1"] = 15, ["z"] = 1, ["name"] = "darkage:stone_brick"}, {["x"] = 3, ["meta"] = {["fields"] = {}, ["inventory"] = {}}, ["y"] = 11, ["param1"] = 170, ["z"] = 2, ["name"] = "stairs:slab_steelblock"}, {["x"] = 3, ["meta"] = {["fields"] = {}, ["inventory"] = {}}, ["y"] = 11, ["param1"] = 187, ["z"] = 3, ["name"] = "stairs:slab_steelblock"}, {["x"] = 3, ["meta"] = {["fields"] = {}, ["inventory"] = {}}, ["y"] = 11, ["z"] = 4, ["name"] = "default:steelblock"}, {["x"] = 3, ["meta"] = {["fields"] = {}, ["inventory"] = {}}, ["y"] = 11, ["param1"] = 15, ["z"] = 7, ["name"] = "darkage:stone_brick"}, {["x"] = 3, ["meta"] = {["fields"] = {}, ["inventory"] = {}}, ["y"] = 12, ["param1"] = 15, ["z"] = 1, ["name"] = "darkage:stone_brick"}, {["x"] = 3, ["meta"] = {["fields"] = {}, ["inventory"] = {}}, ["y"] = 12, ["param1"] = 187, ["z"] = 5, ["name"] = "stairs:slab_steelblock"}, {["x"] = 3, ["meta"] = {["fields"] = {}, ["inventory"] = {}}, ["y"] = 12, ["param1"] = 170, ["z"] = 6, ["name"] = "stairs:slab_steelblock"}, {["x"] = 3, ["meta"] = {["fields"] = {}, ["inventory"] = {}}, ["y"] = 12, ["param1"] = 15, ["z"] = 7, ["name"] = "darkage:stone_brick"}, {["x"] = 3, ["meta"] = {["fields"] = {}, ["inventory"] = {}}, ["y"] = 13, ["param1"] = 15, ["z"] = 1, ["name"] = "darkage:stone_brick"}, {["x"] = 3, ["meta"] = {["fields"] = {}, ["inventory"] = {}}, ["y"] = 13, ["param1"] = 15, ["z"] = 7, ["name"] = "darkage:stone_brick"}, {["x"] = 3, ["meta"] = {["fields"] = {}, ["inventory"] = {}}, ["y"] = 14, ["param1"] = 15, ["z"] = 1, ["name"] = "darkage:stone_brick"}, {["x"] = 3, ["meta"] = {["fields"] = {}, ["inventory"] = {}}, ["y"] = 14, ["param1"] = 15, ["z"] = 7, ["name"] = "darkage:stone_brick"}, {["x"] = 3, ["meta"] = {["fields"] = {}, ["inventory"] = {}}, ["y"] = 15, ["param1"] = 15, ["z"] = 1, ["name"] = "darkage:stone_brick"}, {["x"] = 3, ["meta"] = {["fields"] = {}, ["inventory"] = {}}, ["y"] = 15, ["param1"] = 170, ["z"] = 2, ["name"] = "stairs:slab_steelblock"}, {["x"] = 3, ["meta"] = {["fields"] = {}, ["inventory"] = {}}, ["y"] = 15, ["param1"] = 187, ["z"] = 3, ["name"] = "stairs:slab_steelblock"}, {["x"] = 3, ["meta"] = {["fields"] = {}, ["inventory"] = {}}, ["y"] = 15, ["z"] = 4, ["name"] = "default:steelblock"}, {["x"] = 3, ["meta"] = {["fields"] = {}, ["inventory"] = {}}, ["y"] = 15, ["param1"] = 15, ["z"] = 7, ["name"] = "darkage:stone_brick"}, {["x"] = 3, ["meta"] = {["fields"] = {}, ["inventory"] = {}}, ["y"] = 16, ["param1"] = 15, ["z"] = 1, ["name"] = "darkage:stone_brick"}, {["x"] = 3, ["meta"] = {["fields"] = {}, ["inventory"] = {}}, ["y"] = 16, ["param1"] = 187, ["z"] = 5, ["name"] = "stairs:slab_steelblock"}, {["x"] = 3, ["meta"] = {["fields"] = {}, ["inventory"] = {}}, ["y"] = 16, ["param1"] = 170, ["z"] = 6, ["name"] = "stairs:slab_steelblock"}, {["x"] = 3, ["meta"] = {["fields"] = {}, ["inventory"] = {}}, ["y"] = 16, ["param1"] = 15, ["z"] = 7, ["name"] = "darkage:stone_brick"}, {["x"] = 3, ["meta"] = {["fields"] = {}, ["inventory"] = {}}, ["y"] = 17, ["param1"] = 15, ["z"] = 1, ["name"] = "darkage:stone_brick"}, {["x"] = 3, ["meta"] = {["fields"] = {}, ["inventory"] = {}}, ["y"] = 17, ["param1"] = 15, ["z"] = 7, ["name"] = "darkage:stone_brick"}, {["x"] = 3, ["meta"] = {["fields"] = {}, ["inventory"] = {}}, ["y"] = 18, ["param1"] = 15, ["z"] = 1, ["name"] = "darkage:stone_brick"}, {["x"] = 3, ["meta"] = {["fields"] = {}, ["inventory"] = {}}, ["y"] = 18, ["param1"] = 15, ["z"] = 7, ["name"] = "darkage:stone_brick"}, {["x"] = 3, ["meta"] = {["fields"] = {}, ["inventory"] = {}}, ["y"] = 19, ["param1"] = 15, ["z"] = 1, ["name"] = "darkage:stone_brick"}, {["x"] = 3, ["meta"] = {["fields"] = {}, ["inventory"] = {}}, ["y"] = 19, ["param1"] = 170, ["z"] = 2, ["name"] = "stairs:slab_steelblock"}, {["x"] = 3, ["meta"] = {["fields"] = {}, ["inventory"] = {}}, ["y"] = 19, ["param1"] = 187, ["z"] = 3, ["name"] = "stairs:slab_steelblock"}, {["x"] = 3, ["meta"] = {["fields"] = {}, ["inventory"] = {}}, ["y"] = 19, ["z"] = 4, ["name"] = "default:steelblock"}, {["x"] = 3, ["meta"] = {["fields"] = {}, ["inventory"] = {}}, ["y"] = 19, ["param1"] = 15, ["z"] = 7, ["name"] = "darkage:stone_brick"}, {["x"] = 3, ["meta"] = {["fields"] = {}, ["inventory"] = {}}, ["y"] = 20, ["param1"] = 15, ["z"] = 1, ["name"] = "darkage:stone_brick"}, {["x"] = 3, ["meta"] = {["fields"] = {}, ["inventory"] = {}}, ["y"] = 20, ["param1"] = 187, ["z"] = 5, ["name"] = "stairs:slab_steelblock"}, {["x"] = 3, ["meta"] = {["fields"] = {}, ["inventory"] = {}}, ["y"] = 20, ["param1"] = 170, ["z"] = 6, ["name"] = "stairs:slab_steelblock"}, {["x"] = 3, ["meta"] = {["fields"] = {}, ["inventory"] = {}}, ["y"] = 20, ["param1"] = 15, ["z"] = 7, ["name"] = "darkage:stone_brick"}, {["x"] = 3, ["meta"] = {["fields"] = {}, ["inventory"] = {}}, ["y"] = 21, ["param1"] = 15, ["z"] = 1, ["name"] = "darkage:stone_brick"}, {["x"] = 3, ["meta"] = {["fields"] = {}, ["inventory"] = {}}, ["y"] = 21, ["param1"] = 15, ["z"] = 7, ["name"] = "darkage:stone_brick"}, {["x"] = 3, ["meta"] = {["fields"] = {}, ["inventory"] = {}}, ["param2"] = 20, ["y"] = 22, ["z"] = 0, ["name"] = "homedecor:glowlight_quarter_white"}, {["x"] = 3, ["meta"] = {["fields"] = {}, ["inventory"] = {}}, ["y"] = 22, ["param1"] = 15, ["z"] = 1, ["name"] = "darkage:stone_brick"}, {["x"] = 3, ["meta"] = {["fields"] = {}, ["inventory"] = {}}, ["y"] = 22, ["param1"] = 15, ["z"] = 7, ["name"] = "darkage:stone_brick"}, {["x"] = 3, ["meta"] = {["fields"] = {}, ["inventory"] = {}}, ["param2"] = 22, ["y"] = 22, ["z"] = 8, ["name"] = "homedecor:glowlight_quarter_white"}, {["x"] = 3, ["meta"] = {["fields"] = {}, ["inventory"] = {}}, ["y"] = 23, ["z"] = 0, ["name"] = "darkage:stone_brick"}, {["x"] = 3, ["meta"] = {["fields"] = {}, ["inventory"] = {}}, ["y"] = 23, ["param1"] = 15, ["z"] = 1, ["name"] = "darkage:stone_brick"}, {["x"] = 3, ["meta"] = {["fields"] = {}, ["inventory"] = {}}, ["y"] = 23, ["param1"] = 170, ["z"] = 2, ["name"] = "stairs:slab_steelblock"}, {["x"] = 3, ["meta"] = {["fields"] = {}, ["inventory"] = {}}, ["y"] = 23, ["param1"] = 187, ["z"] = 3, ["name"] = "stairs:slab_steelblock"}, {["x"] = 3, ["meta"] = {["fields"] = {}, ["inventory"] = {}}, ["y"] = 23, ["z"] = 4, ["name"] = "default:steelblock"}, {["x"] = 3, ["meta"] = {["fields"] = {}, ["inventory"] = {}}, ["y"] = 23, ["z"] = 5, ["name"] = "default:steelblock"}, {["x"] = 3, ["meta"] = {["fields"] = {}, ["inventory"] = {}}, ["y"] = 23, ["z"] = 6, ["name"] = "default:steelblock"}, {["x"] = 3, ["meta"] = {["fields"] = {}, ["inventory"] = {}}, ["y"] = 23, ["param1"] = 15, ["z"] = 7, ["name"] = "darkage:stone_brick"}, {["x"] = 3, ["meta"] = {["fields"] = {}, ["inventory"] = {}}, ["y"] = 23, ["z"] = 8, ["name"] = "darkage:stone_brick"}, {["x"] = 3, ["meta"] = {["fields"] = {}, ["inventory"] = {}}, ["param2"] = 2, ["y"] = 24, ["param1"] = 172, ["z"] = 1, ["name"] = "castle:pillars_stonebrick_bottom"}, {["x"] = 3, ["meta"] = {["fields"] = {}, ["inventory"] = {}}, ["param2"] = 2, ["y"] = 24, ["param1"] = 172, ["z"] = 7, ["name"] = "castle:pillars_stonebrick_bottom"}, {["x"] = 3, ["meta"] = {["fields"] = {}, ["inventory"] = {}}, ["param2"] = 2, ["y"] = 25, ["param1"] = 188, ["z"] = 1, ["name"] = "castle:pillars_stonebrick_middle"}, {["x"] = 3, ["meta"] = {["fields"] = {}, ["inventory"] = {}}, ["param2"] = 2, ["y"] = 25, ["param1"] = 188, ["z"] = 7, ["name"] = "castle:pillars_stonebrick_middle"}, {["x"] = 3, ["meta"] = {["fields"] = {}, ["inventory"] = {}}, ["param2"] = 20, ["y"] = 26, ["z"] = 0, ["name"] = "homedecor:glowlight_quarter_white"}, {["x"] = 3, ["meta"] = {["fields"] = {}, ["inventory"] = {}}, ["param2"] = 2, ["y"] = 26, ["param1"] = 204, ["z"] = 1, ["name"] = "castle:pillars_stonebrick_top"}, {["x"] = 3, ["meta"] = {["fields"] = {}, ["inventory"] = {}}, ["param2"] = 2, ["y"] = 26, ["param1"] = 204, ["z"] = 7, ["name"] = "castle:pillars_stonebrick_top"}, {["x"] = 3, ["meta"] = {["fields"] = {}, ["inventory"] = {}}, ["param2"] = 22, ["y"] = 26, ["z"] = 8, ["name"] = "homedecor:glowlight_quarter_white"}, {["x"] = 3, ["meta"] = {["fields"] = {}, ["inventory"] = {}}, ["y"] = 27, ["param1"] = 205, ["z"] = 0, ["name"] = "stairs:slab_darkage_slate_cobble"}, {["x"] = 3, ["meta"] = {["fields"] = {}, ["inventory"] = {}}, ["y"] = 27, ["z"] = 1, ["name"] = "darkage:slate_cobble"}, {["x"] = 3, ["meta"] = {["fields"] = {}, ["inventory"] = {}}, ["y"] = 27, ["param1"] = 188, ["z"] = 2, ["name"] = "stairs:slab_darkage_slate_cobble"}, {["x"] = 3, ["meta"] = {["fields"] = {}, ["inventory"] = {}}, ["y"] = 27, ["param1"] = 188, ["z"] = 6, ["name"] = "stairs:slab_darkage_slate_cobble"}, {["x"] = 3, ["meta"] = {["fields"] = {}, ["inventory"] = {}}, ["y"] = 27, ["z"] = 7, ["name"] = "darkage:slate_cobble"}, {["x"] = 3, ["meta"] = {["fields"] = {}, ["inventory"] = {}}, ["y"] = 27, ["param1"] = 205, ["z"] = 8, ["name"] = "stairs:slab_darkage_slate_cobble"}, {["x"] = 3, ["meta"] = {["fields"] = {}, ["inventory"] = {}}, ["y"] = 28, ["param1"] = 173, ["z"] = 2, ["name"] = "stairs:slab_darkage_slate_cobble"}, {["x"] = 3, ["meta"] = {["fields"] = {}, ["inventory"] = {}}, ["y"] = 28, ["z"] = 3, ["name"] = "darkage:slate_cobble"}, {["x"] = 3, ["meta"] = {["fields"] = {}, ["inventory"] = {}}, ["y"] = 28, ["z"] = 4, ["name"] = "darkage:slate_cobble"}, {["x"] = 3, ["meta"] = {["fields"] = {}, ["inventory"] = {}}, ["y"] = 28, ["z"] = 5, ["name"] = "darkage:slate_cobble"}, {["x"] = 3, ["meta"] = {["fields"] = {}, ["inventory"] = {}}, ["y"] = 28, ["param1"] = 173, ["z"] = 6, ["name"] = "stairs:slab_darkage_slate_cobble"}, {["x"] = 4, ["meta"] = {["fields"] = {}, ["inventory"] = {}}, ["y"] = 0, ["param1"] = 13, ["z"] = 0, ["name"] = "darkage:stone_brick"}, {["x"] = 4, ["meta"] = {["fields"] = {}, ["inventory"] = {}}, ["y"] = 0, ["param1"] = 13, ["z"] = 1, ["name"] = "darkage:stone_brick"}, {["x"] = 4, ["meta"] = {["fields"] = {}, ["inventory"] = {}}, ["y"] = 0, ["param1"] = 13, ["z"] = 2, ["name"] = "darkage:stone_brick"}, {["x"] = 4, ["meta"] = {["fields"] = {}, ["inventory"] = {}}, ["y"] = 0, ["param1"] = 13, ["z"] = 3, ["name"] = "darkage:stone_brick"}, {["x"] = 4, ["meta"] = {["fields"] = {}, ["inventory"] = {}}, ["y"] = 0, ["param1"] = 13, ["z"] = 4, ["name"] = "darkage:stone_brick"}, {["x"] = 4, ["meta"] = {["fields"] = {}, ["inventory"] = {}}, ["y"] = 1, ["param1"] = 13, ["z"] = 0, ["name"] = "darkage:stone_brick"}, {["x"] = 4, ["meta"] = {["fields"] = {}, ["inventory"] = {}}, ["y"] = 1, ["param1"] = 13, ["z"] = 1, ["name"] = "darkage:stone_brick"}, {["x"] = 4, ["meta"] = {["fields"] = {}, ["inventory"] = {}}, ["y"] = 1, ["param1"] = 13, ["z"] = 2, ["name"] = "darkage:stone_brick"}, {["x"] = 4, ["meta"] = {["fields"] = {}, ["inventory"] = {}}, ["y"] = 1, ["param1"] = 13, ["z"] = 3, ["name"] = "darkage:stone_brick"}, {["x"] = 4, ["meta"] = {["fields"] = {}, ["inventory"] = {}}, ["y"] = 1, ["param1"] = 13, ["z"] = 4, ["name"] = "darkage:stone_brick"}, {["x"] = 4, ["meta"] = {["fields"] = {}, ["inventory"] = {}}, ["y"] = 1, ["z"] = 5, ["name"] = "darkage:stone_brick"}, {["x"] = 4, ["meta"] = {["fields"] = {}, ["inventory"] = {}}, ["y"] = 2, ["param1"] = 13, ["z"] = 0, ["name"] = "darkage:stone_brick"}, {["x"] = 4, ["meta"] = {["fields"] = {}, ["inventory"] = {}}, ["y"] = 2, ["param1"] = 13, ["z"] = 1, ["name"] = "darkage:stone_brick"}, {["x"] = 4, ["meta"] = {["fields"] = {}, ["inventory"] = {}}, ["y"] = 2, ["param1"] = 13, ["z"] = 2, ["name"] = "darkage:stone_brick"}, {["x"] = 4, ["meta"] = {["fields"] = {}, ["inventory"] = {}}, ["y"] = 2, ["param1"] = 13, ["z"] = 3, ["name"] = "darkage:stone_brick"}, {["x"] = 4, ["meta"] = {["fields"] = {}, ["inventory"] = {}}, ["y"] = 2, ["param1"] = 13, ["z"] = 4, ["name"] = "darkage:stone_brick"}, {["x"] = 4, ["meta"] = {["fields"] = {}, ["inventory"] = {}}, ["y"] = 2, ["param1"] = 15, ["z"] = 5, ["name"] = "darkage:stone_brick"}, {["x"] = 4, ["meta"] = {["fields"] = {}, ["inventory"] = {}}, ["y"] = 2, ["z"] = 6, ["name"] = "darkage:stone_brick"}, {["x"] = 4, ["meta"] = {["fields"] = {}, ["inventory"] = {}}, ["y"] = 3, ["z"] = 5, ["name"] = "default:steelblock"}, {["x"] = 4, ["meta"] = {["fields"] = {}, ["inventory"] = {}}, ["y"] = 3, ["param1"] = 27, ["z"] = 7, ["name"] = "darkage:stone_brick"}, {["x"] = 4, ["meta"] = {["fields"] = {}, ["inventory"] = {}}, ["y"] = 4, ["z"] = 5, ["name"] = "default:steelblock"}, {["x"] = 4, ["meta"] = {["fields"] = {}, ["inventory"] = {}}, ["y"] = 4, ["z"] = 6, ["name"] = "default:steelblock"}, {["x"] = 4, ["meta"] = {["fields"] = {}, ["inventory"] = {}}, ["y"] = 4, ["z"] = 7, ["name"] = "darkage:stone_brick"}, {["x"] = 4, ["meta"] = {["fields"] = {}, ["inventory"] = {}}, ["param2"] = 2, ["y"] = 5, ["z"] = 4, ["name"] = "homedecor:glowlight_quarter_white"}, {["x"] = 4, ["meta"] = {["fields"] = {}, ["inventory"] = {}}, ["y"] = 5, ["param1"] = 61, ["z"] = 7, ["name"] = "darkage:stone_brick"}, {["x"] = 4, ["meta"] = {["fields"] = {}, ["inventory"] = {}}, ["y"] = 6, ["param1"] = 15, ["z"] = 1, ["name"] = "darkage:stone_brick"}, {["x"] = 4, ["meta"] = {["fields"] = {}, ["inventory"] = {}}, ["y"] = 6, ["z"] = 2, ["name"] = "default:steelblock"}, {["x"] = 4, ["meta"] = {["fields"] = {}, ["inventory"] = {}}, ["y"] = 6, ["z"] = 3, ["name"] = "default:steelblock"}, {["x"] = 4, ["meta"] = {["fields"] = {}, ["inventory"] = {}}, ["param2"] = 2, ["y"] = 6, ["z"] = 4, ["name"] = "homedecor:glowlight_quarter_white"}, {["x"] = 4, ["meta"] = {["fields"] = {}, ["inventory"] = {}}, ["param2"] = 2, ["y"] = 6, ["param1"] = 171, ["z"] = 7, ["name"] = "castle:arrowslit_sandstone_cross"}, {["x"] = 4, ["meta"] = {["fields"] = {}, ["inventory"] = {}}, ["y"] = 7, ["param1"] = 15, ["z"] = 1, ["name"] = "darkage:stone_brick"}, {["x"] = 4, ["meta"] = {["fields"] = {}, ["inventory"] = {}}, ["param2"] = 2, ["y"] = 7, ["z"] = 4, ["name"] = "homedecor:glowlight_quarter_white"}, {["x"] = 4, ["meta"] = {["fields"] = {}, ["inventory"] = {}}, ["y"] = 7, ["param1"] = 31, ["z"] = 7, ["name"] = "darkage:stone_brick"}, {["x"] = 4, ["meta"] = {["fields"] = {}, ["inventory"] = {}}, ["param2"] = 2, ["y"] = 8, ["z"] = 4, ["name"] = "homedecor:glowlight_quarter_white"}, {["x"] = 4, ["meta"] = {["fields"] = {}, ["inventory"] = {}}, ["y"] = 8, ["z"] = 5, ["name"] = "default:steelblock"}, {["x"] = 4, ["meta"] = {["fields"] = {}, ["inventory"] = {}}, ["y"] = 8, ["z"] = 6, ["name"] = "default:steelblock"}, {["x"] = 4, ["meta"] = {["fields"] = {}, ["inventory"] = {}}, ["y"] = 8, ["param1"] = 15, ["z"] = 7, ["name"] = "darkage:stone_brick"}, {["x"] = 4, ["meta"] = {["fields"] = {}, ["inventory"] = {}}, ["y"] = 9, ["z"] = 0, ["name"] = "darkage:stone_brick"}, {["x"] = 4, ["meta"] = {["fields"] = {}, ["inventory"] = {}}, ["y"] = 9, ["z"] = 1, ["name"] = "darkage:stone_brick"}, {["x"] = 4, ["meta"] = {["fields"] = {}, ["inventory"] = {}}, ["param2"] = 2, ["y"] = 9, ["z"] = 4, ["name"] = "homedecor:glowlight_quarter_white"}, {["x"] = 4, ["meta"] = {["fields"] = {}, ["inventory"] = {}}, ["y"] = 9, ["param1"] = 15, ["z"] = 7, ["name"] = "darkage:stone_brick"}, {["x"] = 4, ["meta"] = {["fields"] = {}, ["inventory"] = {}}, ["y"] = 10, ["param1"] = 153, ["z"] = 1, ["name"] = "stairs:slab_nether_brick"}, {["x"] = 4, ["meta"] = {["fields"] = {}, ["inventory"] = {}}, ["y"] = 10, ["z"] = 2, ["name"] = "default:steelblock"}, {["x"] = 4, ["meta"] = {["fields"] = {}, ["inventory"] = {}}, ["y"] = 10, ["z"] = 3, ["name"] = "default:steelblock"}, {["x"] = 4, ["meta"] = {["fields"] = {}, ["inventory"] = {}}, ["param2"] = 2, ["y"] = 10, ["z"] = 4, ["name"] = "homedecor:glowlight_quarter_white"}, {["x"] = 4, ["meta"] = {["fields"] = {}, ["inventory"] = {}}, ["param2"] = 2, ["y"] = 10, ["param1"] = 171, ["z"] = 7, ["name"] = "castle:arrowslit_desertstonebrick_cross"}, {["x"] = 4, ["meta"] = {["fields"] = {}, ["inventory"] = {}}, ["param2"] = 2, ["y"] = 11, ["z"] = 4, ["name"] = "homedecor:glowlight_quarter_white"}, {["x"] = 4, ["meta"] = {["fields"] = {}, ["inventory"] = {}}, ["y"] = 11, ["param1"] = 15, ["z"] = 7, ["name"] = "darkage:stone_brick"}, {["x"] = 4, ["meta"] = {["fields"] = {}, ["inventory"] = {}}, ["param2"] = 2, ["y"] = 12, ["z"] = 4, ["name"] = "homedecor:glowlight_quarter_white"}, {["x"] = 4, ["meta"] = {["fields"] = {}, ["inventory"] = {}}, ["y"] = 12, ["z"] = 5, ["name"] = "default:steelblock"}, {["x"] = 4, ["meta"] = {["fields"] = {}, ["inventory"] = {}}, ["y"] = 12, ["z"] = 6, ["name"] = "default:steelblock"}, {["x"] = 4, ["meta"] = {["fields"] = {}, ["inventory"] = {}}, ["y"] = 12, ["param1"] = 15, ["z"] = 7, ["name"] = "darkage:stone_brick"}, {["x"] = 4, ["meta"] = {["fields"] = {}, ["inventory"] = {}}, ["y"] = 13, ["param1"] = 15, ["z"] = 1, ["name"] = "darkage:stone_brick"}, {["x"] = 4, ["meta"] = {["fields"] = {}, ["inventory"] = {}}, ["param2"] = 2, ["y"] = 13, ["z"] = 4, ["name"] = "homedecor:glowlight_quarter_white"}, {["x"] = 4, ["meta"] = {["fields"] = {}, ["inventory"] = {}}, ["y"] = 13, ["param1"] = 15, ["z"] = 7, ["name"] = "darkage:stone_brick"}, {["x"] = 4, ["meta"] = {["fields"] = {}, ["inventory"] = {}}, ["y"] = 14, ["param1"] = 15, ["z"] = 1, ["name"] = "darkage:stone_brick"}, {["x"] = 4, ["meta"] = {["fields"] = {}, ["inventory"] = {}}, ["y"] = 14, ["z"] = 2, ["name"] = "default:steelblock"}, {["x"] = 4, ["meta"] = {["fields"] = {}, ["inventory"] = {}}, ["y"] = 14, ["z"] = 3, ["name"] = "default:steelblock"}, {["x"] = 4, ["meta"] = {["fields"] = {}, ["inventory"] = {}}, ["param2"] = 2, ["y"] = 14, ["z"] = 4, ["name"] = "homedecor:glowlight_quarter_white"}, {["x"] = 4, ["meta"] = {["fields"] = {}, ["inventory"] = {}}, ["param2"] = 2, ["y"] = 14, ["param1"] = 171, ["z"] = 7, ["name"] = "castle:arrowslit_sandstone_cross"}, {["x"] = 4, ["meta"] = {["fields"] = {}, ["inventory"] = {}}, ["y"] = 15, ["param1"] = 15, ["z"] = 1, ["name"] = "darkage:stone_brick"}, {["x"] = 4, ["meta"] = {["fields"] = {}, ["inventory"] = {}}, ["param2"] = 2, ["y"] = 15, ["z"] = 4, ["name"] = "homedecor:glowlight_quarter_white"}, {["x"] = 4, ["meta"] = {["fields"] = {}, ["inventory"] = {}}, ["y"] = 15, ["param1"] = 15, ["z"] = 7, ["name"] = "darkage:stone_brick"}, {["x"] = 4, ["meta"] = {["fields"] = {}, ["inventory"] = {}}, ["y"] = 16, ["param1"] = 170, ["z"] = 1, ["name"] = "castle:arrowslit_sandstone_cross"}, {["x"] = 4, ["meta"] = {["fields"] = {}, ["inventory"] = {}}, ["param2"] = 2, ["y"] = 16, ["z"] = 4, ["name"] = "homedecor:glowlight_quarter_white"}, {["x"] = 4, ["meta"] = {["fields"] = {}, ["inventory"] = {}}, ["y"] = 16, ["z"] = 5, ["name"] = "default:steelblock"}, {["x"] = 4, ["meta"] = {["fields"] = {}, ["inventory"] = {}}, ["y"] = 16, ["z"] = 6, ["name"] = "default:steelblock"}, {["x"] = 4, ["meta"] = {["fields"] = {}, ["inventory"] = {}}, ["y"] = 16, ["param1"] = 15, ["z"] = 7, ["name"] = "darkage:stone_brick"}, {["x"] = 4, ["meta"] = {["fields"] = {}, ["inventory"] = {}}, ["y"] = 17, ["param1"] = 15, ["z"] = 1, ["name"] = "darkage:stone_brick"}, {["x"] = 4, ["meta"] = {["fields"] = {}, ["inventory"] = {}}, ["param2"] = 2, ["y"] = 17, ["z"] = 4, ["name"] = "homedecor:glowlight_quarter_white"}, {["x"] = 4, ["meta"] = {["fields"] = {}, ["inventory"] = {}}, ["y"] = 17, ["param1"] = 15, ["z"] = 7, ["name"] = "darkage:stone_brick"}, {["x"] = 4, ["meta"] = {["fields"] = {}, ["inventory"] = {}}, ["y"] = 18, ["param1"] = 15, ["z"] = 1, ["name"] = "darkage:stone_brick"}, {["x"] = 4, ["meta"] = {["fields"] = {}, ["inventory"] = {}}, ["y"] = 18, ["z"] = 2, ["name"] = "default:steelblock"}, {["x"] = 4, ["meta"] = {["fields"] = {}, ["inventory"] = {}}, ["y"] = 18, ["z"] = 3, ["name"] = "default:steelblock"}, {["x"] = 4, ["meta"] = {["fields"] = {}, ["inventory"] = {}}, ["param2"] = 2, ["y"] = 18, ["z"] = 4, ["name"] = "homedecor:glowlight_quarter_white"}, {["x"] = 4, ["meta"] = {["fields"] = {}, ["inventory"] = {}}, ["param2"] = 2, ["y"] = 18, ["param1"] = 171, ["z"] = 7, ["name"] = "castle:arrowslit_desertstonebrick_cross"}, {["x"] = 4, ["meta"] = {["fields"] = {}, ["inventory"] = {}}, ["y"] = 19, ["param1"] = 15, ["z"] = 1, ["name"] = "darkage:stone_brick"}, {["x"] = 4, ["meta"] = {["fields"] = {}, ["inventory"] = {}}, ["param2"] = 2, ["y"] = 19, ["z"] = 4, ["name"] = "homedecor:glowlight_quarter_white"}, {["x"] = 4, ["meta"] = {["fields"] = {}, ["inventory"] = {}}, ["y"] = 19, ["param1"] = 15, ["z"] = 7, ["name"] = "darkage:stone_brick"}, {["x"] = 4, ["meta"] = {["fields"] = {}, ["inventory"] = {}}, ["y"] = 20, ["param1"] = 170, ["z"] = 1, ["name"] = "castle:arrowslit_desertstonebrick_cross"}, {["x"] = 4, ["meta"] = {["fields"] = {}, ["inventory"] = {}}, ["param2"] = 2, ["y"] = 20, ["z"] = 4, ["name"] = "homedecor:glowlight_quarter_white"}, {["x"] = 4, ["meta"] = {["fields"] = {}, ["inventory"] = {}}, ["y"] = 20, ["z"] = 5, ["name"] = "default:steelblock"}, {["x"] = 4, ["meta"] = {["fields"] = {}, ["inventory"] = {}}, ["y"] = 20, ["z"] = 6, ["name"] = "default:steelblock"}, {["x"] = 4, ["meta"] = {["fields"] = {}, ["inventory"] = {}}, ["y"] = 20, ["param1"] = 15, ["z"] = 7, ["name"] = "darkage:stone_brick"}, {["x"] = 4, ["meta"] = {["fields"] = {}, ["inventory"] = {}}, ["y"] = 21, ["param1"] = 15, ["z"] = 1, ["name"] = "darkage:stone_brick"}, {["x"] = 4, ["meta"] = {["fields"] = {}, ["inventory"] = {}}, ["param2"] = 2, ["y"] = 21, ["z"] = 4, ["name"] = "homedecor:glowlight_quarter_white"}, {["x"] = 4, ["meta"] = {["fields"] = {}, ["inventory"] = {}}, ["y"] = 21, ["param1"] = 15, ["z"] = 7, ["name"] = "darkage:stone_brick"}, {["x"] = 4, ["meta"] = {["fields"] = {}, ["inventory"] = {}}, ["param2"] = 20, ["y"] = 22, ["z"] = 0, ["name"] = "homedecor:glowlight_quarter_white"}, {["x"] = 4, ["meta"] = {["fields"] = {}, ["inventory"] = {}}, ["y"] = 22, ["param1"] = 15, ["z"] = 1, ["name"] = "darkage:stone_brick"}, {["x"] = 4, ["meta"] = {["fields"] = {}, ["inventory"] = {}}, ["y"] = 22, ["z"] = 2, ["name"] = "default:steelblock"}, {["x"] = 4, ["meta"] = {["fields"] = {}, ["inventory"] = {}}, ["y"] = 22, ["z"] = 3, ["name"] = "default:steelblock"}, {["x"] = 4, ["meta"] = {["fields"] = {}, ["inventory"] = {}}, ["param2"] = 2, ["y"] = 22, ["z"] = 4, ["name"] = "homedecor:glowlight_quarter_white"}, {["x"] = 4, ["meta"] = {["fields"] = {}, ["inventory"] = {}}, ["param2"] = 2, ["y"] = 22, ["param1"] = 204, ["z"] = 7, ["name"] = "castle:arrowslit_sandstone_cross"}, {["x"] = 4, ["meta"] = {["fields"] = {}, ["inventory"] = {}}, ["param2"] = 22, ["y"] = 22, ["z"] = 8, ["name"] = "homedecor:glowlight_quarter_white"}, {["x"] = 4, ["meta"] = {["fields"] = {}, ["inventory"] = {}}, ["y"] = 23, ["z"] = 0, ["name"] = "darkage:stone_brick"}, {["x"] = 4, ["meta"] = {["fields"] = {}, ["inventory"] = {}}, ["y"] = 23, ["param1"] = 15, ["z"] = 1, ["name"] = "darkage:stone_brick"}, {["x"] = 4, ["meta"] = {["fields"] = {}, ["inventory"] = {}}, ["y"] = 23, ["z"] = 4, ["name"] = "default:steelblock"}, {["x"] = 4, ["meta"] = {["fields"] = {}, ["inventory"] = {}}, ["y"] = 23, ["param1"] = 15, ["z"] = 7, ["name"] = "darkage:stone_brick"}, {["x"] = 4, ["meta"] = {["fields"] = {}, ["inventory"] = {}}, ["y"] = 23, ["z"] = 8, ["name"] = "darkage:stone_brick"}, {["x"] = 4, ["meta"] = {["fields"] = {}, ["inventory"] = {}}, ["y"] = 24, ["param1"] = 15, ["z"] = 4, ["name"] = "default:meselamp"}, {["x"] = 4, ["meta"] = {["fields"] = {}, ["inventory"] = {}}, ["y"] = 24, ["z"] = 5, ["name"] = "default:steelblock"}, {["x"] = 4, ["meta"] = {["fields"] = {}, ["inventory"] = {}}, ["y"] = 24, ["z"] = 6, ["name"] = "default:steelblock"}, {["x"] = 4, ["meta"] = {["fields"] = {}, ["inventory"] = {}}, ["y"] = 25, ["param1"] = 15, ["z"] = 4, ["name"] = "default:meselamp"}, {["x"] = 4, ["meta"] = {["fields"] = {}, ["inventory"] = {}}, ["param2"] = 20, ["y"] = 26, ["z"] = 0, ["name"] = "homedecor:glowlight_quarter_white"}, {["x"] = 4, ["meta"] = {["fields"] = {}, ["inventory"] = {}}, ["y"] = 26, ["param1"] = 15, ["z"] = 4, ["name"] = "default:meselamp"}, {["x"] = 4, ["meta"] = {["fields"] = {}, ["inventory"] = {}}, ["param2"] = 22, ["y"] = 26, ["z"] = 8, ["name"] = "homedecor:glowlight_quarter_white"}, {["x"] = 4, ["meta"] = {["fields"] = {}, ["inventory"] = {}}, ["y"] = 27, ["param1"] = 205, ["z"] = 0, ["name"] = "stairs:slab_darkage_slate_cobble"}, {["x"] = 4, ["meta"] = {["fields"] = {}, ["inventory"] = {}}, ["y"] = 27, ["z"] = 1, ["name"] = "darkage:slate_cobble"}, {["x"] = 4, ["meta"] = {["fields"] = {}, ["inventory"] = {}}, ["y"] = 27, ["param1"] = 204, ["z"] = 2, ["name"] = "stairs:slab_darkage_slate_cobble"}, {["x"] = 4, ["meta"] = {["fields"] = {}, ["inventory"] = {}}, ["y"] = 27, ["param1"] = 15, ["z"] = 4, ["name"] = "default:meselamp"}, {["x"] = 4, ["meta"] = {["fields"] = {}, ["inventory"] = {}}, ["y"] = 27, ["param1"] = 204, ["z"] = 6, ["name"] = "stairs:slab_darkage_slate_cobble"}, {["x"] = 4, ["meta"] = {["fields"] = {}, ["inventory"] = {}}, ["y"] = 27, ["z"] = 7, ["name"] = "darkage:slate_cobble"}, {["x"] = 4, ["meta"] = {["fields"] = {}, ["inventory"] = {}}, ["y"] = 27, ["param1"] = 205, ["z"] = 8, ["name"] = "stairs:slab_darkage_slate_cobble"}, {["x"] = 4, ["meta"] = {["fields"] = {}, ["inventory"] = {}}, ["y"] = 28, ["param1"] = 189, ["z"] = 2, ["name"] = "stairs:slab_darkage_slate_cobble"}, {["x"] = 4, ["meta"] = {["fields"] = {}, ["inventory"] = {}}, ["y"] = 28, ["z"] = 3, ["name"] = "darkage:slate_cobble"}, {["x"] = 4, ["meta"] = {["fields"] = {}, ["inventory"] = {}}, ["y"] = 28, ["param1"] = 15, ["z"] = 4, ["name"] = "default:meselamp"}, {["x"] = 4, ["meta"] = {["fields"] = {}, ["inventory"] = {}}, ["y"] = 28, ["z"] = 5, ["name"] = "darkage:slate_cobble"}, {["x"] = 4, ["meta"] = {["fields"] = {}, ["inventory"] = {}}, ["y"] = 28, ["param1"] = 189, ["z"] = 6, ["name"] = "stairs:slab_darkage_slate_cobble"}, {["x"] = 4, ["meta"] = {["fields"] = {}, ["inventory"] = {}}, ["y"] = 29, ["param1"] = 15, ["z"] = 4, ["name"] = "default:meselamp"}, {["x"] = 5, ["meta"] = {["fields"] = {}, ["inventory"] = {}}, ["y"] = 0, ["z"] = 4, ["name"] = "darkage:stone_brick"}, {["x"] = 5, ["meta"] = {["fields"] = {}, ["inventory"] = {}}, ["y"] = 1, ["z"] = 4, ["name"] = "darkage:stone_brick"}, {["x"] = 5, ["meta"] = {["fields"] = {}, ["inventory"] = {}}, ["param2"] = 3, ["y"] = 2, ["z"] = 1, ["name"] = "default:torch"}, {["x"] = 5, ["meta"] = {["fields"] = {}, ["inventory"] = {}}, ["param2"] = 3, ["y"] = 2, ["z"] = 2, ["name"] = "default:torch"}, {["x"] = 5, ["meta"] = {["fields"] = {}, ["inventory"] = {}}, ["y"] = 2, ["param1"] = 13, ["z"] = 4, ["name"] = "darkage:stone_brick"}, {["x"] = 5, ["meta"] = {["fields"] = {}, ["inventory"] = {}}, ["y"] = 2, ["param1"] = 15, ["z"] = 5, ["name"] = "darkage:stone_brick"}, {["x"] = 5, ["meta"] = {["fields"] = {}, ["inventory"] = {}}, ["y"] = 2, ["z"] = 6, ["name"] = "darkage:stone_brick"}, {["x"] = 5, ["meta"] = {["fields"] = {}, ["inventory"] = {}}, ["y"] = 3, ["z"] = 0, ["name"] = "default:dirt"}, {["x"] = 5, ["meta"] = {["fields"] = {}, ["inventory"] = {}}, ["y"] = 3, ["z"] = 1, ["name"] = "darkage:stone_brick"}, {["x"] = 5, ["meta"] = {["fields"] = {}, ["inventory"] = {}}, ["y"] = 3, ["z"] = 2, ["name"] = "darkage:stone_brick"}, {["x"] = 5, ["meta"] = {["fields"] = {}, ["inventory"] = {}}, ["y"] = 3, ["z"] = 3, ["name"] = "darkage:stone_brick"}, {["x"] = 5, ["meta"] = {["fields"] = {}, ["inventory"] = {}}, ["y"] = 3, ["z"] = 5, ["name"] = "default:steelblock"}, {["x"] = 5, ["meta"] = {["fields"] = {}, ["inventory"] = {}}, ["y"] = 3, ["z"] = 6, ["name"] = "default:steelblock"}, {["x"] = 5, ["meta"] = {["fields"] = {}, ["inventory"] = {}}, ["y"] = 3, ["param1"] = 27, ["z"] = 7, ["name"] = "darkage:stone_brick"}, {["x"] = 5, ["meta"] = {["fields"] = {}, ["inventory"] = {}}, ["y"] = 4, ["param1"] = 15, ["z"] = 0, ["name"] = "default:dirt_with_grass"}, {["x"] = 5, ["meta"] = {["fields"] = {}, ["inventory"] = {}}, ["y"] = 4, ["param1"] = 15, ["z"] = 1, ["name"] = "darkage:stone_brick"}, {["x"] = 5, ["meta"] = {["fields"] = {}, ["inventory"] = {}}, ["y"] = 4, ["z"] = 2, ["name"] = "default:steelblock"}, {["x"] = 5, ["meta"] = {["fields"] = {}, ["inventory"] = {}}, ["param2"] = 2, ["y"] = 4, ["z"] = 3, ["name"] = "fake_fire:fancy_fire"}, {["x"] = 5, ["meta"] = {["fields"] = {}, ["inventory"] = {}}, ["y"] = 4, ["z"] = 5, ["name"] = "default:steelblock"}, {["x"] = 5, ["meta"] = {["fields"] = {}, ["inventory"] = {}}, ["y"] = 4, ["z"] = 6, ["name"] = "default:steelblock"}, {["x"] = 5, ["meta"] = {["fields"] = {}, ["inventory"] = {}}, ["y"] = 4, ["param1"] = 44, ["z"] = 7, ["name"] = "darkage:stone_brick"}, {["x"] = 5, ["meta"] = {["fields"] = {}, ["inventory"] = {}}, ["y"] = 5, ["param1"] = 13, ["z"] = 1, ["name"] = "darkage:stone_brick"}, {["x"] = 5, ["meta"] = {["fields"] = {}, ["inventory"] = {}}, ["y"] = 5, ["z"] = 2, ["name"] = "default:steelblock"}, {["x"] = 5, ["meta"] = {["fields"] = {}, ["inventory"] = {}}, ["y"] = 5, ["z"] = 3, ["name"] = "default:steelblock"}, {["x"] = 5, ["meta"] = {["fields"] = {}, ["inventory"] = {}}, ["y"] = 5, ["z"] = 4, ["name"] = "default:steelblock"}, {["x"] = 5, ["meta"] = {["fields"] = {}, ["inventory"] = {}}, ["y"] = 5, ["param1"] = 187, ["z"] = 5, ["name"] = "stairs:slab_steelblock"}, {["x"] = 5, ["meta"] = {["fields"] = {}, ["inventory"] = {}}, ["y"] = 5, ["param1"] = 170, ["z"] = 6, ["name"] = "stairs:slab_steelblock"}, {["x"] = 5, ["meta"] = {["fields"] = {}, ["inventory"] = {}}, ["y"] = 5, ["param1"] = 61, ["z"] = 7, ["name"] = "darkage:stone_brick"}, {["x"] = 5, ["meta"] = {["fields"] = {}, ["inventory"] = {}}, ["y"] = 6, ["param1"] = 15, ["z"] = 1, ["name"] = "darkage:stone_brick"}, {["x"] = 5, ["meta"] = {["fields"] = {}, ["inventory"] = {}}, ["y"] = 6, ["param1"] = 170, ["z"] = 2, ["name"] = "stairs:slab_steelblock"}, {["x"] = 5, ["meta"] = {["fields"] = {}, ["inventory"] = {}}, ["y"] = 6, ["param1"] = 187, ["z"] = 3, ["name"] = "stairs:slab_steelblock"}, {["x"] = 5, ["meta"] = {["fields"] = {}, ["inventory"] = {}}, ["y"] = 6, ["param1"] = 47, ["z"] = 7, ["name"] = "darkage:stone_brick"}, {["x"] = 5, ["meta"] = {["fields"] = {}, ["inventory"] = {}}, ["y"] = 7, ["param1"] = 15, ["z"] = 1, ["name"] = "darkage:stone_brick"}, {["x"] = 5, ["meta"] = {["fields"] = {}, ["inventory"] = {}}, ["y"] = 7, ["param1"] = 31, ["z"] = 7, ["name"] = "darkage:stone_brick"}, {["x"] = 5, ["meta"] = {["fields"] = {}, ["inventory"] = {}}, ["y"] = 8, ["param1"] = 15, ["z"] = 1, ["name"] = "darkage:stone_brick"}, {["x"] = 5, ["meta"] = {["fields"] = {}, ["inventory"] = {}}, ["y"] = 8, ["param1"] = 15, ["z"] = 7, ["name"] = "darkage:stone_brick"}, {["x"] = 5, ["meta"] = {["fields"] = {}, ["inventory"] = {}}, ["y"] = 9, ["param1"] = 15, ["z"] = 1, ["name"] = "darkage:stone_brick"}, {["x"] = 5, ["meta"] = {["fields"] = {}, ["inventory"] = {}}, ["y"] = 9, ["z"] = 4, ["name"] = "default:steelblock"}, {["x"] = 5, ["meta"] = {["fields"] = {}, ["inventory"] = {}}, ["y"] = 9, ["param1"] = 187, ["z"] = 5, ["name"] = "stairs:slab_steelblock"}, {["x"] = 5, ["meta"] = {["fields"] = {}, ["inventory"] = {}}, ["y"] = 9, ["param1"] = 170, ["z"] = 6, ["name"] = "stairs:slab_steelblock"}, {["x"] = 5, ["meta"] = {["fields"] = {}, ["inventory"] = {}}, ["y"] = 9, ["param1"] = 15, ["z"] = 7, ["name"] = "darkage:stone_brick"}, {["x"] = 5, ["meta"] = {["fields"] = {}, ["inventory"] = {}}, ["param2"] = 1, ["y"] = 10, ["param1"] = 123, ["z"] = 0, ["name"] = "castle:arrowslit_stonebrick_cross"}, {["x"] = 5, ["meta"] = {["fields"] = {}, ["inventory"] = {}}, ["y"] = 10, ["z"] = 1, ["name"] = "darkage:stone_brick"}, {["x"] = 5, ["meta"] = {["fields"] = {}, ["inventory"] = {}}, ["y"] = 10, ["param1"] = 170, ["z"] = 2, ["name"] = "stairs:slab_steelblock"}, {["x"] = 5, ["meta"] = {["fields"] = {}, ["inventory"] = {}}, ["y"] = 10, ["param1"] = 187, ["z"] = 3, ["name"] = "stairs:slab_steelblock"}, {["x"] = 5, ["meta"] = {["fields"] = {}, ["inventory"] = {}}, ["y"] = 10, ["param1"] = 15, ["z"] = 7, ["name"] = "darkage:stone_brick"}, {["x"] = 5, ["meta"] = {["fields"] = {}, ["inventory"] = {}}, ["y"] = 11, ["param1"] = 15, ["z"] = 1, ["name"] = "darkage:stone_brick"}, {["x"] = 5, ["meta"] = {["fields"] = {}, ["inventory"] = {}}, ["y"] = 11, ["param1"] = 15, ["z"] = 7, ["name"] = "darkage:stone_brick"}, {["x"] = 5, ["meta"] = {["fields"] = {}, ["inventory"] = {}}, ["y"] = 12, ["param1"] = 15, ["z"] = 1, ["name"] = "darkage:stone_brick"}, {["x"] = 5, ["meta"] = {["fields"] = {}, ["inventory"] = {}}, ["y"] = 12, ["param1"] = 15, ["z"] = 7, ["name"] = "darkage:stone_brick"}, {["x"] = 5, ["meta"] = {["fields"] = {}, ["inventory"] = {}}, ["y"] = 13, ["param1"] = 15, ["z"] = 1, ["name"] = "darkage:stone_brick"}, {["x"] = 5, ["meta"] = {["fields"] = {}, ["inventory"] = {}}, ["y"] = 13, ["z"] = 4, ["name"] = "default:steelblock"}, {["x"] = 5, ["meta"] = {["fields"] = {}, ["inventory"] = {}}, ["y"] = 13, ["param1"] = 187, ["z"] = 5, ["name"] = "stairs:slab_steelblock"}, {["x"] = 5, ["meta"] = {["fields"] = {}, ["inventory"] = {}}, ["y"] = 13, ["param1"] = 170, ["z"] = 6, ["name"] = "stairs:slab_steelblock"}, {["x"] = 5, ["meta"] = {["fields"] = {}, ["inventory"] = {}}, ["y"] = 13, ["param1"] = 15, ["z"] = 7, ["name"] = "darkage:stone_brick"}, {["x"] = 5, ["meta"] = {["fields"] = {}, ["inventory"] = {}}, ["y"] = 14, ["param1"] = 15, ["z"] = 1, ["name"] = "darkage:stone_brick"}, {["x"] = 5, ["meta"] = {["fields"] = {}, ["inventory"] = {}}, ["y"] = 14, ["param1"] = 170, ["z"] = 2, ["name"] = "stairs:slab_steelblock"}, {["x"] = 5, ["meta"] = {["fields"] = {}, ["inventory"] = {}}, ["y"] = 14, ["param1"] = 187, ["z"] = 3, ["name"] = "stairs:slab_steelblock"}, {["x"] = 5, ["meta"] = {["fields"] = {}, ["inventory"] = {}}, ["y"] = 14, ["param1"] = 15, ["z"] = 7, ["name"] = "darkage:stone_brick"}, {["x"] = 5, ["meta"] = {["fields"] = {}, ["inventory"] = {}}, ["y"] = 15, ["param1"] = 15, ["z"] = 1, ["name"] = "darkage:stone_brick"}, {["x"] = 5, ["meta"] = {["fields"] = {}, ["inventory"] = {}}, ["y"] = 15, ["param1"] = 15, ["z"] = 7, ["name"] = "darkage:stone_brick"}, {["x"] = 5, ["meta"] = {["fields"] = {}, ["inventory"] = {}}, ["y"] = 16, ["param1"] = 15, ["z"] = 1, ["name"] = "darkage:stone_brick"}, {["x"] = 5, ["meta"] = {["fields"] = {}, ["inventory"] = {}}, ["y"] = 16, ["param1"] = 15, ["z"] = 7, ["name"] = "darkage:stone_brick"}, {["x"] = 5, ["meta"] = {["fields"] = {}, ["inventory"] = {}}, ["y"] = 17, ["param1"] = 15, ["z"] = 1, ["name"] = "darkage:stone_brick"}, {["x"] = 5, ["meta"] = {["fields"] = {}, ["inventory"] = {}}, ["y"] = 17, ["z"] = 4, ["name"] = "default:steelblock"}, {["x"] = 5, ["meta"] = {["fields"] = {}, ["inventory"] = {}}, ["y"] = 17, ["param1"] = 187, ["z"] = 5, ["name"] = "stairs:slab_steelblock"}, {["x"] = 5, ["meta"] = {["fields"] = {}, ["inventory"] = {}}, ["y"] = 17, ["param1"] = 170, ["z"] = 6, ["name"] = "stairs:slab_steelblock"}, {["x"] = 5, ["meta"] = {["fields"] = {}, ["inventory"] = {}}, ["y"] = 17, ["param1"] = 15, ["z"] = 7, ["name"] = "darkage:stone_brick"}, {["x"] = 5, ["meta"] = {["fields"] = {}, ["inventory"] = {}}, ["y"] = 18, ["param1"] = 15, ["z"] = 1, ["name"] = "darkage:stone_brick"}, {["x"] = 5, ["meta"] = {["fields"] = {}, ["inventory"] = {}}, ["y"] = 18, ["param1"] = 170, ["z"] = 2, ["name"] = "stairs:slab_steelblock"}, {["x"] = 5, ["meta"] = {["fields"] = {}, ["inventory"] = {}}, ["y"] = 18, ["param1"] = 187, ["z"] = 3, ["name"] = "stairs:slab_steelblock"}, {["x"] = 5, ["meta"] = {["fields"] = {}, ["inventory"] = {}}, ["y"] = 18, ["param1"] = 15, ["z"] = 7, ["name"] = "darkage:stone_brick"}, {["x"] = 5, ["meta"] = {["fields"] = {}, ["inventory"] = {}}, ["y"] = 19, ["param1"] = 15, ["z"] = 1, ["name"] = "darkage:stone_brick"}, {["x"] = 5, ["meta"] = {["fields"] = {}, ["inventory"] = {}}, ["y"] = 19, ["param1"] = 15, ["z"] = 7, ["name"] = "darkage:stone_brick"}, {["x"] = 5, ["meta"] = {["fields"] = {}, ["inventory"] = {}}, ["y"] = 20, ["param1"] = 15, ["z"] = 1, ["name"] = "darkage:stone_brick"}, {["x"] = 5, ["meta"] = {["fields"] = {}, ["inventory"] = {}}, ["y"] = 20, ["param1"] = 15, ["z"] = 7, ["name"] = "darkage:stone_brick"}, {["x"] = 5, ["meta"] = {["fields"] = {}, ["inventory"] = {}}, ["y"] = 21, ["param1"] = 15, ["z"] = 1, ["name"] = "darkage:stone_brick"}, {["x"] = 5, ["meta"] = {["fields"] = {}, ["inventory"] = {}}, ["y"] = 21, ["z"] = 4, ["name"] = "default:steelblock"}, {["x"] = 5, ["meta"] = {["fields"] = {}, ["inventory"] = {}}, ["y"] = 21, ["param1"] = 187, ["z"] = 5, ["name"] = "stairs:slab_steelblock"}, {["x"] = 5, ["meta"] = {["fields"] = {}, ["inventory"] = {}}, ["y"] = 21, ["param1"] = 170, ["z"] = 6, ["name"] = "stairs:slab_steelblock"}, {["x"] = 5, ["meta"] = {["fields"] = {}, ["inventory"] = {}}, ["y"] = 21, ["param1"] = 15, ["z"] = 7, ["name"] = "darkage:stone_brick"}, {["x"] = 5, ["meta"] = {["fields"] = {}, ["inventory"] = {}}, ["param2"] = 20, ["y"] = 22, ["z"] = 0, ["name"] = "homedecor:glowlight_quarter_white"}, {["x"] = 5, ["meta"] = {["fields"] = {}, ["inventory"] = {}}, ["y"] = 22, ["param1"] = 15, ["z"] = 1, ["name"] = "darkage:stone_brick"}, {["x"] = 5, ["meta"] = {["fields"] = {}, ["inventory"] = {}}, ["y"] = 22, ["param1"] = 170, ["z"] = 2, ["name"] = "stairs:slab_steelblock"}, {["x"] = 5, ["meta"] = {["fields"] = {}, ["inventory"] = {}}, ["y"] = 22, ["param1"] = 187, ["z"] = 3, ["name"] = "stairs:slab_steelblock"}, {["x"] = 5, ["meta"] = {["fields"] = {}, ["inventory"] = {}}, ["y"] = 22, ["param1"] = 15, ["z"] = 7, ["name"] = "darkage:stone_brick"}, {["x"] = 5, ["meta"] = {["fields"] = {}, ["inventory"] = {}}, ["param2"] = 22, ["y"] = 22, ["z"] = 8, ["name"] = "homedecor:glowlight_quarter_white"}, {["x"] = 5, ["meta"] = {["fields"] = {}, ["inventory"] = {}}, ["y"] = 23, ["z"] = 0, ["name"] = "darkage:stone_brick"}, {["x"] = 5, ["meta"] = {["fields"] = {}, ["inventory"] = {}}, ["y"] = 23, ["param1"] = 15, ["z"] = 1, ["name"] = "darkage:stone_brick"}, {["x"] = 5, ["meta"] = {["fields"] = {}, ["inventory"] = {}}, ["y"] = 23, ["param1"] = 15, ["z"] = 7, ["name"] = "darkage:stone_brick"}, {["x"] = 5, ["meta"] = {["fields"] = {}, ["inventory"] = {}}, ["y"] = 23, ["z"] = 8, ["name"] = "darkage:stone_brick"}, {["x"] = 5, ["meta"] = {["fields"] = {}, ["inventory"] = {}}, ["param2"] = 2, ["y"] = 24, ["param1"] = 172, ["z"] = 1, ["name"] = "castle:pillars_stonebrick_bottom"}, {["x"] = 5, ["meta"] = {["fields"] = {}, ["inventory"] = {}}, ["param2"] = 3, ["y"] = 24, ["param1"] = 172, ["z"] = 7, ["name"] = "castle:pillars_stonebrick_bottom"}, {["x"] = 5, ["meta"] = {["fields"] = {}, ["inventory"] = {}}, ["param2"] = 2, ["y"] = 25, ["param1"] = 188, ["z"] = 1, ["name"] = "castle:pillars_stonebrick_middle"}, {["x"] = 5, ["meta"] = {["fields"] = {}, ["inventory"] = {}}, ["param2"] = 3, ["y"] = 25, ["param1"] = 188, ["z"] = 7, ["name"] = "castle:pillars_stonebrick_middle"}, {["x"] = 5, ["meta"] = {["fields"] = {}, ["inventory"] = {}}, ["param2"] = 20, ["y"] = 26, ["z"] = 0, ["name"] = "homedecor:glowlight_quarter_white"}, {["x"] = 5, ["meta"] = {["fields"] = {}, ["inventory"] = {}}, ["param2"] = 2, ["y"] = 26, ["param1"] = 204, ["z"] = 1, ["name"] = "castle:pillars_stonebrick_top"}, {["x"] = 5, ["meta"] = {["fields"] = {}, ["inventory"] = {}}, ["param2"] = 3, ["y"] = 26, ["param1"] = 204, ["z"] = 7, ["name"] = "castle:pillars_stonebrick_top"}, {["x"] = 5, ["meta"] = {["fields"] = {}, ["inventory"] = {}}, ["param2"] = 22, ["y"] = 26, ["z"] = 8, ["name"] = "homedecor:glowlight_quarter_white"}, {["x"] = 5, ["meta"] = {["fields"] = {}, ["inventory"] = {}}, ["y"] = 27, ["param1"] = 205, ["z"] = 0, ["name"] = "stairs:slab_darkage_slate_cobble"}, {["x"] = 5, ["meta"] = {["fields"] = {}, ["inventory"] = {}}, ["y"] = 27, ["z"] = 1, ["name"] = "darkage:slate_cobble"}, {["x"] = 5, ["meta"] = {["fields"] = {}, ["inventory"] = {}}, ["y"] = 27, ["param1"] = 188, ["z"] = 2, ["name"] = "stairs:slab_darkage_slate_cobble"}, {["x"] = 5, ["meta"] = {["fields"] = {}, ["inventory"] = {}}, ["y"] = 27, ["param1"] = 188, ["z"] = 6, ["name"] = "stairs:slab_darkage_slate_cobble"}, {["x"] = 5, ["meta"] = {["fields"] = {}, ["inventory"] = {}}, ["y"] = 27, ["z"] = 7, ["name"] = "darkage:slate_cobble"}, {["x"] = 5, ["meta"] = {["fields"] = {}, ["inventory"] = {}}, ["y"] = 27, ["param1"] = 205, ["z"] = 8, ["name"] = "stairs:slab_darkage_slate_cobble"}, {["x"] = 5, ["meta"] = {["fields"] = {}, ["inventory"] = {}}, ["y"] = 28, ["param1"] = 173, ["z"] = 2, ["name"] = "stairs:slab_darkage_slate_cobble"}, {["x"] = 5, ["meta"] = {["fields"] = {}, ["inventory"] = {}}, ["y"] = 28, ["z"] = 3, ["name"] = "darkage:slate_cobble"}, {["x"] = 5, ["meta"] = {["fields"] = {}, ["inventory"] = {}}, ["y"] = 28, ["z"] = 4, ["name"] = "darkage:slate_cobble"}, {["x"] = 5, ["meta"] = {["fields"] = {}, ["inventory"] = {}}, ["y"] = 28, ["z"] = 5, ["name"] = "darkage:slate_cobble"}, {["x"] = 5, ["meta"] = {["fields"] = {}, ["inventory"] = {}}, ["y"] = 28, ["param1"] = 173, ["z"] = 6, ["name"] = "stairs:slab_darkage_slate_cobble"}, {["x"] = 6, ["meta"] = {["fields"] = {}, ["inventory"] = {}}, ["y"] = 0, ["param1"] = 13, ["z"] = 4, ["name"] = "darkage:stone_brick"}, {["x"] = 6, ["meta"] = {["fields"] = {}, ["inventory"] = {}}, ["y"] = 1, ["param1"] = 13, ["z"] = 4, ["name"] = "darkage:stone_brick"}, {["x"] = 6, ["meta"] = {["fields"] = {}, ["inventory"] = {}}, ["param2"] = 4, ["y"] = 2, ["z"] = 3, ["name"] = "default:torch"}, {["x"] = 6, ["meta"] = {["fields"] = {}, ["inventory"] = {}}, ["y"] = 2, ["param1"] = 13, ["z"] = 4, ["name"] = "darkage:stone_brick"}, {["x"] = 6, ["meta"] = {["fields"] = {}, ["inventory"] = {}}, ["y"] = 2, ["param1"] = 15, ["z"] = 5, ["name"] = "darkage:stone_brick"}, {["x"] = 6, ["meta"] = {["fields"] = {}, ["inventory"] = {}}, ["y"] = 3, ["z"] = 0, ["name"] = "default:dirt"}, {["x"] = 6, ["meta"] = {["fields"] = {}, ["inventory"] = {}}, ["y"] = 3, ["z"] = 1, ["name"] = "default:dirt"}, {["x"] = 6, ["meta"] = {["fields"] = {}, ["inventory"] = {}}, ["y"] = 3, ["z"] = 2, ["name"] = "darkage:stone_brick"}, {["x"] = 6, ["meta"] = {["fields"] = {}, ["inventory"] = {}}, ["y"] = 3, ["z"] = 3, ["name"] = "darkage:stone_brick"}, {["x"] = 6, ["meta"] = {["fields"] = {}, ["inventory"] = {}}, ["y"] = 3, ["z"] = 5, ["name"] = "default:steelblock"}, {["x"] = 6, ["meta"] = {["fields"] = {}, ["inventory"] = {}}, ["y"] = 3, ["param1"] = 11, ["z"] = 6, ["name"] = "darkage:stone_brick"}, {["x"] = 6, ["meta"] = {["fields"] = {}, ["inventory"] = {}}, ["y"] = 4, ["z"] = 0, ["name"] = "default:dirt"}, {["x"] = 6, ["meta"] = {["fields"] = {}, ["inventory"] = {}}, ["y"] = 4, ["z"] = 1, ["name"] = "default:dirt"}, {["x"] = 6, ["meta"] = {["fields"] = {}, ["inventory"] = {}}, ["y"] = 4, ["z"] = 2, ["name"] = "darkage:stone_brick"}, {["x"] = 6, ["meta"] = {["fields"] = {}, ["inventory"] = {}}, ["y"] = 4, ["z"] = 3, ["name"] = "default:steelblock"}, {["x"] = 6, ["meta"] = {["fields"] = {}, ["inventory"] = {}}, ["y"] = 4, ["z"] = 5, ["name"] = "default:steelblock"}, {["x"] = 6, ["meta"] = {["fields"] = {}, ["inventory"] = {}}, ["y"] = 4, ["param1"] = 28, ["z"] = 6, ["name"] = "darkage:stone_brick"}, {["x"] = 6, ["meta"] = {["fields"] = {}, ["inventory"] = {}}, ["y"] = 5, ["param1"] = 15, ["z"] = 0, ["name"] = "default:dirt_with_grass"}, {["x"] = 6, ["meta"] = {["fields"] = {}, ["inventory"] = {}}, ["y"] = 5, ["param1"] = 15, ["z"] = 1, ["name"] = "default:dirt_with_grass"}, {["x"] = 6, ["meta"] = {["fields"] = {}, ["inventory"] = {}}, ["y"] = 5, ["param1"] = 15, ["z"] = 2, ["name"] = "darkage:stone_brick"}, {["x"] = 6, ["meta"] = {["fields"] = {}, ["inventory"] = {}}, ["y"] = 5, ["z"] = 3, ["name"] = "default:steelblock"}, {["x"] = 6, ["meta"] = {["fields"] = {}, ["inventory"] = {}}, ["y"] = 5, ["z"] = 4, ["name"] = "default:steelblock"}, {["x"] = 6, ["meta"] = {["fields"] = {}, ["inventory"] = {}}, ["y"] = 5, ["param1"] = 170, ["z"] = 5, ["name"] = "stairs:slab_steelblock"}, {["x"] = 6, ["meta"] = {["fields"] = {}, ["inventory"] = {}}, ["y"] = 5, ["param1"] = 45, ["z"] = 6, ["name"] = "darkage:stone_brick"}, {["x"] = 6, ["meta"] = {["fields"] = {}, ["inventory"] = {}}, ["y"] = 6, ["param1"] = 15, ["z"] = 2, ["name"] = "darkage:stone_brick"}, {["x"] = 6, ["meta"] = {["fields"] = {}, ["inventory"] = {}}, ["y"] = 6, ["param1"] = 170, ["z"] = 3, ["name"] = "stairs:slab_steelblock"}, {["x"] = 6, ["meta"] = {["fields"] = {}, ["inventory"] = {}}, ["y"] = 6, ["param1"] = 31, ["z"] = 6, ["name"] = "darkage:stone_brick"}, {["x"] = 6, ["meta"] = {["fields"] = {}, ["inventory"] = {}}, ["y"] = 7, ["param1"] = 15, ["z"] = 2, ["name"] = "darkage:stone_brick"}, {["x"] = 6, ["meta"] = {["fields"] = {}, ["inventory"] = {}}, ["y"] = 7, ["param1"] = 15, ["z"] = 6, ["name"] = "darkage:stone_brick"}, {["x"] = 6, ["meta"] = {["fields"] = {}, ["inventory"] = {}}, ["y"] = 8, ["param1"] = 15, ["z"] = 2, ["name"] = "darkage:stone_brick"}, {["x"] = 6, ["meta"] = {["fields"] = {}, ["inventory"] = {}}, ["y"] = 8, ["param1"] = 15, ["z"] = 6, ["name"] = "darkage:stone_brick"}, {["x"] = 6, ["meta"] = {["fields"] = {}, ["inventory"] = {}}, ["y"] = 9, ["param1"] = 15, ["z"] = 2, ["name"] = "darkage:stone_brick"}, {["x"] = 6, ["meta"] = {["fields"] = {}, ["inventory"] = {}}, ["y"] = 9, ["z"] = 4, ["name"] = "default:steelblock"}, {["x"] = 6, ["meta"] = {["fields"] = {}, ["inventory"] = {}}, ["y"] = 9, ["param1"] = 170, ["z"] = 5, ["name"] = "stairs:slab_steelblock"}, {["x"] = 6, ["meta"] = {["fields"] = {}, ["inventory"] = {}}, ["y"] = 9, ["param1"] = 15, ["z"] = 6, ["name"] = "darkage:stone_brick"}, {["x"] = 6, ["meta"] = {["fields"] = {}, ["inventory"] = {}}, ["y"] = 10, ["param1"] = 15, ["z"] = 2, ["name"] = "darkage:stone_brick"}, {["x"] = 6, ["meta"] = {["fields"] = {}, ["inventory"] = {}}, ["y"] = 10, ["param1"] = 170, ["z"] = 3, ["name"] = "stairs:slab_steelblock"}, {["x"] = 6, ["meta"] = {["fields"] = {}, ["inventory"] = {}}, ["y"] = 10, ["param1"] = 15, ["z"] = 6, ["name"] = "darkage:stone_brick"}, {["x"] = 6, ["meta"] = {["fields"] = {}, ["inventory"] = {}}, ["y"] = 11, ["param1"] = 15, ["z"] = 2, ["name"] = "darkage:stone_brick"}, {["x"] = 6, ["meta"] = {["fields"] = {}, ["inventory"] = {}}, ["y"] = 11, ["param1"] = 15, ["z"] = 6, ["name"] = "darkage:stone_brick"}, {["x"] = 6, ["meta"] = {["fields"] = {}, ["inventory"] = {}}, ["y"] = 12, ["param1"] = 15, ["z"] = 2, ["name"] = "darkage:stone_brick"}, {["x"] = 6, ["meta"] = {["fields"] = {}, ["inventory"] = {}}, ["y"] = 12, ["param1"] = 15, ["z"] = 6, ["name"] = "darkage:stone_brick"}, {["x"] = 6, ["meta"] = {["fields"] = {}, ["inventory"] = {}}, ["y"] = 13, ["param1"] = 15, ["z"] = 2, ["name"] = "darkage:stone_brick"}, {["x"] = 6, ["meta"] = {["fields"] = {}, ["inventory"] = {}}, ["y"] = 13, ["z"] = 4, ["name"] = "default:steelblock"}, {["x"] = 6, ["meta"] = {["fields"] = {}, ["inventory"] = {}}, ["y"] = 13, ["param1"] = 170, ["z"] = 5, ["name"] = "stairs:slab_steelblock"}, {["x"] = 6, ["meta"] = {["fields"] = {}, ["inventory"] = {}}, ["y"] = 13, ["param1"] = 15, ["z"] = 6, ["name"] = "darkage:stone_brick"}, {["x"] = 6, ["meta"] = {["fields"] = {}, ["inventory"] = {}}, ["y"] = 14, ["param1"] = 15, ["z"] = 2, ["name"] = "darkage:stone_brick"}, {["x"] = 6, ["meta"] = {["fields"] = {}, ["inventory"] = {}}, ["y"] = 14, ["param1"] = 170, ["z"] = 3, ["name"] = "stairs:slab_steelblock"}, {["x"] = 6, ["meta"] = {["fields"] = {}, ["inventory"] = {}}, ["y"] = 14, ["param1"] = 15, ["z"] = 6, ["name"] = "darkage:stone_brick"}, {["x"] = 6, ["meta"] = {["fields"] = {}, ["inventory"] = {}}, ["y"] = 15, ["param1"] = 15, ["z"] = 2, ["name"] = "darkage:stone_brick"}, {["x"] = 6, ["meta"] = {["fields"] = {}, ["inventory"] = {}}, ["y"] = 15, ["param1"] = 15, ["z"] = 6, ["name"] = "darkage:stone_brick"}, {["x"] = 6, ["meta"] = {["fields"] = {}, ["inventory"] = {}}, ["y"] = 16, ["param1"] = 15, ["z"] = 2, ["name"] = "darkage:stone_brick"}, {["x"] = 6, ["meta"] = {["fields"] = {}, ["inventory"] = {}}, ["y"] = 16, ["param1"] = 15, ["z"] = 6, ["name"] = "darkage:stone_brick"}, {["x"] = 6, ["meta"] = {["fields"] = {}, ["inventory"] = {}}, ["y"] = 17, ["param1"] = 15, ["z"] = 2, ["name"] = "darkage:stone_brick"}, {["x"] = 6, ["meta"] = {["fields"] = {}, ["inventory"] = {}}, ["y"] = 17, ["z"] = 4, ["name"] = "default:steelblock"}, {["x"] = 6, ["meta"] = {["fields"] = {}, ["inventory"] = {}}, ["y"] = 17, ["param1"] = 170, ["z"] = 5, ["name"] = "stairs:slab_steelblock"}, {["x"] = 6, ["meta"] = {["fields"] = {}, ["inventory"] = {}}, ["y"] = 17, ["param1"] = 15, ["z"] = 6, ["name"] = "darkage:stone_brick"}, {["x"] = 6, ["meta"] = {["fields"] = {}, ["inventory"] = {}}, ["y"] = 18, ["param1"] = 15, ["z"] = 2, ["name"] = "darkage:stone_brick"}, {["x"] = 6, ["meta"] = {["fields"] = {}, ["inventory"] = {}}, ["y"] = 18, ["param1"] = 170, ["z"] = 3, ["name"] = "stairs:slab_steelblock"}, {["x"] = 6, ["meta"] = {["fields"] = {}, ["inventory"] = {}}, ["y"] = 18, ["param1"] = 15, ["z"] = 6, ["name"] = "darkage:stone_brick"}, {["x"] = 6, ["meta"] = {["fields"] = {}, ["inventory"] = {}}, ["y"] = 19, ["param1"] = 15, ["z"] = 2, ["name"] = "darkage:stone_brick"}, {["x"] = 6, ["meta"] = {["fields"] = {}, ["inventory"] = {}}, ["y"] = 19, ["param1"] = 15, ["z"] = 6, ["name"] = "darkage:stone_brick"}, {["x"] = 6, ["meta"] = {["fields"] = {}, ["inventory"] = {}}, ["y"] = 20, ["param1"] = 15, ["z"] = 2, ["name"] = "darkage:stone_brick"}, {["x"] = 6, ["meta"] = {["fields"] = {}, ["inventory"] = {}}, ["y"] = 20, ["param1"] = 15, ["z"] = 6, ["name"] = "darkage:stone_brick"}, {["x"] = 6, ["meta"] = {["fields"] = {}, ["inventory"] = {}}, ["y"] = 21, ["param1"] = 15, ["z"] = 2, ["name"] = "darkage:stone_brick"}, {["x"] = 6, ["meta"] = {["fields"] = {}, ["inventory"] = {}}, ["y"] = 21, ["z"] = 4, ["name"] = "default:steelblock"}, {["x"] = 6, ["meta"] = {["fields"] = {}, ["inventory"] = {}}, ["y"] = 21, ["param1"] = 170, ["z"] = 5, ["name"] = "stairs:slab_steelblock"}, {["x"] = 6, ["meta"] = {["fields"] = {}, ["inventory"] = {}}, ["y"] = 21, ["param1"] = 15, ["z"] = 6, ["name"] = "darkage:stone_brick"}, {["x"] = 6, ["meta"] = {["fields"] = {}, ["inventory"] = {}}, ["param2"] = 20, ["y"] = 22, ["z"] = 0, ["name"] = "homedecor:glowlight_quarter_white"}, {["x"] = 6, ["meta"] = {["fields"] = {}, ["inventory"] = {}}, ["param2"] = 20, ["y"] = 22, ["z"] = 1, ["name"] = "homedecor:glowlight_quarter_white"}, {["x"] = 6, ["meta"] = {["fields"] = {}, ["inventory"] = {}}, ["y"] = 22, ["param1"] = 15, ["z"] = 2, ["name"] = "darkage:stone_brick"}, {["x"] = 6, ["meta"] = {["fields"] = {}, ["inventory"] = {}}, ["y"] = 22, ["param1"] = 170, ["z"] = 3, ["name"] = "stairs:slab_steelblock"}, {["x"] = 6, ["meta"] = {["fields"] = {}, ["inventory"] = {}}, ["y"] = 22, ["param1"] = 15, ["z"] = 6, ["name"] = "darkage:stone_brick"}, {["x"] = 6, ["meta"] = {["fields"] = {}, ["inventory"] = {}}, ["param2"] = 22, ["y"] = 22, ["z"] = 7, ["name"] = "homedecor:glowlight_quarter_white"}, {["x"] = 6, ["meta"] = {["fields"] = {}, ["inventory"] = {}}, ["param2"] = 22, ["y"] = 22, ["z"] = 8, ["name"] = "homedecor:glowlight_quarter_white"}, {["x"] = 6, ["meta"] = {["fields"] = {}, ["inventory"] = {}}, ["y"] = 23, ["z"] = 0, ["name"] = "darkage:stone_brick"}, {["x"] = 6, ["meta"] = {["fields"] = {}, ["inventory"] = {}}, ["y"] = 23, ["z"] = 1, ["name"] = "darkage:stone_brick"}, {["x"] = 6, ["meta"] = {["fields"] = {}, ["inventory"] = {}}, ["y"] = 23, ["param1"] = 15, ["z"] = 2, ["name"] = "darkage:stone_brick"}, {["x"] = 6, ["meta"] = {["fields"] = {}, ["inventory"] = {}}, ["y"] = 23, ["param1"] = 15, ["z"] = 6, ["name"] = "darkage:stone_brick"}, {["x"] = 6, ["meta"] = {["fields"] = {}, ["inventory"] = {}}, ["y"] = 23, ["z"] = 7, ["name"] = "darkage:stone_brick"}, {["x"] = 6, ["meta"] = {["fields"] = {}, ["inventory"] = {}}, ["y"] = 23, ["z"] = 8, ["name"] = "darkage:stone_brick"}, {["x"] = 6, ["meta"] = {["fields"] = {}, ["inventory"] = {}}, ["param2"] = 21, ["y"] = 26, ["z"] = 1, ["name"] = "homedecor:glowlight_quarter_white"}, {["x"] = 6, ["meta"] = {["fields"] = {}, ["inventory"] = {}}, ["param2"] = 21, ["y"] = 26, ["z"] = 7, ["name"] = "homedecor:glowlight_quarter_white"}, {["x"] = 6, ["meta"] = {["fields"] = {}, ["inventory"] = {}}, ["y"] = 27, ["param1"] = 205, ["z"] = 1, ["name"] = "stairs:slab_darkage_slate_cobble"}, {["x"] = 6, ["meta"] = {["fields"] = {}, ["inventory"] = {}}, ["y"] = 27, ["z"] = 2, ["name"] = "darkage:slate_cobble"}, {["x"] = 6, ["meta"] = {["fields"] = {}, ["inventory"] = {}}, ["y"] = 27, ["param1"] = 188, ["z"] = 3, ["name"] = "stairs:slab_darkage_slate_cobble"}, {["x"] = 6, ["meta"] = {["fields"] = {}, ["inventory"] = {}}, ["y"] = 27, ["param1"] = 204, ["z"] = 4, ["name"] = "stairs:slab_darkage_slate_cobble"}, {["x"] = 6, ["meta"] = {["fields"] = {}, ["inventory"] = {}}, ["y"] = 27, ["param1"] = 188, ["z"] = 5, ["name"] = "stairs:slab_darkage_slate_cobble"}, {["x"] = 6, ["meta"] = {["fields"] = {}, ["inventory"] = {}}, ["y"] = 27, ["z"] = 6, ["name"] = "darkage:slate_cobble"}, {["x"] = 6, ["meta"] = {["fields"] = {}, ["inventory"] = {}}, ["y"] = 27, ["param1"] = 205, ["z"] = 7, ["name"] = "stairs:slab_darkage_slate_cobble"}, {["x"] = 6, ["meta"] = {["fields"] = {}, ["inventory"] = {}}, ["y"] = 28, ["param1"] = 173, ["z"] = 3, ["name"] = "stairs:slab_darkage_slate_cobble"}, {["x"] = 6, ["meta"] = {["fields"] = {}, ["inventory"] = {}}, ["y"] = 28, ["param1"] = 189, ["z"] = 4, ["name"] = "stairs:slab_darkage_slate_cobble"}, {["x"] = 6, ["meta"] = {["fields"] = {}, ["inventory"] = {}}, ["y"] = 28, ["param1"] = 173, ["z"] = 5, ["name"] = "stairs:slab_darkage_slate_cobble"}, {["x"] = 7, ["meta"] = {["fields"] = {}, ["inventory"] = {}}, ["y"] = 0, ["param1"] = 13, ["z"] = 4, ["name"] = "darkage:stone_brick"}, {["x"] = 7, ["meta"] = {["fields"] = {}, ["inventory"] = {}}, ["y"] = 1, ["param1"] = 13, ["z"] = 4, ["name"] = "darkage:stone_brick"}, {["x"] = 7, ["meta"] = {["fields"] = {}, ["inventory"] = {}}, ["param2"] = 4, ["y"] = 2, ["z"] = 3, ["name"] = "default:torch"}, {["x"] = 7, ["meta"] = {["fields"] = {}, ["inventory"] = {}}, ["y"] = 2, ["param1"] = 13, ["z"] = 4, ["name"] = "darkage:stone_brick"}, {["x"] = 7, ["meta"] = {["fields"] = {}, ["inventory"] = {}}, ["y"] = 2, ["z"] = 5, ["name"] = "darkage:stone_brick"}, {["x"] = 7, ["meta"] = {["fields"] = {}, ["inventory"] = {}}, ["y"] = 3, ["z"] = 0, ["name"] = "default:dirt"}, {["x"] = 7, ["meta"] = {["fields"] = {}, ["inventory"] = {}}, ["y"] = 3, ["z"] = 1, ["name"] = "default:dirt"}, {["x"] = 7, ["meta"] = {["fields"] = {}, ["inventory"] = {}}, ["y"] = 3, ["z"] = 2, ["name"] = "default:dirt"}, {["x"] = 7, ["meta"] = {["fields"] = {}, ["inventory"] = {}}, ["y"] = 3, ["z"] = 3, ["name"] = "darkage:stone_brick"}, {["x"] = 7, ["meta"] = {["fields"] = {}, ["inventory"] = {}}, ["y"] = 3, ["z"] = 5, ["name"] = "darkage:stone_brick"}, {["x"] = 7, ["meta"] = {["fields"] = {}, ["inventory"] = {}}, ["y"] = 4, ["z"] = 0, ["name"] = "default:dirt"}, {["x"] = 7, ["meta"] = {["fields"] = {}, ["inventory"] = {}}, ["y"] = 4, ["z"] = 1, ["name"] = "default:dirt"}, {["x"] = 7, ["meta"] = {["fields"] = {}, ["inventory"] = {}}, ["y"] = 4, ["z"] = 2, ["name"] = "default:dirt"}, {["x"] = 7, ["meta"] = {["fields"] = {}, ["inventory"] = {}}, ["y"] = 4, ["param1"] = 15, ["z"] = 3, ["name"] = "darkage:stone_brick"}, {["x"] = 7, ["meta"] = {["fields"] = {}, ["inventory"] = {}}, ["y"] = 4, ["z"] = 5, ["name"] = "darkage:stone_brick"}, {["x"] = 7, ["meta"] = {["fields"] = {}, ["inventory"] = {}}, ["y"] = 5, ["z"] = 0, ["name"] = "default:dirt"}, {["x"] = 7, ["meta"] = {["fields"] = {}, ["inventory"] = {}}, ["y"] = 5, ["z"] = 1, ["name"] = "default:dirt"}, {["x"] = 7, ["meta"] = {["fields"] = {}, ["inventory"] = {}}, ["y"] = 5, ["param1"] = 15, ["z"] = 2, ["name"] = "default:dirt_with_grass"}, {["x"] = 7, ["meta"] = {["fields"] = {}, ["inventory"] = {}}, ["y"] = 5, ["param1"] = 13, ["z"] = 3, ["name"] = "darkage:stone_brick"}, {["x"] = 7, ["meta"] = {["fields"] = {}, ["inventory"] = {}}, ["y"] = 5, ["param1"] = 13, ["z"] = 4, ["name"] = "darkage:stone_brick"}, {["x"] = 7, ["meta"] = {["fields"] = {}, ["inventory"] = {}}, ["y"] = 5, ["z"] = 5, ["name"] = "darkage:stone_brick"}, {["x"] = 7, ["meta"] = {["fields"] = {}, ["inventory"] = {}}, ["y"] = 6, ["param1"] = 15, ["z"] = 0, ["name"] = "default:dirt_with_grass"}, {["x"] = 7, ["meta"] = {["fields"] = {}, ["inventory"] = {}}, ["y"] = 6, ["param1"] = 15, ["z"] = 1, ["name"] = "default:dirt_with_grass"}, {["x"] = 7, ["meta"] = {["fields"] = {}, ["inventory"] = {}}, ["y"] = 6, ["param1"] = 15, ["z"] = 3, ["name"] = "darkage:stone_brick"}, {["x"] = 7, ["meta"] = {["fields"] = {}, ["inventory"] = {}}, ["y"] = 6, ["param1"] = 15, ["z"] = 4, ["name"] = "darkage:stone_brick"}, {["x"] = 7, ["meta"] = {["fields"] = {}, ["inventory"] = {}}, ["y"] = 6, ["z"] = 5, ["name"] = "darkage:stone_brick"}, {["x"] = 7, ["meta"] = {["fields"] = {}, ["inventory"] = {}}, ["y"] = 7, ["param1"] = 15, ["z"] = 3, ["name"] = "darkage:stone_brick"}, {["x"] = 7, ["meta"] = {["fields"] = {}, ["inventory"] = {}}, ["y"] = 7, ["z"] = 5, ["name"] = "darkage:stone_brick"}, {["x"] = 7, ["meta"] = {["fields"] = {}, ["inventory"] = {}}, ["y"] = 8, ["param1"] = 15, ["z"] = 3, ["name"] = "darkage:stone_brick"}, {["x"] = 7, ["meta"] = {["fields"] = {}, ["inventory"] = {}}, ["y"] = 8, ["param1"] = 15, ["z"] = 4, ["name"] = "darkage:stone_brick"}, {["x"] = 7, ["meta"] = {["fields"] = {}, ["inventory"] = {}}, ["y"] = 8, ["z"] = 5, ["name"] = "darkage:stone_brick"}, {["x"] = 7, ["meta"] = {["fields"] = {}, ["inventory"] = {}}, ["y"] = 9, ["param1"] = 15, ["z"] = 3, ["name"] = "darkage:stone_brick"}, {["x"] = 7, ["meta"] = {["fields"] = {}, ["inventory"] = {}}, ["y"] = 9, ["z"] = 4, ["name"] = "default:steelblock"}, {["x"] = 7, ["meta"] = {["fields"] = {}, ["inventory"] = {}}, ["y"] = 9, ["z"] = 5, ["name"] = "darkage:stone_brick"}, {["x"] = 7, ["meta"] = {["fields"] = {}, ["inventory"] = {}}, ["y"] = 10, ["param1"] = 15, ["z"] = 3, ["name"] = "darkage:stone_brick"}, {["x"] = 7, ["meta"] = {["fields"] = {}, ["inventory"] = {}}, ["y"] = 10, ["param1"] = 15, ["z"] = 5, ["name"] = "darkage:stone_brick"}, {["x"] = 7, ["meta"] = {["fields"] = {}, ["inventory"] = {}}, ["y"] = 11, ["param1"] = 15, ["z"] = 3, ["name"] = "darkage:stone_brick"}, {["x"] = 7, ["meta"] = {["fields"] = {}, ["inventory"] = {}}, ["y"] = 11, ["param1"] = 15, ["z"] = 5, ["name"] = "darkage:stone_brick"}, {["x"] = 7, ["meta"] = {["fields"] = {}, ["inventory"] = {}}, ["y"] = 12, ["param1"] = 15, ["z"] = 3, ["name"] = "darkage:stone_brick"}, {["x"] = 7, ["meta"] = {["fields"] = {}, ["inventory"] = {}}, ["y"] = 12, ["param1"] = 15, ["z"] = 4, ["name"] = "darkage:stone_brick"}, {["x"] = 7, ["meta"] = {["fields"] = {}, ["inventory"] = {}}, ["y"] = 12, ["param1"] = 15, ["z"] = 5, ["name"] = "darkage:stone_brick"}, {["x"] = 7, ["meta"] = {["fields"] = {}, ["inventory"] = {}}, ["y"] = 13, ["param1"] = 15, ["z"] = 3, ["name"] = "darkage:stone_brick"}, {["x"] = 7, ["meta"] = {["fields"] = {}, ["inventory"] = {}}, ["y"] = 13, ["param1"] = 15, ["z"] = 4, ["name"] = "darkage:stone_brick"}, {["x"] = 7, ["meta"] = {["fields"] = {}, ["inventory"] = {}}, ["y"] = 13, ["param1"] = 15, ["z"] = 5, ["name"] = "darkage:stone_brick"}, {["x"] = 7, ["meta"] = {["fields"] = {}, ["inventory"] = {}}, ["y"] = 14, ["param1"] = 15, ["z"] = 3, ["name"] = "darkage:stone_brick"}, {["x"] = 7, ["meta"] = {["fields"] = {}, ["inventory"] = {}}, ["y"] = 14, ["param1"] = 15, ["z"] = 4, ["name"] = "darkage:stone_brick"}, {["x"] = 7, ["meta"] = {["fields"] = {}, ["inventory"] = {}}, ["y"] = 14, ["param1"] = 15, ["z"] = 5, ["name"] = "darkage:stone_brick"}, {["x"] = 7, ["meta"] = {["fields"] = {}, ["inventory"] = {}}, ["y"] = 15, ["param1"] = 15, ["z"] = 3, ["name"] = "darkage:stone_brick"}, {["x"] = 7, ["meta"] = {["fields"] = {}, ["inventory"] = {}}, ["param2"] = 3, ["y"] = 15, ["param1"] = 171, ["z"] = 4, ["name"] = "castle:arrowslit_desertstonebrick_cross"}, {["x"] = 7, ["meta"] = {["fields"] = {}, ["inventory"] = {}}, ["y"] = 15, ["param1"] = 15, ["z"] = 5, ["name"] = "darkage:stone_brick"}, {["x"] = 7, ["meta"] = {["fields"] = {}, ["inventory"] = {}}, ["y"] = 16, ["param1"] = 15, ["z"] = 3, ["name"] = "darkage:stone_brick"}, {["x"] = 7, ["meta"] = {["fields"] = {}, ["inventory"] = {}}, ["y"] = 16, ["param1"] = 15, ["z"] = 4, ["name"] = "darkage:stone_brick"}, {["x"] = 7, ["meta"] = {["fields"] = {}, ["inventory"] = {}}, ["y"] = 16, ["param1"] = 15, ["z"] = 5, ["name"] = "darkage:stone_brick"}, {["x"] = 7, ["meta"] = {["fields"] = {}, ["inventory"] = {}}, ["y"] = 17, ["param1"] = 15, ["z"] = 3, ["name"] = "darkage:stone_brick"}, {["x"] = 7, ["meta"] = {["fields"] = {}, ["inventory"] = {}}, ["y"] = 17, ["param1"] = 15, ["z"] = 4, ["name"] = "darkage:stone_brick"}, {["x"] = 7, ["meta"] = {["fields"] = {}, ["inventory"] = {}}, ["y"] = 17, ["param1"] = 15, ["z"] = 5, ["name"] = "darkage:stone_brick"}, {["x"] = 7, ["meta"] = {["fields"] = {}, ["inventory"] = {}}, ["y"] = 18, ["param1"] = 15, ["z"] = 3, ["name"] = "darkage:stone_brick"}, {["x"] = 7, ["meta"] = {["fields"] = {}, ["inventory"] = {}}, ["y"] = 18, ["param1"] = 15, ["z"] = 4, ["name"] = "darkage:stone_brick"}, {["x"] = 7, ["meta"] = {["fields"] = {}, ["inventory"] = {}}, ["y"] = 18, ["param1"] = 15, ["z"] = 5, ["name"] = "darkage:stone_brick"}, {["x"] = 7, ["meta"] = {["fields"] = {}, ["inventory"] = {}}, ["y"] = 19, ["param1"] = 15, ["z"] = 3, ["name"] = "darkage:stone_brick"}, {["x"] = 7, ["meta"] = {["fields"] = {}, ["inventory"] = {}}, ["param2"] = 3, ["y"] = 19, ["param1"] = 171, ["z"] = 4, ["name"] = "castle:arrowslit_sandstone_cross"}, {["x"] = 7, ["meta"] = {["fields"] = {}, ["inventory"] = {}}, ["y"] = 19, ["param1"] = 15, ["z"] = 5, ["name"] = "darkage:stone_brick"}, {["x"] = 7, ["meta"] = {["fields"] = {}, ["inventory"] = {}}, ["y"] = 20, ["param1"] = 15, ["z"] = 3, ["name"] = "darkage:stone_brick"}, {["x"] = 7, ["meta"] = {["fields"] = {}, ["inventory"] = {}}, ["y"] = 20, ["param1"] = 15, ["z"] = 4, ["name"] = "darkage:stone_brick"}, {["x"] = 7, ["meta"] = {["fields"] = {}, ["inventory"] = {}}, ["y"] = 20, ["param1"] = 15, ["z"] = 5, ["name"] = "darkage:stone_brick"}, {["x"] = 7, ["meta"] = {["fields"] = {}, ["inventory"] = {}}, ["y"] = 21, ["param1"] = 15, ["z"] = 3, ["name"] = "darkage:stone_brick"}, {["x"] = 7, ["meta"] = {["fields"] = {}, ["inventory"] = {}}, ["y"] = 21, ["param1"] = 15, ["z"] = 4, ["name"] = "darkage:stone_brick"}, {["x"] = 7, ["meta"] = {["fields"] = {}, ["inventory"] = {}}, ["y"] = 21, ["param1"] = 15, ["z"] = 5, ["name"] = "darkage:stone_brick"}, {["x"] = 7, ["meta"] = {["fields"] = {}, ["inventory"] = {}}, ["param2"] = 20, ["y"] = 22, ["z"] = 1, ["name"] = "homedecor:glowlight_quarter_white"}, {["x"] = 7, ["meta"] = {["fields"] = {}, ["inventory"] = {}}, ["param2"] = 20, ["y"] = 22, ["z"] = 2, ["name"] = "homedecor:glowlight_quarter_white"}, {["x"] = 7, ["meta"] = {["fields"] = {}, ["inventory"] = {}}, ["y"] = 22, ["param1"] = 15, ["z"] = 3, ["name"] = "darkage:stone_brick"}, {["x"] = 7, ["meta"] = {["fields"] = {}, ["inventory"] = {}}, ["y"] = 22, ["param1"] = 15, ["z"] = 4, ["name"] = "darkage:stone_brick"}, {["x"] = 7, ["meta"] = {["fields"] = {}, ["inventory"] = {}}, ["y"] = 22, ["param1"] = 15, ["z"] = 5, ["name"] = "darkage:stone_brick"}, {["x"] = 7, ["meta"] = {["fields"] = {}, ["inventory"] = {}}, ["param2"] = 21, ["y"] = 22, ["z"] = 6, ["name"] = "homedecor:glowlight_quarter_white"}, {["x"] = 7, ["meta"] = {["fields"] = {}, ["inventory"] = {}}, ["param2"] = 22, ["y"] = 22, ["z"] = 7, ["name"] = "homedecor:glowlight_quarter_white"}, {["x"] = 7, ["meta"] = {["fields"] = {}, ["inventory"] = {}}, ["y"] = 23, ["z"] = 1, ["name"] = "darkage:stone_brick"}, {["x"] = 7, ["meta"] = {["fields"] = {}, ["inventory"] = {}}, ["y"] = 23, ["z"] = 2, ["name"] = "darkage:stone_brick"}, {["x"] = 7, ["meta"] = {["fields"] = {}, ["inventory"] = {}}, ["y"] = 23, ["param1"] = 15, ["z"] = 3, ["name"] = "darkage:stone_brick"}, {["x"] = 7, ["meta"] = {["fields"] = {}, ["inventory"] = {}}, ["y"] = 23, ["param1"] = 15, ["z"] = 4, ["name"] = "darkage:stone_brick"}, {["x"] = 7, ["meta"] = {["fields"] = {}, ["inventory"] = {}}, ["y"] = 23, ["param1"] = 15, ["z"] = 5, ["name"] = "darkage:stone_brick"}, {["x"] = 7, ["meta"] = {["fields"] = {}, ["inventory"] = {}}, ["y"] = 23, ["z"] = 6, ["name"] = "darkage:stone_brick"}, {["x"] = 7, ["meta"] = {["fields"] = {}, ["inventory"] = {}}, ["y"] = 23, ["z"] = 7, ["name"] = "darkage:stone_brick"}, {["x"] = 7, ["meta"] = {["fields"] = {}, ["inventory"] = {}}, ["param2"] = 1, ["y"] = 24, ["param1"] = 173, ["z"] = 0, ["name"] = "homedecor:fence_wrought_iron"}, {["x"] = 7, ["meta"] = {["fields"] = {}, ["inventory"] = {}}, ["param2"] = 1, ["y"] = 24, ["param1"] = 172, ["z"] = 3, ["name"] = "castle:pillars_stonebrick_bottom"}, {["x"] = 7, ["meta"] = {["fields"] = {}, ["inventory"] = {}}, ["y"] = 24, ["param1"] = 172, ["z"] = 5, ["name"] = "castle:pillars_stonebrick_bottom"}, {["x"] = 7, ["meta"] = {["fields"] = {}, ["inventory"] = {}}, ["param2"] = 3, ["y"] = 24, ["param1"] = 173, ["z"] = 8, ["name"] = "homedecor:fence_wrought_iron"}, {["x"] = 7, ["meta"] = {["fields"] = {}, ["inventory"] = {}}, ["param2"] = 1, ["y"] = 25, ["param1"] = 188, ["z"] = 3, ["name"] = "castle:pillars_stonebrick_middle"}, {["x"] = 7, ["meta"] = {["fields"] = {}, ["inventory"] = {}}, ["y"] = 25, ["param1"] = 188, ["z"] = 5, ["name"] = "castle:pillars_stonebrick_middle"}, {["x"] = 7, ["meta"] = {["fields"] = {}, ["inventory"] = {}}, ["param2"] = 21, ["y"] = 26, ["z"] = 2, ["name"] = "homedecor:glowlight_quarter_white"}, {["x"] = 7, ["meta"] = {["fields"] = {}, ["inventory"] = {}}, ["param2"] = 1, ["y"] = 26, ["param1"] = 204, ["z"] = 3, ["name"] = "castle:pillars_stonebrick_top"}, {["x"] = 7, ["meta"] = {["fields"] = {}, ["inventory"] = {}}, ["y"] = 26, ["param1"] = 204, ["z"] = 5, ["name"] = "castle:pillars_stonebrick_top"}, {["x"] = 7, ["meta"] = {["fields"] = {}, ["inventory"] = {}}, ["param2"] = 21, ["y"] = 26, ["z"] = 6, ["name"] = "homedecor:glowlight_quarter_white"}, {["x"] = 7, ["meta"] = {["fields"] = {}, ["inventory"] = {}}, ["y"] = 27, ["param1"] = 205, ["z"] = 2, ["name"] = "stairs:slab_darkage_slate_cobble"}, {["x"] = 7, ["meta"] = {["fields"] = {}, ["inventory"] = {}}, ["y"] = 27, ["z"] = 3, ["name"] = "darkage:slate_cobble"}, {["x"] = 7, ["meta"] = {["fields"] = {}, ["inventory"] = {}}, ["y"] = 27, ["z"] = 4, ["name"] = "darkage:slate_cobble"}, {["x"] = 7, ["meta"] = {["fields"] = {}, ["inventory"] = {}}, ["y"] = 27, ["z"] = 5, ["name"] = "darkage:slate_cobble"}, {["x"] = 7, ["meta"] = {["fields"] = {}, ["inventory"] = {}}, ["y"] = 27, ["param1"] = 205, ["z"] = 6, ["name"] = "stairs:slab_darkage_slate_cobble"}, {["x"] = 8, ["meta"] = {["fields"] = {}, ["inventory"] = {}}, ["y"] = 0, ["param1"] = 13, ["z"] = 4, ["name"] = "darkage:stone_brick"}, {["x"] = 8, ["meta"] = {["fields"] = {}, ["inventory"] = {}}, ["y"] = 1, ["param1"] = 13, ["z"] = 4, ["name"] = "darkage:stone_brick"}, {["x"] = 8, ["meta"] = {["fields"] = {}, ["inventory"] = {}}, ["param2"] = 4, ["y"] = 2, ["z"] = 3, ["name"] = "default:torch"}, {["x"] = 8, ["meta"] = {["fields"] = {}, ["inventory"] = {}}, ["y"] = 2, ["param1"] = 13, ["z"] = 4, ["name"] = "darkage:stone_brick"}, {["x"] = 8, ["meta"] = {["fields"] = {}, ["inventory"] = {}}, ["y"] = 2, ["z"] = 5, ["name"] = "darkage:stone_brick"}, {["x"] = 8, ["meta"] = {["fields"] = {}, ["inventory"] = {}}, ["y"] = 3, ["z"] = 0, ["name"] = "default:dirt"}, {["x"] = 8, ["meta"] = {["fields"] = {}, ["inventory"] = {}}, ["y"] = 3, ["z"] = 1, ["name"] = "default:dirt"}, {["x"] = 8, ["meta"] = {["fields"] = {}, ["inventory"] = {}}, ["y"] = 3, ["z"] = 2, ["name"] = "default:dirt"}, {["x"] = 8, ["meta"] = {["fields"] = {}, ["inventory"] = {}}, ["y"] = 3, ["z"] = 3, ["name"] = "default:dirt"}, {["x"] = 8, ["meta"] = {["fields"] = {}, ["inventory"] = {}}, ["y"] = 3, ["z"] = 5, ["name"] = "darkage:stone_brick"}, {["x"] = 8, ["meta"] = {["fields"] = {}, ["inventory"] = {}}, ["y"] = 4, ["z"] = 0, ["name"] = "default:dirt"}, {["x"] = 8, ["meta"] = {["fields"] = {}, ["inventory"] = {}},