5:return {{["x"] = 0, ["meta"] = {["fields"] = {}, ["inventory"] = {}}, ["y"] = 0, ["z"] = 0, ["name"] = "default:dirt"}, {["x"] = 0, ["meta"] = {["fields"] = {}, ["inventory"] = {}}, ["y"] = 0, ["z"] = 1, ["name"] = "default:dirt"}, {["x"] = 0, ["meta"] = {["fields"] = {}, ["inventory"] = {}}, ["y"] = 0, ["z"] = 2, ["name"] = "default:dirt"}, {["x"] = 0, ["meta"] = {["fields"] = {}, ["inventory"] = {}}, ["y"] = 0, ["z"] = 3, ["name"] = "default:stone"}, {["x"] = 0, ["meta"] = {["fields"] = {}, ["inventory"] = {}}, ["y"] = 0, ["z"] = 4, ["name"] = "default:stone"}, {["x"] = 0, ["meta"] = {["fields"] = {}, ["inventory"] = {}}, ["y"] = 0, ["z"] = 5, ["name"] = "default:stone"}, {["x"] = 0, ["meta"] = {["fields"] = {}, ["inventory"] = {}}, ["y"] = 0, ["z"] = 6, ["name"] = "default:stone"}, {["x"] = 0, ["meta"] = {["fields"] = {}, ["inventory"] = {}}, ["y"] = 0, ["z"] = 7, ["name"] = "default:dirt"}, {["x"] = 0, ["meta"] = {["fields"] = {}, ["inventory"] = {}}, ["y"] = 0, ["z"] = 8, ["name"] = "default:dirt"}, {["x"] = 0, ["meta"] = {["fields"] = {}, ["inventory"] = {}}, ["y"] = 0, ["z"] = 9, ["name"] = "default:dirt"}, {["x"] = 0, ["meta"] = {["fields"] = {}, ["inventory"] = {}}, ["y"] = 0, ["z"] = 10, ["name"] = "default:dirt"}, {["x"] = 0, ["meta"] = {["fields"] = {}, ["inventory"] = {}}, ["y"] = 0, ["z"] = 11, ["name"] = "default:dirt_with_grass"}, {["x"] = 0, ["meta"] = {["fields"] = {}, ["inventory"] = {}}, ["y"] = 1, ["z"] = 0, ["name"] = "default:dirt"}, {["x"] = 0, ["meta"] = {["fields"] = {}, ["inventory"] = {}}, ["y"] = 1, ["z"] = 1, ["name"] = "default:dirt"}, {["x"] = 0, ["meta"] = {["fields"] = {}, ["inventory"] = {}}, ["y"] = 1, ["z"] = 2, ["name"] = "default:dirt"}, {["x"] = 0, ["meta"] = {["fields"] = {}, ["inventory"] = {}}, ["y"] = 1, ["z"] = 3, ["name"] = "default:stone"}, {["x"] = 0, ["meta"] = {["fields"] = {}, ["inventory"] = {}}, ["y"] = 1, ["z"] = 4, ["name"] = "default:stone"}, {["x"] = 0, ["meta"] = {["fields"] = {}, ["inventory"] = {}}, ["y"] = 1, ["z"] = 5, ["name"] = "default:stone"}, {["x"] = 0, ["meta"] = {["fields"] = {}, ["inventory"] = {}}, ["y"] = 1, ["z"] = 6, ["name"] = "default:stone"}, {["x"] = 0, ["meta"] = {["fields"] = {}, ["inventory"] = {}}, ["y"] = 1, ["z"] = 7, ["name"] = "default:dirt"}, {["x"] = 0, ["meta"] = {["fields"] = {}, ["inventory"] = {}}, ["y"] = 1, ["z"] = 8, ["name"] = "default:dirt"}, {["x"] = 0, ["meta"] = {["fields"] = {}, ["inventory"] = {}}, ["y"] = 1, ["z"] = 9, ["name"] = "default:dirt_with_grass"}, {["x"] = 0, ["meta"] = {["fields"] = {}, ["inventory"] = {}}, ["y"] = 1, ["z"] = 10, ["name"] = "default:dirt"}, {["x"] = 0, ["meta"] = {["fields"] = {}, ["inventory"] = {}}, ["y"] = 2, ["z"] = 0, ["name"] = "default:dirt_with_grass"}, {["x"] = 0, ["meta"] = {["fields"] = {}, ["inventory"] = {}}, ["y"] = 2, ["z"] = 1, ["name"] = "default:dirt"}, {["x"] = 0, ["meta"] = {["fields"] = {}, ["inventory"] = {}}, ["y"] = 2, ["z"] = 2, ["name"] = "default:dirt"}, {["x"] = 0, ["meta"] = {["fields"] = {}, ["inventory"] = {}}, ["y"] = 2, ["z"] = 3, ["name"] = "default:stone"}, {["x"] = 0, ["meta"] = {["fields"] = {}, ["inventory"] = {}}, ["y"] = 2, ["z"] = 4, ["name"] = "default:stone"}, {["x"] = 0, ["meta"] = {["fields"] = {}, ["inventory"] = {}}, ["y"] = 2, ["z"] = 5, ["name"] = "default:stone"}, {["x"] = 0, ["meta"] = {["fields"] = {}, ["inventory"] = {}}, ["y"] = 2, ["z"] = 6, ["name"] = "default:stone"}, {["x"] = 0, ["meta"] = {["fields"] = {}, ["inventory"] = {}}, ["y"] = 2, ["z"] = 7, ["name"] = "default:dirt"}, {["x"] = 0, ["meta"] = {["fields"] = {}, ["inventory"] = {}}, ["y"] = 2, ["z"] = 8, ["name"] = "default:dirt_with_grass"}, {["x"] = 0, ["meta"] = {["fields"] = {}, ["inventory"] = {}}, ["y"] = 2, ["z"] = 10, ["name"] = "default:dirt_with_grass"}, {["x"] = 0, ["meta"] = {["fields"] = {}, ["inventory"] = {}}, ["y"] = 3, ["z"] = 1, ["name"] = "default:dirt_with_grass"}, {["x"] = 0, ["meta"] = {["fields"] = {}, ["inventory"] = {}}, ["y"] = 3, ["z"] = 2, ["name"] = "default:dirt"}, {["x"] = 0, ["meta"] = {["fields"] = {}, ["inventory"] = {}}, ["y"] = 3, ["z"] = 3, ["name"] = "default:stone"}, {["x"] = 0, ["meta"] = {["fields"] = {}, ["inventory"] = {}}, ["y"] = 3, ["z"] = 4, ["name"] = "default:stone"}, {["x"] = 0, ["meta"] = {["fields"] = {}, ["inventory"] = {}}, ["y"] = 3, ["z"] = 5, ["name"] = "default:stone"}, {["x"] = 0, ["meta"] = {["fields"] = {}, ["inventory"] = {}}, ["y"] = 3, ["z"] = 6, ["name"] = "default:stone"}, {["x"] = 0, ["meta"] = {["fields"] = {}, ["inventory"] = {}}, ["y"] = 3, ["z"] = 7, ["name"] = "default:dirt"}, {["x"] = 0, ["meta"] = {["fields"] = {}, ["inventory"] = {}}, ["y"] = 4, ["z"] = 2, ["name"] = "default:dirt"}, {["x"] = 0, ["meta"] = {["fields"] = {}, ["inventory"] = {}}, ["y"] = 4, ["z"] = 3, ["name"] = "default:stone"}, {["x"] = 0, ["meta"] = {["fields"] = {}, ["inventory"] = {}}, ["y"] = 4, ["z"] = 4, ["name"] = "default:stone"}, {["x"] = 0, ["meta"] = {["fields"] = {}, ["inventory"] = {}}, ["y"] = 4, ["z"] = 5, ["name"] = "default:stone"}, {["x"] = 0, ["meta"] = {["fields"] = {}, ["inventory"] = {}}, ["y"] = 4, ["z"] = 6, ["name"] = "default:stone"}, {["x"] = 0, ["meta"] = {["fields"] = {}, ["inventory"] = {}}, ["y"] = 4, ["z"] = 7, ["name"] = "default:dirt_with_grass"}, {["x"] = 0, ["meta"] = {["fields"] = {}, ["inventory"] = {}}, ["y"] = 5, ["z"] = 2, ["name"] = "default:dirt_with_grass"}, {["x"] = 0, ["meta"] = {["fields"] = {}, ["inventory"] = {}}, ["y"] = 5, ["z"] = 3, ["name"] = "default:stone"}, {["x"] = 0, ["meta"] = {["fields"] = {}, ["inventory"] = {}}, ["y"] = 5, ["z"] = 4, ["name"] = "default:stone"}, {["x"] = 0, ["meta"] = {["fields"] = {}, ["inventory"] = {}}, ["y"] = 5, ["z"] = 5, ["name"] = "default:stone"}, {["x"] = 0, ["meta"] = {["fields"] = {}, ["inventory"] = {}}, ["y"] = 5, ["z"] = 6, ["name"] = "default:stone"}, {["x"] = 0, ["meta"] = {["fields"] = {}, ["inventory"] = {}}, ["y"] = 5, ["param1"] = 12, ["z"] = 7, ["name"] = "default:leaves"}, {["x"] = 0, ["meta"] = {["fields"] = {}, ["inventory"] = {}}, ["y"] = 5, ["param1"] = 13, ["z"] = 8, ["name"] = "default:leaves"}, {["x"] = 0, ["meta"] = {["fields"] = {}, ["inventory"] = {}}, ["y"] = 5, ["param1"] = 14, ["z"] = 9, ["name"] = "default:leaves"}, {["x"] = 0, ["meta"] = {["fields"] = {}, ["inventory"] = {}}, ["y"] = 6, ["z"] = 3, ["name"] = "default:stone"}, {["x"] = 0, ["meta"] = {["fields"] = {}, ["inventory"] = {}}, ["y"] = 6, ["z"] = 4, ["name"] = "default:stone"}, {["x"] = 0, ["meta"] = {["fields"] = {}, ["inventory"] = {}}, ["y"] = 6, ["z"] = 5, ["name"] = "default:stone"}, {["x"] = 0, ["meta"] = {["fields"] = {}, ["inventory"] = {}}, ["y"] = 6, ["z"] = 6, ["name"] = "default:stone"}, {["x"] = 0, ["meta"] = {["fields"] = {}, ["inventory"] = {}}, ["y"] = 6, ["param1"] = 12, ["z"] = 7, ["name"] = "default:leaves"}, {["x"] = 0, ["meta"] = {["fields"] = {}, ["inventory"] = {}}, ["y"] = 6, ["param1"] = 13, ["z"] = 8, ["name"] = "default:leaves"}, {["x"] = 0, ["meta"] = {["fields"] = {}, ["inventory"] = {}}, ["y"] = 6, ["param1"] = 14, ["z"] = 9, ["name"] = "default:leaves"}, {["x"] = 0, ["meta"] = {["fields"] = {}, ["inventory"] = {}}, ["y"] = 7, ["z"] = 3, ["name"] = "default:stone"}, {["x"] = 0, ["meta"] = {["fields"] = {}, ["inventory"] = {}}, ["y"] = 7, ["z"] = 4, ["name"] = "default:stone"}, {["x"] = 0, ["meta"] = {["fields"] = {}, ["inventory"] = {}}, ["y"] = 7, ["z"] = 5, ["name"] = "default:stone"}, {["x"] = 0, ["meta"] = {["fields"] = {}, ["inventory"] = {}}, ["y"] = 7, ["z"] = 6, ["name"] = "default:stone"}, {["x"] = 0, ["meta"] = {["fields"] = {}, ["inventory"] = {}}, ["y"] = 7, ["param1"] = 13, ["z"] = 7, ["name"] = "default:leaves"}, {["x"] = 0, ["meta"] = {["fields"] = {}, ["inventory"] = {}}, ["y"] = 7, ["param1"] = 14, ["z"] = 8, ["name"] = "default:leaves"}, {["x"] = 0, ["meta"] = {["fields"] = {}, ["inventory"] = {}}, ["y"] = 8, ["z"] = 3, ["name"] = "default:stone"}, {["x"] = 0, ["meta"] = {["fields"] = {}, ["inventory"] = {}}, ["y"] = 8, ["z"] = 4, ["name"] = "default:stone"}, {["x"] = 0, ["meta"] = {["fields"] = {}, ["inventory"] = {}}, ["y"] = 8, ["z"] = 5, ["name"] = "default:stone"}, {["x"] = 0, ["meta"] = {["fields"] = {}, ["inventory"] = {}}, ["y"] = 8, ["z"] = 6, ["name"] = "default:stone"}, {["x"] = 0, ["meta"] = {["fields"] = {}, ["inventory"] = {}}, ["y"] = 9, ["z"] = 3, ["name"] = "default:stone"}, {["x"] = 0, ["meta"] = {["fields"] = {}, ["inventory"] = {}}, ["y"] = 9, ["z"] = 4, ["name"] = "default:stone"}, {["x"] = 0, ["meta"] = {["fields"] = {}, ["inventory"] = {}}, ["y"] = 9, ["z"] = 5, ["name"] = "default:stone"}, {["x"] = 0, ["meta"] = {["fields"] = {}, ["inventory"] = {}}, ["y"] = 9, ["z"] = 6, ["name"] = "default:stone"}, {["x"] = 0, ["meta"] = {["fields"] = {}, ["inventory"] = {}}, ["y"] = 10, ["z"] = 3, ["name"] = "default:dirt"}, {["x"] = 0, ["meta"] = {["fields"] = {}, ["inventory"] = {}}, ["y"] = 10, ["z"] = 4, ["name"] = "default:stone"}, {["x"] = 0, ["meta"] = {["fields"] = {}, ["inventory"] = {}}, ["y"] = 10, ["z"] = 5, ["name"] = "default:stone"}, {["x"] = 0, ["meta"] = {["fields"] = {}, ["inventory"] = {}}, ["y"] = 10, ["z"] = 6, ["name"] = "default:stone"}, {["x"] = 0, ["meta"] = {["fields"] = {}, ["inventory"] = {}}, ["y"] = 11, ["z"] = 3, ["name"] = "default:dirt"}, {["x"] = 0, ["meta"] = {["fields"] = {}, ["inventory"] = {}}, ["y"] = 11, ["z"] = 4, ["name"] = "default:dirt"}, {["x"] = 0, ["meta"] = {["fields"] = {}, ["inventory"] = {}}, ["y"] = 11, ["z"] = 5, ["name"] = "default:dirt"}, {["x"] = 0, ["meta"] = {["fields"] = {}, ["inventory"] = {}}, ["y"] = 11, ["z"] = 6, ["name"] = "default:dirt"}, {["x"] = 0, ["meta"] = {["fields"] = {}, ["inventory"] = {}}, ["y"] = 12, ["z"] = 3, ["name"] = "default:dirt"}, {["x"] = 0, ["meta"] = {["fields"] = {}, ["inventory"] = {}}, ["y"] = 12, ["z"] = 4, ["name"] = "default:dirt"}, {["x"] = 0, ["meta"] = {["fields"] = {}, ["inventory"] = {}}, ["y"] = 12, ["z"] = 5, ["name"] = "default:dirt"}, {["x"] = 0, ["meta"] = {["fields"] = {}, ["inventory"] = {}}, ["y"] = 12, ["z"] = 6, ["name"] = "default:dirt"}, {["x"] = 0, ["meta"] = {["fields"] = {}, ["inventory"] = {}}, ["y"] = 13, ["z"] = 3, ["name"] = "default:dirt_with_grass"}, {["x"] = 0, ["meta"] = {["fields"] = {}, ["inventory"] = {}}, ["y"] = 13, ["z"] = 4, ["name"] = "default:dirt_with_grass"}, {["x"] = 0, ["meta"] = {["fields"] = {}, ["inventory"] = {}}, ["y"] = 13, ["z"] = 5, ["name"] = "default:dirt_with_grass"}, {["x"] = 0, ["meta"] = {["fields"] = {}, ["inventory"] = {}}, ["y"] = 13, ["z"] = 6, ["name"] = "default:dirt_with_grass"}, {["x"] = 1, ["meta"] = {["fields"] = {}, ["inventory"] = {}}, ["y"] = 0, ["z"] = 0, ["name"] = "default:dirt"}, {["x"] = 1, ["meta"] = {["fields"] = {}, ["inventory"] = {}}, ["y"] = 0, ["z"] = 1, ["name"] = "default:stone"}, {["x"] = 1, ["meta"] = {["fields"] = {}, ["inventory"] = {}}, ["y"] = 0, ["z"] = 2, ["name"] = "default:stone"}, {["x"] = 1, ["meta"] = {["fields"] = {}, ["inventory"] = {}}, ["y"] = 0, ["z"] = 3, ["name"] = "default:stone"}, {["x"] = 1, ["meta"] = {["fields"] = {}, ["inventory"] = {}}, ["y"] = 0, ["z"] = 4, ["name"] = "default:stone"}, {["x"] = 1, ["meta"] = {["fields"] = {}, ["inventory"] = {}}, ["y"] = 0, ["z"] = 5, ["name"] = "default:stone"}, {["x"] = 1, ["meta"] = {["fields"] = {}, ["inventory"] = {}}, ["y"] = 0, ["z"] = 6, ["name"] = "default:stone"}, {["x"] = 1, ["meta"] = {["fields"] = {}, ["inventory"] = {}}, ["y"] = 0, ["z"] = 7, ["name"] = "default:stone"}, {["x"] = 1, ["meta"] = {["fields"] = {}, ["inventory"] = {}}, ["y"] = 0, ["z"] = 8, ["name"] = "default:stone"}, {["x"] = 1, ["meta"] = {["fields"] = {}, ["inventory"] = {}}, ["y"] = 0, ["z"] = 9, ["name"] = "default:stone"}, {["x"] = 1, ["meta"] = {["fields"] = {}, ["inventory"] = {}}, ["y"] = 0, ["z"] = 10, ["name"] = "default:dirt"}, {["x"] = 1, ["meta"] = {["fields"] = {}, ["inventory"] = {}}, ["y"] = 0, ["z"] = 11, ["name"] = "default:dirt"}, {["x"] = 1, ["meta"] = {["fields"] = {}, ["inventory"] = {}}, ["y"] = 0, ["z"] = 12, ["name"] = "default:dirt_with_grass"}, {["x"] = 1, ["meta"] = {["fields"] = {}, ["inventory"] = {}}, ["y"] = 0, ["z"] = 13, ["name"] = "default:dirt_with_grass"}, {["x"] = 1, ["meta"] = {["fields"] = {}, ["inventory"] = {}}, ["y"] = 1, ["z"] = 0, ["name"] = "default:dirt"}, {["x"] = 1, ["meta"] = {["fields"] = {}, ["inventory"] = {}}, ["y"] = 1, ["z"] = 1, ["name"] = "default:stone"}, {["x"] = 1, ["meta"] = {["fields"] = {}, ["inventory"] = {}}, ["y"] = 1, ["z"] = 2, ["name"] = "default:stone"}, {["x"] = 1, ["meta"] = {["fields"] = {}, ["inventory"] = {}}, ["y"] = 1, ["z"] = 3, ["name"] = "default:stone"}, {["x"] = 1, ["meta"] = {["fields"] = {}, ["inventory"] = {}}, ["y"] = 1, ["z"] = 4, ["name"] = "default:stone"}, {["x"] = 1, ["meta"] = {["fields"] = {}, ["inventory"] = {}}, ["y"] = 1, ["z"] = 5, ["name"] = "default:stone"}, {["x"] = 1, ["meta"] = {["fields"] = {}, ["inventory"] = {}}, ["y"] = 1, ["z"] = 6, ["name"] = "default:stone"}, {["x"] = 1, ["meta"] = {["fields"] = {}, ["inventory"] = {}}, ["y"] = 1, ["z"] = 7, ["name"] = "default:stone"}, {["x"] = 1, ["meta"] = {["fields"] = {}, ["inventory"] = {}}, ["y"] = 1, ["z"] = 8, ["name"] = "default:stone"}, {["x"] = 1, ["meta"] = {["fields"] = {}, ["inventory"] = {}}, ["y"] = 1, ["z"] = 9, ["name"] = "default:stone"}, {["x"] = 1, ["meta"] = {["fields"] = {}, ["inventory"] = {}}, ["y"] = 1, ["z"] = 10, ["name"] = "default:dirt"}, {["x"] = 1, ["meta"] = {["fields"] = {}, ["inventory"] = {}}, ["y"] = 1, ["z"] = 11, ["name"] = "default:dirt_with_grass"}, {["x"] = 1, ["meta"] = {["fields"] = {}, ["inventory"] = {}}, ["y"] = 2, ["z"] = 0, ["name"] = "default:dirt"}, {["x"] = 1, ["meta"] = {["fields"] = {}, ["inventory"] = {}}, ["y"] = 2, ["z"] = 1, ["name"] = "default:dirt"}, {["x"] = 1, ["meta"] = {["fields"] = {}, ["inventory"] = {}}, ["y"] = 2, ["z"] = 2, ["name"] = "default:stone"}, {["x"] = 1, ["meta"] = {["fields"] = {}, ["inventory"] = {}}, ["y"] = 2, ["z"] = 3, ["name"] = "default:stone"}, {["x"] = 1, ["meta"] = {["fields"] = {}, ["inventory"] = {}}, ["y"] = 2, ["z"] = 4, ["name"] = "default:stone"}, {["x"] = 1, ["meta"] = {["fields"] = {}, ["inventory"] = {}}, ["y"] = 2, ["z"] = 5, ["name"] = "default:stone"}, {["x"] = 1, ["meta"] = {["fields"] = {}, ["inventory"] = {}}, ["y"] = 2, ["z"] = 6, ["name"] = "default:stone"}, {["x"] = 1, ["meta"] = {["fields"] = {}, ["inventory"] = {}}, ["y"] = 2, ["z"] = 7, ["name"] = "default:stone"}, {["x"] = 1, ["meta"] = {["fields"] = {}, ["inventory"] = {}}, ["y"] = 2, ["z"] = 8, ["name"] = "default:stone"}, {["x"] = 1, ["meta"] = {["fields"] = {}, ["inventory"] = {}}, ["y"] = 2, ["z"] = 9, ["name"] = "default:stone"}, {["x"] = 1, ["meta"] = {["fields"] = {}, ["inventory"] = {}}, ["y"] = 2, ["z"] = 10, ["name"] = "default:dirt_with_grass"}, {["x"] = 1, ["meta"] = {["fields"] = {}, ["inventory"] = {}}, ["y"] = 3, ["z"] = 0, ["name"] = "default:dirt_with_grass"}, {["x"] = 1, ["meta"] = {["fields"] = {}, ["inventory"] = {}}, ["y"] = 3, ["z"] = 1, ["name"] = "default:dirt"}, {["x"] = 1, ["meta"] = {["fields"] = {}, ["inventory"] = {}}, ["y"] = 3, ["z"] = 2, ["name"] = "default:stone"}, {["x"] = 1, ["meta"] = {["fields"] = {}, ["inventory"] = {}}, ["y"] = 3, ["z"] = 3, ["name"] = "default:stone"}, {["x"] = 1, ["meta"] = {["fields"] = {}, ["inventory"] = {}}, ["y"] = 3, ["z"] = 4, ["name"] = "default:stone"}, {["x"] = 1, ["meta"] = {["fields"] = {}, ["inventory"] = {}}, ["y"] = 3, ["z"] = 5, ["name"] = "default:stone"}, {["x"] = 1, ["meta"] = {["fields"] = {}, ["inventory"] = {}}, ["y"] = 3, ["z"] = 6, ["name"] = "default:stone"}, {["x"] = 1, ["meta"] = {["fields"] = {}, ["inventory"] = {}}, ["y"] = 3, ["z"] = 7, ["name"] = "default:stone"}, {["x"] = 1, ["meta"] = {["fields"] = {}, ["inventory"] = {}}, ["y"] = 3, ["z"] = 8, ["name"] = "default:stone"}, {["x"] = 1, ["meta"] = {["fields"] = {}, ["inventory"] = {}}, ["y"] = 3, ["z"] = 9, ["name"] = "default:stone"}, {["x"] = 1, ["meta"] = {["fields"] = {}, ["inventory"] = {}}, ["y"] = 4, ["z"] = 1, ["name"] = "default:dirt"}, {["x"] = 1, ["meta"] = {["fields"] = {}, ["inventory"] = {}}, ["y"] = 4, ["z"] = 2, ["name"] = "default:stone"}, {["x"] = 1, ["meta"] = {["fields"] = {}, ["inventory"] = {}}, ["y"] = 4, ["z"] = 3, ["name"] = "default:stone"}, {["x"] = 1, ["meta"] = {["fields"] = {}, ["inventory"] = {}}, ["y"] = 4, ["z"] = 4, ["name"] = "default:stone"}, {["x"] = 1, ["meta"] = {["fields"] = {}, ["inventory"] = {}}, ["y"] = 4, ["z"] = 5, ["name"] = "default:stone"}, {["x"] = 1, ["meta"] = {["fields"] = {}, ["inventory"] = {}}, ["y"] = 4, ["z"] = 6, ["name"] = "default:stone"}, {["x"] = 1, ["meta"] = {["fields"] = {}, ["inventory"] = {}}, ["y"] = 4, ["z"] = 7, ["name"] = "default:stone"}, {["x"] = 1, ["meta"] = {["fields"] = {}, ["inventory"] = {}}, ["y"] = 4, ["z"] = 8, ["name"] = "default:stone"}, {["x"] = 1, ["meta"] = {["fields"] = {}, ["inventory"] = {}}, ["y"] = 4, ["z"] = 9, ["name"] = "default:stone"}, {["x"] = 1, ["meta"] = {["fields"] = {}, ["inventory"] = {}}, ["y"] = 5, ["z"] = 1, ["name"] = "default:dirt_with_grass"}, {["x"] = 1, ["meta"] = {["fields"] = {}, ["inventory"] = {}}, ["y"] = 5, ["z"] = 2, ["name"] = "default:stone"}, {["x"] = 1, ["meta"] = {["fields"] = {}, ["inventory"] = {}}, ["y"] = 5, ["z"] = 3, ["name"] = "default:stone"}, {["x"] = 1, ["meta"] = {["fields"] = {}, ["inventory"] = {}}, ["y"] = 5, ["z"] = 4, ["name"] = "default:stone"}, {["x"] = 1, ["meta"] = {["fields"] = {}, ["inventory"] = {}}, ["y"] = 5, ["z"] = 5, ["name"] = "default:stone"}, {["x"] = 1, ["meta"] = {["fields"] = {}, ["inventory"] = {}}, ["y"] = 5, ["z"] = 6, ["name"] = "default:stone"}, {["x"] = 1, ["meta"] = {["fields"] = {}, ["inventory"] = {}}, ["y"] = 5, ["z"] = 7, ["name"] = "default:stone"}, {["x"] = 1, ["meta"] = {["fields"] = {}, ["inventory"] = {}}, ["y"] = 5, ["z"] = 8, ["name"] = "default:stone"}, {["x"] = 1, ["meta"] = {["fields"] = {}, ["inventory"] = {}}, ["y"] = 5, ["z"] = 9, ["name"] = "default:stone"}, {["x"] = 1, ["meta"] = {["fields"] = {}, ["inventory"] = {}}, ["y"] = 6, ["z"] = 2, ["name"] = "default:stone"}, {["x"] = 1, ["meta"] = {["fields"] = {}, ["inventory"] = {}}, ["y"] = 6, ["z"] = 3, ["name"] = "default:stone"}, {["x"] = 1, ["meta"] = {["fields"] = {}, ["inventory"] = {}}, ["y"] = 6, ["z"] = 4, ["name"] = "default:stone"}, {["x"] = 1, ["meta"] = {["fields"] = {}, ["inventory"] = {}}, ["y"] = 6, ["z"] = 5, ["name"] = "default:stone"}, {["x"] = 1, ["meta"] = {["fields"] = {}, ["inventory"] = {}}, ["y"] = 6, ["z"] = 6, ["name"] = "default:stone"}, {["x"] = 1, ["meta"] = {["fields"] = {}, ["inventory"] = {}}, ["y"] = 6, ["z"] = 7, ["name"] = "default:stone"}, {["x"] = 1, ["meta"] = {["fields"] = {}, ["inventory"] = {}}, ["y"] = 6, ["z"] = 8, ["name"] = "default:stone"}, {["x"] = 1, ["meta"] = {["fields"] = {}, ["inventory"] = {}}, ["y"] = 6, ["z"] = 9, ["name"] = "default:stone"}, {["x"] = 1, ["meta"] = {["fields"] = {}, ["inventory"] = {}}, ["y"] = 7, ["z"] = 2, ["name"] = "default:stone"}, {["x"] = 1, ["meta"] = {["fields"] = {}, ["inventory"] = {}}, ["y"] = 7, ["z"] = 3, ["name"] = "default:stone"}, {["x"] = 1, ["meta"] = {["fields"] = {}, ["inventory"] = {}}, ["y"] = 7, ["z"] = 4, ["name"] = "default:stone"}, {["x"] = 1, ["meta"] = {["fields"] = {}, ["inventory"] = {}}, ["y"] = 7, ["z"] = 5, ["name"] = "default:stone"}, {["x"] = 1, ["meta"] = {["fields"] = {}, ["inventory"] = {}}, ["y"] = 7, ["z"] = 6, ["name"] = "default:stone"}, {["x"] = 1, ["meta"] = {["fields"] = {}, ["inventory"] = {}}, ["y"] = 7, ["z"] = 7, ["name"] = "default:stone"}, {["x"] = 1, ["meta"] = {["fields"] = {}, ["inventory"] = {}}, ["y"] = 7, ["z"] = 8, ["name"] = "default:stone"}, {["x"] = 1, ["meta"] = {["fields"] = {}, ["inventory"] = {}}, ["y"] = 7, ["z"] = 9, ["name"] = "default:stone"}, {["x"] = 1, ["meta"] = {["fields"] = {}, ["inventory"] = {}}, ["y"] = 8, ["z"] = 2, ["name"] = "default:stone"}, {["x"] = 1, ["meta"] = {["fields"] = {}, ["inventory"] = {}}, ["y"] = 8, ["z"] = 3, ["name"] = "default:stone"}, {["x"] = 1, ["meta"] = {["fields"] = {}, ["inventory"] = {}}, ["y"] = 8, ["z"] = 4, ["name"] = "default:stone"}, {["x"] = 1, ["meta"] = {["fields"] = {}, ["inventory"] = {}}, ["y"] = 8, ["z"] = 5, ["name"] = "default:stone"}, {["x"] = 1, ["meta"] = {["fields"] = {}, ["inventory"] = {}}, ["y"] = 8, ["z"] = 6, ["name"] = "default:stone"}, {["x"] = 1, ["meta"] = {["fields"] = {}, ["inventory"] = {}}, ["y"] = 8, ["z"] = 7, ["name"] = "default:stone"}, {["x"] = 1, ["meta"] = {["fields"] = {}, ["inventory"] = {}}, ["y"] = 8, ["z"] = 8, ["name"] = "default:stone"}, {["x"] = 1, ["meta"] = {["fields"] = {}, ["inventory"] = {}}, ["y"] = 8, ["z"] = 9, ["name"] = "default:stone"}, {["x"] = 1, ["meta"] = {["fields"] = {}, ["inventory"] = {}}, ["y"] = 9, ["z"] = 2, ["name"] = "default:stone"}, {["x"] = 1, ["meta"] = {["fields"] = {}, ["inventory"] = {}}, ["y"] = 9, ["z"] = 3, ["name"] = "default:stone"}, {["x"] = 1, ["meta"] = {["fields"] = {}, ["inventory"] = {}}, ["y"] = 9, ["z"] = 4, ["name"] = "default:stone"}, {["x"] = 1, ["meta"] = {["fields"] = {}, ["inventory"] = {}}, ["y"] = 9, ["z"] = 5, ["name"] = "default:stone"}, {["x"] = 1, ["meta"] = {["fields"] = {}, ["inventory"] = {}}, ["y"] = 9, ["z"] = 6, ["name"] = "default:stone"}, {["x"] = 1, ["meta"] = {["fields"] = {}, ["inventory"] = {}}, ["y"] = 9, ["z"] = 7, ["name"] = "default:stone"}, {["x"] = 1, ["meta"] = {["fields"] = {}, ["inventory"] = {}}, ["y"] = 9, ["z"] = 8, ["name"] = "default:stone"}, {["x"] = 1, ["meta"] = {["fields"] = {}, ["inventory"] = {}}, ["y"] = 9, ["z"] = 9, ["name"] = "default:stone"}, {["x"] = 1, ["meta"] = {["fields"] = {}, ["inventory"] = {}}, ["y"] = 10, ["z"] = 2, ["name"] = "default:stone"}, {["x"] = 1, ["meta"] = {["fields"] = {}, ["inventory"] = {}}, ["y"] = 10, ["z"] = 3, ["name"] = "default:stone"}, {["x"] = 1, ["meta"] = {["fields"] = {}, ["inventory"] = {}}, ["y"] = 10, ["z"] = 4, ["name"] = "default:stone"}, {["x"] = 1, ["meta"] = {["fields"] = {}, ["inventory"] = {}}, ["y"] = 10, ["z"] = 5, ["name"] = "default:stone"}, {["x"] = 1, ["meta"] = {["fields"] = {}, ["inventory"] = {}}, ["y"] = 10, ["z"] = 6, ["name"] = "default:stone"}, {["x"] = 1, ["meta"] = {["fields"] = {}, ["inventory"] = {}}, ["y"] = 10, ["z"] = 7, ["name"] = "default:stone"}, {["x"] = 1, ["meta"] = {["fields"] = {}, ["inventory"] = {}}, ["y"] = 10, ["z"] = 8, ["name"] = "default:stone"}, {["x"] = 1, ["meta"] = {["fields"] = {}, ["inventory"] = {}}, ["y"] = 10, ["z"] = 9, ["name"] = "default:stone"}, {["x"] = 1, ["meta"] = {["fields"] = {}, ["inventory"] = {}}, ["y"] = 11, ["z"] = 2, ["name"] = "default:dirt"}, {["x"] = 1, ["meta"] = {["fields"] = {}, ["inventory"] = {}}, ["y"] = 11, ["z"] = 3, ["name"] = "default:dirt"}, {["x"] = 1, ["meta"] = {["fields"] = {}, ["inventory"] = {}}, ["y"] = 11, ["z"] = 4, ["name"] = "default:dirt"}, {["x"] = 1, ["meta"] = {["fields"] = {}, ["inventory"] = {}}, ["y"] = 11, ["z"] = 5, ["name"] = "default:dirt"}, {["x"] = 1, ["meta"] = {["fields"] = {}, ["inventory"] = {}}, ["y"] = 11, ["z"] = 6, ["name"] = "default:dirt"}, {["x"] = 1, ["meta"] = {["fields"] = {}, ["inventory"] = {}}, ["y"] = 11, ["z"] = 7, ["name"] = "default:dirt"}, {["x"] = 1, ["meta"] = {["fields"] = {}, ["inventory"] = {}}, ["y"] = 11, ["z"] = 8, ["name"] = "default:dirt"}, {["x"] = 1, ["meta"] = {["fields"] = {}, ["inventory"] = {}}, ["y"] = 11, ["z"] = 9, ["name"] = "default:dirt"}, {["x"] = 1, ["meta"] = {["fields"] = {}, ["inventory"] = {}}, ["y"] = 12, ["z"] = 2, ["name"] = "default:dirt"}, {["x"] = 1, ["meta"] = {["fields"] = {}, ["inventory"] = {}}, ["y"] = 12, ["z"] = 3, ["name"] = "default:dirt"}, {["x"] = 1, ["meta"] = {["fields"] = {}, ["inventory"] = {}}, ["y"] = 12, ["z"] = 4, ["name"] = "default:dirt"}, {["x"] = 1, ["meta"] = {["fields"] = {}, ["inventory"] = {}}, ["y"] = 12, ["z"] = 5, ["name"] = "default:dirt"}, {["x"] = 1, ["meta"] = {["fields"] = {}, ["inventory"] = {}}, ["y"] = 12, ["z"] = 6, ["name"] = "default:dirt"}, {["x"] = 1, ["meta"] = {["fields"] = {}, ["inventory"] = {}}, ["y"] = 12, ["z"] = 7, ["name"] = "default:dirt"}, {["x"] = 1, ["meta"] = {["fields"] = {}, ["inventory"] = {}}, ["y"] = 12, ["z"] = 8, ["name"] = "default:dirt"}, {["x"] = 1, ["meta"] = {["fields"] = {}, ["inventory"] = {}}, ["y"] = 12, ["z"] = 9, ["name"] = "default:dirt"}, {["x"] = 1, ["meta"] = {["fields"] = {}, ["inventory"] = {}}, ["y"] = 13, ["z"] = 2, ["name"] = "default:dirt_with_grass"}, {["x"] = 1, ["meta"] = {["fields"] = {}, ["inventory"] = {}}, ["y"] = 13, ["z"] = 3, ["name"] = "default:dirt_with_grass"}, {["x"] = 1, ["meta"] = {["fields"] = {}, ["inventory"] = {}}, ["y"] = 13, ["z"] = 4, ["name"] = "default:dirt_with_grass"}, {["x"] = 1, ["meta"] = {["fields"] = {}, ["inventory"] = {}}, ["y"] = 13, ["z"] = 5, ["name"] = "default:dirt_with_grass"}, {["x"] = 1, ["meta"] = {["fields"] = {}, ["inventory"] = {}}, ["y"] = 13, ["z"] = 6, ["name"] = "default:dirt_with_grass"}, {["x"] = 1, ["meta"] = {["fields"] = {}, ["inventory"] = {}}, ["y"] = 13, ["z"] = 7, ["name"] = "default:dirt_with_grass"}, {["x"] = 1, ["meta"] = {["fields"] = {}, ["inventory"] = {}}, ["y"] = 13, ["z"] = 8, ["name"] = "default:dirt_with_grass"}, {["x"] = 1, ["meta"] = {["fields"] = {}, ["inventory"] = {}}, ["y"] = 13, ["z"] = 9, ["name"] = "default:dirt_with_grass"}, {["x"] = 2, ["meta"] = {["fields"] = {}, ["inventory"] = {}}, ["y"] = 0, ["z"] = 0, ["name"] = "default:dirt"}, {["x"] = 2, ["meta"] = {["fields"] = {}, ["inventory"] = {}}, ["y"] = 0, ["z"] = 1, ["name"] = "default:stone"}, {["x"] = 2, ["meta"] = {["fields"] = {}, ["inventory"] = {}}, ["y"] = 0, ["z"] = 2, ["name"] = "default:stone"}, {["x"] = 2, ["meta"] = {["fields"] = {}, ["inventory"] = {}}, ["y"] = 0, ["z"] = 3, ["name"] = "default:stone"}, {["x"] = 2, ["meta"] = {["fields"] = {}, ["inventory"] = {}}, ["y"] = 0, ["z"] = 4, ["name"] = "default:stone"}, {["x"] = 2, ["meta"] = {["fields"] = {}, ["inventory"] = {}}, ["y"] = 0, ["z"] = 5, ["name"] = "default:stone"}, {["x"] = 2, ["meta"] = {["fields"] = {}, ["inventory"] = {}}, ["y"] = 0, ["z"] = 6, ["name"] = "default:stone"}, {["x"] = 2, ["meta"] = {["fields"] = {}, ["inventory"] = {}}, ["y"] = 0, ["z"] = 7, ["name"] = "default:stone"}, {["x"] = 2, ["meta"] = {["fields"] = {}, ["inventory"] = {}}, ["y"] = 0, ["z"] = 8, ["name"] = "default:stone"}, {["x"] = 2, ["meta"] = {["fields"] = {}, ["inventory"] = {}}, ["y"] = 0, ["z"] = 9, ["name"] = "default:stone"}, {["x"] = 2, ["meta"] = {["fields"] = {}, ["inventory"] = {}}, ["y"] = 0, ["z"] = 10, ["name"] = "default:stone"}, {["x"] = 2, ["meta"] = {["fields"] = {}, ["inventory"] = {}}, ["y"] = 0, ["z"] = 11, ["name"] = "default:dirt"}, {["x"] = 2, ["meta"] = {["fields"] = {}, ["inventory"] = {}}, ["y"] = 0, ["z"] = 12, ["name"] = "default:dirt"}, {["x"] = 2, ["meta"] = {["fields"] = {}, ["inventory"] = {}}, ["y"] = 0, ["z"] = 13, ["name"] = "default:dirt_with_grass"}, {["x"] = 2, ["meta"] = {["fields"] = {}, ["inventory"] = {}}, ["y"] = 1, ["z"] = 0, ["name"] = "default:dirt"}, {["x"] = 2, ["meta"] = {["fields"] = {}, ["inventory"] = {}}, ["y"] = 1, ["z"] = 1, ["name"] = "default:stone"}, {["x"] = 2, ["meta"] = {["fields"] = {}, ["inventory"] = {}}, ["y"] = 1, ["z"] = 2, ["name"] = "default:stone"}, {["x"] = 2, ["meta"] = {["fields"] = {}, ["inventory"] = {}}, ["y"] = 1, ["z"] = 3, ["name"] = "default:stone"}, {["x"] = 2, ["meta"] = {["fields"] = {}, ["inventory"] = {}}, ["y"] = 1, ["z"] = 4, ["name"] = "default:stone"}, {["x"] = 2, ["meta"] = {["fields"] = {}, ["inventory"] = {}}, ["y"] = 1, ["z"] = 5, ["name"] = "default:stone"}, {["x"] = 2, ["meta"] = {["fields"] = {}, ["inventory"] = {}}, ["y"] = 1, ["z"] = 6, ["name"] = "default:stone"}, {["x"] = 2, ["meta"] = {["fields"] = {}, ["inventory"] = {}}, ["y"] = 1, ["z"] = 7, ["name"] = "default:stone"}, {["x"] = 2, ["meta"] = {["fields"] = {}, ["inventory"] = {}}, ["y"] = 1, ["z"] = 8, ["name"] = "default:stone"}, {["x"] = 2, ["meta"] = {["fields"] = {}, ["inventory"] = {}}, ["y"] = 1, ["z"] = 9, ["name"] = "default:stone"}, {["x"] = 2, ["meta"] = {["fields"] = {}, ["inventory"] = {}}, ["y"] = 1, ["z"] = 10, ["name"] = "default:stone"}, {["x"] = 2, ["meta"] = {["fields"] = {}, ["inventory"] = {}}, ["y"] = 1, ["z"] = 11, ["name"] = "default:dirt"}, {["x"] = 2, ["meta"] = {["fields"] = {}, ["inventory"] = {}}, ["y"] = 1, ["z"] = 12, ["name"] = "default:dirt_with_grass"}, {["x"] = 2, ["meta"] = {["fields"] = {}, ["inventory"] = {}}, ["y"] = 2, ["z"] = 0, ["name"] = "default:dirt"}, {["x"] = 2, ["meta"] = {["fields"] = {}, ["inventory"] = {}}, ["y"] = 2, ["z"] = 1, ["name"] = "default:stone"}, {["x"] = 2, ["meta"] = {["fields"] = {}, ["inventory"] = {}}, ["y"] = 2, ["z"] = 2, ["name"] = "default:stone"}, {["x"] = 2, ["meta"] = {["fields"] = {}, ["inventory"] = {}}, ["y"] = 2, ["z"] = 3, ["name"] = "default:stone"}, {["x"] = 2, ["meta"] = {["fields"] = {}, ["inventory"] = {}}, ["y"] = 2, ["z"] = 4, ["name"] = "default:stone"}, {["x"] = 2, ["meta"] = {["fields"] = {}, ["inventory"] = {}}, ["y"] = 2, ["z"] = 5, ["name"] = "default:stone"}, {["x"] = 2, ["meta"] = {["fields"] = {}, ["inventory"] = {}}, ["y"] = 2, ["z"] = 6, ["name"] = "default:stone"}, {["x"] = 2, ["meta"] = {["fields"] = {}, ["inventory"] = {}}, ["y"] = 2, ["z"] = 7, ["name"] = "default:stone"}, {["x"] = 2, ["meta"] = {["fields"] = {}, ["inventory"] = {}}, ["y"] = 2, ["z"] = 8, ["name"] = "default:stone"}, {["x"] = 2, ["meta"] = {["fields"] = {}, ["inventory"] = {}}, ["y"] = 2, ["z"] = 9, ["name"] = "default:stone"}, {["x"] = 2, ["meta"] = {["fields"] = {}, ["inventory"] = {}}, ["y"] = 2, ["z"] = 10, ["name"] = "default:stone"}, {["x"] = 2, ["meta"] = {["fields"] = {}, ["inventory"] = {}}, ["y"] = 2, ["z"] = 11, ["name"] = "default:dirt"}, {["x"] = 2, ["meta"] = {["fields"] = {}, ["inventory"] = {}}, ["y"] = 3, ["z"] = 0, ["name"] = "default:dirt"}, {["x"] = 2, ["meta"] = {["fields"] = {}, ["inventory"] = {}}, ["y"] = 3, ["z"] = 1, ["name"] = "default:stone"}, {["x"] = 2, ["meta"] = {["fields"] = {}, ["inventory"] = {}}, ["y"] = 3, ["z"] = 2, ["name"] = "default:stone"}, {["x"] = 2, ["meta"] = {["fields"] = {}, ["inventory"] = {}}, ["y"] = 3, ["z"] = 3, ["name"] = "default:stone"}, {["x"] = 2, ["meta"] = {["fields"] = {}, ["inventory"] = {}}, ["y"] = 3, ["z"] = 4, ["name"] = "default:stone"}, {["x"] = 2, ["meta"] = {["fields"] = {}, ["inventory"] = {}}, ["y"] = 3, ["z"] = 5, ["name"] = "default:stone"}, {["x"] = 2, ["meta"] = {["fields"] = {}, ["inventory"] = {}}, ["y"] = 3, ["z"] = 6, ["name"] = "default:stone"}, {["x"] = 2, ["meta"] = {["fields"] = {}, ["inventory"] = {}}, ["y"] = 3, ["z"] = 7, ["name"] = "default:stone"}, {["x"] = 2, ["meta"] = {["fields"] = {}, ["inventory"] = {}}, ["y"] = 3, ["z"] = 8, ["name"] = "default:stone"}, {["x"] = 2, ["meta"] = {["fields"] = {}, ["inventory"] = {}}, ["y"] = 3, ["z"] = 9, ["name"] = "default:stone"}, {["x"] = 2, ["meta"] = {["fields"] = {}, ["inventory"] = {}}, ["y"] = 3, ["z"] = 10, ["name"] = "default:stone"}, {["x"] = 2, ["meta"] = {["fields"] = {}, ["inventory"] = {}}, ["y"] = 3, ["z"] = 11, ["name"] = "default:dirt_with_grass"}, {["x"] = 2, ["meta"] = {["fields"] = {}, ["inventory"] = {}}, ["y"] = 4, ["z"] = 0, ["name"] = "default:dirt_with_grass"}, {["x"] = 2, ["meta"] = {["fields"] = {}, ["inventory"] = {}}, ["y"] = 4, ["z"] = 1, ["name"] = "default:stone"}, {["x"] = 2, ["meta"] = {["fields"] = {}, ["inventory"] = {}}, ["y"] = 4, ["z"] = 2, ["name"] = "default:stone"}, {["x"] = 2, ["meta"] = {["fields"] = {}, ["inventory"] = {}}, ["y"] = 4, ["z"] = 3, ["name"] = "default:stone"}, {["x"] = 2, ["meta"] = {["fields"] = {}, ["inventory"] = {}}, ["y"] = 4, ["z"] = 4, ["name"] = "default:stone"}, {["x"] = 2, ["meta"] = {["fields"] = {}, ["inventory"] = {}}, ["y"] = 4, ["z"] = 5, ["name"] = "default:stone"}, {["x"] = 2, ["meta"] = {["fields"] = {}, ["inventory"] = {}}, ["y"] = 4, ["z"] = 6, ["name"] = "default:stone"}, {["x"] = 2, ["meta"] = {["fields"] = {}, ["inventory"] = {}}, ["y"] = 4, ["z"] = 7, ["name"] = "default:stone"}, {["x"] = 2, ["meta"] = {["fields"] = {}, ["inventory"] = {}}, ["y"] = 4, ["z"] = 8, ["name"] = "default:stone"}, {["x"] = 2, ["meta"] = {["fields"] = {}, ["inventory"] = {}}, ["y"] = 4, ["z"] = 9, ["name"] = "default:stone"}, {["x"] = 2, ["meta"] = {["fields"] = {}, ["inventory"] = {}}, ["y"] = 4, ["z"] = 10, ["name"] = "default:stone"}, {["x"] = 2, ["meta"] = {["fields"] = {}, ["inventory"] = {}}, ["y"] = 5, ["z"] = 1, ["name"] = "default:stone"}, {["x"] = 2, ["meta"] = {["fields"] = {}, ["inventory"] = {}}, ["y"] = 5, ["z"] = 2, ["name"] = "default:stone"}, {["x"] = 2, ["meta"] = {["fields"] = {}, ["inventory"] = {}}, ["y"] = 5, ["z"] = 3, ["name"] = "default:stone"}, {["x"] = 2, ["meta"] = {["fields"] = {}, ["inventory"] = {}}, ["y"] = 5, ["z"] = 4, ["name"] = "default:stone"}, {["x"] = 2, ["meta"] = {["fields"] = {}, ["inventory"] = {}}, ["y"] = 5, ["z"] = 5, ["name"] = "default:stone"}, {["x"] = 2, ["meta"] = {["fields"] = {}, ["inventory"] = {}}, ["y"] = 5, ["z"] = 6, ["name"] = "default:stone"}, {["x"] = 2, ["meta"] = {["fields"] = {}, ["inventory"] = {}}, ["y"] = 5, ["z"] = 7, ["name"] = "default:stone"}, {["x"] = 2, ["meta"] = {["fields"] = {}, ["inventory"] = {}}, ["y"] = 5, ["z"] = 8, ["name"] = "default:stone"}, {["x"] = 2, ["meta"] = {["fields"] = {}, ["inventory"] = {}}, ["y"] = 5, ["z"] = 9, ["name"] = "default:stone"}, {["x"] = 2, ["meta"] = {["fields"] = {}, ["inventory"] = {}}, ["y"] = 5, ["z"] = 10, ["name"] = "default:stone"}, {["x"] = 2, ["meta"] = {["fields"] = {}, ["inventory"] = {}}, ["y"] = 6, ["z"] = 1, ["name"] = "default:stone"}, {["x"] = 2, ["meta"] = {["fields"] = {}, ["inventory"] = {}}, ["y"] = 6, ["z"] = 2, ["name"] = "default:stone"}, {["x"] = 2, ["meta"] = {["fields"] = {}, ["inventory"] = {}}, ["y"] = 6, ["z"] = 3, ["name"] = "default:stone"}, {["x"] = 2, ["meta"] = {["fields"] = {}, ["inventory"] = {}}, ["y"] = 6, ["z"] = 4, ["name"] = "default:stone"}, {["x"] = 2, ["meta"] = {["fields"] = {}, ["inventory"] = {}}, ["y"] = 6, ["z"] = 5, ["name"] = "default:stone"}, {["x"] = 2, ["meta"] = {["fields"] = {}, ["inventory"] = {}}, ["y"] = 6, ["z"] = 6, ["name"] = "default:stone"}, {["x"] = 2, ["meta"] = {["fields"] = {}, ["inventory"] = {}}, ["y"] = 6, ["z"] = 7, ["name"] = "default:stone"}, {["x"] = 2, ["meta"] = {["fields"] = {}, ["inventory"] = {}}, ["y"] = 6, ["z"] = 8, ["name"] = "default:stone"}, {["x"] = 2, ["meta"] = {["fields"] = {}, ["inventory"] = {}}, ["y"] = 6, ["z"] = 9, ["name"] = "default:stone"}, {["x"] = 2, ["meta"] = {["fields"] = {}, ["inventory"] = {}}, ["y"] = 6, ["z"] = 10, ["name"] = "default:stone"}, {["x"] = 2, ["meta"] = {["fields"] = {}, ["inventory"] = {}}, ["y"] = 7, ["z"] = 1, ["name"] = "default:stone"}, {["x"] = 2, ["meta"] = {["fields"] = {}, ["inventory"] = {}}, ["y"] = 7, ["z"] = 2, ["name"] = "default:stone"}, {["x"] = 2, ["meta"] = {["fields"] = {}, ["inventory"] = {}}, ["y"] = 7, ["z"] = 3, ["name"] = "default:stone"}, {["x"] = 2, ["meta"] = {["fields"] = {}, ["inventory"] = {}}, ["y"] = 7, ["z"] = 4, ["name"] = "default:stone"}, {["x"] = 2, ["meta"] = {["fields"] = {}, ["inventory"] = {}}, ["y"] = 7, ["z"] = 5, ["name"] = "default:stone"}, {["x"] = 2, ["meta"] = {["fields"] = {}, ["inventory"] = {}}, ["y"] = 7, ["z"] = 6, ["name"] = "default:stone"}, {["x"] = 2, ["meta"] = {["fields"] = {}, ["inventory"] = {}}, ["y"] = 7, ["z"] = 7, ["name"] = "default:stone"}, {["x"] = 2, ["meta"] = {["fields"] = {}, ["inventory"] = {}}, ["y"] = 7, ["z"] = 8, ["name"] = "default:stone"}, {["x"] = 2, ["meta"] = {["fields"] = {}, ["inventory"] = {}}, ["y"] = 7, ["z"] = 9, ["name"] = "default:stone"}, {["x"] = 2, ["meta"] = {["fields"] = {}, ["inventory"] = {}}, ["y"] = 7, ["z"] = 10, ["name"] = "default:stone"}, {["x"] = 2, ["meta"] = {["fields"] = {}, ["inventory"] = {}}, ["y"] = 8, ["z"] = 1, ["name"] = "default:stone"}, {["x"] = 2, ["meta"] = {["fields"] = {}, ["inventory"] = {}}, ["y"] = 8, ["z"] = 2, ["name"] = "default:stone"}, {["x"] = 2, ["meta"] = {["fields"] = {}, ["inventory"] = {}}, ["y"] = 8, ["z"] = 3, ["name"] = "default:stone"}, {["x"] = 2, ["meta"] = {["fields"] = {}, ["inventory"] = {}}, ["y"] = 8, ["z"] = 4, ["name"] = "default:stone"}, {["x"] = 2, ["meta"] = {["fields"] = {}, ["inventory"] = {}}, ["y"] = 8, ["z"] = 5, ["name"] = "default:stone"}, {["x"] = 2, ["meta"] = {["fields"] = {}, ["inventory"] = {}}, ["y"] = 8, ["z"] = 6, ["name"] = "default:stone"}, {["x"] = 2, ["meta"] = {["fields"] = {}, ["inventory"] = {}}, ["y"] = 8, ["z"] = 7, ["name"] = "default:stone"}, {["x"] = 2, ["meta"] = {["fields"] = {}, ["inventory"] = {}}, ["y"] = 8, ["z"] = 8, ["name"] = "default:stone"}, {["x"] = 2, ["meta"] = {["fields"] = {}, ["inventory"] = {}}, ["y"] = 8, ["z"] = 9, ["name"] = "default:stone"}, {["x"] = 2, ["meta"] = {["fields"] = {}, ["inventory"] = {}}, ["y"] = 8, ["z"] = 10, ["name"] = "default:stone"}, {["x"] = 2, ["meta"] = {["fields"] = {}, ["inventory"] = {}}, ["y"] = 9, ["z"] = 1, ["name"] = "default:stone_with_coal"}, {["x"] = 2, ["meta"] = {["fields"] = {}, ["inventory"] = {}}, ["y"] = 9, ["z"] = 2, ["name"] = "default:stone"}, {["x"] = 2, ["meta"] = {["fields"] = {}, ["inventory"] = {}}, ["y"] = 9, ["z"] = 3, ["name"] = "default:stone_with_coal"}, {["x"] = 2, ["meta"] = {["fields"] = {}, ["inventory"] = {}}, ["y"] = 9, ["z"] = 4, ["name"] = "default:stone"}, {["x"] = 2, ["meta"] = {["fields"] = {}, ["inventory"] = {}}, ["y"] = 9, ["z"] = 7, ["name"] = "default:stone"}, {["x"] = 2, ["meta"] = {["fields"] = {}, ["inventory"] = {}}, ["y"] = 9, ["z"] = 8, ["name"] = "default:stone"}, {["x"] = 2, ["meta"] = {["fields"] = {}, ["inventory"] = {}}, ["y"] = 9, ["z"] = 9, ["name"] = "default:stone"}, {["x"] = 2, ["meta"] = {["fields"] = {}, ["inventory"] = {}}, ["y"] = 9, ["z"] = 10, ["name"] = "default:stone"}, {["x"] = 2, ["meta"] = {["fields"] = {}, ["inventory"] = {}}, ["y"] = 10, ["z"] = 1, ["name"] = "default:stone"}, {["x"] = 2, ["meta"] = {["fields"] = {}, ["inventory"] = {}}, ["y"] = 10, ["z"] = 2, ["name"] = "default:stone"}, {["x"] = 2, ["meta"] = {["fields"] = {}, ["inventory"] = {}}, ["y"] = 10, ["z"] = 3, ["name"] = "default:stone"}, {["x"] = 2, ["meta"] = {["fields"] = {}, ["inventory"] = {}}, ["y"] = 10, ["z"] = 4, ["name"] = "default:stone"}, {["x"] = 2, ["meta"] = {["fields"] = {}, ["inventory"] = {}}, ["y"] = 10, ["z"] = 5, ["name"] = "default:stone"}, {["x"] = 2, ["meta"] = {["fields"] = {}, ["inventory"] = {}}, ["y"] = 10, ["z"] = 6, ["name"] = "default:stone"}, {["x"] = 2, ["meta"] = {["fields"] = {}, ["inventory"] = {}}, ["y"] = 10, ["z"] = 7, ["name"] = "default:stone"}, {["x"] = 2, ["meta"] = {["fields"] = {}, ["inventory"] = {}}, ["y"] = 10, ["z"] = 8, ["name"] = "default:stone"}, {["x"] = 2, ["meta"] = {["fields"] = {}, ["inventory"] = {}}, ["y"] = 10, ["z"] = 9, ["name"] = "default:stone"}, {["x"] = 2, ["meta"] = {["fields"] = {}, ["inventory"] = {}}, ["y"] = 10, ["z"] = 10, ["name"] = "default:stone"}, {["x"] = 2, ["meta"] = {["fields"] = {}, ["inventory"] = {}}, ["y"] = 11, ["z"] = 1, ["name"] = "default:dirt"}, {["x"] = 2, ["meta"] = {["fields"] = {}, ["inventory"] = {}}, ["y"] = 11, ["z"] = 2, ["name"] = "default:dirt"}, {["x"] = 2, ["meta"] = {["fields"] = {}, ["inventory"] = {}}, ["y"] = 11, ["z"] = 3, ["name"] = "default:dirt"}, {["x"] = 2, ["meta"] = {["fields"] = {}, ["inventory"] = {}}, ["y"] = 11, ["z"] = 4, ["name"] = "default:dirt"}, {["x"] = 2, ["meta"] = {["fields"] = {}, ["inventory"] = {}}, ["y"] = 11, ["z"] = 5, ["name"] = "default:dirt"}, {["x"] = 2, ["meta"] = {["fields"] = {}, ["inventory"] = {}}, ["y"] = 11, ["z"] = 6, ["name"] = "default:dirt"}, {["x"] = 2, ["meta"] = {["fields"] = {}, ["inventory"] = {}}, ["y"] = 11, ["z"] = 7, ["name"] = "default:dirt"}, {["x"] = 2, ["meta"] = {["fields"] = {}, ["inventory"] = {}}, ["y"] = 11, ["z"] = 8, ["name"] = "default:dirt"}, {["x"] = 2, ["meta"] = {["fields"] = {}, ["inventory"] = {}}, ["y"] = 11, ["z"] = 9, ["name"] = "default:dirt"}, {["x"] = 2, ["meta"] = {["fields"] = {}, ["inventory"] = {}}, ["y"] = 11, ["z"] = 10, ["name"] = "default:dirt"}, {["x"] = 2, ["meta"] = {["fields"] = {}, ["inventory"] = {}}, ["y"] = 12, ["z"] = 1, ["name"] = "default:dirt"}, {["x"] = 2, ["meta"] = {["fields"] = {}, ["inventory"] = {}}, ["y"] = 12, ["z"] = 2, ["name"] = "default:dirt"}, {["x"] = 2, ["meta"] = {["fields"] = {}, ["inventory"] = {}}, ["y"] = 12, ["z"] = 3, ["name"] = "default:dirt"}, {["x"] = 2, ["meta"] = {["fields"] = {}, ["inventory"] = {}}, ["y"] = 12, ["z"] = 4, ["name"] = "default:dirt"}, {["x"] = 2, ["meta"] = {["fields"] = {}, ["inventory"] = {}}, ["y"] = 12, ["z"] = 5, ["name"] = "default:dirt"}, {["x"] = 2, ["meta"] = {["fields"] = {}, ["inventory"] = {}}, ["y"] = 12, ["z"] = 6, ["name"] = "default:dirt"}, {["x"] = 2, ["meta"] = {["fields"] = {}, ["inventory"] = {}}, ["y"] = 12, ["z"] = 7, ["name"] = "default:dirt"}, {["x"] = 2, ["meta"] = {["fields"] = {}, ["inventory"] = {}}, ["y"] = 12, ["z"] = 8, ["name"] = "default:dirt"}, {["x"] = 2, ["meta"] = {["fields"] = {}, ["inventory"] = {}}, ["y"] = 12, ["z"] = 9, ["name"] = "default:dirt"}, {["x"] = 2, ["meta"] = {["fields"] = {}, ["inventory"] = {}}, ["y"] = 12, ["z"] = 10, ["name"] = "default:dirt"}, {["x"] = 2, ["meta"] = {["fields"] = {}, ["inventory"] = {}}, ["y"] = 13, ["z"] = 1, ["name"] = "default:dirt_with_grass"}, {["x"] = 2, ["meta"] = {["fields"] = {}, ["inventory"] = {}}, ["y"] = 13, ["z"] = 2, ["name"] = "default:dirt_with_grass"}, {["x"] = 2, ["meta"] = {["fields"] = {}, ["inventory"] = {}}, ["y"] = 13, ["z"] = 3, ["name"] = "default:dirt"}, {["x"] = 2, ["meta"] = {["fields"] = {}, ["inventory"] = {}}, ["y"] = 13, ["z"] = 4, ["name"] = "default:dirt"}, {["x"] = 2, ["meta"] = {["fields"] = {}, ["inventory"] = {}}, ["y"] = 13, ["z"] = 5, ["name"] = "default:dirt"}, {["x"] = 2, ["meta"] = {["fields"] = {}, ["inventory"] = {}}, ["y"] = 13, ["z"] = 6, ["name"] = "default:dirt"}, {["x"] = 2, ["meta"] = {["fields"] = {}, ["inventory"] = {}}, ["y"] = 13, ["z"] = 7, ["name"] = "default:dirt"}, {["x"] = 2, ["meta"] = {["fields"] = {}, ["inventory"] = {}}, ["y"] = 13, ["z"] = 8, ["name"] = "default:dirt"}, {["x"] = 2, ["meta"] = {["fields"] = {}, ["inventory"] = {}}, ["y"] = 13, ["z"] = 9, ["name"] = "default:dirt"}, {["x"] = 2, ["meta"] = {["fields"] = {}, ["inventory"] = {}}, ["y"] = 13, ["z"] = 10, ["name"] = "default:dirt_with_grass"}, {["x"] = 2, ["meta"] = {["fields"] = {}, ["inventory"] = {}}, ["y"] = 14, ["param1"] = 13, ["z"] = 3, ["name"] = "mesecons_random:ghoststone_active"}, {["x"] = 2, ["meta"] = {["fields"] = {}, ["inventory"] = {}}, ["y"] = 14, ["param1"] = 13, ["z"] = 4, ["name"] = "mesecons_random:ghoststone_active"}, {["x"] = 2, ["meta"] = {["fields"] = {}, ["inventory"] = {}}, ["y"] = 14, ["param1"] = 13, ["z"] = 5, ["name"] = "mesecons_random:ghoststone_active"}, {["x"] = 2, ["meta"] = {["fields"] = {}, ["inventory"] = {}}, ["y"] = 14, ["param1"] = 13, ["z"] = 6, ["name"] = "mesecons_random:ghoststone_active"}, {["x"] = 2, ["meta"] = {["fields"] = {}, ["inventory"] = {}}, ["y"] = 14, ["param1"] = 13, ["z"] = 7, ["name"] = "mesecons_random:ghoststone_active"}, {["x"] = 2, ["meta"] = {["fields"] = {}, ["inventory"] = {}}, ["y"] = 14, ["param1"] = 13, ["z"] = 8, ["name"] = "mesecons_random:ghoststone_active"}, {["x"] = 2, ["meta"] = {["fields"] = {}, ["inventory"] = {}}, ["y"] = 14, ["param1"] = 13, ["z"] = 9, ["name"] = "mesecons_random:ghoststone_active"}, {["x"] = 2, ["meta"] = {["fields"] = {}, ["inventory"] = {}}, ["y"] = 15, ["param1"] = 13, ["z"] = 3, ["name"] = "mesecons_random:ghoststone_active"}, {["x"] = 2, ["meta"] = {["fields"] = {}, ["inventory"] = {}}, ["y"] = 15, ["param1"] = 13, ["z"] = 4, ["name"] = "mesecons_random:ghoststone_active"}, {["x"] = 2, ["meta"] = {["fields"] = {}, ["inventory"] = {}}, ["y"] = 15, ["param1"] = 13, ["z"] = 5, ["name"] = "mesecons_random:ghoststone_active"}, {["x"] = 2, ["meta"] = {["fields"] = {}, ["inventory"] = {}}, ["y"] = 15, ["param1"] = 13, ["z"] = 6, ["name"] = "mesecons_random:ghoststone_active"}, {["x"] = 2, ["meta"] = {["fields"] = {}, ["inventory"] = {}}, ["y"] = 15, ["param1"] = 13, ["z"] = 7, ["name"] = "mesecons_random:ghoststone_active"}, {["x"] = 2, ["meta"] = {["fields"] = {}, ["inventory"] = {}}, ["y"] = 15, ["param1"] = 13, ["z"] = 8, ["name"] = "mesecons_random:ghoststone_active"}, {["x"] = 2, ["meta"] = {["fields"] = {}, ["inventory"] = {}}, ["y"] = 15, ["param1"] = 13, ["z"] = 9, ["name"] = "mesecons_random:ghoststone_active"}, {["x"] = 2, ["meta"] = {["fields"] = {}, ["inventory"] = {}}, ["y"] = 16, ["param1"] = 13, ["z"] = 3, ["name"] = "mesecons_random:ghoststone_active"}, {["x"] = 2, ["meta"] = {["fields"] = {}, ["inventory"] = {}}, ["y"] = 16, ["param1"] = 15, ["z"] = 4, ["name"] = "mesecons_random:ghoststone_active"}, {["x"] = 2, ["meta"] = {["fields"] = {}, ["inventory"] = {}}, ["y"] = 16, ["param1"] = 15, ["z"] = 5, ["name"] = "mesecons_random:ghoststone_active"}, {["x"] = 2, ["meta"] = {["fields"] = {}, ["inventory"] = {}}, ["y"] = 16, ["param1"] = 15, ["z"] = 6, ["name"] = "mesecons_random:ghoststone_active"}, {["x"] = 2, ["meta"] = {["fields"] = {}, ["inventory"] = {}}, ["y"] = 16, ["param1"] = 15, ["z"] = 7, ["name"] = "mesecons_random:ghoststone_active"}, {["x"] = 2, ["meta"] = {["fields"] = {}, ["inventory"] = {}}, ["y"] = 16, ["param1"] = 15, ["z"] = 8, ["name"] = "mesecons_random:ghoststone_active"}, {["x"] = 2, ["meta"] = {["fields"] = {}, ["inventory"] = {}}, ["y"] = 16, ["param1"] = 15, ["z"] = 9, ["name"] = "mesecons_random:ghoststone_active"}, {["x"] = 2, ["meta"] = {["fields"] = {}, ["inventory"] = {}}, ["y"] = 17, ["param1"] = 15, ["z"] = 3, ["name"] = "mesecons_random:ghoststone_active"}, {["x"] = 2, ["meta"] = {["fields"] = {}, ["inventory"] = {}}, ["y"] = 17, ["param1"] = 15, ["z"] = 4, ["name"] = "mesecons_random:ghoststone_active"}, {["x"] = 2, ["meta"] = {["fields"] = {}, ["inventory"] = {}}, ["y"] = 17, ["param1"] = 15, ["z"] = 5, ["name"] = "mesecons_random:ghoststone_active"}, {["x"] = 2, ["meta"] = {["fields"] = {}, ["inventory"] = {}}, ["y"] = 17, ["param1"] = 15, ["z"] = 6, ["name"] = "mesecons_random:ghoststone_active"}, {["x"] = 2, ["meta"] = {["fields"] = {}, ["inventory"] = {}}, ["y"] = 17, ["param1"] = 15, ["z"] = 7, ["name"] = "mesecons_random:ghoststone_active"}, {["x"] = 2, ["meta"] = {["fields"] = {}, ["inventory"] = {}}, ["y"] = 17, ["param1"] = 15, ["z"] = 8, ["name"] = "mesecons_random:ghoststone_active"}, {["x"] = 2, ["meta"] = {["fields"] = {}, ["inventory"] = {}}, ["y"] = 17, ["param1"] = 15, ["z"] = 9, ["name"] = "mesecons_random:ghoststone_active"}, {["x"] = 3, ["meta"] = {["fields"] = {}, ["inventory"] = {}}, ["y"] = 0, ["z"] = 0, ["name"] = "default:dirt"}, {["x"] = 3, ["meta"] = {["fields"] = {}, ["inventory"] = {}}, ["y"] = 0, ["z"] = 1, ["name"] = "default:stone"}, {["x"] = 3, ["meta"] = {["fields"] = {}, ["inventory"] = {}}, ["y"] = 0, ["z"] = 2, ["name"] = "default:stone"}, {["x"] = 3, ["meta"] = {["fields"] = {}, ["inventory"] = {}}, ["y"] = 0, ["z"] = 3, ["name"] = "default:stone"}, {["x"] = 3, ["meta"] = {["fields"] = {}, ["inventory"] = {}}, ["y"] = 0, ["z"] = 4, ["name"] = "default:stone"}, {["x"] = 3, ["meta"] = {["fields"] = {}, ["inventory"] = {}}, ["y"] = 0, ["z"] = 5, ["name"] = "default:stone"}, {["x"] = 3, ["meta"] = {["fields"] = {}, ["inventory"] = {}}, ["y"] = 0, ["z"] = 6, ["name"] = "default:stone"}, {["x"] = 3, ["meta"] = {["fields"] = {}, ["inventory"] = {}}, ["y"] = 0, ["z"] = 7, ["name"] = "default:stone"}, {["x"] = 3, ["meta"] = {["fields"] = {}, ["inventory"] = {}}, ["y"] = 0, ["z"] = 8, ["name"] = "default:stone"}, {["x"] = 3, ["meta"] = {["fields"] = {}, ["inventory"] = {}}, ["y"] = 0, ["z"] = 9, ["name"] = "default:stone"}, {["x"] = 3, ["meta"] = {["fields"] = {}, ["inventory"] = {}}, ["y"] = 0, ["z"] = 10, ["name"] = "default:stone"}, {["x"] = 3, ["meta"] = {["fields"] = {}, ["inventory"] = {}}, ["y"] = 0, ["z"] = 11, ["name"] = "default:stone"}, {["x"] = 3, ["meta"] = {["fields"] = {}, ["inventory"] = {}}, ["y"] = 0, ["z"] = 12, ["name"] = "default:dirt"}, {["x"] = 3, ["meta"] = {["fields"] = {}, ["inventory"] = {}}, ["y"] = 0, ["z"] = 13, ["name"] = "default:dirt_with_grass"}, {["x"] = 3, ["meta"] = {["fields"] = {}, ["inventory"] = {}}, ["y"] = 0, ["z"] = 14, ["name"] = "default:dirt_with_grass"}, {["x"] = 3, ["meta"] = {["fields"] = {}, ["inventory"] = {}}, ["y"] = 1, ["z"] = 0, ["name"] = "default:dirt"}, {["x"] = 3, ["meta"] = {["fields"] = {}, ["inventory"] = {}}, ["y"] = 1, ["z"] = 1, ["name"] = "default:stone"}, {["x"] = 3, ["meta"] = {["fields"] = {}, ["inventory"] = {}}, ["y"] = 1, ["z"] = 2, ["name"] = "default:stone"}, {["x"] = 3, ["meta"] = {["fields"] = {}, ["inventory"] = {}}, ["y"] = 1, ["z"] = 3, ["name"] = "default:stone"}, {["x"] = 3, ["meta"] = {["fields"] = {}, ["inventory"] = {}}, ["y"] = 1, ["z"] = 4, ["name"] = "default:stone"}, {["x"] = 3, ["meta"] = {["fields"] = {}, ["inventory"] = {}}, ["y"] = 1, ["z"] = 5, ["name"] = "default:stone"}, {["x"] = 3, ["meta"] = {["fields"] = {}, ["inventory"] = {}}, ["y"] = 1, ["z"] = 6, ["name"] = "default:stone"}, {["x"] = 3, ["meta"] = {["fields"] = {}, ["inventory"] = {}}, ["y"] = 1, ["z"] = 7, ["name"] = "default:stone"}, {["x"] = 3, ["meta"] = {["fields"] = {}, ["inventory"] = {}}, ["y"] = 1, ["z"] = 8, ["name"] = "default:stone"}, {["x"] = 3, ["meta"] = {["fields"] = {}, ["inventory"] = {}}, ["y"] = 1, ["z"] = 9, ["name"] = "default:stone"}, {["x"] = 3, ["meta"] = {["fields"] = {}, ["inventory"] = {}}, ["y"] = 1, ["z"] = 10, ["name"] = "default:stone"}, {["x"] = 3, ["meta"] = {["fields"] = {}, ["inventory"] = {}}, ["y"] = 1, ["z"] = 11, ["name"] = "default:stone"}, {["x"] = 3, ["meta"] = {["fields"] = {}, ["inventory"] = {}}, ["y"] = 1, ["z"] = 12, ["name"] = "default:dirt_with_grass"}, {["x"] = 3, ["meta"] = {["fields"] = {}, ["inventory"] = {}}, ["y"] = 2, ["z"] = 0, ["name"] = "default:dirt"}, {["x"] = 3, ["meta"] = {["fields"] = {}, ["inventory"] = {}}, ["y"] = 2, ["z"] = 1, ["name"] = "default:stone"}, {["x"] = 3, ["meta"] = {["fields"] = {}, ["inventory"] = {}}, ["y"] = 2, ["z"] = 2, ["name"] = "default:stone"}, {["x"] = 3, ["meta"] = {["fields"] = {}, ["inventory"] = {}}, ["y"] = 2, ["z"] = 3, ["name"] = "default:stone"}, {["x"] = 3, ["meta"] = {["fields"] = {}, ["inventory"] = {}}, ["y"] = 2, ["z"] = 4, ["name"] = "default:stone"}, {["x"] = 3, ["meta"] = {["fields"] = {}, ["inventory"] = {}}, ["y"] = 2, ["z"] = 5, ["name"] = "default:stone"}, {["x"] = 3, ["meta"] = {["fields"] = {}, ["inventory"] = {}}, ["y"] = 2, ["z"] = 6, ["name"] = "default:stone"}, {["x"] = 3, ["meta"] = {["fields"] = {}, ["inventory"] = {}}, ["y"] = 2, ["z"] = 7, ["name"] = "default:stone"}, {["x"] = 3, ["meta"] = {["fields"] = {}, ["inventory"] = {}}, ["y"] = 2, ["z"] = 8, ["name"] = "default:stone"}, {["x"] = 3, ["meta"] = {["fields"] = {}, ["inventory"] = {}}, ["y"] = 2, ["z"] = 9, ["name"] = "default:stone"}, {["x"] = 3, ["meta"] = {["fields"] = {}, ["inventory"] = {}}, ["y"] = 2, ["z"] = 10, ["name"] = "default:stone"}, {["x"] = 3, ["meta"] = {["fields"] = {}, ["inventory"] = {}}, ["y"] = 2, ["z"] = 11, ["name"] = "default:dirt"}, {["x"] = 3, ["meta"] = {["fields"] = {}, ["inventory"] = {}}, ["y"] = 3, ["z"] = 0, ["name"] = "default:dirt_with_grass"}, {["x"] = 3, ["meta"] = {["fields"] = {}, ["inventory"] = {}}, ["y"] = 3, ["z"] = 1, ["name"] = "default:stone"}, {["x"] = 3, ["meta"] = {["fields"] = {}, ["inventory"] = {}}, ["y"] = 3, ["z"] = 2, ["name"] = "default:stone"}, {["x"] = 3, ["meta"] = {["fields"] = {}, ["inventory"] = {}}, ["y"] = 3, ["z"] = 3, ["name"] = "default:stone"}, {["x"] = 3, ["meta"] = {["fields"] = {}, ["inventory"] = {}}, ["y"] = 3, ["z"] = 4, ["name"] = "default:stone"}, {["x"] = 3, ["meta"] = {["fields"] = {}, ["inventory"] = {}}, ["y"] = 3, ["z"] = 5, ["name"] = "default:stone"}, {["x"] = 3, ["meta"] = {["fields"] = {}, ["inventory"] = {}}, ["y"] = 3, ["z"] = 6, ["name"] = "default:stone"}, {["x"] = 3, ["meta"] = {["fields"] = {}, ["inventory"] = {}}, ["y"] = 3, ["z"] = 7, ["name"] = "default:stone"}, {["x"] = 3, ["meta"] = {["fields"] = {}, ["inventory"] = {}}, ["y"] = 3, ["z"] = 8, ["name"] = "default:stone"}, {["x"] = 3, ["meta"] = {["fields"] = {}, ["inventory"] = {}}, ["y"] = 3, ["z"] = 9, ["name"] = "default:stone"}, {["x"] = 3, ["meta"] = {["fields"] = {}, ["inventory"] = {}}, ["y"] = 3, ["z"] = 10, ["name"] = "default:stone"}, {["x"] = 3, ["meta"] = {["fields"] = {}, ["inventory"] = {}}, ["y"] = 3, ["z"] = 11, ["name"] = "default:dirt_with_grass"}, {["x"] = 3, ["meta"] = {["fields"] = {}, ["inventory"] = {}}, ["y"] = 4, ["z"] = 1, ["name"] = "default:stone"}, {["x"] = 3, ["meta"] = {["fields"] = {}, ["inventory"] = {}}, ["y"] = 4, ["z"] = 2, ["name"] = "default:stone"}, {["x"] = 3, ["meta"] = {["fields"] = {}, ["inventory"] = {}}, ["y"] = 4, ["z"] = 3, ["name"] = "default:stone"}, {["x"] = 3, ["meta"] = {["fields"] = {}, ["inventory"] = {}}, ["y"] = 4, ["z"] = 4, ["name"] = "default:stone"}, {["x"] = 3, ["meta"] = {["fields"] = {}, ["inventory"] = {}}, ["y"] = 4, ["z"] = 5, ["name"] = "default:stone"}, {["x"] = 3, ["meta"] = {["fields"] = {}, ["inventory"] = {}}, ["y"] = 4, ["z"] = 6, ["name"] = "default:stone"}, {["x"] = 3, ["meta"] = {["fields"] = {}, ["inventory"] = {}}, ["y"] = 4, ["z"] = 7, ["name"] = "default:stone"}, {["x"] = 3, ["meta"] = {["fields"] = {}, ["inventory"] = {}}, ["y"] = 4, ["z"] = 8, ["name"] = "default:stone"}, {["x"] = 3, ["meta"] = {["fields"] = {}, ["inventory"] = {}}, ["y"] = 4, ["z"] = 9, ["name"] = "default:stone"}, {["x"] = 3, ["meta"] = {["fields"] = {}, ["inventory"] = {}}, ["y"] = 4, ["z"] = 10, ["name"] = "default:stone"}, {["x"] = 3, ["meta"] = {["fields"] = {}, ["inventory"] = {}}, ["y"] = 5, ["z"] = 1, ["name"] = "default:stone"}, {["x"] = 3, ["meta"] = {["fields"] = {}, ["inventory"] = {}}, ["y"] = 5, ["z"] = 2, ["name"] = "default:stone"}, {["x"] = 3, ["meta"] = {["fields"] = {}, ["inventory"] = {}}, ["y"] = 5, ["z"] = 3, ["name"] = "default:stone"}, {["x"] = 3, ["meta"] = {["fields"] = {}, ["inventory"] = {}}, ["y"] = 5, ["z"] = 4, ["name"] = "default:stone"}, {["x"] = 3, ["meta"] = {["fields"] = {}, ["inventory"] = {}}, ["y"] = 5, ["z"] = 5, ["name"] = "default:stone"}, {["x"] = 3, ["meta"] = {["fields"] = {}, ["inventory"] = {}}, ["y"] = 5, ["z"] = 6, ["name"] = "default:stone"}, {["x"] = 3, ["meta"] = {["fields"] = {}, ["inventory"] = {}}, ["y"] = 5, ["z"] = 7, ["name"] = "default:stone"}, {["x"] = 3, ["meta"] = {["fields"] = {}, ["inventory"] = {}}, ["y"] = 5, ["z"] = 8, ["name"] = "default:stone"}, {["x"] = 3, ["meta"] = {["fields"] = {}, ["inventory"] = {}}, ["y"] = 5, ["z"] = 9, ["name"] = "default:stone"}, {["x"] = 3, ["meta"] = {["fields"] = {}, ["inventory"] = {}}, ["y"] = 5, ["z"] = 10, ["name"] = "default:stone"}, {["x"] = 3, ["meta"] = {["fields"] = {}, ["inventory"] = {}}, ["y"] = 6, ["z"] = 1, ["name"] = "default:stone"}, {["x"] = 3, ["meta"] = {["fields"] = {}, ["inventory"] = {}}, ["y"] = 6, ["z"] = 2, ["name"] = "default:stone"}, {["x"] = 3, ["meta"] = {["fields"] = {}, ["inventory"] = {}}, ["y"] = 6, ["z"] = 3, ["name"] = "default:stone"}, {["x"] = 3, ["meta"] = {["fields"] = {}, ["inventory"] = {}}, ["y"] = 6, ["z"] = 4, ["name"] = "default:stone"}, {["x"] = 3, ["meta"] = {["fields"] = {}, ["inventory"] = {}}, ["y"] = 6, ["z"] = 5, ["name"] = "default:stone"}, {["x"] = 3, ["meta"] = {["fields"] = {}, ["inventory"] = {}}, ["y"] = 6, ["z"] = 6, ["name"] = "default:stone"}, {["x"] = 3, ["meta"] = {["fields"] = {}, ["inventory"] = {}}, ["y"] = 6, ["z"] = 7, ["name"] = "default:stone"}, {["x"] = 3, ["meta"] = {["fields"] = {}, ["inventory"] = {}}, ["y"] = 6, ["z"] = 8, ["name"] = "default:stone"}, {["x"] = 3, ["meta"] = {["fields"] = {}, ["inventory"] = {}}, ["y"] = 6, ["z"] = 9, ["name"] = "default:stone"}, {["x"] = 3, ["meta"] = {["fields"] = {}, ["inventory"] = {}}, ["y"] = 6, ["z"] = 10, ["name"] = "default:stone"}, {["x"] = 3, ["meta"] = {["fields"] = {}, ["inventory"] = {}}, ["y"] = 7, ["z"] = 1, ["name"] = "default:stone"}, {["x"] = 3, ["meta"] = {["fields"] = {}, ["inventory"] = {}}, ["y"] = 7, ["z"] = 2, ["name"] = "default:stone_with_coal"}, {["x"] = 3, ["meta"] = {["fields"] = {}, ["inventory"] = {}}, ["y"] = 7, ["z"] = 3, ["name"] = "default:stone_with_coal"}, {["x"] = 3, ["meta"] = {["fields"] = {}, ["inventory"] = {}}, ["y"] = 7, ["z"] = 4, ["name"] = "default:stone"}, {["x"] = 3, ["meta"] = {["fields"] = {}, ["inventory"] = {}}, ["y"] = 7, ["z"] = 5, ["name"] = "default:stone"}, {["x"] = 3, ["meta"] = {["fields"] = {}, ["inventory"] = {}}, ["y"] = 7, ["z"] = 6, ["name"] = "default:stone"}, {["x"] = 3, ["meta"] = {["fields"] = {}, ["inventory"] = {}}, ["y"] = 7, ["z"] = 7, ["name"] = "default:stone"}, {["x"] = 3, ["meta"] = {["fields"] = {}, ["inventory"] = {}}, ["y"] = 7, ["z"] = 8, ["name"] = "default:stone"}, {["x"] = 3, ["meta"] = {["fields"] = {}, ["inventory"] = {}}, ["y"] = 7, ["z"] = 9, ["name"] = "default:stone"}, {["x"] = 3, ["meta"] = {["fields"] = {}, ["inventory"] = {}}, ["y"] = 7, ["z"] = 10, ["name"] = "default:stone"}, {["x"] = 3, ["meta"] = {["fields"] = {}, ["inventory"] = {}}, ["y"] = 8, ["z"] = 1, ["name"] = "default:stone"}, {["x"] = 3, ["meta"] = {["fields"] = {}, ["inventory"] = {}}, ["y"] = 8, ["z"] = 2, ["name"] = "default:stone"}, {["x"] = 3, ["meta"] = {["fields"] = {}, ["inventory"] = {}}, ["y"] = 8, ["z"] = 3, ["name"] = "default:stone"}, {["x"] = 3, ["meta"] = {["fields"] = {}, ["inventory"] = {}}, ["y"] = 8, ["z"] = 4, ["name"] = "default:dirt"}, {["x"] = 3, ["meta"] = {["fields"] = {}, ["inventory"] = {}}, ["y"] = 8, ["z"] = 5, ["name"] = "default:dirt"}, {["x"] = 3, ["meta"] = {["fields"] = {}, ["inventory"] = {}}, ["y"] = 8, ["z"] = 6, ["name"] = "default:dirt"}, {["x"] = 3, ["meta"] = {["fields"] = {}, ["inventory"] = {}}, ["y"] = 8, ["z"] = 7, ["name"] = "default:stone"}, {["x"] = 3, ["meta"] = {["fields"] = {}, ["inventory"] = {}}, ["y"] = 8, ["z"] = 8, ["name"] = "default:stone"}, {["x"] = 3, ["meta"] = {["fields"] = {}, ["inventory"] = {}}, ["y"] = 8, ["z"] = 9, ["name"] = "default:stone"}, {["x"] = 3, ["meta"] = {["fields"] = {}, ["inventory"] = {}}, ["y"] = 8, ["z"] = 10, ["name"] = "default:stone"}, {["x"] = 3, ["meta"] = {["fields"] = {}, ["inventory"] = {}}, ["y"] = 9, ["z"] = 1, ["name"] = "default:stone"}, {["x"] = 3, ["meta"] = {["fields"] = {}, ["inventory"] = {}}, ["y"] = 9, ["z"] = 2, ["name"] = "default:stone"}, {["x"] = 3, ["meta"] = {["fields"] = {}, ["inventory"] = {}}, ["y"] = 9, ["z"] = 3, ["name"] = "default:stone"}, {["x"] = 3, ["meta"] = {["fields"] = {}, ["inventory"] = {}}, ["y"] = 9, ["z"] = 4, ["name"] = "default:dirt"}, {["x"] = 3, ["meta"] = {["fields"] = {}, ["inventory"] = {}}, ["y"] = 9, ["z"] = 5, ["name"] = "default:dirt"}, {["x"] = 3, ["meta"] = {["fields"] = {}, ["inventory"] = {}}, ["y"] = 9, ["z"] = 6, ["name"] = "default:dirt"}, {["x"] = 3, ["meta"] = {["fields"] = {}, ["inventory"] = {}}, ["y"] = 9, ["z"] = 7, ["name"] = "default:stone"}, {["x"] = 3, ["meta"] = {["fields"] = {}, ["inventory"] = {}}, ["y"] = 9, ["z"] = 8, ["name"] = "default:stone"}, {["x"] = 3, ["meta"] = {["fields"] = {}, ["inventory"] = {}}, ["y"] = 9, ["z"] = 9, ["name"] = "default:stone"}, {["x"] = 3, ["meta"] = {["fields"] = {}, ["inventory"] = {}}, ["y"] = 9, ["z"] = 10, ["name"] = "default:stone"}, {["x"] = 3, ["meta"] = {["fields"] = {}, ["inventory"] = {}}, ["y"] = 10, ["z"] = 1, ["name"] = "default:stone"}, {["x"] = 3, ["meta"] = {["fields"] = {}, ["inventory"] = {}}, ["y"] = 10, ["z"] = 2, ["name"] = "default:stone"}, {["x"] = 3, ["meta"] = {["fields"] = {}, ["inventory"] = {}}, ["y"] = 10, ["z"] = 3, ["name"] = "default:stone"}, {["x"] = 3, ["meta"] = {["fields"] = {}, ["inventory"] = {}}, ["y"] = 10, ["z"] = 4, ["name"] = "default:dirt"}, {["x"] = 3, ["meta"] = {["fields"] = {}, ["inventory"] = {}}, ["y"] = 10, ["z"] = 5, ["name"] = "default:dirt"}, {["x"] = 3, ["meta"] = {["fields"] = {}, ["inventory"] = {}}, ["y"] = 10, ["z"] = 6, ["name"] = "default:dirt"}, {["x"] = 3, ["meta"] = {["fields"] = {}, ["inventory"] = {}}, ["y"] = 10, ["z"] = 7, ["name"] = "default:stone"}, {["x"] = 3, ["meta"] = {["fields"] = {}, ["inventory"] = {}}, ["y"] = 10, ["z"] = 8, ["name"] = "default:stone"}, {["x"] = 3, ["meta"] = {["fields"] = {}, ["inventory"] = {}}, ["y"] = 10, ["z"] = 9, ["name"] = "default:stone"}, {["x"] = 3, ["meta"] = {["fields"] = {}, ["inventory"] = {}}, ["y"] = 10, ["z"] = 10, ["name"] = "default:stone"}, {["x"] = 3, ["meta"] = {["fields"] = {}, ["inventory"] = {}}, ["y"] = 11, ["z"] = 1, ["name"] = "default:dirt"}, {["x"] = 3, ["meta"] = {["fields"] = {}, ["inventory"] = {}}, ["y"] = 11, ["z"] = 2, ["name"] = "default:dirt"}, {["x"] = 3, ["meta"] = {["fields"] = {}, ["inventory"] = {}}, ["y"] = 11, ["z"] = 3, ["name"] = "default:dirt"}, {["x"] = 3, ["meta"] = {["fields"] = {}, ["inventory"] = {}}, ["y"] = 11, ["z"] = 4, ["name"] = "default:dirt"}, {["x"] = 3, ["meta"] = {["fields"] = {}, ["inventory"] = {}}, ["y"] = 11, ["z"] = 5, ["name"] = "default:dirt"}, {["x"] = 3, ["meta"] = {["fields"] = {}, ["inventory"] = {}}, ["y"] = 11, ["z"] = 6, ["name"] = "default:dirt"}, {["x"] = 3, ["meta"] = {["fields"] = {}, ["inventory"] = {}}, ["y"] = 11, ["z"] = 7, ["name"] = "default:dirt"}, {["x"] = 3, ["meta"] = {["fields"] = {}, ["inventory"] = {}}, ["y"] = 11, ["z"] = 8, ["name"] = "default:dirt"}, {["x"] = 3, ["meta"] = {["fields"] = {}, ["inventory"] = {}}, ["y"] = 11, ["z"] = 9, ["name"] = "default:dirt"}, {["x"] = 3, ["meta"] = {["fields"] = {}, ["inventory"] = {}}, ["y"] = 11, ["z"] = 10, ["name"] = "default:dirt"}, {["x"] = 3, ["meta"] = {["fields"] = {}, ["inventory"] = {}}, ["y"] = 12, ["z"] = 1, ["name"] = "default:dirt"}, {["x"] = 3, ["meta"] = {["fields"] = {}, ["inventory"] = {}}, ["y"] = 12, ["z"] = 2, ["name"] = "default:dirt"}, {["x"] = 3, ["meta"] = {["fields"] = {}, ["inventory"] = {}}, ["y"] = 12, ["z"] = 3, ["name"] = "default:dirt"}, {["x"] = 3, ["meta"] = {["fields"] = {}, ["inventory"] = {}}, ["y"] = 12, ["z"] = 4, ["name"] = "default:dirt"}, {["x"] = 3, ["meta"] = {["fields"] = {}, ["inventory"] = {}}, ["y"] = 12, ["z"] = 5, ["name"] = "default:dirt"}, {["x"] = 3, ["meta"] = {["fields"] = {}, ["inventory"] = {}}, ["y"] = 12, ["z"] = 6, ["name"] = "default:dirt"}, {["x"] = 3, ["meta"] = {["fields"] = {}, ["inventory"] = {}}, ["y"] = 12, ["z"] = 7, ["name"] = "default:dirt"}, {["x"] = 3, ["meta"] = {["fields"] = {}, ["inventory"] = {}}, ["y"] = 12, ["z"] = 8, ["name"] = "default:dirt"}, {["x"] = 3, ["meta"] = {["fields"] = {}, ["inventory"] = {}}, ["y"] = 12, ["z"] = 9, ["name"] = "default:dirt"}, {["x"] = 3, ["meta"] = {["fields"] = {}, ["inventory"] = {}}, ["y"] = 12, ["z"] = 10, ["name"] = "default:dirt"}, {["x"] = 3, ["meta"] = {["fields"] = {}, ["inventory"] = {}}, ["y"] = 13, ["z"] = 1, ["name"] = "default:dirt_with_grass"}, {["x"] = 3, ["meta"] = {["fields"] = {}, ["inventory"] = {}}, ["y"] = 13, ["z"] = 2, ["name"] = "default:dirt_with_grass"}, {["x"] = 3, ["meta"] = {["fields"] = {}, ["inventory"] = {}}, ["y"] = 13, ["z"] = 3, ["name"] = "default:dirt"}, {["x"] = 3, ["meta"] = {["fields"] = {}, ["inventory"] = {}}, ["y"] = 13, ["z"] = 4, ["name"] = "default:dirt_with_grass"}, {["x"] = 3, ["meta"] = {["fields"] = {}, ["inventory"] = {}}, ["y"] = 13, ["z"] = 5, ["name"] = "default:dirt_with_grass"}, {["x"] = 3, ["meta"] = {["fields"] = {}, ["inventory"] = {}}, ["y"] = 13, ["z"] = 6, ["name"] = "default:dirt_with_grass"}, {["x"] = 3, ["meta"] = {["fields"] = {}, ["inventory"] = {}}, ["y"] = 13, ["z"] = 7, ["name"] = "default:dirt_with_grass"}, {["x"] = 3, ["meta"] = {["fields"] = {}, ["inventory"] = {}}, ["y"] = 13, ["z"] = 8, ["name"] = "default:dirt_with_grass"}, {["x"] = 3, ["meta"] = {["fields"] = {}, ["inventory"] = {}}, ["y"] = 13, ["z"] = 9, ["name"] = "default:dirt"}, {["x"] = 3, ["meta"] = {["fields"] = {}, ["inventory"] = {}}, ["y"] = 13, ["z"] = 10, ["name"] = "default:dirt"}, {["x"] = 3, ["meta"] = {["fields"] = {}, ["inventory"] = {}}, ["y"] = 14, ["param1"] = 13, ["z"] = 3, ["name"] = "mesecons_random:ghoststone_active"}, {["x"] = 3, ["meta"] = {["fields"] = {}, ["inventory"] = {}}, ["y"] = 14, ["param1"] = 12, ["z"] = 9, ["name"] = "mesecons_random:ghoststone_active"}, {["x"] = 3, ["meta"] = {["fields"] = {}, ["inventory"] = {}}, ["y"] = 14, ["param1"] = 13, ["z"] = 10, ["name"] = "mesecons_random:ghoststone_active"}, {["x"] = 3, ["meta"] = {["fields"] = {}, ["inventory"] = {}}, ["y"] = 15, ["param1"] = 13, ["z"] = 3, ["name"] = "mesecons_random:ghoststone_active"}, {["x"] = 3, ["meta"] = {["fields"] = {}, ["inventory"] = {}}, ["y"] = 15, ["param1"] = 13, ["z"] = 9, ["name"] = "mesecons_random:ghoststone_active"}, {["x"] = 3, ["meta"] = {["fields"] = {}, ["inventory"] = {}}, ["y"] = 15, ["param1"] = 13, ["z"] = 10, ["name"] = "mesecons_random:ghoststone_active"}, {["x"] = 3, ["meta"] = {["fields"] = {}, ["inventory"] = {}}, ["y"] = 16, ["param1"] = 15, ["z"] = 9, ["name"] = "mesecons_random:ghoststone_active"}, {["x"] = 3, ["meta"] = {["fields"] = {}, ["inventory"] = {}}, ["y"] = 16, ["param1"] = 13, ["z"] = 10, ["name"] = "mesecons_random:ghoststone_active"}, {["x"] = 3, ["meta"] = {["fields"] = {}, ["inventory"] = {}}, ["y"] = 17, ["param1"] = 15, ["z"] = 3, ["name"] = "mesecons_random:ghoststone_active"}, {["x"] = 3, ["meta"] = {["fields"] = {}, ["inventory"] = {}}, ["y"] = 17, ["param1"] = 15, ["z"] = 4, ["name"] = "mesecons_random:ghoststone_active"}, {["x"] = 3, ["meta"] = {["fields"] = {}, ["inventory"] = {}}, ["y"] = 17, ["param1"] = 15, ["z"] = 5, ["name"] = "mesecons_random:ghoststone_active"}, {["x"] = 3, ["meta"] = {["fields"] = {}, ["inventory"] = {}}, ["y"] = 17, ["param1"] = 15, ["z"] = 6, ["name"] = "mesecons_random:ghoststone_active"}, {["x"] = 3, ["meta"] = {["fields"] = {}, ["inventory"] = {}}, ["y"] = 17, ["param1"] = 15, ["z"] = 7, ["name"] = "mesecons_random:ghoststone_active"}, {["x"] = 3, ["meta"] = {["fields"] = {}, ["inventory"] = {}}, ["y"] = 17, ["param1"] = 15, ["z"] = 8, ["name"] = "mesecons_random:ghoststone_active"}, {["x"] = 3, ["meta"] = {["fields"] = {}, ["inventory"] = {}}, ["y"] = 17, ["param1"] = 15, ["z"] = 9, ["name"] = "mesecons_random:ghoststone_active"}, {["x"] = 3, ["meta"] = {["fields"] = {}, ["inventory"] = {}}, ["y"] = 17, ["param1"] = 15, ["z"] = 10, ["name"] = "mesecons_random:ghoststone_active"}, {["x"] = 4, ["meta"] = {["fields"] = {}, ["inventory"] = {}}, ["y"] = 0, ["z"] = 0, ["name"] = "default:dirt"}, {["x"] = 4, ["meta"] = {["fields"] = {}, ["inventory"] = {}}, ["y"] = 0, ["z"] = 1, ["name"] = "default:stone"}, {["x"] = 4, ["meta"] = {["fields"] = {}, ["inventory"] = {}}, ["y"] = 0, ["z"] = 2, ["name"] = "default:stone"}, {["x"] = 4, ["meta"] = {["fields"] = {}, ["inventory"] = {}}, ["y"] = 0, ["z"] = 3, ["name"] = "default:stone"}, {["x"] = 4, ["meta"] = {["fields"] = {}, ["inventory"] = {}}, ["y"] = 0, ["z"] = 4, ["name"] = "default:stone"}, {["x"] = 4, ["meta"] = {["fields"] = {}, ["inventory"] = {}}, ["y"] = 0, ["z"] = 5, ["name"] = "default:stone"}, {["x"] = 4, ["meta"] = {["fields"] = {}, ["inventory"] = {}}, ["y"] = 0, ["z"] = 6, ["name"] = "default:stone"}, {["x"] = 4, ["meta"] = {["fields"] = {}, ["inventory"] = {}}, ["y"] = 0, ["z"] = 7, ["name"] = "default:stone"}, {["x"] = 4, ["meta"] = {["fields"] = {}, ["inventory"] = {}}, ["y"] = 0, ["z"] = 8, ["name"] = "default:stone"}, {["x"] = 4, ["meta"] = {["fields"] = {}, ["inventory"] = {}}, ["y"] = 0, ["z"] = 9, ["name"] = "default:stone"}, {["x"] = 4, ["meta"] = {["fields"] = {}, ["inventory"] = {}}, ["y"] = 0, ["z"] = 10, ["name"] = "default:stone"}, {["x"] = 4, ["meta"] = {["fields"] = {}, ["inventory"] = {}}, ["y"] = 0, ["z"] = 11, ["name"] = "default:stone"}, {["x"] = 4, ["meta"] = {["fields"] = {}, ["inventory"] = {}}, ["y"] = 0, ["z"] = 12, ["name"] = "default:dirt"}, {["x"] = 4, ["meta"] = {["fields"] = {}, ["inventory"] = {}}, ["y"] = 0, ["z"] = 13, ["name"] = "default:dirt_with_grass"}, {["x"] = 4, ["meta"] = {["fields"] = {}, ["inventory"] = {}}, ["y"] = 0, ["z"] = 14, ["name"] = "default:dirt_with_grass"}, {["x"] = 4, ["meta"] = {["fields"] = {}, ["inventory"] = {}}, ["y"] = 1, ["z"] = 0, ["name"] = "default:dirt"}, {["x"] = 4, ["meta"] = {["fields"] = {}, ["inventory"] = {}}, ["y"] = 1, ["z"] = 1, ["name"] = "default:stone"}, {["x"] = 4, ["meta"] = {["fields"] = {}, ["inventory"] = {}}, ["y"] = 1, ["z"] = 2, ["name"] = "default:stone"}, {["x"] = 4, ["meta"] = {["fields"] = {}, ["inventory"] = {}}, ["y"] = 1, ["z"] = 3, ["name"] = "default:stone"}, {["x"] = 4, ["meta"] = {["fields"] = {}, ["inventory"] = {}}, ["y"] = 1, ["z"] = 4, ["name"] = "default:stone"}, {["x"] = 4, ["meta"] = {["fields"] = {}, ["inventory"] = {}}, ["y"] = 1, ["z"] = 5, ["name"] = "default:stone"}, {["x"] = 4, ["meta"] = {["fields"] = {}, ["inventory"] = {}}, ["y"] = 1, ["z"] = 6, ["name"] = "default:stone"}, {["x"] = 4, ["meta"] = {["fields"] = {}, ["inventory"] = {}}, ["y"] = 1, ["z"] = 7, ["name"] = "default:stone"}, {["x"] = 4, ["meta"] = {["fields"] = {}, ["inventory"] = {}}, ["y"] = 1, ["z"] = 8, ["name"] = "default:stone"}, {["x"] = 4, ["meta"] = {["fields"] = {}, ["inventory"] = {}}, ["y"] = 1, ["z"] = 9, ["name"] = "default:stone"}, {["x"] = 4, ["meta"] = {["fields"] = {}, ["inventory"] = {}}, ["y"] = 1, ["z"] = 10, ["name"] = "default:stone"}, {["x"] = 4, ["meta"] = {["fields"] = {}, ["inventory"] = {}}, ["y"] = 1, ["z"] = 11, ["name"] = "default:stone"}, {["x"] = 4, ["meta"] = {["fields"] = {}, ["inventory"] = {}}, ["y"] = 1, ["z"] = 12, ["name"] = "default:dirt_with_grass"}, {["x"] = 4, ["meta"] = {["fields"] = {}, ["inventory"] = {}}, ["y"] = 2, ["z"] = 0, ["name"] = "default:dirt"}, {["x"] = 4, ["meta"] = {["fields"] = {}, ["inventory"] = {}}, ["y"] = 2, ["z"] = 1, ["name"] = "default:stone"}, {["x"] = 4, ["meta"] = {["fields"] = {}, ["inventory"] = {}}, ["y"] = 2, ["z"] = 2, ["name"] = "default:stone"}, {["x"] = 4, ["meta"] = {["fields"] = {}, ["inventory"] = {}}, ["y"] = 2, ["z"] = 3, ["name"] = "default:stone"}, {["x"] = 4, ["meta"] = {["fields"] = {}, ["inventory"] = {}}, ["y"] = 2, ["z"] = 4, ["name"] = "default:stone"}, {["x"] = 4, ["meta"] = {["fields"] = {}, ["inventory"] = {}}, ["y"] = 2, ["z"] = 5, ["name"] = "default:stone"}, {["x"] = 4, ["meta"] = {["fields"] = {}, ["inventory"] = {}}, ["y"] = 2, ["z"] = 6, ["name"] = "default:stone"}, {["x"] = 4, ["meta"] = {["fields"] = {}, ["inventory"] = {}}, ["y"] = 2, ["z"] = 7, ["name"] = "default:stone"}, {["x"] = 4, ["meta"] = {["fields"] = {}, ["inventory"] = {}}, ["y"] = 2, ["z"] = 8, ["name"] = "default:stone"}, {["x"] = 4, ["meta"] = {["fields"] = {}, ["inventory"] = {}}, ["y"] = 2, ["z"] = 9, ["name"] = "default:stone"}, {["x"] = 4, ["meta"] = {["fields"] = {}, ["inventory"] = {}}, ["y"] = 2, ["z"] = 10, ["name"] = "default:stone"}, {["x"] = 4, ["meta"] = {["fields"] = {}, ["inventory"] = {}}, ["y"] = 2, ["z"] = 11, ["name"] = "default:stone"}, {["x"] = 4, ["meta"] = {["fields"] = {}, ["inventory"] = {}}, ["y"] = 3, ["z"] = 0, ["name"] = "default:dirt"}, {["x"] = 4, ["meta"] = {["fields"] = {}, ["inventory"] = {}}, ["y"] = 3, ["z"] = 1, ["name"] = "default:stone"}, {["x"] = 4, ["meta"] = {["fields"] = {}, ["inventory"] = {}}, ["y"] = 3, ["z"] = 2, ["name"] = "default:stone"}, {["x"] = 4, ["meta"] = {["fields"] = {}, ["inventory"] = {}}, ["y"] = 3, ["z"] = 3, ["name"] = "default:stone"}, {["x"] = 4, ["meta"] = {["fields"] = {}, ["inventory"] = {}}, ["y"] = 3, ["z"] = 4, ["name"] = "default:stone"}, {["x"] = 4, ["meta"] = {["fields"] = {}, ["inventory"] = {}}, ["y"] = 3, ["z"] = 5, ["name"] = "default:stone"}, {["x"] = 4, ["meta"] = {["fields"] = {}, ["inventory"] = {}}, ["y"] = 3, ["z"] = 6, ["name"] = "default:stone"}, {["x"] = 4, ["meta"] = {["fields"] = {}, ["inventory"] = {}}, ["y"] = 3, ["z"] = 7, ["name"] = "default:stone"}, {["x"] = 4, ["meta"] = {["fields"] = {}, ["inventory"] = {}}, ["y"] = 3, ["z"] = 8, ["name"] = "default:stone"}, {["x"] = 4, ["meta"] = {["fields"] = {}, ["inventory"] = {}}, ["y"] = 3, ["z"] = 9, ["name"] = "default:stone"}, {["x"] = 4, ["meta"] = {["fields"] = {}, ["inventory"] = {}}, ["y"] = 3, ["z"] = 10, ["name"] = "default:stone"}, {["x"] = 4, ["meta"] = {["fields"] = {}, ["inventory"] = {}}, ["y"] = 3, ["z"] = 11, ["name"] = "default:stone"}, {["x"] = 4, ["meta"] = {["fields"] = {}, ["inventory"] = {}}, ["y"] = 3, ["param1"] = 13, ["z"] = 14, ["name"] = "default:leaves"}, {["x"] = 4, ["meta"] = {["fields"] = {}, ["inventory"] = {}}, ["y"] = 4, ["z"] = 0, ["name"] = "default:dirt_with_grass"}, {["x"] = 4, ["meta"] = {["fields"] = {}, ["inventory"] = {}}, ["y"] = 4, ["z"] = 1, ["name"] = "default:stone"}, {["x"] = 4, ["meta"] = {["fields"] = {}, ["inventory"] = {}}, ["y"] = 4, ["z"] = 2, ["name"] = "default:stone"}, {["x"] = 4, ["meta"] = {["fields"] = {}, ["inventory"] = {}}, ["y"] = 4, ["z"] = 3, ["name"] = "default:stone"}, {["x"] = 4, ["meta"] = {["fields"] = {}, ["inventory"] = {}}, ["y"] = 4, ["z"] = 4, ["name"] = "default:stone"}, {["x"] = 4, ["meta"] = {["fields"] = {}, ["inventory"] = {}}, ["y"] = 4, ["z"] = 5, ["name"] = "default:stone"}, {["x"] = 4, ["meta"] = {["fields"] = {}, ["inventory"] = {}}, ["y"] = 4, ["z"] = 6, ["name"] = "default:stone"}, {["x"] = 4, ["meta"] = {["fields"] = {}, ["inventory"] = {}}, ["y"] = 4, ["z"] = 7, ["name"] = "default:stone"}, {["x"] = 4, ["meta"] = {["fields"] = {}, ["inventory"] = {}}, ["y"] = 4, ["z"] = 8, ["name"] = "default:stone"}, {["x"] = 4, ["meta"] = {["fields"] = {}, ["inventory"] = {}}, ["y"] = 4, ["z"] = 9, ["name"] = "default:stone"}, {["x"] = 4, ["meta"] = {["fields"] = {}, ["inventory"] = {}}, ["y"] = 4, ["z"] = 10, ["name"] = "default:stone"}, {["x"] = 4, ["meta"] = {["fields"] = {}, ["inventory"] = {}}, ["y"] = 4, ["z"] = 11, ["name"] = "default:stone"}, {["x"] = 4, ["meta"] = {["fields"] = {}, ["inventory"] = {}}, ["y"] = 4, ["param1"] = 13, ["z"] = 14, ["name"] = "default:leaves"}, {["x"] = 4, ["meta"] = {["fields"] = {}, ["inventory"] = {}}, ["y"] = 5, ["z"] = 1, ["name"] = "default:stone"}, {["x"] = 4, ["meta"] = {["fields"] = {}, ["inventory"] = {}}, ["y"] = 5, ["z"] = 2, ["name"] = "default:stone"}, {["x"] = 4, ["meta"] = {["fields"] = {}, ["inventory"] = {}}, ["y"] = 5, ["z"] = 3, ["name"] = "default:stone"}, {["x"] = 4, ["meta"] = {["fields"] = {}, ["inventory"] = {}}, ["y"] = 5, ["z"] = 4, ["name"] = "default:stone"}, {["x"] = 4, ["meta"] = {["fields"] = {}, ["inventory"] = {}}, ["y"] = 5, ["z"] = 5, ["name"] = "default:stone"}, {["x"] = 4, ["meta"] = {["fields"] = {}, ["inventory"] = {}}, ["y"] = 5, ["z"] = 6, ["name"] = "default:stone"}, {["x"] = 4, ["meta"] = {["fields"] = {}, ["inventory"] = {}}, ["y"] = 5, ["z"] = 7, ["name"] = "default:stone"}, {["x"] = 4, ["meta"] = {["fields"] = {}, ["inventory"] = {}}, ["y"] = 5, ["z"] = 8, ["name"] = "default:stone"}, {["x"] = 4, ["meta"] = {["fields"] = {}, ["inventory"] = {}}, ["y"] = 5, ["z"] = 9, ["name"] = "default:stone"}, {["x"] = 4, ["meta"] = {["fields"] = {}, ["inventory"] = {}}, ["y"] = 5, ["z"] = 10, ["name"] = "default:stone"}, {["x"] = 4, ["meta"] = {["fields"] = {}, ["inventory"] = {}}, ["y"] = 5, ["z"] = 11, ["name"] = "default:stone"}, {["x"] = 4, ["meta"] = {["fields"] = {}, ["inventory"] = {}}, ["y"] = 5, ["param1"] = 13, ["z"] = 14, ["name"] = "default:leaves"}, {["x"] = 4, ["meta"] = {["fields"] = {}, ["inventory"] = {}}, ["y"] = 6, ["z"] = 1, ["name"] = "default:stone"}, {["x"] = 4, ["meta"] = {["fields"] = {}, ["inventory"] = {}}, ["y"] = 6, ["z"] = 2, ["name"] = "default:stone"}, {["x"] = 4, ["meta"] = {["fields"] = {}, ["inventory"] = {}}, ["y"] = 6, ["z"] = 3, ["name"] = "default:stone"}, {["x"] = 4, ["meta"] = {["fields"] = {}, ["inventory"] = {}}, ["y"] = 6, ["z"] = 4, ["name"] = "default:stone"}, {["x"] = 4, ["meta"] = {["fields"] = {}, ["inventory"] = {}}, ["y"] = 6, ["z"] = 5, ["name"] = "default:stone"}, {["x"] = 4, ["meta"] = {["fields"] = {}, ["inventory"] = {}}, ["y"] = 6, ["z"] = 6, ["name"] = "default:stone"}, {["x"] = 4, ["meta"] = {["fields"] = {}, ["inventory"] = {}}, ["y"] = 6, ["z"] = 7, ["name"] = "default:stone"}, {["x"] = 4, ["meta"] = {["fields"] = {}, ["inventory"] = {}}, ["y"] = 6, ["z"] = 8, ["name"] = "default:stone"}, {["x"] = 4, ["meta"] = {["fields"] = {}, ["inventory"] = {}}, ["y"] = 6, ["z"] = 9, ["name"] = "default:stone"}, {["x"] = 4, ["meta"] = {["fields"] = {}, ["inventory"] = {}}, ["y"] = 6, ["z"] = 10, ["name"] = "default:stone"}, {["x"] = 4, ["meta"] = {["fields"] = {}, ["inventory"] = {}}, ["y"] = 6, ["z"] = 11, ["name"] = "default:stone"}, {["x"] = 4, ["meta"] = {["fields"] = {}, ["inventory"] = {}}, ["y"] = 7, ["z"] = 1, ["name"] = "default:stone"}, {["x"] = 4, ["meta"] = {["fields"] = {}, ["inventory"] = {}}, ["y"] = 7, ["z"] = 2, ["name"] = "default:stone"}, {["x"] = 4, ["meta"] = {["fields"] = {}, ["inventory"] = {}}, ["y"] = 7, ["z"] = 3, ["name"] = "default:stone"}, {["x"] = 4, ["meta"] = {["fields"] = {}, ["inventory"] = {}}, ["y"] = 7, ["z"] = 4, ["name"] = "default:stone"}, {["x"] = 4, ["meta"] = {["fields"] = {}, ["inventory"] = {}}, ["y"] = 7, ["z"] = 5, ["name"] = "default:stone"}, {["x"] = 4, ["meta"] = {["fields"] = {}, ["inventory"] = {}}, ["y"] = 7, ["z"] = 6, ["name"] = "default:stone"}, {["x"] = 4, ["meta"] = {["fields"] = {}, ["inventory"] = {}}, ["y"] = 7, ["z"] = 7, ["name"] = "default:stone"}, {["x"] = 4, ["meta"] = {["fields"] = {}, ["inventory"] = {}}, ["y"] = 7, ["z"] = 8, ["name"] = "default:stone"}, {["x"] = 4, ["meta"] = {["fields"] = {}, ["inventory"] = {}}, ["y"] = 7, ["z"] = 9, ["name"] = "default:stone"}, {["x"] = 4, ["meta"] = {["fields"] = {}, ["inventory"] = {}}, ["y"] = 7, ["z"] = 10, ["name"] = "default:stone"}, {["x"] = 4, ["meta"] = {["fields"] = {}, ["inventory"] = {}}, ["y"] = 7, ["z"] = 11, ["name"] = "default:stone"}, {["x"] = 4, ["meta"] = {["fields"] = {}, ["inventory"] = {}}, ["y"] = 8, ["z"] = 1, ["name"] = "default:stone"}, {["x"] = 4, ["meta"] = {["fields"] = {}, ["inventory"] = {}}, ["y"] = 8, ["z"] = 2, ["name"] = "default:stone"}, {["x"] = 4, ["meta"] = {["fields"] = {}, ["inventory"] = {}}, ["y"] = 8, ["z"] = 3, ["name"] = "default:stone"}, {["x"] = 4, ["meta"] = {["fields"] = {}, ["inventory"] = {}}, ["y"] = 8, ["z"] = 4, ["name"] = "default:stone"}, {["x"] = 4, ["meta"] = {["fields"] = {}, ["inventory"] = {}}, ["y"] = 8, ["z"] = 5, ["name"] = "default:stone"}, {["x"] = 4, ["meta"] = {["fields"] = {}, ["inventory"] = {}}, ["y"] = 8, ["z"] = 6, ["name"] = "default:stone"}, {["x"] = 4, ["meta"] = {["fields"] = {}, ["inventory"] = {}}, ["y"] = 8, ["z"] = 7, ["name"] = "default:stone"}, {["x"] = 4, ["meta"] = {["fields"] = {}, ["inventory"] = {}}, ["y"] = 8, ["z"] = 8, ["name"] = "default:stone"}, {["x"] = 4, ["meta"] = {["fields"] = {}, ["inventory"] = {}}, ["y"] = 8, ["z"] = 9, ["name"] = "default:stone"}, {["x"] = 4, ["meta"] = {["fields"] = {}, ["inventory"] = {}}, ["y"] = 8, ["z"] = 10, ["name"] = "default:stone"}, {["x"] = 4, ["meta"] = {["fields"] = {}, ["inventory"] = {}}, ["y"] = 8, ["z"] = 11, ["name"] = "default:stone"}, {["x"] = 4, ["meta"] = {["fields"] = {}, ["inventory"] = {}}, ["y"] = 9, ["z"] = 1, ["name"] = "default:stone"}, {["x"] = 4, ["meta"] = {["fields"] = {}, ["inventory"] = {}}, ["y"] = 9, ["z"] = 2, ["name"] = "default:stone"}, {["x"] = 4, ["meta"] = {["fields"] = {}, ["inventory"] = {}}, ["y"] = 9, ["z"] = 3, ["name"] = "default:stone"}, {["x"] = 4, ["meta"] = {["fields"] = {}, ["inventory"] = {}}, ["y"] = 9, ["z"] = 4, ["name"] = "default:stone"}, {["x"] = 4, ["meta"] = {["fields"] = {}, ["inventory"] = {}}, ["y"] = 9, ["z"] = 5, ["name"] = "default:stone"}, {["x"] = 4, ["meta"] = {["fields"] = {}, ["inventory"] = {}}, ["y"] = 9, ["z"] = 6, ["name"] = "default:stone"}, {["x"] = 4, ["meta"] = {["fields"] = {}, ["inventory"] = {}}, ["y"] = 9, ["z"] = 7, ["name"] = "default:stone"}, {["x"] = 4, ["meta"] = {["fields"] = {}, ["inventory"] = {}}, ["y"] = 9, ["z"] = 8, ["name"] = "default:stone"}, {["x"] = 4, ["meta"] = {["fields"] = {}, ["inventory"] = {}}, ["y"] = 9, ["z"] = 9, ["name"] = "default:stone"}, {["x"] = 4, ["meta"] = {["fields"] = {}, ["inventory"] = {}}, ["y"] = 9, ["z"] = 10, ["name"] = "default:stone"}, {["x"] = 4, ["meta"] = {["fields"] = {}, ["inventory"] = {}}, ["y"] = 9, ["z"] = 11, ["name"] = "default:stone"}, {["x"] = 4, ["meta"] = {["fields"] = {}, ["inventory"] = {}}, ["y"] = 10, ["z"] = 1, ["name"] = "default:stone"}, {["x"] = 4, ["meta"] = {["fields"] = {}, ["inventory"] = {}}, ["y"] = 10, ["z"] = 2, ["name"] = "default:stone"}, {["x"] = 4, ["meta"] = {["fields"] = {}, ["inventory"] = {}}, ["y"] = 10, ["z"] = 3, ["name"] = "default:stone"}, {["x"] = 4, ["meta"] = {["fields"] = {}, ["inventory"] = {}}, ["y"] = 10, ["z"] = 4, ["name"] = "default:stone"}, {["x"] = 4, ["meta"] = {["fields"] = {}, ["inventory"] = {}}, ["y"] = 10, ["z"] = 5, ["name"] = "default:stone"}, {["x"] = 4, ["meta"] = {["fields"] = {}, ["inventory"] = {}}, ["y"] = 10, ["z"] = 6, ["name"] = "default:stone"}, {["x"] = 4, ["meta"] = {["fields"] = {}, ["inventory"] = {}}, ["y"] = 10, ["z"] = 7, ["name"] = "default:stone"}, {["x"] = 4, ["meta"] = {["fields"] = {}, ["inventory"] = {}}, ["y"] = 10, ["z"] = 8, ["name"] = "default:stone"}, {["x"] = 4, ["meta"] = {["fields"] = {}, ["inventory"] = {}}, ["y"] = 10, ["z"] = 9, ["name"] = "default:stone"}, {["x"] = 4, ["meta"] = {["fields"] = {}, ["inventory"] = {}}, ["y"] = 10, ["z"] = 10, ["name"] = "default:stone"}, {["x"] = 4, ["meta"] = {["fields"] = {}, ["inventory"] = {}}, ["y"] = 10, ["z"] = 11, ["name"] = "default:stone"}, {["x"] = 4, ["meta"] = {["fields"] = {}, ["inventory"] = {}}, ["y"] = 11, ["z"] = 1, ["name"] = "default:dirt"}, {["x"] = 4, ["meta"] = {["fields"] = {}, ["inventory"] = {}}, ["y"] = 11, ["z"] = 2, ["name"] = "default:dirt"}, {["x"] = 4, ["meta"] = {["fields"] = {}, ["inventory"] = {}}, ["y"] = 11, ["z"] = 3, ["name"] = "default:dirt"}, {["x"] = 4, ["meta"] = {["fields"] = {}, ["inventory"] = {}}, ["y"] = 11, ["z"] = 4, ["name"] = "default:dirt"}, {["x"] = 4, ["meta"] = {["fields"] = {}, ["inventory"] = {}}, ["y"] = 11, ["z"] = 5, ["name"] = "default:dirt"}, {["x"] = 4, ["meta"] = {["fields"] = {}, ["inventory"] = {}}, ["y"] = 11, ["z"] = 6, ["name"] = "default:dirt"}, {["x"] = 4, ["meta"] = {["fields"] = {}, ["inventory"] = {}}, ["y"] = 11, ["z"] = 7, ["name"] = "default:dirt"}, {["x"] = 4, ["meta"] = {["fields"] = {}, ["inventory"] = {}}, ["y"] = 11, ["z"] = 8, ["name"] = "default:dirt"}, {["x"] = 4, ["meta"] = {["fields"] = {}, ["inventory"] = {}}, ["y"] = 11, ["z"] = 9, ["name"] = "default:dirt"}, {["x"] = 4, ["meta"] = {["fields"] = {}, ["inventory"] = {}}, ["y"] = 11, ["z"] = 10, ["name"] = "default:dirt"}, {["x"] = 4, ["meta"] = {["fields"] = {}, ["inventory"] = {}}, ["y"] = 11, ["z"] = 11, ["name"] = "default:dirt"}, {["x"] = 4, ["meta"] = {["fields"] = {}, ["inventory"] = {}}, ["y"] = 12, ["z"] = 1, ["name"] = "default:dirt"}, {["x"] = 4, ["meta"] = {["fields"] = {}, ["inventory"] = {}}, ["y"] = 12, ["z"] = 2, ["name"] = "default:dirt"}, {["x"] = 4, ["meta"] = {["fields"] = {}, ["inventory"] = {}}, ["y"] = 12, ["z"] = 3, ["name"] = "default:dirt"}, {["x"] = 4, ["meta"] = {["fields"] = {}, ["inventory"] = {}}, ["y"] = 12, ["z"] = 4, ["name"] = "default:dirt"}, {["x"] = 4, ["meta"] = {["fields"] = {}, ["inventory"] = {}}, ["y"] = 12, ["z"] = 5, ["name"] = "default:dirt"}, {["x"] = 4, ["meta"] = {["fields"] = {}, ["inventory"] = {}}, ["y"] = 12, ["z"] = 6, ["name"] = "default:dirt"}, {["x"] = 4, ["meta"] = {["fields"] = {}, ["inventory"] = {}}, ["y"] = 12, ["z"] = 7, ["name"] = "default:dirt"}, {["x"] = 4, ["meta"] = {["fields"] = {}, ["inventory"] = {}}, ["y"] = 12, ["z"] = 8, ["name"] = "default:dirt"}, {["x"] = 4, ["meta"] = {["fields"] = {}, ["inventory"] = {}}, ["y"] = 12, ["z"] = 9, ["name"] = "default:dirt"}, {["x"] = 4, ["meta"] = {["fields"] = {}, ["inventory"] = {}}, ["y"] = 12, ["z"] = 10, ["name"] = "default:dirt"}, {["x"] = 4, ["meta"] = {["fields"] = {}, ["inventory"] = {}}, ["y"] = 12, ["z"] = 11, ["name"] = "default:dirt"}, {["x"] = 4, ["meta"] = {["fields"] = {}, ["inventory"] = {}}, ["y"] = 13, ["z"] = 1, ["name"] = "default:dirt_with_grass"}, {["x"] = 4, ["meta"] = {["fields"] = {}, ["inventory"] = {}}, ["y"] = 13, ["z"] = 2, ["name"] = "default:dirt_with_grass"}, {["x"] = 4, ["meta"] = {["fields"] = {}, ["inventory"] = {}}, ["y"] = 13, ["z"] = 3, ["name"] = "default:dirt"}, {["x"] = 4, ["meta"] = {["fields"] = {}, ["inventory"] = {}}, ["y"] = 13, ["z"] = 4, ["name"] = "default:dirt_with_grass"}, {["x"] = 4, ["meta"] = {["fields"] = {}, ["inventory"] = {}}, ["y"] = 13, ["z"] = 5, ["name"] = "default:dirt_with_grass"}, {["x"] = 4, ["meta"] = {["fields"] = {}, ["inventory"] = {}}, ["y"] = 13, ["z"] = 6, ["name"] = "default:dirt_with_grass"}, {["x"] = 4, ["meta"] = {["fields"] = {}, ["inventory"] = {}}, ["y"] = 13, ["z"] = 7, ["name"] = "default:dirt_with_grass"}, {["x"] = 4, ["meta"] = {["fields"] = {}, ["inventory"] = {}}, ["y"] = 13, ["z"] = 8, ["name"] = "default:dirt_with_grass"}, {["x"] = 4, ["meta"] = {["fields"] = {}, ["inventory"] = {}}, ["y"] = 13, ["z"] = 9, ["name"] = "default:dirt_with_grass"}, {["x"] = 4, ["meta"] = {["fields"] = {}, ["inventory"] = {}}, ["y"] = 13, ["z"] = 10, ["name"] = "default:dirt"}, {["x"] = 4, ["meta"] = {["fields"] = {}, ["inventory"] = {}}, ["y"] = 13, ["z"] = 11, ["name"] = "default:dirt_with_grass"}, {["x"] = 4, ["meta"] = {["fields"] = {}, ["inventory"] = {}}, ["y"] = 14, ["param1"] = 13, ["z"] = 3, ["name"] = "mesecons_random:ghoststone_active"}, {["x"] = 4, ["meta"] = {["fields"] = {}, ["inventory"] = {}}, ["y"] = 14, ["param1"] = 13, ["z"] = 10, ["name"] = "mesecons_random:ghoststone_active"}, {["x"] = 4, ["meta"] = {["fields"] = {}, ["inventory"] = {}}, ["y"] = 15, ["param1"] = 13, ["z"] = 3, ["name"] = "mesecons_random:ghoststone_active"}, {["x"] = 4, ["meta"] = {["fields"] = {}, ["inventory"] = {}}, ["y"] = 15, ["param1"] = 13, ["z"] = 10, ["name"] = "mesecons_random:ghoststone_active"}, {["x"] = 4, ["meta"] = {["fields"] = {}, ["inventory"] = {}}, ["y"] = 16, ["param1"] = 13, ["z"] = 3, ["name"] = "mesecons_random:ghoststone_active"}, {["x"] = 4, ["meta"] = {["fields"] = {}, ["inventory"] = {}}, ["y"] = 16, ["param1"] = 13, ["z"] = 10, ["name"] = "mesecons_random:ghoststone_active"}, {["x"] = 4, ["meta"] = {["fields"] = {}, ["inventory"] = {}}, ["y"] = 17, ["param1"] = 15, ["z"] = 3, ["name"] = "mesecons_random:ghoststone_active"}, {["x"] = 4, ["meta"] = {["fields"] = {}, ["inventory"] = {}}, ["y"] = 17, ["param1"] = 15, ["z"] = 4, ["name"] = "mesecons_random:ghoststone_active"}, {["x"] = 4, ["meta"] = {["fields"] = {}, ["inventory"] = {}}, ["y"] = 17, ["param1"] = 15, ["z"] = 5, ["name"] = "mesecons_random:ghoststone_active"}, {["x"] = 4, ["meta"] = {["fields"] = {}, ["inventory"] = {}}, ["y"] = 17, ["param1"] = 15, ["z"] = 6, ["name"] = "mesecons_random:ghoststone_active"}, {["x"] = 4, ["meta"] = {["fields"] = {}, ["inventory"] = {}}, ["y"] = 17, ["param1"] = 15, ["z"] = 7, ["name"] = "mesecons_random:ghoststone_active"}, {["x"] = 4, ["meta"] = {["fields"] = {}, ["inventory"] = {}}, ["y"] = 17, ["param1"] = 15, ["z"] = 8, ["name"] = "mesecons_random:ghoststone_active"}, {["x"] = 4, ["meta"] = {["fields"] = {}, ["inventory"] = {}}, ["y"] = 17, ["param1"] = 15, ["z"] = 9, ["name"] = "mesecons_random:ghoststone_active"}, {["x"] = 4, ["meta"] = {["fields"] = {}, ["inventory"] = {}}, ["y"] = 17, ["param1"] = 15, ["z"] = 10, ["name"] = "mesecons_random:ghoststone_active"}, {["x"] = 5, ["meta"] = {["fields"] = {}, ["inventory"] = {}}, ["y"] = 0, ["z"] = 0, ["name"] = "default:dirt"}, {["x"] = 5, ["meta"] = {["fields"] = {}, ["inventory"] = {}}, ["y"] = 0, ["z"] = 1, ["name"] = "default:stone"}, {["x"] = 5, ["meta"] = {["fields"] = {}, ["inventory"] = {}}, ["y"] = 0, ["z"] = 2, ["name"] = "default:stone"}, {["x"] = 5, ["meta"] = {["fields"] = {}, ["inventory"] = {}}, ["y"] = 0, ["z"] = 3, ["name"] = "default:stone"}, {["x"] = 5, ["meta"] = {["fields"] = {}, ["inventory"] = {}}, ["y"] = 0, ["z"] = 4, ["name"] = "default:stone"}, {["x"] = 5, ["meta"] = {["fields"] = {}, ["inventory"] = {}}, ["y"] = 0, ["z"] = 5, ["name"] = "default:stone"}, {["x"] = 5, ["meta"] = {["fields"] = {}, ["inventory"] = {}}, ["y"] = 0, ["z"] = 6, ["name"] = "default:stone"}, {["x"] = 5, ["meta"] = {["fields"] = {}, ["inventory"] = {}}, ["y"] = 0, ["z"] = 7, ["name"] = "default:dirt"}, {["x"] = 5, ["meta"] = {["fields"] = {}, ["inventory"] = {}}, ["y"] = 0, ["z"] = 8, ["name"] = "default:dirt"}, {["x"] = 5, ["meta"] = {["fields"] = {}, ["inventory"] = {}}, ["y"] = 0, ["z"] = 9, ["name"] = "default:dirt"}, {["x"] = 5, ["meta"] = {["fields"] = {}, ["inventory"] = {}}, ["y"] = 0, ["z"] = 10, ["name"] = "default:dirt"}, {["x"] = 5, ["meta"] = {["fields"] = {}, ["inventory"] = {}}, ["y"] = 0, ["z"] = 11, ["name"] = "default:dirt"}, {["x"] = 5, ["meta"] = {["fields"] = {}, ["inventory"] = {}}, ["y"] = 0, ["z"] = 12, ["name"] = "default:dirt"}, {["x"] = 5, ["meta"] = {["fields"] = {}, ["inventory"] = {}}, ["y"] = 0, ["z"] = 13, ["name"] = "default:dirt"}, {["x"] = 5, ["meta"] = {["fields"] = {}, ["inventory"] = {}}, ["y"] = 0, ["z"] = 14, ["name"] = "default:dirt_with_grass"}, {["x"] = 5, ["meta"] = {["fields"] = {}, ["inventory"] = {}}, ["y"] = 1, ["z"] = 0, ["name"] = "default:dirt"}, {["x"] = 5, ["meta"] = {["fields"] = {}, ["inventory"] = {}}, ["y"] = 1, ["z"] = 1, ["name"] = "default:stone"}, {["x"] = 5, ["meta"] = {["fields"] = {}, ["inventory"] = {}}, ["y"] = 1, ["z"] = 2, ["name"] = "default:stone"}, {["x"] = 5, ["meta"] = {["fields"] = {}, ["inventory"] = {}}, ["y"] = 1, ["z"] = 3, ["name"] = "default:stone"}, {["x"] = 5, ["meta"] = {["fields"] = {}, ["inventory"] = {}}, ["y"] = 1, ["z"] = 4, ["name"] = "default:stone"}, {["x"] = 5, ["meta"] = {["fields"] = {}, ["inventory"] = {}}, ["y"] = 1, ["z"] = 5, ["name"] = "default:stone"}, {["x"] = 5, ["meta"] = {["fields"] = {}, ["inventory"] = {}}, ["y"] = 1, ["z"] = 6, ["name"] = "default:stone"}, {["x"] = 5, ["meta"] = {["fields"] = {}, ["inventory"] = {}}, ["y"] = 1, ["z"] = 7, ["name"] = "default:dirt"}, {["x"] = 5, ["meta"] = {["fields"] = {}, ["inventory"] = {}}, ["y"] = 1, ["z"] = 8, ["name"] = "default:dirt"}, {["x"] = 5, ["meta"] = {["fields"] = {}, ["inventory"] = {}}, ["y"] = 1, ["z"] = 9, ["name"] = "default:dirt"}, {["x"] = 5, ["meta"] = {["fields"] = {}, ["inventory"] = {}}, ["y"] = 1, ["z"] = 10, ["name"] = "default:dirt"}, {["x"] = 5, ["meta"] = {["fields"] = {}, ["inventory"] = {}}, ["y"] = 1, ["z"] = 11, ["name"] = "default:dirt"}, {["x"] = 5, ["meta"] = {["fields"] = {}, ["inventory"] = {}}, ["y"] = 1, ["z"] = 12, ["name"] = "default:dirt"}, {["x"] = 5, ["meta"] = {["fields"] = {}, ["inventory"] = {}}, ["y"] = 1, ["z"] = 13, ["name"] = "default:dirt_with_grass"}, {["x"] = 5, ["meta"] = {["fields"] = {}, ["inventory"] = {}}, ["y"] = 2, ["z"] = 0, ["name"] = "default:dirt"}, {["x"] = 5, ["meta"] = {["fields"] = {}, ["inventory"] = {}}, ["y"] = 2, ["z"] = 1, ["name"] = "default:stone"}, {["x"] = 5, ["meta"] = {["fields"] = {}, ["inventory"] = {}}, ["y"] = 2, ["z"] = 2, ["name"] = "default:stone"}, {["x"] = 5, ["meta"] = {["fields"] = {}, ["inventory"] = {}}, ["y"] = 2, ["z"] = 3, ["name"] = "default:stone"}, {["x"] = 5, ["meta"] = {["fields"] = {}, ["inventory"] = {}}, ["y"] = 2, ["z"] = 4, ["name"] = "default:stone"}, {["x"] = 5, ["meta"] = {["fields"] = {}, ["inventory"] = {}}, ["y"] = 2, ["z"] = 5, ["name"] = "default:stone"}, {["x"] = 5, ["meta"] = {["fields"] = {}, ["inventory"] = {}}, ["y"] = 2, ["z"] = 6, ["name"] = "default:stone"}, {["x"] = 5, ["meta"] = {["fields"] = {}, ["inventory"] = {}}, ["y"] = 2, ["z"] = 7, ["name"] = "default:stone"}, {["x"] = 5, ["meta"] = {["fields"] = {}, ["inventory"] = {}}, ["y"] = 2, ["z"] = 8, ["name"] = "default:stone"}, {["x"] = 5, ["meta"] = {["fields"] = {}, ["inventory"] = {}}, ["y"] = 2, ["z"] = 9, ["name"] = "default:stone"}, {["x"] = 5, ["meta"] = {["fields"] = {}, ["inventory"] = {}}, ["y"] = 2, ["z"] = 10, ["name"] = "default:stone"}, {["x"] = 5, ["meta"] = {["fields"] = {}, ["inventory"] = {}}, ["y"] = 2, ["z"] = 11, ["name"] = "default:stone"}, {["x"] = 5, ["meta"] = {["fields"] = {}, ["inventory"] = {}}, ["y"] = 2, ["z"] = 12, ["name"] = "default:dirt_with_grass"}, {["x"] = 5, ["meta"] = {["fields"] = {}, ["inventory"] = {}}, ["y"] = 3, ["z"] = 0, ["name"] = "default:dirt_with_grass"}, {["x"] = 5, ["meta"] = {["fields"] = {}, ["inventory"] = {}}, ["y"] = 3, ["z"] = 1, ["name"] = "default:stone"}, {["x"] = 5, ["meta"] = {["fields"] = {}, ["inventory"] = {}}, ["y"] = 3, ["z"] = 2, ["name"] = "default:stone"}, {["x"] = 5, ["meta"] = {["fields"] = {}, ["inventory"] = {}}, ["y"] = 3, ["z"] = 3, ["name"] = "default:stone"}, {["x"] = 5, ["meta"] = {["fields"] = {}, ["inventory"] = {}}, ["y"] = 3, ["z"] = 4, ["name"] = "default:stone"}, {["x"] = 5, ["meta"] = {["fields"] = {}, ["inventory"] = {}}, ["y"] = 3, ["z"] = 5, ["name"] = "default:stone"}, {["x"] = 5, ["meta"] = {["fields"] = {}, ["inventory"] = {}}, ["y"] = 3, ["z"] = 6, ["name"] = "default:stone"}, {["x"] = 5, ["meta"] = {["fields"] = {}, ["inventory"] = {}}, ["y"] = 3, ["z"] = 7, ["name"] = "default:stone"}, {["x"] = 5, ["meta"] = {["fields"] = {}, ["inventory"] = {}}, ["y"] = 3, ["z"] = 8, ["name"] = "default:stone"}, {["x"] = 5, ["meta"] = {["fields"] = {}, ["inventory"] = {}}, ["y"] = 3, ["z"] = 9, ["name"] = "default:stone"}, {["x"] = 5, ["meta"] = {["fields"] = {}, ["inventory"] = {}}, ["y"] = 3, ["z"] = 10, ["name"] = "default:stone"}, {["x"] = 5, ["meta"] = {["fields"] = {}, ["inventory"] = {}}, ["y"] = 3, ["z"] = 11, ["name"] = "default:stone"}, {["x"] = 5, ["meta"] = {["fields"] = {}, ["inventory"] = {}}, ["y"] = 3, ["param1"] = 12, ["z"] = 14, ["name"] = "default:leaves"}, {["x"] = 5, ["meta"] = {["fields"] = {}, ["inventory"] = {}}, ["y"] = 4, ["z"] = 1, ["name"] = "default:stone"}, {["x"] = 5, ["meta"] = {["fields"] = {}, ["inventory"] = {}}, ["y"] = 4, ["z"] = 2, ["name"] = "default:stone"}, {["x"] = 5, ["meta"] = {["fields"] = {}, ["inventory"] = {}}, ["y"] = 4, ["z"] = 3, ["name"] = "default:stone"}, {["x"] = 5, ["meta"] = {["fields"] = {}, ["inventory"] = {}}, ["y"] = 4, ["z"] = 4, ["name"] = "default:stone"}, {["x"] = 5, ["meta"] = {["fields"] = {}, ["inventory"] = {}}, ["y"] = 4, ["z"] = 5, ["name"] = "default:stone"}, {["x"] = 5, ["meta"] = {["fields"] = {}, ["inventory"] = {}}, ["y"] = 4, ["z"] = 6, ["name"] = "default:stone"}, {["x"] = 5, ["meta"] = {["fields"] = {}, ["inventory"] = {}}, ["y"] = 4, ["z"] = 7, ["name"] = "default:stone"}, {["x"] = 5, ["meta"] = {["fields"] = {}, ["inventory"] = {}}, ["y"] = 4, ["z"] = 8, ["name"] = "default:stone"}, {["x"] = 5, ["meta"] = {["fields"] = {}, ["inventory"] = {}}, ["y"] = 4, ["z"] = 9, ["name"] = "default:stone"}, {["x"] = 5, ["meta"] = {["fields"] = {}, ["inventory"] = {}}, ["y"] = 4, ["z"] = 10, ["name"] = "default:stone"}, {["x"] = 5, ["meta"] = {["fields"] = {}, ["inventory"] = {}}, ["y"] = 4, ["z"] = 11, ["name"] = "default:stone"}, {["x"] = 5, ["meta"] = {["fields"] = {}, ["inventory"] = {}}, ["y"] = 4, ["param1"] = 13, ["z"] = 13, ["name"] = "default:leaves"}, {["x"] = 5, ["meta"] = {["fields"] = {}, ["inventory"] = {}}, ["y"] = 4, ["param1"] = 13, ["z"] = 14, ["name"] = "default:leaves"}, {["x"] = 5, ["meta"] = {["fields"] = {}, ["inventory"] = {}}, ["y"] = 5, ["z"] = 1, ["name"] = "default:stone"}, {["x"] = 5, ["meta"] = {["fields"] = {}, ["inventory"] = {}}, ["y"] = 5, ["z"] = 2, ["name"] = "default:stone"}, {["x"] = 5, ["meta"] = {["fields"] = {}, ["inventory"] = {}}, ["y"] = 5, ["z"] = 3, ["name"] = "default:stone"}, {["x"] = 5, ["meta"] = {["fields"] = {}, ["inventory"] = {}}, ["y"] = 5, ["z"] = 4, ["name"] = "default:stone"}, {["x"] = 5, ["meta"] = {["fields"] = {}, ["inventory"] = {}}, ["y"] = 5, ["z"] = 5, ["name"] = "default:stone"}, {["x"] = 5, ["meta"] = {["fields"] = {}, ["inventory"] = {}}, ["y"] = 5, ["z"] = 6, ["name"] = "default:stone"}, {["x"] = 5, ["meta"] = {["fields"] = {}, ["inventory"] = {}}, ["y"] = 5, ["z"] = 7, ["name"] = "default:stone"}, {["x"] = 5, ["meta"] = {["fields"] = {}, ["inventory"] = {}}, ["y"] = 5, ["z"] = 8, ["name"] = "default:stone"}, {["x"] = 5, ["meta"] = {["fields"] = {}, ["inventory"] = {}}, ["y"] = 5, ["z"] = 9, ["name"] = "default:stone"}, {["x"] = 5, ["meta"] = {["fields"] = {}, ["inventory"] = {}}, ["y"] = 5, ["z"] = 10, ["name"] = "default:stone"}, {["x"] = 5, ["meta"] = {["fields"] = {}, ["inventory"] = {}}, ["y"] = 5, ["z"] = 11, ["name"] = "default:stone"}, {["x"] = 5, ["meta"] = {["fields"] = {}, ["inventory"] = {}}, ["y"] = 5, ["param1"] = 13, ["z"] = 13, ["name"] = "default:leaves"}, {["x"] = 5, ["meta"] = {["fields"] = {}, ["inventory"] = {}}, ["y"] = 5, ["param1"] = 14, ["z"] = 14, ["name"] = "default:leaves"}, {["x"] = 5, ["meta"] = {["fields"] = {}, ["inventory"] = {}}, ["y"] = 6, ["z"] = 1, ["name"] = "default:stone"}, {["x"] = 5, ["meta"] = {["fields"] = {}, ["inventory"] = {}}, ["y"] = 6, ["z"] = 2, ["name"] = "default:stone"}, {["x"] = 5, ["meta"] = {["fields"] = {}, ["inventory"] = {}}, ["y"] = 6, ["z"] = 3, ["name"] = "default:stone"}, {["x"] = 5, ["meta"] = {["fields"] = {}, ["inventory"] = {}}, ["y"] = 6, ["z"] = 4, ["name"] = "default:stone"}, {["x"] = 5, ["meta"] = {["fields"] = {}, ["inventory"] = {}}, ["y"] = 6, ["z"] = 5, ["name"] = "default:stone"}, {["x"] = 5, ["meta"] = {["fields"] = {}, ["inventory"] = {}}, ["y"] = 6, ["z"] = 6, ["name"] = "default:stone"}, {["x"] = 5, ["meta"] = {["fields"] = {}, ["inventory"] = {}}, ["y"] = 6, ["z"] = 7, ["name"] = "default:stone"}, {["x"] = 5, ["meta"] = {["fields"] = {}, ["inventory"] = {}}, ["y"] = 6, ["z"] = 8, ["name"] = "default:stone"}, {["x"] = 5, ["meta"] = {["fields"] = {}, ["inventory"] = {}}, ["y"] = 6, ["z"] = 9, ["name"] = "default:stone"}, {["x"] = 5, ["meta"] = {["fields"] = {}, ["inventory"] = {}}, ["y"] = 6, ["z"] = 10, ["name"] = "default:stone"}, {["x"] = 5, ["meta"] = {["fields"] = {}, ["inventory"] = {}}, ["y"] = 6, ["z"] = 11, ["name"] = "default:stone"}, {["x"] = 5, ["meta"] = {["fields"] = {}, ["inventory"] = {}}, ["y"] = 7, ["z"] = 1, ["name"] = "default:stone"}, {["x"] = 5, ["meta"] = {["fields"] = {}, ["inventory"] = {}}, ["y"] = 7, ["z"] = 2, ["name"] = "default:stone"}, {["x"] = 5, ["meta"] = {["fields"] = {}, ["inventory"] = {}}, ["y"] = 7, ["z"] = 3, ["name"] = "default:stone"}, {["x"] = 5, ["meta"] = {["fields"] = {}, ["inventory"] = {}}, ["y"] = 7, ["z"] = 4, ["name"] = "default:stone"}, {["x"] = 5, ["meta"] = {["fields"] = {}, ["inventory"] = {}}, ["y"] = 7, ["z"] = 5, ["name"] = "default:stone"}, {["x"] = 5, ["meta"] = {["fields"] = {}, ["inventory"] = {}}, ["y"] = 7, ["z"] = 6, ["name"] = "default:stone"}, {["x"] = 5, ["meta"] = {["fields"] = {}, ["inventory"] = {}}, ["y"] = 7, ["z"] = 7, ["name"] = "default:stone"}, {["x"] = 5, ["meta"] = {["fields"] = {}, ["inventory"] = {}}, ["y"] = 7, ["z"] = 8, ["name"] = "default:stone"}, {["x"] = 5, ["meta"] = {["fields"] = {}, ["inventory"] = {}}, ["y"] = 7, ["z"] = 9, ["name"] = "default:stone"}, {["x"] = 5, ["meta"] = {["fields"] = {}, ["inventory"] = {}}, ["y"] = 7, ["z"] = 10, ["name"] = "default:stone"}, {["x"] = 5, ["meta"] = {["fields"] = {}, ["inventory"] = {}}, ["y"] = 7, ["z"] = 11, ["name"] = "default:stone"}, {["x"] = 5, ["meta"] = {["fields"] = {}, ["inventory"] = {}}, ["y"] = 8, ["z"] = 1, ["name"] = "default:stone"}, {["x"] = 5, ["meta"] = {["fields"] = {}, ["inventory"] = {}}, ["y"] = 8, ["z"] = 2, ["name"] = "default:stone"}, {["x"] = 5, ["meta"] = {["fields"] = {}, ["inventory"] = {}}, ["y"] = 8, ["z"] = 3, ["name"] = "default:stone"}, {["x"] = 5, ["meta"] = {["fields"] = {}, ["inventory"] = {}}, ["y"] = 8, ["z"] = 4, ["name"] = "default:stone"}, {["x"] = 5, ["meta"] = {["fields"] = {}, ["inventory"] = {}}, ["y"] = 8, ["z"] = 5, ["name"] = "default:stone"}, {["x"] = 5, ["meta"] = {["fields"] = {}, ["inventory"] = {}}, ["y"] = 8, ["z"] = 6, ["name"] = "default:stone"}, {["x"] = 5, ["meta"] = {["fields"] = {}, ["inventory"] = {}},