5:return {{["x"] = 0, ["meta"] = {["fields"] = {}, ["inventory"] = {}}, ["param2"] = 18, ["y"] = 3, ["param1"] = 191, ["z"] = 2, ["name"] = "rainbow:slab_coolglass_black_1"}, {["x"] = 0, ["meta"] = {["fields"] = {}, ["inventory"] = {}}, ["param2"] = 18, ["y"] = 3, ["param1"] = 175, ["z"] = 3, ["name"] = "rainbow:slab_coolglass_black_1"}, {["x"] = 0, ["meta"] = {["fields"] = {}, ["inventory"] = {}}, ["param2"] = 18, ["y"] = 3, ["param1"] = 159, ["z"] = 4, ["name"] = "rainbow:slab_coolglass_black_1"}, {["x"] = 0, ["meta"] = {["fields"] = {}, ["inventory"] = {}}, ["param2"] = 18, ["y"] = 3, ["param1"] = 159, ["z"] = 5, ["name"] = "rainbow:slab_coolglass_black_1"}, {["x"] = 0, ["meta"] = {["fields"] = {}, ["inventory"] = {}}, ["param2"] = 18, ["y"] = 3, ["param1"] = 175, ["z"] = 6, ["name"] = "rainbow:slab_coolglass_black_1"}, {["x"] = 0, ["meta"] = {["fields"] = {}, ["inventory"] = {}}, ["param2"] = 18, ["y"] = 3, ["param1"] = 191, ["z"] = 7, ["name"] = "rainbow:slab_coolglass_black_1"}, {["x"] = 0, ["meta"] = {["fields"] = {}, ["inventory"] = {}}, ["param2"] = 18, ["y"] = 4, ["param1"] = 207, ["z"] = 2, ["name"] = "rainbow:slab_coolglass_black_1"}, {["x"] = 0, ["meta"] = {["fields"] = {}, ["inventory"] = {}}, ["param2"] = 18, ["y"] = 4, ["param1"] = 191, ["z"] = 3, ["name"] = "rainbow:slab_coolglass_black_1"}, {["x"] = 0, ["meta"] = {["fields"] = {}, ["inventory"] = {}}, ["param2"] = 18, ["y"] = 4, ["param1"] = 175, ["z"] = 4, ["name"] = "rainbow:slab_coolglass_black_1"}, {["x"] = 0, ["meta"] = {["fields"] = {}, ["inventory"] = {}}, ["param2"] = 18, ["y"] = 4, ["param1"] = 175, ["z"] = 5, ["name"] = "rainbow:slab_coolglass_black_1"}, {["x"] = 0, ["meta"] = {["fields"] = {}, ["inventory"] = {}}, ["param2"] = 18, ["y"] = 4, ["param1"] = 191, ["z"] = 6, ["name"] = "rainbow:slab_coolglass_black_1"}, {["x"] = 0, ["meta"] = {["fields"] = {}, ["inventory"] = {}}, ["param2"] = 18, ["y"] = 4, ["param1"] = 207, ["z"] = 7, ["name"] = "rainbow:slab_coolglass_black_1"}, {["x"] = 0, ["meta"] = {["fields"] = {}, ["inventory"] = {}}, ["param2"] = 18, ["y"] = 5, ["param1"] = 191, ["z"] = 2, ["name"] = "rainbow:slab_coolglass_black_1"}, {["x"] = 0, ["meta"] = {["fields"] = {}, ["inventory"] = {}}, ["param2"] = 18, ["y"] = 5, ["param1"] = 175, ["z"] = 3, ["name"] = "rainbow:slab_coolglass_black_1"}, {["x"] = 0, ["meta"] = {["fields"] = {}, ["inventory"] = {}}, ["param2"] = 18, ["y"] = 5, ["param1"] = 159, ["z"] = 4, ["name"] = "rainbow:slab_coolglass_black_1"}, {["x"] = 0, ["meta"] = {["fields"] = {}, ["inventory"] = {}}, ["param2"] = 18, ["y"] = 5, ["param1"] = 159, ["z"] = 5, ["name"] = "rainbow:slab_coolglass_black_1"}, {["x"] = 0, ["meta"] = {["fields"] = {}, ["inventory"] = {}}, ["param2"] = 18, ["y"] = 5, ["param1"] = 175, ["z"] = 6, ["name"] = "rainbow:slab_coolglass_black_1"}, {["x"] = 0, ["meta"] = {["fields"] = {}, ["inventory"] = {}}, ["param2"] = 18, ["y"] = 5, ["param1"] = 191, ["z"] = 7, ["name"] = "rainbow:slab_coolglass_black_1"}, {["x"] = 1, ["meta"] = {["fields"] = {}, ["inventory"] = {}}, ["param2"] = 20, ["y"] = 0, ["param1"] = 174, ["z"] = 1, ["name"] = "rainbow:slope_render_red_inner"}, {["x"] = 1, ["meta"] = {["fields"] = {}, ["inventory"] = {}}, ["y"] = 0, ["z"] = 2, ["name"] = "rainbow:render_red"}, {["x"] = 1, ["meta"] = {["fields"] = {}, ["inventory"] = {}}, ["y"] = 0, ["z"] = 3, ["name"] = "rainbow:render_red"}, {["x"] = 1, ["meta"] = {["fields"] = {}, ["inventory"] = {}}, ["y"] = 0, ["z"] = 4, ["name"] = "rainbow:render_red"}, {["x"] = 1, ["meta"] = {["fields"] = {}, ["inventory"] = {}}, ["y"] = 0, ["z"] = 5, ["name"] = "rainbow:render_red"}, {["x"] = 1, ["meta"] = {["fields"] = {}, ["inventory"] = {}}, ["y"] = 0, ["z"] = 6, ["name"] = "rainbow:render_red"}, {["x"] = 1, ["meta"] = {["fields"] = {}, ["inventory"] = {}}, ["y"] = 0, ["z"] = 7, ["name"] = "rainbow:render_red"}, {["x"] = 1, ["meta"] = {["fields"] = {}, ["inventory"] = {}}, ["param2"] = 23, ["y"] = 0, ["param1"] = 190, ["z"] = 8, ["name"] = "rainbow:slope_render_red_inner"}, {["x"] = 1, ["meta"] = {["fields"] = {}, ["inventory"] = {}}, ["param2"] = 1, ["y"] = 1, ["param1"] = 190, ["z"] = 1, ["name"] = "rainbow:slope_render_red_inner"}, {["x"] = 1, ["meta"] = {["fields"] = {}, ["inventory"] = {}}, ["y"] = 1, ["param1"] = 206, ["z"] = 2, ["name"] = "rainbow:coolglass_red"}, {["x"] = 1, ["meta"] = {["fields"] = {}, ["inventory"] = {}}, ["y"] = 1, ["param1"] = 190, ["z"] = 3, ["name"] = "rainbow:coolglass_red"}, {["x"] = 1, ["meta"] = {["fields"] = {}, ["inventory"] = {}}, ["y"] = 1, ["param1"] = 174, ["z"] = 4, ["name"] = "rainbow:coolglass_red"}, {["x"] = 1, ["meta"] = {["fields"] = {}, ["inventory"] = {}}, ["y"] = 1, ["param1"] = 174, ["z"] = 5, ["name"] = "rainbow:coolglass_red"}, {["x"] = 1, ["meta"] = {["fields"] = {}, ["inventory"] = {}}, ["y"] = 1, ["param1"] = 190, ["z"] = 6, ["name"] = "rainbow:coolglass_red"}, {["x"] = 1, ["meta"] = {["fields"] = {}, ["inventory"] = {}}, ["y"] = 1, ["param1"] = 206, ["z"] = 7, ["name"] = "rainbow:coolglass_red"}, {["x"] = 1, ["meta"] = {["fields"] = {}, ["inventory"] = {}}, ["param2"] = 2, ["y"] = 1, ["param1"] = 190, ["z"] = 8, ["name"] = "rainbow:slope_render_red_inner"}, {["x"] = 1, ["meta"] = {["fields"] = {}, ["inventory"] = {}}, ["param2"] = 20, ["y"] = 2, ["param1"] = 174, ["z"] = 1, ["name"] = "rainbow:slope_render_red_inner"}, {["x"] = 1, ["meta"] = {["fields"] = {}, ["inventory"] = {}}, ["y"] = 2, ["z"] = 2, ["name"] = "rainbow:render_red"}, {["x"] = 1, ["meta"] = {["fields"] = {}, ["inventory"] = {}}, ["y"] = 2, ["z"] = 3, ["name"] = "rainbow:render_red"}, {["x"] = 1, ["meta"] = {["fields"] = {}, ["inventory"] = {}}, ["y"] = 2, ["z"] = 4, ["name"] = "rainbow:render_red"}, {["x"] = 1, ["meta"] = {["fields"] = {}, ["inventory"] = {}}, ["y"] = 2, ["z"] = 5, ["name"] = "rainbow:render_red"}, {["x"] = 1, ["meta"] = {["fields"] = {}, ["inventory"] = {}}, ["y"] = 2, ["z"] = 6, ["name"] = "rainbow:render_red"}, {["x"] = 1, ["meta"] = {["fields"] = {}, ["inventory"] = {}}, ["y"] = 2, ["z"] = 7, ["name"] = "rainbow:render_red"}, {["x"] = 1, ["meta"] = {["fields"] = {}, ["inventory"] = {}}, ["param2"] = 23, ["y"] = 2, ["param1"] = 174, ["z"] = 8, ["name"] = "rainbow:slope_render_red_inner"}, {["x"] = 1, ["meta"] = {["fields"] = {}, ["inventory"] = {}}, ["param2"] = 1, ["y"] = 3, ["param1"] = 190, ["z"] = 1, ["name"] = "rainbow:slope_render_red_inner"}, {["x"] = 1, ["meta"] = {["fields"] = {}, ["inventory"] = {}}, ["param2"] = 2, ["y"] = 3, ["param1"] = 190, ["z"] = 8, ["name"] = "rainbow:slope_render_red_inner"}, {["x"] = 1, ["meta"] = {["fields"] = {}, ["inventory"] = {}}, ["param2"] = 20, ["y"] = 4, ["param1"] = 206, ["z"] = 1, ["name"] = "rainbow:slope_render_red_inner"}, {["x"] = 1, ["meta"] = {["fields"] = {}, ["inventory"] = {}}, ["param2"] = 5, ["y"] = 4, ["param1"] = 222, ["z"] = 2, ["name"] = "default:torch_wall"}, {["x"] = 1, ["meta"] = {["fields"] = {}, ["inventory"] = {}}, ["param2"] = 4, ["y"] = 4, ["param1"] = 222, ["z"] = 7, ["name"] = "default:torch_wall"}, {["x"] = 1, ["meta"] = {["fields"] = {}, ["inventory"] = {}}, ["param2"] = 23, ["y"] = 4, ["param1"] = 206, ["z"] = 8, ["name"] = "rainbow:slope_render_red_inner"}, {["x"] = 1, ["meta"] = {["fields"] = {}, ["inventory"] = {}}, ["param2"] = 1, ["y"] = 5, ["param1"] = 190, ["z"] = 1, ["name"] = "rainbow:slope_render_red_inner"}, {["x"] = 1, ["meta"] = {["fields"] = {}, ["inventory"] = {}}, ["param2"] = 2, ["y"] = 5, ["param1"] = 190, ["z"] = 8, ["name"] = "rainbow:slope_render_red_inner"}, {["x"] = 1, ["meta"] = {["fields"] = {}, ["inventory"] = {}}, ["param2"] = 20, ["y"] = 6, ["param1"] = 174, ["z"] = 1, ["name"] = "rainbow:slope_render_red_inner"}, {["x"] = 1, ["meta"] = {["fields"] = {}, ["inventory"] = {}}, ["y"] = 6, ["z"] = 2, ["name"] = "rainbow:render_red"}, {["x"] = 1, ["meta"] = {["fields"] = {}, ["inventory"] = {}}, ["y"] = 6, ["z"] = 3, ["name"] = "rainbow:render_red"}, {["x"] = 1, ["meta"] = {["fields"] = {}, ["inventory"] = {}}, ["y"] = 6, ["z"] = 4, ["name"] = "rainbow:render_red"}, {["x"] = 1, ["meta"] = {["fields"] = {}, ["inventory"] = {}}, ["y"] = 6, ["z"] = 5, ["name"] = "rainbow:render_red"}, {["x"] = 1, ["meta"] = {["fields"] = {}, ["inventory"] = {}}, ["y"] = 6, ["z"] = 6, ["name"] = "rainbow:render_red"}, {["x"] = 1, ["meta"] = {["fields"] = {}, ["inventory"] = {}}, ["y"] = 6, ["z"] = 7, ["name"] = "rainbow:render_red"}, {["x"] = 1, ["meta"] = {["fields"] = {}, ["inventory"] = {}}, ["param2"] = 23, ["y"] = 6, ["param1"] = 174, ["z"] = 8, ["name"] = "rainbow:slope_render_red_inner"}, {["x"] = 1, ["meta"] = {["fields"] = {}, ["inventory"] = {}}, ["param2"] = 3, ["y"] = 7, ["param1"] = 158, ["z"] = 1, ["name"] = "rainbow:slope_render_red_outer"}, {["x"] = 1, ["meta"] = {["fields"] = {}, ["inventory"] = {}}, ["y"] = 7, ["param1"] = 142, ["z"] = 2, ["name"] = "rainbow:slope_render_red"}, {["x"] = 1, ["meta"] = {["fields"] = {}, ["inventory"] = {}}, ["param2"] = 2, ["y"] = 7, ["param1"] = 126, ["z"] = 3, ["name"] = "rainbow:slope_render_red"}, {["x"] = 1, ["meta"] = {["fields"] = {}, ["inventory"] = {}}, ["y"] = 7, ["param1"] = 110, ["z"] = 4, ["name"] = "rainbow:slope_render_red"}, {["x"] = 1, ["meta"] = {["fields"] = {}, ["inventory"] = {}}, ["param2"] = 2, ["y"] = 7, ["param1"] = 110, ["z"] = 5, ["name"] = "rainbow:slope_render_red"}, {["x"] = 1, ["meta"] = {["fields"] = {}, ["inventory"] = {}}, ["y"] = 7, ["param1"] = 126, ["z"] = 6, ["name"] = "rainbow:slope_render_red"}, {["x"] = 1, ["meta"] = {["fields"] = {}, ["inventory"] = {}}, ["param2"] = 2, ["y"] = 7, ["param1"] = 142, ["z"] = 7, ["name"] = "rainbow:slope_render_red"}, {["x"] = 1, ["meta"] = {["fields"] = {}, ["inventory"] = {}}, ["y"] = 7, ["param1"] = 158, ["z"] = 8, ["name"] = "rainbow:slope_render_red_outer"}, {["x"] = 2, ["meta"] = {["fields"] = {}, ["inventory"] = {}}, ["y"] = 0, ["z"] = 1, ["name"] = "rainbow:render_red"}, {["x"] = 2, ["meta"] = {["fields"] = {["infotext"] = "Locked Chest (owned by Elektra)", ["owner"] = "Elektra"}, ["inventory"] = {["main"] = {"default:book 28", "", "", "ts_furniture:rainbow_wood_white_chair", "rainbow:render_red 2", "beds:bed_bottom", "homedecor:sportbench 99", "homedecor:soda_machine 98", "default:chest_locked 99", "default:coal_lump 99", "default:bookshelf", "default:coal_lump 99", "default:coal_lump 99", "default:coal_lump 99", "default:coal_lump 99", "default:coal_lump 99", "default:coal_lump 99", "default:coal_lump 99", "default:coal_lump 99", "default:coal_lump 99", "default:coal_lump 99", "default:coal_lump 99", "default:coal_lump 99", "default:coal_lump 99", "homedecor:coin 99", "", "", "", "", "", "", ""}}}, ["param2"] = 2, ["y"] = 0, ["z"] = 2, ["name"] = "default:chest_locked"}, {["x"] = 2, ["meta"] = {["fields"] = {["sound"] = "0", ["smoky"] = "0"}, ["inventory"] = {}}, ["y"] = 0, ["param1"] = 238, ["z"] = 7, ["name"] = "fake_fire:fancy_fire"}, {["x"] = 2, ["meta"] = {["fields"] = {}, ["inventory"] = {}}, ["y"] = 0, ["z"] = 8, ["name"] = "rainbow:render_red"}, {["x"] = 2, ["meta"] = {["fields"] = {}, ["inventory"] = {}}, ["y"] = 1, ["param1"] = 206, ["z"] = 1, ["name"] = "rainbow:coolglass_red"}, {["x"] = 2, ["meta"] = {["fields"] = {}, ["inventory"] = {}}, ["param2"] = 5, ["y"] = 1, ["param1"] = 221, ["z"] = 2, ["name"] = "default:torch_wall"}, {["x"] = 2, ["meta"] = {["fields"] = {}, ["inventory"] = {}}, ["y"] = 1, ["param1"] = 206, ["z"] = 8, ["name"] = "rainbow:coolglass_red"}, {["x"] = 2, ["meta"] = {["fields"] = {}, ["inventory"] = {}}, ["y"] = 2, ["z"] = 1, ["name"] = "rainbow:render_red"}, {["x"] = 2, ["meta"] = {["fields"] = {}, ["inventory"] = {}}, ["param2"] = 21, ["y"] = 2, ["param1"] = 206, ["z"] = 2, ["name"] = "rainbow:slab_render_red_1"}, {["x"] = 2, ["meta"] = {["fields"] = {}, ["inventory"] = {}}, ["param2"] = 22, ["y"] = 2, ["param1"] = 190, ["z"] = 3, ["name"] = "rainbow:slab_render_red_1"}, {["x"] = 2, ["meta"] = {["fields"] = {}, ["inventory"] = {}}, ["param2"] = 22, ["y"] = 2, ["param1"] = 174, ["z"] = 4, ["name"] = "rainbow:slab_render_red_1"}, {["x"] = 2, ["meta"] = {["fields"] = {}, ["inventory"] = {}}, ["param2"] = 21, ["y"] = 2, ["param1"] = 174, ["z"] = 5, ["name"] = "rainbow:slab_render_red_1"}, {["x"] = 2, ["meta"] = {["fields"] = {}, ["inventory"] = {}}, ["param2"] = 21, ["y"] = 2, ["param1"] = 190, ["z"] = 6, ["name"] = "rainbow:slab_render_red_1"}, {["x"] = 2, ["meta"] = {["fields"] = {}, ["inventory"] = {}}, ["param2"] = 21, ["y"] = 2, ["param1"] = 206, ["z"] = 7, ["name"] = "rainbow:slab_render_red_1"}, {["x"] = 2, ["meta"] = {["fields"] = {}, ["inventory"] = {}}, ["y"] = 2, ["z"] = 8, ["name"] = "rainbow:render_red"}, {["x"] = 2, ["meta"] = {["fields"] = {}, ["inventory"] = {}}, ["param2"] = 9, ["y"] = 3, ["param1"] = 191, ["z"] = 0, ["name"] = "rainbow:slab_coolglass_black_1"}, {["x"] = 2, ["meta"] = {["fields"] = {}, ["inventory"] = {}}, ["param2"] = 7, ["y"] = 3, ["param1"] = 191, ["z"] = 9, ["name"] = "rainbow:slab_coolglass_black_1"}, {["x"] = 2, ["meta"] = {["fields"] = {}, ["inventory"] = {}}, ["param2"] = 9, ["y"] = 4, ["param1"] = 207, ["z"] = 0, ["name"] = "rainbow:slab_coolglass_black_1"}, {["x"] = 2, ["meta"] = {["fields"] = {}, ["inventory"] = {}}, ["param2"] = 3, ["y"] = 4, ["param1"] = 222, ["z"] = 1, ["name"] = "default:torch_wall"}, {["x"] = 2, ["meta"] = {["fields"] = {}, ["inventory"] = {}}, ["param2"] = 3, ["y"] = 4, ["param1"] = 222, ["z"] = 8, ["name"] = "default:torch_wall"}, {["x"] = 2, ["meta"] = {["fields"] = {}, ["inventory"] = {}}, ["param2"] = 7, ["y"] = 4, ["param1"] = 207, ["z"] = 9, ["name"] = "rainbow:slab_coolglass_black_1"}, {["x"] = 2, ["meta"] = {["fields"] = {}, ["inventory"] = {}}, ["param2"] = 9, ["y"] = 5, ["param1"] = 191, ["z"] = 0, ["name"] = "rainbow:slab_coolglass_black_1"}, {["x"] = 2, ["meta"] = {["fields"] = {}, ["inventory"] = {}}, ["param2"] = 7, ["y"] = 5, ["param1"] = 191, ["z"] = 9, ["name"] = "rainbow:slab_coolglass_black_1"}, {["x"] = 2, ["meta"] = {["fields"] = {}, ["inventory"] = {}}, ["y"] = 6, ["z"] = 1, ["name"] = "rainbow:render_red"}, {["x"] = 2, ["meta"] = {["fields"] = {}, ["inventory"] = {}}, ["y"] = 6, ["param1"] = 175, ["z"] = 2, ["name"] = "rainbow:coolglass_red"}, {["x"] = 2, ["meta"] = {["fields"] = {}, ["inventory"] = {}}, ["y"] = 6, ["param1"] = 159, ["z"] = 3, ["name"] = "rainbow:coolglass_red"}, {["x"] = 2, ["meta"] = {["fields"] = {}, ["inventory"] = {}}, ["y"] = 6, ["param1"] = 143, ["z"] = 4, ["name"] = "rainbow:coolglass_red"}, {["x"] = 2, ["meta"] = {["fields"] = {}, ["inventory"] = {}}, ["y"] = 6, ["param1"] = 143, ["z"] = 5, ["name"] = "rainbow:coolglass_red"}, {["x"] = 2, ["meta"] = {["fields"] = {}, ["inventory"] = {}}, ["y"] = 6, ["param1"] = 159, ["z"] = 6, ["name"] = "rainbow:coolglass_red"}, {["x"] = 2, ["meta"] = {["fields"] = {}, ["inventory"] = {}}, ["y"] = 6, ["param1"] = 175, ["z"] = 7, ["name"] = "rainbow:coolglass_red"}, {["x"] = 2, ["meta"] = {["fields"] = {}, ["inventory"] = {}}, ["y"] = 6, ["z"] = 8, ["name"] = "rainbow:render_red"}, {["x"] = 2, ["meta"] = {["fields"] = {}, ["inventory"] = {}}, ["param2"] = 1, ["y"] = 7, ["param1"] = 142, ["z"] = 1, ["name"] = "rainbow:slope_render_red"}, {["x"] = 2, ["meta"] = {["fields"] = {}, ["inventory"] = {}}, ["param2"] = 1, ["y"] = 7, ["param1"] = 142, ["z"] = 8, ["name"] = "rainbow:slope_render_red"}, {["x"] = 3, ["meta"] = {["fields"] = {}, ["inventory"] = {}}, ["y"] = 0, ["z"] = 1, ["name"] = "rainbow:render_red"}, {["x"] = 3, ["meta"] = {["fields"] = {}, ["inventory"] = {}}, ["param2"] = 2, ["y"] = 0, ["param1"] = 188, ["z"] = 2, ["name"] = "homedecor:soda_machine"}, {["x"] = 3, ["meta"] = {["fields"] = {}, ["inventory"] = {}}, ["y"] = 0, ["z"] = 8, ["name"] = "rainbow:render_red"}, {["x"] = 3, ["meta"] = {["fields"] = {}, ["inventory"] = {}}, ["y"] = 1, ["param1"] = 190, ["z"] = 1, ["name"] = "rainbow:coolglass_red"}, {["x"] = 3, ["meta"] = {["fields"] = {}, ["inventory"] = {}}, ["y"] = 1, ["param1"] = 190, ["z"] = 8, ["name"] = "rainbow:coolglass_red"}, {["x"] = 3, ["meta"] = {["fields"] = {}, ["inventory"] = {}}, ["y"] = 2, ["z"] = 1, ["name"] = "rainbow:render_red"}, {["x"] = 3, ["meta"] = {["fields"] = {}, ["inventory"] = {}}, ["param2"] = 20, ["y"] = 2, ["param1"] = 190, ["z"] = 2, ["name"] = "rainbow:slab_render_red_1"}, {["x"] = 3, ["meta"] = {["fields"] = {}, ["inventory"] = {}}, ["param2"] = 21, ["y"] = 2, ["param1"] = 174, ["z"] = 3, ["name"] = "rainbow:slab_render_red_1"}, {["x"] = 3, ["meta"] = {["fields"] = {}, ["inventory"] = {}}, ["param2"] = 22, ["y"] = 2, ["param1"] = 158, ["z"] = 4, ["name"] = "rainbow:slab_render_red_1"}, {["x"] = 3, ["meta"] = {["fields"] = {}, ["inventory"] = {}}, ["param2"] = 21, ["y"] = 2, ["param1"] = 158, ["z"] = 5, ["name"] = "rainbow:slab_render_red_1"}, {["x"] = 3, ["meta"] = {["fields"] = {}, ["inventory"] = {}}, ["param2"] = 21, ["y"] = 2, ["param1"] = 174, ["z"] = 6, ["name"] = "rainbow:slab_render_red_1"}, {["x"] = 3, ["meta"] = {["fields"] = {}, ["inventory"] = {}}, ["param2"] = 20, ["y"] = 2, ["param1"] = 190, ["z"] = 7, ["name"] = "rainbow:slab_render_red_1"}, {["x"] = 3, ["meta"] = {["fields"] = {}, ["inventory"] = {}}, ["y"] = 2, ["z"] = 8, ["name"] = "rainbow:render_red"}, {["x"] = 3, ["meta"] = {["fields"] = {}, ["inventory"] = {}}, ["param2"] = 9, ["y"] = 3, ["param1"] = 175, ["z"] = 0, ["name"] = "rainbow:slab_coolglass_black_1"}, {["x"] = 3, ["meta"] = {["fields"] = {}, ["inventory"] = {}}, ["param2"] = 7, ["y"] = 3, ["param1"] = 175, ["z"] = 9, ["name"] = "rainbow:slab_coolglass_black_1"}, {["x"] = 3, ["meta"] = {["fields"] = {}, ["inventory"] = {}}, ["param2"] = 9, ["y"] = 4, ["param1"] = 191, ["z"] = 0, ["name"] = "rainbow:slab_coolglass_black_1"}, {["x"] = 3, ["meta"] = {["fields"] = {}, ["inventory"] = {}}, ["param2"] = 7, ["y"] = 4, ["param1"] = 191, ["z"] = 9, ["name"] = "rainbow:slab_coolglass_black_1"}, {["x"] = 3, ["meta"] = {["fields"] = {}, ["inventory"] = {}}, ["param2"] = 9, ["y"] = 5, ["param1"] = 175, ["z"] = 0, ["name"] = "rainbow:slab_coolglass_black_1"}, {["x"] = 3, ["meta"] = {["fields"] = {}, ["inventory"] = {}}, ["param2"] = 7, ["y"] = 5, ["param1"] = 175, ["z"] = 9, ["name"] = "rainbow:slab_coolglass_black_1"}, {["x"] = 3, ["meta"] = {["fields"] = {}, ["inventory"] = {}}, ["y"] = 6, ["z"] = 1, ["name"] = "rainbow:render_red"}, {["x"] = 3, ["meta"] = {["fields"] = {}, ["inventory"] = {}}, ["y"] = 6, ["param1"] = 159, ["z"] = 2, ["name"] = "rainbow:coolglass_red"}, {["x"] = 3, ["meta"] = {["fields"] = {}, ["inventory"] = {}}, ["y"] = 6, ["param1"] = 143, ["z"] = 3, ["name"] = "rainbow:coolglass_red"}, {["x"] = 3, ["meta"] = {["fields"] = {}, ["inventory"] = {}}, ["y"] = 6, ["param1"] = 127, ["z"] = 4, ["name"] = "rainbow:coolglass_red"}, {["x"] = 3, ["meta"] = {["fields"] = {}, ["inventory"] = {}}, ["y"] = 6, ["param1"] = 127, ["z"] = 5, ["name"] = "rainbow:coolglass_red"}, {["x"] = 3, ["meta"] = {["fields"] = {}, ["inventory"] = {}}, ["y"] = 6, ["param1"] = 143, ["z"] = 6, ["name"] = "rainbow:coolglass_red"}, {["x"] = 3, ["meta"] = {["fields"] = {}, ["inventory"] = {}}, ["y"] = 6, ["param1"] = 159, ["z"] = 7, ["name"] = "rainbow:coolglass_red"}, {["x"] = 3, ["meta"] = {["fields"] = {}, ["inventory"] = {}}, ["y"] = 6, ["z"] = 8, ["name"] = "rainbow:render_red"}, {["x"] = 3, ["meta"] = {["fields"] = {}, ["inventory"] = {}}, ["param2"] = 3, ["y"] = 7, ["param1"] = 126, ["z"] = 1, ["name"] = "rainbow:slope_render_red"}, {["x"] = 3, ["meta"] = {["fields"] = {}, ["inventory"] = {}}, ["param2"] = 3, ["y"] = 7, ["param1"] = 126, ["z"] = 8, ["name"] = "rainbow:slope_render_red"}, {["x"] = 4, ["meta"] = {["fields"] = {}, ["inventory"] = {}}, ["y"] = 0, ["z"] = 1, ["name"] = "rainbow:render_red"}, {["x"] = 4, ["meta"] = {["fields"] = {["infotext"] = "Refrigerator", ["formspec"] = "size[10,10]bgcolor[#080808BB;true]background[5,5;1,1;gui_formbg.png;true]listcolors[#00000069;#5A5A5A;#141318;#30434C;#FFF]list[context;main;0,0;10,5;]list[current_player;main;1,6;8,4;]listring[]"}, ["inventory"] = {["main"] = {"crops:corn_cob 99", "crops:potato 99", "homedecor:soda_can 99", "mobs:bucket_milk", "homedecor:soda_can 99", "", "", "", "", "", "crops:roasted_pumpkin 99", "crops:green_bean 99", "mobs:rat_cooked 99", "mobs:bucket_milk", "homedecor:soda_can 7", "", "", "", "", "", "crops:tomato 99", "crops:corn_on_the_cob 99", "mobs:chicken_egg_fried 99", "mobs:bucket_milk", "mobs:bucket_milk", "", "", "", "", "", "crops:uncooked_vegetable_stew 99", "crops:vegetable_stew 99", "farming:bread 98", "mobs:bucket_milk", "mobs:bucket_milk", "", "", "", "", "", "default:apple 99", "mobs:cheese 99", "crops:melon_slice 99", "mobs:honey 99", "mobs:bucket_milk", "", "", "", "", ""}}}, ["param2"] = 2, ["y"] = 0, ["param1"] = 172, ["z"] = 2, ["name"] = "homedecor:refrigerator_white"}, {["x"] = 4, ["meta"] = {["fields"] = {}, ["inventory"] = {}}, ["y"] = 0, ["z"] = 8, ["name"] = "rainbow:render_red"}, {["x"] = 4, ["meta"] = {["fields"] = {}, ["inventory"] = {}}, ["y"] = 1, ["param1"] = 174, ["z"] = 1, ["name"] = "rainbow:coolglass_red"}, {["x"] = 4, ["meta"] = {["fields"] = {}, ["inventory"] = {}}, ["y"] = 1, ["param1"] = 174, ["z"] = 8, ["name"] = "rainbow:coolglass_red"}, {["x"] = 4, ["meta"] = {["fields"] = {}, ["inventory"] = {}}, ["y"] = 2, ["z"] = 1, ["name"] = "rainbow:render_red"}, {["x"] = 4, ["meta"] = {["fields"] = {}, ["inventory"] = {}}, ["param2"] = 3, ["y"] = 2, ["param1"] = 206, ["z"] = 2, ["name"] = "rainbow:slope_render_white"}, {["x"] = 4, ["meta"] = {["fields"] = {}, ["inventory"] = {}}, ["param2"] = 23, ["y"] = 2, ["param1"] = 190, ["z"] = 3, ["name"] = "rainbow:slab_render_red_1"}, {["x"] = 4, ["meta"] = {["fields"] = {}, ["inventory"] = {}}, ["param2"] = 21, ["y"] = 2, ["param1"] = 174, ["z"] = 4, ["name"] = "rainbow:slab_render_red_1"}, {["x"] = 4, ["meta"] = {["fields"] = {}, ["inventory"] = {}}, ["param2"] = 21, ["y"] = 2, ["param1"] = 158, ["z"] = 5, ["name"] = "rainbow:slab_render_red_1"}, {["x"] = 4, ["meta"] = {["fields"] = {}, ["inventory"] = {}}, ["param2"] = 21, ["y"] = 2, ["param1"] = 158, ["z"] = 6, ["name"] = "rainbow:slab_render_red_1"}, {["x"] = 4, ["meta"] = {["fields"] = {}, ["inventory"] = {}}, ["param2"] = 20, ["y"] = 2, ["param1"] = 174, ["z"] = 7, ["name"] = "rainbow:slab_render_red_1"}, {["x"] = 4, ["meta"] = {["fields"] = {}, ["inventory"] = {}}, ["y"] = 2, ["z"] = 8, ["name"] = "rainbow:render_red"}, {["x"] = 4, ["meta"] = {["fields"] = {}, ["inventory"] = {}}, ["param2"] = 9, ["y"] = 3, ["param1"] = 159, ["z"] = 0, ["name"] = "rainbow:slab_coolglass_black_1"}, {["x"] = 4, ["meta"] = {["fields"] = {}, ["inventory"] = {}}, ["param2"] = 7, ["y"] = 3, ["param1"] = 159, ["z"] = 9, ["name"] = "rainbow:slab_coolglass_black_1"}, {["x"] = 4, ["meta"] = {["fields"] = {}, ["inventory"] = {}}, ["param2"] = 9, ["y"] = 4, ["param1"] = 175, ["z"] = 0, ["name"] = "rainbow:slab_coolglass_black_1"}, {["x"] = 4, ["meta"] = {["fields"] = {}, ["inventory"] = {}}, ["param2"] = 7, ["y"] = 4, ["param1"] = 175, ["z"] = 9, ["name"] = "rainbow:slab_coolglass_black_1"}, {["x"] = 4, ["meta"] = {["fields"] = {}, ["inventory"] = {}}, ["param2"] = 9, ["y"] = 5, ["param1"] = 159, ["z"] = 0, ["name"] = "rainbow:slab_coolglass_black_1"}, {["x"] = 4, ["meta"] = {["fields"] = {}, ["inventory"] = {}}, ["param2"] = 7, ["y"] = 5, ["param1"] = 159, ["z"] = 9, ["name"] = "rainbow:slab_coolglass_black_1"}, {["x"] = 4, ["meta"] = {["fields"] = {}, ["inventory"] = {}}, ["y"] = 6, ["z"] = 1, ["name"] = "rainbow:render_red"}, {["x"] = 4, ["meta"] = {["fields"] = {}, ["inventory"] = {}}, ["y"] = 6, ["param1"] = 143, ["z"] = 2, ["name"] = "rainbow:coolglass_red"}, {["x"] = 4, ["meta"] = {["fields"] = {}, ["inventory"] = {}}, ["y"] = 6, ["param1"] = 127, ["z"] = 3, ["name"] = "rainbow:coolglass_red"}, {["x"] = 4, ["meta"] = {["fields"] = {}, ["inventory"] = {}}, ["y"] = 6, ["param1"] = 111, ["z"] = 4, ["name"] = "rainbow:coolglass_red"}, {["x"] = 4, ["meta"] = {["fields"] = {}, ["inventory"] = {}}, ["y"] = 6, ["param1"] = 111, ["z"] = 5, ["name"] = "rainbow:coolglass_red"}, {["x"] = 4, ["meta"] = {["fields"] = {}, ["inventory"] = {}}, ["y"] = 6, ["param1"] = 127, ["z"] = 6, ["name"] = "rainbow:coolglass_red"}, {["x"] = 4, ["meta"] = {["fields"] = {}, ["inventory"] = {}}, ["y"] = 6, ["param1"] = 143, ["z"] = 7, ["name"] = "rainbow:coolglass_red"}, {["x"] = 4, ["meta"] = {["fields"] = {}, ["inventory"] = {}}, ["y"] = 6, ["z"] = 8, ["name"] = "rainbow:render_red"}, {["x"] = 5, ["meta"] = {["fields"] = {}, ["inventory"] = {}}, ["y"] = 0, ["z"] = 1, ["name"] = "rainbow:render_red"}, {["x"] = 5, ["meta"] = {["fields"] = {["owner"] = "Elektra", ["src_totaltime"] = "0", ["formspec"] = "size[8,9]image[2,2;1,1;default_furnace_fire_bg.png]list[current_name;fuel;2,3;1,1;]list[current_name;src;2,1;1,1;]list[current_name;dst;5,1;2,2;]list[current_player;main;0,5;8,4;]listring[current_name;dst]listring[current_player;main]listring[current_name;src]listring[current_player;main]", ["fuel_time"] = "0", ["fuel_totaltime"] = "0", ["src_time"] = "0", ["infotext"] = "Oven (Locked) (out of fuel)"}, ["inventory"] = {["fuel"] = {"default:coal_lump 99"}, ["dst"] = {"", "", "", ""}, ["src"] = {""}}}, ["param2"] = 2, ["y"] = 0, ["param1"] = 189, ["z"] = 2, ["name"] = "homedecor:oven_locked"}, {["x"] = 5, ["meta"] = {["fields"] = {}, ["inventory"] = {}}, ["y"] = 0, ["z"] = 8, ["name"] = "rainbow:render_red"}, {["x"] = 5, ["meta"] = {["fields"] = {}, ["inventory"] = {}}, ["y"] = 1, ["param1"] = 190, ["z"] = 1, ["name"] = "rainbow:coolglass_red"}, {["x"] = 5, ["meta"] = {["fields"] = {}, ["inventory"] = {}}, ["param2"] = 3, ["y"] = 1, ["param1"] = 206, ["z"] = 2, ["name"] = "rainbow:slope_render_white"}, {["x"] = 5, ["meta"] = {["fields"] = {}, ["inventory"] = {}}, ["y"] = 1, ["param1"] = 174, ["z"] = 8, ["name"] = "rainbow:coolglass_red"}, {["x"] = 5, ["meta"] = {["fields"] = {}, ["inventory"] = {}}, ["y"] = 2, ["z"] = 1, ["name"] = "rainbow:render_red"}, {["x"] = 5, ["meta"] = {["fields"] = {}, ["inventory"] = {}}, ["param2"] = 5, ["y"] = 2, ["param1"] = 223, ["z"] = 2, ["name"] = "default:torch_wall"}, {["x"] = 5, ["meta"] = {["fields"] = {}, ["inventory"] = {}}, ["param2"] = 22, ["y"] = 2, ["param1"] = 206, ["z"] = 3, ["name"] = "rainbow:slab_render_red_1"}, {["x"] = 5, ["meta"] = {["fields"] = {}, ["inventory"] = {}}, ["param2"] = 20, ["y"] = 2, ["param1"] = 190, ["z"] = 4, ["name"] = "rainbow:slab_render_red_1"}, {["x"] = 5, ["meta"] = {["fields"] = {}, ["inventory"] = {}}, ["param2"] = 20, ["y"] = 2, ["param1"] = 174, ["z"] = 5, ["name"] = "rainbow:slab_render_red_1"}, {["x"] = 5, ["meta"] = {["fields"] = {}, ["inventory"] = {}}, ["param2"] = 20, ["y"] = 2, ["param1"] = 158, ["z"] = 6, ["name"] = "rainbow:slab_render_red_1"}, {["x"] = 5, ["meta"] = {["fields"] = {}, ["inventory"] = {}}, ["param2"] = 20, ["y"] = 2, ["param1"] = 158, ["z"] = 7, ["name"] = "rainbow:slab_render_red_1"}, {["x"] = 5, ["meta"] = {["fields"] = {}, ["inventory"] = {}}, ["y"] = 2, ["z"] = 8, ["name"] = "rainbow:render_red"}, {["x"] = 5, ["meta"] = {["fields"] = {}, ["inventory"] = {}}, ["param2"] = 9, ["y"] = 3, ["param1"] = 175, ["z"] = 0, ["name"] = "rainbow:slab_coolglass_black_1"}, {["x"] = 5, ["meta"] = {["fields"] = {}, ["inventory"] = {}}, ["param2"] = 7, ["y"] = 3, ["param1"] = 175, ["z"] = 9, ["name"] = "rainbow:slab_coolglass_black_1"}, {["x"] = 5, ["meta"] = {["fields"] = {}, ["inventory"] = {}}, ["param2"] = 9, ["y"] = 4, ["param1"] = 191, ["z"] = 0, ["name"] = "rainbow:slab_coolglass_black_1"}, {["x"] = 5, ["meta"] = {["fields"] = {}, ["inventory"] = {}}, ["param2"] = 7, ["y"] = 4, ["param1"] = 191, ["z"] = 9, ["name"] = "rainbow:slab_coolglass_black_1"}, {["x"] = 5, ["meta"] = {["fields"] = {}, ["inventory"] = {}}, ["param2"] = 9, ["y"] = 5, ["param1"] = 175, ["z"] = 0, ["name"] = "rainbow:slab_coolglass_black_1"}, {["x"] = 5, ["meta"] = {["fields"] = {}, ["inventory"] = {}}, ["param2"] = 7, ["y"] = 5, ["param1"] = 175, ["z"] = 9, ["name"] = "rainbow:slab_coolglass_black_1"}, {["x"] = 5, ["meta"] = {["fields"] = {}, ["inventory"] = {}}, ["y"] = 6, ["z"] = 1, ["name"] = "rainbow:render_red"}, {["x"] = 5, ["meta"] = {["fields"] = {}, ["inventory"] = {}}, ["y"] = 6, ["param1"] = 159, ["z"] = 2, ["name"] = "rainbow:coolglass_red"}, {["x"] = 5, ["meta"] = {["fields"] = {}, ["inventory"] = {}}, ["y"] = 6, ["param1"] = 143, ["z"] = 3, ["name"] = "rainbow:coolglass_red"}, {["x"] = 5, ["meta"] = {["fields"] = {}, ["inventory"] = {}}, ["y"] = 6, ["param1"] = 127, ["z"] = 4, ["name"] = "rainbow:coolglass_red"}, {["x"] = 5, ["meta"] = {["fields"] = {}, ["inventory"] = {}}, ["y"] = 6, ["param1"] = 127, ["z"] = 5, ["name"] = "rainbow:coolglass_red"}, {["x"] = 5, ["meta"] = {["fields"] = {}, ["inventory"] = {}}, ["y"] = 6, ["param1"] = 143, ["z"] = 6, ["name"] = "rainbow:coolglass_red"}, {["x"] = 5, ["meta"] = {["fields"] = {}, ["inventory"] = {}}, ["y"] = 6, ["param1"] = 159, ["z"] = 7, ["name"] = "rainbow:coolglass_red"}, {["x"] = 5, ["meta"] = {["fields"] = {}, ["inventory"] = {}}, ["y"] = 6, ["z"] = 8, ["name"] = "rainbow:render_red"}, {["x"] = 5, ["meta"] = {["fields"] = {}, ["inventory"] = {}}, ["param2"] = 1, ["y"] = 7, ["param1"] = 126, ["z"] = 1, ["name"] = "rainbow:slope_render_red"}, {["x"] = 5, ["meta"] = {["fields"] = {}, ["inventory"] = {}}, ["param2"] = 1, ["y"] = 7, ["param1"] = 126, ["z"] = 8, ["name"] = "rainbow:slope_render_red"}, {["x"] = 6, ["meta"] = {["fields"] = {}, ["inventory"] = {}}, ["y"] = 0, ["z"] = 1, ["name"] = "rainbow:render_red"}, {["x"] = 6, ["meta"] = {["fields"] = {}, ["inventory"] = {}}, ["param2"] = 3, ["y"] = 0, ["param1"] = 174, ["z"] = 2, ["name"] = "rainbow:slope_render_white"}, {["x"] = 6, ["meta"] = {["fields"] = {}, ["inventory"] = {}}, ["param2"] = 1, ["y"] = 0, ["param1"] = 172, ["z"] = 7, ["name"] = "homedecor:trash_can_green"}, {["x"] = 6, ["meta"] = {["fields"] = {}, ["inventory"] = {}}, ["y"] = 0, ["z"] = 8, ["name"] = "rainbow:render_red"}, {["x"] = 6, ["meta"] = {["fields"] = {}, ["inventory"] = {}}, ["y"] = 1, ["param1"] = 174, ["z"] = 1, ["name"] = "rainbow:coolglass_red"}, {["x"] = 6, ["meta"] = {["fields"] = {}, ["inventory"] = {}}, ["y"] = 1, ["param1"] = 174, ["z"] = 8, ["name"] = "rainbow:coolglass_red"}, {["x"] = 6, ["meta"] = {["fields"] = {}, ["inventory"] = {}}, ["y"] = 2, ["z"] = 1, ["name"] = "rainbow:render_red"}, {["x"] = 6, ["meta"] = {["fields"] = {}, ["inventory"] = {}}, ["param2"] = 22, ["y"] = 2, ["param1"] = 190, ["z"] = 3, ["name"] = "rainbow:slab_render_red_1"}, {["x"] = 6, ["meta"] = {["fields"] = {}, ["inventory"] = {}}, ["param2"] = 21, ["y"] = 2, ["param1"] = 174, ["z"] = 4, ["name"] = "rainbow:slab_render_red_1"}, {["x"] = 6, ["meta"] = {["fields"] = {}, ["inventory"] = {}}, ["param2"] = 20, ["y"] = 2, ["param1"] = 158, ["z"] = 5, ["name"] = "rainbow:slab_render_red_1"}, {["x"] = 6, ["meta"] = {["fields"] = {}, ["inventory"] = {}}, ["param2"] = 23, ["y"] = 2, ["param1"] = 158, ["z"] = 6, ["name"] = "rainbow:slab_render_red_1"}, {["x"] = 6, ["meta"] = {["fields"] = {}, ["inventory"] = {}}, ["param2"] = 23, ["y"] = 2, ["param1"] = 174, ["z"] = 7, ["name"] = "rainbow:slab_render_red_1"}, {["x"] = 6, ["meta"] = {["fields"] = {}, ["inventory"] = {}}, ["y"] = 2, ["z"] = 8, ["name"] = "rainbow:render_red"}, {["x"] = 6, ["meta"] = {["fields"] = {}, ["inventory"] = {}}, ["param2"] = 9, ["y"] = 3, ["param1"] = 191, ["z"] = 0, ["name"] = "rainbow:slab_coolglass_black_1"}, {["x"] = 6, ["meta"] = {["fields"] = {}, ["inventory"] = {}}, ["param2"] = 7, ["y"] = 3, ["param1"] = 191, ["z"] = 9, ["name"] = "rainbow:slab_coolglass_black_1"}, {["x"] = 6, ["meta"] = {["fields"] = {}, ["inventory"] = {}}, ["param2"] = 9, ["y"] = 4, ["param1"] = 207, ["z"] = 0, ["name"] = "rainbow:slab_coolglass_black_1"}, {["x"] = 6, ["meta"] = {["fields"] = {}, ["inventory"] = {}}, ["param2"] = 2, ["y"] = 4, ["param1"] = 222, ["z"] = 1, ["name"] = "default:torch_wall"}, {["x"] = 6, ["meta"] = {["fields"] = {}, ["inventory"] = {}}, ["param2"] = 2, ["y"] = 4, ["param1"] = 222, ["z"] = 8, ["name"] = "default:torch_wall"}, {["x"] = 6, ["meta"] = {["fields"] = {}, ["inventory"] = {}}, ["param2"] = 7, ["y"] = 4, ["param1"] = 207, ["z"] = 9, ["name"] = "rainbow:slab_coolglass_black_1"}, {["x"] = 6, ["meta"] = {["fields"] = {}, ["inventory"] = {}}, ["param2"] = 9, ["y"] = 5, ["param1"] = 191, ["z"] = 0, ["name"] = "rainbow:slab_coolglass_black_1"}, {["x"] = 6, ["meta"] = {["fields"] = {}, ["inventory"] = {}}, ["param2"] = 7, ["y"] = 5, ["param1"] = 191, ["z"] = 9, ["name"] = "rainbow:slab_coolglass_black_1"}, {["x"] = 6, ["meta"] = {["fields"] = {}, ["inventory"] = {}}, ["y"] = 6, ["z"] = 1, ["name"] = "rainbow:render_red"}, {["x"] = 6, ["meta"] = {["fields"] = {}, ["inventory"] = {}}, ["y"] = 6, ["param1"] = 175, ["z"] = 2, ["name"] = "rainbow:coolglass_red"}, {["x"] = 6, ["meta"] = {["fields"] = {}, ["inventory"] = {}}, ["y"] = 6, ["param1"] = 159, ["z"] = 3, ["name"] = "rainbow:coolglass_red"}, {["x"] = 6, ["meta"] = {["fields"] = {}, ["inventory"] = {}}, ["y"] = 6, ["param1"] = 143, ["z"] = 4, ["name"] = "rainbow:coolglass_red"}, {["x"] = 6, ["meta"] = {["fields"] = {}, ["inventory"] = {}}, ["y"] = 6, ["param1"] = 143, ["z"] = 5, ["name"] = "rainbow:coolglass_red"}, {["x"] = 6, ["meta"] = {["fields"] = {}, ["inventory"] = {}}, ["y"] = 6, ["param1"] = 159, ["z"] = 6, ["name"] = "rainbow:coolglass_red"}, {["x"] = 6, ["meta"] = {["fields"] = {}, ["inventory"] = {}}, ["y"] = 6, ["param1"] = 175, ["z"] = 7, ["name"] = "rainbow:coolglass_red"}, {["x"] = 6, ["meta"] = {["fields"] = {}, ["inventory"] = {}}, ["y"] = 6, ["z"] = 8, ["name"] = "rainbow:render_red"}, {["x"] = 6, ["meta"] = {["fields"] = {}, ["inventory"] = {}}, ["param2"] = 3, ["y"] = 7, ["param1"] = 142, ["z"] = 1, ["name"] = "rainbow:slope_render_red"}, {["x"] = 6, ["meta"] = {["fields"] = {}, ["inventory"] = {}}, ["param2"] = 3, ["y"] = 7, ["param1"] = 142, ["z"] = 8, ["name"] = "rainbow:slope_render_red"}, {["x"] = 7, ["meta"] = {["fields"] = {}, ["inventory"] = {}}, ["param2"] = 21, ["y"] = 0, ["param1"] = 142, ["z"] = 1, ["name"] = "rainbow:slope_render_red_inner"}, {["x"] = 7, ["meta"] = {["fields"] = {}, ["inventory"] = {}}, ["y"] = 0, ["z"] = 2, ["name"] = "rainbow:render_red"}, {["x"] = 7, ["meta"] = {["fields"] = {}, ["inventory"] = {}}, ["y"] = 0, ["z"] = 3, ["name"] = "rainbow:render_red"}, {["x"] = 7, ["meta"] = {["fields"] = {}, ["inventory"] = {}}, ["y"] = 0, ["z"] = 4, ["name"] = "rainbow:render_red"}, {["x"] = 7, ["meta"] = {["fields"] = {}, ["inventory"] = {}}, ["y"] = 0, ["z"] = 5, ["name"] = "rainbow:render_red"}, {["x"] = 7, ["meta"] = {["fields"] = {["closed"] = "0"}, ["inventory"] = {}}, ["y"] = 0, ["param1"] = 205, ["z"] = 6, ["name"] = "homedecor:door_woodglass_right"}, {["x"] = 7, ["meta"] = {["fields"] = {}, ["inventory"] = {}}, ["y"] = 0, ["z"] = 7, ["name"] = "rainbow:render_red"}, {["x"] = 7, ["meta"] = {["fields"] = {}, ["inventory"] = {}}, ["param2"] = 22, ["y"] = 0, ["param1"] = 206, ["z"] = 8, ["name"] = "rainbow:slope_render_red_inner"}, {["x"] = 7, ["meta"] = {["fields"] = {}, ["inventory"] = {}}, ["y"] = 1, ["param1"] = 158, ["z"] = 1, ["name"] = "rainbow:slope_render_red_inner"}, {["x"] = 7, ["meta"] = {["fields"] = {}, ["inventory"] = {}}, ["y"] = 1, ["param1"] = 174, ["z"] = 2, ["name"] = "rainbow:coolglass_red"}, {["x"] = 7, ["meta"] = {["fields"] = {}, ["inventory"] = {}}, ["y"] = 1, ["param1"] = 158, ["z"] = 3, ["name"] = "rainbow:coolglass_red"}, {["x"] = 7, ["meta"] = {["fields"] = {}, ["inventory"] = {}}, ["y"] = 1, ["param1"] = 158, ["z"] = 4, ["name"] = "rainbow:coolglass_red"}, {["x"] = 7, ["meta"] = {["fields"] = {}, ["inventory"] = {}}, ["y"] = 1, ["param1"] = 173, ["z"] = 5, ["name"] = "rainbow:coolglass_red"}, {["x"] = 7, ["meta"] = {["fields"] = {}, ["inventory"] = {}}, ["y"] = 1, ["param1"] = 205, ["z"] = 7, ["name"] = "rainbow:coolglass_red"}, {["x"] = 7, ["meta"] = {["fields"] = {}, ["inventory"] = {}}, ["param2"] = 3, ["y"] = 1, ["param1"] = 190, ["z"] = 8, ["name"] = "rainbow:slope_render_red_inner"}, {["x"] = 7, ["meta"] = {["fields"] = {}, ["inventory"] = {}}, ["param2"] = 21, ["y"] = 2, ["param1"] = 174, ["z"] = 1, ["name"] = "rainbow:slope_render_red_inner"}, {["x"] = 7, ["meta"] = {["fields"] = {}, ["inventory"] = {}}, ["y"] = 2, ["z"] = 2, ["name"] = "rainbow:render_red"}, {["x"] = 7, ["meta"] = {["fields"] = {}, ["inventory"] = {}}, ["y"] = 2, ["z"] = 3, ["name"] = "rainbow:render_red"}, {["x"] = 7, ["meta"] = {["fields"] = {}, ["inventory"] = {}}, ["y"] = 2, ["z"] = 4, ["name"] = "rainbow:render_red"}, {["x"] = 7, ["meta"] = {["fields"] = {}, ["inventory"] = {}}, ["y"] = 2, ["z"] = 5, ["name"] = "rainbow:render_red"}, {["x"] = 7, ["meta"] = {["fields"] = {}, ["inventory"] = {}}, ["y"] = 2, ["z"] = 6, ["name"] = "rainbow:render_red"}, {["x"] = 7, ["meta"] = {["fields"] = {}, ["inventory"] = {}}, ["y"] = 2, ["z"] = 7, ["name"] = "rainbow:render_red"}, {["x"] = 7, ["meta"] = {["fields"] = {}, ["inventory"] = {}}, ["param2"] = 22, ["y"] = 2, ["param1"] = 174, ["z"] = 8, ["name"] = "rainbow:slope_render_red_inner"}, {["x"] = 7, ["meta"] = {["fields"] = {}, ["inventory"] = {}}, ["y"] = 3, ["param1"] = 190, ["z"] = 1, ["name"] = "rainbow:slope_render_red_inner"}, {["x"] = 7, ["meta"] = {["fields"] = {}, ["inventory"] = {}}, ["param2"] = 3, ["y"] = 3, ["param1"] = 190, ["z"] = 8, ["name"] = "rainbow:slope_render_red_inner"}, {["x"] = 7, ["meta"] = {["fields"] = {}, ["inventory"] = {}}, ["param2"] = 21, ["y"] = 4, ["param1"] = 206, ["z"] = 1, ["name"] = "rainbow:slope_render_red_inner"}, {["x"] = 7, ["meta"] = {["fields"] = {}, ["inventory"] = {}}, ["param2"] = 5, ["y"] = 4, ["param1"] = 222, ["z"] = 2, ["name"] = "default:torch_wall"}, {["x"] = 7, ["meta"] = {["fields"] = {}, ["inventory"] = {}}, ["param2"] = 4, ["y"] = 4, ["param1"] = 222, ["z"] = 7, ["name"] = "default:torch_wall"}, {["x"] = 7, ["meta"] = {["fields"] = {}, ["inventory"] = {}}, ["param2"] = 22, ["y"] = 4, ["param1"] = 206, ["z"] = 8, ["name"] = "rainbow:slope_render_red_inner"}, {["x"] = 7, ["meta"] = {["fields"] = {}, ["inventory"] = {}}, ["y"] = 5, ["param1"] = 190, ["z"] = 1, ["name"] = "rainbow:slope_render_red_inner"}, {["x"] = 7, ["meta"] = {["fields"] = {}, ["inventory"] = {}}, ["param2"] = 3, ["y"] = 5, ["param1"] = 190, ["z"] = 8, ["name"] = "rainbow:slope_render_red_inner"}, {["x"] = 7, ["meta"] = {["fields"] = {}, ["inventory"] = {}}, ["param2"] = 21, ["y"] = 6, ["param1"] = 174, ["z"] = 1, ["name"] = "rainbow:slope_render_red_inner"}, {["x"] = 7, ["meta"] = {["fields"] = {}, ["inventory"] = {}}, ["y"] = 6, ["z"] = 2, ["name"] = "rainbow:render_red"}, {["x"] = 7, ["meta"] = {["fields"] = {}, ["inventory"] = {}}, ["y"] = 6, ["z"] = 3, ["name"] = "rainbow:render_red"}, {["x"] = 7, ["meta"] = {["fields"] = {}, ["inventory"] = {}}, ["y"] = 6, ["z"] = 4, ["name"] = "rainbow:render_red"}, {["x"] = 7, ["meta"] = {["fields"] = {}, ["inventory"] = {}}, ["y"] = 6, ["z"] = 5, ["name"] = "rainbow:render_red"}, {["x"] = 7, ["meta"] = {["fields"] = {}, ["inventory"] = {}}, ["y"] = 6, ["z"] = 6, ["name"] = "rainbow:render_red"}, {["x"] = 7, ["meta"] = {["fields"] = {}, ["inventory"] = {}}, ["y"] = 6, ["z"] = 7, ["name"] = "rainbow:render_red"}, {["x"] = 7, ["meta"] = {["fields"] = {}, ["inventory"] = {}}, ["param2"] = 22, ["y"] = 6, ["param1"] = 174, ["z"] = 8, ["name"] = "rainbow:slope_render_red_inner"}, {["x"] = 7, ["meta"] = {["fields"] = {}, ["inventory"] = {}}, ["param2"] = 2, ["y"] = 7, ["param1"] = 158, ["z"] = 1, ["name"] = "rainbow:slope_render_red_outer"}, {["x"] = 7, ["meta"] = {["fields"] = {}, ["inventory"] = {}}, ["y"] = 7, ["param1"] = 142, ["z"] = 2, ["name"] = "rainbow:slope_render_red"}, {["x"] = 7, ["meta"] = {["fields"] = {}, ["inventory"] = {}}, ["param2"] = 2, ["y"] = 7, ["param1"] = 126, ["z"] = 3, ["name"] = "rainbow:slope_render_red"}, {["x"] = 7, ["meta"] = {["fields"] = {}, ["inventory"] = {}}, ["y"] = 7, ["param1"] = 110, ["z"] = 4, ["name"] = "rainbow:slope_render_red"}, {["x"] = 7, ["meta"] = {["fields"] = {}, ["inventory"] = {}}, ["param2"] = 2, ["y"] = 7, ["param1"] = 110, ["z"] = 5, ["name"] = "rainbow:slope_render_red"}, {["x"] = 7, ["meta"] = {["fields"] = {}, ["inventory"] = {}}, ["y"] = 7, ["param1"] = 126, ["z"] = 6, ["name"] = "rainbow:slope_render_red"}, {["x"] = 7, ["meta"] = {["fields"] = {}, ["inventory"] = {}}, ["param2"] = 2, ["y"] = 7, ["param1"] = 142, ["z"] = 7, ["name"] = "rainbow:slope_render_red"}, {["x"] = 7, ["meta"] = {["fields"] = {}, ["inventory"] = {}}, ["param2"] = 1, ["y"] = 7, ["param1"] = 158, ["z"] = 8, ["name"] = "rainbow:slope_render_red_outer"}, {["x"] = 8, ["meta"] = {["fields"] = {["infotext"] = "Cardboard box", ["formspec"] = "size[8,8]bgcolor[#080808BB;true]background[5,5;1,1;gui_formbg.png;true]listcolors[#00000069;#5A5A5A;#141318;#30434C;#FFF]list[context;main;0,0;8,3;]list[current_player;main;0,4;8,4;]listring[]"}, ["inventory"] = {["main"] = {"rainbow:wool_yellow", "rainbow:dirt_yellow 2", "beds:bed_bottom", "homedecor:shower_head 99", "my_hidden_doors:hidden_doorbookshelf 99", "boats:boat 99", "rainbow:dirt_black", "homedecor:barbecue 98", "default:mese_post_light 99", "default:book 48", "inbox:empty 99", "default:mese_post_light 99", "homedecor:trash_can_green", "homedecor:cardboard_box_big 99", "mobs:chicken_raw 2", "mobs:meat_raw", "homedecor:cardboard_box_big", "", "", "", "", "", "", ""}}}, ["param2"] = 2, ["y"] = 0, ["param1"] = 174, ["z"] = 3, ["name"] = "homedecor:cardboard_box_big"}, {["x"] = 8, ["meta"] = {["fields"] = {["infotext"] = "Cardboard box", ["formspec"] = "size[8,8]bgcolor[#080808BB;true]background[5,5;1,1;gui_formbg.png;true]listcolors[#00000069;#5A5A5A;#141318;#30434C;#FFF]list[context;main;0,0;8,3;]list[current_player;main;0,4;8,4;]listring[]"}, ["inventory"] = {["main"] = {"farming:bread 99", "crops:tomato 99", "default:apple 99", "crops:roasted_pumpkin 99", "crops:corn_cob 99", "crops:melon_slice 99", "crops:uncooked_vegetable_stew 99", "homedecor:beer_mug 99", "crops:potato 99", "crops:vegetable_stew 99", "", "", "", "", "", "", "", "", "", "", "", "", "", ""}}}, ["param2"] = 2, ["y"] = 0, ["param1"] = 190, ["z"] = 4, ["name"] = "homedecor:cardboard_box_big"}, {["x"] = 8, ["meta"] = {["fields"] = {}, ["inventory"] = {}}, ["param2"] = 3, ["y"] = 0, ["param1"] = 222, ["z"] = 6, ["name"] = "homedecor:welcome_mat_green"}, {["x"] = 8, ["meta"] = {["fields"] = {}, ["inventory"] = {}}, ["y"] = 0, ["param1"] = 238, ["z"] = 7, ["name"] = "default:mese_post_light"}, {["x"] = 8, ["meta"] = {["fields"] = {}, ["inventory"] = {}}, ["param2"] = 3, ["y"] = 1, ["param1"] = 190, ["z"] = 5, ["name"] = "homedecor:doorbell"}, {["x"] = 8, ["meta"] = {["fields"] = {["infotext"] = "Elektra's Mailbox", ["owner"] = "Elektra"}, ["inventory"] = {["main"] = {"", "", "", "", "", "", "", "", "", "", "", "", "", "", "", "", "", "", "", "", "", "", "", "", "", "", "", "", "", "", "", ""}, ["drop"] = {""}}}, ["param2"] = 3, ["y"] = 1, ["param1"] = 222, ["z"] = 7, ["name"] = "inbox:empty"}, {["x"] = 8, ["meta"] = {["fields"] = {}, ["inventory"] = {}}, ["param2"] = 12, ["y"] = 3, ["param1"] = 191, ["z"] = 2, ["name"] = "rainbow:slab_coolglass_black_1"}, {["x"] = 8, ["meta"] = {["fields"] = {}, ["inventory"] = {}}, ["param2"] = 12, ["y"] = 3, ["param1"] = 175, ["z"] = 3, ["name"] = "rainbow:slab_coolglass_black_1"}, {["x"] = 8, ["meta"] = {["fields"] = {}, ["inventory"] = {}}, ["param2"] = 12, ["y"] = 3, ["param1"] = 159, ["z"] = 4, ["name"] = "rainbow:slab_coolglass_black_1"}, {["x"] = 8, ["meta"] = {["fields"] = {}, ["inventory"] = {}}, ["param2"] = 12, ["y"] = 3, ["param1"] = 159, ["z"] = 5, ["name"] = "rainbow:slab_coolglass_black_1"}, {["x"] = 8, ["meta"] = {["fields"] = {}, ["inventory"] = {}}, ["param2"] = 12, ["y"] = 3, ["param1"] = 175, ["z"] = 6, ["name"] = "rainbow:slab_coolglass_black_1"}, {["x"] = 8, ["meta"] = {["fields"] = {}, ["inventory"] = {}}, ["param2"] = 12, ["y"] = 3, ["param1"] = 191, ["z"] = 7, ["name"] = "rainbow:slab_coolglass_black_1"}, {["x"] = 8, ["meta"] = {["fields"] = {}, ["inventory"] = {}}, ["param2"] = 12, ["y"] = 4, ["param1"] = 207, ["z"] = 2, ["name"] = "rainbow:slab_coolglass_black_1"}, {["x"] = 8, ["meta"] = {["fields"] = {}, ["inventory"] = {}}, ["param2"] = 12, ["y"] = 4, ["param1"] = 191, ["z"] = 3, ["name"] = "rainbow:slab_coolglass_black_1"}, {["x"] = 8, ["meta"] = {["fields"] = {}, ["inventory"] = {}}, ["param2"] = 12, ["y"] = 4, ["param1"] = 175, ["z"] = 4, ["name"] = "rainbow:slab_coolglass_black_1"}, {["x"] = 8, ["meta"] = {["fields"] = {}, ["inventory"] = {}}, ["param2"] = 12, ["y"] = 4, ["param1"] = 175, ["z"] = 5, ["name"] = "rainbow:slab_coolglass_black_1"}, {["x"] = 8, ["meta"] = {["fields"] = {}, ["inventory"] = {}}, ["param2"] = 12, ["y"] = 4, ["param1"] = 191, ["z"] = 6, ["name"] = "rainbow:slab_coolglass_black_1"}, {["x"] = 8, ["meta"] = {["fields"] = {}, ["inventory"] = {}}, ["param2"] = 12, ["y"] = 4, ["param1"] = 207, ["z"] = 7, ["name"] = "rainbow:slab_coolglass_black_1"}, {["x"] = 8, ["meta"] = {["fields"] = {}, ["inventory"] = {}}, ["param2"] = 12, ["y"] = 5, ["param1"] = 191, ["z"] = 2, ["name"] = "rainbow:slab_coolglass_black_1"}, {["x"] = 8, ["meta"] = {["fields"] = {}, ["inventory"] = {}}, ["param2"] = 12, ["y"] = 5, ["param1"] = 175, ["z"] = 3, ["name"] = "rainbow:slab_coolglass_black_1"}, {["x"] = 8, ["meta"] = {["fields"] = {}, ["inventory"] = {}}, ["param2"] = 12, ["y"] = 5, ["param1"] = 159, ["z"] = 4, ["name"] = "rainbow:slab_coolglass_black_1"}, {["x"] = 8, ["meta"] = {["fields"] = {}, ["inventory"] = {}}, ["param2"] = 12, ["y"] = 5, ["param1"] = 159, ["z"] = 5, ["name"] = "rainbow:slab_coolglass_black_1"}, {["x"] = 8, ["meta"] = {["fields"] = {}, ["inventory"] = {}}, ["param2"] = 12, ["y"] = 5, ["param1"] = 175, ["z"] = 6, ["name"] = "rainbow:slab_coolglass_black_1"}, {["x"] = 8, ["meta"] = {["fields"] = {}, ["inventory"] = {}}, ["param2"] = 12, ["y"] = 5, ["param1"] = 191, ["z"] = 7, ["name"] = "rainbow:slab_coolglass_black_1"}}