5:return {{["x"] = 1, ["meta"] = {["fields"] = {}, ["inventory"] = {}}, ["y"] = 4, ["z"] = 11, ["name"] = "wool:red"}, {["x"] = 1, ["meta"] = {["fields"] = {}, ["inventory"] = {}}, ["y"] = 4, ["z"] = 12, ["name"] = "wool:red"}, {["x"] = 2, ["meta"] = {["fields"] = {}, ["inventory"] = {}}, ["y"] = 4, ["z"] = 11, ["name"] = "wool:red"}, {["x"] = 2, ["meta"] = {["fields"] = {}, ["inventory"] = {}}, ["y"] = 4, ["z"] = 12, ["name"] = "wool:red"}, {["x"] = 2, ["meta"] = {["fields"] = {}, ["inventory"] = {}}, ["y"] = 4, ["z"] = 13, ["name"] = "wool:red"}, {["x"] = 3, ["meta"] = {["fields"] = {}, ["inventory"] = {}}, ["y"] = 4, ["z"] = 11, ["name"] = "wool:red"}, {["x"] = 3, ["meta"] = {["fields"] = {}, ["inventory"] = {}}, ["y"] = 4, ["z"] = 12, ["name"] = "wool:red"}, {["x"] = 3, ["meta"] = {["fields"] = {}, ["inventory"] = {}}, ["y"] = 4, ["z"] = 13, ["name"] = "wool:red"}, {["x"] = 4, ["meta"] = {["fields"] = {}, ["inventory"] = {}}, ["y"] = 4, ["z"] = 11, ["name"] = "wool:red"}, {["x"] = 4, ["meta"] = {["fields"] = {}, ["inventory"] = {}}, ["y"] = 4, ["z"] = 12, ["name"] = "wool:red"}, {["x"] = 4, ["meta"] = {["fields"] = {}, ["inventory"] = {}}, ["y"] = 4, ["z"] = 13, ["name"] = "wool:red"}, {["x"] = 5, ["meta"] = {["fields"] = {}, ["inventory"] = {}}, ["y"] = 3, ["z"] = 10, ["name"] = "wool:red"}, {["x"] = 5, ["meta"] = {["fields"] = {}, ["inventory"] = {}}, ["y"] = 3, ["z"] = 11, ["name"] = "wool:red"}, {["x"] = 5, ["meta"] = {["fields"] = {}, ["inventory"] = {}}, ["y"] = 4, ["z"] = 12, ["name"] = "wool:red"}, {["x"] = 5, ["meta"] = {["fields"] = {}, ["inventory"] = {}}, ["y"] = 4, ["z"] = 13, ["name"] = "wool:red"}, {["x"] = 6, ["meta"] = {["fields"] = {}, ["inventory"] = {}}, ["y"] = 3, ["z"] = 10, ["name"] = "wool:cyan"}, {["x"] = 6, ["meta"] = {["fields"] = {}, ["inventory"] = {}}, ["y"] = 3, ["z"] = 11, ["name"] = "wool:red"}, {["x"] = 6, ["meta"] = {["fields"] = {}, ["inventory"] = {}}, ["y"] = 4, ["z"] = 4, ["name"] = "wool:cyan"}, {["x"] = 6, ["meta"] = {["fields"] = {}, ["inventory"] = {}}, ["y"] = 4, ["z"] = 7, ["name"] = "wool:red"}, {["x"] = 6, ["meta"] = {["fields"] = {}, ["inventory"] = {}}, ["y"] = 4, ["z"] = 8, ["name"] = "wool:red"}, {["x"] = 6, ["meta"] = {["fields"] = {}, ["inventory"] = {}}, ["y"] = 4, ["z"] = 9, ["name"] = "wool:red"}, {["x"] = 6, ["meta"] = {["fields"] = {}, ["inventory"] = {}}, ["y"] = 4, ["z"] = 10, ["name"] = "wool:red"}, {["x"] = 6, ["meta"] = {["fields"] = {}, ["inventory"] = {}}, ["y"] = 4, ["z"] = 11, ["name"] = "wool:red"}, {["x"] = 6, ["meta"] = {["fields"] = {}, ["inventory"] = {}}, ["y"] = 4, ["z"] = 12, ["name"] = "wool:red"}, {["x"] = 6, ["meta"] = {["fields"] = {}, ["inventory"] = {}}, ["y"] = 4, ["z"] = 13, ["name"] = "wool:red"}, {["x"] = 6, ["meta"] = {["fields"] = {}, ["inventory"] = {}}, ["y"] = 4, ["z"] = 14, ["name"] = "wool:red"}, {["x"] = 6, ["meta"] = {["fields"] = {}, ["inventory"] = {}}, ["y"] = 4, ["z"] = 15, ["name"] = "wool:red"}, {["x"] = 6, ["meta"] = {["fields"] = {}, ["inventory"] = {}}, ["y"] = 5, ["z"] = 7, ["name"] = "wool:white"}, {["x"] = 6, ["meta"] = {["fields"] = {}, ["inventory"] = {}}, ["y"] = 5, ["z"] = 8, ["name"] = "wool:white"}, {["x"] = 6, ["meta"] = {["fields"] = {}, ["inventory"] = {}}, ["y"] = 5, ["z"] = 9, ["name"] = "wool:white"}, {["x"] = 6, ["meta"] = {["fields"] = {}, ["inventory"] = {}}, ["y"] = 5, ["param1"] = 109, ["z"] = 10, ["name"] = "xpanes:pane_10"}, {["x"] = 6, ["meta"] = {["fields"] = {}, ["inventory"] = {}}, ["y"] = 5, ["z"] = 11, ["name"] = "wool:white"}, {["x"] = 6, ["meta"] = {["fields"] = {}, ["inventory"] = {}}, ["y"] = 5, ["param1"] = 109, ["z"] = 12, ["name"] = "xpanes:pane_10"}, {["x"] = 6, ["meta"] = {["fields"] = {}, ["inventory"] = {}}, ["y"] = 5, ["z"] = 13, ["name"] = "wool:white"}, {["x"] = 6, ["meta"] = {["fields"] = {}, ["inventory"] = {}}, ["y"] = 5, ["param1"] = 109, ["z"] = 14, ["name"] = "xpanes:pane_10"}, {["x"] = 6, ["meta"] = {["fields"] = {}, ["inventory"] = {}}, ["y"] = 5, ["z"] = 15, ["name"] = "wool:white"}, {["x"] = 6, ["meta"] = {["fields"] = {}, ["inventory"] = {}}, ["y"] = 5, ["z"] = 16, ["name"] = "wool:red"}, {["x"] = 6, ["meta"] = {["fields"] = {}, ["inventory"] = {}}, ["y"] = 5, ["z"] = 17, ["name"] = "wool:white"}, {["x"] = 6, ["meta"] = {["fields"] = {}, ["inventory"] = {}}, ["y"] = 6, ["z"] = 7, ["name"] = "wool:red"}, {["x"] = 6, ["meta"] = {["fields"] = {}, ["inventory"] = {}}, ["y"] = 6, ["z"] = 8, ["name"] = "wool:red"}, {["x"] = 6, ["meta"] = {["fields"] = {}, ["inventory"] = {}}, ["y"] = 6, ["z"] = 9, ["name"] = "wool:red"}, {["x"] = 6, ["meta"] = {["fields"] = {}, ["inventory"] = {}}, ["y"] = 6, ["z"] = 10, ["name"] = "wool:red"}, {["x"] = 6, ["meta"] = {["fields"] = {}, ["inventory"] = {}}, ["y"] = 6, ["z"] = 11, ["name"] = "wool:red"}, {["x"] = 6, ["meta"] = {["fields"] = {}, ["inventory"] = {}}, ["y"] = 6, ["z"] = 12, ["name"] = "wool:red"}, {["x"] = 6, ["meta"] = {["fields"] = {}, ["inventory"] = {}}, ["y"] = 6, ["z"] = 13, ["name"] = "wool:red"}, {["x"] = 6, ["meta"] = {["fields"] = {}, ["inventory"] = {}}, ["y"] = 6, ["z"] = 14, ["name"] = "wool:red"}, {["x"] = 6, ["meta"] = {["fields"] = {}, ["inventory"] = {}}, ["y"] = 6, ["z"] = 15, ["name"] = "wool:red"}, {["x"] = 6, ["meta"] = {["fields"] = {}, ["inventory"] = {}}, ["y"] = 6, ["z"] = 16, ["name"] = "wool:red"}, {["x"] = 7, ["meta"] = {["fields"] = {}, ["inventory"] = {}}, ["y"] = 3, ["z"] = 4, ["name"] = "wool:white"}, {["x"] = 7, ["meta"] = {["fields"] = {}, ["inventory"] = {}}, ["y"] = 3, ["z"] = 8, ["name"] = "wool:white"}, {["x"] = 7, ["meta"] = {["fields"] = {}, ["inventory"] = {}}, ["y"] = 3, ["z"] = 9, ["name"] = "wool:white"}, {["x"] = 7, ["meta"] = {["fields"] = {}, ["inventory"] = {}}, ["y"] = 3, ["z"] = 10, ["name"] = "wool:white"}, {["x"] = 7, ["meta"] = {["fields"] = {}, ["inventory"] = {}}, ["y"] = 3, ["z"] = 11, ["name"] = "wool:white"}, {["x"] = 7, ["meta"] = {["fields"] = {}, ["inventory"] = {}}, ["y"] = 3, ["z"] = 12, ["name"] = "wool:white"}, {["x"] = 7, ["meta"] = {["fields"] = {}, ["inventory"] = {}}, ["y"] = 3, ["z"] = 13, ["name"] = "wool:white"}, {["x"] = 7, ["meta"] = {["fields"] = {}, ["inventory"] = {}}, ["y"] = 3, ["z"] = 14, ["name"] = "wool:white"}, {["x"] = 7, ["meta"] = {["fields"] = {}, ["inventory"] = {}}, ["y"] = 3, ["z"] = 15, ["name"] = "wool:white"}, {["x"] = 7, ["meta"] = {["fields"] = {}, ["inventory"] = {}}, ["y"] = 4, ["z"] = 4, ["name"] = "wool:cyan"}, {["x"] = 7, ["meta"] = {["fields"] = {}, ["inventory"] = {}}, ["y"] = 4, ["z"] = 5, ["name"] = "wool:red"}, {["x"] = 7, ["meta"] = {["fields"] = {}, ["inventory"] = {}}, ["y"] = 4, ["z"] = 6, ["name"] = "wool:red"}, {["x"] = 7, ["meta"] = {["fields"] = {}, ["inventory"] = {}}, ["y"] = 4, ["z"] = 7, ["name"] = "wool:red"}, {["x"] = 7, ["meta"] = {["fields"] = {}, ["inventory"] = {}}, ["param2"] = 2, ["y"] = 4, ["param1"] = 137, ["z"] = 8, ["name"] = "lrfurn:armchair_white"}, {["x"] = 7, ["meta"] = {["fields"] = {}, ["inventory"] = {}}, ["param2"] = 1, ["y"] = 4, ["param1"] = 10, ["z"] = 9, ["name"] = "mesecons_torch:mesecon_torch_on"}, {["x"] = 7, ["meta"] = {["fields"] = {}, ["inventory"] = {}}, ["param2"] = 2, ["y"] = 4, ["param1"] = 139, ["z"] = 10, ["name"] = "lrfurn:armchair_white"}, {["x"] = 7, ["meta"] = {["fields"] = {}, ["inventory"] = {}}, ["param2"] = 1, ["y"] = 4, ["param1"] = 10, ["z"] = 11, ["name"] = "mesecons_torch:mesecon_torch_on"}, {["x"] = 7, ["meta"] = {["fields"] = {}, ["inventory"] = {}}, ["param2"] = 2, ["y"] = 4, ["param1"] = 139, ["z"] = 12, ["name"] = "lrfurn:armchair_white"}, {["x"] = 7, ["meta"] = {["fields"] = {}, ["inventory"] = {}}, ["param2"] = 1, ["y"] = 4, ["param1"] = 10, ["z"] = 13, ["name"] = "mesecons_torch:mesecon_torch_on"}, {["x"] = 7, ["meta"] = {["fields"] = {}, ["inventory"] = {}}, ["param2"] = 2, ["y"] = 4, ["param1"] = 139, ["z"] = 14, ["name"] = "lrfurn:armchair_white"}, {["x"] = 7, ["meta"] = {["fields"] = {}, ["inventory"] = {}}, ["param2"] = 1, ["y"] = 4, ["param1"] = 10, ["z"] = 15, ["name"] = "mesecons_torch:mesecon_torch_on"}, {["x"] = 7, ["meta"] = {["fields"] = {}, ["inventory"] = {}}, ["y"] = 4, ["z"] = 16, ["name"] = "wool:red"}, {["x"] = 7, ["meta"] = {["fields"] = {}, ["inventory"] = {}}, ["y"] = 4, ["z"] = 17, ["name"] = "wool:red"}, {["x"] = 7, ["meta"] = {["fields"] = {}, ["inventory"] = {}}, ["y"] = 4, ["z"] = 18, ["name"] = "wool:white"}, {["x"] = 7, ["meta"] = {["fields"] = {}, ["inventory"] = {}}, ["y"] = 5, ["z"] = 5, ["name"] = "wool:red"}, {["x"] = 7, ["meta"] = {["fields"] = {}, ["inventory"] = {}}, ["y"] = 5, ["z"] = 6, ["name"] = "wool:white"}, {["x"] = 7, ["meta"] = {["fields"] = {}, ["inventory"] = {}}, ["y"] = 5, ["z"] = 7, ["name"] = "wool:white"}, {["x"] = 7, ["meta"] = {["fields"] = {}, ["inventory"] = {}}, ["y"] = 5, ["z"] = 16, ["name"] = "wool:red"}, {["x"] = 7, ["meta"] = {["fields"] = {}, ["inventory"] = {}}, ["param2"] = 3, ["y"] = 5, ["param1"] = 75, ["z"] = 17, ["name"] = "homedecor:analog_clock_plastic"}, {["x"] = 7, ["meta"] = {["fields"] = {}, ["inventory"] = {}}, ["y"] = 5, ["z"] = 18, ["name"] = "wool:cyan"}, {["x"] = 7, ["meta"] = {["fields"] = {}, ["inventory"] = {}}, ["y"] = 6, ["z"] = 6, ["name"] = "wool:red"}, {["x"] = 7, ["meta"] = {["fields"] = {}, ["inventory"] = {}}, ["y"] = 6, ["z"] = 17, ["name"] = "wool:red"}, {["x"] = 7, ["meta"] = {["fields"] = {}, ["inventory"] = {}}, ["y"] = 7, ["z"] = 7, ["name"] = "wool:cyan"}, {["x"] = 7, ["meta"] = {["fields"] = {}, ["inventory"] = {}}, ["y"] = 7, ["z"] = 8, ["name"] = "wool:cyan"}, {["x"] = 7, ["meta"] = {["fields"] = {}, ["inventory"] = {}}, ["y"] = 7, ["z"] = 9, ["name"] = "wool:cyan"}, {["x"] = 7, ["meta"] = {["fields"] = {}, ["inventory"] = {}}, ["y"] = 7, ["z"] = 10, ["name"] = "wool:cyan"}, {["x"] = 7, ["meta"] = {["fields"] = {}, ["inventory"] = {}}, ["y"] = 7, ["z"] = 11, ["name"] = "wool:cyan"}, {["x"] = 7, ["meta"] = {["fields"] = {}, ["inventory"] = {}}, ["y"] = 7, ["z"] = 12, ["name"] = "wool:cyan"}, {["x"] = 7, ["meta"] = {["fields"] = {}, ["inventory"] = {}}, ["y"] = 7, ["z"] = 13, ["name"] = "wool:cyan"}, {["x"] = 7, ["meta"] = {["fields"] = {}, ["inventory"] = {}}, ["y"] = 7, ["z"] = 14, ["name"] = "wool:cyan"}, {["x"] = 7, ["meta"] = {["fields"] = {}, ["inventory"] = {}}, ["y"] = 7, ["z"] = 15, ["name"] = "wool:cyan"}, {["x"] = 7, ["meta"] = {["fields"] = {}, ["inventory"] = {}}, ["y"] = 7, ["z"] = 16, ["name"] = "wool:cyan"}, {["x"] = 8, ["meta"] = {["fields"] = {}, ["inventory"] = {}}, ["y"] = 3, ["z"] = 3, ["name"] = "wool:white"}, {["x"] = 8, ["meta"] = {["fields"] = {}, ["inventory"] = {}}, ["y"] = 3, ["z"] = 4, ["name"] = "wool:white"}, {["x"] = 8, ["meta"] = {["fields"] = {}, ["inventory"] = {}}, ["y"] = 3, ["z"] = 5, ["name"] = "wool:white"}, {["x"] = 8, ["meta"] = {["fields"] = {}, ["inventory"] = {}}, ["y"] = 3, ["z"] = 6, ["name"] = "wool:white"}, {["x"] = 8, ["meta"] = {["fields"] = {}, ["inventory"] = {}}, ["y"] = 3, ["z"] = 7, ["name"] = "wool:white"}, {["x"] = 8, ["meta"] = {["fields"] = {}, ["inventory"] = {}}, ["y"] = 3, ["z"] = 8, ["name"] = "wool:white"}, {["x"] = 8, ["meta"] = {["fields"] = {}, ["inventory"] = {}}, ["y"] = 3, ["z"] = 9, ["name"] = "wool:white"}, {["x"] = 8, ["meta"] = {["fields"] = {}, ["inventory"] = {}}, ["y"] = 3, ["z"] = 10, ["name"] = "wool:white"}, {["x"] = 8, ["meta"] = {["fields"] = {}, ["inventory"] = {}}, ["y"] = 3, ["z"] = 11, ["name"] = "wool:white"}, {["x"] = 8, ["meta"] = {["fields"] = {}, ["inventory"] = {}}, ["y"] = 3, ["z"] = 12, ["name"] = "wool:white"}, {["x"] = 8, ["meta"] = {["fields"] = {}, ["inventory"] = {}}, ["y"] = 3, ["z"] = 13, ["name"] = "wool:white"}, {["x"] = 8, ["meta"] = {["fields"] = {}, ["inventory"] = {}}, ["y"] = 3, ["z"] = 14, ["name"] = "wool:white"}, {["x"] = 8, ["meta"] = {["fields"] = {}, ["inventory"] = {}}, ["y"] = 3, ["z"] = 15, ["name"] = "wool:white"}, {["x"] = 8, ["meta"] = {["fields"] = {}, ["inventory"] = {}}, ["y"] = 3, ["z"] = 16, ["name"] = "wool:white"}, {["x"] = 8, ["meta"] = {["fields"] = {}, ["inventory"] = {}}, ["y"] = 3, ["z"] = 17, ["name"] = "wool:white"}, {["x"] = 8, ["meta"] = {["fields"] = {}, ["inventory"] = {}}, ["y"] = 3, ["z"] = 18, ["name"] = "wool:red"}, {["x"] = 8, ["meta"] = {["fields"] = {}, ["inventory"] = {}}, ["param2"] = 5, ["y"] = 3, ["param1"] = 15, ["z"] = 19, ["name"] = "windmill:windmill_farm"}, {["x"] = 8, ["meta"] = {["fields"] = {}, ["inventory"] = {}}, ["y"] = 4, ["z"] = 1, ["name"] = "wool:cyan"}, {["x"] = 8, ["meta"] = {["fields"] = {}, ["inventory"] = {}}, ["y"] = 4, ["z"] = 2, ["name"] = "wool:cyan"}, {["x"] = 8, ["meta"] = {["fields"] = {}, ["inventory"] = {}}, ["y"] = 4, ["z"] = 3, ["name"] = "wool:cyan"}, {["x"] = 8, ["meta"] = {["fields"] = {}, ["inventory"] = {}}, ["y"] = 4, ["z"] = 4, ["name"] = "wool:white"}, {["x"] = 8, ["meta"] = {["fields"] = {}, ["inventory"] = {}}, ["param2"] = 1, ["y"] = 4, ["param1"] = 122, ["z"] = 16, ["name"] = "doors:door_wood_b_2"}, {["x"] = 8, ["meta"] = {["fields"] = {}, ["inventory"] = {}}, ["y"] = 4, ["z"] = 18, ["name"] = "wool:red"}, {["x"] = 8, ["meta"] = {["fields"] = {}, ["inventory"] = {}}, ["y"] = 5, ["z"] = 4, ["name"] = "wool:cyan"}, {["x"] = 8, ["meta"] = {["fields"] = {}, ["inventory"] = {}}, ["y"] = 5, ["z"] = 5, ["name"] = "wool:red"}, {["x"] = 8, ["meta"] = {["fields"] = {}, ["inventory"] = {}}, ["param2"] = 1, ["y"] = 5, ["param1"] = 107, ["z"] = 16, ["name"] = "doors:door_wood_t_2"}, {["x"] = 8, ["meta"] = {["fields"] = {}, ["inventory"] = {}}, ["y"] = 5, ["param1"] = 77, ["z"] = 18, ["name"] = "xpanes:pane_5"}, {["x"] = 8, ["meta"] = {["fields"] = {}, ["inventory"] = {}}, ["y"] = 6, ["z"] = 5, ["name"] = "wool:cyan"}, {["x"] = 8, ["meta"] = {["fields"] = {}, ["inventory"] = {}}, ["y"] = 6, ["z"] = 16, ["name"] = "wool:red"}, {["x"] = 8, ["meta"] = {["fields"] = {}, ["inventory"] = {}}, ["y"] = 6, ["z"] = 17, ["name"] = "wool:red"}, {["x"] = 8, ["meta"] = {["fields"] = {}, ["inventory"] = {}}, ["y"] = 6, ["z"] = 18, ["name"] = "wool:cyan"}, {["x"] = 8, ["meta"] = {["fields"] = {}, ["inventory"] = {}}, ["y"] = 7, ["z"] = 6, ["name"] = "wool:cyan"}, {["x"] = 8, ["meta"] = {["fields"] = {}, ["inventory"] = {}}, ["y"] = 7, ["z"] = 7, ["name"] = "wool:cyan"}, {["x"] = 8, ["meta"] = {["fields"] = {}, ["inventory"] = {}}, ["y"] = 7, ["z"] = 8, ["name"] = "wool:cyan"}, {["x"] = 8, ["meta"] = {["fields"] = {}, ["inventory"] = {}}, ["y"] = 7, ["z"] = 9, ["name"] = "wool:cyan"}, {["x"] = 8, ["meta"] = {["fields"] = {}, ["inventory"] = {}}, ["y"] = 7, ["z"] = 10, ["name"] = "wool:cyan"}, {["x"] = 8, ["meta"] = {["fields"] = {}, ["inventory"] = {}}, ["y"] = 7, ["z"] = 11, ["name"] = "wool:cyan"}, {["x"] = 8, ["meta"] = {["fields"] = {}, ["inventory"] = {}}, ["y"] = 7, ["z"] = 12, ["name"] = "wool:cyan"}, {["x"] = 8, ["meta"] = {["fields"] = {}, ["inventory"] = {}}, ["y"] = 7, ["z"] = 13, ["name"] = "wool:cyan"}, {["x"] = 8, ["meta"] = {["fields"] = {}, ["inventory"] = {}}, ["y"] = 7, ["z"] = 14, ["name"] = "wool:cyan"}, {["x"] = 8, ["meta"] = {["fields"] = {}, ["inventory"] = {}}, ["y"] = 7, ["z"] = 15, ["name"] = "wool:cyan"}, {["x"] = 8, ["meta"] = {["fields"] = {}, ["inventory"] = {}}, ["y"] = 7, ["z"] = 16, ["name"] = "wool:cyan"}, {["x"] = 9, ["meta"] = {["fields"] = {}, ["inventory"] = {}}, ["y"] = 3, ["z"] = 4, ["name"] = "wool:white"}, {["x"] = 9, ["meta"] = {["fields"] = {}, ["inventory"] = {}}, ["y"] = 3, ["z"] = 8, ["name"] = "wool:white"}, {["x"] = 9, ["meta"] = {["fields"] = {}, ["inventory"] = {}}, ["y"] = 3, ["z"] = 9, ["name"] = "wool:white"}, {["x"] = 9, ["meta"] = {["fields"] = {}, ["inventory"] = {}}, ["y"] = 3, ["z"] = 10, ["name"] = "wool:white"}, {["x"] = 9, ["meta"] = {["fields"] = {}, ["inventory"] = {}}, ["y"] = 3, ["z"] = 11, ["name"] = "wool:white"}, {["x"] = 9, ["meta"] = {["fields"] = {}, ["inventory"] = {}}, ["y"] = 3, ["z"] = 12, ["name"] = "wool:white"}, {["x"] = 9, ["meta"] = {["fields"] = {}, ["inventory"] = {}}, ["y"] = 3, ["z"] = 13, ["name"] = "wool:white"}, {["x"] = 9, ["meta"] = {["fields"] = {}, ["inventory"] = {}}, ["y"] = 3, ["z"] = 14, ["name"] = "wool:white"}, {["x"] = 9, ["meta"] = {["fields"] = {}, ["inventory"] = {}}, ["y"] = 3, ["z"] = 15, ["name"] = "wool:white"}, {["x"] = 9, ["meta"] = {["fields"] = {}, ["inventory"] = {}}, ["y"] = 4, ["z"] = 4, ["name"] = "wool:cyan"}, {["x"] = 9, ["meta"] = {["fields"] = {}, ["inventory"] = {}}, ["y"] = 4, ["z"] = 5, ["name"] = "wool:red"}, {["x"] = 9, ["meta"] = {["fields"] = {}, ["inventory"] = {}}, ["y"] = 4, ["z"] = 6, ["name"] = "wool:red"}, {["x"] = 9, ["meta"] = {["fields"] = {}, ["inventory"] = {}}, ["y"] = 4, ["z"] = 7, ["name"] = "wool:red"}, {["x"] = 9, ["meta"] = {["fields"] = {}, ["inventory"] = {}}, ["param2"] = 2, ["y"] = 4, ["param1"] = 138, ["z"] = 8, ["name"] = "lrfurn:armchair_white"}, {["x"] = 9, ["meta"] = {["fields"] = {}, ["inventory"] = {}}, ["param2"] = 1, ["y"] = 4, ["param1"] = 11, ["z"] = 9, ["name"] = "mesecons_torch:mesecon_torch_on"}, {["x"] = 9, ["meta"] = {["fields"] = {}, ["inventory"] = {}}, ["param2"] = 2, ["y"] = 4, ["param1"] = 139, ["z"] = 12, ["name"] = "lrfurn:armchair_white"}, {["x"] = 9, ["meta"] = {["fields"] = {}, ["inventory"] = {}}, ["param2"] = 1, ["y"] = 4, ["param1"] = 10, ["z"] = 13, ["name"] = "mesecons_torch:mesecon_torch_on"}, {["x"] = 9, ["meta"] = {["fields"] = {}, ["inventory"] = {}}, ["param2"] = 2, ["y"] = 4, ["param1"] = 139, ["z"] = 14, ["name"] = "lrfurn:armchair_white"}, {["x"] = 9, ["meta"] = {["fields"] = {}, ["inventory"] = {}}, ["param2"] = 1, ["y"] = 4, ["param1"] = 10, ["z"] = 15, ["name"] = "mesecons_torch:mesecon_torch_on"}, {["x"] = 9, ["meta"] = {["fields"] = {}, ["inventory"] = {}}, ["y"] = 4, ["z"] = 16, ["name"] = "wool:red"}, {["x"] = 9, ["meta"] = {["fields"] = {}, ["inventory"] = {}}, ["y"] = 4, ["z"] = 17, ["name"] = "wool:red"}, {["x"] = 9, ["meta"] = {["fields"] = {}, ["inventory"] = {}}, ["y"] = 4, ["z"] = 18, ["name"] = "wool:white"}, {["x"] = 9, ["meta"] = {["fields"] = {}, ["inventory"] = {}}, ["y"] = 5, ["z"] = 5, ["name"] = "wool:red"}, {["x"] = 9, ["meta"] = {["fields"] = {}, ["inventory"] = {}}, ["y"] = 5, ["z"] = 6, ["name"] = "wool:white"}, {["x"] = 9, ["meta"] = {["fields"] = {}, ["inventory"] = {}}, ["y"] = 5, ["z"] = 7, ["name"] = "wool:white"}, {["x"] = 9, ["meta"] = {["fields"] = {}, ["inventory"] = {}}, ["y"] = 5, ["z"] = 16, ["name"] = "wool:red"}, {["x"] = 9, ["meta"] = {["fields"] = {}, ["inventory"] = {}}, ["param2"] = 1, ["y"] = 5, ["param1"] = 75, ["z"] = 17, ["name"] = "homedecor:analog_clock_plastic"}, {["x"] = 9, ["meta"] = {["fields"] = {}, ["inventory"] = {}}, ["y"] = 5, ["z"] = 18, ["name"] = "wool:cyan"}, {["x"] = 9, ["meta"] = {["fields"] = {}, ["inventory"] = {}}, ["y"] = 6, ["z"] = 6, ["name"] = "wool:red"}, {["x"] = 9, ["meta"] = {["fields"] = {}, ["inventory"] = {}}, ["y"] = 6, ["z"] = 7, ["name"] = "wool:red"}, {["x"] = 9, ["meta"] = {["fields"] = {}, ["inventory"] = {}}, ["y"] = 6, ["z"] = 17, ["name"] = "wool:red"}, {["x"] = 9, ["meta"] = {["fields"] = {}, ["inventory"] = {}}, ["y"] = 7, ["z"] = 8, ["name"] = "wool:cyan"}, {["x"] = 9, ["meta"] = {["fields"] = {}, ["inventory"] = {}}, ["y"] = 7, ["z"] = 9, ["name"] = "wool:cyan"}, {["x"] = 9, ["meta"] = {["fields"] = {}, ["inventory"] = {}}, ["y"] = 7, ["z"] = 10, ["name"] = "wool:cyan"}, {["x"] = 9, ["meta"] = {["fields"] = {}, ["inventory"] = {}}, ["y"] = 7, ["z"] = 11, ["name"] = "wool:cyan"}, {["x"] = 9, ["meta"] = {["fields"] = {}, ["inventory"] = {}}, ["y"] = 7, ["z"] = 12, ["name"] = "wool:cyan"}, {["x"] = 9, ["meta"] = {["fields"] = {}, ["inventory"] = {}}, ["y"] = 7, ["z"] = 13, ["name"] = "wool:cyan"}, {["x"] = 9, ["meta"] = {["fields"] = {}, ["inventory"] = {}}, ["y"] = 7, ["z"] = 14, ["name"] = "wool:cyan"}, {["x"] = 9, ["meta"] = {["fields"] = {}, ["inventory"] = {}}, ["y"] = 7, ["z"] = 15, ["name"] = "wool:cyan"}, {["x"] = 9, ["meta"] = {["fields"] = {}, ["inventory"] = {}}, ["y"] = 7, ["z"] = 16, ["name"] = "wool:cyan"}, {["x"] = 10, ["meta"] = {["fields"] = {}, ["inventory"] = {}}, ["y"] = 3, ["z"] = 10, ["name"] = "wool:cyan"}, {["x"] = 10, ["meta"] = {["fields"] = {}, ["inventory"] = {}}, ["y"] = 3, ["z"] = 11, ["name"] = "wool:red"}, {["x"] = 10, ["meta"] = {["fields"] = {}, ["inventory"] = {}}, ["y"] = 4, ["z"] = 4, ["name"] = "wool:cyan"}, {["x"] = 10, ["meta"] = {["fields"] = {}, ["inventory"] = {}}, ["y"] = 4, ["z"] = 7, ["name"] = "wool:red"}, {["x"] = 10, ["meta"] = {["fields"] = {}, ["inventory"] = {}}, ["y"] = 4, ["z"] = 8, ["name"] = "wool:red"}, {["x"] = 10, ["meta"] = {["fields"] = {}, ["inventory"] = {}}, ["y"] = 4, ["z"] = 9, ["name"] = "wool:red"}, {["x"] = 10, ["meta"] = {["fields"] = {}, ["inventory"] = {}}, ["y"] = 4, ["param1"] = 125, ["z"] = 10, ["name"] = "doors:door_wood_b_2"}, {["x"] = 10, ["meta"] = {["fields"] = {}, ["inventory"] = {}}, ["y"] = 4, ["z"] = 11, ["name"] = "wool:red"}, {["x"] = 10, ["meta"] = {["fields"] = {}, ["inventory"] = {}}, ["y"] = 4, ["z"] = 12, ["name"] = "wool:red"}, {["x"] = 10, ["meta"] = {["fields"] = {}, ["inventory"] = {}}, ["y"] = 4, ["z"] = 13, ["name"] = "wool:red"}, {["x"] = 10, ["meta"] = {["fields"] = {}, ["inventory"] = {}}, ["y"] = 4, ["z"] = 14, ["name"] = "wool:red"}, {["x"] = 10, ["meta"] = {["fields"] = {}, ["inventory"] = {}}, ["y"] = 4, ["z"] = 15, ["name"] = "wool:red"}, {["x"] = 10, ["meta"] = {["fields"] = {}, ["inventory"] = {}}, ["y"] = 5, ["z"] = 7, ["name"] = "wool:white"}, {["x"] = 10, ["meta"] = {["fields"] = {}, ["inventory"] = {}}, ["y"] = 5, ["z"] = 8, ["name"] = "wool:white"}, {["x"] = 10, ["meta"] = {["fields"] = {}, ["inventory"] = {}}, ["y"] = 5, ["z"] = 9, ["name"] = "wool:white"}, {["x"] = 10, ["meta"] = {["fields"] = {}, ["inventory"] = {}}, ["y"] = 5, ["param1"] = 109, ["z"] = 10, ["name"] = "doors:door_wood_t_2"}, {["x"] = 10, ["meta"] = {["fields"] = {}, ["inventory"] = {}}, ["y"] = 5, ["z"] = 11, ["name"] = "wool:white"}, {["x"] = 10, ["meta"] = {["fields"] = {}, ["inventory"] = {}}, ["y"] = 5, ["param1"] = 109, ["z"] = 12, ["name"] = "xpanes:pane_10"}, {["x"] = 10, ["meta"] = {["fields"] = {}, ["inventory"] = {}}, ["y"] = 5, ["z"] = 13, ["name"] = "wool:white"}, {["x"] = 10, ["meta"] = {["fields"] = {}, ["inventory"] = {}}, ["y"] = 5, ["param1"] = 109, ["z"] = 14, ["name"] = "xpanes:pane_10"}, {["x"] = 10, ["meta"] = {["fields"] = {}, ["inventory"] = {}}, ["y"] = 5, ["z"] = 15, ["name"] = "wool:white"}, {["x"] = 10, ["meta"] = {["fields"] = {}, ["inventory"] = {}}, ["y"] = 5, ["z"] = 16, ["name"] = "wool:red"}, {["x"] = 10, ["meta"] = {["fields"] = {}, ["inventory"] = {}}, ["y"] = 5, ["z"] = 17, ["name"] = "wool:white"}, {["x"] = 10, ["meta"] = {["fields"] = {}, ["inventory"] = {}}, ["y"] = 6, ["z"] = 7, ["name"] = "wool:red"}, {["x"] = 10, ["meta"] = {["fields"] = {}, ["inventory"] = {}}, ["y"] = 6, ["z"] = 8, ["name"] = "wool:red"}, {["x"] = 10, ["meta"] = {["fields"] = {}, ["inventory"] = {}}, ["y"] = 6, ["z"] = 9, ["name"] = "wool:red"}, {["x"] = 10, ["meta"] = {["fields"] = {}, ["inventory"] = {}}, ["y"] = 6, ["z"] = 10, ["name"] = "wool:red"}, {["x"] = 10, ["meta"] = {["fields"] = {}, ["inventory"] = {}}, ["y"] = 6, ["z"] = 11, ["name"] = "wool:red"}, {["x"] = 10, ["meta"] = {["fields"] = {}, ["inventory"] = {}}, ["y"] = 6, ["z"] = 12, ["name"] = "wool:red"}, {["x"] = 10, ["meta"] = {["fields"] = {}, ["inventory"] = {}}, ["y"] = 6, ["z"] = 13, ["name"] = "wool:red"}, {["x"] = 10, ["meta"] = {["fields"] = {}, ["inventory"] = {}}, ["y"] = 6, ["z"] = 14, ["name"] = "wool:red"}, {["x"] = 10, ["meta"] = {["fields"] = {}, ["inventory"] = {}}, ["y"] = 6, ["z"] = 15, ["name"] = "wool:red"}, {["x"] = 10, ["meta"] = {["fields"] = {}, ["inventory"] = {}}, ["y"] = 6, ["z"] = 16, ["name"] = "wool:red"}, {["x"] = 11, ["meta"] = {["fields"] = {}, ["inventory"] = {}}, ["y"] = 3, ["z"] = 10, ["name"] = "wool:red"}, {["x"] = 11, ["meta"] = {["fields"] = {}, ["inventory"] = {}}, ["y"] = 3, ["z"] = 11, ["name"] = "wool:red"}, {["x"] = 11, ["meta"] = {["fields"] = {}, ["inventory"] = {}}, ["y"] = 4, ["z"] = 12, ["name"] = "wool:red"}, {["x"] = 11, ["meta"] = {["fields"] = {}, ["inventory"] = {}}, ["y"] = 4, ["z"] = 13, ["name"] = "wool:red"}, {["x"] = 12, ["meta"] = {["fields"] = {}, ["inventory"] = {}}, ["y"] = 4, ["z"] = 11, ["name"] = "wool:red"}, {["x"] = 12, ["meta"] = {["fields"] = {}, ["inventory"] = {}}, ["y"] = 4, ["z"] = 12, ["name"] = "wool:red"}, {["x"] = 12, ["meta"] = {["fields"] = {}, ["inventory"] = {}}, ["y"] = 4, ["z"] = 13, ["name"] = "wool:red"}, {["x"] = 13, ["meta"] = {["fields"] = {}, ["inventory"] = {}}, ["y"] = 4, ["z"] = 11, ["name"] = "wool:red"}, {["x"] = 13, ["meta"] = {["fields"] = {}, ["inventory"] = {}}, ["y"] = 4, ["z"] = 12, ["name"] = "wool:red"}, {["x"] = 13, ["meta"] = {["fields"] = {}, ["inventory"] = {}}, ["y"] = 4, ["z"] = 13, ["name"] = "wool:red"}, {["x"] = 14, ["meta"] = {["fields"] = {}, ["inventory"] = {}}, ["y"] = 4, ["z"] = 11, ["name"] = "wool:red"}, {["x"] = 14, ["meta"] = {["fields"] = {}, ["inventory"] = {}}, ["y"] = 4, ["z"] = 12, ["name"] = "wool:red"}, {["x"] = 14, ["meta"] = {["fields"] = {}, ["inventory"] = {}}, ["y"] = 4, ["z"] = 13, ["name"] = "wool:red"}, {["x"] = 15, ["meta"] = {["fields"] = {}, ["inventory"] = {}}, ["y"] = 4, ["z"] = 11, ["name"] = "wool:red"}, {["x"] = 15, ["meta"] = {["fields"] = {}, ["inventory"] = {}}, ["y"] = 4, ["z"] = 12, ["name"] = "wool:red"}, {["x"] = 16, ["meta"] = {["fields"] = {}, ["inventory"] = {}}, ["y"] = 4, ["z"] = 11, ["name"] = "wool:red"}}