5:return {{["x"] = 0, ["meta"] = {["fields"] = {}, ["inventory"] = {}}, ["y"] = 0, ["z"] = 14, ["name"] = "rainbow:dirt_black"}, {["x"] = 0, ["meta"] = {["fields"] = {}, ["inventory"] = {}}, ["param2"] = 18, ["y"] = 6, ["param1"] = 206, ["z"] = 3, ["name"] = "rainbow:slab_tree_black_1"}, {["x"] = 0, ["meta"] = {["fields"] = {}, ["inventory"] = {}}, ["param2"] = 18, ["y"] = 6, ["param1"] = 206, ["z"] = 11, ["name"] = "rainbow:slab_tree_black_1"}, {["x"] = 0, ["meta"] = {["fields"] = {}, ["inventory"] = {}}, ["param2"] = 1, ["y"] = 10, ["param1"] = 190, ["z"] = 2, ["name"] = "rainbow:slope_fancybrick_red_outer_cut"}, {["x"] = 0, ["meta"] = {["fields"] = {}, ["inventory"] = {}}, ["param2"] = 1, ["y"] = 10, ["param1"] = 206, ["z"] = 3, ["name"] = "rainbow:slope_fancybrick_red"}, {["x"] = 0, ["meta"] = {["fields"] = {}, ["inventory"] = {}}, ["param2"] = 2, ["y"] = 10, ["param1"] = 190, ["z"] = 4, ["name"] = "rainbow:slope_fancybrick_red_outer_cut"}, {["x"] = 0, ["meta"] = {["fields"] = {}, ["inventory"] = {}}, ["param2"] = 1, ["y"] = 10, ["param1"] = 190, ["z"] = 10, ["name"] = "rainbow:slope_fancybrick_red_outer_cut"}, {["x"] = 0, ["meta"] = {["fields"] = {}, ["inventory"] = {}}, ["param2"] = 1, ["y"] = 10, ["param1"] = 206, ["z"] = 11, ["name"] = "rainbow:slope_fancybrick_red"}, {["x"] = 0, ["meta"] = {["fields"] = {}, ["inventory"] = {}}, ["param2"] = 2, ["y"] = 10, ["param1"] = 190, ["z"] = 12, ["name"] = "rainbow:slope_fancybrick_red_outer_cut"}, {["x"] = 1, ["meta"] = {["fields"] = {}, ["inventory"] = {}}, ["param2"] = 19, ["y"] = 1, ["param1"] = 189, ["z"] = 4, ["name"] = "rainbow:slab_stone_black_1"}, {["x"] = 1, ["meta"] = {["fields"] = {}, ["inventory"] = {}}, ["param2"] = 19, ["y"] = 1, ["param1"] = 206, ["z"] = 5, ["name"] = "rainbow:slab_stone_black_1"}, {["x"] = 1, ["meta"] = {["fields"] = {}, ["inventory"] = {}}, ["param2"] = 19, ["y"] = 1, ["param1"] = 190, ["z"] = 6, ["name"] = "rainbow:slab_stone_black_1"}, {["x"] = 1, ["meta"] = {["fields"] = {}, ["inventory"] = {}}, ["param2"] = 19, ["y"] = 1, ["param1"] = 206, ["z"] = 7, ["name"] = "rainbow:slab_stone_black_1"}, {["x"] = 1, ["meta"] = {["fields"] = {}, ["inventory"] = {}}, ["param2"] = 19, ["y"] = 1, ["param1"] = 190, ["z"] = 8, ["name"] = "rainbow:slab_stone_black_1"}, {["x"] = 1, ["meta"] = {["fields"] = {}, ["inventory"] = {}}, ["param2"] = 19, ["y"] = 1, ["param1"] = 206, ["z"] = 9, ["name"] = "rainbow:slab_stone_black_1"}, {["x"] = 1, ["meta"] = {["fields"] = {}, ["inventory"] = {}}, ["param2"] = 19, ["y"] = 1, ["param1"] = 189, ["z"] = 10, ["name"] = "rainbow:slab_stone_black_1"}, {["x"] = 1, ["meta"] = {["fields"] = {}, ["inventory"] = {}}, ["param2"] = 19, ["y"] = 2, ["param1"] = 205, ["z"] = 4, ["name"] = "rainbow:slab_stone_black_1"}, {["x"] = 1, ["meta"] = {["fields"] = {}, ["inventory"] = {}}, ["param2"] = 19, ["y"] = 2, ["param1"] = 222, ["z"] = 5, ["name"] = "rainbow:slab_stone_black_1"}, {["x"] = 1, ["meta"] = {["fields"] = {}, ["inventory"] = {}}, ["param2"] = 19, ["y"] = 2, ["param1"] = 206, ["z"] = 6, ["name"] = "rainbow:slab_stone_black_1"}, {["x"] = 1, ["meta"] = {["fields"] = {}, ["inventory"] = {}}, ["param2"] = 19, ["y"] = 2, ["param1"] = 222, ["z"] = 7, ["name"] = "rainbow:slab_stone_black_1"}, {["x"] = 1, ["meta"] = {["fields"] = {}, ["inventory"] = {}}, ["param2"] = 19, ["y"] = 2, ["param1"] = 206, ["z"] = 8, ["name"] = "rainbow:slab_stone_black_1"}, {["x"] = 1, ["meta"] = {["fields"] = {}, ["inventory"] = {}}, ["param2"] = 19, ["y"] = 2, ["param1"] = 222, ["z"] = 9, ["name"] = "rainbow:slab_stone_black_1"}, {["x"] = 1, ["meta"] = {["fields"] = {}, ["inventory"] = {}}, ["param2"] = 19, ["y"] = 2, ["param1"] = 205, ["z"] = 10, ["name"] = "rainbow:slab_stone_black_1"}, {["x"] = 1, ["meta"] = {["fields"] = {}, ["inventory"] = {}}, ["param2"] = 19, ["y"] = 3, ["param1"] = 221, ["z"] = 4, ["name"] = "rainbow:slab_wood_black_1"}, {["x"] = 1, ["meta"] = {["fields"] = {}, ["inventory"] = {}}, ["param2"] = 18, ["y"] = 3, ["param1"] = 238, ["z"] = 5, ["name"] = "rainbow:slab_lightglass_red_1"}, {["x"] = 1, ["meta"] = {["fields"] = {}, ["inventory"] = {}}, ["param2"] = 19, ["y"] = 3, ["param1"] = 222, ["z"] = 6, ["name"] = "rainbow:slab_wood_black_1"}, {["x"] = 1, ["meta"] = {["fields"] = {}, ["inventory"] = {}}, ["param2"] = 18, ["y"] = 3, ["param1"] = 238, ["z"] = 7, ["name"] = "rainbow:slab_lightglass_red_1"}, {["x"] = 1, ["meta"] = {["fields"] = {}, ["inventory"] = {}}, ["param2"] = 19, ["y"] = 3, ["param1"] = 222, ["z"] = 8, ["name"] = "rainbow:slab_wood_black_1"}, {["x"] = 1, ["meta"] = {["fields"] = {}, ["inventory"] = {}}, ["param2"] = 18, ["y"] = 3, ["param1"] = 238, ["z"] = 9, ["name"] = "rainbow:slab_lightglass_red_1"}, {["x"] = 1, ["meta"] = {["fields"] = {}, ["inventory"] = {}}, ["param2"] = 19, ["y"] = 3, ["param1"] = 221, ["z"] = 10, ["name"] = "rainbow:slab_wood_black_1"}, {["x"] = 1, ["meta"] = {["fields"] = {}, ["inventory"] = {}}, ["param2"] = 18, ["y"] = 4, ["param1"] = 238, ["z"] = 4, ["name"] = "rainbow:slab_lightglass_red_1"}, {["x"] = 1, ["meta"] = {["fields"] = {}, ["inventory"] = {}}, ["param2"] = 19, ["y"] = 4, ["param1"] = 222, ["z"] = 5, ["name"] = "rainbow:slab_wood_black_1"}, {["x"] = 1, ["meta"] = {["fields"] = {}, ["inventory"] = {}}, ["param2"] = 18, ["y"] = 4, ["param1"] = 238, ["z"] = 6, ["name"] = "rainbow:slab_lightglass_red_1"}, {["x"] = 1, ["meta"] = {["fields"] = {}, ["inventory"] = {}}, ["param2"] = 19, ["y"] = 4, ["param1"] = 222, ["z"] = 7, ["name"] = "rainbow:slab_wood_black_1"}, {["x"] = 1, ["meta"] = {["fields"] = {}, ["inventory"] = {}}, ["param2"] = 18, ["y"] = 4, ["param1"] = 238, ["z"] = 8, ["name"] = "rainbow:slab_lightglass_red_1"}, {["x"] = 1, ["meta"] = {["fields"] = {}, ["inventory"] = {}}, ["param2"] = 19, ["y"] = 4, ["param1"] = 222, ["z"] = 9, ["name"] = "rainbow:slab_wood_black_1"}, {["x"] = 1, ["meta"] = {["fields"] = {}, ["inventory"] = {}}, ["param2"] = 18, ["y"] = 4, ["param1"] = 238, ["z"] = 10, ["name"] = "rainbow:slab_lightglass_red_1"}, {["x"] = 1, ["meta"] = {["fields"] = {}, ["inventory"] = {}}, ["param2"] = 20, ["y"] = 5, ["param1"] = 205, ["z"] = 3, ["name"] = "rainbow:slab_wood_red_1"}, {["x"] = 1, ["meta"] = {["fields"] = {}, ["inventory"] = {}}, ["param2"] = 19, ["y"] = 5, ["param1"] = 221, ["z"] = 4, ["name"] = "rainbow:slab_stone_black_1"}, {["x"] = 1, ["meta"] = {["fields"] = {}, ["inventory"] = {}}, ["param2"] = 19, ["y"] = 5, ["param1"] = 206, ["z"] = 5, ["name"] = "rainbow:slab_stone_black_1"}, {["x"] = 1, ["meta"] = {["fields"] = {}, ["inventory"] = {}}, ["param2"] = 19, ["y"] = 5, ["param1"] = 222, ["z"] = 6, ["name"] = "rainbow:slab_stone_black_1"}, {["x"] = 1, ["meta"] = {["fields"] = {}, ["inventory"] = {}}, ["param2"] = 19, ["y"] = 5, ["param1"] = 206, ["z"] = 7, ["name"] = "rainbow:slab_stone_black_1"}, {["x"] = 1, ["meta"] = {["fields"] = {}, ["inventory"] = {}}, ["param2"] = 19, ["y"] = 5, ["param1"] = 222, ["z"] = 8, ["name"] = "rainbow:slab_stone_black_1"}, {["x"] = 1, ["meta"] = {["fields"] = {}, ["inventory"] = {}}, ["param2"] = 19, ["y"] = 5, ["param1"] = 206, ["z"] = 9, ["name"] = "rainbow:slab_stone_black_1"}, {["x"] = 1, ["meta"] = {["fields"] = {}, ["inventory"] = {}}, ["param2"] = 19, ["y"] = 5, ["param1"] = 221, ["z"] = 10, ["name"] = "rainbow:slab_stone_black_1"}, {["x"] = 1, ["meta"] = {["fields"] = {}, ["inventory"] = {}}, ["param2"] = 20, ["y"] = 5, ["param1"] = 205, ["z"] = 11, ["name"] = "rainbow:slab_wood_red_1"}, {["x"] = 1, ["meta"] = {["fields"] = {}, ["inventory"] = {}}, ["param2"] = 9, ["y"] = 6, ["param1"] = 205, ["z"] = 2, ["name"] = "rainbow:slope_tree_black"}, {["x"] = 1, ["meta"] = {["fields"] = {}, ["inventory"] = {}}, ["param2"] = 18, ["y"] = 6, ["param1"] = 205, ["z"] = 4, ["name"] = "rainbow:slope_tree_black"}, {["x"] = 1, ["meta"] = {["fields"] = {}, ["inventory"] = {}}, ["param2"] = 9, ["y"] = 6, ["param1"] = 205, ["z"] = 10, ["name"] = "rainbow:slope_tree_black"}, {["x"] = 1, ["meta"] = {["fields"] = {}, ["inventory"] = {}}, ["param2"] = 18, ["y"] = 6, ["param1"] = 205, ["z"] = 12, ["name"] = "rainbow:slope_tree_black"}, {["x"] = 1, ["meta"] = {["fields"] = {}, ["inventory"] = {}}, ["param2"] = 9, ["y"] = 7, ["param1"] = 221, ["z"] = 2, ["name"] = "rainbow:slope_tree_black"}, {["x"] = 1, ["meta"] = {["fields"] = {}, ["inventory"] = {}}, ["param2"] = 12, ["y"] = 7, ["param1"] = 238, ["z"] = 3, ["name"] = "rainbow:slab_lightglass_red_1"}, {["x"] = 1, ["meta"] = {["fields"] = {}, ["inventory"] = {}}, ["param2"] = 18, ["y"] = 7, ["param1"] = 221, ["z"] = 4, ["name"] = "rainbow:slope_tree_black"}, {["x"] = 1, ["meta"] = {["fields"] = {}, ["inventory"] = {}}, ["param2"] = 9, ["y"] = 7, ["param1"] = 221, ["z"] = 10, ["name"] = "rainbow:slope_tree_black"}, {["x"] = 1, ["meta"] = {["fields"] = {}, ["inventory"] = {}}, ["param2"] = 12, ["y"] = 7, ["param1"] = 238, ["z"] = 11, ["name"] = "rainbow:slab_lightglass_red_1"}, {["x"] = 1, ["meta"] = {["fields"] = {}, ["inventory"] = {}}, ["param2"] = 18, ["y"] = 7, ["param1"] = 221, ["z"] = 12, ["name"] = "rainbow:slope_tree_black"}, {["x"] = 1, ["meta"] = {["fields"] = {}, ["inventory"] = {}}, ["param2"] = 9, ["y"] = 8, ["param1"] = 221, ["z"] = 2, ["name"] = "rainbow:slope_tree_black"}, {["x"] = 1, ["meta"] = {["fields"] = {}, ["inventory"] = {}}, ["param2"] = 12, ["y"] = 8, ["param1"] = 238, ["z"] = 3, ["name"] = "rainbow:slab_lightglass_red_1"}, {["x"] = 1, ["meta"] = {["fields"] = {}, ["inventory"] = {}}, ["param2"] = 18, ["y"] = 8, ["param1"] = 221, ["z"] = 4, ["name"] = "rainbow:slope_tree_black"}, {["x"] = 1, ["meta"] = {["fields"] = {}, ["inventory"] = {}}, ["param2"] = 9, ["y"] = 8, ["param1"] = 221, ["z"] = 10, ["name"] = "rainbow:slope_tree_black"}, {["x"] = 1, ["meta"] = {["fields"] = {}, ["inventory"] = {}}, ["param2"] = 12, ["y"] = 8, ["param1"] = 238, ["z"] = 11, ["name"] = "rainbow:slab_lightglass_red_1"}, {["x"] = 1, ["meta"] = {["fields"] = {}, ["inventory"] = {}}, ["param2"] = 18, ["y"] = 8, ["param1"] = 221, ["z"] = 12, ["name"] = "rainbow:slope_tree_black"}, {["x"] = 1, ["meta"] = {["fields"] = {}, ["inventory"] = {}}, ["param2"] = 9, ["y"] = 9, ["param1"] = 221, ["z"] = 2, ["name"] = "rainbow:slope_tree_black"}, {["x"] = 1, ["meta"] = {["fields"] = {}, ["inventory"] = {}}, ["param2"] = 12, ["y"] = 9, ["param1"] = 238, ["z"] = 3, ["name"] = "rainbow:slab_lightglass_red_1"}, {["x"] = 1, ["meta"] = {["fields"] = {}, ["inventory"] = {}}, ["param2"] = 18, ["y"] = 9, ["param1"] = 221, ["z"] = 4, ["name"] = "rainbow:slope_tree_black"}, {["x"] = 1, ["meta"] = {["fields"] = {}, ["inventory"] = {}}, ["param2"] = 16, ["y"] = 9, ["param1"] = 221, ["z"] = 10, ["name"] = "rainbow:slope_tree_black"}, {["x"] = 1, ["meta"] = {["fields"] = {}, ["inventory"] = {}}, ["param2"] = 12, ["y"] = 9, ["param1"] = 238, ["z"] = 11, ["name"] = "rainbow:slab_lightglass_red_1"}, {["x"] = 1, ["meta"] = {["fields"] = {}, ["inventory"] = {}}, ["param2"] = 18, ["y"] = 9, ["param1"] = 221, ["z"] = 12, ["name"] = "rainbow:slope_tree_black"}, {["x"] = 1, ["meta"] = {["fields"] = {}, ["inventory"] = {}}, ["param2"] = 1, ["y"] = 10, ["param1"] = 190, ["z"] = 1, ["name"] = "rainbow:slope_fancybrick_red_outer_cut"}, {["x"] = 1, ["meta"] = {["fields"] = {}, ["inventory"] = {}}, ["param2"] = 1, ["y"] = 10, ["param1"] = 205, ["z"] = 2, ["name"] = "rainbow:slope_fancybrick_red_inner_cut"}, {["x"] = 1, ["meta"] = {["fields"] = {}, ["inventory"] = {}}, ["param2"] = 2, ["y"] = 10, ["param1"] = 205, ["z"] = 4, ["name"] = "rainbow:slope_fancybrick_red_inner_cut"}, {["x"] = 1, ["meta"] = {["fields"] = {}, ["inventory"] = {}}, ["param2"] = 2, ["y"] = 10, ["param1"] = 190, ["z"] = 5, ["name"] = "rainbow:slope_fancybrick_red_outer_cut"}, {["x"] = 1, ["meta"] = {["fields"] = {}, ["inventory"] = {}}, ["param2"] = 1, ["y"] = 10, ["param1"] = 190, ["z"] = 9, ["name"] = "rainbow:slope_fancybrick_red_outer_cut"}, {["x"] = 1, ["meta"] = {["fields"] = {}, ["inventory"] = {}}, ["param2"] = 1, ["y"] = 10, ["param1"] = 205, ["z"] = 10, ["name"] = "rainbow:slope_fancybrick_red_inner_cut"}, {["x"] = 1, ["meta"] = {["fields"] = {}, ["inventory"] = {}}, ["param2"] = 2, ["y"] = 10, ["param1"] = 205, ["z"] = 12, ["name"] = "rainbow:slope_fancybrick_red_inner_cut"}, {["x"] = 1, ["meta"] = {["fields"] = {}, ["inventory"] = {}}, ["param2"] = 2, ["y"] = 10, ["param1"] = 190, ["z"] = 13, ["name"] = "rainbow:slope_fancybrick_red_outer_cut"}, {["x"] = 1, ["meta"] = {["fields"] = {}, ["inventory"] = {}}, ["param2"] = 1, ["y"] = 11, ["param1"] = 190, ["z"] = 2, ["name"] = "rainbow:slope_fancybrick_red_outer_cut"}, {["x"] = 1, ["meta"] = {["fields"] = {}, ["inventory"] = {}}, ["param2"] = 1, ["y"] = 11, ["param1"] = 206, ["z"] = 3, ["name"] = "rainbow:slope_fancybrick_red"}, {["x"] = 1, ["meta"] = {["fields"] = {}, ["inventory"] = {}}, ["param2"] = 2, ["y"] = 11, ["param1"] = 190, ["z"] = 4, ["name"] = "rainbow:slope_fancybrick_red_outer_cut"}, {["x"] = 1, ["meta"] = {["fields"] = {}, ["inventory"] = {}}, ["param2"] = 1, ["y"] = 11, ["param1"] = 190, ["z"] = 10, ["name"] = "rainbow:slope_fancybrick_red_outer_cut"}, {["x"] = 1, ["meta"] = {["fields"] = {}, ["inventory"] = {}}, ["param2"] = 1, ["y"] = 11, ["param1"] = 206, ["z"] = 11, ["name"] = "rainbow:slope_fancybrick_red"}, {["x"] = 1, ["meta"] = {["fields"] = {}, ["inventory"] = {}}, ["param2"] = 2, ["y"] = 11, ["param1"] = 190, ["z"] = 12, ["name"] = "rainbow:slope_fancybrick_red_outer_cut"}, {["x"] = 2, ["meta"] = {["fields"] = {}, ["inventory"] = {}}, ["y"] = 0, ["z"] = 2, ["name"] = "rainbow:dirt_black"}, {["x"] = 2, ["meta"] = {["fields"] = {}, ["inventory"] = {}}, ["y"] = 0, ["z"] = 3, ["name"] = "rainbow:dirt_black"}, {["x"] = 2, ["meta"] = {["fields"] = {}, ["inventory"] = {}}, ["y"] = 0, ["z"] = 4, ["name"] = "rainbow:dirt_black"}, {["x"] = 2, ["meta"] = {["fields"] = {}, ["inventory"] = {}}, ["y"] = 0, ["z"] = 5, ["name"] = "rainbow:dirt_black"}, {["x"] = 2, ["meta"] = {["fields"] = {}, ["inventory"] = {}}, ["y"] = 0, ["z"] = 6, ["name"] = "rainbow:stone_black"}, {["x"] = 2, ["meta"] = {["fields"] = {}, ["inventory"] = {}}, ["y"] = 0, ["z"] = 7, ["name"] = "rainbow:stone_black"}, {["x"] = 2, ["meta"] = {["fields"] = {}, ["inventory"] = {}}, ["y"] = 0, ["z"] = 8, ["name"] = "rainbow:stone_black"}, {["x"] = 2, ["meta"] = {["fields"] = {}, ["inventory"] = {}}, ["y"] = 0, ["z"] = 9, ["name"] = "rainbow:dirt_black"}, {["x"] = 2, ["meta"] = {["fields"] = {}, ["inventory"] = {}}, ["y"] = 0, ["z"] = 10, ["name"] = "rainbow:dirt_black"}, {["x"] = 2, ["meta"] = {["fields"] = {}, ["inventory"] = {}}, ["y"] = 0, ["z"] = 11, ["name"] = "rainbow:dirt_black"}, {["x"] = 2, ["meta"] = {["fields"] = {}, ["inventory"] = {}}, ["y"] = 0, ["z"] = 12, ["name"] = "rainbow:dirt_black"}, {["x"] = 2, ["meta"] = {["fields"] = {}, ["inventory"] = {}}, ["param2"] = 1, ["y"] = 1, ["param1"] = 205, ["z"] = 2, ["name"] = "rainbow:column_bottom_tree_darkgrey"}, {["x"] = 2, ["meta"] = {["fields"] = {}, ["inventory"] = {}}, ["param2"] = 9, ["y"] = 1, ["param1"] = 221, ["z"] = 3, ["name"] = "rainbow:slope_tree_black"}, {["x"] = 2, ["meta"] = {["fields"] = {}, ["inventory"] = {}}, ["param2"] = 7, ["y"] = 1, ["z"] = 4, ["name"] = "rainbow:tree_black"}, {["x"] = 2, ["meta"] = {["fields"] = {}, ["inventory"] = {}}, ["param2"] = 7, ["y"] = 1, ["z"] = 5, ["name"] = "rainbow:tree_black"}, {["x"] = 2, ["meta"] = {["fields"] = {}, ["inventory"] = {}}, ["param2"] = 7, ["y"] = 1, ["z"] = 6, ["name"] = "rainbow:tree_black"}, {["x"] = 2, ["meta"] = {["fields"] = {}, ["inventory"] = {}}, ["param2"] = 7, ["y"] = 1, ["z"] = 7, ["name"] = "rainbow:tree_black"}, {["x"] = 2, ["meta"] = {["fields"] = {}, ["inventory"] = {}}, ["param2"] = 7, ["y"] = 1, ["z"] = 8, ["name"] = "rainbow:tree_black"}, {["x"] = 2, ["meta"] = {["fields"] = {}, ["inventory"] = {}}, ["param2"] = 7, ["y"] = 1, ["z"] = 9, ["name"] = "rainbow:tree_black"}, {["x"] = 2, ["meta"] = {["fields"] = {}, ["inventory"] = {}}, ["param2"] = 7, ["y"] = 1, ["z"] = 10, ["name"] = "rainbow:tree_black"}, {["x"] = 2, ["meta"] = {["fields"] = {}, ["inventory"] = {}}, ["param2"] = 18, ["y"] = 1, ["param1"] = 221, ["z"] = 11, ["name"] = "rainbow:slope_tree_black"}, {["x"] = 2, ["meta"] = {["fields"] = {}, ["inventory"] = {}}, ["param2"] = 1, ["y"] = 1, ["param1"] = 204, ["z"] = 12, ["name"] = "rainbow:column_bottom_tree_darkgrey"}, {["x"] = 2, ["meta"] = {["fields"] = {}, ["inventory"] = {}}, ["param2"] = 1, ["y"] = 2, ["param1"] = 189, ["z"] = 2, ["name"] = "rainbow:column_middle_tree_darkgrey"}, {["x"] = 2, ["meta"] = {["fields"] = {}, ["inventory"] = {}}, ["param2"] = 9, ["y"] = 2, ["param1"] = 204, ["z"] = 3, ["name"] = "rainbow:slope_tree_black"}, {["x"] = 2, ["meta"] = {["fields"] = {}, ["inventory"] = {}}, ["param2"] = 18, ["y"] = 2, ["param1"] = 204, ["z"] = 11, ["name"] = "rainbow:slope_tree_black"}, {["x"] = 2, ["meta"] = {["fields"] = {}, ["inventory"] = {}}, ["param2"] = 1, ["y"] = 2, ["param1"] = 188, ["z"] = 12, ["name"] = "rainbow:column_middle_tree_darkgrey"}, {["x"] = 2, ["meta"] = {["fields"] = {}, ["inventory"] = {}}, ["param2"] = 1, ["y"] = 3, ["param1"] = 173, ["z"] = 2, ["name"] = "rainbow:column_middle_tree_darkgrey"}, {["x"] = 2, ["meta"] = {["fields"] = {}, ["inventory"] = {}}, ["param2"] = 9, ["y"] = 3, ["param1"] = 188, ["z"] = 3, ["name"] = "rainbow:slope_tree_black"}, {["x"] = 2, ["meta"] = {["fields"] = {}, ["inventory"] = {}}, ["param2"] = 18, ["y"] = 3, ["param1"] = 188, ["z"] = 11, ["name"] = "rainbow:slope_tree_black"}, {["x"] = 2, ["meta"] = {["fields"] = {}, ["inventory"] = {}}, ["param2"] = 1, ["y"] = 3, ["param1"] = 172, ["z"] = 12, ["name"] = "rainbow:column_middle_tree_darkgrey"}, {["x"] = 2, ["meta"] = {["fields"] = {}, ["inventory"] = {}}, ["param2"] = 1, ["y"] = 4, ["param1"] = 189, ["z"] = 2, ["name"] = "rainbow:column_middle_tree_darkgrey"}, {["x"] = 2, ["meta"] = {["fields"] = {}, ["inventory"] = {}}, ["param2"] = 9, ["y"] = 4, ["param1"] = 204, ["z"] = 3, ["name"] = "rainbow:slope_tree_black"}, {["x"] = 2, ["meta"] = {["fields"] = {}, ["inventory"] = {}}, ["param2"] = 18, ["y"] = 4, ["param1"] = 204, ["z"] = 11, ["name"] = "rainbow:slope_tree_black"}, {["x"] = 2, ["meta"] = {["fields"] = {}, ["inventory"] = {}}, ["param2"] = 1, ["y"] = 4, ["param1"] = 188, ["z"] = 12, ["name"] = "rainbow:column_middle_tree_darkgrey"}, {["x"] = 2, ["meta"] = {["fields"] = {}, ["inventory"] = {}}, ["param2"] = 1, ["y"] = 5, ["param1"] = 173, ["z"] = 2, ["name"] = "rainbow:column_top_tree_darkgrey"}, {["x"] = 2, ["meta"] = {["fields"] = {}, ["inventory"] = {}}, ["param2"] = 9, ["y"] = 5, ["param1"] = 188, ["z"] = 3, ["name"] = "rainbow:slope_tree_black"}, {["x"] = 2, ["meta"] = {["fields"] = {}, ["inventory"] = {}}, ["param2"] = 21, ["y"] = 5, ["param1"] = 189, ["z"] = 5, ["name"] = "rainbow:slab_stone_black_1"}, {["x"] = 2, ["meta"] = {["fields"] = {}, ["inventory"] = {}}, ["param2"] = 21, ["y"] = 5, ["param1"] = 205, ["z"] = 6, ["name"] = "rainbow:slab_stone_black_1"}, {["x"] = 2, ["meta"] = {["fields"] = {}, ["inventory"] = {}}, ["param2"] = 21, ["y"] = 5, ["param1"] = 221, ["z"] = 7, ["name"] = "rainbow:slab_stone_black_1"}, {["x"] = 2, ["meta"] = {["fields"] = {}, ["inventory"] = {}}, ["param2"] = 21, ["y"] = 5, ["param1"] = 205, ["z"] = 8, ["name"] = "rainbow:slab_stone_black_1"}, {["x"] = 2, ["meta"] = {["fields"] = {}, ["inventory"] = {}}, ["param2"] = 21, ["y"] = 5, ["param1"] = 189, ["z"] = 9, ["name"] = "rainbow:slab_stone_black_1"}, {["x"] = 2, ["meta"] = {["fields"] = {}, ["inventory"] = {}}, ["param2"] = 18, ["y"] = 5, ["param1"] = 188, ["z"] = 11, ["name"] = "rainbow:slope_tree_black"}, {["x"] = 2, ["meta"] = {["fields"] = {}, ["inventory"] = {}}, ["param2"] = 1, ["y"] = 5, ["param1"] = 172, ["z"] = 12, ["name"] = "rainbow:column_top_tree_darkgrey"}, {["x"] = 2, ["meta"] = {["fields"] = {}, ["inventory"] = {}}, ["param2"] = 9, ["y"] = 6, ["param1"] = 206, ["z"] = 1, ["name"] = "rainbow:slope_tree_black"}, {["x"] = 2, ["meta"] = {["fields"] = {}, ["inventory"] = {}}, ["y"] = 6, ["param1"] = 204, ["z"] = 3, ["name"] = "rainbow:slab_wood_red_1"}, {["x"] = 2, ["meta"] = {["fields"] = {}, ["inventory"] = {}}, ["y"] = 6, ["param1"] = 188, ["z"] = 4, ["name"] = "rainbow:slab_wood_red_1"}, {["x"] = 2, ["meta"] = {["fields"] = {}, ["inventory"] = {}}, ["param2"] = 5, ["y"] = 6, ["param1"] = 173, ["z"] = 5, ["name"] = "rainbow:slope_tree_black"}, {["x"] = 2, ["meta"] = {["fields"] = {}, ["inventory"] = {}}, ["param2"] = 19, ["y"] = 6, ["param1"] = 190, ["z"] = 6, ["name"] = "rainbow:slab_wood_black_1"}, {["x"] = 2, ["meta"] = {["fields"] = {}, ["inventory"] = {}}, ["param2"] = 19, ["y"] = 6, ["param1"] = 206, ["z"] = 7, ["name"] = "rainbow:slab_wood_black_1"}, {["x"] = 2, ["meta"] = {["fields"] = {}, ["inventory"] = {}}, ["param2"] = 19, ["y"] = 6, ["param1"] = 190, ["z"] = 8, ["name"] = "rainbow:slab_wood_black_1"}, {["x"] = 2, ["meta"] = {["fields"] = {}, ["inventory"] = {}}, ["param2"] = 9, ["y"] = 6, ["param1"] = 173, ["z"] = 9, ["name"] = "rainbow:slope_tree_black"}, {["x"] = 2, ["meta"] = {["fields"] = {}, ["inventory"] = {}}, ["y"] = 6, ["param1"] = 188, ["z"] = 10, ["name"] = "rainbow:slab_wood_red_1"}, {["x"] = 2, ["meta"] = {["fields"] = {}, ["inventory"] = {}}, ["y"] = 6, ["param1"] = 204, ["z"] = 11, ["name"] = "rainbow:slab_wood_red_1"}, {["x"] = 2, ["meta"] = {["fields"] = {}, ["inventory"] = {}}, ["param2"] = 18, ["y"] = 6, ["param1"] = 205, ["z"] = 13, ["name"] = "rainbow:slope_tree_black"}, {["x"] = 2, ["meta"] = {["fields"] = {}, ["inventory"] = {}}, ["param2"] = 9, ["y"] = 7, ["param1"] = 222, ["z"] = 1, ["name"] = "rainbow:slope_tree_black"}, {["x"] = 2, ["meta"] = {["fields"] = {}, ["inventory"] = {}}, ["param2"] = 18, ["y"] = 7, ["param1"] = 189, ["z"] = 5, ["name"] = "rainbow:slope_tree_black"}, {["x"] = 2, ["meta"] = {["fields"] = {}, ["inventory"] = {}}, ["param2"] = 19, ["y"] = 7, ["param1"] = 174, ["z"] = 6, ["name"] = "rainbow:slab_wood_red_1"}, {["x"] = 2, ["meta"] = {["fields"] = {}, ["inventory"] = {}}, ["param2"] = 19, ["y"] = 7, ["param1"] = 190, ["z"] = 7, ["name"] = "rainbow:slab_wood_red_1"}, {["x"] = 2, ["meta"] = {["fields"] = {}, ["inventory"] = {}}, ["param2"] = 19, ["y"] = 7, ["param1"] = 190, ["z"] = 8, ["name"] = "rainbow:slab_wood_red_1"}, {["x"] = 2, ["meta"] = {["fields"] = {}, ["inventory"] = {}}, ["param2"] = 9, ["y"] = 7, ["param1"] = 189, ["z"] = 9, ["name"] = "rainbow:slope_tree_black"}, {["x"] = 2, ["meta"] = {["fields"] = {}, ["inventory"] = {}}, ["param2"] = 18, ["y"] = 7, ["param1"] = 221, ["z"] = 13, ["name"] = "rainbow:slope_tree_black"}, {["x"] = 2, ["meta"] = {["fields"] = {}, ["inventory"] = {}}, ["param2"] = 9, ["y"] = 8, ["param1"] = 222, ["z"] = 1, ["name"] = "rainbow:slope_tree_black"}, {["x"] = 2, ["meta"] = {["fields"] = {}, ["inventory"] = {}}, ["param2"] = 18, ["y"] = 8, ["param1"] = 189, ["z"] = 5, ["name"] = "rainbow:slope_tree_black"}, {["x"] = 2, ["meta"] = {["fields"] = {}, ["inventory"] = {}}, ["param2"] = 19, ["y"] = 8, ["param1"] = 174, ["z"] = 6, ["name"] = "rainbow:slab_wood_black_1"}, {["x"] = 2, ["meta"] = {["fields"] = {}, ["inventory"] = {}}, ["param2"] = 19, ["y"] = 8, ["param1"] = 190, ["z"] = 7, ["name"] = "rainbow:slab_wood_black_1"}, {["x"] = 2, ["meta"] = {["fields"] = {}, ["inventory"] = {}}, ["param2"] = 19, ["y"] = 8, ["param1"] = 174, ["z"] = 8, ["name"] = "rainbow:slab_wood_black_1"}, {["x"] = 2, ["meta"] = {["fields"] = {}, ["inventory"] = {}}, ["param2"] = 9, ["y"] = 8, ["param1"] = 189, ["z"] = 9, ["name"] = "rainbow:slope_tree_black"}, {["x"] = 2, ["meta"] = {["fields"] = {}, ["inventory"] = {}}, ["param2"] = 18, ["y"] = 8, ["param1"] = 221, ["z"] = 13, ["name"] = "rainbow:slope_tree_black"}, {["x"] = 2, ["meta"] = {["fields"] = {}, ["inventory"] = {}}, ["param2"] = 9, ["y"] = 9, ["param1"] = 222, ["z"] = 1, ["name"] = "rainbow:slope_tree_black"}, {["x"] = 2, ["meta"] = {["fields"] = {}, ["inventory"] = {}}, ["param2"] = 18, ["y"] = 9, ["param1"] = 189, ["z"] = 5, ["name"] = "rainbow:slope_tree_black"}, {["x"] = 2, ["meta"] = {["fields"] = {}, ["inventory"] = {}}, ["param2"] = 9, ["y"] = 9, ["param1"] = 189, ["z"] = 9, ["name"] = "rainbow:slope_tree_black"}, {["x"] = 2, ["meta"] = {["fields"] = {}, ["inventory"] = {}}, ["param2"] = 18, ["y"] = 9, ["param1"] = 221, ["z"] = 13, ["name"] = "rainbow:slope_tree_black"}, {["x"] = 2, ["meta"] = {["fields"] = {}, ["inventory"] = {}}, ["param2"] = 1, ["y"] = 10, ["param1"] = 206, ["z"] = 1, ["name"] = "rainbow:slope_fancybrick_red_inner_cut"}, {["x"] = 2, ["meta"] = {["fields"] = {}, ["inventory"] = {}}, ["param2"] = 2, ["y"] = 10, ["param1"] = 173, ["z"] = 5, ["name"] = "rainbow:slope_fancybrick_red_inner_cut"}, {["x"] = 2, ["meta"] = {["fields"] = {}, ["inventory"] = {}}, ["param2"] = 2, ["y"] = 10, ["param1"] = 190, ["z"] = 6, ["name"] = "rainbow:slope_fancybrick_red_outer_cut"}, {["x"] = 2, ["meta"] = {["fields"] = {}, ["inventory"] = {}}, ["param2"] = 1, ["y"] = 10, ["param1"] = 190, ["z"] = 8, ["name"] = "rainbow:slope_fancybrick_red_outer_cut"}, {["x"] = 2, ["meta"] = {["fields"] = {}, ["inventory"] = {}}, ["param2"] = 1, ["y"] = 10, ["param1"] = 173, ["z"] = 9, ["name"] = "rainbow:slope_fancybrick_red_inner_cut"}, {["x"] = 2, ["meta"] = {["fields"] = {}, ["inventory"] = {}}, ["param2"] = 2, ["y"] = 10, ["param1"] = 205, ["z"] = 13, ["name"] = "rainbow:slope_fancybrick_red_inner_cut"}, {["x"] = 2, ["meta"] = {["fields"] = {}, ["inventory"] = {}}, ["param2"] = 2, ["y"] = 10, ["param1"] = 190, ["z"] = 14, ["name"] = "rainbow:slope_fancybrick_red_outer_cut"}, {["x"] = 2, ["meta"] = {["fields"] = {}, ["inventory"] = {}}, ["param2"] = 1, ["y"] = 11, ["param1"] = 190, ["z"] = 1, ["name"] = "rainbow:slope_fancybrick_red_outer_cut"}, {["x"] = 2, ["meta"] = {["fields"] = {}, ["inventory"] = {}}, ["param2"] = 1, ["y"] = 11, ["param1"] = 205, ["z"] = 2, ["name"] = "rainbow:slope_fancybrick_red_inner_cut"}, {["x"] = 2, ["meta"] = {["fields"] = {}, ["inventory"] = {}}, ["param2"] = 2, ["y"] = 11, ["param1"] = 205, ["z"] = 4, ["name"] = "rainbow:slope_fancybrick_red_inner_cut"}, {["x"] = 2, ["meta"] = {["fields"] = {}, ["inventory"] = {}}, ["param2"] = 2, ["y"] = 11, ["param1"] = 190, ["z"] = 5, ["name"] = "rainbow:slope_fancybrick_red_outer_cut"}, {["x"] = 2, ["meta"] = {["fields"] = {}, ["inventory"] = {}}, ["param2"] = 1, ["y"] = 11, ["param1"] = 190, ["z"] = 9, ["name"] = "rainbow:slope_fancybrick_red_outer_cut"}, {["x"] = 2, ["meta"] = {["fields"] = {}, ["inventory"] = {}}, ["param2"] = 1, ["y"] = 11, ["param1"] = 205, ["z"] = 10, ["name"] = "rainbow:slope_fancybrick_red_inner_cut"}, {["x"] = 2, ["meta"] = {["fields"] = {}, ["inventory"] = {}}, ["param2"] = 2, ["y"] = 11, ["param1"] = 205, ["z"] = 12, ["name"] = "rainbow:slope_fancybrick_red_inner_cut"}, {["x"] = 2, ["meta"] = {["fields"] = {}, ["inventory"] = {}}, ["param2"] = 2, ["y"] = 11, ["param1"] = 190, ["z"] = 13, ["name"] = "rainbow:slope_fancybrick_red_outer_cut"}, {["x"] = 2, ["meta"] = {["fields"] = {}, ["inventory"] = {}}, ["param2"] = 1, ["y"] = 12, ["param1"] = 190, ["z"] = 2, ["name"] = "rainbow:slope_fancybrick_red_outer_cut"}, {["x"] = 2, ["meta"] = {["fields"] = {}, ["inventory"] = {}}, ["param2"] = 1, ["y"] = 12, ["param1"] = 206, ["z"] = 3, ["name"] = "rainbow:slope_fancybrick_red"}, {["x"] = 2, ["meta"] = {["fields"] = {}, ["inventory"] = {}}, ["param2"] = 2, ["y"] = 12, ["param1"] = 190, ["z"] = 4, ["name"] = "rainbow:slope_fancybrick_red_outer_cut"}, {["x"] = 2, ["meta"] = {["fields"] = {}, ["inventory"] = {}}, ["param2"] = 1, ["y"] = 12, ["param1"] = 190, ["z"] = 10, ["name"] = "rainbow:slope_fancybrick_red_outer_cut"}, {["x"] = 2, ["meta"] = {["fields"] = {}, ["inventory"] = {}}, ["param2"] = 1, ["y"] = 12, ["param1"] = 206, ["z"] = 11, ["name"] = "rainbow:slope_fancybrick_red"}, {["x"] = 2, ["meta"] = {["fields"] = {}, ["inventory"] = {}}, ["param2"] = 2, ["y"] = 12, ["param1"] = 190, ["z"] = 12, ["name"] = "rainbow:slope_fancybrick_red_outer_cut"}, {["x"] = 3, ["meta"] = {["fields"] = {}, ["inventory"] = {}}, ["y"] = 0, ["z"] = 2, ["name"] = "rainbow:dirt_black"}, {["x"] = 3, ["meta"] = {["fields"] = {}, ["inventory"] = {}}, ["y"] = 0, ["z"] = 3, ["name"] = "rainbow:dirt_black"}, {["x"] = 3, ["meta"] = {["fields"] = {}, ["inventory"] = {}}, ["y"] = 0, ["z"] = 4, ["name"] = "rainbow:dirt_black"}, {["x"] = 3, ["meta"] = {["fields"] = {}, ["inventory"] = {}}, ["y"] = 0, ["z"] = 5, ["name"] = "rainbow:dirt_black"}, {["x"] = 3, ["meta"] = {["fields"] = {}, ["inventory"] = {}}, ["y"] = 0, ["z"] = 6, ["name"] = "rainbow:stone_black"}, {["x"] = 3, ["meta"] = {["fields"] = {}, ["inventory"] = {}}, ["y"] = 0, ["z"] = 7, ["name"] = "rainbow:stone_black"}, {["x"] = 3, ["meta"] = {["fields"] = {}, ["inventory"] = {}}, ["y"] = 0, ["z"] = 8, ["name"] = "rainbow:stone_black"}, {["x"] = 3, ["meta"] = {["fields"] = {}, ["inventory"] = {}}, ["y"] = 0, ["z"] = 9, ["name"] = "rainbow:dirt_black"}, {["x"] = 3, ["meta"] = {["fields"] = {}, ["inventory"] = {}}, ["y"] = 0, ["z"] = 10, ["name"] = "rainbow:dirt_black"}, {["x"] = 3, ["meta"] = {["fields"] = {}, ["inventory"] = {}}, ["y"] = 0, ["z"] = 11, ["name"] = "rainbow:dirt_black"}, {["x"] = 3, ["meta"] = {["fields"] = {}, ["inventory"] = {}}, ["y"] = 0, ["z"] = 12, ["name"] = "rainbow:dirt_black"}, {["x"] = 3, ["meta"] = {["fields"] = {}, ["inventory"] = {}}, ["param2"] = 9, ["y"] = 1, ["param1"] = 221, ["z"] = 2, ["name"] = "rainbow:slope_tree_black"}, {["x"] = 3, ["meta"] = {["fields"] = {}, ["inventory"] = {}}, ["y"] = 1, ["param1"] = 238, ["z"] = 3, ["name"] = "rainbow:lightblock_gold"}, {["x"] = 3, ["meta"] = {["fields"] = {}, ["inventory"] = {}}, ["y"] = 1, ["z"] = 4, ["name"] = "rainbow:wood_black"}, {["x"] = 3, ["meta"] = {["fields"] = {}, ["inventory"] = {}}, ["y"] = 1, ["z"] = 5, ["name"] = "rainbow:wood_black"}, {["x"] = 3, ["meta"] = {["fields"] = {}, ["inventory"] = {}}, ["y"] = 1, ["z"] = 6, ["name"] = "rainbow:wood_black"}, {["x"] = 3, ["meta"] = {["fields"] = {}, ["inventory"] = {}}, ["y"] = 1, ["param1"] = 238, ["z"] = 7, ["name"] = "rainbow:lightblock_gold"}, {["x"] = 3, ["meta"] = {["fields"] = {}, ["inventory"] = {}}, ["y"] = 1, ["z"] = 8, ["name"] = "rainbow:wood_black"}, {["x"] = 3, ["meta"] = {["fields"] = {}, ["inventory"] = {}}, ["y"] = 1, ["z"] = 9, ["name"] = "rainbow:wood_black"}, {["x"] = 3, ["meta"] = {["fields"] = {}, ["inventory"] = {}}, ["y"] = 1, ["z"] = 10, ["name"] = "rainbow:wood_black"}, {["x"] = 3, ["meta"] = {["fields"] = {}, ["inventory"] = {}}, ["y"] = 1, ["param1"] = 238, ["z"] = 11, ["name"] = "rainbow:lightblock_gold"}, {["x"] = 3, ["meta"] = {["fields"] = {}, ["inventory"] = {}}, ["param2"] = 18, ["y"] = 1, ["param1"] = 221, ["z"] = 12, ["name"] = "rainbow:slope_tree_black"}, {["x"] = 3, ["meta"] = {["fields"] = {}, ["inventory"] = {}}, ["param2"] = 9, ["y"] = 2, ["param1"] = 205, ["z"] = 2, ["name"] = "rainbow:slope_tree_black"}, {["x"] = 3, ["meta"] = {["fields"] = {}, ["inventory"] = {}}, ["param2"] = 18, ["y"] = 2, ["param1"] = 204, ["z"] = 12, ["name"] = "rainbow:slope_tree_black"}, {["x"] = 3, ["meta"] = {["fields"] = {}, ["inventory"] = {}}, ["param2"] = 9, ["y"] = 3, ["param1"] = 189, ["z"] = 2, ["name"] = "rainbow:slope_tree_black"}, {["x"] = 3, ["meta"] = {["fields"] = {}, ["inventory"] = {}}, ["param2"] = 18, ["y"] = 3, ["param1"] = 188, ["z"] = 12, ["name"] = "rainbow:slope_tree_black"}, {["x"] = 3, ["meta"] = {["fields"] = {}, ["inventory"] = {}}, ["param2"] = 9, ["y"] = 4, ["param1"] = 173, ["z"] = 2, ["name"] = "rainbow:slope_tree_black"}, {["x"] = 3, ["meta"] = {["fields"] = {}, ["inventory"] = {}}, ["param2"] = 18, ["y"] = 4, ["param1"] = 172, ["z"] = 12, ["name"] = "rainbow:slope_tree_black"}, {["x"] = 3, ["meta"] = {["fields"] = {}, ["inventory"] = {}}, ["param2"] = 20, ["y"] = 5, ["param1"] = 206, ["z"] = 1, ["name"] = "rainbow:slab_wood_red_1"}, {["x"] = 3, ["meta"] = {["fields"] = {}, ["inventory"] = {}}, ["param2"] = 9, ["y"] = 5, ["param1"] = 189, ["z"] = 2, ["name"] = "rainbow:slope_tree_black"}, {["x"] = 3, ["meta"] = {["fields"] = {}, ["inventory"] = {}}, ["param2"] = 22, ["y"] = 5, ["param1"] = 187, ["z"] = 4, ["name"] = "rainbow:slab_wood_black_1"}, {["x"] = 3, ["meta"] = {["fields"] = {}, ["inventory"] = {}}, ["param2"] = 20, ["y"] = 5, ["param1"] = 204, ["z"] = 5, ["name"] = "rainbow:slab_wood_black_1"}, {["x"] = 3, ["meta"] = {["fields"] = {}, ["inventory"] = {}}, ["param2"] = 22, ["y"] = 5, ["param1"] = 221, ["z"] = 6, ["name"] = "rainbow:slab_wood_black_1"}, {["x"] = 3, ["meta"] = {["fields"] = {}, ["inventory"] = {}}, ["param2"] = 21, ["y"] = 5, ["param1"] = 238, ["z"] = 7, ["name"] = "rainbow:slab_lightcoolglass_yellow_1"}, {["x"] = 3, ["meta"] = {["fields"] = {}, ["inventory"] = {}}, ["param2"] = 22, ["y"] = 5, ["param1"] = 221, ["z"] = 8, ["name"] = "rainbow:slab_wood_black_1"}, {["x"] = 3, ["meta"] = {["fields"] = {}, ["inventory"] = {}}, ["param2"] = 22, ["y"] = 5, ["param1"] = 204, ["z"] = 9, ["name"] = "rainbow:slab_wood_black_1"}, {["x"] = 3, ["meta"] = {["fields"] = {}, ["inventory"] = {}}, ["param2"] = 22, ["y"] = 5, ["param1"] = 187, ["z"] = 10, ["name"] = "rainbow:slab_wood_black_1"}, {["x"] = 3, ["meta"] = {["fields"] = {}, ["inventory"] = {}}, ["param2"] = 18, ["y"] = 5, ["param1"] = 188, ["z"] = 12, ["name"] = "rainbow:slope_tree_black"}, {["x"] = 3, ["meta"] = {["fields"] = {}, ["inventory"] = {}}, ["param2"] = 20, ["y"] = 5, ["param1"] = 205, ["z"] = 13, ["name"] = "rainbow:slab_wood_red_1"}, {["x"] = 3, ["meta"] = {["fields"] = {}, ["inventory"] = {}}, ["y"] = 6, ["param1"] = 205, ["z"] = 2, ["name"] = "rainbow:slab_wood_red_1"}, {["x"] = 3, ["meta"] = {["fields"] = {}, ["inventory"] = {}}, ["y"] = 6, ["param1"] = 188, ["z"] = 3, ["name"] = "rainbow:slab_wood_red_1"}, {["x"] = 3, ["meta"] = {["fields"] = {}, ["inventory"] = {}}, ["y"] = 6, ["param1"] = 187, ["z"] = 11, ["name"] = "rainbow:slab_wood_red_1"}, {["x"] = 3, ["meta"] = {["fields"] = {}, ["inventory"] = {}}, ["y"] = 6, ["param1"] = 204, ["z"] = 12, ["name"] = "rainbow:slab_wood_red_1"}, {["x"] = 3, ["meta"] = {["fields"] = {}, ["inventory"] = {}}, ["param2"] = 7, ["y"] = 6, ["param1"] = 206, ["z"] = 14, ["name"] = "rainbow:slab_tree_black_1"}, {["x"] = 3, ["meta"] = {["fields"] = {}, ["inventory"] = {}}, ["param2"] = 7, ["y"] = 7, ["param1"] = 238, ["z"] = 1, ["name"] = "rainbow:slab_lightglass_red_1"}, {["x"] = 3, ["meta"] = {["fields"] = {}, ["inventory"] = {}}, ["param2"] = 9, ["y"] = 7, ["param1"] = 238, ["z"] = 13, ["name"] = "rainbow:slab_lightglass_red_1"}, {["x"] = 3, ["meta"] = {["fields"] = {}, ["inventory"] = {}}, ["param2"] = 7, ["y"] = 8, ["param1"] = 238, ["z"] = 1, ["name"] = "rainbow:slab_lightglass_red_1"}, {["x"] = 3, ["meta"] = {["fields"] = {}, ["inventory"] = {}}, ["param2"] = 20, ["y"] = 8, ["param1"] = 189, ["z"] = 6, ["name"] = "rainbow:slab_wood_black_1"}, {["x"] = 3, ["meta"] = {["fields"] = {}, ["inventory"] = {}}, ["param2"] = 20, ["y"] = 8, ["param1"] = 206, ["z"] = 7, ["name"] = "rainbow:slab_wood_black_1"}, {["x"] = 3, ["meta"] = {["fields"] = {}, ["inventory"] = {}}, ["param2"] = 20, ["y"] = 8, ["param1"] = 189, ["z"] = 8, ["name"] = "rainbow:slab_wood_black_1"}, {["x"] = 3, ["meta"] = {["fields"] = {}, ["inventory"] = {}}, ["param2"] = 9, ["y"] = 8, ["param1"] = 238, ["z"] = 13, ["name"] = "rainbow:slab_lightglass_red_1"}, {["x"] = 3, ["meta"] = {["fields"] = {}, ["inventory"] = {}}, ["param2"] = 7, ["y"] = 9, ["param1"] = 238, ["z"] = 1, ["name"] = "rainbow:slab_lightglass_red_1"}, {["x"] = 3, ["meta"] = {["fields"] = {}, ["inventory"] = {}}, ["param2"] = 7, ["y"] = 9, ["param1"] = 206, ["z"] = 6, ["name"] = "rainbow:slab_tree_black_1"}, {["x"] = 3, ["meta"] = {["fields"] = {}, ["inventory"] = {}}, ["param2"] = 9, ["y"] = 9, ["param1"] = 206, ["z"] = 8, ["name"] = "rainbow:slab_tree_black_1"}, {["x"] = 3, ["meta"] = {["fields"] = {}, ["inventory"] = {}}, ["param2"] = 9, ["y"] = 9, ["param1"] = 238, ["z"] = 13, ["name"] = "rainbow:slab_lightglass_red_1"}, {["x"] = 3, ["meta"] = {["fields"] = {}, ["inventory"] = {}}, ["param2"] = 2, ["y"] = 10, ["param1"] = 206, ["z"] = 6, ["name"] = "rainbow:slope_fancybrick_red"}, {["x"] = 3, ["meta"] = {["fields"] = {}, ["inventory"] = {}}, ["y"] = 10, ["param1"] = 206, ["z"] = 8, ["name"] = "rainbow:slope_fancybrick_red"}, {["x"] = 3, ["meta"] = {["fields"] = {}, ["inventory"] = {}}, ["param2"] = 2, ["y"] = 10, ["param1"] = 206, ["z"] = 14, ["name"] = "rainbow:slope_fancybrick_red"}, {["x"] = 3, ["meta"] = {["fields"] = {}, ["inventory"] = {}}, ["y"] = 11, ["param1"] = 206, ["z"] = 1, ["name"] = "rainbow:slope_fancybrick_red"}, {["x"] = 3, ["meta"] = {["fields"] = {}, ["inventory"] = {}}, ["param2"] = 22, ["y"] = 11, ["param1"] = 238, ["z"] = 3, ["name"] = "rainbow:slab_lightcoolglass_yellow_1"}, {["x"] = 3, ["meta"] = {["fields"] = {}, ["inventory"] = {}}, ["param2"] = 2, ["y"] = 11, ["param1"] = 206, ["z"] = 5, ["name"] = "rainbow:slope_fancybrick_red"}, {["x"] = 3, ["meta"] = {["fields"] = {}, ["inventory"] = {}}, ["y"] = 11, ["param1"] = 206, ["z"] = 9, ["name"] = "rainbow:slope_fancybrick_red"}, {["x"] = 3, ["meta"] = {["fields"] = {}, ["inventory"] = {}}, ["param2"] = 21, ["y"] = 11, ["param1"] = 238, ["z"] = 11, ["name"] = "rainbow:slab_lightcoolglass_yellow_1"}, {["x"] = 3, ["meta"] = {["fields"] = {}, ["inventory"] = {}}, ["param2"] = 2, ["y"] = 11, ["param1"] = 206, ["z"] = 13, ["name"] = "rainbow:slope_fancybrick_red"}, {["x"] = 3, ["meta"] = {["fields"] = {}, ["inventory"] = {}}, ["y"] = 12, ["param1"] = 206, ["z"] = 2, ["name"] = "rainbow:slope_fancybrick_red"}, {["x"] = 3, ["meta"] = {["fields"] = {["banner"] = "(bg_white.png^[mask:mask_background.png^[makealpha:0,0,0)^(bg_white.png^[mask:fullpentagram.png^[makealpha:0,0,0)^(bg_white.png^[mask:fullpentagram.png^[makealpha:0,0,0)^(bg_white.png^[mask:mask_background.png^[makealpha:0,0,0)^(bg_white.png^[mask:mask_background.png^[makealpha:0,0,0)^(bg_violet.png^[mask:chevron_top.png^[makealpha:0,0,0)^(bg_violet.png^[mask:chevron_top.png^[makealpha:0,0,0)^(bg_violet.png^[mask:chevron_top.png^[makealpha:0,0,0)^(bg_violet.png^[mask:chevron_top.png^[makealpha:0,0,0)^(bg_violet.png^[mask:fullpentagram.png^[makealpha:0,0,0)^(bg_violet.png^[mask:chevron_bottom.png^[makealpha:0,0,0)^(bg_white.png^[mask:mask_background.png^[makealpha:0,0,0)^(bg_white.png^[mask:mask_background.png^[makealpha:0,0,0)^(bg_white.png^[mask:mask_background.png^[makealpha:0,0,0)^(bg_white.png^[mask:mask_background.png^[makealpha:0,0,0)^(bg_white.png^[mask:mask_background.png^[makealpha:0,0,0)^(bg_white.png^[mask:chevron_top.png^[makealpha:0,0,0)^(bg_white.png^[mask:chevron_top.png^[makealpha:0,0,0)^(bg_white.png^[mask:chevron_top.png^[makealpha:0,0,0)^(bg_white.png^[mask:chevron_top.png^[makealpha:0,0,0)^(bg_white.png^[mask:chevron_top.png^[makealpha:0,0,0)^(bg_cyan.png^[mask:chevron_top.png^[makealpha:0,0,0)^(bg_cyan.png^[mask:hilal.png^[makealpha:0,0,0)^(bg_cyan.png^[mask:chevron_bottom.png^[makealpha:0,0,0)^(bg_white.png^[mask:mask_background.png^[makealpha:0,0,0)^(bg_white.png^[mask:mask_background.png^[makealpha:0,0,0)^(bg_white.png^[mask:mask_background.png^[makealpha:0,0,0)^(bg_black.png^[mask:mask_background.png^[makealpha:0,0,0)^(bg_red.png^[mask:stripes_horiz_4.png^[makealpha:0,0,0)^(bg_yellow.png^[mask:fleur_de_lis.png^[makealpha:0,0,0)^(bg_yellow.png^[mask:fleur_de_lis.png^[makealpha:0,0,0)^(bg_white.png^[mask:mask_background.png^[makealpha:0,0,0)^(bg_black.png^[mask:stripes_horiz_4.png^[makealpha:0,0,0)^(bg_red.png^[mask:mask_background.png^[makealpha:0,0,0)^(bg_black.png^[mask:mask_background.png^[makealpha:0,0,0)^(bg_red.png^[mask:stripes_horiz_4.png^[makealpha:0,0,0)^(bg_red.png^[mask:fleur_de_lis.png^[makealpha:0,0,0)^(bg_yellow.png^[mask:fleur_de_lis.png^[makealpha:0,0,0)"}, ["inventory"] = {}}, ["param2"] = 1, ["y"] = 12, ["param1"] = 222, ["z"] = 3, ["name"] = "banners:wooden_banner"}, {["x"] = 3, ["meta"] = {["fields"] = {}, ["inventory"] = {}}, ["param2"] = 2, ["y"] = 12, ["param1"] = 206, ["z"] = 4, ["name"] = "rainbow:slope_fancybrick_red"}, {["x"] = 3, ["meta"] = {["fields"] = {}, ["inventory"] = {}}, ["y"] = 12, ["param1"] = 206, ["z"] = 10, ["name"] = "rainbow:slope_fancybrick_red"}, {["x"] = 3, ["meta"] = {["fields"] = {["banner"] = "(bg_white.png^[mask:mask_background.png^[makealpha:0,0,0)^(bg_white.png^[mask:fullpentagram.png^[makealpha:0,0,0)^(bg_white.png^[mask:fullpentagram.png^[makealpha:0,0,0)^(bg_white.png^[mask:mask_background.png^[makealpha:0,0,0)^(bg_white.png^[mask:mask_background.png^[makealpha:0,0,0)^(bg_violet.png^[mask:chevron_top.png^[makealpha:0,0,0)^(bg_violet.png^[mask:chevron_top.png^[makealpha:0,0,0)^(bg_violet.png^[mask:chevron_top.png^[makealpha:0,0,0)^(bg_violet.png^[mask:chevron_top.png^[makealpha:0,0,0)^(bg_violet.png^[mask:fullpentagram.png^[makealpha:0,0,0)^(bg_violet.png^[mask:chevron_bottom.png^[makealpha:0,0,0)^(bg_white.png^[mask:mask_background.png^[makealpha:0,0,0)^(bg_white.png^[mask:mask_background.png^[makealpha:0,0,0)^(bg_white.png^[mask:mask_background.png^[makealpha:0,0,0)^(bg_white.png^[mask:mask_background.png^[makealpha:0,0,0)^(bg_white.png^[mask:mask_background.png^[makealpha:0,0,0)^(bg_white.png^[mask:chevron_top.png^[makealpha:0,0,0)^(bg_white.png^[mask:chevron_top.png^[makealpha:0,0,0)^(bg_white.png^[mask:chevron_top.png^[makealpha:0,0,0)^(bg_white.png^[mask:chevron_top.png^[makealpha:0,0,0)^(bg_white.png^[mask:chevron_top.png^[makealpha:0,0,0)^(bg_cyan.png^[mask:chevron_top.png^[makealpha:0,0,0)^(bg_cyan.png^[mask:hilal.png^[makealpha:0,0,0)^(bg_cyan.png^[mask:chevron_bottom.png^[makealpha:0,0,0)^(bg_white.png^[mask:mask_background.png^[makealpha:0,0,0)^(bg_white.png^[mask:mask_background.png^[makealpha:0,0,0)^(bg_white.png^[mask:mask_background.png^[makealpha:0,0,0)^(bg_black.png^[mask:mask_background.png^[makealpha:0,0,0)^(bg_red.png^[mask:stripes_horiz_4.png^[makealpha:0,0,0)^(bg_yellow.png^[mask:fleur_de_lis.png^[makealpha:0,0,0)^(bg_yellow.png^[mask:fleur_de_lis.png^[makealpha:0,0,0)^(bg_white.png^[mask:mask_background.png^[makealpha:0,0,0)^(bg_black.png^[mask:stripes_horiz_4.png^[makealpha:0,0,0)^(bg_red.png^[mask:mask_background.png^[makealpha:0,0,0)^(bg_black.png^[mask:mask_background.png^[makealpha:0,0,0)^(bg_red.png^[mask:stripes_horiz_4.png^[makealpha:0,0,0)^(bg_red.png^[mask:fleur_de_lis.png^[makealpha:0,0,0)^(bg_yellow.png^[mask:fleur_de_lis.png^[makealpha:0,0,0)"}, ["inventory"] = {}}, ["param2"] = 2, ["y"] = 12, ["param1"] = 222, ["z"] = 11, ["name"] = "banners:wooden_banner"}, {["x"] = 3, ["meta"] = {["fields"] = {}, ["inventory"] = {}}, ["param2"] = 2, ["y"] = 12, ["param1"] = 206, ["z"] = 12, ["name"] = "rainbow:slope_fancybrick_red"}, {["x"] = 4, ["meta"] = {["fields"] = {}, ["inventory"] = {}}, ["y"] = 0, ["z"] = 2, ["name"] = "rainbow:dirt_black"}, {["x"] = 4, ["meta"] = {["fields"] = {}, ["inventory"] = {}}, ["y"] = 0, ["z"] = 3, ["name"] = "rainbow:dirt_black"}, {["x"] = 4, ["meta"] = {["fields"] = {}, ["inventory"] = {}}, ["y"] = 0, ["z"] = 4, ["name"] = "rainbow:stone_black"}, {["x"] = 4, ["meta"] = {["fields"] = {}, ["inventory"] = {}}, ["y"] = 0, ["z"] = 5, ["name"] = "rainbow:stone_black"}, {["x"] = 4, ["meta"] = {["fields"] = {}, ["inventory"] = {}}, ["y"] = 0, ["z"] = 6, ["name"] = "rainbow:stone_black"}, {["x"] = 4, ["meta"] = {["fields"] = {}, ["inventory"] = {}}, ["y"] = 0, ["z"] = 7, ["name"] = "rainbow:stone_black"}, {["x"] = 4, ["meta"] = {["fields"] = {}, ["inventory"] = {}}, ["y"] = 0, ["z"] = 8, ["name"] = "rainbow:stone_black"}, {["x"] = 4, ["meta"] = {["fields"] = {}, ["inventory"] = {}}, ["y"] = 0, ["z"] = 9, ["name"] = "rainbow:stone_black"}, {["x"] = 4, ["meta"] = {["fields"] = {}, ["inventory"] = {}}, ["y"] = 0, ["z"] = 10, ["name"] = "rainbow:dirt_black"}, {["x"] = 4, ["meta"] = {["fields"] = {}, ["inventory"] = {}}, ["y"] = 0, ["z"] = 11, ["name"] = "rainbow:dirt_black"}, {["x"] = 4, ["meta"] = {["fields"] = {}, ["inventory"] = {}}, ["y"] = 0, ["z"] = 12, ["name"] = "rainbow:dirt_black"}, {["x"] = 4, ["meta"] = {["fields"] = {}, ["inventory"] = {}}, ["param2"] = 10, ["y"] = 1, ["param1"] = 190, ["z"] = 1, ["name"] = "rainbow:slab_stone_black_1"}, {["x"] = 4, ["meta"] = {["fields"] = {}, ["inventory"] = {}}, ["param2"] = 18, ["y"] = 1, ["z"] = 2, ["name"] = "rainbow:tree_black"}, {["x"] = 4, ["meta"] = {["fields"] = {}, ["inventory"] = {}}, ["y"] = 1, ["z"] = 3, ["name"] = "rainbow:wood_black"}, {["x"] = 4, ["meta"] = {["fields"] = {}, ["inventory"] = {}}, ["y"] = 1, ["z"] = 4, ["name"] = "rainbow:wood_red"}, {["x"] = 4, ["meta"] = {["fields"] = {}, ["inventory"] = {}}, ["y"] = 1, ["z"] = 5, ["name"] = "rainbow:wood_red"}, {["x"] = 4, ["meta"] = {["fields"] = {}, ["inventory"] = {}}, ["y"] = 1, ["z"] = 6, ["name"] = "rainbow:wood_red"}, {["x"] = 4, ["meta"] = {["fields"] = {}, ["inventory"] = {}}, ["y"] = 1, ["z"] = 7, ["name"] = "rainbow:wood_red"}, {["x"] = 4, ["meta"] = {["fields"] = {}, ["inventory"] = {}}, ["y"] = 1, ["z"] = 8, ["name"] = "rainbow:wood_red"}, {["x"] = 4, ["meta"] = {["fields"] = {}, ["inventory"] = {}}, ["y"] = 1, ["z"] = 9, ["name"] = "rainbow:wood_red"}, {["x"] = 4, ["meta"] = {["fields"] = {}, ["inventory"] = {}}, ["y"] = 1, ["z"] = 10, ["name"] = "rainbow:wood_red"}, {["x"] = 4, ["meta"] = {["fields"] = {}, ["inventory"] = {}}, ["y"] = 1, ["z"] = 11, ["name"] = "rainbow:wood_black"}, {["x"] = 4, ["meta"] = {["fields"] = {}, ["inventory"] = {}}, ["param2"] = 18, ["y"] = 1, ["z"] = 12, ["name"] = "rainbow:tree_black"}, {["x"] = 4, ["meta"] = {["fields"] = {}, ["inventory"] = {}}, ["param2"] = 4, ["y"] = 1, ["param1"] = 189, ["z"] = 13, ["name"] = "rainbow:slab_stone_black_1"}, {["x"] = 4, ["meta"] = {["fields"] = {}, ["inventory"] = {}}, ["param2"] = 10, ["y"] = 2, ["param1"] = 206, ["z"] = 1, ["name"] = "rainbow:slab_stone_black_1"}, {["x"] = 4, ["meta"] = {["fields"] = {}, ["inventory"] = {}}, ["param2"] = 4, ["y"] = 2, ["param1"] = 205, ["z"] = 13, ["name"] = "rainbow:slab_stone_black_1"}, {["x"] = 4, ["meta"] = {["fields"] = {}, ["inventory"] = {}}, ["param2"] = 10, ["y"] = 3, ["param1"] = 222, ["z"] = 1, ["name"] = "rainbow:slab_wood_black_1"}, {["x"] = 4, ["meta"] = {["fields"] = {}, ["inventory"] = {}}, ["param2"] = 4, ["y"] = 3, ["param1"] = 221, ["z"] = 13, ["name"] = "rainbow:slab_wood_black_1"}, {["x"] = 4, ["meta"] = {["fields"] = {}, ["inventory"] = {}}, ["param2"] = 10, ["y"] = 4, ["param1"] = 206, ["z"] = 1, ["name"] = "rainbow:slab_wood_black_1"}, {["x"] = 4, ["meta"] = {["fields"] = {}, ["inventory"] = {}}, ["param2"] = 4, ["y"] = 4, ["param1"] = 205, ["z"] = 13, ["name"] = "rainbow:slab_wood_black_1"}, {["x"] = 4, ["meta"] = {["fields"] = {}, ["inventory"] = {}}, ["param2"] = 10, ["y"] = 5, ["param1"] = 190, ["z"] = 1, ["name"] = "rainbow:slab_stone_black_1"}, {["x"] = 4, ["meta"] = {["fields"] = {}, ["inventory"] = {}}, ["param2"] = 22, ["y"] = 5, ["param1"] = 204, ["z"] = 3, ["name"] = "rainbow:slab_wood_black_1"}, {["x"] = 4, ["meta"] = {["fields"] = {}, ["inventory"] = {}}, ["param2"] = 22, ["y"] = 5, ["param1"] = 187, ["z"] = 4, ["name"] = "rainbow:slab_wood_red_1"}, {["x"] = 4, ["meta"] = {["fields"] = {}, ["inventory"] = {}}, ["param2"] = 22, ["y"] = 5, ["param1"] = 187, ["z"] = 5, ["name"] = "rainbow:slab_wood_red_1"}, {["x"] = 4, ["meta"] = {["fields"] = {}, ["inventory"] = {}}, ["param2"] = 22, ["y"] = 5, ["param1"] = 204, ["z"] = 6, ["name"] = "rainbow:slab_wood_red_1"}, {["x"] = 4, ["meta"] = {["fields"] = {}, ["inventory"] = {}}, ["param2"] = 22, ["y"] = 5, ["param1"] = 221, ["z"] = 7, ["name"] = "rainbow:slab_wood_red_1"}, {["x"] = 4, ["meta"] = {["fields"] = {}, ["inventory"] = {}}, ["param2"] = 22, ["y"] = 5, ["param1"] = 204, ["z"] = 8, ["name"] = "rainbow:slab_wood_red_1"}, {["x"] = 4, ["meta"] = {["fields"] = {}, ["inventory"] = {}}, ["param2"] = 22, ["y"] = 5, ["param1"] = 187, ["z"] = 9, ["name"] = "rainbow:slab_wood_red_1"}, {["x"] = 4, ["meta"] = {["fields"] = {}, ["inventory"] = {}}, ["param2"] = 20, ["y"] = 5, ["param1"] = 187, ["z"] = 10, ["name"] = "rainbow:slab_wood_red_1"}, {["x"] = 4, ["meta"] = {["fields"] = {}, ["inventory"] = {}}, ["param2"] = 20, ["y"] = 5, ["param1"] = 204, ["z"] = 11, ["name"] = "rainbow:slab_wood_black_1"}, {["x"] = 4, ["meta"] = {["fields"] = {}, ["inventory"] = {}}, ["param2"] = 4, ["y"] = 5, ["param1"] = 189, ["z"] = 13, ["name"] = "rainbow:slab_stone_black_1"}, {["x"] = 4, ["meta"] = {["fields"] = {}, ["inventory"] = {}}, ["param2"] = 12, ["y"] = 6, ["param1"] = 206, ["z"] = 1, ["name"] = "rainbow:slope_tree_black"}, {["x"] = 4, ["meta"] = {["fields"] = {}, ["inventory"] = {}}, ["y"] = 6, ["param1"] = 189, ["z"] = 2, ["name"] = "rainbow:slab_wood_red_1"}, {["x"] = 4, ["meta"] = {["fields"] = {}, ["inventory"] = {}}, ["y"] = 6, ["param1"] = 188, ["z"] = 12, ["name"] = "rainbow:slab_wood_red_1"}, {["x"] = 4, ["meta"] = {["fields"] = {}, ["inventory"] = {}}, ["param2"] = 7, ["y"] = 6, ["param1"] = 205, ["z"] = 13, ["name"] = "rainbow:slope_tree_black"}, {["x"] = 4, ["meta"] = {["fields"] = {}, ["inventory"] = {}}, ["param2"] = 12, ["y"] = 7, ["param1"] = 222, ["z"] = 1, ["name"] = "rainbow:slope_tree_black"}, {["x"] = 4, ["meta"] = {["fields"] = {}, ["inventory"] = {}}, ["param2"] = 7, ["y"] = 7, ["param1"] = 221, ["z"] = 13, ["name"] = "rainbow:slope_tree_black"}, {["x"] = 4, ["meta"] = {["fields"] = {}, ["inventory"] = {}}, ["param2"] = 12, ["y"] = 8, ["param1"] = 222, ["z"] = 1, ["name"] = "rainbow:slope_tree_black"}, {["x"] = 4, ["meta"] = {["fields"] = {}, ["inventory"] = {}}, ["param2"] = 22, ["y"] = 8, ["param1"] = 187, ["z"] = 5, ["name"] = "rainbow:slab_wood_black_1"}, {["x"] = 4, ["meta"] = {["fields"] = {}, ["inventory"] = {}}, ["param2"] = 20, ["y"] = 8, ["param1"] = 204, ["z"] = 6, ["name"] = "rainbow:slab_wood_black_1"}, {["x"] = 4, ["meta"] = {["fields"] = {}, ["inventory"] = {}}, ["param2"] = 20, ["y"] = 8, ["param1"] = 221, ["z"] = 7, ["name"] = "rainbow:slab_wood_black_1"}, {["x"] = 4, ["meta"] = {["fields"] = {}, ["inventory"] = {}}, ["param2"] = 20, ["y"] = 8, ["param1"] = 204, ["z"] = 8, ["name"] = "rainbow:slab_wood_black_1"}, {["x"] = 4, ["meta"] = {["fields"] = {}, ["inventory"] = {}}, ["param2"] = 20, ["y"] = 8, ["param1"] = 187, ["z"] = 9, ["name"] = "rainbow:slab_wood_black_1"}, {["x"] = 4, ["meta"] = {["fields"] = {}, ["inventory"] = {}}, ["param2"] = 7, ["y"] = 8, ["param1"] = 221, ["z"] = 13, ["name"] = "rainbow:slope_tree_black"}, {["x"] = 4, ["meta"] = {["fields"] = {}, ["inventory"] = {}}, ["param2"] = 12, ["y"] = 9, ["param1"] = 222, ["z"] = 1, ["name"] = "rainbow:slope_tree_black"}, {["x"] = 4, ["meta"] = {["fields"] = {}, ["inventory"] = {}}, ["param2"] = 7, ["y"] = 9, ["param1"] = 204, ["z"] = 5, ["name"] = "rainbow:slope_tree_black"}, {["x"] = 4, ["meta"] = {["fields"] = {}, ["inventory"] = {}}, ["param2"] = 19, ["y"] = 9, ["param1"] = 206, ["z"] = 7, ["name"] = "rainbow:slab_wood_red_1"}, {["x"] = 4, ["meta"] = {["fields"] = {}, ["inventory"] = {}}, ["param2"] = 12, ["y"] = 9, ["param1"] = 204, ["z"] = 9, ["name"] = "rainbow:slope_tree_black"}, {["x"] = 4, ["meta"] = {["fields"] = {}, ["inventory"] = {}}, ["param2"] = 7, ["y"] = 9, ["param1"] = 221, ["z"] = 13, ["name"] = "rainbow:slope_tree_black"}, {["x"] = 4, ["meta"] = {["fields"] = {}, ["inventory"] = {}}, ["y"] = 10, ["param1"] = 206, ["z"] = 1, ["name"] = "rainbow:slope_fancybrick_red_inner_cut"}, {["x"] = 4, ["meta"] = {["fields"] = {}, ["inventory"] = {}}, ["param2"] = 3, ["y"] = 10, ["param1"] = 205, ["z"] = 5, ["name"] = "rainbow:slope_fancybrick_red_inner_cut"}, {["x"] = 4, ["meta"] = {["fields"] = {}, ["inventory"] = {}}, ["param2"] = 3, ["y"] = 10, ["param1"] = 221, ["z"] = 6, ["name"] = "rainbow:slope_fancybrick_red_outer_cut"}, {["x"] = 4, ["meta"] = {["fields"] = {}, ["inventory"] = {}}, ["param2"] = 19, ["y"] = 10, ["param1"] = 206, ["z"] = 7, ["name"] = "rainbow:slab_wood_black_1"}, {["x"] = 4, ["meta"] = {["fields"] = {}, ["inventory"] = {}}, ["y"] = 10, ["param1"] = 221, ["z"] = 8, ["name"] = "rainbow:slope_fancybrick_red_outer_cut"}, {["x"] = 4, ["meta"] = {["fields"] = {}, ["inventory"] = {}}, ["y"] = 10, ["param1"] = 205, ["z"] = 9, ["name"] = "rainbow:slope_fancybrick_red_inner_cut"}, {["x"] = 4, ["meta"] = {["fields"] = {}, ["inventory"] = {}}, ["param2"] = 3, ["y"] = 10, ["param1"] = 205, ["z"] = 13, ["name"] = "rainbow:slope_fancybrick_red_inner_cut"}, {["x"] = 4, ["meta"] = {["fields"] = {}, ["inventory"] = {}}, ["param2"] = 3, ["y"] = 10, ["param1"] = 190, ["z"] = 14, ["name"] = "rainbow:slope_fancybrick_red_outer_cut"}, {["x"] = 4, ["meta"] = {["fields"] = {}, ["inventory"] = {}}, ["y"] = 11, ["param1"] = 190, ["z"] = 1, ["name"] = "rainbow:slope_fancybrick_red_outer_cut"}, {["x"] = 4, ["meta"] = {["fields"] = {}, ["inventory"] = {}}, ["y"] = 11, ["param1"] = 205, ["z"] = 2, ["name"] = "rainbow:slope_fancybrick_red_inner_cut"}, {["x"] = 4, ["meta"] = {["fields"] = {}, ["inventory"] = {}}, ["param2"] = 3, ["y"] = 11, ["param1"] = 205, ["z"] = 4, ["name"] = "rainbow:slope_fancybrick_red_inner_cut"}, {["x"] = 4, ["meta"] = {["fields"] = {}, ["inventory"] = {}}, ["param2"] = 3, ["y"] = 11, ["param1"] = 206, ["z"] = 5, ["name"] = "rainbow:slope_fancybrick_red_outer_cut"}, {["x"] = 4, ["meta"] = {["fields"] = {}, ["inventory"] = {}}, ["param2"] = 19, ["y"] = 11, ["param1"] = 206, ["z"] = 7, ["name"] = "rainbow:slab_wood_red_1"}, {["x"] = 4, ["meta"] = {["fields"] = {}, ["inventory"] = {}}, ["y"] = 11, ["param1"] = 206, ["z"] = 9, ["name"] = "rainbow:slope_fancybrick_red_outer_cut"}, {["x"] = 4, ["meta"] = {["fields"] = {}, ["inventory"] = {}}, ["y"] = 11, ["param1"] = 205, ["z"] = 10, ["name"] = "rainbow:slope_fancybrick_red_inner_cut"}, {["x"] = 4, ["meta"] = {["fields"] = {}, ["inventory"] = {}}, ["param2"] = 3, ["y"] = 11, ["param1"] = 205, ["z"] = 12, ["name"] = "rainbow:slope_fancybrick_red_inner_cut"}, {["x"] = 4, ["meta"] = {["fields"] = {}, ["inventory"] = {}}, ["param2"] = 3, ["y"] = 11, ["param1"] = 190, ["z"] = 13, ["name"] = "rainbow:slope_fancybrick_red_outer_cut"}, {["x"] = 4, ["meta"] = {["fields"] = {}, ["inventory"] = {}}, ["y"] = 12, ["param1"] = 190, ["z"] = 2, ["name"] = "rainbow:slope_fancybrick_red_outer_cut"}, {["x"] = 4, ["meta"] = {["fields"] = {}, ["inventory"] = {}}, ["param2"] = 3, ["y"] = 12, ["param1"] = 206, ["z"] = 3, ["name"] = "rainbow:slope_fancybrick_red"}, {["x"] = 4, ["meta"] = {["fields"] = {}, ["inventory"] = {}}, ["param2"] = 3, ["y"] = 12, ["param1"] = 190, ["z"] = 4, ["name"] = "rainbow:slope_fancybrick_red_outer_cut"}, {["x"] = 4, ["meta"] = {["fields"] = {}, ["inventory"] = {}}, ["param2"] = 19, ["y"] = 12, ["param1"] = 206, ["z"] = 7, ["name"] = "rainbow:slab_wood_black_1"}, {["x"] = 4, ["meta"] = {["fields"] = {}, ["inventory"] = {}}, ["y"] = 12, ["param1"] = 190, ["z"] = 10, ["name"] = "rainbow:slope_fancybrick_red_outer_cut"}, {["x"] = 4, ["meta"] = {["fields"] = {}, ["inventory"] = {}}, ["param2"] = 3, ["y"] = 12, ["param1"] = 206, ["z"] = 11, ["name"] = "rainbow:slope_fancybrick_red"}, {["x"] = 4, ["meta"] = {["fields"] = {}, ["inventory"] = {}}, ["param2"] = 3, ["y"] = 12, ["param1"] = 190, ["z"] = 12, ["name"] = "rainbow:slope_fancybrick_red_outer_cut"}, {["x"] = 4, ["meta"] = {["fields"] = {}, ["inventory"] = {}}, ["param2"] = 19, ["y"] = 13, ["param1"] = 206, ["z"] = 7, ["name"] = "rainbow:slab_wood_red_1"}, {["x"] = 4, ["meta"] = {["fields"] = {}, ["inventory"] = {}}, ["param2"] = 1, ["y"] = 14, ["param1"] = 206, ["z"] = 6, ["name"] = "rainbow:slope_stone_darkgrey_outer_cut"}, {["x"] = 4, ["meta"] = {["fields"] = {}, ["inventory"] = {}}, ["param2"] = 1, ["y"] = 14, ["param1"] = 190, ["z"] = 7, ["name"] = "rainbow:slope_stone_black"}, {["x"] = 4, ["meta"] = {["fields"] = {}, ["inventory"] = {}}, ["param2"] = 2, ["y"] = 14, ["param1"] = 206, ["z"] = 8, ["name"] = "rainbow:slope_stone_darkgrey_outer_cut"}, {["x"] = 5, ["meta"] = {["fields"] = {}, ["inventory"] = {}}, ["y"] = 0, ["z"] = 2, ["name"] = "rainbow:dirt_black"}, {["x"] = 5, ["meta"] = {["fields"] = {}, ["inventory"] = {}}, ["y"] = 0, ["z"] = 3, ["name"] = "rainbow:stone_black"}, {["x"] = 5, ["meta"] = {["fields"] = {}, ["inventory"] = {}}, ["y"] = 0, ["z"] = 4, ["name"] = "rainbow:stone_black"}, {["x"] = 5, ["meta"] = {["fields"] = {}, ["inventory"] = {}}, ["y"] = 0, ["z"] = 5, ["name"] = "rainbow:stone_black"}, {["x"] = 5, ["meta"] = {["fields"] = {}, ["inventory"] = {}}, ["y"] = 0, ["z"] = 6, ["name"] = "rainbow:stone_black"}, {["x"] = 5, ["meta"] = {["fields"] = {}, ["inventory"] = {}}, ["y"] = 0, ["z"] = 7, ["name"] = "rainbow:stone_black"}, {["x"] = 5, ["meta"] = {["fields"] = {}, ["inventory"] = {}}, ["y"] = 0, ["z"] = 8, ["name"] = "rainbow:stone_black"}, {["x"] = 5, ["meta"] = {["fields"] = {}, ["inventory"] = {}}, ["y"] = 0, ["z"] = 9, ["name"] = "rainbow:stone_black"}, {["x"] = 5, ["meta"] = {["fields"] = {}, ["inventory"] = {}}, ["y"] = 0, ["z"] = 10, ["name"] = "rainbow:dirt_black"}, {["x"] = 5, ["meta"] = {["fields"] = {}, ["inventory"] = {}}, ["y"] = 0, ["z"] = 11, ["name"] = "rainbow:dirt_black"}, {["x"] = 5, ["meta"] = {["fields"] = {}, ["inventory"] = {}}, ["y"] = 0, ["z"] = 12, ["name"] = "rainbow:dirt_black"}, {["x"] = 5, ["meta"] = {["fields"] = {}, ["inventory"] = {}}, ["param2"] = 10, ["y"] = 1, ["param1"] = 206, ["z"] = 1, ["name"] = "rainbow:slab_stone_black_1"}, {["x"] = 5, ["meta"] = {["fields"] = {}, ["inventory"] = {}}, ["param2"] = 18, ["y"] = 1, ["z"] = 2, ["name"] = "rainbow:tree_black"}, {["x"] = 5, ["meta"] = {["fields"] = {}, ["inventory"] = {}}, ["y"] = 1, ["z"] = 3, ["name"] = "rainbow:wood_black"}, {["x"] = 5, ["meta"] = {["fields"] = {}, ["inventory"] = {}}, ["y"] = 1, ["z"] = 4, ["name"] = "rainbow:wood_red"}, {["x"] = 5, ["meta"] = {["fields"] = {}, ["inventory"] = {}}, ["y"] = 1, ["z"] = 5, ["name"] = "rainbow:wood_red"}, {["x"] = 5, ["meta"] = {["fields"] = {}, ["inventory"] = {}}, ["y"] = 1, ["z"] = 6, ["name"] = "rainbow:wood_red"}, {["x"] = 5, ["meta"] = {["fields"] = {}, ["inventory"] = {}}, ["y"] = 1, ["z"] = 7, ["name"] = "rainbow:wood_red"}, {["x"] = 5, ["meta"] = {["fields"] = {}, ["inventory"] = {}}, ["y"] = 1, ["z"] = 8, ["name"] = "rainbow:wood_red"}, {["x"] = 5, ["meta"] = {["fields"] = {}, ["inventory"] = {}}, ["y"] = 1, ["z"] = 9, ["name"] = "rainbow:wood_red"}, {["x"] = 5, ["meta"] = {["fields"] = {}, ["inventory"] = {}}, ["y"] = 1, ["z"] = 10, ["name"] = "rainbow:wood_red"}, {["x"] = 5, ["meta"] = {["fields"] = {}, ["inventory"] = {}}, ["y"] = 1, ["z"] = 11, ["name"] = "rainbow:wood_black"}, {["x"] = 5, ["meta"] = {["fields"] = {}, ["inventory"] = {}}, ["param2"] = 18, ["y"] = 1, ["z"] = 12, ["name"] = "rainbow:tree_black"}, {["x"] = 5, ["meta"] = {["fields"] = {}, ["inventory"] = {}}, ["param2"] = 4, ["y"] = 1, ["param1"] = 206, ["z"] = 13, ["name"] = "rainbow:slab_stone_black_1"}, {["x"] = 5, ["meta"] = {["fields"] = {}, ["inventory"] = {}}, ["param2"] = 10, ["y"] = 2, ["param1"] = 222, ["z"] = 1, ["name"] = "rainbow:slab_stone_black_1"}, {["x"] = 5, ["meta"] = {["fields"] = {}, ["inventory"] = {}}, ["param2"] = 4, ["y"] = 2, ["param1"] = 222, ["z"] = 13, ["name"] = "rainbow:slab_stone_black_1"}, {["x"] = 5, ["meta"] = {["fields"] = {}, ["inventory"] = {}}, ["param2"] = 9, ["y"] = 3, ["param1"] = 238, ["z"] = 1, ["name"] = "rainbow:slab_lightglass_red_1"}, {["x"] = 5, ["meta"] = {["fields"] = {}, ["inventory"] = {}}, ["param2"] = 7, ["y"] = 3, ["param1"] = 238, ["z"] = 13, ["name"] = "rainbow:slab_lightglass_red_1"}, {["x"] = 5, ["meta"] = {["fields"] = {}, ["inventory"] = {}}, ["param2"] = 10, ["y"] = 4, ["param1"] = 222, ["z"] = 1, ["name"] = "rainbow:slab_wood_black_1"}, {["x"] = 5, ["meta"] = {["fields"] = {}, ["inventory"] = {}}, ["param2"] = 4, ["y"] = 4, ["param1"] = 222, ["z"] = 13, ["name"] = "rainbow:slab_wood_black_1"}, {["x"] = 5, ["meta"] = {["fields"] = {}, ["inventory"] = {}}, ["param2"] = 10, ["y"] = 5, ["param1"] = 206, ["z"] = 1, ["name"] = "rainbow:slab_stone_black_1"}, {["x"] = 5, ["meta"] = {["fields"] = {}, ["inventory"] = {}}, ["param2"] = 22, ["y"] = 5, ["param1"] = 205, ["z"] = 2, ["name"] = "rainbow:slab_stone_black_1"}, {["x"] = 5, ["meta"] = {["fields"] = {}, ["inventory"] = {}}, ["param2"] = 22, ["y"] = 5, ["param1"] = 221, ["z"] = 3, ["name"] = "rainbow:slab_wood_black_1"}, {["x"] = 5, ["meta"] = {["fields"] = {}, ["inventory"] = {}}, ["param2"] = 22, ["y"] = 5, ["param1"] = 204, ["z"] = 4, ["name"] = "rainbow:slab_wood_red_1"}, {["x"] = 5, ["meta"] = {["fields"] = {}, ["inventory"] = {}}, ["param2"] = 22, ["y"] = 5, ["param1"] = 204, ["z"] = 5, ["name"] = "rainbow:slab_wood_red_1"}, {["x"] = 5, ["meta"] = {["fields"] = {}, ["inventory"] = {}}, ["param2"] = 22, ["y"] = 5, ["param1"] = 221, ["z"] = 6, ["name"] = "rainbow:slab_wood_red_1"}, {["x"] = 5, ["meta"] = {["fields"] = {}, ["inventory"] = {}}, ["param2"] = 22, ["y"] = 5, ["param1"] = 221, ["z"] = 7, ["name"] = "rainbow:slab_wood_red_1"}, {["x"] = 5, ["meta"] = {["fields"] = {}, ["inventory"] = {}}, ["param2"] = 22, ["y"] = 5, ["param1"] = 221, ["z"] = 8, ["name"] = "rainbow:slab_wood_red_1"}, {["x"] = 5, ["meta"] = {["fields"] = {}, ["inventory"] = {}}, ["param2"] = 22, ["y"] = 5, ["param1"] = 204, ["z"] = 9, ["name"] = "rainbow:slab_wood_red_1"}, {["x"] = 5, ["meta"] = {["fields"] = {}, ["inventory"] = {}}, ["param2"] = 22, ["y"] = 5, ["param1"] = 204, ["z"] = 10, ["name"] = "rainbow:slab_wood_red_1"}, {["x"] = 5, ["meta"] = {["fields"] = {}, ["inventory"] = {}}, ["param2"] = 20, ["y"] = 5, ["param1"] = 221, ["z"] = 11, ["name"] = "rainbow:slab_wood_black_1"}, {["x"] = 5, ["meta"] = {["fields"] = {}, ["inventory"] = {}}, ["param2"] = 20, ["y"] = 5, ["param1"] = 205, ["z"] = 12, ["name"] = "rainbow:slab_stone_black_1"}, {["x"] = 5, ["meta"] = {["fields"] = {}, ["inventory"] = {}}, ["param2"] = 4, ["y"] = 5, ["param1"] = 206, ["z"] = 13, ["name"] = "rainbow:slab_stone_black_1"}, {["x"] = 5, ["meta"] = {["fields"] = {}, ["inventory"] = {}}, ["param2"] = 12, ["y"] = 6, ["param1"] = 189, ["z"] = 2, ["name"] = "rainbow:slope_tree_black"}, {["x"] = 5, ["meta"] = {["fields"] = {}, ["inventory"] = {}}, ["param2"] = 16, ["y"] = 6, ["param1"] = 238, ["z"] = 6, ["name"] = "rainbow:slab_lightcoolglass_yellow_1"}, {["x"] = 5, ["meta"] = {["fields"] = {}, ["inventory"] = {}}, ["param2"] = 16, ["y"] = 6, ["param1"] = 238, ["z"] = 7, ["name"] = "rainbow:slab_lightcoolglass_yellow_1"}, {["x"] = 5, ["meta"] = {["fields"] = {}, ["inventory"] = {}}, ["param2"] = 16, ["y"] = 6, ["param1"] = 238, ["z"] = 8, ["name"] = "rainbow:slab_lightcoolglass_yellow_1"}, {["x"] = 5, ["meta"] = {["fields"] = {}, ["inventory"] = {}}, ["param2"] = 7, ["y"] = 6, ["param1"] = 189, ["z"] = 12, ["name"] = "rainbow:slope_tree_black"}, {["x"] = 5, ["meta"] = {["fields"] = {}, ["inventory"] = {}}, ["param2"] = 12, ["y"] = 7, ["param1"] = 189, ["z"] = 2, ["name"] = "rainbow:slope_tree_black"}, {["x"] = 5, ["meta"] = {["fields"] = {}, ["inventory"] = {}}, ["param2"] = 18, ["y"] = 7, ["param1"] = 238, ["z"] = 8, ["name"] = "rainbow:slab_lightcoolglass_yellow_1"}, {["x"] = 5, ["meta"] = {["fields"] = {}, ["inventory"] = {}}, ["param2"] = 7, ["y"] = 7, ["param1"] = 189, ["z"] = 12, ["name"] = "rainbow:slope_tree_black"}, {["x"] = 5, ["meta"] = {["fields"] = {}, ["inventory"] = {}}, ["param2"] = 12, ["y"] = 8, ["param1"] = 189, ["z"] = 2, ["name"] = "rainbow:slope_tree_black"}, {["x"] = 5, ["meta"] = {["fields"] = {}, ["inventory"] = {}}, ["param2"] = 22, ["y"] = 8, ["param1"] = 187, ["z"] = 4, ["name"] = "rainbow:slab_wood_black_1"}, {["x"] = 5, ["meta"] = {["fields"] = {}, ["inventory"] = {}}, ["param2"] = 22, ["y"] = 8, ["param1"] = 204, ["z"] = 5, ["name"] = "rainbow:slab_wood_black_1"}, {["x"] = 5, ["meta"] = {["fields"] = {}, ["inventory"] = {}}, ["param2"] = 20, ["y"] = 8, ["param1"] = 221, ["z"] = 6, ["name"] = "rainbow:slab_wood_black_1"}, {["x"] = 5, ["meta"] = {["fields"] = {}, ["inventory"] = {}}, ["param2"] = 16, ["y"] = 8, ["param1"] = 238, ["z"] = 7, ["name"] = "rainbow:slab_lightcoolglass_yellow_1"}, {["x"] = 5, ["meta"] = {["fields"] = {}, ["inventory"] = {}}, ["param2"] = 20, ["y"] = 8, ["param1"] = 221, ["z"] = 8, ["name"] = "rainbow:slab_wood_black_1"}, {["x"] = 5, ["meta"] = {["fields"] = {}, ["inventory"] = {}}, ["param2"] = 20, ["y"] = 8, ["param1"] = 204, ["z"] = 9, ["name"] = "rainbow:slab_wood_black_1"}, {["x"] = 5, ["meta"] = {["fields"] = {}, ["inventory"] = {}}, ["param2"] = 20, ["y"] = 8, ["param1"] = 187, ["z"] = 10, ["name"] = "rainbow:slab_wood_black_1"}, {["x"] = 5, ["meta"] = {["fields"] = {}, ["inventory"] = {}}, ["param2"] = 7, ["y"] = 8, ["param1"] = 189, ["z"] = 12, ["name"] = "rainbow:slope_tree_black"}, {["x"] = 5, ["meta"] = {["fields"] = {}, ["inventory"] = {}}, ["param2"] = 12, ["y"] = 9, ["param1"] = 189, ["z"] = 2, ["name"] = "rainbow:slope_tree_black"}, {["x"] = 5, ["meta"] = {["fields"] = {}, ["inventory"] = {}}, ["param2"] = 7, ["y"] = 9, ["param1"] = 204, ["z"] = 4, ["name"] = "rainbow:slope_tree_black"}, {["x"] = 5, ["meta"] = {["fields"] = {}, ["inventory"] = {}}, ["y"] = 9, ["param1"] = 221, ["z"] = 5, ["name"] = "rainbow:stair_wood_red_alt_1"}, {["x"] = 5, ["meta"] = {["fields"] = {}, ["inventory"] = {}}, ["param2"] = 9, ["y"] = 9, ["param1"] = 238, ["z"] = 6, ["name"] = "rainbow:slope_lightglass_red"}, {["x"] = 5, ["meta"] = {["fields"] = {}, ["inventory"] = {}}, ["param2"] = 18, ["y"] = 9, ["param1"] = 238, ["z"] = 8, ["name"] = "rainbow:slope_lightglass_red"}, {["x"] = 5, ["meta"] = {["fields"] = {}, ["inventory"] = {}}, ["param2"] = 12, ["y"] = 9, ["param1"] = 204, ["z"] = 10, ["name"] = "rainbow:slope_tree_black"}, {["x"] = 5, ["meta"] = {["fields"] = {}, ["inventory"] = {}}, ["param2"] = 7, ["y"] = 9, ["param1"] = 189, ["z"] = 12, ["name"] = "rainbow:slope_tree_black"}, {["x"] = 5, ["meta"] = {["fields"] = {}, ["inventory"] = {}}, ["y"] = 10, ["param1"] = 190, ["z"] = 1, ["name"] = "rainbow:slope_fancybrick_red_outer_cut"}, {["x"] = 5, ["meta"] = {["fields"] = {}, ["inventory"] = {}}, ["y"] = 10, ["param1"] = 173, ["z"] = 2, ["name"] = "rainbow:slope_fancybrick_red_inner_cut"}, {["x"] = 5, ["meta"] = {["fields"] = {}, ["inventory"] = {}}, ["param2"] = 3, ["y"] = 10, ["param1"] = 205, ["z"] = 4, ["name"] = "rainbow:slope_fancybrick_red_inner_cut"}, {["x"] = 5, ["meta"] = {["fields"] = {}, ["inventory"] = {}}, ["param2"] = 3, ["y"] = 10, ["param1"] = 221, ["z"] = 5, ["name"] = "rainbow:slope_fancybrick_red_outer_cut"}, {["x"] = 5, ["meta"] = {["fields"] = {}, ["inventory"] = {}}, ["param2"] = 9, ["y"] = 10, ["param1"] = 238, ["z"] = 6, ["name"] = "rainbow:slope_lightglass_black"}, {["x"] = 5, ["meta"] = {["fields"] = {}, ["inventory"] = {}}, ["param2"] = 5, ["y"] = 10, ["param1"] = 238, ["z"] = 8, ["name"] = "rainbow:slope_lightglass_black"}, {["x"] = 5, ["meta"] = {["fields"] = {}, ["inventory"] = {}}, ["y"] = 10, ["param1"] = 221, ["z"] = 9, ["name"] = "rainbow:slope_fancybrick_red_outer_cut"}, {["x"] = 5, ["meta"] = {["fields"] = {}, ["inventory"] = {}}, ["y"] = 10, ["param1"] = 205, ["z"] = 10, ["name"] = "rainbow:slope_fancybrick_red_inner_cut"}, {["x"] = 5, ["meta"] = {["fields"] = {}, ["inventory"] = {}}, ["param2"] = 3, ["y"] = 10, ["param1"] = 173, ["z"] = 12, ["name"] = "rainbow:slope_fancybrick_red_inner_cut"}, {["x"] = 5, ["meta"] = {["fields"] = {}, ["inventory"] = {}}, ["param2"] = 3, ["y"] = 10, ["param1"] = 190, ["z"] = 13, ["name"] = "rainbow:slope_fancybrick_red_outer_cut"}, {["x"] = 5, ["meta"] = {["fields"] = {}, ["inventory"] = {}}, ["y"] = 11, ["param1"] = 190, ["z"] = 2, ["name"] = "rainbow:slope_fancybrick_red_outer_cut"}, {["x"] = 5, ["meta"] = {["fields"] = {}, ["inventory"] = {}}, ["param2"] = 3, ["y"] = 11, ["param1"] = 206, ["z"] = 3, ["name"] = "rainbow:slope_fancybrick_red"}, {["x"] = 5, ["meta"] = {["fields"] = {}, ["inventory"] = {}}, ["param2"] = 3, ["y"] = 11, ["param1"] = 206, ["z"] = 4, ["name"] = "rainbow:slope_fancybrick_red_outer_cut"}, {["x"] = 5, ["meta"] = {["fields"] = {}, ["inventory"] = {}}, ["param2"] = 9, ["y"] = 11, ["param1"] = 238, ["z"] = 6, ["name"] = "rainbow:slope_lightglass_red"}, {["x"] = 5, ["meta"] = {["fields"] = {}, ["inventory"] = {}}, ["param2"] = 5, ["y"] = 11, ["param1"] = 238, ["z"] = 8, ["name"] = "rainbow:slope_lightglass_red"}, {["x"] = 5, ["meta"] = {["fields"] = {}, ["inventory"] = {}}, ["y"] = 11, ["param1"] = 206, ["z"] = 10, ["name"] = "rainbow:slope_fancybrick_red_outer_cut"}, {["x"] = 5, ["meta"] = {["fields"] = {}, ["inventory"] = {}}, ["param2"] = 3, ["y"] = 11, ["param1"] = 206, ["z"] = 11, ["name"] = "rainbow:slope_fancybrick_red"}, {["x"] = 5, ["meta"] = {["fields"] = {}, ["inventory"] = {}}, ["param2"] = 3, ["y"] = 11, ["param1"] = 190, ["z"] = 12, ["name"] = "rainbow:slope_fancybrick_red_outer_cut"}, {["x"] = 5, ["meta"] = {["fields"] = {}, ["inventory"] = {}}, ["param2"] = 9, ["y"] = 12, ["param1"] = 238, ["z"] = 6, ["name"] = "rainbow:slope_lightglass_black"}, {["x"] = 5, ["meta"] = {["fields"] = {}, ["inventory"] = {}}, ["param2"] = 18, ["y"] = 12, ["param1"] = 238, ["z"] = 8, ["name"] = "rainbow:slope_lightglass_black"}, {["x"] = 5, ["meta"] = {["fields"] = {}, ["inventory"] = {}}, ["param2"] = 9, ["y"] = 13, ["param1"] = 238, ["z"] = 6, ["name"] = "rainbow:slope_lightglass_red"}, {["x"] = 5, ["meta"] = {["fields"] = {}, ["inventory"] = {}}, ["param2"] = 18, ["y"] = 13, ["param1"] = 238, ["z"] = 8, ["name"] = "rainbow:slope_lightglass_red"}, {["x"] = 5, ["meta"] = {["fields"] = {}, ["inventory"] = {}}, ["param2"] = 1, ["y"] = 14, ["param1"] = 206, ["z"] = 5, ["name"] = "rainbow:slope_stone_darkgrey_outer_cut"}, {["x"] = 5, ["meta"] = {["fields"] = {}, ["inventory"] = {}}, ["param2"] = 1, ["y"] = 14, ["param1"] = 221, ["z"] = 6, ["name"] = "rainbow:slope_stone_black_inner_cut"}, {["x"] = 5, ["meta"] = {["fields"] = {}, ["inventory"] = {}}, ["param2"] = 2, ["y"] = 14, ["param1"] = 221, ["z"] = 8, ["name"] = "rainbow:slope_stone_black_inner_cut"}, {["x"] = 5, ["meta"] = {["fields"] = {}, ["inventory"] = {}}, ["param2"] = 2, ["y"] = 14, ["param1"] = 206, ["z"] = 9, ["name"] = "rainbow:slope_stone_darkgrey_outer_cut"}, {["x"] = 5, ["meta"] = {["fields"] = {}, ["inventory"] = {}}, ["param2"] = 1, ["y"] = 15, ["param1"] = 206, ["z"] = 6, ["name"] = "rainbow:slope_stone_black_outer_cut"}, {["x"] = 5, ["meta"] = {["fields"] = {}, ["inventory"] = {}}, ["param2"] = 1, ["y"] = 15, ["param1"] = 190, ["z"] = 7, ["name"] = "rainbow:slope_stone_darkgrey"}, {["x"] = 5, ["meta"] = {["fields"] = {}, ["inventory"] = {}}, ["param2"] = 2, ["y"] = 15, ["param1"] = 206, ["z"] = 8, ["name"] = "rainbow:slope_stone_black_outer_cut"}, {["x"] = 6, ["meta"] = {["fields"] = {}, ["inventory"] = {}}, ["y"] = 0, ["z"] = 2, ["name"] = "rainbow:dirt_black"}, {["x"] = 6, ["meta"] = {["fields"] = {}, ["inventory"] = {}}, ["y"] = 0, ["z"] = 3, ["name"] = "rainbow:stone_black"}, {["x"] = 6, ["meta"] = {["fields"] = {}, ["inventory"] = {}}, ["y"] = 0, ["z"] = 4, ["name"] = "rainbow:stone_black"}, {["x"] = 6, ["meta"] = {["fields"] = {}, ["inventory"] = {}}, ["y"] = 0, ["z"] = 5, ["name"] = "rainbow:stone_black"}, {["x"] = 6, ["meta"] = {["fields"] = {}, ["inventory"] = {}}, ["y"] = 0, ["z"] = 6, ["name"] = "rainbow:stone_black"}, {["x"] = 6, ["meta"] = {["fields"] = {}, ["inventory"] = {}}, ["y"] = 0, ["z"] = 7, ["name"] = "rainbow:stone_black"}, {["x"] = 6, ["meta"] = {["fields"] = {}, ["inventory"] = {}}, ["y"] = 0, ["z"] = 8, ["name"] = "rainbow:stone_black"}, {["x"] = 6, ["meta"] = {["fields"] = {}, ["inventory"] = {}}, ["y"] = 0, ["z"] = 9, ["name"] = "rainbow:stone_black"}, {["x"] = 6, ["meta"] = {["fields"] = {}, ["inventory"] = {}}, ["y"] = 0, ["z"] = 10, ["name"] = "rainbow:dirt_black"}, {["x"] = 6, ["meta"] = {["fields"] = {}, ["inventory"] = {}}, ["y"] = 0, ["z"] = 11, ["name"] = "rainbow:dirt_black"}, {["x"] = 6, ["meta"] = {["fields"] = {}, ["inventory"] = {}}, ["y"] = 0, ["z"] = 12, ["name"] = "rainbow:dirt_black"}, {["x"] = 6, ["meta"] = {["fields"] = {}, ["inventory"] = {}}, ["param2"] = 10, ["y"] = 1, ["param1"] = 190, ["z"] = 1, ["name"] = "rainbow:slab_stone_black_1"}, {["x"] = 6, ["meta"] = {["fields"] = {}, ["inventory"] = {}}, ["param2"] = 18, ["y"] = 1, ["z"] = 2, ["name"] = "rainbow:tree_black"}, {["x"] = 6, ["meta"] = {["fields"] = {}, ["inventory"] = {}}, ["y"] = 1, ["param1"] = 238, ["z"] = 3, ["name"] = "rainbow:lightblock_gold"}, {["x"] = 6, ["meta"] = {["fields"] = {}, ["inventory"] = {}}, ["y"] = 1, ["z"] = 4, ["name"] = "rainbow:wood_red"}, {["x"] = 6, ["meta"] = {["fields"] = {}, ["inventory"] = {}}, ["y"] = 1, ["z"] = 5, ["name"] = "rainbow:wood_red"}, {["x"] = 6, ["meta"] = {["fields"] = {}, ["inventory"] = {}}, ["y"] = 1, ["param1"] = 238, ["z"] = 6, ["name"] = "rainbow:lightblock_gold"}, {["x"] = 6, ["meta"] = {["fields"] = {}, ["inventory"] = {}}, ["y"] = 1, ["z"] = 7, ["name"] = "rainbow:wood_black"}, {["x"] = 6, ["meta"] = {["fields"] = {}, ["inventory"] = {}}, ["y"] = 1, ["param1"] = 238, ["z"] = 8, ["name"] = "rainbow:lightblock_gold"}, {["x"] = 6, ["meta"] = {["fields"] = {}, ["inventory"] = {}}, ["y"] = 1, ["z"] = 9, ["name"] = "rainbow:wood_red"}, {["x"] = 6, ["meta"] = {["fields"] = {}, ["inventory"] = {}}, ["y"] = 1, ["z"] = 10, ["name"] = "rainbow:wood_red"}, {["x"] = 6, ["meta"] = {["fields"] = {}, ["inventory"] = {}}, ["y"] = 1, ["param1"] = 238, ["z"] = 11, ["name"] = "rainbow:lightblock_gold"}, {["x"] = 6, ["meta"] = {["fields"] = {}, ["inventory"] = {}}, ["param2"] = 18, ["y"] = 1, ["z"] = 12, ["name"] = "rainbow:tree_black"}, {["x"] = 6, ["meta"] = {["fields"] = {}, ["inventory"] = {}}, ["param2"] = 4, ["y"] = 1, ["param1"] = 190, ["z"] = 13, ["name"] = "rainbow:slab_stone_black_1"}, {["x"] = 6, ["meta"] = {["fields"] = {}, ["inventory"] = {}}, ["param2"] = 10, ["y"] = 2, ["param1"] = 206, ["z"] = 1, ["name"] = "rainbow:slab_stone_black_1"}, {["x"] = 6, ["meta"] = {["fields"] = {}, ["inventory"] = {}}, ["param2"] = 8, ["y"] = 2, ["param1"] = 238, ["z"] = 5, ["name"] = "rainbow:slab_lightcoolglass_yellow_1"}, {["x"] = 6, ["meta"] = {["fields"] = {}, ["inventory"] = {}}, ["param2"] = 4, ["y"] = 2, ["param1"] = 206, ["z"] = 13, ["name"] = "rainbow:slab_stone_black_1"}, {["x"] = 6, ["meta"] = {["fields"] = {}, ["inventory"] = {}}, ["param2"] = 10, ["y"] = 3, ["param1"] = 222, ["z"] = 1, ["name"] = "rainbow:slab_wood_black_1"}, {["x"] = 6, ["meta"] = {["fields"] = {}, ["inventory"] = {}}, ["param2"] = 4, ["y"] = 3, ["param1"] = 222, ["z"] = 13, ["name"] = "rainbow:slab_wood_black_1"}, {["x"] = 6, ["meta"] = {["fields"] = {}, ["inventory"] = {}}, ["param2"] = 9, ["y"] = 4, ["param1"] = 238, ["z"] = 1, ["name"] = "rainbow:slab_lightglass_red_1"}, {["x"] = 6, ["meta"] = {["fields"] = {}, ["inventory"] = {}}, ["param2"] = 7, ["y"] = 4, ["param1"] = 238, ["z"] = 13, ["name"] = "rainbow:slab_lightglass_red_1"}, {["x"] = 6, ["meta"] = {["fields"] = {}, ["inventory"] = {}}, ["param2"] = 10, ["y"] = 5, ["param1"] = 222, ["z"] = 1, ["name"] = "rainbow:slab_stone_black_1"}, {["x"] = 6, ["meta"] = {["fields"] = {}, ["inventory"] = {}}, ["param2"] = 22, ["y"] = 5, ["param1"] = 221, ["z"] = 2, ["name"] = "rainbow:slab_stone_black_1"}, {["x"] = 6, ["meta"] = {["fields"] = {}, ["inventory"] = {}}, ["param2"] = 21, ["y"] = 5, ["param1"] = 238, ["z"] = 3, ["name"] = "rainbow:slab_lightcoolglass_yellow_1"}, {["x"] = 6, ["meta"] = {["fields"] = {}, ["inventory"] = {}}, ["param2"] = 22, ["y"] = 5, ["param1"] = 221, ["z"] = 4, ["name"] = "rainbow:slab_wood_red_1"}, {["x"] = 6, ["meta"] = {["fields"] = {}, ["inventory"] = {}}, ["param2"] = 22, ["y"] = 5, ["param1"] = 221, ["z"] = 5, ["name"] = "rainbow:slab_wood_red_1"}, {["x"] = 6, ["meta"] = {["fields"] = {}, ["inventory"] = {}}, ["param2"] = 22, ["y"] = 5, ["param1"] = 221, ["z"] = 9, ["name"] = "rainbow:slab_wood_red_1"}, {["x"] = 6, ["meta"] = {["fields"] = {}, ["inventory"] = {}}, ["param2"] = 20, ["y"] = 5, ["param1"] = 221, ["z"] = 10, ["name"] = "rainbow:slab_wood_red_1"}, {["x"] = 6, ["meta"] = {["fields"] = {}, ["inventory"] = {}}, ["param2"] = 20, ["y"] = 5, ["param1"] = 238, ["z"] = 11, ["name"] = "rainbow:slab_lightcoolglass_yellow_1"}, {["x"] = 6, ["meta"] = {["fields"] = {}, ["inventory"] = {}}, ["param2"] = 20, ["y"] = 5, ["param1"] = 221, ["z"] = 12, ["name"] = "rainbow:slab_stone_black_1"}, {["x"] = 6, ["meta"] = {["fields"] = {}, ["inventory"] = {}}, ["param2"] = 4, ["y"] = 5, ["param1"] = 222, ["z"] = 13, ["name"] = "rainbow:slab_stone_black_1"}, {["x"] = 6, ["meta"] = {["fields"] = {}, ["inventory"] = {}}, ["param2"] = 10, ["y"] = 6, ["param1"] = 206, ["z"] = 2, ["name"] = "rainbow:slab_wood_black_1"}, {["x"] = 6, ["meta"] = {["fields"] = {}, ["inventory"] = {}}, ["param2"] = 8, ["y"] = 6, ["param1"] = 238, ["z"] = 5, ["name"] = "rainbow:slab_lightcoolglass_yellow_1"}, {["x"] = 6, ["meta"] = {["fields"] = {}, ["inventory"] = {}}, ["param2"] = 20, ["y"] = 6, ["param1"] = 221, ["z"] = 8, ["name"] = "rainbow:slab_wood_yellow_1"}, {["x"] = 6, ["meta"] = {["fields"] = {}, ["inventory"] = {}}, ["param2"] = 4, ["y"] = 6, ["param1"] = 238, ["z"] = 9, ["name"] = "rainbow:slab_lightcoolglass_yellow_1"}, {["x"] = 6, ["meta"] = {["fields"] = {}, ["inventory"] = {}}, ["param2"] = 4, ["y"] = 6, ["param1"] = 206, ["z"] = 12, ["name"] = "rainbow:slab_wood_black_1"}, {["x"] = 6, ["meta"] = {["fields"] = {}, ["inventory"] = {}}, ["param2"] = 10, ["y"] = 7, ["param1"] = 190, ["z"] = 2, ["name"] = "rainbow:slab_wood_red_1"}, {["x"] = 6, ["meta"] = {["fields"] = {}, ["inventory"] = {}}, ["param2"] = 21, ["y"] = 7, ["param1"] = 204, ["z"] = 6, ["name"] = "rainbow:slab_wood_yellow_1"}, {["x"] = 6, ["meta"] = {["fields"] = {}, ["inventory"] = {}}, ["param2"] = 2, ["y"] = 7, ["param1"] = 204, ["z"] = 7, ["name"] = "rainbow:stair_wood_yellow_alt_1"}, {["x"] = 6, ["meta"] = {["fields"] = {}, ["inventory"] = {}}, ["param2"] = 4, ["y"] = 7, ["param1"] = 238, ["z"] = 9, ["name"] = "rainbow:slab_lightcoolglass_yellow_1"}, {["x"] = 6, ["meta"] = {["fields"] = {}, ["inventory"] = {}}, ["param2"] = 4, ["y"] = 7, ["param1"] = 190, ["z"] = 12, ["name"] = "rainbow:slab_wood_red_1"}, {["x"] = 6, ["meta"] = {["fields"] = {}, ["inventory"] = {}}, ["param2"] = 10, ["y"] = 8, ["param1"] = 174, ["z"] = 2, ["name"] = "rainbow:slab_wood_black_1"}, {["x"] = 6, ["meta"] = {["fields"] = {}, ["inventory"] = {}}, ["param2"] = 20, ["y"] = 8, ["param1"] = 189, ["z"] = 3, ["name"] = "rainbow:slab_wood_black_1"}, {["x"] = 6, ["meta"] = {["fields"] = {}, ["inventory"] = {}}, ["param2"] = 22, ["y"] = 8, ["param1"] = 204, ["z"] = 4, ["name"] = "rainbow:slab_wood_black_1"}, {["x"] = 6, ["meta"] = {["fields"] = {}, ["inventory"] = {}}, ["param2"] = 22, ["y"] = 8, ["param1"] = 221, ["z"] = 5, ["name"] = "rainbow:slab_wood_black_1"}, {["x"] = 6, ["meta"] = {["fields"] = {}, ["inventory"] = {}}, ["param2"] = 20, ["y"] = 8, ["param1"] = 221, ["z"] = 9, ["name"] = "rainbow:slab_wood_black_1"}, {["x"] = 6, ["meta"] = {["fields"] = {}, ["inventory"] = {}}, ["param2"] = 20, ["y"] = 8, ["param1"] = 204, ["z"] = 10, ["name"] = "rainbow:slab_wood_black_1"}, {["x"] = 6, ["meta"] = {["fields"] = {}, ["inventory"] = {}}, ["param2"] = 20, ["y"] = 8, ["param1"] = 189, ["z"] = 11, ["name"] = "rainbow:slab_wood_black_1"}, {["x"] = 6, ["meta"] = {["fields"] = {}, ["inventory"] = {}}, ["param2"] = 4, ["y"] = 8, ["param1"] = 174, ["z"] = 12, ["name"] = "rainbow:slab_wood_black_1"}, {["x"] = 6, ["meta"] = {["fields"] = {}, ["inventory"] = {}}, ["param2"] = 12, ["y"] = 9, ["param1"] = 206, ["z"] = 3, ["name"] = "rainbow:slab_tree_black_1"}, {["x"] = 6, ["meta"] = {["fields"] = {}, ["inventory"] = {}}, ["param2"] = 9, ["y"] = 9, ["param1"] = 238, ["z"] = 5, ["name"] = "rainbow:slope_lightglass_red"}, {["x"] = 6, ["meta"] = {["fields"] = {}, ["inventory"] = {}}, ["param2"] = 18, ["y"] = 9, ["param1"] = 238, ["z"] = 9, ["name"] = "rainbow:slope_lightglass_red"}, {["x"] = 6, ["meta"] = {["fields"] = {}, ["inventory"] = {}}, ["param2"] = 12, ["y"] = 9, ["param1"] = 206, ["z"] = 11, ["name"] = "rainbow:slab_tree_black_1"}, {["x"] = 6, ["meta"] = {["fields"] = {}, ["inventory"] = {}}, ["y"] = 10, ["param1"] = 190, ["z"] = 2, ["name"] = "rainbow:slope_fancybrick_red_outer_cut"}, {["x"] = 6, ["meta"] = {["fields"] = {}, ["inventory"] = {}}, ["param2"] = 3, ["y"] = 10, ["param1"] = 206, ["z"] = 3, ["name"] = "rainbow:slope_fancybrick_red"}, {["x"] = 6, ["meta"] = {["fields"] = {}, ["inventory"] = {}}, ["param2"] = 3, ["y"] = 10, ["param1"] = 221, ["z"] = 4, ["name"] = "rainbow:slope_fancybrick_red_outer_cut"}, {["x"] = 6, ["meta"] = {["fields"] = {}, ["inventory"] = {}}, ["param2"] = 9, ["y"] = 10, ["param1"] = 238, ["z"] = 5, ["name"] = "rainbow:slope_lightglass_black"}, {["x"] = 6, ["meta"] = {["fields"] = {}, ["inventory"] = {}}, ["param2"] = 5, ["y"] = 10, ["param1"] = 238, ["z"] = 9, ["name"] = "rainbow:slope_lightglass_black"}, {["x"] = 6, ["meta"] = {["fields"] = {}, ["inventory"] = {}}, ["y"] = 10, ["param1"] = 221, ["z"] = 10, ["name"] = "rainbow:slope_fancybrick_red_outer_cut"}, {["x"] = 6, ["meta"] = {["fields"] = {}, ["inventory"] = {}}, ["param2"] = 3, ["y"] = 10, ["param1"] = 206, ["z"] = 11, ["name"] = "rainbow:slope_fancybrick_red"}, {["x"] = 6, ["meta"] = {["fields"] = {}, ["inventory"] = {}}, ["param2"] = 3, ["y"] = 10, ["param1"] = 190, ["z"] = 12, ["name"] = "rainbow:slope_fancybrick_red_outer_cut"}, {["x"] = 6, ["meta"] = {["fields"] = {}, ["inventory"] = {}}, ["param2"] = 9, ["y"] = 11, ["param1"] = 238, ["z"] = 5, ["name"] = "rainbow:slope_lightglass_red"}, {["x"] = 6, ["meta"] = {["fields"] = {}, ["inventory"] = {}}, ["param2"] = 5, ["y"] = 11, ["param1"] = 238, ["z"] = 9, ["name"] = "rainbow:slope_lightglass_red"}, {["x"] = 6, ["meta"] = {["fields"] = {}, ["inventory"] = {}}, ["param2"] = 9, ["y"] = 12, ["param1"] = 238, ["z"] = 5, ["name"] = "rainbow:slope_lightglass_black"}, {["x"] = 6, ["meta"] = {["fields"] = {}, ["inventory"] = {}}, ["param2"] = 18, ["y"] = 12, ["param1"] = 238, ["z"] = 9, ["name"] = "rainbow:slope_lightglass_black"}, {["x"] = 6, ["meta"] = {["fields"] = {}, ["inventory"] = {}}, ["param2"] = 9, ["y"] = 13, ["param1"] = 238, ["z"] = 5, ["name"] = "rainbow:slope_lightglass_red"}, {["x"] = 6, ["meta"] = {["fields"] = {}, ["inventory"] = {}}, ["param2"] = 18, ["y"] = 13, ["param1"] = 238, ["z"] = 9, ["name"] = "rainbow:slope_lightglass_red"}, {["x"] = 6, ["meta"] = {["fields"] = {}, ["inventory"] = {}}, ["param2"] = 1, ["y"] = 14, ["param1"] = 206, ["z"] = 4, ["name"] = "rainbow:slope_stone_darkgrey_outer_cut"}, {["x"] = 6, ["meta"] = {["fields"] = {}, ["inventory"] = {}}, ["param2"] = 1, ["y"] = 14, ["param1"] = 221, ["z"] = 5, ["name"] = "rainbow:slope_stone_black_inner_cut"}, {["x"] = 6, ["meta"] = {["fields"] = {}, ["inventory"] = {}}, ["param2"] = 2, ["y"] = 14, ["param1"] = 221, ["z"] = 9, ["name"] = "rainbow:slope_stone_black_inner_cut"}, {["x"] = 6, ["meta"] = {["fields"] = {}, ["inventory"] = {}}, ["param2"] = 2, ["y"] = 14, ["param1"] = 206, ["z"] = 10, ["name"] = "rainbow:slope_stone_darkgrey_outer_cut"}, {["x"] = 6, ["meta"] = {["fields"] = {}, ["inventory"] = {}}, ["param2"] = 1, ["y"] = 15, ["param1"] = 206, ["z"] = 5, ["name"] = "rainbow:slope_stone_black_outer_cut"}, {["x"] = 6, ["meta"] = {["fields"] = {}, ["inventory"] = {}}, ["param2"] = 1, ["y"] = 15, ["param1"] = 189, ["z"] = 6, ["name"] = "rainbow:slope_stone_darkgrey_inner_cut"}, {["x"] = 6, ["meta"] = {["fields"] = {}, ["inventory"] = {}}, ["param2"] = 2, ["y"] = 15, ["param1"] = 189, ["z"] = 8, ["name"] = "rainbow:slope_stone_darkgrey_inner_cut"}, {["x"] = 6, ["meta"] = {["fields"] = {}, ["inventory"] = {}}, ["param2"] = 2, ["y"] = 15, ["param1"] = 206, ["z"] = 9, ["name"] = "rainbow:slope_stone_black_outer_cut"}, {["x"] = 6, ["meta"] = {["fields"] = {}, ["inventory"] = {}}, ["param2"] = 1, ["y"] = 16, ["param1"] = 174, ["z"] = 6, ["name"] = "rainbow:slope_stone_darkgrey_outer_cut"}, {["x"] = 6, ["meta"] = {["fields"] = {}, ["inventory"] = {}}, ["param2"] = 1, ["y"] = 16, ["param1"] = 158, ["z"] = 7, ["name"] = "rainbow:slope_stone_black"}, {["x"] = 6, ["meta"] = {["fields"] = {}, ["inventory"] = {}}, ["param2"] = 2, ["y"] = 16, ["param1"] = 174, ["z"] = 8, ["name"] = "rainbow:slope_stone_darkgrey_outer_cut"}, {["x"] = 7, ["meta"] = {["fields"] = {}, ["inventory"] = {}}, ["y"] = 0, ["z"] = 2, ["name"] = "rainbow:dirt_black"}, {["x"] = 7, ["meta"] = {["fields"] = {}, ["inventory"] = {}}, ["y"] = 0, ["z"] = 3, ["name"] = "rainbow:stone_black"}, {["x"] = 7, ["meta"] = {["fields"] = {}, ["inventory"] = {}}, ["y"] = 0, ["z"] = 4, ["name"] = "rainbow:stone_black"}, {["x"] = 7, ["meta"] = {["fields"] = {}, ["inventory"] = {}}, ["y"] = 0, ["z"] = 5, ["name"] = "rainbow:stone_black"}, {["x"] = 7, ["meta"] = {["fields"] = {}, ["inventory"] = {}}, ["y"] = 0, ["z"] = 6, ["name"] = "rainbow:stone_black"}, {["x"] = 7, ["meta"] = {["fields"] = {}, ["inventory"] = {}}, ["y"] = 0, ["z"] = 7, ["name"] = "rainbow:stone_black"}, {["x"] = 7, ["meta"] = {["fields"] = {}, ["inventory"] = {}}, ["y"] = 0, ["z"] = 8, ["name"] = "rainbow:stone_black"}, {["x"] = 7, ["meta"] = {["fields"] = {}, ["inventory"] = {}}, ["y"] = 0, ["z"] = 9, ["name"] = "rainbow:stone_black"}, {["x"] = 7, ["meta"] = {["fields"] = {}, ["inventory"] = {}}, ["y"] = 0, ["z"] = 10, ["name"] = "rainbow:dirt_black"}, {["x"] = 7, ["meta"] = {["fields"] = {}, ["inventory"] = {}}, ["y"] = 0, ["z"] = 11, ["name"] = "rainbow:stone_black"}, {["x"] = 7, ["meta"] = {["fields"] = {}, ["inventory"] = {}}, ["y"] = 0, ["z"] = 12, ["name"] = "rainbow:dirt_black"}, {["x"] = 7, ["meta"] = {["fields"] = {}, ["inventory"] = {}}, ["param2"] = 10, ["y"] = 1, ["param1"] = 206, ["z"] = 1, ["name"] = "rainbow:slab_stone_black_1"}, {["x"] = 7, ["meta"] = {["fields"] = {}, ["inventory"] = {}}, ["param2"] = 18, ["y"] = 1, ["z"] = 2, ["name"] = "rainbow:tree_black"}, {["x"] = 7, ["meta"] = {["fields"] = {}, ["inventory"] = {}}, ["y"] = 1, ["z"] = 3, ["name"] = "rainbow:wood_black"}, {["x"] = 7, ["meta"] = {["fields"] = {}, ["inventory"] = {}}, ["y"] = 1, ["z"] = 4, ["name"] = "rainbow:wood_red"}, {["x"] = 7, ["meta"] = {["fields"] = {}, ["inventory"] = {}}, ["y"] = 1, ["z"] = 5, ["name"] = "rainbow:wood_red"}, {["x"] = 7, ["meta"] = {["fields"] = {}, ["inventory"] = {}}, ["y"] = 1, ["z"] = 6, ["name"] = "rainbow:wood_black"}, {["x"] = 7, ["meta"] = {["fields"] = {}, ["inventory"] = {}}, ["y"] = 1, ["z"] = 8, ["name"] = "rainbow:wood_black"}, {["x"] = 7, ["meta"] = {["fields"] = {}, ["inventory"] = {}}, ["y"] = 1, ["z"] = 9, ["name"] = "rainbow:wood_red"}, {["x"] = 7, ["meta"] = {["fields"] = {}, ["inventory"] = {}}, ["y"] = 1, ["z"] = 10, ["name"] = "rainbow:wood_red"}, {["x"] = 7, ["meta"] = {["fields"] = {}, ["inventory"] = {}}, ["y"] = 1, ["z"] = 11, ["name"] = "rainbow:wood_black"}, {["x"] = 7, ["meta"] = {["fields"] = {}, ["inventory"] = {}}, ["param2"] = 18, ["y"] = 1, ["z"] = 12, ["name"] = "rainbow:tree_black"}, {["x"] = 7, ["meta"] = {["fields"] = {}, ["inventory"] = {}}, ["param2"] = 4, ["y"] = 1, ["param1"] = 206, ["z"] = 13, ["name"] = "rainbow:slab_stone_black_1"}, {["x"] = 7, ["meta"] = {["fields"] = {}, ["inventory"] = {}}, ["param2"] = 10, ["y"] = 2, ["param1"] = 222, ["z"] = 1, ["name"] = "rainbow:slab_stone_black_1"}, {["x"] = 7, ["meta"] = {["fields"] = {}, ["inventory"] = {}}, ["param2"] = 1, ["y"] = 2, ["param1"] = 204, ["z"] = 6, ["name"] = "rainbow:stair_wood_yellow_alt_1"}, {["x"] = 7, ["meta"] = {["fields"] = {}, ["inventory"] = {}}, ["param2"] = 4, ["y"] = 2, ["param1"] = 222, ["z"] = 13, ["name"] = "rainbow:slab_stone_black_1"}, {["x"] = 7, ["meta"] = {["fields"] = {}, ["inventory"] = {}}, ["param2"] = 8, ["y"] = 3, ["param1"] = 238, ["z"] = 1, ["name"] = "rainbow:slab_lightglass_red_1"}, {["x"] = 7, ["meta"] = {["fields"] = {}, ["inventory"] = {}}, ["param2"] = 8, ["y"] = 3, ["param1"] = 238, ["z"] = 5, ["name"] = "rainbow:slab_lightcoolglass_yellow_1"}, {["x"] = 7, ["meta"] = {["fields"] = {}, ["inventory"] = {}}, ["param2"] = 7, ["y"] = 3, ["param1"] = 238, ["z"] = 13, ["name"] = "rainbow:slab_lightglass_red_1"}, {["x"] = 7, ["meta"] = {["fields"] = {}, ["inventory"] = {}}, ["param2"] = 10, ["y"] = 4, ["param1"] = 222, ["z"] = 1, ["name"] = "rainbow:slab_wood_black_1"}, {["x"] = 7, ["meta"] = {["fields"] = {}, ["inventory"] = {}}, ["param2"] = 4, ["y"] = 4, ["param1"] = 222, ["z"] = 13, ["name"] = "rainbow:slab_wood_black_1"}, {["x"] = 7, ["meta"] = {["fields"] = {}, ["inventory"] = {}}, ["param2"] = 10, ["y"] = 5, ["param1"] = 206, ["z"] = 1, ["name"] = "rainbow:slab_stone_black_1"}, {["x"] = 7, ["meta"] = {["fields"] = {}, ["inventory"] = {}}, ["param2"] = 22, ["y"] = 5, ["param1"] = 205, ["z"] = 2, ["name"] = "rainbow:slab_stone_black_1"}, {["x"] = 7, ["meta"] = {["fields"] = {}, ["inventory"] = {}}, ["param2"] = 22, ["y"] = 5, ["param1"] = 221, ["z"] = 3, ["name"] = "rainbow:slab_wood_black_1"}, {["x"] = 7, ["meta"] = {["fields"] = {}, ["inventory"] = {}}, ["param2"] = 22, ["y"] = 5, ["param1"] = 204, ["z"] = 4, ["name"] = "rainbow:slab_wood_red_1"}, {["x"] = 7, ["meta"] = {["fields"] = {}, ["inventory"] = {}}, ["param2"] = 22, ["y"] = 5, ["param1"] = 221, ["z"] = 5, ["name"] = "rainbow:slab_wood_red_1"}, {["x"] = 7, ["meta"] = {["fields"] = {}, ["inventory"] = {}}, ["param2"] = 20, ["y"] = 5, ["param1"] = 221, ["z"] = 9, ["name"] = "rainbow:slab_wood_red_1"}, {["x"] = 7, ["meta"] = {["fields"] = {}, ["inventory"] = {}}, ["param2"] = 20, ["y"] = 5, ["param1"] = 204, ["z"] = 10, ["name"] = "rainbow:slab_wood_red_1"}, {["x"] = 7, ["meta"] = {["fields"] = {}, ["inventory"] = {}}, ["param2"] = 20, ["y"] = 5, ["param1"] = 221, ["z"] = 11, ["name"] = "rainbow:slab_wood_black_1"}, {["x"] = 7, ["meta"] = {["fields"] = {}, ["inventory"] = {}}, ["param2"] = 20, ["y"] = 5, ["param1"] = 205, ["z"] = 12, ["name"] = "rainbow:slab_stone_black_1"}, {["x"] = 7, ["meta"] = {["fields"] = {}, ["inventory"] = {}}, ["param2"] = 4, ["y"] = 5, ["param1"] = 206, ["z"] = 13, ["name"] = "rainbow:slab_stone_black_1"}, {["x"] = 7, ["meta"] = {["fields"] = {}, ["inventory"] = {}}, ["param2"] = 10, ["y"] = 6, ["param1"] = 190, ["z"] = 2, ["name"] = "rainbow:slab_wood_black_1"}, {["x"] = 7, ["meta"] = {["fields"] = {}, ["inventory"] = {}}, ["param2"] = 8, ["y"] = 6, ["param1"] = 238, ["z"] = 5, ["name"] = "rainbow:slab_lightcoolglass_yellow_1"}, {["x"] = 7, ["meta"] = {["fields"] = {}, ["inventory"] = {}}, ["param2"] = 3, ["y"] = 6, ["param1"] = 221, ["z"] = 8, ["name"] = "rainbow:stair_wood_yellow_alt_1"}, {["x"] = 7, ["meta"] = {["fields"] = {}, ["inventory"] = {}}, ["param2"] = 4, ["y"] = 6, ["param1"] = 238, ["z"] = 9, ["name"] = "rainbow:slab_lightcoolglass_yellow_1"}, {["x"] = 7, ["meta"] = {["fields"] = {}, ["inventory"] = {}}, ["param2"] = 4, ["y"] = 6, ["param1"] = 190, ["z"] = 12, ["name"] = "rainbow:slab_wood_black_1"}, {["x"] = 7, ["meta"] = {["fields"] = {}, ["inventory"] = {}}, ["param2"] = 10, ["y"] = 7, ["param1"] = 174, ["z"] = 2, ["name"] = "rainbow:slab_wood_red_1"}, {["x"] = 7, ["meta"] = {["fields"] = {}, ["inventory"] = {}}, ["param2"] = 4, ["y"] = 7, ["param1"] = 238, ["z"] = 9, ["name"] = "rainbow:slab_lightcoolglass_yellow_1"}, {["x"] = 7, ["meta"] = {["fields"] = {}, ["inventory"] = {}}, ["param2"] = 4, ["y"] = 7, ["param1"] = 190, ["z"] = 12, ["name"] = "rainbow:slab_wood_red_1"}, {["x"] = 7, ["meta"] = {["fields"] = {}, ["inventory"] = {}}, ["param2"] = 10, ["y"] = 8, ["param1"] = 158, ["z"] = 2, ["name"] = "rainbow:slab_wood_black_1"}, {["x"] = 7, ["meta"] = {["fields"] = {}, ["inventory"] = {}}, ["param2"] = 20, ["y"] = 8, ["param1"] = 174, ["z"] = 3, ["name"] = "rainbow:slab_wood_black_1"}, {["x"] = 7, ["meta"] = {["fields"] = {}, ["inventory"] = {}}, ["param2"] = 22, ["y"] = 8, ["param1"] = 189, ["z"] = 4, ["name"] = "rainbow:slab_wood_black_1"}, {["x"] = 7, ["meta"] = {["fields"] = {}, ["inventory"] = {}}, ["param2"] = 21, ["y"] = 8, ["param1"] = 204, ["z"] = 5, ["name"] = "rainbow:slab_coolglass_black_1"}, {["x"] = 7, ["meta"] = {["fields"] = {}, ["inventory"] = {}}, ["param2"] = 1, ["y"] = 8, ["param1"] = 187, ["z"] = 6, ["name"] = "rainbow:stair_wood_yellow_alt_1"}, {["x"] = 7, ["meta"] = {["fields"] = {}, ["inventory"] = {}}, ["param2"] = 20, ["y"] = 8, ["param1"] = 205, ["z"] = 10, ["name"] = "rainbow:slab_wood_black_1"}, {["x"] = 7, ["meta"] = {["fields"] = {}, ["inventory"] = {}}, ["param2"] = 20, ["y"] = 8, ["param1"] = 190, ["z"] = 11, ["name"] = "rainbow:slab_wood_black_1"}, {["x"] = 7, ["meta"] = {["fields"] = {}, ["inventory"] = {}}, ["param2"] = 4, ["y"] = 8, ["param1"] = 174, ["z"] = 12, ["name"] = "rainbow:slab_wood_black_1"}, {["x"] = 7, ["meta"] = {["fields"] = {}, ["inventory"] = {}}, ["param2"] = 10, ["y"] = 9, ["param1"] = 206, ["z"] = 4, ["name"] = "rainbow:slab_wood_red_1"}, {["x"] = 7, ["meta"] = {["fields"] = {}, ["inventory"] = {}}, ["param2"] = 6, ["y"] = 9, ["param1"] = 221, ["z"] = 9, ["name"] = "rainbow:panel_coolglass_yellow_1"}, {["x"] = 7, ["meta"] = {["fields"] = {}, ["inventory"] = {}}, ["param2"] = 4, ["y"] = 9, ["param1"] = 206, ["z"] = 10, ["name"] = "rainbow:slab_wood_red_1"}, {["x"] = 7, ["meta"] = {["fields"] = {}, ["inventory"] = {}}, ["param2"] = 10, ["y"] = 10, ["param1"] = 206, ["z"] = 4, ["name"] = "rainbow:slab_wood_black_1"}, {["x"] = 7, ["meta"] = {["fields"] = {}, ["inventory"] = {}}, ["param2"] = 4, ["y"] = 10, ["param1"] = 206, ["z"] = 10, ["name"] = "rainbow:slab_wood_black_1"}, {["x"] = 7, ["meta"] = {["fields"] = {}, ["inventory"] = {}}, ["param2"] = 10, ["y"] = 11, ["param1"] = 206, ["z"] = 4, ["name"] = "rainbow:slab_wood_red_1"}, {["x"] = 7, ["meta"] = {["fields"] = {}, ["inventory"] = {}}, ["param2"] = 4, ["y"] = 11, ["param1"] = 206, ["z"] = 10, ["name"] = "rainbow:slab_wood_red_1"}, {["x"] = 7, ["meta"] = {["fields"] = {}, ["inventory"] = {}}, ["param2"] = 10, ["y"] = 12, ["param1"] = 206, ["z"] = 4, ["name"] = "rainbow:slab_wood_black_1"}, {["x"] = 7, ["meta"] = {["fields"] = {}, ["inventory"] = {}}, ["param2"] = 4, ["y"] = 12, ["param1"] = 206, ["z"] = 10, ["name"] = "rainbow:slab_wood_black_1"}, {["x"] = 7, ["meta"] = {["fields"] = {}, ["inventory"] = {}}, ["param2"] = 10, ["y"] = 13, ["param1"] = 206, ["z"] = 4, ["name"] = "rainbow:slab_wood_red_1"}, {["x"] = 7, ["meta"] = {["fields"] = {}, ["inventory"] = {}}, ["param2"] = 4, ["y"] = 13, ["param1"] = 206, ["z"] = 10, ["name"] = "rainbow:slab_wood_red_1"}, {["x"] = 7, ["meta"] = {["fields"] = {}, ["inventory"] = {}}, ["y"] = 14, ["param1"] = 190, ["z"] = 4, ["name"] = "rainbow:slope_stone_black"}, {["x"] = 7, ["meta"] = {["fields"] = {}, ["inventory"] = {}}, ["param2"] = 2, ["y"] = 14, ["param1"] = 190, ["z"] = 10, ["name"] = "rainbow:slope_stone_black"}, {["x"] = 7, ["meta"] = {["fields"] = {}, ["inventory"] = {}}, ["y"] = 15, ["param1"] = 190, ["z"] = 5, ["name"] = "rainbow:slope_stone_darkgrey"}, {["x"] = 7, ["meta"] = {["fields"] = {}, ["inventory"] = {}}, ["param2"] = 2, ["y"] = 15, ["param1"] = 190, ["z"] = 9, ["name"] = "rainbow:slope_stone_darkgrey"}, {["x"] = 7, ["meta"] = {["fields"] = {}, ["inventory"] = {}}, ["y"] = 16, ["param1"] = 158, ["z"] = 6, ["name"] = "rainbow:slope_stone_black"}, {["x"] = 7, ["meta"] = {["fields"] = {["banner"] = "(bg_white.png^[mask:mask_background.png^[makealpha:0,0,0)^(bg_white.png^[mask:fullpentagram.png^[makealpha:0,0,0)^(bg_white.png^[mask:fullpentagram.png^[makealpha:0,0,0)^(bg_white.png^[mask:mask_background.png^[makealpha:0,0,0)^(bg_white.png^[mask:mask_background.png^[makealpha:0,0,0)^(bg_violet.png^[mask:chevron_top.png^[makealpha:0,0,0)^(bg_violet.png^[mask:chevron_top.png^[makealpha:0,0,0)^(bg_violet.png^[mask:chevron_top.png^[makealpha:0,0,0)^(bg_violet.png^[mask:chevron_top.png^[makealpha:0,0,0)^(bg_violet.png^[mask:fullpentagram.png^[makealpha:0,0,0)^(bg_violet.png^[mask:chevron_bottom.png^[makealpha:0,0,0)^(bg_white.png^[mask:mask_background.png^[makealpha:0,0,0)^(bg_white.png^[mask:mask_background.png^[makealpha:0,0,0)^(bg_white.png^[mask:mask_background.png^[makealpha:0,0,0)^(bg_white.png^[mask:mask_background.png^[makealpha:0,0,0)^(bg_white.png^[mask:mask_background.png^[makealpha:0,0,0)^(bg_white.png^[mask:chevron_top.png^[makealpha:0,0,0)^(bg_white.png^[mask:chevron_top.png^[makealpha:0,0,0)^(bg_white.png^[mask:chevron_top.png^[makealpha:0,0,0)^(bg_white.png^[mask:chevron_top.png^[makealpha:0,0,0)^(bg_white.png^[mask:chevron_top.png^[makealpha:0,0,0)^(bg_cyan.png^[mask:chevron_top.png^[makealpha:0,0,0)^(bg_cyan.png^[mask:hilal.png^[makealpha:0,0,0)^(bg_cyan.png^[mask:chevron_bottom.png^[makealpha:0,0,0)^(bg_white.png^[mask:mask_background.png^[makealpha:0,0,0)^(bg_white.png^[mask:mask_background.png^[makealpha:0,0,0)^(bg_white.png^[mask:mask_background.png^[makealpha:0,0,0)^(bg_black.png^[mask:mask_background.png^[makealpha:0,0,0)^(bg_red.png^[mask:stripes_horiz_4.png^[makealpha:0,0,0)^(bg_yellow.png^[mask:fleur_de_lis.png^[makealpha:0,0,0)^(bg_yellow.png^[mask:fleur_de_lis.png^[makealpha:0,0,0)^(bg_white.png^[mask:mask_background.png^[makealpha:0,0,0)^(bg_black.png^[mask:stripes_horiz_4.png^[makealpha:0,0,0)^(bg_red.png^[mask:mask_background.png^[makealpha:0,0,0)^(bg_black.png^[mask:mask_background.png^[makealpha:0,0,0)^(bg_red.png^[mask:stripes_horiz_4.png^[makealpha:0,0,0)^(bg_red.png^[mask:fleur_de_lis.png^[makealpha:0,0,0)^(bg_yellow.png^[mask:fleur_de_lis.png^[makealpha:0,0,0)^(bg_white.png^[mask:mask_background.png^[makealpha:0,0,0)^(bg_white.png^[mask:mask_background.png^[makealpha:0,0,0)^(bg_red.png^[mask:mask_background.png^[makealpha:0,0,0)^(bg_black.png^[mask:fleur_de_lis.png^[makealpha:0,0,0)^(bg_white.png^[mask:mask_background.png^[makealpha:0,0,0)^(bg_black.png^[mask:mask_background.png^[makealpha:0,0,0)^(bg_red.png^[mask:fleur_de_lis.png^[makealpha:0,0,0)^(bg_white.png^[mask:mask_background.png^[makealpha:0,0,0)^(bg_white.png^[mask:mask_background.png^[makealpha:0,0,0)^(bg_red.png^[mask:mask_background.png^[makealpha:0,0,0)^(bg_red.png^[mask:fleur_de_lis.png^[makealpha:0,0,0)^(bg_black.png^[mask:fleur_de_lis.png^[makealpha:0,0,0)"}, ["inventory"] = {}}, ["param2"] = 2, ["y"] = 16, ["param1"] = 142, ["z"] = 7, ["name"] = "banners:wooden_banner"}, {["x"] = 7, ["meta"] = {["fields"] = {}, ["inventory"] = {}}, ["param2"] = 2, ["y"] = 16, ["param1"] = 158, ["z"] = 8, ["name"] = "rainbow:slope_stone_black"}, {["x"] = 8, ["meta"] = {["fields"] = {}, ["inventory"] = {}}, ["y"] = 0, ["z"] = 2, ["name"] = "rainbow:stone_black"}, {["x"] = 8, ["meta"] = {["fields"] = {}, ["inventory"] = {}}, ["y"] = 0, ["z"] = 3, ["name"] = "rainbow:stone_black"}, {["x"] = 8, ["meta"] = {["fields"] = {}, ["inventory"] = {}}, ["y"] = 0, ["z"] = 4, ["name"] = "rainbow:stone_black"}, {["x"] = 8, ["meta"] = {["fields"] = {}, ["inventory"] = {}}, ["y"] = 0, ["z"] = 5, ["name"] = "rainbow:stone_black"}, {["x"] = 8, ["meta"] = {["fields"] = {}, ["inventory"] = {}}, ["y"] = 0, ["z"] = 6, ["name"] = "rainbow:stone_black"}, {["x"] = 8, ["meta"] = {["fields"] = {}, ["inventory"] = {}}, ["y"] = 0, ["z"] = 7, ["name"] = "rainbow:stone_black"}, {["x"] = 8, ["meta"] = {["fields"] = {}, ["inventory"] = {}}, ["y"] = 0, ["z"] = 8, ["name"] = "rainbow:stone_black"}, {["x"] = 8, ["meta"] = {["fields"] = {}, ["inventory"] = {}}, ["y"] = 0, ["z"] = 9, ["name"] = "rainbow:stone_black"}, {["x"] = 8, ["meta"] = {["fields"] = {}, ["inventory"] = {}}, ["y"] = 0, ["z"] = 10, ["name"] = "rainbow:stone_black"}, {["x"] = 8, ["meta"] = {["fields"] = {}, ["inventory"] = {}}, ["y"] = 0, ["z"] = 11, ["name"] = "rainbow:stone_black"}, {["x"] = 8, ["meta"] = {["fields"] = {}, ["inventory"] = {}}, ["y"] = 0, ["z"] = 12, ["name"] = "rainbow:dirt_black"}, {["x"] = 8, ["meta"] = {["fields"] = {}, ["inventory"] = {}}, ["param2"] = 10, ["y"] = 1, ["param1"] = 190, ["z"] = 1, ["name"] = "rainbow:slab_stone_black_1"}, {["x"] = 8, ["meta"] = {["fields"] = {}, ["inventory"] = {}}, ["param2"] = 18, ["y"] = 1, ["z"] = 2, ["name"] = "rainbow:tree_black"}, {["x"] = 8, ["meta"] = {["fields"] = {}, ["inventory"] = {}}, ["y"] = 1, ["z"] = 3, ["name"] = "rainbow:wood_black"}, {["x"] = 8, ["meta"] = {["fields"] = {}, ["inventory"] = {}}, ["y"] = 1, ["z"] = 4, ["name"] = "rainbow:wood_red"}, {["x"] = 8, ["meta"] = {["fields"] = {}, ["inventory"] = {}}, ["y"] = 1, ["z"] = 5, ["name"] = "rainbow:wood_red"}, {["x"] = 8, ["meta"] = {["fields"] = {}, ["inventory"] = {}}, ["y"] = 1, ["z"] = 6, ["name"] = "rainbow:wood_black"}, {["x"] = 8, ["meta"] = {["fields"] = {},