5:return {{["x"] = 0, ["meta"] = {["fields"] = {}, ["inventory"] = {}}, ["param2"] = 1, ["y"] = 0, ["param1"] = 206, ["z"] = 0, ["name"] = "stairs:stair_outer_black"}, {["x"] = 0, ["meta"] = {["fields"] = {}, ["inventory"] = {}}, ["param2"] = 1, ["y"] = 0, ["param1"] = 222, ["z"] = 1, ["name"] = "stairs:stair_black"}, {["x"] = 0, ["meta"] = {["fields"] = {}, ["inventory"] = {}}, ["param2"] = 1, ["y"] = 0, ["param1"] = 222, ["z"] = 2, ["name"] = "stairs:stair_black"}, {["x"] = 0, ["meta"] = {["fields"] = {}, ["inventory"] = {}}, ["param2"] = 1, ["y"] = 0, ["param1"] = 222, ["z"] = 3, ["name"] = "stairs:stair_black"}, {["x"] = 0, ["meta"] = {["fields"] = {}, ["inventory"] = {}}, ["param2"] = 1, ["y"] = 0, ["param1"] = 222, ["z"] = 4, ["name"] = "stairs:stair_black"}, {["x"] = 0, ["meta"] = {["fields"] = {}, ["inventory"] = {}}, ["param2"] = 1, ["y"] = 0, ["param1"] = 222, ["z"] = 5, ["name"] = "stairs:stair_black"}, {["x"] = 0, ["meta"] = {["fields"] = {}, ["inventory"] = {}}, ["param2"] = 1, ["y"] = 0, ["param1"] = 222, ["z"] = 6, ["name"] = "stairs:stair_black"}, {["x"] = 0, ["meta"] = {["fields"] = {}, ["inventory"] = {}}, ["param2"] = 1, ["y"] = 0, ["param1"] = 222, ["z"] = 7, ["name"] = "stairs:stair_black"}, {["x"] = 0, ["meta"] = {["fields"] = {}, ["inventory"] = {}}, ["param2"] = 1, ["y"] = 0, ["param1"] = 222, ["z"] = 8, ["name"] = "stairs:stair_black"}, {["x"] = 0, ["meta"] = {["fields"] = {}, ["inventory"] = {}}, ["param2"] = 1, ["y"] = 0, ["param1"] = 222, ["z"] = 9, ["name"] = "stairs:stair_black"}, {["x"] = 0, ["meta"] = {["fields"] = {}, ["inventory"] = {}}, ["param2"] = 1, ["y"] = 0, ["param1"] = 222, ["z"] = 10, ["name"] = "stairs:stair_black"}, {["x"] = 0, ["meta"] = {["fields"] = {}, ["inventory"] = {}}, ["param2"] = 1, ["y"] = 0, ["param1"] = 222, ["z"] = 11, ["name"] = "stairs:stair_black"}, {["x"] = 0, ["meta"] = {["fields"] = {}, ["inventory"] = {}}, ["param2"] = 2, ["y"] = 0, ["param1"] = 206, ["z"] = 12, ["name"] = "stairs:stair_outer_black"}, {["x"] = 1, ["meta"] = {["fields"] = {}, ["inventory"] = {}}, ["y"] = 0, ["param1"] = 222, ["z"] = 0, ["name"] = "stairs:stair_black"}, {["x"] = 1, ["meta"] = {["fields"] = {}, ["inventory"] = {}}, ["y"] = 0, ["param1"] = 238, ["z"] = 1, ["name"] = "light:blue"}, {["x"] = 1, ["meta"] = {["fields"] = {}, ["inventory"] = {}}, ["y"] = 0, ["param1"] = 238, ["z"] = 2, ["name"] = "light:blue"}, {["x"] = 1, ["meta"] = {["fields"] = {}, ["inventory"] = {}}, ["y"] = 0, ["param1"] = 238, ["z"] = 3, ["name"] = "light:blue"}, {["x"] = 1, ["meta"] = {["fields"] = {}, ["inventory"] = {}}, ["y"] = 0, ["param1"] = 238, ["z"] = 4, ["name"] = "light:blue"}, {["x"] = 1, ["meta"] = {["fields"] = {}, ["inventory"] = {}}, ["y"] = 0, ["param1"] = 238, ["z"] = 5, ["name"] = "light:blue"}, {["x"] = 1, ["meta"] = {["fields"] = {}, ["inventory"] = {}}, ["y"] = 0, ["param1"] = 238, ["z"] = 6, ["name"] = "light:blue"}, {["x"] = 1, ["meta"] = {["fields"] = {}, ["inventory"] = {}}, ["y"] = 0, ["param1"] = 238, ["z"] = 7, ["name"] = "light:blue"}, {["x"] = 1, ["meta"] = {["fields"] = {}, ["inventory"] = {}}, ["y"] = 0, ["param1"] = 238, ["z"] = 8, ["name"] = "light:blue"}, {["x"] = 1, ["meta"] = {["fields"] = {}, ["inventory"] = {}}, ["y"] = 0, ["param1"] = 238, ["z"] = 9, ["name"] = "light:blue"}, {["x"] = 1, ["meta"] = {["fields"] = {}, ["inventory"] = {}}, ["y"] = 0, ["param1"] = 238, ["z"] = 10, ["name"] = "light:blue"}, {["x"] = 1, ["meta"] = {["fields"] = {}, ["inventory"] = {}}, ["y"] = 0, ["param1"] = 238, ["z"] = 11, ["name"] = "light:blue"}, {["x"] = 1, ["meta"] = {["fields"] = {}, ["inventory"] = {}}, ["param2"] = 2, ["y"] = 0, ["param1"] = 222, ["z"] = 12, ["name"] = "stairs:stair_black"}, {["x"] = 1, ["meta"] = {["fields"] = {}, ["inventory"] = {}}, ["y"] = 1, ["param1"] = 222, ["z"] = 1, ["name"] = "slope:cone_blue"}, {["x"] = 1, ["meta"] = {["fields"] = {}, ["inventory"] = {}}, ["param2"] = 1, ["y"] = 1, ["param1"] = 222, ["z"] = 3, ["name"] = "slope:cone_blue"}, {["x"] = 1, ["meta"] = {["fields"] = {}, ["inventory"] = {}}, ["param2"] = 1, ["y"] = 1, ["param1"] = 222, ["z"] = 5, ["name"] = "slope:cone_blue"}, {["x"] = 1, ["meta"] = {["fields"] = {}, ["inventory"] = {}}, ["param2"] = 1, ["y"] = 1, ["param1"] = 222, ["z"] = 7, ["name"] = "slope:cone_blue"}, {["x"] = 1, ["meta"] = {["fields"] = {}, ["inventory"] = {}}, ["param2"] = 1, ["y"] = 1, ["param1"] = 222, ["z"] = 9, ["name"] = "slope:cone_blue"}, {["x"] = 1, ["meta"] = {["fields"] = {}, ["inventory"] = {}}, ["param2"] = 1, ["y"] = 1, ["param1"] = 222, ["z"] = 11, ["name"] = "slope:cone_blue"}, {["x"] = 1, ["meta"] = {["fields"] = {}, ["inventory"] = {}}, ["y"] = 2, ["param1"] = 206, ["z"] = 1, ["name"] = "slope:sphere_red"}, {["x"] = 1, ["meta"] = {["fields"] = {}, ["inventory"] = {}}, ["param2"] = 1, ["y"] = 2, ["param1"] = 206, ["z"] = 3, ["name"] = "slope:sphere_blue"}, {["x"] = 1, ["meta"] = {["fields"] = {}, ["inventory"] = {}}, ["param2"] = 1, ["y"] = 2, ["param1"] = 206, ["z"] = 5, ["name"] = "slope:sphere_green"}, {["x"] = 1, ["meta"] = {["fields"] = {}, ["inventory"] = {}}, ["param2"] = 1, ["y"] = 2, ["param1"] = 206, ["z"] = 7, ["name"] = "slope:sphere_pink"}, {["x"] = 1, ["meta"] = {["fields"] = {}, ["inventory"] = {}}, ["param2"] = 1, ["y"] = 2, ["param1"] = 206, ["z"] = 9, ["name"] = "slope:sphere_orange"}, {["x"] = 1, ["meta"] = {["fields"] = {}, ["inventory"] = {}}, ["param2"] = 1, ["y"] = 2, ["param1"] = 206, ["z"] = 11, ["name"] = "slope:sphere_red"}, {["x"] = 1, ["meta"] = {["fields"] = {}, ["inventory"] = {}}, ["param2"] = 23, ["y"] = 3, ["param1"] = 190, ["z"] = 1, ["name"] = "slope:cone_blue"}, {["x"] = 1, ["meta"] = {["fields"] = {}, ["inventory"] = {}}, ["param2"] = 23, ["y"] = 3, ["param1"] = 190, ["z"] = 3, ["name"] = "slope:cone_blue"}, {["x"] = 1, ["meta"] = {["fields"] = {}, ["inventory"] = {}}, ["param2"] = 23, ["y"] = 3, ["param1"] = 190, ["z"] = 5, ["name"] = "slope:cone_blue"}, {["x"] = 1, ["meta"] = {["fields"] = {}, ["inventory"] = {}}, ["param2"] = 23, ["y"] = 3, ["param1"] = 190, ["z"] = 7, ["name"] = "slope:cone_blue"}, {["x"] = 1, ["meta"] = {["fields"] = {}, ["inventory"] = {}}, ["param2"] = 23, ["y"] = 3, ["param1"] = 190, ["z"] = 9, ["name"] = "slope:cone_blue"}, {["x"] = 1, ["meta"] = {["fields"] = {}, ["inventory"] = {}}, ["param2"] = 22, ["y"] = 3, ["param1"] = 190, ["z"] = 11, ["name"] = "slope:cone_blue"}, {["x"] = 1, ["meta"] = {["fields"] = {}, ["inventory"] = {}}, ["param2"] = 1, ["y"] = 4, ["param1"] = 174, ["z"] = 1, ["name"] = "slope:ocorner_blue"}, {["x"] = 1, ["meta"] = {["fields"] = {}, ["inventory"] = {}}, ["param2"] = 1, ["y"] = 4, ["param1"] = 174, ["z"] = 2, ["name"] = "slope:slopelong_blue"}, {["x"] = 1, ["meta"] = {["fields"] = {}, ["inventory"] = {}}, ["param2"] = 1, ["y"] = 4, ["param1"] = 174, ["z"] = 3, ["name"] = "slope:slopelong_blue"}, {["x"] = 1, ["meta"] = {["fields"] = {}, ["inventory"] = {}}, ["param2"] = 1, ["y"] = 4, ["param1"] = 174, ["z"] = 4, ["name"] = "slope:slopelong_blue"}, {["x"] = 1, ["meta"] = {["fields"] = {}, ["inventory"] = {}}, ["param2"] = 1, ["y"] = 4, ["param1"] = 174, ["z"] = 5, ["name"] = "slope:slopelong_blue"}, {["x"] = 1, ["meta"] = {["fields"] = {}, ["inventory"] = {}}, ["param2"] = 1, ["y"] = 4, ["param1"] = 174, ["z"] = 7, ["name"] = "slope:slopelong_blue"}, {["x"] = 1, ["meta"] = {["fields"] = {}, ["inventory"] = {}}, ["param2"] = 1, ["y"] = 4, ["param1"] = 174, ["z"] = 8, ["name"] = "slope:slopelong_blue"}, {["x"] = 1, ["meta"] = {["fields"] = {}, ["inventory"] = {}}, ["param2"] = 1, ["y"] = 4, ["param1"] = 174, ["z"] = 9, ["name"] = "slope:slopelong_blue"}, {["x"] = 1, ["meta"] = {["fields"] = {}, ["inventory"] = {}}, ["param2"] = 1, ["y"] = 4, ["param1"] = 174, ["z"] = 10, ["name"] = "slope:slopelong_blue"}, {["x"] = 1, ["meta"] = {["fields"] = {}, ["inventory"] = {}}, ["param2"] = 2, ["y"] = 4, ["param1"] = 174, ["z"] = 11, ["name"] = "slope:ocorner_blue"}, {["x"] = 2, ["meta"] = {["fields"] = {}, ["inventory"] = {}}, ["y"] = 0, ["param1"] = 222, ["z"] = 0, ["name"] = "stairs:stair_black"}, {["x"] = 2, ["meta"] = {["fields"] = {}, ["inventory"] = {}}, ["y"] = 0, ["param1"] = 238, ["z"] = 1, ["name"] = "light:blue"}, {["x"] = 2, ["meta"] = {["fields"] = {}, ["inventory"] = {}}, ["y"] = 0, ["param1"] = 238, ["z"] = 2, ["name"] = "light:blue"}, {["x"] = 2, ["meta"] = {["fields"] = {}, ["inventory"] = {}}, ["y"] = 0, ["param1"] = 238, ["z"] = 3, ["name"] = "light:blue"}, {["x"] = 2, ["meta"] = {["fields"] = {}, ["inventory"] = {}}, ["y"] = 0, ["param1"] = 238, ["z"] = 4, ["name"] = "light:blue"}, {["x"] = 2, ["meta"] = {["fields"] = {}, ["inventory"] = {}}, ["y"] = 0, ["param1"] = 238, ["z"] = 5, ["name"] = "light:blue"}, {["x"] = 2, ["meta"] = {["fields"] = {}, ["inventory"] = {}}, ["y"] = 0, ["param1"] = 238, ["z"] = 6, ["name"] = "light:blue"}, {["x"] = 2, ["meta"] = {["fields"] = {}, ["inventory"] = {}}, ["y"] = 0, ["param1"] = 238, ["z"] = 7, ["name"] = "light:blue"}, {["x"] = 2, ["meta"] = {["fields"] = {}, ["inventory"] = {}}, ["y"] = 0, ["param1"] = 238, ["z"] = 8, ["name"] = "light:blue"}, {["x"] = 2, ["meta"] = {["fields"] = {}, ["inventory"] = {}}, ["y"] = 0, ["param1"] = 238, ["z"] = 9, ["name"] = "light:blue"}, {["x"] = 2, ["meta"] = {["fields"] = {}, ["inventory"] = {}}, ["y"] = 0, ["param1"] = 238, ["z"] = 10, ["name"] = "light:blue"}, {["x"] = 2, ["meta"] = {["fields"] = {}, ["inventory"] = {}}, ["y"] = 0, ["param1"] = 238, ["z"] = 11, ["name"] = "light:blue"}, {["x"] = 2, ["meta"] = {["fields"] = {}, ["inventory"] = {}}, ["param2"] = 2, ["y"] = 0, ["param1"] = 222, ["z"] = 12, ["name"] = "stairs:stair_black"}, {["x"] = 2, ["meta"] = {["fields"] = {}, ["inventory"] = {}}, ["y"] = 4, ["param1"] = 174, ["z"] = 1, ["name"] = "slope:slopelong_blue"}, {["x"] = 2, ["meta"] = {["fields"] = {}, ["inventory"] = {}}, ["y"] = 4, ["param1"] = 190, ["z"] = 2, ["name"] = "carpet:pink"}, {["x"] = 2, ["meta"] = {["fields"] = {}, ["inventory"] = {}}, ["y"] = 4, ["param1"] = 190, ["z"] = 10, ["name"] = "carpet:pink"}, {["x"] = 2, ["meta"] = {["fields"] = {}, ["inventory"] = {}}, ["param2"] = 2, ["y"] = 4, ["param1"] = 174, ["z"] = 11, ["name"] = "slope:slopelong_blue"}, {["x"] = 2, ["meta"] = {["fields"] = {}, ["inventory"] = {}}, ["param2"] = 23, ["y"] = 5, ["param1"] = 206, ["z"] = 2, ["name"] = "slope:cone_pink"}, {["x"] = 2, ["meta"] = {["fields"] = {}, ["inventory"] = {}}, ["param2"] = 1, ["y"] = 5, ["param1"] = 191, ["z"] = 3, ["name"] = "carpet:pink"}, {["x"] = 2, ["meta"] = {["fields"] = {}, ["inventory"] = {}}, ["param2"] = 1, ["y"] = 5, ["param1"] = 191, ["z"] = 9, ["name"] = "carpet:pink"}, {["x"] = 2, ["meta"] = {["fields"] = {}, ["inventory"] = {}}, ["param2"] = 23, ["y"] = 5, ["param1"] = 206, ["z"] = 10, ["name"] = "slope:cone_pink"}, {["x"] = 2, ["meta"] = {["fields"] = {}, ["inventory"] = {}}, ["param2"] = 1, ["y"] = 6, ["param1"] = 222, ["z"] = 2, ["name"] = "slope:cone_pink"}, {["x"] = 2, ["meta"] = {["fields"] = {}, ["inventory"] = {}}, ["param2"] = 2, ["y"] = 6, ["param1"] = 222, ["z"] = 10, ["name"] = "slope:cone_pink"}, {["x"] = 2, ["meta"] = {["fields"] = {}, ["inventory"] = {}}, ["y"] = 7, ["param1"] = 238, ["z"] = 2, ["name"] = "light:pink"}, {["x"] = 2, ["meta"] = {["fields"] = {}, ["inventory"] = {}}, ["y"] = 7, ["param1"] = 238, ["z"] = 10, ["name"] = "light:pink"}, {["x"] = 2, ["meta"] = {["fields"] = {}, ["inventory"] = {}}, ["param2"] = 23, ["y"] = 8, ["param1"] = 222, ["z"] = 2, ["name"] = "slope:cone_pink"}, {["x"] = 2, ["meta"] = {["fields"] = {}, ["inventory"] = {}}, ["param2"] = 23, ["y"] = 8, ["param1"] = 222, ["z"] = 10, ["name"] = "slope:cone_pink"}, {["x"] = 2, ["meta"] = {["fields"] = {}, ["inventory"] = {}}, ["param2"] = 1, ["y"] = 9, ["param1"] = 206, ["z"] = 2, ["name"] = "slope:sphere_orange"}, {["x"] = 2, ["meta"] = {["fields"] = {}, ["inventory"] = {}}, ["y"] = 9, ["param1"] = 206, ["z"] = 10, ["name"] = "slope:sphere_orange"}, {["x"] = 2, ["meta"] = {["fields"] = {}, ["inventory"] = {}}, ["param2"] = 1, ["y"] = 10, ["param1"] = 190, ["z"] = 2, ["name"] = "slope:cone_pink"}, {["x"] = 2, ["meta"] = {["fields"] = {}, ["inventory"] = {}}, ["param2"] = 3, ["y"] = 10, ["param1"] = 190, ["z"] = 10, ["name"] = "slope:cone_pink"}, {["x"] = 2, ["meta"] = {["fields"] = {}, ["inventory"] = {}}, ["param2"] = 3, ["y"] = 11, ["param1"] = 174, ["z"] = 2, ["name"] = "slope:sphere_pink"}, {["x"] = 2, ["meta"] = {["fields"] = {}, ["inventory"] = {}}, ["y"] = 11, ["param1"] = 174, ["z"] = 10, ["name"] = "slope:sphere_pink"}, {["x"] = 3, ["meta"] = {["fields"] = {}, ["inventory"] = {}}, ["y"] = 0, ["param1"] = 222, ["z"] = 0, ["name"] = "stairs:stair_black"}, {["x"] = 3, ["meta"] = {["fields"] = {}, ["inventory"] = {}}, ["y"] = 0, ["param1"] = 238, ["z"] = 1, ["name"] = "light:blue"}, {["x"] = 3, ["meta"] = {["fields"] = {}, ["inventory"] = {}}, ["y"] = 0, ["param1"] = 238, ["z"] = 2, ["name"] = "light:blue"}, {["x"] = 3, ["meta"] = {["fields"] = {}, ["inventory"] = {}}, ["y"] = 0, ["param1"] = 238, ["z"] = 10, ["name"] = "light:blue"}, {["x"] = 3, ["meta"] = {["fields"] = {}, ["inventory"] = {}}, ["y"] = 0, ["param1"] = 238, ["z"] = 11, ["name"] = "light:blue"}, {["x"] = 3, ["meta"] = {["fields"] = {}, ["inventory"] = {}}, ["param2"] = 2, ["y"] = 0, ["param1"] = 222, ["z"] = 12, ["name"] = "stairs:stair_black"}, {["x"] = 3, ["meta"] = {["fields"] = {}, ["inventory"] = {}}, ["y"] = 1, ["param1"] = 222, ["z"] = 1, ["name"] = "slope:cone_blue"}, {["x"] = 3, ["meta"] = {["fields"] = {}, ["inventory"] = {}}, ["param2"] = 1, ["y"] = 1, ["param1"] = 206, ["z"] = 3, ["name"] = "stairs:stair_outer_orange"}, {["x"] = 3, ["meta"] = {["fields"] = {}, ["inventory"] = {}}, ["param2"] = 1, ["y"] = 1, ["param1"] = 222, ["z"] = 4, ["name"] = "stairs:stair_orange"}, {["x"] = 3, ["meta"] = {["fields"] = {}, ["inventory"] = {}}, ["param2"] = 1, ["y"] = 1, ["param1"] = 222, ["z"] = 5, ["name"] = "stairs:stair_orange"}, {["x"] = 3, ["meta"] = {["fields"] = {}, ["inventory"] = {}}, ["param2"] = 1, ["y"] = 1, ["param1"] = 222, ["z"] = 6, ["name"] = "stairs:stair_orange"}, {["x"] = 3, ["meta"] = {["fields"] = {}, ["inventory"] = {}}, ["param2"] = 1, ["y"] = 1, ["param1"] = 222, ["z"] = 7, ["name"] = "stairs:stair_orange"}, {["x"] = 3, ["meta"] = {["fields"] = {}, ["inventory"] = {}}, ["param2"] = 1, ["y"] = 1, ["param1"] = 222, ["z"] = 8, ["name"] = "stairs:stair_orange"}, {["x"] = 3, ["meta"] = {["fields"] = {}, ["inventory"] = {}}, ["param2"] = 2, ["y"] = 1, ["param1"] = 206, ["z"] = 9, ["name"] = "stairs:stair_outer_orange"}, {["x"] = 3, ["meta"] = {["fields"] = {}, ["inventory"] = {}}, ["param2"] = 2, ["y"] = 1, ["param1"] = 222, ["z"] = 11, ["name"] = "slope:cone_blue"}, {["x"] = 3, ["meta"] = {["fields"] = {}, ["inventory"] = {}}, ["y"] = 2, ["param1"] = 206, ["z"] = 1, ["name"] = "slope:sphere_orange"}, {["x"] = 3, ["meta"] = {["fields"] = {}, ["inventory"] = {}}, ["param2"] = 2, ["y"] = 2, ["param1"] = 206, ["z"] = 11, ["name"] = "slope:sphere_blue"}, {["x"] = 3, ["meta"] = {["fields"] = {}, ["inventory"] = {}}, ["param2"] = 20, ["y"] = 3, ["param1"] = 190, ["z"] = 1, ["name"] = "slope:cone_blue"}, {["x"] = 3, ["meta"] = {["fields"] = {}, ["inventory"] = {}}, ["param2"] = 22, ["y"] = 3, ["param1"] = 190, ["z"] = 11, ["name"] = "slope:cone_blue"}, {["x"] = 3, ["meta"] = {["fields"] = {}, ["inventory"] = {}}, ["y"] = 4, ["param1"] = 174, ["z"] = 1, ["name"] = "slope:slopelong_blue"}, {["x"] = 3, ["meta"] = {["fields"] = {}, ["inventory"] = {}}, ["param2"] = 2, ["y"] = 4, ["param1"] = 174, ["z"] = 11, ["name"] = "slope:slopelong_blue"}, {["x"] = 3, ["meta"] = {["fields"] = {}, ["inventory"] = {}}, ["param2"] = 1, ["y"] = 5, ["param1"] = 191, ["z"] = 2, ["name"] = "carpet:pink"}, {["x"] = 3, ["meta"] = {["fields"] = {}, ["inventory"] = {}}, ["param2"] = 1, ["y"] = 5, ["param1"] = 174, ["z"] = 3, ["name"] = "slope:ocorner_pink"}, {["x"] = 3, ["meta"] = {["fields"] = {}, ["inventory"] = {}}, ["param2"] = 1, ["y"] = 5, ["param1"] = 158, ["z"] = 4, ["name"] = "slope:slopelong_pink"}, {["x"] = 3, ["meta"] = {["fields"] = {}, ["inventory"] = {}}, ["param2"] = 1, ["y"] = 5, ["param1"] = 158, ["z"] = 5, ["name"] = "slope:slopelong_pink"}, {["x"] = 3, ["meta"] = {["fields"] = {}, ["inventory"] = {}}, ["param2"] = 1, ["y"] = 5, ["param1"] = 158, ["z"] = 7, ["name"] = "slope:slopelong_pink"}, {["x"] = 3, ["meta"] = {["fields"] = {}, ["inventory"] = {}}, ["param2"] = 1, ["y"] = 5, ["param1"] = 158, ["z"] = 8, ["name"] = "slope:slopelong_pink"}, {["x"] = 3, ["meta"] = {["fields"] = {}, ["inventory"] = {}}, ["param2"] = 2, ["y"] = 5, ["param1"] = 174, ["z"] = 9, ["name"] = "slope:ocorner_pink"}, {["x"] = 3, ["meta"] = {["fields"] = {}, ["inventory"] = {}}, ["param2"] = 1, ["y"] = 5, ["param1"] = 191, ["z"] = 10, ["name"] = "carpet:pink"}, {["x"] = 4, ["meta"] = {["fields"] = {}, ["inventory"] = {}}, ["y"] = 0, ["param1"] = 222, ["z"] = 0, ["name"] = "stairs:stair_black"}, {["x"] = 4, ["meta"] = {["fields"] = {}, ["inventory"] = {}}, ["y"] = 0, ["param1"] = 238, ["z"] = 1, ["name"] = "light:blue"}, {["x"] = 4, ["meta"] = {["fields"] = {}, ["inventory"] = {}}, ["y"] = 0, ["param1"] = 238, ["z"] = 2, ["name"] = "light:blue"}, {["x"] = 4, ["meta"] = {["fields"] = {}, ["inventory"] = {}}, ["y"] = 0, ["param1"] = 238, ["z"] = 4, ["name"] = "light:pink"}, {["x"] = 4, ["meta"] = {["fields"] = {}, ["inventory"] = {}}, ["y"] = 0, ["param1"] = 238, ["z"] = 5, ["name"] = "light:yellow"}, {["x"] = 4, ["meta"] = {["fields"] = {}, ["inventory"] = {}}, ["y"] = 0, ["param1"] = 238, ["z"] = 6, ["name"] = "light:pink"}, {["x"] = 4, ["meta"] = {["fields"] = {}, ["inventory"] = {}}, ["y"] = 0, ["param1"] = 238, ["z"] = 7, ["name"] = "light:yellow"}, {["x"] = 4, ["meta"] = {["fields"] = {}, ["inventory"] = {}}, ["y"] = 0, ["param1"] = 238, ["z"] = 8, ["name"] = "light:pink"}, {["x"] = 4, ["meta"] = {["fields"] = {}, ["inventory"] = {}}, ["y"] = 0, ["param1"] = 238, ["z"] = 10, ["name"] = "light:blue"}, {["x"] = 4, ["meta"] = {["fields"] = {}, ["inventory"] = {}}, ["y"] = 0, ["param1"] = 238, ["z"] = 11, ["name"] = "light:blue"}, {["x"] = 4, ["meta"] = {["fields"] = {}, ["inventory"] = {}}, ["param2"] = 2, ["y"] = 0, ["param1"] = 222, ["z"] = 12, ["name"] = "stairs:stair_black"}, {["x"] = 4, ["meta"] = {["fields"] = {}, ["inventory"] = {}}, ["y"] = 1, ["param1"] = 222, ["z"] = 3, ["name"] = "stairs:stair_orange"}, {["x"] = 4, ["meta"] = {["fields"] = {}, ["inventory"] = {}}, ["y"] = 1, ["param1"] = 238, ["z"] = 4, ["name"] = "light:orange"}, {["x"] = 4, ["meta"] = {["fields"] = {}, ["inventory"] = {}}, ["y"] = 1, ["param1"] = 238, ["z"] = 5, ["name"] = "light:orange"}, {["x"] = 4, ["meta"] = {["fields"] = {}, ["inventory"] = {}}, ["y"] = 1, ["param1"] = 238, ["z"] = 6, ["name"] = "light:orange"}, {["x"] = 4, ["meta"] = {["fields"] = {}, ["inventory"] = {}}, ["y"] = 1, ["param1"] = 238, ["z"] = 7, ["name"] = "light:orange"}, {["x"] = 4, ["meta"] = {["fields"] = {}, ["inventory"] = {}}, ["y"] = 1, ["param1"] = 238, ["z"] = 8, ["name"] = "light:orange"}, {["x"] = 4, ["meta"] = {["fields"] = {}, ["inventory"] = {}}, ["param2"] = 2, ["y"] = 1, ["param1"] = 222, ["z"] = 9, ["name"] = "stairs:stair_orange"}, {["x"] = 4, ["meta"] = {["fields"] = {}, ["inventory"] = {}}, ["y"] = 4, ["param1"] = 174, ["z"] = 1, ["name"] = "slope:slopelong_blue"}, {["x"] = 4, ["meta"] = {["fields"] = {}, ["inventory"] = {}}, ["param2"] = 2, ["y"] = 4, ["param1"] = 174, ["z"] = 11, ["name"] = "slope:slopelong_blue"}, {["x"] = 4, ["meta"] = {["fields"] = {}, ["inventory"] = {}}, ["y"] = 5, ["param1"] = 158, ["z"] = 3, ["name"] = "slope:slopelong_pink"}, {["x"] = 4, ["meta"] = {["fields"] = {}, ["inventory"] = {}}, ["y"] = 5, ["param1"] = 174, ["z"] = 4, ["name"] = "carpet:green"}, {["x"] = 4, ["meta"] = {["fields"] = {}, ["inventory"] = {}}, ["y"] = 5, ["param1"] = 174, ["z"] = 8, ["name"] = "carpet:green"}, {["x"] = 4, ["meta"] = {["fields"] = {}, ["inventory"] = {}}, ["param2"] = 2, ["y"] = 5, ["param1"] = 158, ["z"] = 9, ["name"] = "slope:slopelong_pink"}, {["x"] = 4, ["meta"] = {["fields"] = {}, ["inventory"] = {}}, ["param2"] = 23, ["y"] = 6, ["param1"] = 190, ["z"] = 4, ["name"] = "slope:cone_green"}, {["x"] = 4, ["meta"] = {["fields"] = {}, ["inventory"] = {}}, ["param2"] = 1, ["y"] = 6, ["param1"] = 175, ["z"] = 5, ["name"] = "carpet:green"}, {["x"] = 4, ["meta"] = {["fields"] = {}, ["inventory"] = {}}, ["param2"] = 1, ["y"] = 6, ["param1"] = 175, ["z"] = 7, ["name"] = "carpet:green"}, {["x"] = 4, ["meta"] = {["fields"] = {}, ["inventory"] = {}}, ["param2"] = 23, ["y"] = 6, ["param1"] = 190, ["z"] = 8, ["name"] = "slope:cone_green"}, {["x"] = 4, ["meta"] = {["fields"] = {}, ["inventory"] = {}}, ["param2"] = 1, ["y"] = 7, ["param1"] = 206, ["z"] = 4, ["name"] = "slope:cylinder_green"}, {["x"] = 4, ["meta"] = {["fields"] = {}, ["inventory"] = {}}, ["param2"] = 1, ["y"] = 7, ["param1"] = 206, ["z"] = 8, ["name"] = "slope:cylinder_green"}, {["x"] = 4, ["meta"] = {["fields"] = {}, ["inventory"] = {}}, ["y"] = 8, ["param1"] = 222, ["z"] = 4, ["name"] = "slope:cone_green"}, {["x"] = 4, ["meta"] = {["fields"] = {}, ["inventory"] = {}}, ["param2"] = 2, ["y"] = 8, ["param1"] = 222, ["z"] = 8, ["name"] = "slope:cone_green"}, {["x"] = 4, ["meta"] = {["fields"] = {}, ["inventory"] = {}}, ["y"] = 9, ["param1"] = 238, ["z"] = 4, ["name"] = "light:green"}, {["x"] = 4, ["meta"] = {["fields"] = {}, ["inventory"] = {}}, ["y"] = 9, ["param1"] = 238, ["z"] = 8, ["name"] = "light:green"}, {["x"] = 4, ["meta"] = {["fields"] = {}, ["inventory"] = {}}, ["param2"] = 20, ["y"] = 10, ["param1"] = 222, ["z"] = 4, ["name"] = "slope:cone_green"}, {["x"] = 4, ["meta"] = {["fields"] = {}, ["inventory"] = {}}, ["param2"] = 22, ["y"] = 10, ["param1"] = 222, ["z"] = 8, ["name"] = "slope:cone_green"}, {["x"] = 4, ["meta"] = {["fields"] = {}, ["inventory"] = {}}, ["param2"] = 3, ["y"] = 11, ["param1"] = 206, ["z"] = 4, ["name"] = "slope:cone_green"}, {["x"] = 4, ["meta"] = {["fields"] = {}, ["inventory"] = {}}, ["y"] = 11, ["param1"] = 206, ["z"] = 8, ["name"] = "slope:cone_green"}, {["x"] = 4, ["meta"] = {["fields"] = {}, ["inventory"] = {}}, ["param2"] = 2, ["y"] = 12, ["param1"] = 190, ["z"] = 4, ["name"] = "slope:sphere_red"}, {["x"] = 4, ["meta"] = {["fields"] = {}, ["inventory"] = {}}, ["param2"] = 2, ["y"] = 12, ["param1"] = 190, ["z"] = 8, ["name"] = "slope:sphere_red"}, {["x"] = 5, ["meta"] = {["fields"] = {}, ["inventory"] = {}}, ["y"] = 0, ["param1"] = 206, ["z"] = 0, ["name"] = "stairs:stair_black"}, {["x"] = 5, ["meta"] = {["fields"] = {}, ["inventory"] = {}}, ["y"] = 0, ["z"] = 1, ["name"] = "color:blue"}, {["x"] = 5, ["meta"] = {["fields"] = {}, ["inventory"] = {}}, ["y"] = 0, ["param1"] = 238, ["z"] = 2, ["name"] = "light:blue"}, {["x"] = 5, ["meta"] = {["fields"] = {}, ["inventory"] = {}}, ["y"] = 0, ["param1"] = 238, ["z"] = 4, ["name"] = "light:yellow"}, {["x"] = 5, ["meta"] = {["fields"] = {}, ["inventory"] = {}}, ["y"] = 0, ["param1"] = 238, ["z"] = 8, ["name"] = "light:yellow"}, {["x"] = 5, ["meta"] = {["fields"] = {}, ["inventory"] = {}}, ["y"] = 0, ["param1"] = 238, ["z"] = 10, ["name"] = "light:blue"}, {["x"] = 5, ["meta"] = {["fields"] = {}, ["inventory"] = {}}, ["y"] = 0, ["param1"] = 238, ["z"] = 11, ["name"] = "light:blue"}, {["x"] = 5, ["meta"] = {["fields"] = {}, ["inventory"] = {}}, ["param2"] = 2, ["y"] = 0, ["param1"] = 222, ["z"] = 12, ["name"] = "stairs:stair_black"}, {["x"] = 5, ["meta"] = {["fields"] = {}, ["inventory"] = {}}, ["y"] = 1, ["param1"] = 206, ["z"] = 1, ["name"] = "slope:cone_blue"}, {["x"] = 5, ["meta"] = {["fields"] = {}, ["inventory"] = {}}, ["y"] = 1, ["param1"] = 222, ["z"] = 3, ["name"] = "stairs:stair_orange"}, {["x"] = 5, ["meta"] = {["fields"] = {}, ["inventory"] = {}}, ["y"] = 1, ["param1"] = 238, ["z"] = 4, ["name"] = "light:orange"}, {["x"] = 5, ["meta"] = {["fields"] = {}, ["inventory"] = {}}, ["y"] = 1, ["param1"] = 238, ["z"] = 8, ["name"] = "light:orange"}, {["x"] = 5, ["meta"] = {["fields"] = {}, ["inventory"] = {}}, ["param2"] = 2, ["y"] = 1, ["param1"] = 222, ["z"] = 9, ["name"] = "stairs:stair_orange"}, {["x"] = 5, ["meta"] = {["fields"] = {}, ["inventory"] = {}}, ["param2"] = 2, ["y"] = 1, ["param1"] = 222, ["z"] = 11, ["name"] = "slope:cone_blue"}, {["x"] = 5, ["meta"] = {["fields"] = {}, ["inventory"] = {}}, ["y"] = 2, ["param1"] = 190, ["z"] = 1, ["name"] = "slope:sphere_pink"}, {["x"] = 5, ["meta"] = {["fields"] = {}, ["inventory"] = {}}, ["param2"] = 1, ["y"] = 2, ["param1"] = 206, ["z"] = 5, ["name"] = "stairs:stair_outer_red"}, {["x"] = 5, ["meta"] = {["fields"] = {}, ["inventory"] = {}}, ["param2"] = 1, ["y"] = 2, ["param1"] = 206, ["z"] = 6, ["name"] = "stairs:stair_red"}, {["x"] = 5, ["meta"] = {["fields"] = {}, ["inventory"] = {}}, ["param2"] = 2, ["y"] = 2, ["param1"] = 206, ["z"] = 7, ["name"] = "stairs:stair_outer_red"}, {["x"] = 5, ["meta"] = {["fields"] = {}, ["inventory"] = {}}, ["param2"] = 2, ["y"] = 2, ["param1"] = 206, ["z"] = 11, ["name"] = "slope:sphere_green"}, {["x"] = 5, ["meta"] = {["fields"] = {}, ["inventory"] = {}}, ["param2"] = 20, ["y"] = 3, ["param1"] = 174, ["z"] = 1, ["name"] = "slope:cone_blue"}, {["x"] = 5, ["meta"] = {["fields"] = {}, ["inventory"] = {}}, ["param2"] = 1, ["y"] = 3, ["param1"] = 190, ["z"] = 5, ["name"] = "slope:sphere_red"}, {["x"] = 5, ["meta"] = {["fields"] = {}, ["inventory"] = {}}, ["param2"] = 1, ["y"] = 3, ["param1"] = 190, ["z"] = 7, ["name"] = "slope:sphere_red"}, {["x"] = 5, ["meta"] = {["fields"] = {}, ["inventory"] = {}}, ["param2"] = 22, ["y"] = 3, ["param1"] = 190, ["z"] = 11, ["name"] = "slope:cone_blue"}, {["x"] = 5, ["meta"] = {["fields"] = {}, ["inventory"] = {}}, ["y"] = 4, ["param1"] = 158, ["z"] = 1, ["name"] = "slope:slopelong_blue"}, {["x"] = 5, ["meta"] = {["fields"] = {}, ["inventory"] = {}}, ["param2"] = 2, ["y"] = 4, ["param1"] = 174, ["z"] = 11, ["name"] = "slope:slopelong_blue"}, {["x"] = 5, ["meta"] = {["fields"] = {}, ["inventory"] = {}}, ["y"] = 5, ["param1"] = 158, ["z"] = 3, ["name"] = "slope:slopelong_pink"}, {["x"] = 5, ["meta"] = {["fields"] = {}, ["inventory"] = {}}, ["param2"] = 2, ["y"] = 5, ["param1"] = 158, ["z"] = 9, ["name"] = "slope:slopelong_pink"}, {["x"] = 5, ["meta"] = {["fields"] = {}, ["inventory"] = {}}, ["param2"] = 1, ["y"] = 6, ["param1"] = 175, ["z"] = 4, ["name"] = "carpet:green"}, {["x"] = 5, ["meta"] = {["fields"] = {}, ["inventory"] = {}}, ["param2"] = 1, ["y"] = 6, ["param1"] = 158, ["z"] = 5, ["name"] = "slope:ocorner_green"}, {["x"] = 5, ["meta"] = {["fields"] = {}, ["inventory"] = {}}, ["param2"] = 1, ["y"] = 6, ["param1"] = 142, ["z"] = 6, ["name"] = "slope:slopelong_green"}, {["x"] = 5, ["meta"] = {["fields"] = {}, ["inventory"] = {}}, ["param2"] = 2, ["y"] = 6, ["param1"] = 158, ["z"] = 7, ["name"] = "slope:ocorner_green"}, {["x"] = 5, ["meta"] = {["fields"] = {}, ["inventory"] = {}}, ["param2"] = 1, ["y"] = 6, ["param1"] = 175, ["z"] = 8, ["name"] = "carpet:green"}, {["x"] = 6, ["meta"] = {["fields"] = {}, ["inventory"] = {}}, ["y"] = 0, ["param1"] = 206, ["z"] = 0, ["name"] = "stairs:stair_black"}, {["x"] = 6, ["meta"] = {["fields"] = {}, ["inventory"] = {}}, ["y"] = 0, ["z"] = 1, ["name"] = "color:blue"}, {["x"] = 6, ["meta"] = {["fields"] = {}, ["inventory"] = {}}, ["y"] = 0, ["param1"] = 238, ["z"] = 2, ["name"] = "light:blue"}, {["x"] = 6, ["meta"] = {["fields"] = {}, ["inventory"] = {}}, ["y"] = 0, ["param1"] = 238, ["z"] = 4, ["name"] = "light:pink"}, {["x"] = 6, ["meta"] = {["fields"] = {}, ["inventory"] = {}}, ["y"] = 0, ["param1"] = 238, ["z"] = 8, ["name"] = "light:pink"}, {["x"] = 6, ["meta"] = {["fields"] = {}, ["inventory"] = {}}, ["y"] = 0, ["param1"] = 238, ["z"] = 10, ["name"] = "light:blue"}, {["x"] = 6, ["meta"] = {["fields"] = {}, ["inventory"] = {}}, ["y"] = 0, ["param1"] = 238, ["z"] = 11, ["name"] = "light:blue"}, {["x"] = 6, ["meta"] = {["fields"] = {}, ["inventory"] = {}}, ["param2"] = 2, ["y"] = 0, ["param1"] = 222, ["z"] = 12, ["name"] = "stairs:stair_black"}, {["x"] = 6, ["meta"] = {["fields"] = {}, ["inventory"] = {}}, ["y"] = 1, ["param1"] = 222, ["z"] = 3, ["name"] = "stairs:stair_orange"}, {["x"] = 6, ["meta"] = {["fields"] = {}, ["inventory"] = {}}, ["y"] = 1, ["param1"] = 238, ["z"] = 4, ["name"] = "light:orange"}, {["x"] = 6, ["meta"] = {["fields"] = {}, ["inventory"] = {}}, ["y"] = 1, ["param1"] = 238, ["z"] = 8, ["name"] = "light:orange"}, {["x"] = 6, ["meta"] = {["fields"] = {}, ["inventory"] = {}}, ["param2"] = 2, ["y"] = 1, ["param1"] = 222, ["z"] = 9, ["name"] = "stairs:stair_orange"}, {["x"] = 6, ["meta"] = {["fields"] = {}, ["inventory"] = {}}, ["y"] = 2, ["param1"] = 206, ["z"] = 5, ["name"] = "stairs:stair_red"}, {["x"] = 6, ["meta"] = {["fields"] = {}, ["inventory"] = {}}, ["param2"] = 21, ["y"] = 2, ["param1"] = 189, ["z"] = 6, ["name"] = "slope:cylinder_blue"}, {["x"] = 6, ["meta"] = {["fields"] = {}, ["inventory"] = {}}, ["param2"] = 2, ["y"] = 2, ["param1"] = 206, ["z"] = 7, ["name"] = "stairs:stair_red"}, {["x"] = 6, ["meta"] = {["fields"] = {}, ["inventory"] = {}}, ["param2"] = 2, ["y"] = 3, ["param1"] = 173, ["z"] = 6, ["name"] = "slope:cone_blue"}, {["x"] = 6, ["meta"] = {["fields"] = {}, ["inventory"] = {}}, ["y"] = 4, ["param1"] = 158, ["z"] = 1, ["name"] = "slope:slopelong_blue"}, {["x"] = 6, ["meta"] = {["fields"] = {}, ["inventory"] = {}}, ["param2"] = 2, ["y"] = 4, ["param1"] = 174, ["z"] = 11, ["name"] = "slope:slopelong_blue"}, {["x"] = 6, ["meta"] = {["fields"] = {}, ["inventory"] = {}}, ["y"] = 5, ["param1"] = 158, ["z"] = 3, ["name"] = "slope:slopelong_pink"}, {["x"] = 6, ["meta"] = {["fields"] = {}, ["inventory"] = {}}, ["param2"] = 22, ["y"] = 5, ["param1"] = 141, ["z"] = 6, ["name"] = "slope:cone_green"}, {["x"] = 6, ["meta"] = {["fields"] = {}, ["inventory"] = {}}, ["param2"] = 2, ["y"] = 5, ["param1"] = 158, ["z"] = 9, ["name"] = "slope:slopelong_pink"}, {["x"] = 6, ["meta"] = {["fields"] = {}, ["inventory"] = {}}, ["y"] = 6, ["param1"] = 142, ["z"] = 5, ["name"] = "slope:slopelong_green"}, {["x"] = 6, ["meta"] = {["fields"] = {}, ["inventory"] = {}}, ["param2"] = 21, ["y"] = 6, ["param1"] = 157, ["z"] = 6, ["name"] = "slope:cylinder_blue"}, {["x"] = 6, ["meta"] = {["fields"] = {}, ["inventory"] = {}}, ["param2"] = 2, ["y"] = 6, ["param1"] = 142, ["z"] = 7, ["name"] = "slope:slopelong_green"}, {["x"] = 6, ["meta"] = {["fields"] = {}, ["inventory"] = {}}, ["y"] = 7, ["param1"] = 174, ["z"] = 6, ["name"] = "slope:cone_blue"}, {["x"] = 6, ["meta"] = {["fields"] = {}, ["inventory"] = {}}, ["y"] = 8, ["param1"] = 190, ["z"] = 6, ["name"] = "slope:sphere_blue"}, {["x"] = 6, ["meta"] = {["fields"] = {}, ["inventory"] = {}}, ["param2"] = 20, ["y"] = 9, ["param1"] = 206, ["z"] = 6, ["name"] = "slope:cone_blue"}, {["x"] = 6, ["meta"] = {["fields"] = {}, ["inventory"] = {}}, ["param2"] = 2, ["y"] = 10, ["param1"] = 222, ["z"] = 6, ["name"] = "slope:cone_blue"}, {["x"] = 6, ["meta"] = {["fields"] = {}, ["inventory"] = {}}, ["y"] = 11, ["param1"] = 238, ["z"] = 6, ["name"] = "light:blue"}, {["x"] = 6, ["meta"] = {["fields"] = {}, ["inventory"] = {}}, ["param2"] = 22, ["y"] = 12, ["param1"] = 222, ["z"] = 6, ["name"] = "slope:cone_blue"}, {["x"] = 6, ["meta"] = {["fields"] = {}, ["inventory"] = {}}, ["param2"] = 2, ["y"] = 13, ["param1"] = 206, ["z"] = 6, ["name"] = "slope:cone_blue"}, {["x"] = 6, ["meta"] = {["fields"] = {}, ["inventory"] = {}}, ["param2"] = 2, ["y"] = 14, ["param1"] = 190, ["z"] = 6, ["name"] = "slope:sphere_blue"}, {["x"] = 7, ["meta"] = {["fields"] = {}, ["inventory"] = {}}, ["y"] = 0, ["param1"] = 222, ["z"] = 0, ["name"] = "stairs:stair_black"}, {["x"] = 7, ["meta"] = {["fields"] = {}, ["inventory"] = {}}, ["y"] = 0, ["param1"] = 238, ["z"] = 1, ["name"] = "light:blue"}, {["x"] = 7, ["meta"] = {["fields"] = {}, ["inventory"] = {}}, ["y"] = 0, ["param1"] = 238, ["z"] = 2, ["name"] = "light:blue"}, {["x"] = 7, ["meta"] = {["fields"] = {}, ["inventory"] = {}}, ["y"] = 0, ["param1"] = 238, ["z"] = 4, ["name"] = "light:yellow"}, {["x"] = 7, ["meta"] = {["fields"] = {}, ["inventory"] = {}}, ["y"] = 0, ["param1"] = 238, ["z"] = 8, ["name"] = "light:yellow"}, {["x"] = 7, ["meta"] = {["fields"] = {}, ["inventory"] = {}}, ["y"] = 0, ["param1"] = 238, ["z"] = 10, ["name"] = "light:blue"}, {["x"] = 7, ["meta"] = {["fields"] = {}, ["inventory"] = {}}, ["y"] = 0, ["param1"] = 238, ["z"] = 11, ["name"] = "light:blue"}, {["x"] = 7, ["meta"] = {["fields"] = {}, ["inventory"] = {}}, ["param2"] = 2, ["y"] = 0, ["param1"] = 222, ["z"] = 12, ["name"] = "stairs:stair_black"}, {["x"] = 7, ["meta"] = {["fields"] = {}, ["inventory"] = {}}, ["y"] = 1, ["param1"] = 222, ["z"] = 1, ["name"] = "slope:cone_blue"}, {["x"] = 7, ["meta"] = {["fields"] = {}, ["inventory"] = {}}, ["y"] = 1, ["param1"] = 222, ["z"] = 3, ["name"] = "stairs:stair_orange"}, {["x"] = 7, ["meta"] = {["fields"] = {}, ["inventory"] = {}}, ["y"] = 1, ["param1"] = 238, ["z"] = 4, ["name"] = "light:orange"}, {["x"] = 7, ["meta"] = {["fields"] = {}, ["inventory"] = {}}, ["y"] = 1, ["param1"] = 238, ["z"] = 8, ["name"] = "light:orange"}, {["x"] = 7, ["meta"] = {["fields"] = {}, ["inventory"] = {}}, ["param2"] = 2, ["y"] = 1, ["param1"] = 222, ["z"] = 9, ["name"] = "stairs:stair_orange"}, {["x"] = 7, ["meta"] = {["fields"] = {}, ["inventory"] = {}}, ["param2"] = 2, ["y"] = 1, ["param1"] = 222, ["z"] = 11, ["name"] = "slope:cone_blue"}, {["x"] = 7, ["meta"] = {["fields"] = {}, ["inventory"] = {}}, ["y"] = 2, ["param1"] = 206, ["z"] = 1, ["name"] = "slope:sphere_green"}, {["x"] = 7, ["meta"] = {["fields"] = {}, ["inventory"] = {}}, ["y"] = 2, ["param1"] = 206, ["z"] = 5, ["name"] = "stairs:stair_outer_red"}, {["x"] = 7, ["meta"] = {["fields"] = {}, ["inventory"] = {}}, ["param2"] = 3, ["y"] = 2, ["param1"] = 206, ["z"] = 6, ["name"] = "stairs:stair_red"}, {["x"] = 7, ["meta"] = {["fields"] = {}, ["inventory"] = {}}, ["param2"] = 3, ["y"] = 2, ["param1"] = 206, ["z"] = 7, ["name"] = "stairs:stair_outer_red"}, {["x"] = 7, ["meta"] = {["fields"] = {}, ["inventory"] = {}}, ["param2"] = 2, ["y"] = 2, ["param1"] = 206, ["z"] = 11, ["name"] = "slope:sphere_pink"}, {["x"] = 7, ["meta"] = {["fields"] = {}, ["inventory"] = {}}, ["param2"] = 20, ["y"] = 3, ["param1"] = 190, ["z"] = 1, ["name"] = "slope:cone_blue"}, {["x"] = 7, ["meta"] = {["fields"] = {}, ["inventory"] = {}}, ["param2"] = 3, ["y"] = 3, ["param1"] = 190, ["z"] = 5, ["name"] = "slope:sphere_red"}, {["x"] = 7, ["meta"] = {["fields"] = {}, ["inventory"] = {}}, ["param2"] = 3, ["y"] = 3, ["param1"] = 190, ["z"] = 7, ["name"] = "slope:sphere_red"}, {["x"] = 7, ["meta"] = {["fields"] = {}, ["inventory"] = {}}, ["param2"] = 22, ["y"] = 3, ["param1"] = 190, ["z"] = 11, ["name"] = "slope:cone_blue"}, {["x"] = 7, ["meta"] = {["fields"] = {}, ["inventory"] = {}}, ["y"] = 4, ["param1"] = 174, ["z"] = 1, ["name"] = "slope:slopelong_blue"}, {["x"] = 7, ["meta"] = {["fields"] = {}, ["inventory"] = {}}, ["param2"] = 2, ["y"] = 4, ["param1"] = 174, ["z"] = 11, ["name"] = "slope:slopelong_blue"}, {["x"] = 7, ["meta"] = {["fields"] = {}, ["inventory"] = {}}, ["y"] = 5, ["param1"] = 158, ["z"] = 3, ["name"] = "slope:slopelong_pink"}, {["x"] = 7, ["meta"] = {["fields"] = {}, ["inventory"] = {}}, ["param2"] = 2, ["y"] = 5, ["param1"] = 158, ["z"] = 9, ["name"] = "slope:slopelong_pink"}, {["x"] = 7, ["meta"] = {["fields"] = {}, ["inventory"] = {}}, ["param2"] = 1, ["y"] = 6, ["param1"] = 175, ["z"] = 4, ["name"] = "carpet:green"}, {["x"] = 7, ["meta"] = {["fields"] = {}, ["inventory"] = {}}, ["y"] = 6, ["param1"] = 158, ["z"] = 5, ["name"] = "slope:ocorner_green"}, {["x"] = 7, ["meta"] = {["fields"] = {}, ["inventory"] = {}}, ["param2"] = 3, ["y"] = 6, ["param1"] = 142, ["z"] = 6, ["name"] = "slope:slopelong_green"}, {["x"] = 7, ["meta"] = {["fields"] = {}, ["inventory"] = {}}, ["param2"] = 3, ["y"] = 6, ["param1"] = 158, ["z"] = 7, ["name"] = "slope:ocorner_green"}, {["x"] = 7, ["meta"] = {["fields"] = {}, ["inventory"] = {}}, ["param2"] = 1, ["y"] = 6, ["param1"] = 175, ["z"] = 8, ["name"] = "carpet:green"}, {["x"] = 8, ["meta"] = {["fields"] = {}, ["inventory"] = {}}, ["y"] = 0, ["param1"] = 222, ["z"] = 0, ["name"] = "stairs:stair_black"}, {["x"] = 8, ["meta"] = {["fields"] = {}, ["inventory"] = {}}, ["y"] = 0, ["param1"] = 238, ["z"] = 1, ["name"] = "light:blue"}, {["x"] = 8, ["meta"] = {["fields"] = {}, ["inventory"] = {}}, ["y"] = 0, ["param1"] = 238, ["z"] = 2, ["name"] = "light:blue"}, {["x"] = 8, ["meta"] = {["fields"] = {}, ["inventory"] = {}}, ["y"] = 0, ["param1"] = 238, ["z"] = 4, ["name"] = "light:pink"}, {["x"] = 8, ["meta"] = {["fields"] = {}, ["inventory"] = {}}, ["y"] = 0, ["param1"] = 238, ["z"] = 5, ["name"] = "light:yellow"}, {["x"] = 8, ["meta"] = {["fields"] = {}, ["inventory"] = {}}, ["y"] = 0, ["param1"] = 238, ["z"] = 6, ["name"] = "light:pink"}, {["x"] = 8, ["meta"] = {["fields"] = {}, ["inventory"] = {}}, ["y"] = 0, ["param1"] = 238, ["z"] = 7, ["name"] = "light:yellow"}, {["x"] = 8, ["meta"] = {["fields"] = {}, ["inventory"] = {}}, ["y"] = 0, ["param1"] = 238, ["z"] = 8, ["name"] = "light:pink"}, {["x"] = 8, ["meta"] = {["fields"] = {}, ["inventory"] = {}}, ["y"] = 0, ["param1"] = 238, ["z"] = 10, ["name"] = "light:blue"}, {["x"] = 8, ["meta"] = {["fields"] = {}, ["inventory"] = {}}, ["y"] = 0, ["param1"] = 238, ["z"] = 11, ["name"] = "light:blue"}, {["x"] = 8, ["meta"] = {["fields"] = {}, ["inventory"] = {}}, ["param2"] = 2, ["y"] = 0, ["param1"] = 222, ["z"] = 12, ["name"] = "stairs:stair_black"}, {["x"] = 8, ["meta"] = {["fields"] = {}, ["inventory"] = {}}, ["y"] = 1, ["param1"] = 222, ["z"] = 3, ["name"] = "stairs:stair_orange"}, {["x"] = 8, ["meta"] = {["fields"] = {}, ["inventory"] = {}}, ["y"] = 1, ["param1"] = 238, ["z"] = 4, ["name"] = "light:orange"}, {["x"] = 8, ["meta"] = {["fields"] = {}, ["inventory"] = {}}, ["y"] = 1, ["param1"] = 238, ["z"] = 5, ["name"] = "light:orange"}, {["x"] = 8, ["meta"] = {["fields"] = {}, ["inventory"] = {}}, ["y"] = 1, ["param1"] = 238, ["z"] = 6, ["name"] = "light:orange"}, {["x"] = 8, ["meta"] = {["fields"] = {}, ["inventory"] = {}}, ["y"] = 1, ["param1"] = 238, ["z"] = 7, ["name"] = "light:orange"}, {["x"] = 8, ["meta"] = {["fields"] = {}, ["inventory"] = {}}, ["y"] = 1, ["param1"] = 238, ["z"] = 8, ["name"] = "light:orange"}, {["x"] = 8, ["meta"] = {["fields"] = {}, ["inventory"] = {}}, ["param2"] = 2, ["y"] = 1, ["param1"] = 222, ["z"] = 9, ["name"] = "stairs:stair_orange"}, {["x"] = 8, ["meta"] = {["fields"] = {}, ["inventory"] = {}}, ["y"] = 4, ["param1"] = 174, ["z"] = 1, ["name"] = "slope:slopelong_blue"}, {["x"] = 8, ["meta"] = {["fields"] = {}, ["inventory"] = {}}, ["param2"] = 2, ["y"] = 4, ["param1"] = 174, ["z"] = 11, ["name"] = "slope:slopelong_blue"}, {["x"] = 8, ["meta"] = {["fields"] = {}, ["inventory"] = {}}, ["y"] = 5, ["param1"] = 158, ["z"] = 3, ["name"] = "slope:slopelong_pink"}, {["x"] = 8, ["meta"] = {["fields"] = {}, ["inventory"] = {}}, ["y"] = 5, ["param1"] = 174, ["z"] = 4, ["name"] = "carpet:green"}, {["x"] = 8, ["meta"] = {["fields"] = {}, ["inventory"] = {}}, ["y"] = 5, ["param1"] = 174, ["z"] = 8, ["name"] = "carpet:green"}, {["x"] = 8, ["meta"] = {["fields"] = {}, ["inventory"] = {}}, ["param2"] = 2, ["y"] = 5, ["param1"] = 158, ["z"] = 9, ["name"] = "slope:slopelong_pink"}, {["x"] = 8, ["meta"] = {["fields"] = {}, ["inventory"] = {}}, ["param2"] = 21, ["y"] = 6, ["param1"] = 190, ["z"] = 4, ["name"] = "slope:cone_green"}, {["x"] = 8, ["meta"] = {["fields"] = {}, ["inventory"] = {}}, ["param2"] = 1, ["y"] = 6, ["param1"] = 175, ["z"] = 5, ["name"] = "carpet:green"}, {["x"] = 8, ["meta"] = {["fields"] = {}, ["inventory"] = {}}, ["param2"] = 1, ["y"] = 6, ["param1"] = 175, ["z"] = 7, ["name"] = "carpet:green"}, {["x"] = 8, ["meta"] = {["fields"] = {}, ["inventory"] = {}}, ["param2"] = 21, ["y"] = 6, ["param1"] = 190, ["z"] = 8, ["name"] = "slope:cone_green"}, {["x"] = 8, ["meta"] = {["fields"] = {}, ["inventory"] = {}}, ["y"] = 7, ["param1"] = 206, ["z"] = 4, ["name"] = "slope:cylinder_green"}, {["x"] = 8, ["meta"] = {["fields"] = {}, ["inventory"] = {}}, ["param2"] = 3, ["y"] = 7, ["param1"] = 206, ["z"] = 8, ["name"] = "slope:cylinder_green"}, {["x"] = 8, ["meta"] = {["fields"] = {}, ["inventory"] = {}}, ["y"] = 8, ["param1"] = 222, ["z"] = 4, ["name"] = "slope:cone_green"}, {["x"] = 8, ["meta"] = {["fields"] = {}, ["inventory"] = {}}, ["param2"] = 3, ["y"] = 8, ["param1"] = 222, ["z"] = 8, ["name"] = "slope:cone_green"}, {["x"] = 8, ["meta"] = {["fields"] = {}, ["inventory"] = {}}, ["y"] = 9, ["param1"] = 238, ["z"] = 4, ["name"] = "light:green"}, {["x"] = 8, ["meta"] = {["fields"] = {}, ["inventory"] = {}}, ["y"] = 9, ["param1"] = 238, ["z"] = 8, ["name"] = "light:green"}, {["x"] = 8, ["meta"] = {["fields"] = {}, ["inventory"] = {}}, ["param2"] = 20, ["y"] = 10, ["param1"] = 222, ["z"] = 4, ["name"] = "slope:cone_green"}, {["x"] = 8, ["meta"] = {["fields"] = {}, ["inventory"] = {}}, ["param2"] = 21, ["y"] = 10, ["param1"] = 222, ["z"] = 8, ["name"] = "slope:cone_green"}, {["x"] = 8, ["meta"] = {["fields"] = {}, ["inventory"] = {}}, ["param2"] = 2, ["y"] = 11, ["param1"] = 206, ["z"] = 4, ["name"] = "slope:cone_green"}, {["x"] = 8, ["meta"] = {["fields"] = {}, ["inventory"] = {}}, ["param2"] = 1, ["y"] = 11, ["param1"] = 206, ["z"] = 8, ["name"] = "slope:cone_green"}, {["x"] = 8, ["meta"] = {["fields"] = {}, ["inventory"] = {}}, ["param2"] = 1, ["y"] = 12, ["param1"] = 190, ["z"] = 4, ["name"] = "slope:sphere_red"}, {["x"] = 8, ["meta"] = {["fields"] = {}, ["inventory"] = {}}, ["param2"] = 1, ["y"] = 12, ["param1"] = 190, ["z"] = 8, ["name"] = "slope:sphere_red"}, {["x"] = 9, ["meta"] = {["fields"] = {}, ["inventory"] = {}}, ["y"] = 0, ["param1"] = 222, ["z"] = 0, ["name"] = "stairs:stair_black"}, {["x"] = 9, ["meta"] = {["fields"] = {}, ["inventory"] = {}}, ["y"] = 0, ["param1"] = 238, ["z"] = 1, ["name"] = "light:blue"}, {["x"] = 9, ["meta"] = {["fields"] = {}, ["inventory"] = {}}, ["y"] = 0, ["param1"] = 238, ["z"] = 2, ["name"] = "light:blue"}, {["x"] = 9, ["meta"] = {["fields"] = {}, ["inventory"] = {}}, ["y"] = 0, ["param1"] = 238, ["z"] = 10, ["name"] = "light:blue"}, {["x"] = 9, ["meta"] = {["fields"] = {}, ["inventory"] = {}}, ["y"] = 0, ["param1"] = 238, ["z"] = 11, ["name"] = "light:blue"}, {["x"] = 9, ["meta"] = {["fields"] = {}, ["inventory"] = {}}, ["param2"] = 2, ["y"] = 0, ["param1"] = 222, ["z"] = 12, ["name"] = "stairs:stair_black"}, {["x"] = 9, ["meta"] = {["fields"] = {}, ["inventory"] = {}}, ["y"] = 1, ["param1"] = 222, ["z"] = 1, ["name"] = "slope:cone_blue"}, {["x"] = 9, ["meta"] = {["fields"] = {}, ["inventory"] = {}}, ["y"] = 1, ["param1"] = 206, ["z"] = 3, ["name"] = "stairs:stair_outer_orange"}, {["x"] = 9, ["meta"] = {["fields"] = {}, ["inventory"] = {}}, ["param2"] = 3, ["y"] = 1, ["param1"] = 222, ["z"] = 4, ["name"] = "stairs:stair_orange"}, {["x"] = 9, ["meta"] = {["fields"] = {}, ["inventory"] = {}}, ["param2"] = 3, ["y"] = 1, ["param1"] = 222, ["z"] = 5, ["name"] = "stairs:stair_orange"}, {["x"] = 9, ["meta"] = {["fields"] = {}, ["inventory"] = {}}, ["param2"] = 3, ["y"] = 1, ["param1"] = 222, ["z"] = 6, ["name"] = "stairs:stair_orange"}, {["x"] = 9, ["meta"] = {["fields"] = {}, ["inventory"] = {}}, ["param2"] = 3, ["y"] = 1, ["param1"] = 222, ["z"] = 7, ["name"] = "stairs:stair_orange"}, {["x"] = 9, ["meta"] = {["fields"] = {}, ["inventory"] = {}}, ["param2"] = 3, ["y"] = 1, ["param1"] = 222, ["z"] = 8, ["name"] = "stairs:stair_orange"}, {["x"] = 9, ["meta"] = {["fields"] = {}, ["inventory"] = {}}, ["param2"] = 3, ["y"] = 1, ["param1"] = 206, ["z"] = 9, ["name"] = "stairs:stair_outer_orange"}, {["x"] = 9, ["meta"] = {["fields"] = {}, ["inventory"] = {}}, ["param2"] = 2, ["y"] = 1, ["param1"] = 222, ["z"] = 11, ["name"] = "slope:cone_blue"}, {["x"] = 9, ["meta"] = {["fields"] = {}, ["inventory"] = {}}, ["y"] = 2, ["param1"] = 206, ["z"] = 1, ["name"] = "slope:sphere_blue"}, {["x"] = 9, ["meta"] = {["fields"] = {}, ["inventory"] = {}}, ["param2"] = 2, ["y"] = 2, ["param1"] = 206, ["z"] = 11, ["name"] = "slope:sphere_orange"}, {["x"] = 9, ["meta"] = {["fields"] = {}, ["inventory"] = {}}, ["param2"] = 20, ["y"] = 3, ["param1"] = 190, ["z"] = 1, ["name"] = "slope:cone_blue"}, {["x"] = 9, ["meta"] = {["fields"] = {}, ["inventory"] = {}}, ["param2"] = 22, ["y"] = 3, ["param1"] = 190, ["z"] = 11, ["name"] = "slope:cone_blue"}, {["x"] = 9, ["meta"] = {["fields"] = {}, ["inventory"] = {}}, ["y"] = 4, ["param1"] = 174, ["z"] = 1, ["name"] = "slope:slopelong_blue"}, {["x"] = 9, ["meta"] = {["fields"] = {}, ["inventory"] = {}}, ["param2"] = 2, ["y"] = 4, ["param1"] = 174, ["z"] = 11, ["name"] = "slope:slopelong_blue"}, {["x"] = 9, ["meta"] = {["fields"] = {}, ["inventory"] = {}}, ["param2"] = 1, ["y"] = 5, ["param1"] = 191, ["z"] = 2, ["name"] = "carpet:pink"}, {["x"] = 9, ["meta"] = {["fields"] = {}, ["inventory"] = {}}, ["y"] = 5, ["param1"] = 174, ["z"] = 3, ["name"] = "slope:ocorner_pink"}, {["x"] = 9, ["meta"] = {["fields"] = {}, ["inventory"] = {}}, ["param2"] = 3, ["y"] = 5, ["param1"] = 158, ["z"] = 4, ["name"] = "slope:slopelong_pink"}, {["x"] = 9, ["meta"] = {["fields"] = {}, ["inventory"] = {}}, ["param2"] = 3, ["y"] = 5, ["param1"] = 158, ["z"] = 5, ["name"] = "slope:slopelong_pink"}, {["x"] = 9, ["meta"] = {["fields"] = {}, ["inventory"] = {}}, ["param2"] = 3, ["y"] = 5, ["param1"] = 158, ["z"] = 6, ["name"] = "slope:slopelong_pink"}, {["x"] = 9, ["meta"] = {["fields"] = {}, ["inventory"] = {}}, ["param2"] = 3, ["y"] = 5, ["param1"] = 158, ["z"] = 7, ["name"] = "slope:slopelong_pink"}, {["x"] = 9, ["meta"] = {["fields"] = {}, ["inventory"] = {}}, ["param2"] = 3, ["y"] = 5, ["param1"] = 158, ["z"] = 8, ["name"] = "slope:slopelong_pink"}, {["x"] = 9, ["meta"] = {["fields"] = {}, ["inventory"] = {}}, ["param2"] = 3, ["y"] = 5, ["param1"] = 174, ["z"] = 9, ["name"] = "slope:ocorner_pink"}, {["x"] = 9, ["meta"] = {["fields"] = {}, ["inventory"] = {}}, ["param2"] = 1, ["y"] = 5, ["param1"] = 191, ["z"] = 10, ["name"] = "carpet:pink"}, {["x"] = 10, ["meta"] = {["fields"] = {}, ["inventory"] = {}}, ["y"] = 0, ["param1"] = 222, ["z"] = 0, ["name"] = "stairs:stair_black"}, {["x"] = 10, ["meta"] = {["fields"] = {}, ["inventory"] = {}}, ["y"] = 0, ["param1"] = 238, ["z"] = 1, ["name"] = "light:blue"}, {["x"] = 10, ["meta"] = {["fields"] = {}, ["inventory"] = {}}, ["y"] = 0, ["param1"] = 238, ["z"] = 2, ["name"] = "light:blue"}, {["x"] = 10, ["meta"] = {["fields"] = {}, ["inventory"] = {}}, ["y"] = 0, ["param1"] = 238, ["z"] = 3, ["name"] = "light:blue"}, {["x"] = 10, ["meta"] = {["fields"] = {}, ["inventory"] = {}}, ["y"] = 0, ["param1"] = 238, ["z"] = 4, ["name"] = "light:blue"}, {["x"] = 10, ["meta"] = {["fields"] = {}, ["inventory"] = {}}, ["y"] = 0, ["param1"] = 238, ["z"] = 5, ["name"] = "light:blue"}, {["x"] = 10, ["meta"] = {["fields"] = {}, ["inventory"] = {}}, ["y"] = 0, ["param1"] = 238, ["z"] = 6, ["name"] = "light:blue"}, {["x"] = 10, ["meta"] = {["fields"] = {}, ["inventory"] = {}}, ["y"] = 0, ["param1"] = 238, ["z"] = 7, ["name"] = "light:blue"}, {["x"] = 10, ["meta"] = {["fields"] = {}, ["inventory"] = {}}, ["y"] = 0, ["param1"] = 238, ["z"] = 8, ["name"] = "light:blue"}, {["x"] = 10, ["meta"] = {["fields"] = {}, ["inventory"] = {}}, ["y"] = 0, ["param1"] = 238, ["z"] = 9, ["name"] = "light:blue"}, {["x"] = 10, ["meta"] = {["fields"] = {}, ["inventory"] = {}}, ["y"] = 0, ["param1"] = 238, ["z"] = 10, ["name"] = "light:blue"}, {["x"] = 10, ["meta"] = {["fields"] = {}, ["inventory"] = {}}, ["y"] = 0, ["param1"] = 238, ["z"] = 11, ["name"] = "light:blue"}, {["x"] = 10, ["meta"] = {["fields"] = {}, ["inventory"] = {}}, ["param2"] = 2, ["y"] = 0, ["param1"] = 222, ["z"] = 12, ["name"] = "stairs:stair_black"}, {["x"] = 10, ["meta"] = {["fields"] = {}, ["inventory"] = {}}, ["y"] = 4, ["param1"] = 174, ["z"] = 1, ["name"] = "slope:slopelong_blue"}, {["x"] = 10, ["meta"] = {["fields"] = {}, ["inventory"] = {}}, ["y"] = 4, ["param1"] = 190, ["z"] = 2, ["name"] = "carpet:pink"}, {["x"] = 10, ["meta"] = {["fields"] = {}, ["inventory"] = {}}, ["y"] = 4, ["param1"] = 190, ["z"] = 10, ["name"] = "carpet:pink"}, {["x"] = 10, ["meta"] = {["fields"] = {}, ["inventory"] = {}}, ["param2"] = 2, ["y"] = 4, ["param1"] = 174, ["z"] = 11, ["name"] = "slope:slopelong_blue"}, {["x"] = 10, ["meta"] = {["fields"] = {}, ["inventory"] = {}}, ["param2"] = 20, ["y"] = 5, ["param1"] = 206, ["z"] = 2, ["name"] = "slope:cone_pink"}, {["x"] = 10, ["meta"] = {["fields"] = {}, ["inventory"] = {}}, ["param2"] = 1, ["y"] = 5, ["param1"] = 191, ["z"] = 3, ["name"] = "carpet:pink"}, {["x"] = 10, ["meta"] = {["fields"] = {}, ["inventory"] = {}}, ["param2"] = 1, ["y"] = 5, ["param1"] = 191, ["z"] = 9, ["name"] = "carpet:pink"}, {["x"] = 10, ["meta"] = {["fields"] = {}, ["inventory"] = {}}, ["param2"] = 21, ["y"] = 5, ["param1"] = 206, ["z"] = 10, ["name"] = "slope:cone_pink"}, {["x"] = 10, ["meta"] = {["fields"] = {}, ["inventory"] = {}}, ["y"] = 6, ["param1"] = 222, ["z"] = 2, ["name"] = "slope:cone_pink"}, {["x"] = 10, ["meta"] = {["fields"] = {}, ["inventory"] = {}}, ["y"] = 6, ["param1"] = 222, ["z"] = 10, ["name"] = "slope:cone_pink"}, {["x"] = 10, ["meta"] = {["fields"] = {}, ["inventory"] = {}}, ["y"] = 7, ["param1"] = 238, ["z"] = 2, ["name"] = "light:pink"}, {["x"] = 10, ["meta"] = {["fields"] = {}, ["inventory"] = {}}, ["y"] = 7, ["param1"] = 238, ["z"] = 10, ["name"] = "light:pink"}, {["x"] = 10, ["meta"] = {["fields"] = {}, ["inventory"] = {}}, ["param2"] = 20, ["y"] = 8, ["param1"] = 222, ["z"] = 2, ["name"] = "slope:cone_pink"}, {["x"] = 10, ["meta"] = {["fields"] = {}, ["inventory"] = {}}, ["param2"] = 21, ["y"] = 8, ["param1"] = 222, ["z"] = 10, ["name"] = "slope:cone_pink"}, {["x"] = 10, ["meta"] = {["fields"] = {}, ["inventory"] = {}}, ["param2"] = 3, ["y"] = 9, ["param1"] = 206, ["z"] = 2, ["name"] = "slope:sphere_orange"}, {["x"] = 10, ["meta"] = {["fields"] = {}, ["inventory"] = {}}, ["param2"] = 2, ["y"] = 9, ["param1"] = 206, ["z"] = 10, ["name"] = "slope:sphere_orange"}, {["x"] = 10, ["meta"] = {["fields"] = {}, ["inventory"] = {}}, ["param2"] = 1, ["y"] = 10, ["param1"] = 190, ["z"] = 2, ["name"] = "slope:cone_pink"}, {["x"] = 10, ["meta"] = {["fields"] = {}, ["inventory"] = {}}, ["y"] = 10, ["param1"] = 190, ["z"] = 10, ["name"] = "slope:cone_pink"}, {["x"] = 10, ["meta"] = {["fields"] = {}, ["inventory"] = {}}, ["param2"] = 2, ["y"] = 11, ["param1"] = 174, ["z"] = 2, ["name"] = "slope:sphere_pink"}, {["x"] = 10, ["meta"] = {["fields"] = {}, ["inventory"] = {}}, ["param2"] = 2, ["y"] = 11, ["param1"] = 174, ["z"] = 10, ["name"] = "slope:sphere_pink"}, {["x"] = 11, ["meta"] = {["fields"] = {}, ["inventory"] = {}}, ["y"] = 0, ["param1"] = 222, ["z"] = 0, ["name"] = "stairs:stair_black"}, {["x"] = 11, ["meta"] = {["fields"] = {}, ["inventory"] = {}}, ["y"] = 0, ["param1"] = 238, ["z"] = 1, ["name"] = "light:blue"}, {["x"] = 11, ["meta"] = {["fields"] = {}, ["inventory"] = {}}, ["y"] = 0, ["param1"] = 238, ["z"] = 2, ["name"] = "light:blue"}, {["x"] = 11, ["meta"] = {["fields"] = {}, ["inventory"] = {}}, ["y"] = 0, ["param1"] = 238, ["z"] = 3, ["name"] = "light:blue"}, {["x"] = 11, ["meta"] = {["fields"] = {}, ["inventory"] = {}}, ["y"] = 0, ["param1"] = 238, ["z"] = 4, ["name"] = "light:blue"}, {["x"] = 11, ["meta"] = {["fields"] = {}, ["inventory"] = {}}, ["y"] = 0, ["param1"] = 238, ["z"] = 5, ["name"] = "light:blue"}, {["x"] = 11, ["meta"] = {["fields"] = {}, ["inventory"] = {}}, ["y"] = 0, ["param1"] = 238, ["z"] = 6, ["name"] = "light:blue"}, {["x"] = 11, ["meta"] = {["fields"] = {}, ["inventory"] = {}}, ["y"] = 0, ["param1"] = 238, ["z"] = 7, ["name"] = "light:blue"}, {["x"] = 11, ["meta"] = {["fields"] = {}, ["inventory"] = {}}, ["y"] = 0, ["param1"] = 238, ["z"] = 8, ["name"] = "light:blue"}, {["x"] = 11, ["meta"] = {["fields"] = {}, ["inventory"] = {}}, ["y"] = 0, ["param1"] = 238, ["z"] = 9, ["name"] = "light:blue"}, {["x"] = 11, ["meta"] = {["fields"] = {}, ["inventory"] = {}}, ["y"] = 0, ["param1"] = 238, ["z"] = 10, ["name"] = "light:blue"}, {["x"] = 11, ["meta"] = {["fields"] = {}, ["inventory"] = {}}, ["y"] = 0, ["param1"] = 238, ["z"] = 11, ["name"] = "light:blue"}, {["x"] = 11, ["meta"] = {["fields"] = {}, ["inventory"] = {}}, ["param2"] = 2, ["y"] = 0, ["param1"] = 222, ["z"] = 12, ["name"] = "stairs:stair_black"}, {["x"] = 11, ["meta"] = {["fields"] = {}, ["inventory"] = {}}, ["param2"] = 3, ["y"] = 1, ["param1"] = 222, ["z"] = 1, ["name"] = "slope:cone_blue"}, {["x"] = 11, ["meta"] = {["fields"] = {}, ["inventory"] = {}}, ["param2"] = 3, ["y"] = 1, ["param1"] = 222, ["z"] = 3, ["name"] = "slope:cone_blue"}, {["x"] = 11, ["meta"] = {["fields"] = {}, ["inventory"] = {}}, ["param2"] = 3, ["y"] = 1, ["param1"] = 222, ["z"] = 5, ["name"] = "slope:cone_blue"}, {["x"] = 11, ["meta"] = {["fields"] = {}, ["inventory"] = {}}, ["param2"] = 3, ["y"] = 1, ["param1"] = 222, ["z"] = 7, ["name"] = "slope:cone_blue"}, {["x"] = 11, ["meta"] = {["fields"] = {}, ["inventory"] = {}}, ["param2"] = 3, ["y"] = 1, ["param1"] = 222, ["z"] = 9, ["name"] = "slope:cone_blue"}, {["x"] = 11, ["meta"] = {["fields"] = {}, ["inventory"] = {}}, ["param2"] = 3, ["y"] = 1, ["param1"] = 222, ["z"] = 11, ["name"] = "slope:cone_blue"}, {["x"] = 11, ["meta"] = {["fields"] = {}, ["inventory"] = {}}, ["param2"] = 3, ["y"] = 2, ["param1"] = 206, ["z"] = 1, ["name"] = "slope:sphere_red"}, {["x"] = 11, ["meta"] = {["fields"] = {}, ["inventory"] = {}}, ["param2"] = 3, ["y"] = 2, ["param1"] = 206, ["z"] = 3, ["name"] = "slope:sphere_orange"}, {["x"] = 11, ["meta"] = {["fields"] = {}, ["inventory"] = {}}, ["param2"] = 3, ["y"] = 2, ["param1"] = 206, ["z"] = 5, ["name"] = "slope:sphere_pink"}, {["x"] = 11, ["meta"] = {["fields"] = {}, ["inventory"] = {}}, ["param2"] = 3, ["y"] = 2, ["param1"] = 206, ["z"] = 7, ["name"] = "slope:sphere_green"}, {["x"] = 11, ["meta"] = {["fields"] = {}, ["inventory"] = {}}, ["param2"] = 3, ["y"] = 2, ["param1"] = 206, ["z"] = 9, ["name"] = "slope:sphere_blue"}, {["x"] = 11, ["meta"] = {["fields"] = {}, ["inventory"] = {}}, ["param2"] = 2, ["y"] = 2, ["param1"] = 206, ["z"] = 11, ["name"] = "slope:sphere_red"}, {["x"] = 11, ["meta"] = {["fields"] = {}, ["inventory"] = {}}, ["param2"] = 21, ["y"] = 3, ["param1"] = 190, ["z"] = 1, ["name"] = "slope:cone_blue"}, {["x"] = 11, ["meta"] = {["fields"] = {}, ["inventory"] = {}}, ["param2"] = 21, ["y"] = 3, ["param1"] = 190, ["z"] = 3, ["name"] = "slope:cone_blue"}, {["x"] = 11, ["meta"] = {["fields"] = {}, ["inventory"] = {}}, ["param2"] = 22, ["y"] = 3, ["param1"] = 190, ["z"] = 5, ["name"] = "slope:cone_blue"}, {["x"] = 11, ["meta"] = {["fields"] = {}, ["inventory"] = {}}, ["param2"] = 21, ["y"] = 3, ["param1"] = 190, ["z"] = 7, ["name"] = "slope:cone_blue"}, {["x"] = 11, ["meta"] = {["fields"] = {}, ["inventory"] = {}}, ["param2"] = 21, ["y"] = 3, ["param1"] = 190, ["z"] = 9, ["name"] = "slope:cone_blue"}, {["x"] = 11, ["meta"] = {["fields"] = {}, ["inventory"] = {}}, ["param2"] = 21, ["y"] = 3, ["param1"] = 190, ["z"] = 11, ["name"] = "slope:cone_blue"}, {["x"] = 11, ["meta"] = {["fields"] = {}, ["inventory"] = {}}, ["y"] = 4, ["param1"] = 174, ["z"] = 1, ["name"] = "slope:ocorner_blue"}, {["x"] = 11, ["meta"] = {["fields"] = {}, ["inventory"] = {}}, ["param2"] = 3, ["y"] = 4, ["param1"] = 174, ["z"] = 2, ["name"] = "slope:slopelong_blue"}, {["x"] = 11, ["meta"] = {["fields"] = {}, ["inventory"] = {}}, ["param2"] = 3, ["y"] = 4, ["param1"] = 174, ["z"] = 3, ["name"] = "slope:slopelong_blue"}, {["x"] = 11, ["meta"] = {["fields"] = {}, ["inventory"] = {}}, ["param2"] = 3, ["y"] = 4, ["param1"] = 174, ["z"] = 4, ["name"] = "slope:slopelong_blue"}, {["x"] = 11, ["meta"] = {["fields"] = {}, ["inventory"] = {}}, ["param2"] = 3, ["y"] = 4, ["param1"] = 174, ["z"] = 5, ["name"] = "slope:slopelong_blue"}, {["x"] = 11, ["meta"] = {["fields"] = {}, ["inventory"] = {}}, ["param2"] = 3, ["y"] = 4, ["param1"] = 174, ["z"] = 6, ["name"] = "slope:slopelong_blue"}, {["x"] = 11, ["meta"] = {["fields"] = {}, ["inventory"] = {}}, ["param2"] = 3, ["y"] = 4, ["param1"] = 174, ["z"] = 7, ["name"] = "slope:slopelong_blue"}, {["x"] = 11, ["meta"] = {["fields"] = {}, ["inventory"] = {}}, ["param2"] = 3, ["y"] = 4, ["param1"] = 174, ["z"] = 8, ["name"] = "slope:slopelong_blue"}, {["x"] = 11, ["meta"] = {["fields"] = {}, ["inventory"] = {}}, ["param2"] = 3, ["y"] = 4, ["param1"] = 174, ["z"] = 9, ["name"] = "slope:slopelong_blue"}, {["x"] = 11, ["meta"] = {["fields"] = {}, ["inventory"] = {}}, ["param2"] = 3, ["y"] = 4, ["param1"] = 174, ["z"] = 10, ["name"] = "slope:slopelong_blue"}, {["x"] = 11, ["meta"] = {["fields"] = {}, ["inventory"] = {}}, ["param2"] = 3, ["y"] = 4, ["param1"] = 174, ["z"] = 11, ["name"] = "slope:ocorner_blue"}, {["x"] = 12, ["meta"] = {["fields"] = {}, ["inventory"] = {}}, ["y"] = 0, ["param1"] = 206, ["z"] = 0, ["name"] = "stairs:stair_outer_black"}, {["x"] = 12, ["meta"] = {["fields"] = {}, ["inventory"] = {}}, ["param2"] = 3, ["y"] = 0, ["param1"] = 222, ["z"] = 1, ["name"] = "stairs:stair_black"}, {["x"] = 12, ["meta"] = {["fields"] = {}, ["inventory"] = {}}, ["param2"] = 3, ["y"] = 0, ["param1"] = 222, ["z"] = 2, ["name"] = "stairs:stair_black"}, {["x"] = 12, ["meta"] = {["fields"] = {}, ["inventory"] = {}}, ["param2"] = 3, ["y"] = 0, ["param1"] = 222, ["z"] = 3, ["name"] = "stairs:stair_black"}, {["x"] = 12, ["meta"] = {["fields"] = {}, ["inventory"] = {}}, ["param2"] = 3, ["y"] = 0, ["param1"] = 222, ["z"] = 4, ["name"] = "stairs:stair_black"}, {["x"] = 12, ["meta"] = {["fields"] = {}, ["inventory"] = {}}, ["param2"] = 3, ["y"] = 0, ["param1"] = 222, ["z"] = 5, ["name"] = "stairs:stair_black"}, {["x"] = 12, ["meta"] = {["fields"] = {}, ["inventory"] = {}}, ["param2"] = 3, ["y"] = 0, ["param1"] = 222, ["z"] = 6, ["name"] = "stairs:stair_black"}, {["x"] = 12, ["meta"] = {["fields"] = {}, ["inventory"] = {}}, ["param2"] = 3, ["y"] = 0, ["param1"] = 222, ["z"] = 7, ["name"] = "stairs:stair_black"}, {["x"] = 12, ["meta"] = {["fields"] = {}, ["inventory"] = {}}, ["param2"] = 3, ["y"] = 0, ["param1"] = 222, ["z"] = 8, ["name"] = "stairs:stair_black"}, {["x"] = 12, ["meta"] = {["fields"] = {}, ["inventory"] = {}}, ["param2"] = 3, ["y"] = 0, ["param1"] = 222, ["z"] = 9, ["name"] = "stairs:stair_black"}, {["x"] = 12, ["meta"] = {["fields"] = {}, ["inventory"] = {}}, ["param2"] = 3, ["y"] = 0, ["param1"] = 222, ["z"] = 10, ["name"] = "stairs:stair_black"}, {["x"] = 12, ["meta"] = {["fields"] = {}, ["inventory"] = {}}, ["param2"] = 3, ["y"] = 0, ["param1"] = 222, ["z"] = 11, ["name"] = "stairs:stair_black"}, {["x"] = 12, ["meta"] = {["fields"] = {}, ["inventory"] = {}}, ["param2"] = 3, ["y"] = 0, ["param1"] = 206, ["z"] = 12, ["name"] = "stairs:stair_outer_black"}}