5:return {{["x"] = 0, ["meta"] = {["fields"] = {}, ["inventory"] = {}}, ["param2"] = 1, ["y"] = 17, ["param1"] = 190, ["z"] = 5, ["name"] = "slope:sphere_red"}, {["x"] = 1, ["meta"] = {["fields"] = {}, ["inventory"] = {}}, ["param2"] = 18, ["y"] = 17, ["param1"] = 206, ["z"] = 5, ["name"] = "slope:cone_blue"}, {["x"] = 2, ["meta"] = {["fields"] = {}, ["inventory"] = {}}, ["param2"] = 12, ["y"] = 17, ["param1"] = 222, ["z"] = 5, ["name"] = "slope:cone_blue"}, {["x"] = 3, ["meta"] = {["fields"] = {}, ["inventory"] = {}}, ["param2"] = 1, ["y"] = 15, ["param1"] = 205, ["z"] = 5, ["name"] = "slope:sphere_red"}, {["x"] = 3, ["meta"] = {["fields"] = {}, ["inventory"] = {}}, ["param2"] = 22, ["y"] = 16, ["param1"] = 221, ["z"] = 5, ["name"] = "slope:cone_blue"}, {["x"] = 3, ["meta"] = {["fields"] = {}, ["inventory"] = {}}, ["param2"] = 1, ["y"] = 17, ["param1"] = 206, ["z"] = 3, ["name"] = "slope:sphere_red"}, {["x"] = 3, ["meta"] = {["fields"] = {}, ["inventory"] = {}}, ["param2"] = 9, ["y"] = 17, ["param1"] = 222, ["z"] = 4, ["name"] = "slope:cone_blue"}, {["x"] = 3, ["meta"] = {["fields"] = {}, ["inventory"] = {}}, ["y"] = 17, ["param1"] = 238, ["z"] = 5, ["name"] = "light:blue"}, {["x"] = 3, ["meta"] = {["fields"] = {}, ["inventory"] = {}}, ["param2"] = 7, ["y"] = 17, ["param1"] = 222, ["z"] = 6, ["name"] = "slope:cone_blue"}, {["x"] = 3, ["meta"] = {["fields"] = {}, ["inventory"] = {}}, ["param2"] = 1, ["y"] = 17, ["param1"] = 206, ["z"] = 7, ["name"] = "slope:sphere_red"}, {["x"] = 3, ["meta"] = {["fields"] = {}, ["inventory"] = {}}, ["y"] = 18, ["param1"] = 222, ["z"] = 5, ["name"] = "slope:cone_blue"}, {["x"] = 3, ["meta"] = {["fields"] = {}, ["inventory"] = {}}, ["param2"] = 1, ["y"] = 19, ["param1"] = 206, ["z"] = 5, ["name"] = "slope:sphere_red"}, {["x"] = 4, ["meta"] = {["fields"] = {}, ["inventory"] = {}}, ["param2"] = 18, ["y"] = 15, ["param1"] = 222, ["z"] = 5, ["name"] = "slope:cone_white"}, {["x"] = 4, ["meta"] = {["fields"] = {}, ["inventory"] = {}}, ["param2"] = 18, ["y"] = 17, ["param1"] = 190, ["z"] = 3, ["name"] = "slope:cone_yellow"}, {["x"] = 4, ["meta"] = {["fields"] = {}, ["inventory"] = {}}, ["param2"] = 18, ["y"] = 17, ["param1"] = 222, ["z"] = 5, ["name"] = "slope:cone_blue"}, {["x"] = 4, ["meta"] = {["fields"] = {}, ["inventory"] = {}}, ["param2"] = 18, ["y"] = 17, ["param1"] = 222, ["z"] = 7, ["name"] = "slope:cone_pink"}, {["x"] = 4, ["meta"] = {["fields"] = {}, ["inventory"] = {}}, ["param2"] = 18, ["y"] = 19, ["param1"] = 222, ["z"] = 5, ["name"] = "slope:cone_white"}, {["x"] = 5, ["meta"] = {["fields"] = {}, ["inventory"] = {}}, ["param2"] = 23, ["y"] = 0, ["param1"] = 61, ["z"] = 5, ["name"] = "slope:cone_white"}, {["x"] = 5, ["meta"] = {["fields"] = {}, ["inventory"] = {}}, ["param2"] = 23, ["y"] = 1, ["param1"] = 45, ["z"] = 5, ["name"] = "slope:cylinder_white"}, {["x"] = 5, ["meta"] = {["fields"] = {}, ["inventory"] = {}}, ["param2"] = 1, ["y"] = 2, ["param1"] = 29, ["z"] = 5, ["name"] = "slope:cone_white"}, {["x"] = 5, ["meta"] = {["fields"] = {}, ["inventory"] = {}}, ["param2"] = 1, ["y"] = 3, ["param1"] = 45, ["z"] = 5, ["name"] = "slope:sphere_red"}, {["x"] = 5, ["meta"] = {["fields"] = {}, ["inventory"] = {}}, ["param2"] = 23, ["y"] = 4, ["param1"] = 61, ["z"] = 5, ["name"] = "slope:cone_white"}, {["x"] = 5, ["meta"] = {["fields"] = {}, ["inventory"] = {}}, ["param2"] = 23, ["y"] = 5, ["param1"] = 77, ["z"] = 5, ["name"] = "slope:cylinder_white"}, {["x"] = 5, ["meta"] = {["fields"] = {}, ["inventory"] = {}}, ["param2"] = 1, ["y"] = 6, ["param1"] = 93, ["z"] = 5, ["name"] = "slope:cone_white"}, {["x"] = 5, ["meta"] = {["fields"] = {}, ["inventory"] = {}}, ["param2"] = 1, ["y"] = 7, ["param1"] = 109, ["z"] = 5, ["name"] = "slope:sphere_red"}, {["x"] = 5, ["meta"] = {["fields"] = {}, ["inventory"] = {}}, ["param2"] = 23, ["y"] = 8, ["param1"] = 125, ["z"] = 5, ["name"] = "slope:cone_white"}, {["x"] = 5, ["meta"] = {["fields"] = {}, ["inventory"] = {}}, ["param2"] = 23, ["y"] = 9, ["param1"] = 141, ["z"] = 5, ["name"] = "slope:cylinder_white"}, {["x"] = 5, ["meta"] = {["fields"] = {}, ["inventory"] = {}}, ["param2"] = 1, ["y"] = 10, ["param1"] = 157, ["z"] = 5, ["name"] = "slope:cone_white"}, {["x"] = 5, ["meta"] = {["fields"] = {}, ["inventory"] = {}}, ["param2"] = 1, ["y"] = 11, ["param1"] = 173, ["z"] = 5, ["name"] = "slope:sphere_red"}, {["x"] = 5, ["meta"] = {["fields"] = {}, ["inventory"] = {}}, ["param2"] = 23, ["y"] = 12, ["param1"] = 189, ["z"] = 5, ["name"] = "slope:cone_white"}, {["x"] = 5, ["meta"] = {["fields"] = {}, ["inventory"] = {}}, ["param2"] = 23, ["y"] = 13, ["param1"] = 205, ["z"] = 5, ["name"] = "slope:cylinder_white"}, {["x"] = 5, ["meta"] = {["fields"] = {}, ["inventory"] = {}}, ["param2"] = 1, ["y"] = 14, ["param1"] = 221, ["z"] = 5, ["name"] = "slope:cone_white"}, {["x"] = 5, ["meta"] = {["fields"] = {}, ["inventory"] = {}}, ["y"] = 15, ["param1"] = 205, ["z"] = 3, ["name"] = "slope:sphere_red"}, {["x"] = 5, ["meta"] = {["fields"] = {}, ["inventory"] = {}}, ["param2"] = 9, ["y"] = 15, ["param1"] = 222, ["z"] = 4, ["name"] = "slope:cone_white"}, {["x"] = 5, ["meta"] = {["fields"] = {}, ["inventory"] = {}}, ["y"] = 15, ["param1"] = 238, ["z"] = 5, ["name"] = "light:white"}, {["x"] = 5, ["meta"] = {["fields"] = {}, ["inventory"] = {}}, ["param2"] = 7, ["y"] = 15, ["param1"] = 222, ["z"] = 6, ["name"] = "slope:cone_white"}, {["x"] = 5, ["meta"] = {["fields"] = {}, ["inventory"] = {}}, ["param2"] = 2, ["y"] = 15, ["param1"] = 205, ["z"] = 7, ["name"] = "slope:sphere_red"}, {["x"] = 5, ["meta"] = {["fields"] = {}, ["inventory"] = {}}, ["param2"] = 21, ["y"] = 16, ["param1"] = 189, ["z"] = 3, ["name"] = "slope:cone_yellow"}, {["x"] = 5, ["meta"] = {["fields"] = {}, ["inventory"] = {}}, ["param2"] = 23, ["y"] = 16, ["param1"] = 221, ["z"] = 5, ["name"] = "slope:cone_white"}, {["x"] = 5, ["meta"] = {["fields"] = {}, ["inventory"] = {}}, ["param2"] = 23, ["y"] = 16, ["param1"] = 221, ["z"] = 7, ["name"] = "slope:cone_pink"}, {["x"] = 5, ["meta"] = {["fields"] = {}, ["inventory"] = {}}, ["y"] = 17, ["param1"] = 158, ["z"] = 0, ["name"] = "slope:sphere_red"}, {["x"] = 5, ["meta"] = {["fields"] = {}, ["inventory"] = {}}, ["param2"] = 9, ["y"] = 17, ["param1"] = 174, ["z"] = 1, ["name"] = "slope:cone_yellow"}, {["x"] = 5, ["meta"] = {["fields"] = {}, ["inventory"] = {}}, ["param2"] = 4, ["y"] = 17, ["param1"] = 190, ["z"] = 2, ["name"] = "slope:cone_yellow"}, {["x"] = 5, ["meta"] = {["fields"] = {}, ["inventory"] = {}}, ["param2"] = 3, ["y"] = 17, ["param1"] = 205, ["z"] = 3, ["name"] = "slope:sphere_yellow"}, {["x"] = 5, ["meta"] = {["fields"] = {}, ["inventory"] = {}}, ["param2"] = 9, ["y"] = 17, ["param1"] = 222, ["z"] = 4, ["name"] = "slope:cone_yellow"}, {["x"] = 5, ["meta"] = {["fields"] = {}, ["inventory"] = {}}, ["y"] = 17, ["param1"] = 238, ["z"] = 5, ["name"] = "light:white"}, {["x"] = 5, ["meta"] = {["fields"] = {}, ["inventory"] = {}}, ["param2"] = 7, ["y"] = 17, ["param1"] = 222, ["z"] = 6, ["name"] = "slope:cone_pink"}, {["x"] = 5, ["meta"] = {["fields"] = {}, ["inventory"] = {}}, ["y"] = 17, ["param1"] = 238, ["z"] = 7, ["name"] = "light:pink"}, {["x"] = 5, ["meta"] = {["fields"] = {}, ["inventory"] = {}}, ["param2"] = 8, ["y"] = 17, ["param1"] = 222, ["z"] = 8, ["name"] = "slope:cone_pink"}, {["x"] = 5, ["meta"] = {["fields"] = {}, ["inventory"] = {}}, ["param2"] = 7, ["y"] = 17, ["param1"] = 206, ["z"] = 9, ["name"] = "slope:cone_pink"}, {["x"] = 5, ["meta"] = {["fields"] = {}, ["inventory"] = {}}, ["param2"] = 2, ["y"] = 17, ["param1"] = 190, ["z"] = 10, ["name"] = "slope:sphere_red"}, {["x"] = 5, ["meta"] = {["fields"] = {}, ["inventory"] = {}}, ["param2"] = 1, ["y"] = 18, ["param1"] = 190, ["z"] = 3, ["name"] = "slope:cone_yellow"}, {["x"] = 5, ["meta"] = {["fields"] = {}, ["inventory"] = {}}, ["param2"] = 3, ["y"] = 18, ["param1"] = 221, ["z"] = 5, ["name"] = "slope:cone_white"}, {["x"] = 5, ["meta"] = {["fields"] = {}, ["inventory"] = {}}, ["param2"] = 3, ["y"] = 18, ["param1"] = 222, ["z"] = 7, ["name"] = "slope:cone_pink"}, {["x"] = 5, ["meta"] = {["fields"] = {}, ["inventory"] = {}}, ["param2"] = 3, ["y"] = 19, ["param1"] = 206, ["z"] = 3, ["name"] = "slope:sphere_red"}, {["x"] = 5, ["meta"] = {["fields"] = {}, ["inventory"] = {}}, ["param2"] = 9, ["y"] = 19, ["param1"] = 222, ["z"] = 4, ["name"] = "slope:cone_white"}, {["x"] = 5, ["meta"] = {["fields"] = {}, ["inventory"] = {}}, ["y"] = 19, ["param1"] = 238, ["z"] = 5, ["name"] = "light:white"}, {["x"] = 5, ["meta"] = {["fields"] = {}, ["inventory"] = {}}, ["param2"] = 7, ["y"] = 19, ["param1"] = 222, ["z"] = 6, ["name"] = "slope:cone_white"}, {["x"] = 5, ["meta"] = {["fields"] = {}, ["inventory"] = {}}, ["param2"] = 2, ["y"] = 19, ["param1"] = 206, ["z"] = 7, ["name"] = "slope:sphere_red"}, {["x"] = 5, ["meta"] = {["fields"] = {}, ["inventory"] = {}}, ["param2"] = 20, ["y"] = 20, ["param1"] = 222, ["z"] = 5, ["name"] = "slope:cone_white"}, {["x"] = 5, ["meta"] = {["fields"] = {}, ["inventory"] = {}}, ["param2"] = 3, ["y"] = 21, ["param1"] = 206, ["z"] = 5, ["name"] = "slope:cone_white"}, {["x"] = 5, ["meta"] = {["fields"] = {}, ["inventory"] = {}}, ["param2"] = 2, ["y"] = 22, ["param1"] = 190, ["z"] = 5, ["name"] = "slope:sphere_red"}, {["x"] = 6, ["meta"] = {["fields"] = {}, ["inventory"] = {}}, ["param2"] = 12, ["y"] = 15, ["param1"] = 222, ["z"] = 5, ["name"] = "slope:cone_white"}, {["x"] = 6, ["meta"] = {["fields"] = {}, ["inventory"] = {}}, ["param2"] = 12, ["y"] = 17, ["param1"] = 190, ["z"] = 3, ["name"] = "slope:cone_yellow"}, {["x"] = 6, ["meta"] = {["fields"] = {}, ["inventory"] = {}}, ["param2"] = 12, ["y"] = 17, ["param1"] = 222, ["z"] = 5, ["name"] = "slope:cone_green"}, {["x"] = 6, ["meta"] = {["fields"] = {}, ["inventory"] = {}}, ["param2"] = 12, ["y"] = 17, ["param1"] = 222, ["z"] = 7, ["name"] = "slope:cone_pink"}, {["x"] = 6, ["meta"] = {["fields"] = {}, ["inventory"] = {}}, ["param2"] = 12, ["y"] = 19, ["param1"] = 222, ["z"] = 5, ["name"] = "slope:cone_white"}, {["x"] = 7, ["meta"] = {["fields"] = {}, ["inventory"] = {}}, ["param2"] = 3, ["y"] = 15, ["param1"] = 205, ["z"] = 5, ["name"] = "slope:sphere_red"}, {["x"] = 7, ["meta"] = {["fields"] = {}, ["inventory"] = {}}, ["param2"] = 22, ["y"] = 16, ["param1"] = 221, ["z"] = 5, ["name"] = "slope:cone_green"}, {["x"] = 7, ["meta"] = {["fields"] = {}, ["inventory"] = {}}, ["y"] = 17, ["param1"] = 206, ["z"] = 3, ["name"] = "slope:sphere_red"}, {["x"] = 7, ["meta"] = {["fields"] = {}, ["inventory"] = {}}, ["param2"] = 9, ["y"] = 17, ["param1"] = 222, ["z"] = 4, ["name"] = "slope:cone_green"}, {["x"] = 7, ["meta"] = {["fields"] = {}, ["inventory"] = {}}, ["y"] = 17, ["param1"] = 238, ["z"] = 5, ["name"] = "light:green"}, {["x"] = 7, ["meta"] = {["fields"] = {}, ["inventory"] = {}}, ["param2"] = 7, ["y"] = 17, ["param1"] = 222, ["z"] = 6, ["name"] = "slope:cone_green"}, {["x"] = 7, ["meta"] = {["fields"] = {}, ["inventory"] = {}}, ["param2"] = 3, ["y"] = 17, ["param1"] = 206, ["z"] = 7, ["name"] = "slope:sphere_red"}, {["x"] = 7, ["meta"] = {["fields"] = {}, ["inventory"] = {}}, ["param2"] = 3, ["y"] = 18, ["param1"] = 222, ["z"] = 5, ["name"] = "slope:cone_green"}, {["x"] = 7, ["meta"] = {["fields"] = {}, ["inventory"] = {}}, ["param2"] = 3, ["y"] = 19, ["param1"] = 206, ["z"] = 5, ["name"] = "slope:sphere_red"}, {["x"] = 8, ["meta"] = {["fields"] = {}, ["inventory"] = {}}, ["param2"] = 16, ["y"] = 17, ["param1"] = 222, ["z"] = 5, ["name"] = "slope:cone_green"}, {["x"] = 9, ["meta"] = {["fields"] = {}, ["inventory"] = {}}, ["param2"] = 12, ["y"] = 17, ["param1"] = 206, ["z"] = 5, ["name"] = "slope:cone_green"}, {["x"] = 10, ["meta"] = {["fields"] = {}, ["inventory"] = {}}, ["param2"] = 3, ["y"] = 17, ["param1"] = 190, ["z"] = 5, ["name"] = "slope:sphere_red"}}