5:return {{["x"] = 0, ["y"] = 0, ["z"] = 0, ["name"] = "mcl_core:darkwood"}, {["x"] = 0, ["y"] = 0, ["z"] = 1, ["name"] = "mcl_core:darkwood"}, {["x"] = 0, ["y"] = 0, ["z"] = 2, ["name"] = "mcl_core:darkwood"}, {["x"] = 0, ["y"] = 0, ["z"] = 3, ["name"] = "mcl_core:darkwood"}, {["x"] = 0, ["y"] = 0, ["z"] = 4, ["name"] = "mcl_core:darkwood"}, {["x"] = 0, ["y"] = 0, ["z"] = 5, ["name"] = "mcl_core:darkwood"}, {["x"] = 0, ["y"] = 0, ["z"] = 6, ["name"] = "mcl_core:darkwood"}, {["x"] = 0, ["y"] = 1, ["z"] = 0, ["name"] = "mcl_core:junglewood"}, {["x"] = 0, ["y"] = 1, ["z"] = 1, ["name"] = "mcl_core:junglewood"}, {["x"] = 0, ["y"] = 1, ["z"] = 2, ["name"] = "mcl_core:junglewood"}, {["x"] = 0, ["y"] = 1, ["z"] = 3, ["name"] = "mcl_core:junglewood"}, {["x"] = 0, ["y"] = 1, ["z"] = 4, ["name"] = "mcl_core:junglewood"}, {["x"] = 0, ["y"] = 1, ["z"] = 5, ["name"] = "mcl_core:junglewood"}, {["x"] = 0, ["y"] = 1, ["z"] = 6, ["name"] = "mcl_core:junglewood"}, {["x"] = 0, ["y"] = 2, ["z"] = 0, ["name"] = "mcl_core:junglewood"}, {["x"] = 0, ["y"] = 2, ["z"] = 6, ["name"] = "mcl_core:junglewood"}, {["x"] = 0, ["y"] = 3, ["z"] = 0, ["name"] = "mcl_core:wood"}, {["x"] = 0, ["y"] = 3, ["z"] = 6, ["name"] = "mcl_core:wood"}, {["x"] = 0, ["y"] = 4, ["z"] = 0, ["name"] = "mcl_core:wood"}, {["x"] = 0, ["y"] = 4, ["z"] = 1, ["name"] = "mcl_core:wood"}, {["x"] = 0, ["y"] = 4, ["z"] = 2, ["name"] = "mcl_core:wood"}, {["x"] = 0, ["y"] = 4, ["z"] = 3, ["name"] = "mcl_core:wood"}, {["x"] = 0, ["y"] = 4, ["z"] = 4, ["name"] = "mcl_core:wood"}, {["x"] = 0, ["y"] = 4, ["z"] = 5, ["name"] = "mcl_core:wood"}, {["x"] = 0, ["y"] = 4, ["z"] = 6, ["name"] = "mcl_core:wood"}, {["x"] = 1, ["y"] = 0, ["z"] = 0, ["name"] = "mcl_core:darkwood"}, {["x"] = 1, ["param2"] = 2, ["y"] = 0, ["param1"] = 124, ["z"] = 1, ["name"] = "mcl_beds:bed_white_top"}, {["x"] = 1, ["param2"] = 2, ["y"] = 0, ["param1"] = 140, ["z"] = 2, ["name"] = "mcl_beds:bed_white_bottom"}, {["x"] = 1, ["y"] = 0, ["z"] = 3, ["name"] = "mcl_core:darkwood"}, {["x"] = 1, ["y"] = 0, ["z"] = 4, ["name"] = "mcl_core:darkwood"}, {["x"] = 1, ["y"] = 0, ["z"] = 5, ["name"] = "mcl_core:darkwood"}, {["x"] = 1, ["y"] = 0, ["z"] = 6, ["name"] = "mcl_core:darkwood"}, {["x"] = 1, ["y"] = 1, ["z"] = 0, ["name"] = "mcl_core:junglewood"}, {["x"] = 1, ["param2"] = 4, ["y"] = 1, ["param1"] = 175, ["z"] = 5, ["name"] = "mcl_core:ladder"}, {["x"] = 1, ["y"] = 1, ["z"] = 6, ["name"] = "mcl_core:junglewood"}, {["x"] = 1, ["param2"] = 4, ["y"] = 2, ["param1"] = 191, ["z"] = 5, ["name"] = "mcl_core:ladder"}, {["x"] = 1, ["y"] = 2, ["z"] = 6, ["name"] = "mcl_core:darkwood"}, {["x"] = 1, ["param2"] = 4, ["y"] = 3, ["param1"] = 175, ["z"] = 5, ["name"] = "mcl_core:ladder"}, {["x"] = 1, ["y"] = 3, ["z"] = 6, ["name"] = "mcl_core:darkwood"}, {["x"] = 1, ["y"] = 4, ["z"] = 0, ["name"] = "mcl_core:wood"}, {["x"] = 1, ["y"] = 4, ["z"] = 1, ["name"] = "mcl_core:wood"}, {["x"] = 1, ["y"] = 4, ["z"] = 2, ["name"] = "mcl_core:wood"}, {["x"] = 1, ["y"] = 4, ["z"] = 3, ["name"] = "mcl_core:darkwood"}, {["x"] = 1, ["y"] = 4, ["z"] = 4, ["name"] = "mcl_core:darkwood"}, {["x"] = 1, ["param2"] = 4, ["y"] = 4, ["param1"] = 191, ["z"] = 5, ["name"] = "mcl_core:ladder"}, {["x"] = 1, ["y"] = 4, ["z"] = 6, ["name"] = "mcl_core:wood"}, {["x"] = 2, ["y"] = 0, ["z"] = 0, ["name"] = "mcl_core:darkwood"}, {["x"] = 2, ["y"] = 0, ["z"] = 1, ["name"] = "mcl_core:darkwood"}, {["x"] = 2, ["y"] = 0, ["z"] = 2, ["name"] = "mcl_core:darkwood"}, {["x"] = 2, ["y"] = 0, ["z"] = 3, ["name"] = "mcl_core:darkwood"}, {["x"] = 2, ["y"] = 0, ["z"] = 4, ["name"] = "mcl_core:darkwood"}, {["x"] = 2, ["y"] = 0, ["z"] = 5, ["name"] = "mcl_core:darkwood"}, {["x"] = 2, ["y"] = 0, ["z"] = 6, ["name"] = "mcl_core:darkwood"}, {["x"] = 2, ["y"] = 1, ["z"] = 0, ["name"] = "mcl_core:junglewood"}, {["x"] = 2, ["y"] = 1, ["z"] = 6, ["name"] = "mcl_core:junglewood"}, {["x"] = 2, ["y"] = 2, ["z"] = 6, ["name"] = "mcl_core:darkwood"}, {["x"] = 2, ["y"] = 3, ["z"] = 6, ["name"] = "mcl_core:darkwood"}, {["x"] = 2, ["y"] = 4, ["z"] = 0, ["name"] = "mcl_core:wood"}, {["x"] = 2, ["y"] = 4, ["z"] = 1, ["name"] = "mcl_core:wood"}, {["x"] = 2, ["y"] = 4, ["z"] = 2, ["name"] = "mcl_core:wood"}, {["x"] = 2, ["y"] = 4, ["z"] = 3, ["name"] = "mcl_core:darkwood"}, {["x"] = 2, ["y"] = 4, ["z"] = 4, ["name"] = "mcl_core:darkwood"}, {["x"] = 2, ["y"] = 4, ["z"] = 5, ["name"] = "mcl_core:wood"}, {["x"] = 2, ["y"] = 4, ["z"] = 6, ["name"] = "mcl_core:wood"}, {["x"] = 3, ["y"] = 0, ["z"] = 0, ["name"] = "mcl_core:darkwood"}, {["x"] = 3, ["param2"] = 4, ["y"] = 0, ["param1"] = 124, ["z"] = 1, ["name"] = "mcl_core:ladder"}, {["x"] = 3, ["y"] = 0, ["z"] = 2, ["name"] = "mcl_core:darkwood"}, {["x"] = 3, ["y"] = 0, ["z"] = 3, ["name"] = "mcl_core:darkwood"}, {["x"] = 3, ["y"] = 0, ["z"] = 4, ["name"] = "mcl_core:darkwood"}, {["x"] = 3, ["y"] = 0, ["z"] = 5, ["name"] = "mcl_core:darkwood"}, {["x"] = 3, ["y"] = 0, ["z"] = 6, ["name"] = "mcl_core:darkwood"}, {["x"] = 3, ["y"] = 1, ["z"] = 0, ["name"] = "mcl_core:junglewood"}, {["x"] = 3, ["param2"] = 2, ["y"] = 1, ["param1"] = 140, ["z"] = 1, ["name"] = "mcl_doors:trapdoor_open"}, {["x"] = 3, ["y"] = 1, ["z"] = 6, ["name"] = "mcl_core:junglewood"}, {["x"] = 3, ["y"] = 2, ["z"] = 6, ["name"] = "mcl_core:darkwood"}, {["x"] = 3, ["y"] = 3, ["z"] = 6, ["name"] = "mcl_core:darkwood"}, {["x"] = 3, ["y"] = 4, ["z"] = 0, ["name"] = "mcl_core:wood"}, {["x"] = 3, ["y"] = 4, ["z"] = 1, ["name"] = "mcl_core:wood"}, {["x"] = 3, ["y"] = 4, ["z"] = 2, ["name"] = "mcl_core:wood"}, {["x"] = 3, ["y"] = 4, ["z"] = 3, ["name"] = "mcl_core:wood"}, {["x"] = 3, ["y"] = 4, ["z"] = 4, ["name"] = "mcl_core:junglewood"}, {["x"] = 3, ["y"] = 4, ["z"] = 5, ["name"] = "mcl_core:wood"}, {["x"] = 3, ["y"] = 4, ["z"] = 6, ["name"] = "mcl_core:wood"}, {["x"] = 4, ["y"] = 0, ["z"] = 0, ["name"] = "mcl_core:darkwood"}, {["x"] = 4, ["y"] = 0, ["z"] = 1, ["name"] = "mcl_core:darkwood"}, {["x"] = 4, ["y"] = 0, ["z"] = 2, ["name"] = "mcl_core:darkwood"}, {["x"] = 4, ["y"] = 0, ["z"] = 3, ["name"] = "mcl_core:darkwood"}, {["x"] = 4, ["y"] = 0, ["z"] = 4, ["name"] = "mcl_core:darkwood"}, {["x"] = 4, ["y"] = 0, ["z"] = 5, ["name"] = "mcl_core:darkwood"}, {["x"] = 4, ["y"] = 0, ["z"] = 6, ["name"] = "mcl_core:darkwood"}, {["x"] = 4, ["y"] = 1, ["z"] = 0, ["name"] = "mcl_core:junglewood"}, {["x"] = 4, ["y"] = 1, ["z"] = 6, ["name"] = "mcl_core:junglewood"}, {["x"] = 4, ["param2"] = 4, ["y"] = 2, ["param1"] = 238, ["z"] = 5, ["name"] = "mcl_torches:torch_wall"}, {["x"] = 4, ["y"] = 2, ["z"] = 6, ["name"] = "mcl_core:darkwood"}, {["x"] = 4, ["y"] = 3, ["z"] = 6, ["name"] = "mcl_core:darkwood"}, {["x"] = 4, ["y"] = 4, ["z"] = 0, ["name"] = "mcl_core:wood"}, {["x"] = 4, ["y"] = 4, ["z"] = 1, ["name"] = "mcl_core:wood"}, {["x"] = 4, ["y"] = 4, ["z"] = 2, ["name"] = "mcl_core:wood"}, {["x"] = 4, ["y"] = 4, ["z"] = 3, ["name"] = "mcl_core:wood"}, {["x"] = 4, ["y"] = 4, ["z"] = 4, ["name"] = "mcl_core:wood"}, {["x"] = 4, ["y"] = 4, ["z"] = 5, ["name"] = "mcl_core:wood"}, {["x"] = 4, ["y"] = 4, ["z"] = 6, ["name"] = "mcl_core:wood"}, {["x"] = 5, ["y"] = 0, ["z"] = 0, ["name"] = "mcl_core:darkwood"}, {["x"] = 5, ["y"] = 0, ["z"] = 1, ["name"] = "mcl_core:darkwood"}, {["x"] = 5, ["y"] = 0, ["z"] = 2, ["name"] = "mcl_core:darkwood"}, {["x"] = 5, ["y"] = 0, ["z"] = 3, ["name"] = "mcl_core:darkwood"}, {["x"] = 5, ["y"] = 0, ["z"] = 4, ["name"] = "mcl_core:darkwood"}, {["x"] = 5, ["y"] = 0, ["z"] = 5, ["name"] = "mcl_core:darkwood"}, {["x"] = 5, ["y"] = 0, ["z"] = 6, ["name"] = "mcl_core:darkwood"}, {["x"] = 5, ["y"] = 1, ["z"] = 0, ["name"] = "mcl_core:junglewood"}, {["x"] = 5, ["y"] = 1, ["z"] = 1, ["name"] = "mcl_core:junglewood"}, {["x"] = 5, ["y"] = 2, ["z"] = 0, ["name"] = "mcl_core:junglewood"}, {["x"] = 5, ["y"] = 2, ["z"] = 1, ["name"] = "mcl_core:wood"}, {["x"] = 5, ["y"] = 3, ["z"] = 0, ["name"] = "mcl_core:wood"}, {["x"] = 5, ["y"] = 3, ["z"] = 1, ["name"] = "mcl_core:wood"}, {["x"] = 5, ["y"] = 3, ["z"] = 6, ["name"] = "mcl_core:wood"}, {["x"] = 5, ["y"] = 4, ["z"] = 0, ["name"] = "mcl_core:wood"}, {["x"] = 5, ["y"] = 4, ["z"] = 1, ["name"] = "mcl_core:wood"}, {["x"] = 5, ["y"] = 4, ["z"] = 2, ["name"] = "mcl_core:wood"}, {["x"] = 5, ["y"] = 4, ["z"] = 3, ["name"] = "mcl_core:wood"}, {["x"] = 5, ["y"] = 4, ["z"] = 4, ["name"] = "mcl_core:wood"}, {["x"] = 5, ["y"] = 4, ["z"] = 5, ["name"] = "mcl_core:wood"}, {["x"] = 5, ["y"] = 4, ["z"] = 6, ["name"] = "mcl_core:wood"}, {["x"] = 6, ["y"] = 0, ["z"] = 2, ["name"] = "mcl_core:darkwood"}, {["x"] = 6, ["y"] = 0, ["z"] = 3, ["name"] = "mcl_core:darkwood"}, {["x"] = 6, ["y"] = 0, ["z"] = 4, ["name"] = "mcl_core:darkwood"}, {["x"] = 6, ["y"] = 0, ["z"] = 5, ["name"] = "mcl_core:darkwood"}, {["x"] = 6, ["y"] = 0, ["z"] = 6, ["name"] = "mcl_core:darkwood"}, {["x"] = 6, ["y"] = 1, ["z"] = 2, ["name"] = "mcl_core:darkwood"}, {["x"] = 6, ["meta"] = {["fields"] = {}, ["inventory"] = {["main"] = {"mcl_core:dirt 3", "mcl_dye:orange 3", "mcl_farming:wheat_item 3", "mcl_dye:pink 13", "mcl_core:sapling 21", "mcl_farming:bread 2", "mcl_core:birchtree 8", "mcl_dye:magenta 7", "mcl_mobitems:chicken", "mcl_tools:pick_wood 1 36036", "mcl_mobitems:gunpowder 5", "mcl_mushrooms:mushroom_brown 5", "mcl_mobitems:rotten_flesh 8", "mcl_tools:axe_wood 1 40404", "mcl_mobitems:bone 8", "mcl_bows:bow", "mcl_torches:torch 19", "mcl_tools:pick_wood 1 1092", "mcl_crafting_table:crafting_table 2", "mcl_dye:red 6", "mcl_wool:white", "mcl_mobitems:leather 3", "mcl_mobitems:mutton 9", "mcl_mobitems:cooked_porkchop 5", "", "mcl_mobitems:string 20", ""}, ["input"] = {""}}}, ["y"] = 1, ["param1"] = 188, ["z"] = 5, ["name"] = "mcl_chests:chest_left"}, {["x"] = 6, ["y"] = 1, ["z"] = 6, ["name"] = "mcl_core:darkwood"}, {["x"] = 6, ["y"] = 2, ["z"] = 2, ["name"] = "mcl_core:darkwood"}, {["x"] = 6, ["y"] = 2, ["z"] = 6, ["name"] = "mcl_core:wood"}, {["x"] = 6, ["y"] = 3, ["z"] = 2, ["name"] = "mcl_core:darkwood"}, {["x"] = 6, ["y"] = 3, ["z"] = 6, ["name"] = "mcl_core:wood"}, {["x"] = 6, ["y"] = 4, ["z"] = 2, ["name"] = "mcl_core:darkwood"}, {["x"] = 6, ["y"] = 4, ["z"] = 3, ["name"] = "mcl_core:darkwood"}, {["x"] = 6, ["y"] = 4, ["z"] = 4, ["name"] = "mcl_core:darkwood"}, {["x"] = 6, ["y"] = 4, ["z"] = 5, ["name"] = "mcl_core:darkwood"}, {["x"] = 6, ["y"] = 4, ["z"] = 6, ["name"] = "mcl_core:darkwood"}, {["x"] = 7, ["y"] = 0, ["z"] = 2, ["name"] = "mcl_core:darkwood"}, {["x"] = 7, ["y"] = 0, ["z"] = 3, ["name"] = "mcl_core:darkwood"}, {["x"] = 7, ["y"] = 0, ["z"] = 4, ["name"] = "mcl_core:darkwood"}, {["x"] = 7, ["y"] = 0, ["z"] = 5, ["name"] = "mcl_core:darkwood"}, {["x"] = 7, ["y"] = 0, ["z"] = 6, ["name"] = "mcl_core:darkwood"}, {["x"] = 7, ["y"] = 1, ["z"] = 2, ["name"] = "mcl_core:darkwood"}, {["x"] = 7, ["meta"] = {["fields"] = {}, ["inventory"] = {["main"] = {"mcl_core:diamond 7", "mcl_core:gold_ingot 10", "mcl_tools:sword_gold", "mcl_tools:sword_diamond 1 675", "mcl_mobitems:carrot_on_a_stick", "mcl_farming:beetroot_item 3", "mcl_dye:black", "mcl_core:emerald 4", "mcl_books:book 5", "mcl_mobs:nametag 3", "mcl_tools:sword_gold 1 525", "mcl_core:stick 4", "", "", "", "", "", "", "", "", "", "", "", "", "", "", ""}, ["input"] = {""}}}, ["y"] = 1, ["param1"] = 204, ["z"] = 5, ["name"] = "mcl_chests:chest_right"}, {["x"] = 7, ["y"] = 1, ["z"] = 6, ["name"] = "mcl_core:darkwood"}, {["x"] = 7, ["y"] = 2, ["z"] = 2, ["name"] = "mcl_core:darkwood"}, {["x"] = 7, ["y"] = 2, ["z"] = 6, ["name"] = "mcl_core:wood"}, {["x"] = 7, ["y"] = 3, ["z"] = 2, ["name"] = "mcl_core:darkwood"}, {["x"] = 7, ["y"] = 3, ["z"] = 6, ["name"] = "mcl_core:wood"}, {["x"] = 7, ["y"] = 4, ["z"] = 2, ["name"] = "mcl_core:darkwood"}, {["x"] = 7, ["y"] = 4, ["z"] = 3, ["name"] = "mcl_core:darkwood"}, {["x"] = 7, ["y"] = 4, ["z"] = 4, ["name"] = "mcl_core:darkwood"}, {["x"] = 7, ["y"] = 4, ["z"] = 5, ["name"] = "mcl_core:darkwood"}, {["x"] = 7, ["y"] = 4, ["z"] = 6, ["name"] = "mcl_core:darkwood"}, {["x"] = 8, ["y"] = 0, ["z"] = 2, ["name"] = "mcl_core:darkwood"}, {["x"] = 8, ["y"] = 0, ["z"] = 3, ["name"] = "mcl_core:darkwood"}, {["x"] = 8, ["y"] = 0, ["z"] = 4, ["name"] = "mcl_core:darkwood"}, {["x"] = 8, ["y"] = 0, ["z"] = 5, ["name"] = "mcl_core:darkwood"}, {["x"] = 8, ["y"] = 0, ["z"] = 6, ["name"] = "mcl_core:darkwood"}, {["x"] = 8, ["y"] = 1, ["z"] = 2, ["name"] = "mcl_core:darkwood"}, {["x"] = 8, ["meta"] = {["fields"] = {}, ["inventory"] = {["main"] = {"mcl_mobitems:feather 3", "", "", "", "mcl_tools:shovel_iron 1 35760", "mcl_mobitems:beef 9", "mcl_nether:netherrack 6", "mcl_tools:sword_iron 1 2775", "", "", "mcl_core:obsidian 24", "mcl_tools:pick_iron 1 44109", "", "", "", "", "", "", "", "", "", "", "", "", "", "", ""}, ["input"] = {""}}}, ["param2"] = 1, ["y"] = 1, ["param1"] = 187, ["z"] = 3, ["name"] = "mcl_chests:chest_right"}, {["x"] = 8, ["meta"] = {["fields"] = {}, ["inventory"] = {["main"] = {"mcl_core:cobble 42", "mcl_core:dirt 31", "mcl_farming:hoe_wood 1 55692", "", "mcl_doors:dark_oak_door 2", "", "", "mcl_wool:white 2", "mesecons:wire_00000000_off 64", "", "", "mcl_nether:glowstone_dust 3", "mcl_core:sand 62", "mcl_core:apple", "mcl_core:junglewood 3", "mcl_core:coal_lump 13", "mcl_core:ladder 2", "mcl_dye:grey 10", "", "mcl_flowers:peony 2", "mcl_mobitems:porkchop 3", "mcl_mobitems:rotten_flesh", "mcl_core:granite 42", "mobs_mc:iron_horse_armor", "mcl_core:diorite", "mcl_mobitems:chicken 2", "mcl_wool:black"}, ["input"] = {""}}}, ["param2"] = 1, ["y"] = 1, ["param1"] = 204, ["z"] = 4, ["name"] = "mcl_chests:chest_left"}, {["x"] = 8, ["y"] = 1, ["z"] = 5, ["name"] = "mcl_crafting_table:crafting_table"}, {["x"] = 8, ["y"] = 1, ["z"] = 6, ["name"] = "mcl_core:darkwood"}, {["x"] = 8, ["y"] = 2, ["z"] = 2, ["name"] = "mcl_core:darkwood"}, {["x"] = 8, ["param2"] = 1, ["y"] = 2, ["param1"] = 238, ["z"] = 5, ["name"] = "mcl_torches:torch"}, {["x"] = 8, ["y"] = 2, ["z"] = 6, ["name"] = "mcl_core:wood"}, {["x"] = 8, ["y"] = 3, ["z"] = 2, ["name"] = "mcl_core:darkwood"}, {["x"] = 8, ["meta"] = {["fields"] = {["formspec"] = "size[9,8.75]background[-0.19,-0.25;9.41,9.49;crafting_inventory_furnace.png]bgcolor[#080808BB;true]label[0,4;\27(c@#313131)\27(T@mcl_furnaces)Inventory\27E\27(c@#ffffff)]list[current_player;main;0,4.5;9,3;9]list[current_player;main;0,7.74;9,1;]label[2.75,0;\27(c@#313131)\27(T@mcl_furnaces)Furnace\27E\27(c@#ffffff)]list[current_name;src;2.75,0.5;1,1;]list[current_name;fuel;2.75,2.5;1,1;]list[current_name;dst;5.75,1.5;1,1;]image[2.75,1.5;1,1;default_furnace_fire_bg.png]image[4.1,1.5;1.5,1;gui_furnace_arrow_bg.png^[transformR270]image_button[8,0;1,1;craftguide_book.png;craftguide;]tooltip[craftguide;\27(T@mcl_furnaces)Recipe book\27E]listring[current_name;dst]listring[current_player;main]listring[current_name;src]listring[current_player;main]listring[current_name;fuel]listring[current_player;main]"}, ["inventory"] = {["fuel"] = {""}, ["dst"] = {""}, ["src"] = {""}}}, ["param2"] = 1, ["y"] = 3, ["z"] = 3, ["name"] = "mcl_furnaces:furnace"}, {["x"] = 8, ["meta"] = {["fields"] = {["formspec"] = "size[9,8.75]background[-0.19,-0.25;9.41,9.49;crafting_inventory_furnace.png]bgcolor[#080808BB;true]label[0,4;\27(c@#313131)\27(T@mcl_furnaces)Inventory\27E\27(c@#ffffff)]list[current_player;main;0,4.5;9,3;9]list[current_player;main;0,7.74;9,1;]label[2.75,0;\27(c@#313131)\27(T@mcl_furnaces)Furnace\27E\27(c@#ffffff)]list[current_name;src;2.75,0.5;1,1;]list[current_name;fuel;2.75,2.5;1,1;]list[current_name;dst;5.75,1.5;1,1;]image[2.75,1.5;1,1;default_furnace_fire_bg.png]image[4.1,1.5;1.5,1;gui_furnace_arrow_bg.png^[transformR270]image_button[8,0;1,1;craftguide_book.png;craftguide;]tooltip[craftguide;\27(T@mcl_furnaces)Recipe book\27E]listring[current_name;dst]listring[current_player;main]listring[current_name;src]listring[current_player;main]listring[current_name;fuel]listring[current_player;main]"}, ["inventory"] = {["fuel"] = {""}, ["dst"] = {""}, ["src"] = {""}}}, ["param2"] = 1, ["y"] = 3, ["z"] = 4, ["name"] = "mcl_furnaces:furnace"}, {["x"] = 8, ["meta"] = {["fields"] = {["formspec"] = "size[9,8.75]background[-0.19,-0.25;9.41,9.49;crafting_inventory_furnace.png]bgcolor[#080808BB;true]label[0,4;\27(c@#313131)\27(T@mcl_furnaces)Inventory\27E\27(c@#ffffff)]list[current_player;main;0,4.5;9,3;9]list[current_player;main;0,7.74;9,1;]label[2.75,0;\27(c@#313131)\27(T@mcl_furnaces)Furnace\27E\27(c@#ffffff)]list[current_name;src;2.75,0.5;1,1;]list[current_name;fuel;2.75,2.5;1,1;]list[current_name;dst;5.75,1.5;1,1;]image[2.75,1.5;1,1;default_furnace_fire_bg.png]image[4.1,1.5;1.5,1;gui_furnace_arrow_bg.png^[transformR270]image_button[8,0;1,1;craftguide_book.png;craftguide;]tooltip[craftguide;\27(T@mcl_furnaces)Recipe book\27E]listring[current_name;dst]listring[current_player;main]listring[current_name;src]listring[current_player;main]listring[current_name;fuel]listring[current_player;main]"}, ["inventory"] = {["fuel"] = {""}, ["dst"] = {""}, ["src"] = {""}}}, ["param2"] = 1, ["y"] = 3, ["z"] = 5, ["name"] = "mcl_furnaces:furnace"}, {["x"] = 8, ["y"] = 3, ["z"] = 6, ["name"] = "mcl_core:wood"}, {["x"] = 8, ["y"] = 4, ["z"] = 2, ["name"] = "mcl_core:darkwood"}, {["x"] = 8, ["y"] = 4, ["z"] = 3, ["name"] = "mcl_core:darkwood"}, {["x"] = 8, ["y"] = 4, ["z"] = 4, ["name"] = "mcl_core:darkwood"}, {["x"] = 8, ["y"] = 4, ["z"] = 5, ["name"] = "mcl_core:darkwood"}, {["x"] = 8, ["y"] = 4, ["z"] = 6, ["name"] = "mcl_core:darkwood"}, {["x"] = 9, ["y"] = 0, ["z"] = 2, ["name"] = "mcl_core:darkwood"}, {["x"] = 9, ["y"] = 0, ["z"] = 3, ["name"] = "mcl_core:darkwood"}, {["x"] = 9, ["y"] = 0, ["z"] = 4, ["name"] = "mcl_core:darkwood"}, {["x"] = 9, ["y"] = 0, ["z"] = 5, ["name"] = "mcl_core:darkwood"}, {["x"] = 9, ["y"] = 0, ["z"] = 6, ["name"] = "mcl_core:darkwood"}, {["x"] = 9, ["y"] = 1, ["z"] = 2, ["name"] = "mcl_core:darkwood"}, {["x"] = 9, ["y"] = 1, ["z"] = 3, ["name"] = "mcl_core:darkwood"}, {["x"] = 9, ["y"] = 1, ["z"] = 4, ["name"] = "mcl_core:darkwood"}, {["x"] = 9, ["y"] = 1, ["z"] = 5, ["name"] = "mcl_core:darkwood"}, {["x"] = 9, ["y"] = 1, ["z"] = 6, ["name"] = "mcl_core:darkwood"}, {["x"] = 9, ["y"] = 2, ["z"] = 2, ["name"] = "mcl_core:darkwood"}, {["x"] = 9, ["y"] = 2, ["z"] = 3, ["name"] = "mcl_core:wood"}, {["x"] = 9, ["y"] = 2, ["z"] = 4, ["name"] = "mcl_core:wood"}, {["x"] = 9, ["y"] = 2, ["z"] = 5, ["name"] = "mcl_core:wood"}, {["x"] = 9, ["y"] = 2, ["z"] = 6, ["name"] = "mcl_core:darkwood"}, {["x"] = 9, ["y"] = 3, ["z"] = 2, ["name"] = "mcl_core:darkwood"}, {["x"] = 9, ["y"] = 3, ["z"] = 3, ["name"] = "mcl_core:wood"}, {["x"] = 9, ["y"] = 3, ["z"] = 4, ["name"] = "mcl_core:wood"}, {["x"] = 9, ["y"] = 3, ["z"] = 5, ["name"] = "mcl_core:wood"}, {["x"] = 9, ["y"] = 3, ["z"] = 6, ["name"] = "mcl_core:wood"}, {["x"] = 9, ["y"] = 4, ["z"] = 2, ["name"] = "mcl_core:darkwood"}, {["x"] = 9, ["y"] = 4, ["z"] = 3, ["name"] = "mcl_core:darkwood"}, {["x"] = 9, ["y"] = 4, ["z"] = 4, ["name"] = "mcl_core:darkwood"}, {["x"] = 9, ["y"] = 4, ["z"] = 5, ["name"] = "mcl_core:darkwood"}, {["x"] = 9, ["y"] = 4, ["z"] = 6, ["name"] = "mcl_core:darkwood"}}