5:return {{["x"] = 0, ["meta"] = {["fields"] = {}, ["inventory"] = {}}, ["y"] = 0, ["param1"] = 15, ["z"] = 0, ["name"] = "rainbow:binary_white"}, {["x"] = 0, ["meta"] = {["fields"] = {}, ["inventory"] = {}}, ["y"] = 0, ["param1"] = 15, ["z"] = 1, ["name"] = "rainbow:binary_white"}, {["x"] = 0, ["meta"] = {["fields"] = {}, ["inventory"] = {}}, ["y"] = 0, ["param1"] = 15, ["z"] = 2, ["name"] = "rainbow:binary_white"}, {["x"] = 0, ["meta"] = {["fields"] = {}, ["inventory"] = {}}, ["y"] = 0, ["param1"] = 15, ["z"] = 3, ["name"] = "rainbow:binary_white"}, {["x"] = 0, ["meta"] = {["fields"] = {}, ["inventory"] = {}}, ["y"] = 0, ["param1"] = 15, ["z"] = 4, ["name"] = "rainbow:binary_white"}, {["x"] = 0, ["meta"] = {["fields"] = {}, ["inventory"] = {}}, ["y"] = 0, ["param1"] = 15, ["z"] = 5, ["name"] = "rainbow:binary_white"}, {["x"] = 0, ["meta"] = {["fields"] = {}, ["inventory"] = {}}, ["y"] = 0, ["param1"] = 15, ["z"] = 6, ["name"] = "rainbow:binary_white"}, {["x"] = 0, ["meta"] = {["fields"] = {}, ["inventory"] = {}}, ["y"] = 0, ["param1"] = 15, ["z"] = 7, ["name"] = "rainbow:binary_white"}, {["x"] = 0, ["meta"] = {["fields"] = {}, ["inventory"] = {}}, ["y"] = 0, ["param1"] = 15, ["z"] = 8, ["name"] = "rainbow:binary_white"}, {["x"] = 0, ["meta"] = {["fields"] = {}, ["inventory"] = {}}, ["y"] = 0, ["param1"] = 15, ["z"] = 9, ["name"] = "rainbow:binary_white"}, {["x"] = 0, ["meta"] = {["fields"] = {}, ["inventory"] = {}}, ["y"] = 0, ["param1"] = 15, ["z"] = 10, ["name"] = "rainbow:binary_white"}, {["x"] = 0, ["meta"] = {["fields"] = {}, ["inventory"] = {}}, ["y"] = 0, ["param1"] = 14, ["z"] = 11, ["name"] = "rainbow:binary_white"}, {["x"] = 0, ["meta"] = {["fields"] = {}, ["inventory"] = {}}, ["y"] = 0, ["param1"] = 14, ["z"] = 12, ["name"] = "rainbow:binary_white"}, {["x"] = 0, ["meta"] = {["fields"] = {}, ["inventory"] = {}}, ["param2"] = 1, ["y"] = 1, ["param1"] = 222, ["z"] = 4, ["name"] = "rainbow:slope_render_violet_outer"}, {["x"] = 0, ["meta"] = {["fields"] = {}, ["inventory"] = {}}, ["param2"] = 2, ["y"] = 1, ["param1"] = 222, ["z"] = 5, ["name"] = "rainbow:slope_render_violet_outer"}, {["x"] = 0, ["meta"] = {["fields"] = {}, ["inventory"] = {}}, ["param2"] = 1, ["y"] = 1, ["param1"] = 222, ["z"] = 7, ["name"] = "rainbow:slope_render_violet_outer"}, {["x"] = 0, ["meta"] = {["fields"] = {}, ["inventory"] = {}}, ["param2"] = 2, ["y"] = 1, ["param1"] = 222, ["z"] = 8, ["name"] = "rainbow:slope_render_violet_outer"}, {["x"] = 1, ["meta"] = {["fields"] = {}, ["inventory"] = {}}, ["y"] = 0, ["param1"] = 15, ["z"] = 0, ["name"] = "rainbow:binary_white"}, {["x"] = 1, ["meta"] = {["fields"] = {}, ["inventory"] = {}}, ["y"] = 0, ["param1"] = 15, ["z"] = 1, ["name"] = "rainbow:binary_white"}, {["x"] = 1, ["meta"] = {["fields"] = {}, ["inventory"] = {}}, ["y"] = 0, ["param1"] = 15, ["z"] = 2, ["name"] = "rainbow:binary_white"}, {["x"] = 1, ["meta"] = {["fields"] = {}, ["inventory"] = {}}, ["y"] = 0, ["param1"] = 15, ["z"] = 3, ["name"] = "rainbow:binary_white"}, {["x"] = 1, ["meta"] = {["fields"] = {}, ["inventory"] = {}}, ["y"] = 0, ["param1"] = 15, ["z"] = 4, ["name"] = "rainbow:binary_white"}, {["x"] = 1, ["meta"] = {["fields"] = {}, ["inventory"] = {}}, ["y"] = 0, ["param1"] = 15, ["z"] = 5, ["name"] = "rainbow:binary_white"}, {["x"] = 1, ["meta"] = {["fields"] = {}, ["inventory"] = {}}, ["y"] = 0, ["param1"] = 15, ["z"] = 6, ["name"] = "rainbow:binary_white"}, {["x"] = 1, ["meta"] = {["fields"] = {}, ["inventory"] = {}}, ["y"] = 0, ["param1"] = 15, ["z"] = 7, ["name"] = "rainbow:binary_white"}, {["x"] = 1, ["meta"] = {["fields"] = {}, ["inventory"] = {}}, ["y"] = 0, ["param1"] = 15, ["z"] = 8, ["name"] = "rainbow:binary_white"}, {["x"] = 1, ["meta"] = {["fields"] = {}, ["inventory"] = {}}, ["y"] = 0, ["param1"] = 15, ["z"] = 9, ["name"] = "rainbow:binary_white"}, {["x"] = 1, ["meta"] = {["fields"] = {}, ["inventory"] = {}}, ["y"] = 0, ["param1"] = 15, ["z"] = 10, ["name"] = "rainbow:binary_white"}, {["x"] = 1, ["meta"] = {["fields"] = {}, ["inventory"] = {}}, ["y"] = 0, ["param1"] = 14, ["z"] = 11, ["name"] = "rainbow:binary_white"}, {["x"] = 1, ["meta"] = {["fields"] = {}, ["inventory"] = {}}, ["y"] = 0, ["param1"] = 14, ["z"] = 12, ["name"] = "rainbow:binary_white"}, {["x"] = 1, ["meta"] = {["fields"] = {}, ["inventory"] = {}}, ["param2"] = 1, ["y"] = 1, ["param1"] = 222, ["z"] = 3, ["name"] = "rainbow:slope_render_violet_outer"}, {["x"] = 1, ["meta"] = {["fields"] = {}, ["inventory"] = {}}, ["y"] = 1, ["z"] = 4, ["name"] = "rainbow:render_violet"}, {["x"] = 1, ["meta"] = {["fields"] = {}, ["inventory"] = {}}, ["param2"] = 2, ["y"] = 1, ["param1"] = 221, ["z"] = 5, ["name"] = "rainbow:slope_render_violet"}, {["x"] = 1, ["meta"] = {["fields"] = {}, ["inventory"] = {}}, ["param2"] = 3, ["y"] = 1, ["param1"] = 222, ["z"] = 6, ["name"] = "rainbow:slab_coolglass_violet_1"}, {["x"] = 1, ["meta"] = {["fields"] = {}, ["inventory"] = {}}, ["y"] = 1, ["param1"] = 221, ["z"] = 7, ["name"] = "rainbow:slope_render_violet"}, {["x"] = 1, ["meta"] = {["fields"] = {}, ["inventory"] = {}}, ["y"] = 1, ["z"] = 8, ["name"] = "rainbow:render_violet"}, {["x"] = 1, ["meta"] = {["fields"] = {}, ["inventory"] = {}}, ["param2"] = 2, ["y"] = 1, ["param1"] = 222, ["z"] = 9, ["name"] = "rainbow:slope_render_violet_outer"}, {["x"] = 1, ["meta"] = {["fields"] = {}, ["inventory"] = {}}, ["y"] = 2, ["z"] = 4, ["name"] = "rainbow:render_violet"}, {["x"] = 1, ["meta"] = {["fields"] = {}, ["inventory"] = {}}, ["y"] = 2, ["z"] = 8, ["name"] = "rainbow:render_violet"}, {["x"] = 1, ["meta"] = {["fields"] = {}, ["inventory"] = {}}, ["y"] = 3, ["z"] = 4, ["name"] = "rainbow:render_violet"}, {["x"] = 1, ["meta"] = {["fields"] = {}, ["inventory"] = {}}, ["param2"] = 22, ["y"] = 3, ["param1"] = 190, ["z"] = 5, ["name"] = "rainbow:slope_render_violet"}, {["x"] = 1, ["meta"] = {["fields"] = {}, ["inventory"] = {}}, ["param2"] = 21, ["y"] = 3, ["param1"] = 190, ["z"] = 6, ["name"] = "rainbow:slab_coolglass_violet_1"}, {["x"] = 1, ["meta"] = {["fields"] = {}, ["inventory"] = {}}, ["param2"] = 20, ["y"] = 3, ["param1"] = 190, ["z"] = 7, ["name"] = "rainbow:slope_render_violet"}, {["x"] = 1, ["meta"] = {["fields"] = {}, ["inventory"] = {}}, ["y"] = 3, ["z"] = 8, ["name"] = "rainbow:render_violet"}, {["x"] = 1, ["meta"] = {["fields"] = {}, ["inventory"] = {}}, ["y"] = 4, ["param1"] = 63, ["z"] = 4, ["name"] = "rainbow:render_white"}, {["x"] = 1, ["meta"] = {["fields"] = {}, ["inventory"] = {}}, ["y"] = 4, ["param1"] = 79, ["z"] = 5, ["name"] = "rainbow:render_white"}, {["x"] = 1, ["meta"] = {["fields"] = {}, ["inventory"] = {}}, ["y"] = 4, ["z"] = 6, ["name"] = "rainbow:render_white"}, {["x"] = 1, ["meta"] = {["fields"] = {}, ["inventory"] = {}}, ["y"] = 4, ["param1"] = 79, ["z"] = 7, ["name"] = "rainbow:render_white"}, {["x"] = 1, ["meta"] = {["fields"] = {}, ["inventory"] = {}}, ["y"] = 4, ["param1"] = 63, ["z"] = 8, ["name"] = "rainbow:render_white"}, {["x"] = 1, ["meta"] = {["fields"] = {}, ["inventory"] = {}}, ["y"] = 5, ["param1"] = 47, ["z"] = 4, ["name"] = "rainbow:render_white"}, {["x"] = 1, ["meta"] = {["fields"] = {}, ["inventory"] = {}}, ["y"] = 5, ["param1"] = 63, ["z"] = 5, ["name"] = "rainbow:render_white"}, {["x"] = 1, ["meta"] = {["fields"] = {}, ["inventory"] = {}}, ["y"] = 5, ["param1"] = 79, ["z"] = 6, ["name"] = "rainbow:render_white"}, {["x"] = 1, ["meta"] = {["fields"] = {}, ["inventory"] = {}}, ["y"] = 5, ["param1"] = 63, ["z"] = 7, ["name"] = "rainbow:render_white"}, {["x"] = 1, ["meta"] = {["fields"] = {}, ["inventory"] = {}}, ["y"] = 5, ["param1"] = 47, ["z"] = 8, ["name"] = "rainbow:render_white"}, {["x"] = 1, ["meta"] = {["fields"] = {}, ["inventory"] = {}}, ["y"] = 6, ["z"] = 4, ["name"] = "rainbow:render_lightgreen"}, {["x"] = 1, ["meta"] = {["fields"] = {}, ["inventory"] = {}}, ["param2"] = 2, ["y"] = 6, ["param1"] = 126, ["z"] = 5, ["name"] = "rainbow:slope_render_lightgreen"}, {["x"] = 1, ["meta"] = {["fields"] = {}, ["inventory"] = {}}, ["param2"] = 1, ["y"] = 6, ["param1"] = 126, ["z"] = 6, ["name"] = "rainbow:slab_coolglass_lightgreen_1"}, {["x"] = 1, ["meta"] = {["fields"] = {}, ["inventory"] = {}}, ["y"] = 6, ["param1"] = 126, ["z"] = 7, ["name"] = "rainbow:slope_render_lightgreen"}, {["x"] = 1, ["meta"] = {["fields"] = {}, ["inventory"] = {}}, ["y"] = 6, ["z"] = 8, ["name"] = "rainbow:render_lightgreen"}, {["x"] = 1, ["meta"] = {["fields"] = {}, ["inventory"] = {}}, ["y"] = 7, ["z"] = 4, ["name"] = "rainbow:render_lightgreen"}, {["x"] = 1, ["meta"] = {["fields"] = {}, ["inventory"] = {}}, ["y"] = 7, ["z"] = 8, ["name"] = "rainbow:render_lightgreen"}, {["x"] = 1, ["meta"] = {["fields"] = {}, ["inventory"] = {}}, ["y"] = 8, ["z"] = 4, ["name"] = "rainbow:render_lightgreen"}, {["x"] = 1, ["meta"] = {["fields"] = {}, ["inventory"] = {}}, ["param2"] = 22, ["y"] = 8, ["param1"] = 94, ["z"] = 5, ["name"] = "rainbow:slope_render_lightgreen"}, {["x"] = 1, ["meta"] = {["fields"] = {}, ["inventory"] = {}}, ["param2"] = 23, ["y"] = 8, ["param1"] = 94, ["z"] = 6, ["name"] = "rainbow:slab_coolglass_lightgreen_1"}, {["x"] = 1, ["meta"] = {["fields"] = {}, ["inventory"] = {}}, ["param2"] = 20, ["y"] = 8, ["param1"] = 94, ["z"] = 7, ["name"] = "rainbow:slope_render_lightgreen"}, {["x"] = 1, ["meta"] = {["fields"] = {}, ["inventory"] = {}}, ["y"] = 8, ["z"] = 8, ["name"] = "rainbow:render_lightgreen"}, {["x"] = 1, ["meta"] = {["fields"] = {}, ["inventory"] = {}}, ["y"] = 9, ["param1"] = 63, ["z"] = 4, ["name"] = "rainbow:render_white"}, {["x"] = 1, ["meta"] = {["fields"] = {}, ["inventory"] = {}}, ["y"] = 9, ["param1"] = 79, ["z"] = 5, ["name"] = "rainbow:render_white"}, {["x"] = 1, ["meta"] = {["fields"] = {}, ["inventory"] = {}}, ["y"] = 9, ["z"] = 6, ["name"] = "rainbow:render_white"}, {["x"] = 1, ["meta"] = {["fields"] = {}, ["inventory"] = {}}, ["y"] = 9, ["param1"] = 79, ["z"] = 7, ["name"] = "rainbow:render_white"}, {["x"] = 1, ["meta"] = {["fields"] = {}, ["inventory"] = {}}, ["y"] = 9, ["param1"] = 63, ["z"] = 8, ["name"] = "rainbow:render_white"}, {["x"] = 1, ["meta"] = {["fields"] = {}, ["inventory"] = {}}, ["y"] = 10, ["param1"] = 47, ["z"] = 4, ["name"] = "rainbow:render_white"}, {["x"] = 1, ["meta"] = {["fields"] = {}, ["inventory"] = {}}, ["y"] = 10, ["param1"] = 63, ["z"] = 5, ["name"] = "rainbow:render_white"}, {["x"] = 1, ["meta"] = {["fields"] = {}, ["inventory"] = {}}, ["y"] = 10, ["param1"] = 79, ["z"] = 6, ["name"] = "rainbow:render_white"}, {["x"] = 1, ["meta"] = {["fields"] = {}, ["inventory"] = {}}, ["y"] = 10, ["param1"] = 63, ["z"] = 7, ["name"] = "rainbow:render_white"}, {["x"] = 1, ["meta"] = {["fields"] = {}, ["inventory"] = {}}, ["y"] = 10, ["param1"] = 47, ["z"] = 8, ["name"] = "rainbow:render_white"}, {["x"] = 1, ["meta"] = {["fields"] = {}, ["inventory"] = {}}, ["y"] = 11, ["z"] = 4, ["name"] = "rainbow:render_blue"}, {["x"] = 1, ["meta"] = {["fields"] = {}, ["inventory"] = {}}, ["param2"] = 2, ["y"] = 11, ["param1"] = 94, ["z"] = 5, ["name"] = "rainbow:slope_render_blue"}, {["x"] = 1, ["meta"] = {["fields"] = {}, ["inventory"] = {}}, ["param2"] = 1, ["y"] = 11, ["param1"] = 78, ["z"] = 6, ["name"] = "rainbow:slab_coolglass_blue_1"}, {["x"] = 1, ["meta"] = {["fields"] = {}, ["inventory"] = {}}, ["y"] = 11, ["param1"] = 62, ["z"] = 7, ["name"] = "rainbow:slope_render_blue"}, {["x"] = 1, ["meta"] = {["fields"] = {}, ["inventory"] = {}}, ["y"] = 11, ["z"] = 8, ["name"] = "rainbow:render_blue"}, {["x"] = 1, ["meta"] = {["fields"] = {}, ["inventory"] = {}}, ["y"] = 12, ["z"] = 4, ["name"] = "rainbow:render_blue"}, {["x"] = 1, ["meta"] = {["fields"] = {}, ["inventory"] = {}}, ["y"] = 12, ["z"] = 8, ["name"] = "rainbow:render_blue"}, {["x"] = 1, ["meta"] = {["fields"] = {}, ["inventory"] = {}}, ["y"] = 13, ["z"] = 4, ["name"] = "rainbow:render_blue"}, {["x"] = 1, ["meta"] = {["fields"] = {}, ["inventory"] = {}}, ["param2"] = 22, ["y"] = 13, ["param1"] = 94, ["z"] = 5, ["name"] = "rainbow:slope_render_blue"}, {["x"] = 1, ["meta"] = {["fields"] = {}, ["inventory"] = {}}, ["param2"] = 23, ["y"] = 13, ["param1"] = 78, ["z"] = 6, ["name"] = "rainbow:slab_coolglass_blue_1"}, {["x"] = 1, ["meta"] = {["fields"] = {}, ["inventory"] = {}}, ["param2"] = 20, ["y"] = 13, ["param1"] = 62, ["z"] = 7, ["name"] = "rainbow:slope_render_blue"}, {["x"] = 1, ["meta"] = {["fields"] = {}, ["inventory"] = {}}, ["y"] = 13, ["z"] = 8, ["name"] = "rainbow:render_blue"}, {["x"] = 1, ["meta"] = {["fields"] = {}, ["inventory"] = {}}, ["y"] = 14, ["param1"] = 63, ["z"] = 4, ["name"] = "rainbow:render_white"}, {["x"] = 1, ["meta"] = {["fields"] = {}, ["inventory"] = {}}, ["y"] = 14, ["param1"] = 79, ["z"] = 5, ["name"] = "rainbow:render_white"}, {["x"] = 1, ["meta"] = {["fields"] = {}, ["inventory"] = {}}, ["y"] = 14, ["z"] = 6, ["name"] = "rainbow:render_white"}, {["x"] = 1, ["meta"] = {["fields"] = {}, ["inventory"] = {}}, ["y"] = 14, ["param1"] = 79, ["z"] = 7, ["name"] = "rainbow:render_white"}, {["x"] = 1, ["meta"] = {["fields"] = {}, ["inventory"] = {}}, ["y"] = 14, ["param1"] = 63, ["z"] = 8, ["name"] = "rainbow:render_white"}, {["x"] = 1, ["meta"] = {["fields"] = {}, ["inventory"] = {}}, ["y"] = 15, ["param1"] = 47, ["z"] = 4, ["name"] = "rainbow:render_white"}, {["x"] = 1, ["meta"] = {["fields"] = {}, ["inventory"] = {}}, ["y"] = 15, ["param1"] = 63, ["z"] = 5, ["name"] = "rainbow:render_white"}, {["x"] = 1, ["meta"] = {["fields"] = {}, ["inventory"] = {}}, ["y"] = 15, ["param1"] = 79, ["z"] = 6, ["name"] = "rainbow:render_white"}, {["x"] = 1, ["meta"] = {["fields"] = {}, ["inventory"] = {}}, ["y"] = 15, ["param1"] = 63, ["z"] = 7, ["name"] = "rainbow:render_white"}, {["x"] = 1, ["meta"] = {["fields"] = {}, ["inventory"] = {}}, ["y"] = 15, ["param1"] = 47, ["z"] = 8, ["name"] = "rainbow:render_white"}, {["x"] = 1, ["meta"] = {["fields"] = {}, ["inventory"] = {}}, ["y"] = 16, ["z"] = 4, ["name"] = "rainbow:render_black"}, {["x"] = 1, ["meta"] = {["fields"] = {}, ["inventory"] = {}}, ["param2"] = 2, ["y"] = 16, ["param1"] = 94, ["z"] = 5, ["name"] = "rainbow:slope_render_black"}, {["x"] = 1, ["meta"] = {["fields"] = {}, ["inventory"] = {}}, ["param2"] = 1, ["y"] = 16, ["param1"] = 78, ["z"] = 6, ["name"] = "rainbow:slab_coolglass_black_1"}, {["x"] = 1, ["meta"] = {["fields"] = {}, ["inventory"] = {}}, ["y"] = 16, ["param1"] = 62, ["z"] = 7, ["name"] = "rainbow:slope_render_black"}, {["x"] = 1, ["meta"] = {["fields"] = {}, ["inventory"] = {}}, ["y"] = 16, ["z"] = 8, ["name"] = "rainbow:render_black"}, {["x"] = 1, ["meta"] = {["fields"] = {}, ["inventory"] = {}}, ["y"] = 17, ["z"] = 4, ["name"] = "rainbow:render_black"}, {["x"] = 1, ["meta"] = {["fields"] = {}, ["inventory"] = {}}, ["y"] = 17, ["z"] = 8, ["name"] = "rainbow:render_black"}, {["x"] = 1, ["meta"] = {["fields"] = {}, ["inventory"] = {}}, ["y"] = 18, ["z"] = 4, ["name"] = "rainbow:render_black"}, {["x"] = 1, ["meta"] = {["fields"] = {}, ["inventory"] = {}}, ["param2"] = 22, ["y"] = 18, ["param1"] = 94, ["z"] = 5, ["name"] = "rainbow:slope_render_black"}, {["x"] = 1, ["meta"] = {["fields"] = {}, ["inventory"] = {}}, ["param2"] = 23, ["y"] = 18, ["param1"] = 78, ["z"] = 6, ["name"] = "rainbow:slab_coolglass_black_1"}, {["x"] = 1, ["meta"] = {["fields"] = {}, ["inventory"] = {}}, ["param2"] = 20, ["y"] = 18, ["param1"] = 62, ["z"] = 7, ["name"] = "rainbow:slope_render_black"}, {["x"] = 1, ["meta"] = {["fields"] = {}, ["inventory"] = {}}, ["y"] = 18, ["z"] = 8, ["name"] = "rainbow:render_black"}, {["x"] = 1, ["meta"] = {["fields"] = {}, ["inventory"] = {}}, ["y"] = 19, ["param1"] = 63, ["z"] = 4, ["name"] = "rainbow:render_white"}, {["x"] = 1, ["meta"] = {["fields"] = {}, ["inventory"] = {}}, ["y"] = 19, ["param1"] = 79, ["z"] = 5, ["name"] = "rainbow:render_white"}, {["x"] = 1, ["meta"] = {["fields"] = {}, ["inventory"] = {}}, ["y"] = 19, ["z"] = 6, ["name"] = "rainbow:render_white"}, {["x"] = 1, ["meta"] = {["fields"] = {}, ["inventory"] = {}}, ["y"] = 19, ["param1"] = 79, ["z"] = 7, ["name"] = "rainbow:render_white"}, {["x"] = 1, ["meta"] = {["fields"] = {}, ["inventory"] = {}}, ["y"] = 19, ["param1"] = 63, ["z"] = 8, ["name"] = "rainbow:render_white"}, {["x"] = 1, ["meta"] = {["fields"] = {}, ["inventory"] = {}}, ["y"] = 20, ["param1"] = 47, ["z"] = 4, ["name"] = "rainbow:render_white"}, {["x"] = 1, ["meta"] = {["fields"] = {}, ["inventory"] = {}}, ["y"] = 20, ["param1"] = 63, ["z"] = 5, ["name"] = "rainbow:render_white"}, {["x"] = 1, ["meta"] = {["fields"] = {}, ["inventory"] = {}}, ["y"] = 20, ["param1"] = 79, ["z"] = 6, ["name"] = "rainbow:render_white"}, {["x"] = 1, ["meta"] = {["fields"] = {}, ["inventory"] = {}}, ["y"] = 20, ["param1"] = 63, ["z"] = 7, ["name"] = "rainbow:render_white"}, {["x"] = 1, ["meta"] = {["fields"] = {}, ["inventory"] = {}}, ["y"] = 20, ["param1"] = 47, ["z"] = 8, ["name"] = "rainbow:render_white"}, {["x"] = 1, ["meta"] = {["fields"] = {}, ["inventory"] = {}}, ["param2"] = 1, ["y"] = 21, ["param1"] = 78, ["z"] = 4, ["name"] = "rainbow:slope_render_white_outer"}, {["x"] = 1, ["meta"] = {["fields"] = {}, ["inventory"] = {}}, ["param2"] = 1, ["y"] = 21, ["param1"] = 94, ["z"] = 5, ["name"] = "rainbow:slope_render_white"}, {["x"] = 1, ["meta"] = {["fields"] = {}, ["inventory"] = {}}, ["param2"] = 1, ["y"] = 21, ["param1"] = 78, ["z"] = 6, ["name"] = "rainbow:slope_render_white"}, {["x"] = 1, ["meta"] = {["fields"] = {}, ["inventory"] = {}}, ["param2"] = 1, ["y"] = 21, ["param1"] = 62, ["z"] = 7, ["name"] = "rainbow:slope_render_white"}, {["x"] = 1, ["meta"] = {["fields"] = {}, ["inventory"] = {}}, ["param2"] = 2, ["y"] = 21, ["param1"] = 46, ["z"] = 8, ["name"] = "rainbow:slope_render_white_outer"}, {["x"] = 2, ["meta"] = {["fields"] = {}, ["inventory"] = {}}, ["y"] = 0, ["param1"] = 15, ["z"] = 0, ["name"] = "rainbow:binary_white"}, {["x"] = 2, ["meta"] = {["fields"] = {}, ["inventory"] = {}}, ["y"] = 0, ["param1"] = 15, ["z"] = 1, ["name"] = "rainbow:binary_white"}, {["x"] = 2, ["meta"] = {["fields"] = {}, ["inventory"] = {}}, ["y"] = 0, ["param1"] = 15, ["z"] = 2, ["name"] = "rainbow:binary_white"}, {["x"] = 2, ["meta"] = {["fields"] = {}, ["inventory"] = {}}, ["y"] = 0, ["param1"] = 15, ["z"] = 3, ["name"] = "rainbow:binary_white"}, {["x"] = 2, ["meta"] = {["fields"] = {}, ["inventory"] = {}}, ["y"] = 0, ["param1"] = 15, ["z"] = 4, ["name"] = "rainbow:binary_white"}, {["x"] = 2, ["meta"] = {["fields"] = {}, ["inventory"] = {}}, ["y"] = 0, ["param1"] = 15, ["z"] = 5, ["name"] = "rainbow:binary_white"}, {["x"] = 2, ["meta"] = {["fields"] = {}, ["inventory"] = {}}, ["y"] = 0, ["param1"] = 15, ["z"] = 6, ["name"] = "rainbow:binary_white"}, {["x"] = 2, ["meta"] = {["fields"] = {}, ["inventory"] = {}}, ["y"] = 0, ["param1"] = 15, ["z"] = 7, ["name"] = "rainbow:binary_white"}, {["x"] = 2, ["meta"] = {["fields"] = {}, ["inventory"] = {}}, ["y"] = 0, ["param1"] = 15, ["z"] = 8, ["name"] = "rainbow:binary_white"}, {["x"] = 2, ["meta"] = {["fields"] = {}, ["inventory"] = {}}, ["y"] = 0, ["param1"] = 15, ["z"] = 9, ["name"] = "rainbow:binary_white"}, {["x"] = 2, ["meta"] = {["fields"] = {}, ["inventory"] = {}}, ["y"] = 0, ["param1"] = 15, ["z"] = 10, ["name"] = "rainbow:binary_white"}, {["x"] = 2, ["meta"] = {["fields"] = {}, ["inventory"] = {}}, ["y"] = 0, ["param1"] = 14, ["z"] = 11, ["name"] = "rainbow:binary_white"}, {["x"] = 2, ["meta"] = {["fields"] = {}, ["inventory"] = {}}, ["y"] = 0, ["param1"] = 14, ["z"] = 12, ["name"] = "rainbow:binary_white"}, {["x"] = 2, ["meta"] = {["fields"] = {}, ["inventory"] = {}}, ["param2"] = 1, ["y"] = 1, ["param1"] = 222, ["z"] = 2, ["name"] = "rainbow:slope_render_violet_outer"}, {["x"] = 2, ["meta"] = {["fields"] = {}, ["inventory"] = {}}, ["y"] = 1, ["z"] = 3, ["name"] = "rainbow:render_violet"}, {["x"] = 2, ["meta"] = {["fields"] = {}, ["inventory"] = {}}, ["y"] = 1, ["z"] = 9, ["name"] = "rainbow:render_violet"}, {["x"] = 2, ["meta"] = {["fields"] = {}, ["inventory"] = {}}, ["param2"] = 2, ["y"] = 1, ["param1"] = 222, ["z"] = 10, ["name"] = "rainbow:slope_render_violet_outer"}, {["x"] = 2, ["meta"] = {["fields"] = {}, ["inventory"] = {}}, ["y"] = 2, ["z"] = 3, ["name"] = "rainbow:render_violet"}, {["x"] = 2, ["meta"] = {["fields"] = {}, ["inventory"] = {}}, ["y"] = 2, ["z"] = 9, ["name"] = "rainbow:render_violet"}, {["x"] = 2, ["meta"] = {["fields"] = {}, ["inventory"] = {}}, ["y"] = 3, ["z"] = 3, ["name"] = "rainbow:render_violet"}, {["x"] = 2, ["meta"] = {["fields"] = {}, ["inventory"] = {}}, ["y"] = 3, ["z"] = 9, ["name"] = "rainbow:render_violet"}, {["x"] = 2, ["meta"] = {["fields"] = {}, ["inventory"] = {}}, ["y"] = 4, ["param1"] = 63, ["z"] = 3, ["name"] = "rainbow:render_white"}, {["x"] = 2, ["meta"] = {["fields"] = {}, ["inventory"] = {}}, ["param2"] = 21, ["y"] = 4, ["param1"] = 171, ["z"] = 4, ["name"] = "rainbow:slab_render_white_1"}, {["x"] = 2, ["meta"] = {["fields"] = {}, ["inventory"] = {}}, ["param2"] = 21, ["y"] = 4, ["param1"] = 172, ["z"] = 5, ["name"] = "rainbow:slab_render_white_1"}, {["x"] = 2, ["meta"] = {["fields"] = {}, ["inventory"] = {}}, ["param2"] = 21, ["y"] = 4, ["param1"] = 172, ["z"] = 6, ["name"] = "rainbow:slab_render_white_1"}, {["x"] = 2, ["meta"] = {["fields"] = {}, ["inventory"] = {}}, ["param2"] = 21, ["y"] = 4, ["param1"] = 172, ["z"] = 7, ["name"] = "rainbow:slab_render_white_1"}, {["x"] = 2, ["meta"] = {["fields"] = {}, ["inventory"] = {}}, ["param2"] = 20, ["y"] = 4, ["param1"] = 171, ["z"] = 8, ["name"] = "rainbow:slab_render_white_1"}, {["x"] = 2, ["meta"] = {["fields"] = {}, ["inventory"] = {}}, ["y"] = 4, ["param1"] = 63, ["z"] = 9, ["name"] = "rainbow:render_white"}, {["x"] = 2, ["meta"] = {["fields"] = {}, ["inventory"] = {}}, ["y"] = 5, ["param1"] = 47, ["z"] = 3, ["name"] = "rainbow:render_white"}, {["x"] = 2, ["meta"] = {["fields"] = {}, ["inventory"] = {}}, ["y"] = 5, ["param1"] = 47, ["z"] = 9, ["name"] = "rainbow:render_white"}, {["x"] = 2, ["meta"] = {["fields"] = {}, ["inventory"] = {}}, ["y"] = 6, ["z"] = 3, ["name"] = "rainbow:render_lightgreen"}, {["x"] = 2, ["meta"] = {["fields"] = {}, ["inventory"] = {}}, ["param2"] = 12, ["y"] = 6, ["param1"] = 141, ["z"] = 5, ["name"] = "rainbow:slab_coolglass_lightgreen_1"}, {["x"] = 2, ["meta"] = {["fields"] = {}, ["inventory"] = {}}, ["param2"] = 12, ["y"] = 6, ["param1"] = 141, ["z"] = 6, ["name"] = "rainbow:slab_coolglass_lightgreen_1"}, {["x"] = 2, ["meta"] = {["fields"] = {}, ["inventory"] = {}}, ["param2"] = 12, ["y"] = 6, ["param1"] = 141, ["z"] = 7, ["name"] = "rainbow:slab_coolglass_lightgreen_1"}, {["x"] = 2, ["meta"] = {["fields"] = {}, ["inventory"] = {}}, ["y"] = 6, ["z"] = 9, ["name"] = "rainbow:render_lightgreen"}, {["x"] = 2, ["meta"] = {["fields"] = {}, ["inventory"] = {}}, ["y"] = 7, ["z"] = 3, ["name"] = "rainbow:render_lightgreen"}, {["x"] = 2, ["meta"] = {["fields"] = {}, ["inventory"] = {}}, ["param2"] = 12, ["y"] = 7, ["param1"] = 125, ["z"] = 5, ["name"] = "rainbow:slab_coolglass_lightgreen_1"}, {["x"] = 2, ["meta"] = {["fields"] = {}, ["inventory"] = {}}, ["param2"] = 12, ["y"] = 7, ["param1"] = 125, ["z"] = 6, ["name"] = "rainbow:slab_coolglass_lightgreen_1"}, {["x"] = 2, ["meta"] = {["fields"] = {}, ["inventory"] = {}}, ["param2"] = 12, ["y"] = 7, ["param1"] = 125, ["z"] = 7, ["name"] = "rainbow:slab_coolglass_lightgreen_1"}, {["x"] = 2, ["meta"] = {["fields"] = {}, ["inventory"] = {}}, ["y"] = 7, ["z"] = 9, ["name"] = "rainbow:render_lightgreen"}, {["x"] = 2, ["meta"] = {["fields"] = {}, ["inventory"] = {}}, ["y"] = 8, ["z"] = 3, ["name"] = "rainbow:render_lightgreen"}, {["x"] = 2, ["meta"] = {["fields"] = {}, ["inventory"] = {}}, ["param2"] = 12, ["y"] = 8, ["param1"] = 109, ["z"] = 5, ["name"] = "rainbow:slab_coolglass_lightgreen_1"}, {["x"] = 2, ["meta"] = {["fields"] = {}, ["inventory"] = {}}, ["param2"] = 12, ["y"] = 8, ["param1"] = 109, ["z"] = 6, ["name"] = "rainbow:slab_coolglass_lightgreen_1"}, {["x"] = 2, ["meta"] = {["fields"] = {}, ["inventory"] = {}}, ["param2"] = 12, ["y"] = 8, ["param1"] = 109, ["z"] = 7, ["name"] = "rainbow:slab_coolglass_lightgreen_1"}, {["x"] = 2, ["meta"] = {["fields"] = {}, ["inventory"] = {}}, ["y"] = 8, ["z"] = 9, ["name"] = "rainbow:render_lightgreen"}, {["x"] = 2, ["meta"] = {["fields"] = {}, ["inventory"] = {}}, ["y"] = 9, ["param1"] = 63, ["z"] = 3, ["name"] = "rainbow:render_white"}, {["x"] = 2, ["meta"] = {["fields"] = {}, ["inventory"] = {}}, ["param2"] = 21, ["y"] = 9, ["param1"] = 107, ["z"] = 4, ["name"] = "rainbow:slab_render_white_1"}, {["x"] = 2, ["meta"] = {["fields"] = {}, ["inventory"] = {}}, ["param2"] = 21, ["y"] = 9, ["param1"] = 92, ["z"] = 5, ["name"] = "rainbow:slab_render_white_1"}, {["x"] = 2, ["meta"] = {["fields"] = {}, ["inventory"] = {}}, ["param2"] = 21, ["y"] = 9, ["param1"] = 92, ["z"] = 6, ["name"] = "rainbow:slab_render_white_1"}, {["x"] = 2, ["meta"] = {["fields"] = {}, ["inventory"] = {}}, ["param2"] = 21, ["y"] = 9, ["param1"] = 92, ["z"] = 7, ["name"] = "rainbow:slab_render_white_1"}, {["x"] = 2, ["meta"] = {["fields"] = {}, ["inventory"] = {}}, ["param2"] = 21, ["y"] = 9, ["param1"] = 91, ["z"] = 8, ["name"] = "rainbow:slab_render_white_1"}, {["x"] = 2, ["meta"] = {["fields"] = {}, ["inventory"] = {}}, ["y"] = 9, ["param1"] = 63, ["z"] = 9, ["name"] = "rainbow:render_white"}, {["x"] = 2, ["meta"] = {["fields"] = {}, ["inventory"] = {}}, ["y"] = 10, ["param1"] = 47, ["z"] = 3, ["name"] = "rainbow:render_white"}, {["x"] = 2, ["meta"] = {["fields"] = {}, ["inventory"] = {}}, ["y"] = 10, ["param1"] = 47, ["z"] = 9, ["name"] = "rainbow:render_white"}, {["x"] = 2, ["meta"] = {["fields"] = {}, ["inventory"] = {}}, ["y"] = 11, ["z"] = 3, ["name"] = "rainbow:render_blue"}, {["x"] = 2, ["meta"] = {["fields"] = {}, ["inventory"] = {}}, ["param2"] = 12, ["y"] = 11, ["param1"] = 109, ["z"] = 5, ["name"] = "rainbow:slab_coolglass_blue_1"}, {["x"] = 2, ["meta"] = {["fields"] = {}, ["inventory"] = {}}, ["param2"] = 12, ["y"] = 11, ["param1"] = 93, ["z"] = 6, ["name"] = "rainbow:slab_coolglass_blue_1"}, {["x"] = 2, ["meta"] = {["fields"] = {}, ["inventory"] = {}}, ["param2"] = 12, ["y"] = 11, ["param1"] = 77, ["z"] = 7, ["name"] = "rainbow:slab_coolglass_blue_1"}, {["x"] = 2, ["meta"] = {["fields"] = {}, ["inventory"] = {}}, ["y"] = 11, ["z"] = 9, ["name"] = "rainbow:render_blue"}, {["x"] = 2, ["meta"] = {["fields"] = {}, ["inventory"] = {}}, ["y"] = 12, ["z"] = 3, ["name"] = "rainbow:render_blue"}, {["x"] = 2, ["meta"] = {["fields"] = {}, ["inventory"] = {}}, ["param2"] = 12, ["y"] = 12, ["param1"] = 125, ["z"] = 5, ["name"] = "rainbow:slab_coolglass_blue_1"}, {["x"] = 2, ["meta"] = {["fields"] = {}, ["inventory"] = {}}, ["param2"] = 12, ["y"] = 12, ["param1"] = 109, ["z"] = 6, ["name"] = "rainbow:slab_coolglass_blue_1"}, {["x"] = 2, ["meta"] = {["fields"] = {}, ["inventory"] = {}}, ["param2"] = 12, ["y"] = 12, ["param1"] = 93, ["z"] = 7, ["name"] = "rainbow:slab_coolglass_blue_1"}, {["x"] = 2, ["meta"] = {["fields"] = {}, ["inventory"] = {}}, ["y"] = 12, ["z"] = 9, ["name"] = "rainbow:render_blue"}, {["x"] = 2, ["meta"] = {["fields"] = {}, ["inventory"] = {}}, ["y"] = 13, ["z"] = 3, ["name"] = "rainbow:render_blue"}, {["x"] = 2, ["meta"] = {["fields"] = {}, ["inventory"] = {}}, ["param2"] = 12, ["y"] = 13, ["param1"] = 109, ["z"] = 5, ["name"] = "rainbow:slab_coolglass_blue_1"}, {["x"] = 2, ["meta"] = {["fields"] = {}, ["inventory"] = {}}, ["param2"] = 12, ["y"] = 13, ["param1"] = 93, ["z"] = 6, ["name"] = "rainbow:slab_coolglass_blue_1"}, {["x"] = 2, ["meta"] = {["fields"] = {}, ["inventory"] = {}}, ["param2"] = 12, ["y"] = 13, ["param1"] = 77, ["z"] = 7, ["name"] = "rainbow:slab_coolglass_blue_1"}, {["x"] = 2, ["meta"] = {["fields"] = {}, ["inventory"] = {}}, ["y"] = 13, ["z"] = 9, ["name"] = "rainbow:render_blue"}, {["x"] = 2, ["meta"] = {["fields"] = {}, ["inventory"] = {}}, ["y"] = 14, ["param1"] = 63, ["z"] = 3, ["name"] = "rainbow:render_white"}, {["x"] = 2, ["meta"] = {["fields"] = {}, ["inventory"] = {}}, ["param2"] = 21, ["y"] = 14, ["param1"] = 107, ["z"] = 4, ["name"] = "rainbow:slab_render_white_1"}, {["x"] = 2, ["meta"] = {["fields"] = {}, ["inventory"] = {}}, ["param2"] = 21, ["y"] = 14, ["param1"] = 92, ["z"] = 5, ["name"] = "rainbow:slab_render_white_1"}, {["x"] = 2, ["meta"] = {["fields"] = {}, ["inventory"] = {}}, ["param2"] = 21, ["y"] = 14, ["param1"] = 76, ["z"] = 6, ["name"] = "rainbow:slab_render_white_1"}, {["x"] = 2, ["meta"] = {["fields"] = {}, ["inventory"] = {}}, ["param2"] = 21, ["y"] = 14, ["param1"] = 60, ["z"] = 7, ["name"] = "rainbow:slab_render_white_1"}, {["x"] = 2, ["meta"] = {["fields"] = {}, ["inventory"] = {}}, ["param2"] = 21, ["y"] = 14, ["param1"] = 43, ["z"] = 8, ["name"] = "rainbow:slab_render_white_1"}, {["x"] = 2, ["meta"] = {["fields"] = {}, ["inventory"] = {}}, ["y"] = 14, ["param1"] = 63, ["z"] = 9, ["name"] = "rainbow:render_white"}, {["x"] = 2, ["meta"] = {["fields"] = {}, ["inventory"] = {}}, ["y"] = 15, ["param1"] = 47, ["z"] = 3, ["name"] = "rainbow:render_white"}, {["x"] = 2, ["meta"] = {["fields"] = {}, ["inventory"] = {}}, ["y"] = 15, ["param1"] = 47, ["z"] = 9, ["name"] = "rainbow:render_white"}, {["x"] = 2, ["meta"] = {["fields"] = {}, ["inventory"] = {}}, ["y"] = 16, ["z"] = 3, ["name"] = "rainbow:render_black"}, {["x"] = 2, ["meta"] = {["fields"] = {}, ["inventory"] = {}}, ["param2"] = 12, ["y"] = 16, ["param1"] = 109, ["z"] = 5, ["name"] = "rainbow:slab_coolglass_black_1"}, {["x"] = 2, ["meta"] = {["fields"] = {}, ["inventory"] = {}}, ["param2"] = 12, ["y"] = 16, ["param1"] = 93, ["z"] = 6, ["name"] = "rainbow:slab_coolglass_black_1"}, {["x"] = 2, ["meta"] = {["fields"] = {}, ["inventory"] = {}}, ["param2"] = 12, ["y"] = 16, ["param1"] = 77, ["z"] = 7, ["name"] = "rainbow:slab_coolglass_black_1"}, {["x"] = 2, ["meta"] = {["fields"] = {}, ["inventory"] = {}}, ["y"] = 16, ["z"] = 9, ["name"] = "rainbow:render_black"}, {["x"] = 2, ["meta"] = {["fields"] = {}, ["inventory"] = {}}, ["y"] = 17, ["z"] = 3, ["name"] = "rainbow:render_black"}, {["x"] = 2, ["meta"] = {["fields"] = {}, ["inventory"] = {}}, ["param2"] = 12, ["y"] = 17, ["param1"] = 125, ["z"] = 5, ["name"] = "rainbow:slab_coolglass_black_1"}, {["x"] = 2, ["meta"] = {["fields"] = {}, ["inventory"] = {}}, ["param2"] = 12, ["y"] = 17, ["param1"] = 109, ["z"] = 6, ["name"] = "rainbow:slab_coolglass_black_1"}, {["x"] = 2, ["meta"] = {["fields"] = {}, ["inventory"] = {}}, ["param2"] = 12, ["y"] = 17, ["param1"] = 93, ["z"] = 7, ["name"] = "rainbow:slab_coolglass_black_1"}, {["x"] = 2, ["meta"] = {["fields"] = {}, ["inventory"] = {}}, ["y"] = 17, ["z"] = 9, ["name"] = "rainbow:render_black"}, {["x"] = 2, ["meta"] = {["fields"] = {}, ["inventory"] = {}}, ["y"] = 18, ["z"] = 3, ["name"] = "rainbow:render_black"}, {["x"] = 2, ["meta"] = {["fields"] = {}, ["inventory"] = {}}, ["param2"] = 12, ["y"] = 18, ["param1"] = 109, ["z"] = 5, ["name"] = "rainbow:slab_coolglass_black_1"}, {["x"] = 2, ["meta"] = {["fields"] = {}, ["inventory"] = {}}, ["param2"] = 12, ["y"] = 18, ["param1"] = 93, ["z"] = 6, ["name"] = "rainbow:slab_coolglass_black_1"}, {["x"] = 2, ["meta"] = {["fields"] = {}, ["inventory"] = {}}, ["param2"] = 12, ["y"] = 18, ["param1"] = 77, ["z"] = 7, ["name"] = "rainbow:slab_coolglass_black_1"}, {["x"] = 2, ["meta"] = {["fields"] = {}, ["inventory"] = {}}, ["y"] = 18, ["z"] = 9, ["name"] = "rainbow:render_black"}, {["x"] = 2, ["meta"] = {["fields"] = {}, ["inventory"] = {}}, ["y"] = 19, ["param1"] = 63, ["z"] = 3, ["name"] = "rainbow:render_white"}, {["x"] = 2, ["meta"] = {["fields"] = {}, ["inventory"] = {}}, ["param2"] = 21, ["y"] = 19, ["param1"] = 107, ["z"] = 4, ["name"] = "rainbow:slab_render_white_1"}, {["x"] = 2, ["meta"] = {["fields"] = {}, ["inventory"] = {}}, ["param2"] = 21, ["y"] = 19, ["param1"] = 92, ["z"] = 5, ["name"] = "rainbow:slab_render_white_1"}, {["x"] = 2, ["meta"] = {["fields"] = {}, ["inventory"] = {}}, ["param2"] = 21, ["y"] = 19, ["param1"] = 76, ["z"] = 6, ["name"] = "rainbow:slab_render_white_1"}, {["x"] = 2, ["meta"] = {["fields"] = {}, ["inventory"] = {}}, ["param2"] = 21, ["y"] = 19, ["param1"] = 60, ["z"] = 7, ["name"] = "rainbow:slab_render_white_1"}, {["x"] = 2, ["meta"] = {["fields"] = {}, ["inventory"] = {}}, ["param2"] = 21, ["y"] = 19, ["param1"] = 43, ["z"] = 8, ["name"] = "rainbow:slab_render_white_1"}, {["x"] = 2, ["meta"] = {["fields"] = {}, ["inventory"] = {}}, ["y"] = 19, ["param1"] = 63, ["z"] = 9, ["name"] = "rainbow:render_white"}, {["x"] = 2, ["meta"] = {["fields"] = {}, ["inventory"] = {}}, ["y"] = 20, ["param1"] = 47, ["z"] = 3, ["name"] = "rainbow:render_white"}, {["x"] = 2, ["meta"] = {["fields"] = {}, ["inventory"] = {}}, ["y"] = 20, ["z"] = 4, ["name"] = "rainbow:render_white"}, {["x"] = 2, ["meta"] = {["fields"] = {}, ["inventory"] = {}}, ["y"] = 20, ["z"] = 5, ["name"] = "rainbow:render_white"}, {["x"] = 2, ["meta"] = {["fields"] = {}, ["inventory"] = {}}, ["y"] = 20, ["z"] = 6, ["name"] = "rainbow:render_white"}, {["x"] = 2, ["meta"] = {["fields"] = {}, ["inventory"] = {}}, ["y"] = 20, ["z"] = 7, ["name"] = "rainbow:render_white"}, {["x"] = 2, ["meta"] = {["fields"] = {}, ["inventory"] = {}}, ["y"] = 20, ["z"] = 8, ["name"] = "rainbow:render_white"}, {["x"] = 2, ["meta"] = {["fields"] = {}, ["inventory"] = {}}, ["y"] = 20, ["param1"] = 47, ["z"] = 9, ["name"] = "rainbow:render_white"}, {["x"] = 2, ["meta"] = {["fields"] = {}, ["inventory"] = {}}, ["param2"] = 1, ["y"] = 21, ["param1"] = 110, ["z"] = 3, ["name"] = "rainbow:slope_render_white_outer"}, {["x"] = 2, ["meta"] = {["fields"] = {}, ["inventory"] = {}}, ["y"] = 21, ["z"] = 4, ["name"] = "rainbow:render_white"}, {["x"] = 2, ["meta"] = {["fields"] = {}, ["inventory"] = {}}, ["y"] = 21, ["z"] = 5, ["name"] = "rainbow:render_white"}, {["x"] = 2, ["meta"] = {["fields"] = {}, ["inventory"] = {}}, ["y"] = 21, ["z"] = 6, ["name"] = "rainbow:render_white"}, {["x"] = 2, ["meta"] = {["fields"] = {}, ["inventory"] = {}}, ["y"] = 21, ["z"] = 7, ["name"] = "rainbow:render_white"}, {["x"] = 2, ["meta"] = {["fields"] = {}, ["inventory"] = {}}, ["y"] = 21, ["param1"] = 175, ["z"] = 8, ["name"] = "rainbow:render_white"}, {["x"] = 2, ["meta"] = {["fields"] = {}, ["inventory"] = {}}, ["param2"] = 2, ["y"] = 21, ["param1"] = 30, ["z"] = 9, ["name"] = "rainbow:slope_render_white_outer"}, {["x"] = 2, ["meta"] = {["fields"] = {}, ["inventory"] = {}}, ["y"] = 22, ["z"] = 4, ["name"] = "rainbow:render_red"}, {["x"] = 2, ["meta"] = {["fields"] = {}, ["inventory"] = {}}, ["param2"] = 2, ["y"] = 22, ["param1"] = 126, ["z"] = 5, ["name"] = "rainbow:slope_render_red"}, {["x"] = 2, ["meta"] = {["fields"] = {}, ["inventory"] = {}}, ["param2"] = 3, ["y"] = 22, ["param1"] = 110, ["z"] = 6, ["name"] = "rainbow:slab_coolglass_red_1"}, {["x"] = 2, ["meta"] = {["fields"] = {}, ["inventory"] = {}}, ["y"] = 22, ["param1"] = 94, ["z"] = 7, ["name"] = "rainbow:slope_render_red"}, {["x"] = 2, ["meta"] = {["fields"] = {}, ["inventory"] = {}}, ["y"] = 22, ["z"] = 8, ["name"] = "rainbow:render_red"}, {["x"] = 2, ["meta"] = {["fields"] = {}, ["inventory"] = {}}, ["y"] = 23, ["z"] = 4, ["name"] = "rainbow:render_red"}, {["x"] = 2, ["meta"] = {["fields"] = {}, ["inventory"] = {}}, ["y"] = 23, ["z"] = 8, ["name"] = "rainbow:render_red"}, {["x"] = 2, ["meta"] = {["fields"] = {}, ["inventory"] = {}}, ["y"] = 24, ["z"] = 4, ["name"] = "rainbow:render_red"}, {["x"] = 2, ["meta"] = {["fields"] = {}, ["inventory"] = {}}, ["param2"] = 22, ["y"] = 24, ["param1"] = 126, ["z"] = 5, ["name"] = "rainbow:slope_render_red"}, {["x"] = 2, ["meta"] = {["fields"] = {}, ["inventory"] = {}}, ["param2"] = 21, ["y"] = 24, ["param1"] = 110, ["z"] = 6, ["name"] = "rainbow:slab_coolglass_red_1"}, {["x"] = 2, ["meta"] = {["fields"] = {}, ["inventory"] = {}}, ["param2"] = 20, ["y"] = 24, ["param1"] = 94, ["z"] = 7, ["name"] = "rainbow:slope_render_red"}, {["x"] = 2, ["meta"] = {["fields"] = {}, ["inventory"] = {}}, ["y"] = 24, ["z"] = 8, ["name"] = "rainbow:render_red"}, {["x"] = 2, ["meta"] = {["fields"] = {}, ["inventory"] = {}}, ["y"] = 25, ["param1"] = 111, ["z"] = 4, ["name"] = "rainbow:render_white"}, {["x"] = 2, ["meta"] = {["fields"] = {}, ["inventory"] = {}}, ["y"] = 25, ["param1"] = 127, ["z"] = 5, ["name"] = "rainbow:render_white"}, {["x"] = 2, ["meta"] = {["fields"] = {}, ["inventory"] = {}}, ["y"] = 25, ["param1"] = 143, ["z"] = 6, ["name"] = "rainbow:render_white"}, {["x"] = 2, ["meta"] = {["fields"] = {}, ["inventory"] = {}}, ["y"] = 25, ["param1"] = 127, ["z"] = 7, ["name"] = "rainbow:render_white"}, {["x"] = 2, ["meta"] = {["fields"] = {}, ["inventory"] = {}}, ["y"] = 25, ["param1"] = 111, ["z"] = 8, ["name"] = "rainbow:render_white"}, {["x"] = 2, ["meta"] = {["fields"] = {}, ["inventory"] = {}}, ["y"] = 26, ["param1"] = 95, ["z"] = 4, ["name"] = "rainbow:render_white"}, {["x"] = 2, ["meta"] = {["fields"] = {}, ["inventory"] = {}}, ["y"] = 26, ["param1"] = 111, ["z"] = 5, ["name"] = "rainbow:render_white"}, {["x"] = 2, ["meta"] = {["fields"] = {}, ["inventory"] = {}}, ["y"] = 26, ["param1"] = 127, ["z"] = 6, ["name"] = "rainbow:render_white"}, {["x"] = 2, ["meta"] = {["fields"] = {}, ["inventory"] = {}}, ["y"] = 26, ["param1"] = 111, ["z"] = 7, ["name"] = "rainbow:render_white"}, {["x"] = 2, ["meta"] = {["fields"] = {}, ["inventory"] = {}}, ["y"] = 26, ["param1"] = 95, ["z"] = 8, ["name"] = "rainbow:render_white"}, {["x"] = 2, ["meta"] = {["fields"] = {}, ["inventory"] = {}}, ["y"] = 27, ["z"] = 4, ["name"] = "rainbow:render_cyan"}, {["x"] = 2, ["meta"] = {["fields"] = {}, ["inventory"] = {}}, ["param2"] = 2, ["y"] = 27, ["param1"] = 126, ["z"] = 5, ["name"] = "rainbow:slope_render_cyan"}, {["x"] = 2, ["meta"] = {["fields"] = {}, ["inventory"] = {}}, ["param2"] = 3, ["y"] = 27, ["param1"] = 110, ["z"] = 6, ["name"] = "rainbow:slab_coolglass_cyan_1"}, {["x"] = 2, ["meta"] = {["fields"] = {}, ["inventory"] = {}}, ["y"] = 27, ["param1"] = 94, ["z"] = 7, ["name"] = "rainbow:slope_render_cyan"}, {["x"] = 2, ["meta"] = {["fields"] = {}, ["inventory"] = {}}, ["y"] = 27, ["z"] = 8, ["name"] = "rainbow:render_cyan"}, {["x"] = 2, ["meta"] = {["fields"] = {}, ["inventory"] = {}}, ["y"] = 28, ["z"] = 4, ["name"] = "rainbow:render_cyan"}, {["x"] = 2, ["meta"] = {["fields"] = {}, ["inventory"] = {}}, ["y"] = 28, ["z"] = 8, ["name"] = "rainbow:render_cyan"}, {["x"] = 2, ["meta"] = {["fields"] = {}, ["inventory"] = {}}, ["y"] = 29, ["z"] = 4, ["name"] = "rainbow:render_cyan"}, {["x"] = 2, ["meta"] = {["fields"] = {}, ["inventory"] = {}}, ["param2"] = 22, ["y"] = 29, ["param1"] = 126, ["z"] = 5, ["name"] = "rainbow:slope_render_cyan"}, {["x"] = 2, ["meta"] = {["fields"] = {}, ["inventory"] = {}}, ["param2"] = 21, ["y"] = 29, ["param1"] = 110, ["z"] = 6, ["name"] = "rainbow:slab_coolglass_cyan_1"}, {["x"] = 2, ["meta"] = {["fields"] = {}, ["inventory"] = {}}, ["param2"] = 20, ["y"] = 29, ["param1"] = 94, ["z"] = 7, ["name"] = "rainbow:slope_render_cyan"}, {["x"] = 2, ["meta"] = {["fields"] = {}, ["inventory"] = {}}, ["y"] = 29, ["z"] = 8, ["name"] = "rainbow:render_cyan"}, {["x"] = 2, ["meta"] = {["fields"] = {}, ["inventory"] = {}}, ["y"] = 30, ["param1"] = 111, ["z"] = 4, ["name"] = "rainbow:render_white"}, {["x"] = 2, ["meta"] = {["fields"] = {}, ["inventory"] = {}}, ["y"] = 30, ["param1"] = 127, ["z"] = 5, ["name"] = "rainbow:render_white"}, {["x"] = 2, ["meta"] = {["fields"] = {}, ["inventory"] = {}}, ["y"] = 30, ["param1"] = 143, ["z"] = 6, ["name"] = "rainbow:render_white"}, {["x"] = 2, ["meta"] = {["fields"] = {}, ["inventory"] = {}}, ["y"] = 30, ["param1"] = 127, ["z"] = 7, ["name"] = "rainbow:render_white"}, {["x"] = 2, ["meta"] = {["fields"] = {}, ["inventory"] = {}}, ["y"] = 30, ["param1"] = 111, ["z"] = 8, ["name"] = "rainbow:render_white"}, {["x"] = 2, ["meta"] = {["fields"] = {}, ["inventory"] = {}}, ["y"] = 31, ["param1"] = 95, ["z"] = 4, ["name"] = "rainbow:render_white"}, {["x"] = 2, ["meta"] = {["fields"] = {}, ["inventory"] = {}}, ["y"] = 31, ["param1"] = 111, ["z"] = 5, ["name"] = "rainbow:render_white"}, {["x"] = 2, ["meta"] = {["fields"] = {}, ["inventory"] = {}}, ["y"] = 31, ["param1"] = 127, ["z"] = 6, ["name"] = "rainbow:render_white"}, {["x"] = 2, ["meta"] = {["fields"] = {}, ["inventory"] = {}}, ["y"] = 31, ["param1"] = 111, ["z"] = 7, ["name"] = "rainbow:render_white"}, {["x"] = 2, ["meta"] = {["fields"] = {}, ["inventory"] = {}}, ["y"] = 31, ["param1"] = 95, ["z"] = 8, ["name"] = "rainbow:render_white"}, {["x"] = 2, ["meta"] = {["fields"] = {}, ["inventory"] = {}}, ["y"] = 32, ["z"] = 4, ["name"] = "rainbow:render_yellow"}, {["x"] = 2, ["meta"] = {["fields"] = {}, ["inventory"] = {}}, ["param2"] = 2, ["y"] = 32, ["param1"] = 126, ["z"] = 5, ["name"] = "rainbow:slope_render_yellow"}, {["x"] = 2, ["meta"] = {["fields"] = {}, ["inventory"] = {}}, ["param2"] = 3, ["y"] = 32, ["param1"] = 110, ["z"] = 6, ["name"] = "rainbow:slab_coolglass_yellow_1"}, {["x"] = 2, ["meta"] = {["fields"] = {}, ["inventory"] = {}}, ["y"] = 32, ["param1"] = 94, ["z"] = 7, ["name"] = "rainbow:slope_render_yellow"}, {["x"] = 2, ["meta"] = {["fields"] = {}, ["inventory"] = {}}, ["y"] = 32, ["z"] = 8, ["name"] = "rainbow:render_yellow"}, {["x"] = 2, ["meta"] = {["fields"] = {}, ["inventory"] = {}}, ["y"] = 33, ["z"] = 4, ["name"] = "rainbow:render_yellow"}, {["x"] = 2, ["meta"] = {["fields"] = {}, ["inventory"] = {}}, ["y"] = 33, ["z"] = 8, ["name"] = "rainbow:render_yellow"}, {["x"] = 2, ["meta"] = {["fields"] = {}, ["inventory"] = {}}, ["y"] = 34, ["z"] = 4, ["name"] = "rainbow:render_yellow"}, {["x"] = 2, ["meta"] = {["fields"] = {}, ["inventory"] = {}}, ["param2"] = 22, ["y"] = 34, ["param1"] = 126, ["z"] = 5, ["name"] = "rainbow:slope_render_yellow"}, {["x"] = 2, ["meta"] = {["fields"] = {}, ["inventory"] = {}}, ["param2"] = 21, ["y"] = 34, ["param1"] = 110, ["z"] = 6, ["name"] = "rainbow:slab_coolglass_yellow_1"}, {["x"] = 2, ["meta"] = {["fields"] = {}, ["inventory"] = {}}, ["param2"] = 20, ["y"] = 34, ["param1"] = 94, ["z"] = 7, ["name"] = "rainbow:slope_render_yellow"}, {["x"] = 2, ["meta"] = {["fields"] = {}, ["inventory"] = {}}, ["y"] = 34, ["z"] = 8, ["name"] = "rainbow:render_yellow"}, {["x"] = 2, ["meta"] = {["fields"] = {}, ["inventory"] = {}}, ["y"] = 35, ["param1"] = 111, ["z"] = 4, ["name"] = "rainbow:render_white"}, {["x"] = 2, ["meta"] = {["fields"] = {}, ["inventory"] = {}}, ["y"] = 35, ["param1"] = 127, ["z"] = 5, ["name"] = "rainbow:render_white"}, {["x"] = 2, ["meta"] = {["fields"] = {}, ["inventory"] = {}}, ["y"] = 35, ["param1"] = 143, ["z"] = 6, ["name"] = "rainbow:render_white"}, {["x"] = 2, ["meta"] = {["fields"] = {}, ["inventory"] = {}}, ["y"] = 35, ["param1"] = 127, ["z"] = 7, ["name"] = "rainbow:render_white"}, {["x"] = 2, ["meta"] = {["fields"] = {}, ["inventory"] = {}}, ["y"] = 35, ["param1"] = 111, ["z"] = 8, ["name"] = "rainbow:render_white"}, {["x"] = 2, ["meta"] = {["fields"] = {}, ["inventory"] = {}}, ["y"] = 36, ["param1"] = 95, ["z"] = 4, ["name"] = "rainbow:render_white"}, {["x"] = 2, ["meta"] = {["fields"] = {}, ["inventory"] = {}}, ["y"] = 36, ["param1"] = 111, ["z"] = 5, ["name"] = "rainbow:render_white"}, {["x"] = 2, ["meta"] = {["fields"] = {}, ["inventory"] = {}}, ["y"] = 36, ["param1"] = 127, ["z"] = 6, ["name"] = "rainbow:render_white"}, {["x"] = 2, ["meta"] = {["fields"] = {}, ["inventory"] = {}}, ["y"] = 36, ["param1"] = 111, ["z"] = 7, ["name"] = "rainbow:render_white"}, {["x"] = 2, ["meta"] = {["fields"] = {}, ["inventory"] = {}}, ["y"] = 36, ["param1"] = 95, ["z"] = 8, ["name"] = "rainbow:render_white"}, {["x"] = 2, ["meta"] = {["fields"] = {}, ["inventory"] = {}}, ["y"] = 37, ["z"] = 4, ["name"] = "rainbow:render_orange"}, {["x"] = 2, ["meta"] = {["fields"] = {}, ["inventory"] = {}}, ["param2"] = 2, ["y"] = 37, ["param1"] = 126, ["z"] = 5, ["name"] = "rainbow:slope_render_orange"}, {["x"] = 2, ["meta"] = {["fields"] = {}, ["inventory"] = {}}, ["param2"] = 3, ["y"] = 37, ["param1"] = 110, ["z"] = 6, ["name"] = "rainbow:slab_coolglass_orange_1"}, {["x"] = 2, ["meta"] = {["fields"] = {}, ["inventory"] = {}}, ["y"] = 37, ["param1"] = 94, ["z"] = 7, ["name"] = "rainbow:slope_render_orange"}, {["x"] = 2, ["meta"] = {["fields"] = {}, ["inventory"] = {}}, ["y"] = 37, ["z"] = 8, ["name"] = "rainbow:render_orange"}, {["x"] = 2, ["meta"] = {["fields"] = {}, ["inventory"] = {}}, ["y"] = 38, ["z"] = 4, ["name"] = "rainbow:render_orange"}, {["x"] = 2, ["meta"] = {["fields"] = {}, ["inventory"] = {}}, ["y"] = 38, ["z"] = 8, ["name"] = "rainbow:render_orange"}, {["x"] = 2, ["meta"] = {["fields"] = {}, ["inventory"] = {}}, ["y"] = 39, ["z"] = 4, ["name"] = "rainbow:render_orange"}, {["x"] = 2, ["meta"] = {["fields"] = {}, ["inventory"] = {}}, ["param2"] = 22, ["y"] = 39, ["param1"] = 126, ["z"] = 5, ["name"] = "rainbow:slope_render_orange"}, {["x"] = 2, ["meta"] = {["fields"] = {}, ["inventory"] = {}}, ["param2"] = 21, ["y"] = 39, ["param1"] = 110, ["z"] = 6, ["name"] = "rainbow:slab_coolglass_orange_1"}, {["x"] = 2, ["meta"] = {["fields"] = {}, ["inventory"] = {}}, ["param2"] = 20, ["y"] = 39, ["param1"] = 94, ["z"] = 7, ["name"] = "rainbow:slope_render_orange"}, {["x"] = 2, ["meta"] = {["fields"] = {}, ["inventory"] = {}}, ["y"] = 39, ["z"] = 8, ["name"] = "rainbow:render_orange"}, {["x"] = 2, ["meta"] = {["fields"] = {}, ["inventory"] = {}}, ["y"] = 40, ["param1"] = 111, ["z"] = 4, ["name"] = "rainbow:render_white"}, {["x"] = 2, ["meta"] = {["fields"] = {}, ["inventory"] = {}}, ["y"] = 40, ["param1"] = 127, ["z"] = 5, ["name"] = "rainbow:render_white"}, {["x"] = 2, ["meta"] = {["fields"] = {}, ["inventory"] = {}}, ["y"] = 40, ["param1"] = 143, ["z"] = 6, ["name"] = "rainbow:render_white"}, {["x"] = 2, ["meta"] = {["fields"] = {}, ["inventory"] = {}}, ["y"] = 40, ["param1"] = 127, ["z"] = 7, ["name"] = "rainbow:render_white"}, {["x"] = 2, ["meta"] = {["fields"] = {}, ["inventory"] = {}}, ["y"] = 40, ["param1"] = 111, ["z"] = 8, ["name"] = "rainbow:render_white"}, {["x"] = 2, ["meta"] = {["fields"] = {}, ["inventory"] = {}}, ["y"] = 41, ["param1"] = 95, ["z"] = 4, ["name"] = "rainbow:render_white"}, {["x"] = 2, ["meta"] = {["fields"] = {}, ["inventory"] = {}}, ["y"] = 41, ["param1"] = 111, ["z"] = 5, ["name"] = "rainbow:render_white"}, {["x"] = 2, ["meta"] = {["fields"] = {}, ["inventory"] = {}}, ["y"] = 41, ["param1"] = 127, ["z"] = 6, ["name"] = "rainbow:render_white"}, {["x"] = 2, ["meta"] = {["fields"] = {}, ["inventory"] = {}}, ["y"] = 41, ["param1"] = 111, ["z"] = 7, ["name"] = "rainbow:render_white"}, {["x"] = 2, ["meta"] = {["fields"] = {}, ["inventory"] = {}}, ["y"] = 41, ["param1"] = 95, ["z"] = 8, ["name"] = "rainbow:render_white"}, {["x"] = 3, ["meta"] = {["fields"] = {}, ["inventory"] = {}}, ["y"] = 0, ["param1"] = 15, ["z"] = 0, ["name"] = "rainbow:binary_white"}, {["x"] = 3, ["meta"] = {["fields"] = {}, ["inventory"] = {}}, ["y"] = 0, ["param1"] = 15, ["z"] = 1, ["name"] = "rainbow:binary_white"}, {["x"] = 3, ["meta"] = {["fields"] = {}, ["inventory"] = {}}, ["y"] = 0, ["param1"] = 15, ["z"] = 2, ["name"] = "rainbow:binary_white"}, {["x"] = 3, ["meta"] = {["fields"] = {}, ["inventory"] = {}}, ["y"] = 0, ["param1"] = 15, ["z"] = 3, ["name"] = "rainbow:binary_white"}, {["x"] = 3, ["meta"] = {["fields"] = {}, ["inventory"] = {}}, ["y"] = 0, ["param1"] = 15, ["z"] = 4, ["name"] = "rainbow:binary_white"}, {["x"] = 3, ["meta"] = {["fields"] = {}, ["inventory"] = {}}, ["y"] = 0, ["param1"] = 15, ["z"] = 5, ["name"] = "rainbow:binary_white"}, {["x"] = 3, ["meta"] = {["fields"] = {}, ["inventory"] = {}}, ["y"] = 0, ["param1"] = 15, ["z"] = 6, ["name"] = "rainbow:binary_white"}, {["x"] = 3, ["meta"] = {["fields"] = {}, ["inventory"] = {}}, ["y"] = 0, ["param1"] = 15, ["z"] = 7, ["name"] = "rainbow:binary_white"}, {["x"] = 3, ["meta"] = {["fields"] = {}, ["inventory"] = {}}, ["y"] = 0, ["param1"] = 15, ["z"] = 8, ["name"] = "rainbow:binary_white"}, {["x"] = 3, ["meta"] = {["fields"] = {}, ["inventory"] = {}}, ["y"] = 0, ["param1"] = 15, ["z"] = 9, ["name"] = "rainbow:binary_white"}, {["x"] = 3, ["meta"] = {["fields"] = {}, ["inventory"] = {}}, ["y"] = 0, ["param1"] = 15, ["z"] = 10, ["name"] = "rainbow:binary_white"}, {["x"] = 3, ["meta"] = {["fields"] = {}, ["inventory"] = {}}, ["y"] = 0, ["param1"] = 14, ["z"] = 11, ["name"] = "rainbow:binary_white"}, {["x"] = 3, ["meta"] = {["fields"] = {}, ["inventory"] = {}}, ["y"] = 0, ["param1"] = 14, ["z"] = 12, ["name"] = "rainbow:binary_white"}, {["x"] = 3, ["meta"] = {["fields"] = {}, ["inventory"] = {}}, ["param2"] = 1, ["y"] = 1, ["param1"] = 222, ["z"] = 1, ["name"] = "rainbow:slope_render_violet_outer"}, {["x"] = 3, ["meta"] = {["fields"] = {}, ["inventory"] = {}}, ["y"] = 1, ["z"] = 2, ["name"] = "rainbow:render_violet"}, {["x"] = 3, ["meta"] = {["fields"] = {}, ["inventory"] = {}}, ["param2"] = 20, ["y"] = 1, ["param1"] = 221, ["z"] = 4, ["name"] = "rainbow:slope_render_violet"}, {["x"] = 3, ["meta"] = {["fields"] = {}, ["inventory"] = {}}, ["param2"] = 2, ["y"] = 1, ["param1"] = 221, ["z"] = 5, ["name"] = "rainbow:slope_render_violet"}, {["x"] = 3, ["meta"] = {["fields"] = {}, ["inventory"] = {}}, ["y"] = 1, ["z"] = 10, ["name"] = "rainbow:render_violet"}, {["x"] = 3, ["meta"] = {["fields"] = {}, ["inventory"] = {}}, ["param2"] = 2, ["y"] = 1, ["param1"] = 222, ["z"] = 11, ["name"] = "rainbow:slope_render_violet_outer"}, {["x"] = 3, ["meta"] = {["fields"] = {}, ["inventory"] = {}}, ["y"] = 2, ["z"] = 2, ["name"] = "rainbow:render_violet"}, {["x"] = 3, ["meta"] = {["fields"] = {}, ["inventory"] = {}}, ["y"] = 2, ["z"] = 3, ["name"] = "rainbow:render_violet"}, {["x"] = 3, ["meta"] = {["fields"] = {}, ["inventory"] = {}}, ["param2"] = 2, ["y"] = 2, ["param1"] = 204, ["z"] = 4, ["name"] = "rainbow:slope_render_violet"}, {["x"] = 3, ["meta"] = {["fields"] = {}, ["inventory"] = {}}, ["y"] = 2, ["z"] = 10, ["name"] = "rainbow:render_violet"}, {["x"] = 3, ["meta"] = {["fields"] = {}, ["inventory"] = {}}, ["y"] = 3, ["z"] = 2, ["name"] = "rainbow:render_violet"}, {["x"] = 3, ["meta"] = {["fields"] = {}, ["inventory"] = {}}, ["y"] = 3, ["z"] = 10, ["name"] = "rainbow:render_violet"}, {["x"] = 3, ["meta"] = {["fields"] = {}, ["inventory"] = {}}, ["y"] = 4, ["param1"] = 63, ["z"] = 2, ["name"] = "rainbow:render_white"}, {["x"] = 3, ["meta"] = {["fields"] = {}, ["inventory"] = {}}, ["param2"] = 21, ["y"] = 4, ["param1"] = 170, ["z"] = 4, ["name"] = "rainbow:slab_render_white_1"}, {["x"] = 3, ["meta"] = {["fields"] = {}, ["inventory"] = {}}, ["param2"] = 21, ["y"] = 4, ["param1"] = 171, ["z"] = 5, ["name"] = "rainbow:slab_render_white_1"}, {["x"] = 3, ["meta"] = {["fields"] = {}, ["inventory"] = {}}, ["param2"] = 21, ["y"] = 4, ["param1"] = 171, ["z"] = 6, ["name"] = "rainbow:slab_render_white_1"}, {["x"] = 3, ["meta"] = {["fields"] = {}, ["inventory"] = {}}, ["param2"] = 21, ["y"] = 4, ["param1"] = 171, ["z"] = 7, ["name"] = "rainbow:slab_render_white_1"}, {["x"] = 3, ["meta"] = {["fields"] = {}, ["inventory"] = {}}, ["param2"] = 21, ["y"] = 4, ["param1"] = 170, ["z"] = 8, ["name"] = "rainbow:slab_render_white_1"}, {["x"] = 3, ["meta"] = {["fields"] = {}, ["inventory"] = {}}, ["param2"] = 21, ["y"] = 4, ["param1"] = 170, ["z"] = 9, ["name"] = "rainbow:slab_render_white_1"}, {["x"] = 3, ["meta"] = {["fields"] = {}, ["inventory"] = {}}, ["y"] = 4, ["param1"] = 63, ["z"] = 10, ["name"] = "rainbow:render_white"}, {["x"] = 3, ["meta"] = {["fields"] = {}, ["inventory"] = {}}, ["y"] = 5, ["param1"] = 47, ["z"] = 2, ["name"] = "rainbow:render_white"}, {["x"] = 3, ["meta"] = {["fields"] = {}, ["inventory"] = {}}, ["param2"] = 20, ["y"] = 5, ["param1"] = 155, ["z"] = 5, ["name"] = "rainbow:slope_render_lightgreen"}, {["x"] = 3, ["meta"] = {["fields"] = {}, ["inventory"] = {}}, ["param2"] = 2, ["y"] = 5, ["param1"] = 155, ["z"] = 6, ["name"] = "rainbow:slope_render_lightgreen"}, {["x"] = 3, ["meta"] = {["fields"] = {}, ["inventory"] = {}}, ["y"] = 5, ["param1"] = 47, ["z"] = 10, ["name"] = "rainbow:render_white"}, {["x"] = 3, ["meta"] = {["fields"] = {}, ["inventory"] = {}}, ["y"] = 6, ["z"] = 2, ["name"] = "rainbow:render_lightgreen"}, {["x"] = 3, ["meta"] = {["fields"] = {}, ["inventory"] = {}}, ["param2"] = 20, ["y"] = 6, ["param1"] = 139, ["z"] = 4, ["name"] = "rainbow:slope_render_lightgreen"}, {["x"] = 3, ["meta"] = {["fields"] = {}, ["inventory"] = {}}, ["param2"] = 2, ["y"] = 6, ["param1"] = 140, ["z"] = 5, ["name"] = "rainbow:slope_render_lightgreen"}, {["x"] = 3, ["meta"] = {["fields"] = {}, ["inventory"] = {}}, ["y"] = 6, ["z"] = 10, ["name"] = "rainbow:render_lightgreen"}, {["x"] = 3, ["meta"] = {["fields"] = {}, ["inventory"] = {}}, ["y"] = 7, ["z"] = 2, ["name"] = "rainbow:render_lightgreen"}, {["x"] = 3, ["meta"] = {["fields"] = {}, ["inventory"] = {}}, ["y"] = 7, ["z"] = 3, ["name"] = "rainbow:render_lightgreen"}, {["x"] = 3, ["meta"] = {["fields"] = {}, ["inventory"] = {}}, ["param2"] = 2, ["y"] = 7, ["param1"] = 155, ["z"] = 4, ["name"] = "rainbow:slope_render_lightgreen"}, {["x"] = 3, ["meta"] = {["fields"] = {}, ["inventory"] = {}}, ["y"] = 7, ["z"] = 10, ["name"] = "rainbow:render_lightgreen"}, {["x"] = 3, ["meta"] = {["fields"] = {}, ["inventory"] = {}}, ["y"] = 8, ["z"] = 2, ["name"] = "rainbow:render_lightgreen"}, {["x"] = 3, ["meta"] = {["fields"] = {}, ["inventory"] = {}}, ["y"] = 8, ["z"] = 10, ["name"] = "rainbow:render_lightgreen"}, {["x"] = 3, ["meta"] = {["fields"] = {}, ["inventory"] = {}}, ["y"] = 9, ["param1"] = 63, ["z"] = 2, ["name"] = "rainbow:render_white"}, {["x"] = 3, ["meta"] = {["fields"] = {}, ["inventory"] = {}}, ["param2"] = 21, ["y"] = 9, ["param1"] = 122, ["z"] = 4, ["name"] = "rainbow:slab_render_white_1"}, {["x"] = 3, ["meta"] = {["fields"] = {}, ["inventory"] = {}}, ["param2"] = 21, ["y"] = 9, ["param1"] = 107, ["z"] = 5, ["name"] = "rainbow:slab_render_white_1"}, {["x"] = 3, ["meta"] = {["fields"] = {}, ["inventory"] = {}}, ["param2"] = 21, ["y"] = 9, ["param1"] = 91, ["z"] = 6, ["name"] = "rainbow:slab_render_white_1"}, {["x"] = 3, ["meta"] = {["fields"] = {}, ["inventory"] = {}}, ["param2"] = 21, ["y"] = 9, ["param1"] = 91, ["z"] = 7, ["name"] = "rainbow:slab_render_white_1"}, {["x"] = 3, ["meta"] = {["fields"] = {}, ["inventory"] = {}}, ["param2"] = 21, ["y"] = 9, ["param1"] = 90, ["z"] = 8, ["name"] = "rainbow:slab_render_white_1"}, {["x"] = 3, ["meta"] = {["fields"] = {}, ["inventory"] = {}}, ["param2"] = 21, ["y"] = 9, ["param1"] = 89, ["z"] = 9, ["name"] = "rainbow:slab_render_white_1"}, {["x"] = 3, ["meta"] = {["fields"] = {}, ["inventory"] = {}}, ["y"] = 9, ["param1"] = 63, ["z"] = 10, ["name"] = "rainbow:render_white"}, {["x"] = 3, ["meta"] = {["fields"] = {}, ["inventory"] = {}}, ["y"] = 10, ["param1"] = 47, ["z"] = 2, ["name"] = "rainbow:render_white"}, {["x"] = 3, ["meta"] = {["fields"] = {}, ["inventory"] = {}}, ["param2"] = 20, ["y"] = 10, ["param1"] = 107, ["z"] = 5, ["name"] = "rainbow:slope_render_blue"}, {["x"] = 3, ["meta"] = {["fields"] = {}, ["inventory"] = {}}, ["param2"] = 2, ["y"] = 10, ["param1"] = 91, ["z"] = 6, ["name"] = "rainbow:slope_render_blue"}, {["x"] = 3, ["meta"] = {["fields"] = {}, ["inventory"] = {}}, ["y"] = 10, ["param1"] = 47, ["z"] = 10, ["name"] = "rainbow:render_white"}, {["x"] = 3, ["meta"] = {["fields"] = {}, ["inventory"] = {}}, ["y"] = 11, ["z"] = 2, ["name"] = "rainbow:render_blue"}, {["x"] = 3, ["meta"] = {["fields"] = {}, ["inventory"] = {}}, ["param2"] = 20, ["y"] = 11, ["param1"] = 139, ["z"] = 4, ["name"] = "rainbow:slope_render_blue"}, {["x"] = 3, ["meta"] = {["fields"] = {}, ["inventory"] = {}}, ["param2"] = 2, ["y"] = 11, ["param1"] = 124, ["z"] = 5, ["name"] = "rainbow:slope_render_blue"}, {["x"] = 3, ["meta"] = {["fields"] = {}, ["inventory"] = {}}, ["y"] = 11, ["z"] = 10, ["name"] = "rainbow:render_blue"}, {["x"] = 3, ["meta"] = {["fields"] = {}, ["inventory"] = {}}, ["y"] = 12, ["z"] = 2, ["name"] = "rainbow:render_blue"}, {["x"] = 3, ["meta"] = {["fields"] = {}, ["inventory"] = {}}, ["y"] = 12, ["z"] = 3, ["name"] = "rainbow:render_blue"}, {["x"] = 3, ["meta"] = {["fields"] = {}, ["inventory"] = {}}, ["param2"] = 2, ["y"] = 12, ["param1"] = 155, ["z"] = 4, ["name"] = "rainbow:slope_render_blue"}, {["x"] = 3, ["meta"] = {["fields"] = {}, ["inventory"] = {}}, ["y"] = 12, ["z"] = 10, ["name"] = "rainbow:render_blue"}, {["x"] = 3, ["meta"] = {["fields"] = {}, ["inventory"] = {}}, ["y"] = 13, ["z"] = 2, ["name"] = "rainbow:render_blue"}, {["x"] = 3, ["meta"] = {["fields"] = {}, ["inventory"] = {}}, ["y"] = 13, ["z"] = 10, ["name"] = "rainbow:render_blue"}, {["x"] = 3, ["meta"] = {["fields"] = {}, ["inventory"] = {}}, ["y"] = 14, ["param1"] = 63, ["z"] = 2, ["name"] = "rainbow:render_white"}, {["x"] = 3, ["meta"] = {["fields"] = {}, ["inventory"] = {}}, ["param2"] = 21, ["y"] = 14, ["param1"] = 122, ["z"] = 4, ["name"] = "rainbow:slab_render_white_1"}, {["x"] = 3, ["meta"] = {["fields"] = {}, ["inventory"] = {}}, ["param2"] = 21, ["y"] = 14, ["param1"] = 107, ["z"] = 5, ["name"] = "rainbow:slab_render_white_1"}, {["x"] = 3, ["meta"] = {["fields"] = {}, ["inventory"] = {}}, ["param2"] = 21, ["y"] = 14, ["param1"] = 91, ["z"] = 6, ["name"] = "rainbow:slab_render_white_1"}, {["x"] = 3, ["meta"] = {["fields"] = {}, ["inventory"] = {}}, ["param2"] = 21, ["y"] = 14, ["param1"] = 75, ["z"] = 7, ["name"] = "rainbow:slab_render_white_1"}, {["x"] = 3, ["meta"] = {["fields"] = {}, ["inventory"] = {}}, ["param2"] = 21, ["y"] = 14, ["param1"] = 58, ["z"] = 8, ["name"] = "rainbow:slab_render_white_1"}, {["x"] = 3, ["meta"] = {["fields"] = {}, ["inventory"] = {}}, ["param2"] = 21, ["y"] = 14, ["param1"] = 41, ["z"] = 9, ["name"] = "rainbow:slab_render_white_1"}, {["x"] = 3, ["meta"] = {["fields"] = {}, ["inventory"] = {}}, ["y"] = 14, ["param1"] = 63, ["z"] = 10, ["name"] = "rainbow:render_white"}, {["x"] = 3, ["meta"] = {["fields"] = {}, ["inventory"] = {}}, ["y"] = 15, ["param1"] = 47, ["z"] = 2, ["name"] = "rainbow:render_white"}, {["x"] = 3, ["meta"] = {["fields"] = {}, ["inventory"] = {}}, ["param2"] = 20, ["y"] = 15, ["param1"] = 107, ["z"] = 5, ["name"] = "rainbow:slope_render_black"}, {["x"] = 3, ["meta"] = {["fields"] = {}, ["inventory"] = {}}, ["param2"] = 2, ["y"] = 15, ["param1"] = 91, ["z"] = 6, ["name"] = "rainbow:slope_render_black"}, {["x"] = 3, ["meta"] = {["fields"] = {}, ["inventory"] = {}}, ["y"] = 15, ["z"] = 10, ["name"] = "rainbow:render_white"}, {["x"] = 3, ["meta"] = {["fields"] = {}, ["inventory"] = {}}, ["y"] = 16, ["z"] = 2, ["name"] = "rainbow:render_black"}, {["x"] = 3, ["meta"] = {["fields"] = {}, ["inventory"] = {}}, ["param2"] = 20, ["y"] = 16, ["param1"] = 139, ["z"] = 4, ["name"] = "rainbow:slope_render_black"}, {["x"] = 3, ["meta"] = {["fields"] = {}, ["inventory"] = {}}, ["param2"] = 2, ["y"] = 16, ["param1"] = 124, ["z"] = 5, ["name"] = "rainbow:slope_render_black"}, {["x"] = 3, ["meta"] = {["fields"] = {}, ["inventory"] = {}}, ["y"] = 16, ["z"] = 10, ["name"] = "rainbow:render_black"}, {["x"] = 3, ["meta"] = {["fields"] = {}, ["inventory"] = {}}, ["y"] = 17, ["z"] = 2, ["name"] = "rainbow:render_black"}, {["x"] = 3, ["meta"] = {["fields"] = {}, ["inventory"] = {}}, ["y"] = 17, ["z"] = 3, ["name"] = "rainbow:render_black"}, {["x"] = 3, ["meta"] = {["fields"] = {}, ["inventory"] = {}}, ["param2"] = 2, ["y"] = 17, ["param1"] = 155, ["z"] = 4, ["name"] = "rainbow:slope_render_black"}, {["x"] = 3, ["meta"] = {["fields"] = {}, ["inventory"] = {}}, ["y"] = 17, ["z"] = 10, ["name"] = "rainbow:render_black"}, {["x"] = 3, ["meta"] = {["fields"] = {}, ["inventory"] = {}}, ["y"] = 18, ["z"] = 2, ["name"] = "rainbow:render_black"}, {["x"] = 3, ["meta"] = {["fields"] = {}, ["inventory"] = {}}, ["y"] = 18, ["z"] = 10, ["name"] = "rainbow:render_black"}, {["x"] = 3, ["meta"] = {["fields"] = {}, ["inventory"] = {}}, ["y"] = 19, ["param1"] = 63, ["z"] = 2, ["name"] = "rainbow:render_white"}, {["x"] = 3, ["meta"] = {["fields"] = {}, ["inventory"] = {}}, ["param2"] = 21, ["y"] = 19, ["param1"] = 122, ["z"] = 4, ["name"] = "rainbow:slab_render_white_1"}, {["x"] = 3, ["meta"] = {["fields"] = {}, ["inventory"] = {}}, ["param2"] = 21, ["y"] = 19, ["param1"] = 107, ["z"] = 5, ["name"] = "rainbow:slab_render_white_1"}, {["x"] = 3, ["meta"] = {["fields"] = {}, ["inventory"] = {}}, ["param2"] = 21, ["y"] = 19, ["param1"] = 91, ["z"] = 6, ["name"] = "rainbow:slab_render_white_1"}, {["x"] = 3, ["meta"] = {["fields"] = {}, ["inventory"] = {}}, ["param2"] = 21, ["y"] = 19, ["param1"] = 75, ["z"] = 7, ["name"] = "rainbow:slab_render_white_1"}, {["x"] = 3, ["meta"] = {["fields"] = {}, ["inventory"] = {}}, ["param2"] = 21, ["y"] = 19, ["param1"] = 58, ["z"] = 8, ["name"] = "rainbow:slab_render_white_1"}, {["x"] = 3, ["meta"] = {["fields"] = {}, ["inventory"] = {}}, ["param2"] = 21, ["y"] = 19, ["param1"] = 41, ["z"] = 9, ["name"] = "rainbow:slab_render_white_1"}, {["x"] = 3, ["meta"] = {["fields"] = {}, ["inventory"] = {}}, ["y"] = 19, ["param1"] = 63, ["z"] = 10, ["name"] = "rainbow:render_white"}, {["x"] = 3, ["meta"] = {["fields"] = {}, ["inventory"] = {}}, ["y"] = 20, ["param1"] = 47, ["z"] = 2, ["name"] = "rainbow:render_white"}, {["x"] = 3, ["meta"] = {["fields"] = {}, ["inventory"] = {}}, ["y"] = 20, ["z"] = 4, ["name"] = "rainbow:render_black"}, {["x"] = 3, ["meta"] = {["fields"] = {}, ["inventory"] = {}}, ["y"] = 20, ["z"] = 5, ["name"] = "rainbow:render_black"}, {["x"] = 3, ["meta"] = {["fields"] = {}, ["inventory"] = {}}, ["y"] = 20, ["z"] = 6, ["name"] = "rainbow:render_black"}, {["x"] = 3, ["meta"] = {["fields"] = {}, ["inventory"] = {}}, ["y"] = 20, ["z"] = 7, ["name"] = "rainbow:render_black"}, {["x"] = 3, ["meta"] = {["fields"] = {}, ["inventory"] = {}}, ["y"] = 20, ["z"] = 8, ["name"] = "rainbow:render_black"}, {["x"] = 3, ["meta"] = {["fields"] = {}, ["inventory"] = {}}, ["y"] = 20, ["z"] = 9, ["name"] = "rainbow:render_white"}, {["x"] = 3, ["meta"] = {["fields"] = {}, ["inventory"] = {}}, ["y"] = 20, ["param1"] = 47, ["z"] = 10, ["name"] = "rainbow:render_white"}, {["x"] = 3, ["meta"] = {["fields"] = {}, ["inventory"] = {}}, ["param2"] = 1, ["y"] = 21, ["param1"] = 142, ["z"] = 2, ["name"] = "rainbow:slope_render_white_outer"}, {["x"] = 3, ["meta"] = {["fields"] = {}, ["inventory"] = {}}, ["y"] = 21, ["z"] = 3, ["name"] = "rainbow:render_white"}, {["x"] = 3, ["meta"] = {["fields"] = {}, ["inventory"] = {}}, ["y"] = 21, ["param1"] = 159, ["z"] = 9, ["name"] = "rainbow:render_white"}, {["x"] = 3, ["meta"] = {["fields"] = {}, ["inventory"] = {}}, ["param2"] = 2, ["y"] = 21, ["param1"] = 14, ["z"] = 10, ["name"] = "rainbow:slope_render_white_outer"}, {["x"] = 3, ["meta"] = {["fields"] = {}, ["inventory"] = {}}, ["y"] = 22, ["z"] = 3, ["name"] = "rainbow:render_red"}, {["x"] = 3, ["meta"] = {["fields"] = {}, ["inventory"] = {}}, ["param2"] = 12, ["y"] = 22, ["param1"] = 141, ["z"] = 5, ["name"] = "rainbow:slab_coolglass_red_1"}, {["x"] = 3, ["meta"] = {["fields"] = {}, ["inventory"] = {}}, ["param2"] = 12, ["y"] = 22, ["param1"] = 125, ["z"] = 6, ["name"] = "rainbow:slab_coolglass_red_1"}, {["x"] = 3, ["meta"] = {["fields"] = {}, ["inventory"] = {}}, ["param2"] = 12, ["y"] = 22, ["param1"] = 109, ["z"] = 7, ["name"] = "rainbow:slab_coolglass_red_1"}, {["x"] = 3, ["meta"] = {["fields"] = {}, ["inventory"] = {}}, ["y"] = 22, ["z"] = 9, ["name"] = "rainbow:render_red"}, {["x"] = 3, ["meta"] = {["fields"] = {}, ["inventory"] = {}}, ["y"] = 23, ["z"] = 3, ["name"] = "rainbow:render_red"}, {["x"] = 3, ["meta"] = {["fields"] = {}, ["inventory"] = {}}, ["param2"] = 12, ["y"] = 23, ["param1"] = 157, ["z"] = 5, ["name"] = "rainbow:slab_coolglass_red_1"}, {["x"] = 3, ["meta"] = {["fields"] = {}, ["inventory"] = {}}, ["param2"] = 12, ["y"] = 23, ["param1"] = 141, ["z"] = 6, ["name"] = "rainbow:slab_coolglass_red_1"}, {["x"] = 3, ["meta"] = {["fields"] = {}, ["inventory"] = {}}, ["param2"] = 12, ["y"] = 23, ["param1"] = 125, ["z"] = 7, ["name"] = "rainbow:slab_coolglass_red_1"}, {["x"] = 3, ["meta"] = {["fields"] = {}, ["inventory"] = {}}, ["y"] = 23, ["z"] = 9, ["name"] = "rainbow:render_red"}, {["x"] = 3, ["meta"] = {["fields"] = {}, ["inventory"] = {}}, ["y"] = 24, ["z"] = 3, ["name"] = "rainbow:render_red"}, {["x"] = 3, ["meta"] = {["fields"] = {}, ["inventory"] = {}}, ["param2"] = 12, ["y"] = 24, ["param1"] = 141, ["z"] = 5, ["name"] = "rainbow:slab_coolglass_red_1"}, {["x"] = 3, ["meta"] = {["fields"] = {}, ["inventory"] = {}}, ["param2"] = 12, ["y"] = 24, ["param1"] = 125, ["z"] = 6, ["name"] = "rainbow:slab_coolglass_red_1"}, {["x"] = 3, ["meta"] = {["fields"] = {}, ["inventory"] = {}}, ["param2"] = 12, ["y"] = 24, ["param1"] = 109, ["z"] = 7, ["name"] = "rainbow:slab_coolglass_red_1"}, {["x"] = 3, ["meta"] = {["fields"] = {}, ["inventory"] = {}}, ["y"] = 24, ["z"] = 9, ["name"] = "rainbow:render_red"}, {["x"] = 3, ["meta"] = {["fields"] = {}, ["inventory"] = {}}, ["y"] = 25, ["param1"] = 95, ["z"] = 3, ["name"] = "rainbow:render_white"}, {["x"] = 3, ["meta"] = {["fields"] = {}, ["inventory"] = {}}, ["param2"] = 3, ["y"] = 25, ["param1"] = 139, ["z"] = 4, ["name"] = "rainbow:slab_render_cyan_1"}, {["x"] = 3, ["meta"] = {["fields"] = {}, ["inventory"] = {}}, ["param2"] = 3, ["y"] = 25, ["param1"] = 124, ["z"] = 5, ["name"] = "rainbow:slab_render_cyan_1"}, {["x"] = 3, ["meta"] = {["fields"] = {}, ["inventory"] = {}}, ["param2"] = 3, ["y"] = 25, ["param1"] = 108, ["z"] = 6, ["name"] = "rainbow:slab_render_cyan_1"}, {["x"] = 3, ["meta"] = {["fields"] = {}, ["inventory"] = {}}, ["param2"] = 3, ["y"] = 25, ["param1"] = 92, ["z"] = 7, ["name"] = "rainbow:slab_render_cyan_1"}, {["x"] = 3, ["meta"] = {["fields"] = {}, ["inventory"] = {}}, ["param2"] = 3, ["y"] = 25, ["param1"] = 75, ["z"] = 8, ["name"] = "rainbow:slab_render_cyan_1"}, {["x"] = 3, ["meta"] = {["fields"] = {}, ["inventory"] = {}}, ["y"] = 25, ["param1"] = 95, ["z"] = 9, ["name"] = "rainbow:render_white"}, {["x"] = 3, ["meta"] = {["fields"] = {}, ["inventory"] = {}}, ["y"] = 26, ["param1"] = 79, ["z"] = 3, ["name"] = "rainbow:render_white"}, {["x"] = 3, ["meta"] = {["fields"] = {}, ["inventory"] = {}}, ["y"] = 26, ["param1"] = 79, ["z"] = 9, ["name"] = "rainbow:render_white"}, {["x"] = 3, ["meta"] = {["fields"] = {}, ["inventory"] = {}}, ["y"] = 27, ["z"] = 3, ["name"] = "rainbow:render_cyan"}, {["x"] = 3, ["meta"] = {["fields"] = {}, ["inventory"] = {}}, ["param2"] = 12, ["y"] = 27, ["param1"] = 141, ["z"] = 5, ["name"] = "rainbow:slab_coolglass_cyan_1"}, {["x"] = 3, ["meta"] = {["fields"] = {}, ["inventory"] = {}}, ["param2"] = 12, ["y"] = 27, ["param1"] = 125, ["z"] = 6, ["name"] = "rainbow:slab_coolglass_cyan_1"}, {["x"] = 3, ["meta"] = {["fields"] = {}, ["inventory"] = {}}, ["param2"] = 12, ["y"] = 27, ["param1"] = 109, ["z"] = 7, ["name"] = "rainbow:slab_coolglass_cyan_1"}, {["x"] = 3, ["meta"] = {["fields"] = {}, ["inventory"] = {}}, ["y"] = 27, ["z"] = 9, ["name"] = "rainbow:render_cyan"}, {["x"] = 3, ["meta"] = {["fields"] = {}, ["inventory"] = {}}, ["y"] = 28, ["z"] = 3, ["name"] = "rainbow:render_cyan"}, {["x"] = 3, ["meta"] = {["fields"] = {}, ["inventory"] = {}}, ["param2"] = 12, ["y"] = 28, ["param1"] = 157, ["z"] = 5, ["name"] = "rainbow:slab_coolglass_cyan_1"}, {["x"] = 3, ["meta"] = {["fields"] = {}, ["inventory"] = {}}, ["param2"] = 12, ["y"] = 28, ["param1"] = 141, ["z"] = 6, ["name"] = "rainbow:slab_coolglass_cyan_1"}, {["x"] = 3, ["meta"] = {["fields"] = {}, ["inventory"] = {}}, ["param2"] = 12, ["y"] = 28, ["param1"] = 125, ["z"] = 7, ["name"] = "rainbow:slab_coolglass_cyan_1"}, {["x"] = 3, ["meta"] = {["fields"] = {}, ["inventory"] = {}}, ["y"] = 28, ["z"] = 9, ["name"] = "rainbow:render_cyan"}, {["x"] = 3, ["meta"] = {["fields"] = {}, ["inventory"] = {}}, ["y"] = 29, ["z"] = 3, ["name"] = "rainbow:render_cyan"}, {["x"] = 3, ["meta"] = {["fields"] = {}, ["inventory"] = {}}, ["param2"] = 12, ["y"] = 29, ["param1"] = 141, ["z"] = 5, ["name"] = "rainbow:slab_coolglass_cyan_1"}, {["x"] = 3, ["meta"] = {["fields"] = {}, ["inventory"] = {}}, ["param2"] = 12, ["y"] = 29, ["param1"] = 125, ["z"] = 6, ["name"] = "rainbow:slab_coolglass_cyan_1"}, {["x"] = 3, ["meta"] = {["fields"] = {}, ["inventory"] = {}}, ["param2"] = 12, ["y"] = 29, ["param1"] = 109, ["z"] = 7, ["name"] = "rainbow:slab_coolglass_cyan_1"}, {["x"] = 3, ["meta"] = {["fields"] = {}, ["inventory"] = {}}, ["y"] = 29, ["z"] = 9, ["name"] = "rainbow:render_cyan"}, {["x"] = 3, ["meta"] = {["fields"] = {}, ["inventory"] = {}}, ["y"] = 30, ["param1"] = 95, ["z"] = 3, ["name"] = "rainbow:render_white"}, {["x"] = 3, ["meta"] = {["fields"] = {}, ["inventory"] = {}}, ["param2"] = 3, ["y"] = 30, ["param1"] = 139, ["z"] = 4, ["name"] = "rainbow:slab_render_yellow_1"}, {["x"] = 3, ["meta"] = {["fields"] = {}, ["inventory"] = {}}, ["param2"] = 3, ["y"] = 30, ["param1"] = 124, ["z"] = 5, ["name"] = "rainbow:slab_render_yellow_1"}, {["x"] = 3, ["meta"] = {["fields"] = {}, ["inventory"] = {}}, ["param2"] = 3, ["y"] = 30, ["param1"] = 108, ["z"] = 6, ["name"] = "rainbow:slab_render_yellow_1"}, {["x"] = 3, ["meta"] = {["fields"] = {}, ["inventory"] = {}}, ["param2"] = 3, ["y"] = 30, ["param1"] = 92, ["z"] = 7, ["name"] = "rainbow:slab_render_yellow_1"}, {["x"] = 3, ["meta"] = {["fields"] = {}, ["inventory"] = {}}, ["param2"] = 3, ["y"] = 30, ["param1"] = 75, ["z"] = 8, ["name"] = "rainbow:slab_render_yellow_1"}, {["x"] = 3, ["meta"] = {["fields"] = {}, ["inventory"] = {}}, ["y"] = 30, ["param1"] = 95, ["z"] = 9, ["name"] = "rainbow:render_white"}, {["x"] = 3, ["meta"] = {["fields"] = {}, ["inventory"] = {}}, ["y"] = 31, ["param1"] = 79, ["z"] = 3, ["name"] = "rainbow:render_white"}, {["x"] = 3, ["meta"] = {["fields"] = {}, ["inventory"] = {}}, ["y"] = 31, ["param1"] = 79, ["z"] = 9, ["name"] = "rainbow:render_white"}, {["x"] = 3, ["meta"] = {["fields"] = {}, ["inventory"] = {}}, ["y"] = 32, ["z"] = 3, ["name"] = "rainbow:render_yellow"}, {["x"] = 3, ["meta"] = {["fields"] = {}, ["inventory"] = {}}, ["param2"] = 12, ["y"] = 32, ["param1"] = 141, ["z"] = 5, ["name"] = "rainbow:slab_coolglass_yellow_1"}, {["x"] = 3, ["meta"] = {["fields"] = {}, ["inventory"] = {}}, ["param2"] = 12, ["y"] = 32, ["param1"] = 125, ["z"] = 6, ["name"] = "rainbow:slab_coolglass_yellow_1"}, {["x"] = 3, ["meta"] = {["fields"] = {}, ["inventory"] = {}}, ["param2"] = 12, ["y"] = 32, ["param1"] = 109, ["z"] = 7, ["name"] = "rainbow:slab_coolglass_yellow_1"}, {["x"] = 3, ["meta"] = {["fields"] = {}, ["inventory"] = {}}, ["y"] = 32, ["z"] = 9, ["name"] = "rainbow:render_yellow"}, {["x"] = 3, ["meta"] = {["fields"] = {}, ["inventory"] = {}}, ["y"] = 33, ["z"] = 3, ["name"] = "rainbow:render_yellow"}, {["x"] = 3, ["meta"] = {["fields"] = {}, ["inventory"] = {}}, ["param2"] = 12, ["y"] = 33, ["param1"] = 157, ["z"] = 5, ["name"] = "rainbow:slab_coolglass_yellow_1"}, {["x"] = 3, ["meta"] = {["fields"] = {}, ["inventory"] = {}}, ["param2"] = 12, ["y"] = 33, ["param1"] = 141, ["z"] = 6, ["name"] = "rainbow:slab_coolglass_yellow_1"}, {["x"] = 3, ["meta"] = {["fields"] = {}, ["inventory"] = {}}, ["param2"] = 12, ["y"] = 33, ["param1"] = 125, ["z"] = 7, ["name"] = "rainbow:slab_coolglass_yellow_1"}, {["x"] = 3, ["meta"] = {["fields"] = {}, ["inventory"] = {}}, ["y"] = 33, ["z"] = 9, ["name"] = "rainbow:render_yellow"}, {["x"] = 3, ["meta"] = {["fields"] = {}, ["inventory"] = {}}, ["y"] = 34, ["z"] = 3, ["name"] = "rainbow:render_yellow"}, {["x"] = 3, ["meta"] = {["fields"] = {}, ["inventory"] = {}}, ["param2"] = 12, ["y"] = 34, ["param1"] = 141, ["z"] = 5, ["name"] = "rainbow:slab_coolglass_yellow_1"}, {["x"] = 3, ["meta"] = {["fields"] = {}, ["inventory"] = {}}, ["param2"] = 12, ["y"] = 34, ["param1"] = 125, ["z"] = 6, ["name"] = "rainbow:slab_coolglass_yellow_1"}, {["x"] = 3, ["meta"] = {["fields"] = {}, ["inventory"] = {}}, ["param2"] = 12, ["y"] = 34, ["param1"] = 109, ["z"] = 7, ["name"] = "rainbow:slab_coolglass_yellow_1"}, {["x"] = 3, ["meta"] = {["fields"] = {}, ["inventory"] = {}}, ["y"] = 34, ["z"] = 9, ["name"] = "rainbow:render_yellow"}, {["x"] = 3, ["meta"] = {["fields"] = {}, ["inventory"] = {}}, ["y"] = 35, ["param1"] = 95, ["z"] = 3, ["name"] = "rainbow:render_white"}, {["x"] = 3, ["meta"] = {["fields"] = {}, ["inventory"] = {}}, ["param2"] = 3, ["y"] = 35, ["param1"] = 139, ["z"] = 4, ["name"] = "rainbow:slab_render_orange_1"}, {["x"] = 3, ["meta"] = {["fields"] = {}, ["inventory"] = {}}, ["param2"] = 3, ["y"] = 35, ["param1"] = 124, ["z"] = 5, ["name"] = "rainbow:slab_render_orange_1"}, {["x"] = 3, ["meta"] = {["fields"] = {}, ["inventory"] = {}}, ["param2"] = 3, ["y"] = 35, ["param1"] = 108, ["z"] = 6, ["name"] = "rainbow:slab_render_orange_1"}, {["x"] = 3, ["meta"] = {["fields"] = {}, ["inventory"] = {}}, ["param2"] = 3, ["y"] = 35, ["param1"] = 92, ["z"] = 7, ["name"] = "rainbow:slab_render_orange_1"}, {["x"] = 3, ["meta"] = {["fields"] = {}, ["inventory"] = {}}, ["param2"] = 3, ["y"] = 35, ["param1"] = 75, ["z"] = 8, ["name"] = "rainbow:slab_render_orange_1"}, {["x"] = 3, ["meta"] = {["fields"] = {}, ["inventory"] = {}}, ["y"] = 35, ["param1"] = 95, ["z"] = 9, ["name"] = "rainbow:render_white"}, {["x"] = 3, ["meta"] = {["fields"] = {}, ["inventory"] = {}}, ["y"] = 36, ["param1"] = 79, ["z"] = 3, ["name"] = "rainbow:render_white"}, {["x"] = 3, ["meta"] = {["fields"] = {}, ["inventory"] = {}}, ["y"] = 36, ["param1"] = 79, ["z"] = 9, ["name"] = "rainbow:render_white"}, {["x"] = 3, ["meta"] = {["fields"] = {}, ["inventory"] = {}}, ["y"] = 37, ["z"] = 3, ["name"] = "rainbow:render_orange"}, {["x"] = 3, ["meta"] = {["fields"] = {}, ["inventory"] = {}}, ["param2"] = 12, ["y"] = 37, ["param1"] = 141, ["z"] = 5, ["name"] = "rainbow:slab_coolglass_orange_1"}, {["x"] = 3, ["meta"] = {["fields"] = {}, ["inventory"] = {}}, ["param2"] = 12, ["y"] = 37, ["param1"] = 125, ["z"] = 6, ["name"] = "rainbow:slab_coolglass_orange_1"}, {["x"] = 3, ["meta"] = {["fields"] = {}, ["inventory"] = {}}, ["param2"] = 12, ["y"] = 37, ["param1"] = 109, ["z"] = 7, ["name"] = "rainbow:slab_coolglass_orange_1"}, {["x"] = 3, ["meta"] = {["fields"] = {}, ["inventory"] = {}}, ["y"] = 37, ["z"] = 9, ["name"] = "rainbow:render_orange"}, {["x"] = 3, ["meta"] = {["fields"] = {}, ["inventory"] = {}}, ["y"] = 38, ["z"] = 3, ["name"] = "rainbow:render_orange"}, {["x"] = 3, ["meta"] = {["fields"] = {}, ["inventory"] = {}}, ["param2"] = 12, ["y"] = 38, ["param1"] = 157, ["z"] = 5, ["name"] = "rainbow:slab_coolglass_orange_1"}, {["x"] = 3, ["meta"] = {["fields"] = {}, ["inventory"] = {}}, ["param2"] = 12, ["y"] = 38, ["param1"] = 141, ["z"] = 6, ["name"] = "rainbow:slab_coolglass_orange_1"}, {["x"] = 3, ["meta"] = {["fields"] = {}, ["inventory"] = {}}, ["param2"] = 12, ["y"] = 38, ["param1"] = 125, ["z"] = 7, ["name"] = "rainbow:slab_coolglass_orange_1"}, {["x"] = 3, ["meta"] = {["fields"] = {}, ["inventory"] = {}}, ["y"] = 38, ["z"] = 9, ["name"] = "rainbow:render_orange"}, {["x"] = 3, ["meta"] = {["fields"] = {}, ["inventory"] = {}}, ["y"] = 39, ["z"] = 3, ["name"] = "rainbow:render_orange"}, {["x"] = 3, ["meta"] = {["fields"] = {}, ["inventory"] = {}}, ["param2"] = 12, ["y"] = 39, ["param1"] = 141, ["z"] = 5, ["name"] = "rainbow:slab_coolglass_orange_1"}, {["x"] = 3, ["meta"] = {["fields"] = {}, ["inventory"] = {}}, ["param2"] = 12, ["y"] = 39, ["param1"] = 125, ["z"] = 6, ["name"] = "rainbow:slab_coolglass_orange_1"}, {["x"] = 3, ["meta"] = {["fields"] = {}, ["inventory"] = {}}, ["param2"] = 12, ["y"] = 39, ["param1"] = 109, ["z"] = 7, ["name"] = "rainbow:slab_coolglass_orange_1"}, {["x"] = 3, ["meta"] = {["fields"] = {}, ["inventory"] = {}}, ["y"] = 39, ["z"] = 9, ["name"] = "rainbow:render_orange"}, {["x"] = 3, ["meta"] = {["fields"] = {}, ["inventory"] = {}}, ["y"] = 40, ["param1"] = 95, ["z"] = 3, ["name"] = "rainbow:render_white"}, {["x"] = 3, ["meta"] = {["fields"] = {}, ["inventory"] = {}}, ["param2"] = 3, ["y"] = 40, ["param1"] = 142, ["z"] = 4, ["name"] = "rainbow:slab_render_red_1"}, {["x"] = 3, ["meta"] = {["fields"] = {}, ["inventory"] = {}}, ["param2"] = 3, ["y"] = 40, ["param1"] = 125, ["z"] = 5, ["name"] = "rainbow:slab_render_red_1"}, {["x"] = 3, ["meta"] = {["fields"] = {}, ["inventory"] = {}}, ["param2"] = 3, ["y"] = 40, ["param1"] = 108, ["z"] = 6, ["name"] = "rainbow:slab_render_red_1"}, {["x"] = 3, ["meta"] = {["fields"] = {}, ["inventory"] = {}}, ["param2"] = 3, ["y"] = 40, ["param1"] = 93, ["z"] = 7, ["name"] = "rainbow:slab_render_red_1"}, {["x"] = 3, ["meta"] = {["fields"] = {}, ["inventory"] = {}}, ["param2"] = 3, ["y"] = 40, ["param1"] = 78, ["z"] = 8, ["name"] = "rainbow:slab_render_red_1"}, {["x"] = 3, ["meta"] = {["fields"] = {}, ["inventory"] = {}}, ["y"] = 40, ["param1"] = 95, ["z"] = 9, ["name"] = "rainbow:render_white"}, {["x"] = 3, ["meta"] = {["fields"] = {}, ["inventory"] = {}}, ["y"] = 41, ["param1"] = 79, ["z"] = 3, ["name"] = "rainbow:render_white"}, {["x"] = 3, ["meta"] = {["fields"] = {}, ["inventory"] = {}}, ["y"] = 41, ["param1"] = 79, ["z"] = 9, ["name"] = "rainbow:render_white"}, {["x"] = 3, ["meta"] = {["fields"] = {}, ["inventory"] = {}}, ["y"] = 42, ["param1"] = 175, ["z"] = 5, ["name"] = "rainbow:render_white"}, {["x"] = 3, ["meta"] = {["fields"] = {}, ["inventory"] = {}}, ["y"] = 42, ["param1"] = 191, ["z"] = 6, ["name"] = "rainbow:render_white"}, {["x"] = 3, ["meta"] = {["fields"] = {}, ["inventory"] = {}}, ["y"] = 42, ["param1"] = 175, ["z"] = 7, ["name"] = "rainbow:render_white"}, {["x"] = 3, ["meta"] = {["fields"] = {}, ["inventory"] = {}}, ["y"] = 43, ["param1"] = 159, ["z"] = 5, ["name"] = "rainbow:render_white"}, {["x"] = 3, ["meta"] = {["fields"] = {}, ["inventory"] = {}}, ["y"] = 43, ["param1"] = 175, ["z"] = 6, ["name"] = "rainbow:render_white"}, {["x"] = 3, ["meta"] = {["fields"] = {}, ["inventory"] = {}}, ["y"] = 43, ["param1"] = 159, ["z"] = 7, ["name"] = "rainbow:render_white"}, {["x"] = 3, ["meta"] = {["fields"] = {}, ["inventory"] = {}}, ["y"] = 44, ["param1"] = 143, ["z"] = 5, ["name"] = "rainbow:render_white"}, {["x"] = 3, ["meta"] = {["fields"] = {}, ["inventory"] = {}}, ["y"] = 44, ["param1"] = 159, ["z"] = 6, ["name"] = "rainbow:render_white"}, {["x"] = 3, ["meta"] = {["fields"] = {}, ["inventory"] = {}}, ["y"] = 44, ["param1"] = 143, ["z"] = 7, ["name"] = "rainbow:render_white"}, {["x"] = 3, ["meta"] = {["fields"] = {}, ["inventory"] = {}}, ["y"] = 45, ["param1"] = 127, ["z"] = 5, ["name"] = "rainbow:render_white"}, {["x"] = 3, ["meta"] = {["fields"] = {}, ["inventory"] = {}}, ["y"] = 45, ["param1"] = 143, ["z"] = 6, ["name"] = "rainbow:render_white"}, {["x"] = 3, ["meta"] = {["fields"] = {}, ["inventory"] = {}}, ["y"] = 45, ["param1"] = 127, ["z"] = 7, ["name"] = "rainbow:render_white"}, {["x"] = 3, ["meta"] = {["fields"] = {}, ["inventory"] = {}}, ["y"] = 46, ["param1"] = 111, ["z"] = 5, ["name"] = "rainbow:render_white"}, {["x"] = 3, ["meta"] = {["fields"] = {}, ["inventory"] = {}}, ["y"] = 46, ["param1"] = 127, ["z"] = 6, ["name"] = "rainbow:render_white"}, {["x"] = 3, ["meta"] = {["fields"] = {}, ["inventory"] = {}}, ["y"] = 46, ["param1"] = 111, ["z"] = 7, ["name"] = "rainbow:render_white"}, {["x"] = 3, ["meta"] = {["fields"] = {}, ["inventory"] = {}}, ["y"] = 47, ["param1"] = 95, ["z"] = 5, ["name"] = "rainbow:render_white"}, {["x"] = 3, ["meta"] = {["fields"] = {}, ["inventory"] = {}}, ["y"] = 47, ["param1"] = 111, ["z"] = 6, ["name"] = "rainbow:render_white"}, {["x"] = 3, ["meta"] = {["fields"] = {}, ["inventory"] = {}}, ["y"] = 47, ["param1"] = 95, ["z"] = 7, ["name"] = "rainbow:render_white"}, {["x"] = 3, ["meta"] = {["fields"] = {}, ["inventory"] = {}}, ["y"] = 48, ["param1"] = 79, ["z"] = 5, ["name"] = "rainbow:render_white"}, {["x"] = 3, ["meta"] = {["fields"] = {}, ["inventory"] = {}}, ["y"] = 48, ["param1"] = 95, ["z"] = 6, ["name"] = "rainbow:render_white"}, {["x"] = 3, ["meta"] = {["fields"] = {}, ["inventory"] = {}}, ["y"] = 48, ["param1"] = 79, ["z"] = 7, ["name"] = "rainbow:render_white"}, {["x"] = 3, ["meta"] = {["fields"] = {}, ["inventory"] = {}}, ["y"] = 49, ["param1"] = 63, ["z"] = 5, ["name"] = "rainbow:render_white"}, {["x"] = 3, ["meta"] = {["fields"] = {}, ["inventory"] = {}}, ["y"] = 49, ["param1"] = 79, ["z"] = 6, ["name"] = "rainbow:render_white"}, {["x"] = 3, ["meta"] = {["fields"] = {}, ["inventory"] = {}}, ["y"] = 49, ["param1"] = 63, ["z"] = 7, ["name"] = "rainbow:render_white"}, {["x"] = 3, ["meta"] = {["fields"] = {}, ["inventory"] = {}}, ["y"] = 50, ["param1"] = 47, ["z"] = 5, ["name"] = "rainbow:render_white"}, {["x"] = 3, ["meta"] = {["fields"] = {}, ["inventory"] = {}}, ["y"] = 50, ["param1"] = 63, ["z"] = 6, ["name"] = "rainbow:render_white"}, {["x"] = 3, ["meta"] = {["fields"] = {}, ["inventory"] = {}}, ["y"] = 50, ["param1"] = 47, ["z"] = 7, ["name"] = "rainbow:render_white"}, {["x"] = 3, ["meta"] = {["fields"] = {}, ["inventory"] = {}}, ["y"] = 51, ["param1"] = 31, ["z"] = 5, ["name"] = "rainbow:render_white"}, {["x"] = 3, ["meta"] = {["fields"] = {}, ["inventory"] = {}}, ["y"] = 51, ["param1"] = 47, ["z"] = 6, ["name"] = "rainbow:render_white"}, {["x"] = 3, ["meta"] = {["fields"] = {}, ["inventory"] = {}}, ["y"] = 51, ["param1"] = 31, ["z"] = 7, ["name"] = "rainbow:render_white"}, {["x"] = 3, ["meta"] = {["fields"] = {}, ["inventory"] = {}}, ["y"] = 52, ["param1"] = 15, ["z"] = 5, ["name"] = "rainbow:render_white"}, {["x"] = 3, ["meta"] = {["fields"] = {}, ["inventory"] = {}}, ["y"] = 52, ["param1"] = 31, ["z"] = 6, ["name"] = "rainbow:render_white"}, {["x"] = 3, ["meta"] = {["fields"] = {}, ["inventory"] = {}}, ["y"] = 52, ["param1"] = 15, ["z"] = 7, ["name"] = "rainbow:render_white"}, {["x"] = 3, ["meta"] = {["fields"] = {}, ["inventory"] = {}}, ["y"] = 53, ["param1"] = 15, ["z"] = 5, ["name"] = "rainbow:render_white"}, {["x"] = 3, ["meta"] = {["fields"] = {}, ["inventory"] = {}}, ["y"] = 53, ["param1"] = 15, ["z"] = 6, ["name"] = "rainbow:render_white"}, {["x"] = 3, ["meta"] = {["fields"] = {}, ["inventory"] = {}}, ["y"] = 53, ["param1"] = 15, ["z"] = 7, ["name"] = "rainbow:render_white"}, {["x"] = 3, ["meta"] = {["fields"] = {}, ["inventory"] = {}}, ["y"] = 54, ["param1"] = 15, ["z"] = 5, ["name"] = "rainbow:render_white"}, {["x"] = 3, ["meta"] = {["fields"] = {}, ["inventory"] = {}}, ["y"] = 54, ["param1"] = 15, ["z"] = 6, ["name"] = "rainbow:render_white"}, {["x"] = 3, ["meta"] = {["fields"] = {}, ["inventory"] = {}}, ["y"] = 54, ["param1"] = 15, ["z"] = 7, ["name"] = "rainbow:render_white"}, {["x"] = 3, ["meta"] = {["fields"] = {}, ["inventory"] = {}}, ["y"] = 55, ["param1"] = 15, ["z"] = 5, ["name"] = "rainbow:render_white"}, {["x"] = 3, ["meta"] = {["fields"] = {}, ["inventory"] = {}}, ["y"] = 55, ["param1"] = 15, ["z"] = 6, ["name"] = "rainbow:render_white"}, {["x"] = 3, ["meta"] = {["fields"] = {}, ["inventory"] = {}}, ["y"] = 55, ["param1"] = 15, ["z"] = 7, ["name"] = "rainbow:render_white"}, {["x"] = 3, ["meta"] = {["fields"] = {}, ["inventory"] = {}}, ["y"] = 56, ["param1"] = 15, ["z"] = 5, ["name"] = "rainbow:render_white"}, {["x"] = 3, ["meta"] = {["fields"] = {}, ["inventory"] = {}}, ["y"] = 56, ["param1"] = 15, ["z"] = 6, ["name"] = "rainbow:render_white"}, {["x"] = 3, ["meta"] = {["fields"] = {}, ["inventory"] = {}}, ["y"] = 56, ["param1"] = 15, ["z"] = 7, ["name"] = "rainbow:render_white"}, {["x"] = 3, ["meta"] = {["fields"] = {}, ["inventory"] = {}}, ["y"] = 57, ["param1"] = 15, ["z"] = 5, ["name"] = "rainbow:render_white"}, {["x"] = 3, ["meta"] = {["fields"] = {}, ["inventory"] = {}}, ["y"] = 57, ["param1"] = 15, ["z"] = 6, ["name"] = "rainbow:render_white"}, {["x"] = 3, ["meta"] = {["fields"] = {}, ["inventory"] = {}}, ["y"] = 57, ["param1"] = 15, ["z"] = 7, ["name"] = "rainbow:render_white"}, {["x"] = 3, ["meta"] = {["fields"] = {}, ["inventory"] = {}}, ["y"] = 58, ["param1"] = 15, ["z"] = 5, ["name"] = "rainbow:render_white"}, {["x"] = 3, ["meta"] = {["fields"] = {}, ["inventory"] = {}}, ["y"] = 58, ["param1"] = 15, ["z"] = 6, ["name"] = "rainbow:render_white"}, {["x"] = 3, ["meta"] = {["fields"] = {}, ["inventory"] = {}}, ["y"] = 58, ["param1"] = 15, ["z"] = 7, ["name"] = "rainbow:render_white"}, {["x"] = 3, ["meta"] = {["fields"] = {}, ["inventory"] = {}}, ["y"] = 59, ["param1"] = 15, ["z"] = 5, ["name"] = "rainbow:render_white"}, {["x"] = 3, ["meta"] = {["fields"] = {}, ["inventory"] = {}}, ["y"] = 59, ["param1"] = 15, ["z"] = 6, ["name"] = "rainbow:render_white"}, {["x"] = 3, ["meta"] = {["fields"] = {}, ["inventory"] = {}}, ["y"] = 59, ["param1"] = 15, ["z"] = 7, ["name"] = "rainbow:render_white"}, {["x"] = 3, ["meta"] = {["fields"] = {}, ["inventory"] = {}}, ["param2"] = 1, ["y"] = 60, ["param1"] = 126, ["z"] = 5, ["name"] = "rainbow:slope_render_white_outer"}, {["x"] = 3, ["meta"] = {["fields"] = {}, ["inventory"] = {}}, ["param2"] = 1, ["y"] = 60, ["param1"] = 142, ["z"] = 6, ["name"] = "rainbow:slope_render_white"}, {["x"] = 3, ["meta"] = {["fields"] = {}, ["inventory"] = {}}, ["param2"] = 2, ["y"] = 60, ["param1"] = 126, ["z"] = 7, ["name"] = "rainbow:slope_render_white_outer"}, {["x"] = 4, ["meta"] = {["fields"] = {}, ["inventory"] = {}}, ["y"] = 0, ["param1"] = 15, ["z"] = 0, ["name"] = "rainbow:binary_white"}, {["x"] = 4, ["meta"] = {["fields"] = {}, ["inventory"] = {}}, ["y"] = 0, ["param1"] = 15, ["z"] = 1, ["name"] = "rainbow:binary_white"}, {["x"] = 4, ["meta"] = {["fields"] = {}, ["inventory"] = {}}, ["y"] = 0, ["param1"] = 15, ["z"] = 2, ["name"] = "rainbow:binary_white"}, {["x"] = 4, ["meta"] = {["fields"] = {}, ["inventory"] = {}}, ["y"] = 0, ["param1"] = 15, ["z"] = 3, ["name"] = "rainbow:binary_white"}, {["x"] = 4, ["meta"] = {["fields"] = {}, ["inventory"] = {}}, ["y"] = 0, ["param1"] = 15, ["z"] = 4, ["name"] = "rainbow:binary_white"}, {["x"] = 4, ["meta"] = {["fields"] = {}, ["inventory"] = {}}, ["y"] = 0, ["param1"] = 15, ["z"] = 5, ["name"] = "rainbow:binary_white"}, {["x"] = 4, ["meta"] = {["fields"] = {}, ["inventory"] = {}}, ["y"] = 0, ["param1"] = 15, ["z"] = 6, ["name"] = "rainbow:binary_white"}, {["x"] = 4, ["meta"] = {["fields"] = {}, ["inventory"] = {}}, ["y"] = 0, ["param1"] = 15, ["z"] = 7, ["name"] = "rainbow:binary_white"}, {["x"] = 4, ["meta"] = {["fields"] = {}, ["inventory"] = {}}, ["y"] = 0, ["param1"] = 15, ["z"] = 8, ["name"] = "rainbow:binary_white"}, {["x"] = 4, ["meta"] = {["fields"] = {}, ["inventory"] = {}}, ["y"] = 0, ["param1"] = 15, ["z"] = 9, ["name"] = "rainbow:binary_white"}, {["x"] = 4, ["meta"] = {["fields"] = {}, ["inventory"] = {}}, ["y"] = 0, ["param1"] = 15, ["z"] = 10, ["name"] = "rainbow:binary_white"}, {["x"] = 4, ["meta"] = {["fields"] = {}, ["inventory"] = {}}, ["y"] = 0, ["param1"] = 14, ["z"] = 11, ["name"] = "rainbow:binary_white"}, {["x"] = 4, ["meta"] = {["fields"] = {}, ["inventory"] = {}}, ["y"] = 0, ["param1"] = 14, ["z"] = 12, ["name"] = "rainbow:binary_white"}, {["x"] = 4, ["meta"] = {["fields"] = {}, ["inventory"] = {}}, ["param2"] = 1, ["y"] = 1, ["param1"] = 222, ["z"] = 0, ["name"] = "rainbow:slope_render_violet_outer"}, {["x"] = 4, ["meta"] = {["fields"] = {}, ["inventory"] = {}}, ["y"] = 1, ["z"] = 1, ["name"] = "rainbow:render_violet"}, {["x"] = 4, ["meta"] = {["fields"] = {}, ["inventory"] = {}}, ["y"] = 1, ["z"] = 11, ["name"] = "rainbow:render_violet"}, {["x"] = 4, ["meta"] = {["fields"] = {}, ["inventory"] = {}}, ["param2"] = 2, ["y"] = 1, ["param1"] = 222, ["z"] = 12, ["name"] = "rainbow:slope_render_violet_outer"}, {["x"] = 4, ["meta"] = {["fields"] = {}, ["inventory"] = {}}, ["y"] = 2, ["z"] = 1, ["name"] = "rainbow:render_violet"}, {["x"] = 4, ["meta"] = {["fields"] = {}, ["inventory"] = {}}, ["param2"] = 21, ["y"] = 2, ["param1"] = 204, ["z"] = 3, ["name"] = "rainbow:slope_render_violet"}, {["x"] = 4, ["meta"] = {["fields"] = {}, ["inventory"] = {}}, ["y"] = 2, ["z"] = 11, ["name"] = "rainbow:render_violet"}, {["x"] = 4, ["meta"] = {["fields"] = {}, ["inventory"] = {}}, ["y"] = 3, ["z"] = 1, ["name"] = "rainbow:render_violet"}, {["x"] = 4, ["meta"] = {["fields"] = {}, ["inventory"] = {}}, ["param2"] = 1, ["y"] = 3, ["param1"] = 187, ["z"] = 3, ["name"] = "rainbow:slope_render_violet"}, {["x"] = 4, ["meta"] = {["fields"] = {}, ["inventory"] = {}}, ["y"] = 3, ["z"] = 11, ["name"] = "rainbow:render_violet"}, {["x"] = 4, ["meta"] = {["fields"] = {}, ["inventory"] = {}}, ["y"] = 4, ["param1"] = 63, ["z"] = 1, ["name"] = "rainbow:render_white"}, {["x"] = 4, ["meta"] = {["fields"] = {}, ["inventory"] = {}}, ["param2"] = 21, ["y"] = 4, ["param1"] = 171, ["z"] = 2, ["name"] = "rainbow:slab_render_white_1"}, {["x"] = 4, ["meta"] = {["fields"] = {}, ["inventory"] = {}}, ["param2"] = 21, ["y"] = 4, ["param1"] = 170, ["z"] = 4, ["name"] = "rainbow:slab_render_white_1"}, {["x"] = 4, ["meta"] = {["fields"] = {}, ["inventory"] = {}}, ["param2"] = 21, ["y"] = 4, ["param1"] = 170, ["z"] = 5, ["name"] = "rainbow:slab_render_white_1"}, {["x"] = 4, ["meta"] = {["fields"] = {}, ["inventory"] = {}}, ["param2"] = 21, ["y"] = 4, ["param1"] = 170, ["z"] = 6, ["name"] = "rainbow:slab_render_white_1"}, {["x"] = 4, ["meta"] = {["fields"] = {}, ["inventory"] = {}}, ["param2"] = 21, ["y"] = 4, ["param1"] = 170, ["z"] = 7, ["name"] = "rainbow:slab_render_white_1"}, {["x"] = 4, ["meta"] = {["fields"] = {}, ["inventory"] = {}}, ["param2"] = 21, ["y"] = 4, ["param1"] = 170, ["z"] = 8, ["name"] = "rainbow:slab_render_white_1"}, {["x"] = 4, ["meta"] = {["fields"] = {}, ["inventory"] = {}}, ["param2"] = 21, ["y"] = 4, ["param1"] = 170, ["z"] = 9, ["name"] = "rainbow:slab_render_white_1"}, {["x"] = 4, ["meta"] = {["fields"] = {}, ["inventory"] = {}}, ["param2"] = 20, ["y"] = 4, ["param1"] = 171, ["z"] = 10, ["name"] = "rainbow:slab_render_white_1"}, {["x"] = 4, ["meta"] = {["fields"] = {}, ["inventory"] = {}}, ["y"] = 4, ["param1"] = 63, ["z"] = 11, ["name"] = "rainbow:render_white"}, {["x"] = 4, ["meta"] = {["fields"] = {}, ["inventory"] = {}}, ["y"] = 5, ["param1"] = 47, ["z"] = 1, ["name"] = "rainbow:render_white"}, {["x"] = 4, ["meta"] = {["fields"] = {}, ["inventory"] = {}}, ["y"] = 5, ["param1"] = 47, ["z"] = 11, ["name"] = "rainbow:render_white"}, {["x"] = 4, ["meta"] = {["fields"] = {}, ["inventory"] = {}}, ["y"] = 6, ["z"] = 1, ["name"] = "rainbow:render_lightgreen"}, {["x"] = 4, ["meta"] = {["fields"] = {}, ["inventory"] = {}}, ["y"] = 6, ["z"] = 11, ["name"] = "rainbow:render_lightgreen"}, {["x"] = 4, ["meta"] = {["fields"] = {}, ["inventory"] = {}}, ["y"] = 7, ["z"] = 1, ["name"] = "rainbow:render_lightgreen"}, {["x"] = 4, ["meta"] = {["fields"] = {}, ["inventory"] = {}}, ["param2"] = 21, ["y"] = 7, ["param1"] = 187, ["z"] = 3, ["name"] = "rainbow:slope_render_lightgreen"}, {["x"] = 4, ["meta"] = {["fields"] = {}, ["inventory"] = {}}, ["y"] = 7, ["z"] = 11, ["name"] = "rainbow:render_lightgreen"}, {["x"] = 4, ["meta"] = {["fields"] = {}, ["inventory"] = {}}, ["y"] = 8, ["z"] = 1, ["name"] = "rainbow:render_lightgreen"}, {["x"] = 4, ["meta"] = {["fields"] = {}, ["inventory"] = {}}, ["param2"] = 1, ["y"] = 8, ["param1"] = 171, ["z"] = 3, ["name"] = "rainbow:slope_render_lightgreen"}, {["x"] = 4, ["meta"] = {["fields"] = {}, ["inventory"] = {}}, ["y"] = 8, ["z"] = 11, ["name"] = "rainbow:render_lightgreen"}, {["x"] = 4, ["meta"] = {["fields"] = {}, ["inventory"] = {}}, ["y"] = 9, ["param1"] = 63, ["z"] = 1, ["name"] = "rainbow:render_white"}, {["x"] = 4, ["meta"] = {["fields"] = {}, ["inventory"] = {}}, ["param2"] = 21, ["y"] = 9, ["param1"] = 171, ["z"] = 2, ["name"] = "rainbow:slab_render_white_1"}, {["x"] = 4, ["meta"] = {["fields"] = {}, ["inventory"] = {}}, ["param2"] = 21, ["y"] = 9, ["param1"] = 137, ["z"] = 4, ["name"] = "rainbow:slab_render_white_1"}, {["x"] = 4, ["meta"] = {["fields"] = {}, ["inventory"] = {}}, ["param2"] = 21, ["y"] = 9, ["param1"] = 122, ["z"] = 5, ["name"] = "rainbow:slab_render_white_1"}, {["x"] = 4, ["meta"] = {["fields"] = {}, ["inventory"] = {}}, ["param2"] = 21, ["y"] = 9, ["param1"] = 106, ["z"] = 6, ["name"] = "rainbow:slab_render_white_1"}, {["x"] = 4, ["meta"] = {["fields"] = {}, ["inventory"] = {}}, ["param2"] = 21, ["y"] = 9, ["param1"] = 90, ["z"] = 7, ["name"] = "rainbow:slab_render_white_1"}, {["x"] = 4, ["meta"] = {["fields"] = {}, ["inventory"] = {}}, ["param2"] = 21, ["y"] = 9, ["param1"] = 89, ["z"] = 8, ["name"] = "rainbow:slab_render_white_1"}, {["x"] = 4, ["meta"] = {["fields"] = {}, ["inventory"] = {}}, ["param2"] = 21, ["y"] = 9, ["param1"] = 90, ["z"] = 9, ["name"] = "rainbow:slab_render_white_1"}, {["x"] = 4, ["meta"] = {["fields"] = {}, ["inventory"] = {}}, ["param2"] = 21, ["y"] = 9, ["param1"] = 91, ["z"] = 10, ["name"] = "rainbow:slab_render_white_1"}, {["x"] = 4, ["meta"] = {["fields"] = {}, ["inventory"] = {}}, ["y"] = 9, ["param1"] = 63, ["z"] = 11, ["name"] = "rainbow:render_white"}, {["x"] = 4, ["meta"] = {["fields"] = {}, ["inventory"] = {}}, ["y"] = 10, ["param1"] = 47, ["z"] = 1, ["name"] = "rainbow:render_white"}, {["x"] = 4, ["meta"] = {["fields"] = {}, ["inventory"] = {}}, ["y"] = 10, ["param1"] = 47, ["z"] = 11, ["name"] = "rainbow:render_white"}, {["x"] = 4, ["meta"] = {["fields"] = {}, ["inventory"] = {}}, ["y"] = 11, ["z"] = 1, ["name"] = "rainbow:render_blue"}, {["x"] = 4, ["meta"] = {["fields"] = {}, ["inventory"] = {}}, ["y"] = 11, ["z"] = 11, ["name"] = "rainbow:render_blue"}, {["x"] = 4, ["meta"] = {["fields"] = {}, ["inventory"] = {}}, ["y"] = 12, ["z"] = 1, ["name"] = "rainbow:render_blue"}, {["x"] = 4, ["meta"] = {["fields"] = {}, ["inventory"] = {}}, ["param2"] = 21, ["y"] = 12, ["param1"] = 187, ["z"] = 3, ["name"] = "rainbow:slope_render_blue"}, {["x"] = 4, ["meta"] = {["fields"] = {}, ["inventory"] = {}}, ["y"] = 12, ["z"] = 11, ["name"] = "rainbow:render_blue"}, {["x"] = 4, ["meta"] = {["fields"] = {}, ["inventory"] = {}}, ["y"] = 13, ["z"] = 1, ["name"] = "rainbow:render_blue"}, {["x"] = 4, ["meta"] = {["fields"] = {}, ["inventory"] = {}}, ["param2"] = 1, ["y"] = 13, ["param1"] = 170, ["z"] = 3, ["name"] = "rainbow:slope_render_blue"}, {["x"] = 4, ["meta"] = {["fields"] = {}, ["inventory"] = {}}, ["y"] = 13, ["z"] = 11, ["name"] = "rainbow:render_blue"}, {["x"] = 4, ["meta"] = {["fields"] = {}, ["inventory"] = {}}, ["y"] = 14, ["param1"] = 63, ["z"] = 1, ["name"] = "rainbow:render_white"}, {["x"] = 4, ["meta"] = {["fields"] = {}, ["inventory"] = {}}, ["param2"] = 21, ["y"] = 14, ["param1"] = 170, ["z"] = 2, ["name"] = "rainbow:slab_render_white_1"}, {["x"] = 4, ["meta"] = {["fields"] = {}, ["inventory"] = {}}, ["param2"] = 21, ["y"] = 14, ["param1"] = 137, ["z"] = 4, ["name"] = "rainbow:slab_render_white_1"}, {["x"] = 4, ["meta"] = {["fields"] = {}, ["inventory"] = {}}, ["param2"] = 21, ["y"] = 14, ["param1"] = 122, ["z"] = 5, ["name"] = "rainbow:slab_render_white_1"}, {["x"] = 4, ["meta"] = {["fields"] = {}, ["inventory"] = {}}, ["param2"] = 21, ["y"] = 14, ["param1"] = 106, ["z"] = 6, ["name"] = "rainbow:slab_render_white_1"}, {["x"] = 4, ["meta"] = {["fields"] = {}, ["inventory"] = {}}, ["param2"] = 21, ["y"] = 14, ["param1"] = 90, ["z"] = 7, ["name"] = "rainbow:slab_render_white_1"}, {["x"] = 4, ["meta"] = {["fields"] = {}, ["inventory"] = {}}, ["param2"] = 21, ["y"] = 14, ["param1"] = 73, ["z"] = 8, ["name"] = "rainbow:slab_render_white_1"}, {["x"] = 4, ["meta"] = {["fields"] = {}, ["inventory"] = {}}, ["param2"] = 21, ["y"] = 14, ["param1"] = 58, ["z"] = 9, ["name"] = "rainbow:slab_render_white_1"}, {["x"] = 4, ["meta"] = {["fields"] = {}, ["inventory"] = {}}, ["param2"] = 20, ["y"] = 14, ["param1"] = 43, ["z"] = 10, ["name"] = "rainbow:slab_render_white_1"}, {["x"] = 4, ["meta"] = {["fields"] = {}, ["inventory"] = {}}, ["y"] = 14, ["param1"] = 63, ["z"] = 11, ["name"] = "rainbow:render_white"}, {["x"] = 4, ["meta"] = {["fields"] = {}, ["inventory"] = {}}, ["y"] = 15, ["param1"] = 47, ["z"] = 1, ["name"] = "rainbow:render_white"}, {["x"] = 4, ["meta"] = {["fields"] = {}, ["inventory"] = {}}, ["y"] = 15, ["param1"] = 47, ["z"] = 11, ["name"] = "rainbow:render_white"}, {["x"] = 4, ["meta"] = {["fields"] = {}, ["inventory"] = {}}, ["y"] = 16, ["z"] = 1, ["name"] = "rainbow:render_black"}, {["x"] = 4, ["meta"] = {["fields"] = {}, ["inventory"] = {}}, ["y"] = 16, ["z"] = 11, ["name"] = "rainbow:render_black"}, {["x"] = 4, ["meta"] = {["fields"] = {}, ["inventory"] = {}}, ["y"] = 17, ["z"] = 1, ["name"] = "rainbow:render_black"}, {["x"] = 4, ["meta"] = {["fields"] = {}, ["inventory"] = {}}, ["param2"] = 21, ["y"] = 17, ["param1"] = 187, ["z"] = 3, ["name"] = "rainbow:slope_render_black"}, {["x"] = 4, ["meta"] = {["fields"] = {}, ["inventory"] = {}}, ["y"] = 17, ["z"] = 11, ["name"] = "rainbow:render_black"}, {["x"] = 4, ["meta"] = {["fields"] = {}, ["inventory"] = {}}, ["y"] = 18, ["z"] = 1, ["name"] = "rainbow:render_black"}, {["x"] = 4, ["meta"] = {["fields"] = {}, ["inventory"] = {}}, ["param2"] = 1, ["y"] = 18, ["param1"] = 171, ["z"] = 3, ["name"] = "rainbow:slope_render_black"}, {["x"] = 4, ["meta"] = {["fields"] = {}, ["inventory"] = {}}, ["y"] = 18, ["z"] = 11, ["name"] = "rainbow:render_black"}, {["x"] = 4, ["meta"] = {["fields"] = {}, ["inventory"] = {}}, ["y"] = 19, ["param1"] = 63, ["z"] = 1, ["name"] = "rainbow:render_white"}, {["x"] = 4, ["meta"] = {["fields"] = {}, ["inventory"] = {}}, ["param2"] = 22, ["y"] = 19, ["param1"] = 171, ["z"] = 2, ["name"] = "rainbow:slab_render_white_1"}, {["x"] = 4, ["meta"] = {["fields"] = {}, ["inventory"] = {}}, ["param2"] = 21, ["y"] = 19, ["param1"] = 137, ["z"] = 4, ["name"] = "rainbow:slab_render_white_1"}, {["x"] = 4, ["meta"] = {["fields"] = {}, ["inventory"] = {}}, ["param2"] = 21, ["y"] = 19, ["param1"] = 122, ["z"] = 5, ["name"] = "rainbow:slab_render_white_1"}, {["x"] = 4, ["meta"] = {["fields"] = {}, ["inventory"] = {}}, ["param2"] = 21, ["y"] = 19, ["param1"] = 106, ["z"] = 6, ["name"] = "rainbow:slab_render_white_1"}, {["x"] = 4, ["meta"] = {["fields"] = {}, ["inventory"] = {}}, ["param2"] = 21, ["y"] = 19, ["param1"] = 90, ["z"] = 7, ["name"] = "rainbow:slab_render_white_1"}, {["x"] = 4, ["meta"] = {["fields"] = {}, ["inventory"] = {}}, ["param2"] = 21, ["y"] = 19, ["param1"] = 73, ["z"] = 8, ["name"] = "rainbow:slab_render_white_1"}, {["x"] = 4, ["meta"] = {["fields"] = {}, ["inventory"] = {}}, ["param2"] = 21, ["y"] = 19, ["param1"] = 58, ["z"] = 9, ["name"] = "rainbow:slab_render_white_1"}, {["x"] = 4, ["meta"] = {["fields"] = {}, ["inventory"] = {}}, ["param2"] = 20, ["y"] = 19, ["param1"] = 43, ["z"] = 10, ["name"] = "rainbow:slab_render_white_1"}, {["x"] = 4, ["meta"] = {["fields"] = {}, ["inventory"] = {}}, ["y"] = 19, ["param1"] = 63, ["z"] = 11, ["name"] = "rainbow:render_white"}, {["x"] = 4, ["meta"] = {["fields"] = {}, ["inventory"] = {}}, ["y"] = 20, ["param1"] = 47, ["z"] = 1, ["name"] = "rainbow:render_white"}, {["x"] = 4, ["meta"] = {["fields"] = {}, ["inventory"] = {}}, ["y"] = 20, ["z"] = 2, ["name"] = "rainbow:render_white"}, {["x"] = 4, ["meta"] = {["fields"] = {}, ["inventory"] = {}}, ["y"] = 20, ["z"] = 4, ["name"] = "rainbow:render_black"}, {["x"] = 4, ["meta"] = {["fields"] = {}, ["inventory"] = {}}, ["y"] = 20, ["z"] = 5, ["name"] = "rainbow:render_black"}, {["x"] = 4, ["meta"] = {["fields"] = {}, ["inventory"] = {}}, ["y"] = 20, ["z"] = 6, ["name"] = "rainbow:render_black"}, {["x"] = 4, ["meta"] = {["fields"] = {}, ["inventory"] = {}}, ["y"] = 20, ["z"] = 7, ["name"] = "rainbow:render_black"}, {["x"] = 4, ["meta"] = {["fields"] = {}, ["inventory"] = {}}, ["y"] = 20, ["z"] = 8, ["name"] = "rainbow:render_black"}, {["x"] = 4, ["meta"] = {["fields"] = {}, ["inventory"] = {}}, ["y"] = 20, ["z"] = 9, ["name"] = "rainbow:render_black"}, {["x"] = 4, ["meta"] = {["fields"] = {}, ["inventory"] = {}}, ["y"] = 20, ["z"] = 10, ["name"] = "rainbow:render_white"}, {["x"] = 4, ["meta"] = {["fields"] = {}, ["inventory"] = {}}, ["y"] = 20, ["param1"] = 47, ["z"] = 11, ["name"] = "rainbow:render_white"}, {["x"] = 4, ["meta"] = {["fields"] = {}, ["inventory"] = {}}, ["param2"] = 1, ["y"] = 21, ["param1"] = 174, ["z"] = 1, ["name"] = "rainbow:slope_render_white_outer"}, {["x"] = 4, ["meta"] = {["fields"] = {}, ["inventory"] = {}}, ["y"] = 21, ["param1"] = 175, ["z"] = 2, ["name"] = "rainbow:render_white"}, {["x"] = 4, ["meta"] = {["fields"] = {}, ["inventory"] = {}}, ["y"] = 21, ["z"] = 10, ["name"] = "rainbow:render_white"}, {["x"] = 4, ["meta"] = {["fields"] = {}, ["inventory"] = {}}, ["param2"] = 2, ["y"] = 21, ["param1"] = 46, ["z"] = 11, ["name"] = "rainbow:slope_render_white_outer"}, {["x"] = 4, ["meta"] = {["fields"] = {}, ["inventory"] = {}}, ["y"] = 22, ["z"] = 2, ["name"] = "rainbow:render_red"},