5:return {{["x"] = 0, ["meta"] = {["fields"] = {}, ["inventory"] = {}}, ["param2"] = 17, ["y"] = 13, ["param1"] = 78, ["z"] = 7, ["name"] = "moreblocks:slope_steelblock_half"}, {["x"] = 0, ["meta"] = {["fields"] = {}, ["inventory"] = {}}, ["param2"] = 17, ["y"] = 14, ["param1"] = 94, ["z"] = 7, ["name"] = "moreblocks:slope_steelblock_half_raised"}, {["x"] = 0, ["meta"] = {["fields"] = {}, ["inventory"] = {}}, ["y"] = 15, ["z"] = 7, ["name"] = "default:steelblock"}, {["x"] = 0, ["meta"] = {["fields"] = {}, ["inventory"] = {}}, ["y"] = 16, ["z"] = 7, ["name"] = "default:steelblock"}, {["x"] = 0, ["meta"] = {["fields"] = {}, ["inventory"] = {}}, ["y"] = 17, ["z"] = 7, ["name"] = "default:steelblock"}, {["x"] = 0, ["meta"] = {["fields"] = {}, ["inventory"] = {}}, ["y"] = 18, ["z"] = 7, ["name"] = "default:steelblock"}, {["x"] = 0, ["meta"] = {["fields"] = {}, ["inventory"] = {}}, ["param2"] = 16, ["y"] = 19, ["param1"] = 126, ["z"] = 4, ["name"] = "moreblocks:slope_steelblock_half"}, {["x"] = 0, ["meta"] = {["fields"] = {}, ["inventory"] = {}}, ["param2"] = 16, ["y"] = 19, ["param1"] = 143, ["z"] = 5, ["name"] = "moreblocks:slope_steelblock_half_raised"}, {["x"] = 0, ["meta"] = {["fields"] = {}, ["inventory"] = {}}, ["y"] = 19, ["z"] = 6, ["name"] = "default:steelblock"}, {["x"] = 0, ["meta"] = {["fields"] = {}, ["inventory"] = {}}, ["y"] = 19, ["z"] = 7, ["name"] = "default:steelblock"}, {["x"] = 0, ["meta"] = {["fields"] = {}, ["inventory"] = {}}, ["y"] = 19, ["z"] = 8, ["name"] = "default:steelblock"}, {["x"] = 0, ["meta"] = {["fields"] = {}, ["inventory"] = {}}, ["param2"] = 18, ["y"] = 19, ["param1"] = 143, ["z"] = 9, ["name"] = "moreblocks:slope_steelblock_half_raised"}, {["x"] = 0, ["meta"] = {["fields"] = {}, ["inventory"] = {}}, ["param2"] = 18, ["y"] = 19, ["param1"] = 127, ["z"] = 10, ["name"] = "moreblocks:slope_steelblock_half"}, {["x"] = 0, ["meta"] = {["fields"] = {}, ["inventory"] = {}}, ["y"] = 20, ["z"] = 7, ["name"] = "default:steelblock"}, {["x"] = 0, ["meta"] = {["fields"] = {}, ["inventory"] = {}}, ["y"] = 21, ["z"] = 7, ["name"] = "default:steelblock"}, {["x"] = 0, ["meta"] = {["fields"] = {}, ["inventory"] = {}}, ["y"] = 22, ["z"] = 7, ["name"] = "default:steelblock"}, {["x"] = 0, ["meta"] = {["fields"] = {}, ["inventory"] = {}}, ["y"] = 23, ["z"] = 7, ["name"] = "default:steelblock"}, {["x"] = 0, ["meta"] = {["fields"] = {}, ["inventory"] = {}}, ["param2"] = 19, ["y"] = 24, ["param1"] = 95, ["z"] = 7, ["name"] = "moreblocks:slope_steelblock_half_raised"}, {["x"] = 0, ["meta"] = {["fields"] = {}, ["inventory"] = {}}, ["param2"] = 19, ["y"] = 25, ["param1"] = 79, ["z"] = 7, ["name"] = "moreblocks:slope_steelblock_half"}, {["x"] = 1, ["meta"] = {["fields"] = {}, ["inventory"] = {}}, ["param2"] = 17, ["y"] = 12, ["param1"] = 79, ["z"] = 7, ["name"] = "moreblocks:slope_steelblock"}, {["x"] = 1, ["meta"] = {["fields"] = {}, ["inventory"] = {}}, ["param2"] = 13, ["y"] = 13, ["param1"] = 95, ["z"] = 7, ["name"] = "moreblocks:slope_steelblock_half_raised"}, {["x"] = 1, ["meta"] = {["fields"] = {}, ["inventory"] = {}}, ["param2"] = 13, ["y"] = 14, ["param1"] = 111, ["z"] = 7, ["name"] = "moreblocks:slope_steelblock_half"}, {["x"] = 1, ["meta"] = {["fields"] = {}, ["inventory"] = {}}, ["param2"] = 16, ["y"] = 19, ["param1"] = 127, ["z"] = 3, ["name"] = "moreblocks:slope_steelblock"}, {["x"] = 1, ["meta"] = {["fields"] = {}, ["inventory"] = {}}, ["param2"] = 14, ["y"] = 19, ["param1"] = 142, ["z"] = 4, ["name"] = "moreblocks:slope_steelblock_half_raised"}, {["x"] = 1, ["meta"] = {["fields"] = {}, ["inventory"] = {}}, ["param2"] = 14, ["y"] = 19, ["param1"] = 159, ["z"] = 5, ["name"] = "moreblocks:slope_steelblock_half"}, {["x"] = 1, ["meta"] = {["fields"] = {}, ["inventory"] = {}}, ["param2"] = 12, ["y"] = 19, ["param1"] = 159, ["z"] = 9, ["name"] = "moreblocks:slope_steelblock_half"}, {["x"] = 1, ["meta"] = {["fields"] = {}, ["inventory"] = {}}, ["param2"] = 12, ["y"] = 19, ["param1"] = 143, ["z"] = 10, ["name"] = "moreblocks:slope_steelblock_half_raised"}, {["x"] = 1, ["meta"] = {["fields"] = {}, ["inventory"] = {}}, ["param2"] = 18, ["y"] = 19, ["param1"] = 127, ["z"] = 11, ["name"] = "moreblocks:slope_steelblock"}, {["x"] = 1, ["meta"] = {["fields"] = {}, ["inventory"] = {}}, ["param2"] = 15, ["y"] = 24, ["param1"] = 111, ["z"] = 7, ["name"] = "moreblocks:slope_steelblock_half"}, {["x"] = 1, ["meta"] = {["fields"] = {}, ["inventory"] = {}}, ["param2"] = 15, ["y"] = 25, ["param1"] = 95, ["z"] = 7, ["name"] = "moreblocks:slope_steelblock_half_raised"}, {["x"] = 1, ["meta"] = {["fields"] = {}, ["inventory"] = {}}, ["param2"] = 1, ["y"] = 26, ["param1"] = 79, ["z"] = 7, ["name"] = "moreblocks:slope_steelblock"}, {["x"] = 2, ["meta"] = {["fields"] = {}, ["inventory"] = {}}, ["param2"] = 23, ["y"] = 11, ["param1"] = 78, ["z"] = 7, ["name"] = "moreblocks:slope_steelblock_half"}, {["x"] = 2, ["meta"] = {["fields"] = {}, ["inventory"] = {}}, ["param2"] = 3, ["y"] = 12, ["param1"] = 94, ["z"] = 7, ["name"] = "moreblocks:slope_steelblock_half_raised"}, {["x"] = 2, ["meta"] = {["fields"] = {}, ["inventory"] = {}}, ["param2"] = 23, ["y"] = 15, ["param1"] = 142, ["z"] = 7, ["name"] = "moreblocks:slope_steelblock_half"}, {["x"] = 2, ["meta"] = {["fields"] = {}, ["inventory"] = {}}, ["param2"] = 16, ["y"] = 16, ["param1"] = 110, ["z"] = 4, ["name"] = "moreblocks:slope_steelblock_half"}, {["x"] = 2, ["meta"] = {["fields"] = {}, ["inventory"] = {}}, ["param2"] = 16, ["y"] = 16, ["param1"] = 127, ["z"] = 5, ["name"] = "moreblocks:slope_steelblock_half_raised"}, {["x"] = 2, ["meta"] = {["fields"] = {}, ["inventory"] = {}}, ["y"] = 16, ["z"] = 6, ["name"] = "default:steelblock"}, {["x"] = 2, ["meta"] = {["fields"] = {}, ["inventory"] = {}}, ["y"] = 16, ["z"] = 7, ["name"] = "default:steelblock"}, {["x"] = 2, ["meta"] = {["fields"] = {}, ["inventory"] = {}}, ["y"] = 16, ["z"] = 8, ["name"] = "default:steelblock"}, {["x"] = 2, ["meta"] = {["fields"] = {}, ["inventory"] = {}}, ["param2"] = 18, ["y"] = 16, ["param1"] = 127, ["z"] = 9, ["name"] = "moreblocks:slope_steelblock_half_raised"}, {["x"] = 2, ["meta"] = {["fields"] = {}, ["inventory"] = {}}, ["param2"] = 18, ["y"] = 16, ["param1"] = 111, ["z"] = 10, ["name"] = "moreblocks:slope_steelblock_half"}, {["x"] = 2, ["meta"] = {["fields"] = {}, ["inventory"] = {}}, ["param2"] = 16, ["y"] = 19, ["param1"] = 127, ["z"] = 2, ["name"] = "moreblocks:slope_steelblock"}, {["x"] = 2, ["meta"] = {["fields"] = {}, ["inventory"] = {}}, ["param2"] = 14, ["y"] = 19, ["param1"] = 143, ["z"] = 3, ["name"] = "moreblocks:slope_steelblock"}, {["x"] = 2, ["meta"] = {["fields"] = {}, ["inventory"] = {}}, ["param2"] = 12, ["y"] = 19, ["param1"] = 143, ["z"] = 11, ["name"] = "moreblocks:slope_steelblock"}, {["x"] = 2, ["meta"] = {["fields"] = {}, ["inventory"] = {}}, ["param2"] = 18, ["y"] = 19, ["param1"] = 127, ["z"] = 12, ["name"] = "moreblocks:slope_steelblock"}, {["x"] = 2, ["meta"] = {["fields"] = {}, ["inventory"] = {}}, ["param2"] = 16, ["y"] = 22, ["param1"] = 110, ["z"] = 4, ["name"] = "moreblocks:slope_steelblock_half"}, {["x"] = 2, ["meta"] = {["fields"] = {}, ["inventory"] = {}}, ["param2"] = 16, ["y"] = 22, ["param1"] = 127, ["z"] = 5, ["name"] = "moreblocks:slope_steelblock_half_raised"}, {["x"] = 2, ["meta"] = {["fields"] = {}, ["inventory"] = {}}, ["y"] = 22, ["z"] = 6, ["name"] = "default:steelblock"}, {["x"] = 2, ["meta"] = {["fields"] = {}, ["inventory"] = {}}, ["y"] = 22, ["z"] = 7, ["name"] = "default:steelblock"}, {["x"] = 2, ["meta"] = {["fields"] = {}, ["inventory"] = {}}, ["y"] = 22, ["z"] = 8, ["name"] = "default:steelblock"}, {["x"] = 2, ["meta"] = {["fields"] = {}, ["inventory"] = {}}, ["param2"] = 18, ["y"] = 22, ["param1"] = 127, ["z"] = 9, ["name"] = "moreblocks:slope_steelblock_half_raised"}, {["x"] = 2, ["meta"] = {["fields"] = {}, ["inventory"] = {}}, ["param2"] = 18, ["y"] = 22, ["param1"] = 111, ["z"] = 10, ["name"] = "moreblocks:slope_steelblock_half"}, {["x"] = 2, ["meta"] = {["fields"] = {}, ["inventory"] = {}}, ["param2"] = 1, ["y"] = 23, ["param1"] = 143, ["z"] = 7, ["name"] = "moreblocks:slope_steelblock_half"}, {["x"] = 2, ["meta"] = {["fields"] = {}, ["inventory"] = {}}, ["param2"] = 21, ["y"] = 26, ["param1"] = 95, ["z"] = 7, ["name"] = "moreblocks:slope_steelblock_half_raised"}, {["x"] = 2, ["meta"] = {["fields"] = {}, ["inventory"] = {}}, ["param2"] = 1, ["y"] = 27, ["param1"] = 79, ["z"] = 7, ["name"] = "moreblocks:slope_steelblock_half"}, {["x"] = 3, ["meta"] = {["fields"] = {}, ["inventory"] = {}}, ["param2"] = 23, ["y"] = 11, ["param1"] = 94, ["z"] = 7, ["name"] = "moreblocks:slope_steelblock_half_raised"}, {["x"] = 3, ["meta"] = {["fields"] = {}, ["inventory"] = {}}, ["param2"] = 3, ["y"] = 12, ["param1"] = 109, ["z"] = 7, ["name"] = "moreblocks:slope_steelblock_half"}, {["x"] = 3, ["meta"] = {["fields"] = {}, ["inventory"] = {}}, ["param2"] = 23, ["y"] = 15, ["param1"] = 157, ["z"] = 7, ["name"] = "moreblocks:slope_steelblock_half_raised"}, {["x"] = 3, ["meta"] = {["fields"] = {}, ["inventory"] = {}}, ["param2"] = 9, ["y"] = 16, ["param1"] = 111, ["z"] = 3, ["name"] = "moreblocks:slope_steelblock"}, {["x"] = 3, ["meta"] = {["fields"] = {}, ["inventory"] = {}}, ["y"] = 16, ["z"] = 4, ["name"] = "default:steelblock"}, {["x"] = 3, ["meta"] = {["fields"] = {}, ["inventory"] = {}}, ["y"] = 16, ["z"] = 5, ["name"] = "default:steelblock"}, {["x"] = 3, ["meta"] = {["fields"] = {}, ["inventory"] = {}}, ["y"] = 16, ["z"] = 6, ["name"] = "default:steelblock"}, {["x"] = 3, ["meta"] = {["fields"] = {}, ["inventory"] = {}}, ["y"] = 16, ["z"] = 7, ["name"] = "default:steelblock"}, {["x"] = 3, ["meta"] = {["fields"] = {}, ["inventory"] = {}}, ["y"] = 16, ["z"] = 8, ["name"] = "default:steelblock"}, {["x"] = 3, ["meta"] = {["fields"] = {}, ["inventory"] = {}}, ["y"] = 16, ["z"] = 9, ["name"] = "default:steelblock"}, {["x"] = 3, ["meta"] = {["fields"] = {}, ["inventory"] = {}}, ["y"] = 16, ["z"] = 10, ["name"] = "default:steelblock"}, {["x"] = 3, ["meta"] = {["fields"] = {}, ["inventory"] = {}}, ["param2"] = 18, ["y"] = 16, ["param1"] = 111, ["z"] = 11, ["name"] = "moreblocks:slope_steelblock"}, {["x"] = 3, ["meta"] = {["fields"] = {}, ["inventory"] = {}}, ["param2"] = 9, ["y"] = 19, ["param1"] = 127, ["z"] = 1, ["name"] = "moreblocks:slope_steelblock"}, {["x"] = 3, ["meta"] = {["fields"] = {}, ["inventory"] = {}}, ["param2"] = 7, ["y"] = 19, ["param1"] = 143, ["z"] = 2, ["name"] = "moreblocks:slope_steelblock"}, {["x"] = 3, ["meta"] = {["fields"] = {}, ["inventory"] = {}}, ["param2"] = 12, ["y"] = 19, ["param1"] = 143, ["z"] = 12, ["name"] = "moreblocks:slope_steelblock"}, {["x"] = 3, ["meta"] = {["fields"] = {}, ["inventory"] = {}}, ["param2"] = 5, ["y"] = 19, ["param1"] = 127, ["z"] = 13, ["name"] = "moreblocks:slope_steelblock"}, {["x"] = 3, ["meta"] = {["fields"] = {}, ["inventory"] = {}}, ["param2"] = 9, ["y"] = 22, ["param1"] = 111, ["z"] = 3, ["name"] = "moreblocks:slope_steelblock"}, {["x"] = 3, ["meta"] = {["fields"] = {}, ["inventory"] = {}}, ["y"] = 22, ["z"] = 4, ["name"] = "default:steelblock"}, {["x"] = 3, ["meta"] = {["fields"] = {}, ["inventory"] = {}}, ["y"] = 22, ["z"] = 5, ["name"] = "default:steelblock"}, {["x"] = 3, ["meta"] = {["fields"] = {}, ["inventory"] = {}}, ["y"] = 22, ["z"] = 6, ["name"] = "default:steelblock"}, {["x"] = 3, ["meta"] = {["fields"] = {}, ["inventory"] = {}}, ["y"] = 22, ["z"] = 7, ["name"] = "default:steelblock"}, {["x"] = 3, ["meta"] = {["fields"] = {}, ["inventory"] = {}}, ["y"] = 22, ["z"] = 8, ["name"] = "default:steelblock"}, {["x"] = 3, ["meta"] = {["fields"] = {}, ["inventory"] = {}}, ["y"] = 22, ["z"] = 9, ["name"] = "default:steelblock"}, {["x"] = 3, ["meta"] = {["fields"] = {}, ["inventory"] = {}}, ["y"] = 22, ["z"] = 10, ["name"] = "default:steelblock"}, {["x"] = 3, ["meta"] = {["fields"] = {}, ["inventory"] = {}}, ["param2"] = 18, ["y"] = 22, ["param1"] = 111, ["z"] = 11, ["name"] = "moreblocks:slope_steelblock"}, {["x"] = 3, ["meta"] = {["fields"] = {}, ["inventory"] = {}}, ["param2"] = 1, ["y"] = 23, ["param1"] = 159, ["z"] = 7, ["name"] = "moreblocks:slope_steelblock_half_raised"}, {["x"] = 3, ["meta"] = {["fields"] = {}, ["inventory"] = {}}, ["param2"] = 21, ["y"] = 26, ["param1"] = 111, ["z"] = 7, ["name"] = "moreblocks:slope_steelblock_half"}, {["x"] = 3, ["meta"] = {["fields"] = {}, ["inventory"] = {}}, ["param2"] = 1, ["y"] = 27, ["param1"] = 95, ["z"] = 7, ["name"] = "moreblocks:slope_steelblock_half_raised"}, {["x"] = 4, ["meta"] = {["fields"] = {}, ["inventory"] = {}}, ["y"] = 11, ["z"] = 7, ["name"] = "default:steelblock"}, {["x"] = 4, ["meta"] = {["fields"] = {}, ["inventory"] = {}}, ["param2"] = 17, ["y"] = 14, ["param1"] = 158, ["z"] = 7, ["name"] = "moreblocks:slope_steelblock"}, {["x"] = 4, ["meta"] = {["fields"] = {}, ["inventory"] = {}}, ["param2"] = 3, ["y"] = 15, ["param1"] = 174, ["z"] = 7, ["name"] = "moreblocks:slope_steelblock"}, {["x"] = 4, ["meta"] = {["fields"] = {}, ["inventory"] = {}}, ["param2"] = 9, ["y"] = 16, ["param1"] = 111, ["z"] = 2, ["name"] = "moreblocks:slope_steelblock_half"}, {["x"] = 4, ["meta"] = {["fields"] = {}, ["inventory"] = {}}, ["y"] = 16, ["z"] = 3, ["name"] = "default:steelblock"}, {["x"] = 4, ["meta"] = {["fields"] = {}, ["inventory"] = {}}, ["y"] = 16, ["z"] = 4, ["name"] = "default:steelblock"}, {["x"] = 4, ["meta"] = {["fields"] = {}, ["inventory"] = {}}, ["param2"] = 14, ["y"] = 16, ["param1"] = 159, ["z"] = 5, ["name"] = "moreblocks:slope_steelblock_half_raised"}, {["x"] = 4, ["meta"] = {["fields"] = {}, ["inventory"] = {}}, ["param2"] = 14, ["y"] = 16, ["param1"] = 175, ["z"] = 6, ["name"] = "moreblocks:slope_steelblock_half"}, {["x"] = 4, ["meta"] = {["fields"] = {}, ["inventory"] = {}}, ["param2"] = 12, ["y"] = 16, ["param1"] = 175, ["z"] = 8, ["name"] = "moreblocks:slope_steelblock_half"}, {["x"] = 4, ["meta"] = {["fields"] = {}, ["inventory"] = {}}, ["param2"] = 12, ["y"] = 16, ["param1"] = 159, ["z"] = 9, ["name"] = "moreblocks:slope_steelblock_half_raised"}, {["x"] = 4, ["meta"] = {["fields"] = {}, ["inventory"] = {}}, ["y"] = 16, ["z"] = 10, ["name"] = "default:steelblock"}, {["x"] = 4, ["meta"] = {["fields"] = {}, ["inventory"] = {}}, ["y"] = 16, ["z"] = 11, ["name"] = "default:steelblock"}, {["x"] = 4, ["meta"] = {["fields"] = {}, ["inventory"] = {}}, ["param2"] = 5, ["y"] = 16, ["param1"] = 111, ["z"] = 12, ["name"] = "moreblocks:slope_steelblock_half"}, {["x"] = 4, ["meta"] = {["fields"] = {}, ["inventory"] = {}}, ["param2"] = 9, ["y"] = 19, ["param1"] = 127, ["z"] = 0, ["name"] = "moreblocks:slope_steelblock_half"}, {["x"] = 4, ["meta"] = {["fields"] = {}, ["inventory"] = {}}, ["param2"] = 7, ["y"] = 19, ["param1"] = 143, ["z"] = 1, ["name"] = "moreblocks:slope_steelblock_half_raised"}, {["x"] = 4, ["meta"] = {["fields"] = {}, ["inventory"] = {}}, ["param2"] = 18, ["y"] = 19, ["param1"] = 238, ["z"] = 7, ["name"] = "rainbow:slab_lightblock_cyan_1"}, {["x"] = 4, ["meta"] = {["fields"] = {}, ["inventory"] = {}}, ["param2"] = 11, ["y"] = 19, ["param1"] = 143, ["z"] = 13, ["name"] = "moreblocks:slope_steelblock_half_raised"}, {["x"] = 4, ["meta"] = {["fields"] = {}, ["inventory"] = {}}, ["param2"] = 5, ["y"] = 19, ["param1"] = 127, ["z"] = 14, ["name"] = "moreblocks:slope_steelblock_half"}, {["x"] = 4, ["meta"] = {["fields"] = {}, ["inventory"] = {}}, ["param2"] = 9, ["y"] = 22, ["param1"] = 111, ["z"] = 2, ["name"] = "moreblocks:slope_steelblock_half"}, {["x"] = 4, ["meta"] = {["fields"] = {}, ["inventory"] = {}}, ["y"] = 22, ["z"] = 3, ["name"] = "default:steelblock"}, {["x"] = 4, ["meta"] = {["fields"] = {}, ["inventory"] = {}}, ["y"] = 22, ["z"] = 4, ["name"] = "default:steelblock"}, {["x"] = 4, ["meta"] = {["fields"] = {}, ["inventory"] = {}}, ["param2"] = 14, ["y"] = 22, ["param1"] = 159, ["z"] = 5, ["name"] = "moreblocks:slope_steelblock_half_raised"}, {["x"] = 4, ["meta"] = {["fields"] = {}, ["inventory"] = {}}, ["param2"] = 14, ["y"] = 22, ["param1"] = 175, ["z"] = 6, ["name"] = "moreblocks:slope_steelblock_half"}, {["x"] = 4, ["meta"] = {["fields"] = {}, ["inventory"] = {}}, ["param2"] = 12, ["y"] = 22, ["param1"] = 175, ["z"] = 8, ["name"] = "moreblocks:slope_steelblock_half"}, {["x"] = 4, ["meta"] = {["fields"] = {}, ["inventory"] = {}}, ["param2"] = 12, ["y"] = 22, ["param1"] = 159, ["z"] = 9, ["name"] = "moreblocks:slope_steelblock_half_raised"}, {["x"] = 4, ["meta"] = {["fields"] = {}, ["inventory"] = {}}, ["y"] = 22, ["z"] = 10, ["name"] = "default:steelblock"}, {["x"] = 4, ["meta"] = {["fields"] = {}, ["inventory"] = {}}, ["y"] = 22, ["z"] = 11, ["name"] = "default:steelblock"}, {["x"] = 4, ["meta"] = {["fields"] = {}, ["inventory"] = {}}, ["param2"] = 5, ["y"] = 22, ["param1"] = 111, ["z"] = 12, ["name"] = "moreblocks:slope_steelblock_half"}, {["x"] = 4, ["meta"] = {["fields"] = {}, ["inventory"] = {}}, ["param2"] = 21, ["y"] = 23, ["param1"] = 174, ["z"] = 7, ["name"] = "moreblocks:slope_steelblock"}, {["x"] = 4, ["meta"] = {["fields"] = {}, ["inventory"] = {}}, ["param2"] = 19, ["y"] = 24, ["param1"] = 158, ["z"] = 7, ["name"] = "moreblocks:slope_steelblock"}, {["x"] = 4, ["meta"] = {["fields"] = {}, ["inventory"] = {}}, ["y"] = 27, ["z"] = 7, ["name"] = "default:steelblock"}, {["x"] = 5, ["meta"] = {["fields"] = {}, ["inventory"] = {}}, ["param2"] = 18, ["y"] = 0, ["param1"] = 62, ["z"] = 7, ["name"] = "moreblocks:slab_steelblock_1"}, {["x"] = 5, ["meta"] = {["fields"] = {}, ["inventory"] = {}}, ["param2"] = 18, ["y"] = 1, ["param1"] = 62, ["z"] = 7, ["name"] = "moreblocks:slab_steelblock_1"}, {["x"] = 5, ["meta"] = {["fields"] = {}, ["inventory"] = {}}, ["param2"] = 18, ["y"] = 2, ["param1"] = 62, ["z"] = 7, ["name"] = "moreblocks:slab_steelblock_1"}, {["x"] = 5, ["meta"] = {["fields"] = {}, ["inventory"] = {}}, ["param2"] = 18, ["y"] = 3, ["param1"] = 62, ["z"] = 7, ["name"] = "moreblocks:slab_steelblock_1"}, {["x"] = 5, ["meta"] = {["fields"] = {}, ["inventory"] = {}}, ["param2"] = 18, ["y"] = 4, ["param1"] = 62, ["z"] = 7, ["name"] = "moreblocks:slab_steelblock_1"}, {["x"] = 5, ["meta"] = {["fields"] = {}, ["inventory"] = {}}, ["param2"] = 18, ["y"] = 5, ["param1"] = 62, ["z"] = 7, ["name"] = "moreblocks:slab_steelblock_1"}, {["x"] = 5, ["meta"] = {["fields"] = {}, ["inventory"] = {}}, ["param2"] = 18, ["y"] = 6, ["param1"] = 62, ["z"] = 7, ["name"] = "moreblocks:slab_steelblock_1"}, {["x"] = 5, ["meta"] = {["fields"] = {}, ["inventory"] = {}}, ["param2"] = 18, ["y"] = 7, ["param1"] = 62, ["z"] = 7, ["name"] = "moreblocks:slab_steelblock_1"}, {["x"] = 5, ["meta"] = {["fields"] = {}, ["inventory"] = {}}, ["param2"] = 18, ["y"] = 8, ["param1"] = 78, ["z"] = 7, ["name"] = "moreblocks:slab_steelblock_1"}, {["x"] = 5, ["meta"] = {["fields"] = {}, ["inventory"] = {}}, ["param2"] = 18, ["y"] = 9, ["param1"] = 94, ["z"] = 7, ["name"] = "moreblocks:slab_steelblock_1"}, {["x"] = 5, ["meta"] = {["fields"] = {}, ["inventory"] = {}}, ["param2"] = 18, ["y"] = 10, ["param1"] = 110, ["z"] = 7, ["name"] = "moreblocks:slab_steelblock_1"}, {["x"] = 5, ["meta"] = {["fields"] = {}, ["inventory"] = {}}, ["y"] = 11, ["z"] = 7, ["name"] = "default:steelblock"}, {["x"] = 5, ["meta"] = {["fields"] = {}, ["inventory"] = {}}, ["param2"] = 17, ["y"] = 12, ["param1"] = 142, ["z"] = 7, ["name"] = "moreblocks:slope_steelblock_half"}, {["x"] = 5, ["meta"] = {["fields"] = {}, ["inventory"] = {}}, ["param2"] = 17, ["y"] = 13, ["param1"] = 158, ["z"] = 7, ["name"] = "moreblocks:slope_steelblock_half_raised"}, {["x"] = 5, ["meta"] = {["fields"] = {}, ["inventory"] = {}}, ["param2"] = 3, ["y"] = 14, ["param1"] = 174, ["z"] = 7, ["name"] = "moreblocks:slope_steelblock"}, {["x"] = 5, ["meta"] = {["fields"] = {}, ["inventory"] = {}}, ["param2"] = 9, ["y"] = 16, ["param1"] = 127, ["z"] = 2, ["name"] = "moreblocks:slope_steelblock_half_raised"}, {["x"] = 5, ["meta"] = {["fields"] = {}, ["inventory"] = {}}, ["y"] = 16, ["z"] = 3, ["name"] = "default:steelblock"}, {["x"] = 5, ["meta"] = {["fields"] = {}, ["inventory"] = {}}, ["param2"] = 7, ["y"] = 16, ["param1"] = 158, ["z"] = 4, ["name"] = "moreblocks:slope_steelblock_half_raised"}, {["x"] = 5, ["meta"] = {["fields"] = {}, ["inventory"] = {}}, ["param2"] = 11, ["y"] = 16, ["param1"] = 159, ["z"] = 10, ["name"] = "moreblocks:slope_steelblock_half_raised"}, {["x"] = 5, ["meta"] = {["fields"] = {}, ["inventory"] = {}}, ["y"] = 16, ["z"] = 11, ["name"] = "default:steelblock"}, {["x"] = 5, ["meta"] = {["fields"] = {}, ["inventory"] = {}}, ["param2"] = 5, ["y"] = 16, ["param1"] = 127, ["z"] = 12, ["name"] = "moreblocks:slope_steelblock_half_raised"}, {["x"] = 5, ["meta"] = {["fields"] = {}, ["inventory"] = {}}, ["param2"] = 9, ["y"] = 19, ["param1"] = 143, ["z"] = 0, ["name"] = "moreblocks:slope_steelblock_half_raised"}, {["x"] = 5, ["meta"] = {["fields"] = {}, ["inventory"] = {}}, ["param2"] = 7, ["y"] = 19, ["param1"] = 159, ["z"] = 1, ["name"] = "moreblocks:slope_steelblock_half"}, {["x"] = 5, ["meta"] = {["fields"] = {}, ["inventory"] = {}}, ["param2"] = 18, ["y"] = 19, ["param1"] = 238, ["z"] = 7, ["name"] = "rainbow:slab_lightblock_cyan_1"}, {["x"] = 5, ["meta"] = {["fields"] = {}, ["inventory"] = {}}, ["param2"] = 11, ["y"] = 19, ["param1"] = 159, ["z"] = 13, ["name"] = "moreblocks:slope_steelblock_half"}, {["x"] = 5, ["meta"] = {["fields"] = {}, ["inventory"] = {}}, ["param2"] = 5, ["y"] = 19, ["param1"] = 143, ["z"] = 14, ["name"] = "moreblocks:slope_steelblock_half_raised"}, {["x"] = 5, ["meta"] = {["fields"] = {}, ["inventory"] = {}}, ["param2"] = 9, ["y"] = 22, ["param1"] = 127, ["z"] = 2, ["name"] = "moreblocks:slope_steelblock_half_raised"}, {["x"] = 5, ["meta"] = {["fields"] = {}, ["inventory"] = {}}, ["y"] = 22, ["z"] = 3, ["name"] = "default:steelblock"}, {["x"] = 5, ["meta"] = {["fields"] = {}, ["inventory"] = {}}, ["param2"] = 7, ["y"] = 22, ["param1"] = 158, ["z"] = 4, ["name"] = "moreblocks:slope_steelblock_half_raised"}, {["x"] = 5, ["meta"] = {["fields"] = {}, ["inventory"] = {}}, ["param2"] = 11, ["y"] = 22, ["param1"] = 159, ["z"] = 10, ["name"] = "moreblocks:slope_steelblock_half_raised"}, {["x"] = 5, ["meta"] = {["fields"] = {}, ["inventory"] = {}}, ["y"] = 22, ["z"] = 11, ["name"] = "default:steelblock"}, {["x"] = 5, ["meta"] = {["fields"] = {}, ["inventory"] = {}}, ["param2"] = 5, ["y"] = 22, ["param1"] = 127, ["z"] = 12, ["name"] = "moreblocks:slope_steelblock_half_raised"}, {["x"] = 5, ["meta"] = {["fields"] = {}, ["inventory"] = {}}, ["param2"] = 21, ["y"] = 24, ["param1"] = 174, ["z"] = 7, ["name"] = "moreblocks:slope_steelblock"}, {["x"] = 5, ["meta"] = {["fields"] = {}, ["inventory"] = {}}, ["param2"] = 19, ["y"] = 25, ["param1"] = 158, ["z"] = 7, ["name"] = "moreblocks:slope_steelblock_half_raised"}, {["x"] = 5, ["meta"] = {["fields"] = {}, ["inventory"] = {}}, ["param2"] = 19, ["y"] = 26, ["param1"] = 142, ["z"] = 7, ["name"] = "moreblocks:slope_steelblock_half"}, {["x"] = 5, ["meta"] = {["fields"] = {}, ["inventory"] = {}}, ["y"] = 27, ["z"] = 7, ["name"] = "default:steelblock"}, {["x"] = 6, ["meta"] = {["fields"] = {}, ["inventory"] = {}}, ["param2"] = 9, ["y"] = 0, ["param1"] = 79, ["z"] = 6, ["name"] = "moreblocks:slope_steelblock"}, {["x"] = 6, ["meta"] = {["fields"] = {}, ["inventory"] = {}}, ["param2"] = 18, ["y"] = 0, ["param1"] = 79, ["z"] = 8, ["name"] = "moreblocks:slope_steelblock"}, {["x"] = 6, ["meta"] = {["fields"] = {}, ["inventory"] = {}}, ["param2"] = 9, ["y"] = 1, ["param1"] = 79, ["z"] = 6, ["name"] = "moreblocks:slope_steelblock"}, {["x"] = 6, ["meta"] = {["fields"] = {}, ["inventory"] = {}}, ["param2"] = 18, ["y"] = 1, ["param1"] = 79, ["z"] = 8, ["name"] = "moreblocks:slope_steelblock"}, {["x"] = 6, ["meta"] = {["fields"] = {}, ["inventory"] = {}}, ["param2"] = 9, ["y"] = 2, ["param1"] = 79, ["z"] = 6, ["name"] = "moreblocks:slope_steelblock"}, {["x"] = 6, ["meta"] = {["fields"] = {}, ["inventory"] = {}}, ["param2"] = 18, ["y"] = 2, ["param1"] = 79, ["z"] = 8, ["name"] = "moreblocks:slope_steelblock"}, {["x"] = 6, ["meta"] = {["fields"] = {}, ["inventory"] = {}}, ["param2"] = 9, ["y"] = 3, ["param1"] = 79, ["z"] = 6, ["name"] = "moreblocks:slope_steelblock"}, {["x"] = 6, ["meta"] = {["fields"] = {}, ["inventory"] = {}}, ["param2"] = 18, ["y"] = 3, ["param1"] = 79, ["z"] = 8, ["name"] = "moreblocks:slope_steelblock"}, {["x"] = 6, ["meta"] = {["fields"] = {}, ["inventory"] = {}}, ["param2"] = 9, ["y"] = 4, ["param1"] = 79, ["z"] = 6, ["name"] = "moreblocks:slope_steelblock"}, {["x"] = 6, ["meta"] = {["fields"] = {}, ["inventory"] = {}}, ["param2"] = 18, ["y"] = 4, ["param1"] = 79, ["z"] = 8, ["name"] = "moreblocks:slope_steelblock"}, {["x"] = 6, ["meta"] = {["fields"] = {}, ["inventory"] = {}}, ["param2"] = 9, ["y"] = 5, ["param1"] = 79, ["z"] = 6, ["name"] = "moreblocks:slope_steelblock"}, {["x"] = 6, ["meta"] = {["fields"] = {}, ["inventory"] = {}}, ["param2"] = 18, ["y"] = 5, ["param1"] = 79, ["z"] = 8, ["name"] = "moreblocks:slope_steelblock"}, {["x"] = 6, ["meta"] = {["fields"] = {}, ["inventory"] = {}}, ["param2"] = 9, ["y"] = 6, ["param1"] = 79, ["z"] = 6, ["name"] = "moreblocks:slope_steelblock"}, {["x"] = 6, ["meta"] = {["fields"] = {}, ["inventory"] = {}}, ["param2"] = 18, ["y"] = 6, ["param1"] = 79, ["z"] = 8, ["name"] = "moreblocks:slope_steelblock"}, {["x"] = 6, ["meta"] = {["fields"] = {}, ["inventory"] = {}}, ["param2"] = 9, ["y"] = 7, ["param1"] = 79, ["z"] = 6, ["name"] = "moreblocks:slope_steelblock"}, {["x"] = 6, ["meta"] = {["fields"] = {}, ["inventory"] = {}}, ["param2"] = 18, ["y"] = 7, ["param1"] = 79, ["z"] = 8, ["name"] = "moreblocks:slope_steelblock"}, {["x"] = 6, ["meta"] = {["fields"] = {}, ["inventory"] = {}}, ["param2"] = 9, ["y"] = 8, ["param1"] = 79, ["z"] = 6, ["name"] = "moreblocks:slope_steelblock"}, {["x"] = 6, ["meta"] = {["fields"] = {}, ["inventory"] = {}}, ["param2"] = 18, ["y"] = 8, ["param1"] = 79, ["z"] = 8, ["name"] = "moreblocks:slope_steelblock"}, {["x"] = 6, ["meta"] = {["fields"] = {}, ["inventory"] = {}}, ["param2"] = 9, ["y"] = 9, ["param1"] = 95, ["z"] = 6, ["name"] = "moreblocks:slope_steelblock"}, {["x"] = 6, ["meta"] = {["fields"] = {}, ["inventory"] = {}}, ["param2"] = 18, ["y"] = 9, ["param1"] = 95, ["z"] = 8, ["name"] = "moreblocks:slope_steelblock"}, {["x"] = 6, ["meta"] = {["fields"] = {}, ["inventory"] = {}}, ["param2"] = 9, ["y"] = 10, ["param1"] = 111, ["z"] = 6, ["name"] = "moreblocks:slope_steelblock"}, {["x"] = 6, ["meta"] = {["fields"] = {}, ["inventory"] = {}}, ["param2"] = 18, ["y"] = 10, ["param1"] = 111, ["z"] = 8, ["name"] = "moreblocks:slope_steelblock"}, {["x"] = 6, ["meta"] = {["fields"] = {}, ["inventory"] = {}}, ["param2"] = 9, ["y"] = 11, ["param1"] = 127, ["z"] = 6, ["name"] = "moreblocks:slope_steelblock"}, {["x"] = 6, ["meta"] = {["fields"] = {}, ["inventory"] = {}}, ["y"] = 11, ["z"] = 7, ["name"] = "default:steelblock"}, {["x"] = 6, ["meta"] = {["fields"] = {}, ["inventory"] = {}}, ["param2"] = 18, ["y"] = 11, ["param1"] = 127, ["z"] = 8, ["name"] = "moreblocks:slope_steelblock"}, {["x"] = 6, ["meta"] = {["fields"] = {}, ["inventory"] = {}}, ["y"] = 12, ["z"] = 7, ["name"] = "default:steelblock"}, {["x"] = 6, ["meta"] = {["fields"] = {}, ["inventory"] = {}}, ["param2"] = 3, ["y"] = 13, ["param1"] = 174, ["z"] = 7, ["name"] = "moreblocks:slope_steelblock"}, {["x"] = 6, ["meta"] = {["fields"] = {}, ["inventory"] = {}}, ["y"] = 16, ["z"] = 2, ["name"] = "default:steelblock"}, {["x"] = 6, ["meta"] = {["fields"] = {}, ["inventory"] = {}}, ["y"] = 16, ["z"] = 3, ["name"] = "default:steelblock"}, {["x"] = 6, ["meta"] = {["fields"] = {}, ["inventory"] = {}}, ["param2"] = 7, ["y"] = 16, ["param1"] = 174, ["z"] = 4, ["name"] = "moreblocks:slope_steelblock_half"}, {["x"] = 6, ["meta"] = {["fields"] = {}, ["inventory"] = {}}, ["param2"] = 11, ["y"] = 16, ["param1"] = 175, ["z"] = 10, ["name"] = "moreblocks:slope_steelblock_half"}, {["x"] = 6, ["meta"] = {["fields"] = {}, ["inventory"] = {}}, ["y"] = 16, ["z"] = 11, ["name"] = "default:steelblock"}, {["x"] = 6, ["meta"] = {["fields"] = {}, ["inventory"] = {}}, ["y"] = 16, ["z"] = 12, ["name"] = "default:steelblock"}, {["x"] = 6, ["meta"] = {["fields"] = {}, ["inventory"] = {}}, ["y"] = 19, ["z"] = 0, ["name"] = "default:steelblock"}, {["x"] = 6, ["meta"] = {["fields"] = {}, ["inventory"] = {}}, ["param2"] = 18, ["y"] = 19, ["param1"] = 238, ["z"] = 7, ["name"] = "rainbow:slab_lightblock_cyan_1"}, {["x"] = 6, ["meta"] = {["fields"] = {}, ["inventory"] = {}}, ["y"] = 19, ["z"] = 14, ["name"] = "default:steelblock"}, {["x"] = 6, ["meta"] = {["fields"] = {}, ["inventory"] = {}}, ["y"] = 22, ["z"] = 2, ["name"] = "default:steelblock"}, {["x"] = 6, ["meta"] = {["fields"] = {}, ["inventory"] = {}}, ["y"] = 22, ["z"] = 3, ["name"] = "default:steelblock"}, {["x"] = 6, ["meta"] = {["fields"] = {}, ["inventory"] = {}}, ["param2"] = 7, ["y"] = 22, ["param1"] = 174, ["z"] = 4, ["name"] = "moreblocks:slope_steelblock_half"}, {["x"] = 6, ["meta"] = {["fields"] = {}, ["inventory"] = {}}, ["param2"] = 11, ["y"] = 22, ["param1"] = 175, ["z"] = 10, ["name"] = "moreblocks:slope_steelblock_half"}, {["x"] = 6, ["meta"] = {["fields"] = {}, ["inventory"] = {}}, ["y"] = 22, ["z"] = 11, ["name"] = "default:steelblock"}, {["x"] = 6, ["meta"] = {["fields"] = {}, ["inventory"] = {}}, ["y"] = 22, ["z"] = 12, ["name"] = "default:steelblock"}, {["x"] = 6, ["meta"] = {["fields"] = {}, ["inventory"] = {}}, ["param2"] = 21, ["y"] = 25, ["param1"] = 174, ["z"] = 7, ["name"] = "moreblocks:slope_steelblock"}, {["x"] = 6, ["meta"] = {["fields"] = {}, ["inventory"] = {}}, ["y"] = 26, ["z"] = 7, ["name"] = "default:steelblock"}, {["x"] = 6, ["meta"] = {["fields"] = {}, ["inventory"] = {}}, ["param2"] = 9, ["y"] = 27, ["param1"] = 127, ["z"] = 6, ["name"] = "moreblocks:slope_steelblock"}, {["x"] = 6, ["meta"] = {["fields"] = {}, ["inventory"] = {}}, ["param2"] = 18, ["y"] = 27, ["param1"] = 127, ["z"] = 8, ["name"] = "moreblocks:slope_steelblock"}, {["x"] = 7, ["meta"] = {["fields"] = {}, ["inventory"] = {}}, ["param2"] = 9, ["y"] = 0, ["param1"] = 94, ["z"] = 5, ["name"] = "moreblocks:slab_steelblock_1"}, {["x"] = 7, ["meta"] = {["fields"] = {}, ["inventory"] = {}}, ["param2"] = 9, ["y"] = 1, ["param1"] = 94, ["z"] = 5, ["name"] = "moreblocks:slab_steelblock_1"}, {["x"] = 7, ["meta"] = {["fields"] = {}, ["inventory"] = {}}, ["param2"] = 9, ["y"] = 2, ["param1"] = 94, ["z"] = 5, ["name"] = "moreblocks:slab_steelblock_1"}, {["x"] = 7, ["meta"] = {["fields"] = {}, ["inventory"] = {}}, ["param2"] = 7, ["y"] = 2, ["param1"] = 94, ["z"] = 9, ["name"] = "moreblocks:slab_steelblock_1"}, {["x"] = 7, ["meta"] = {["fields"] = {}, ["inventory"] = {}}, ["param2"] = 9, ["y"] = 3, ["param1"] = 94, ["z"] = 5, ["name"] = "moreblocks:slab_steelblock_1"}, {["x"] = 7, ["meta"] = {["fields"] = {}, ["inventory"] = {}}, ["param2"] = 7, ["y"] = 3, ["param1"] = 94, ["z"] = 9, ["name"] = "moreblocks:slab_steelblock_1"}, {["x"] = 7, ["meta"] = {["fields"] = {}, ["inventory"] = {}}, ["param2"] = 9, ["y"] = 4, ["param1"] = 94, ["z"] = 5, ["name"] = "moreblocks:slab_steelblock_1"}, {["x"] = 7, ["meta"] = {["fields"] = {}, ["inventory"] = {}}, ["param2"] = 7, ["y"] = 4, ["param1"] = 94, ["z"] = 9, ["name"] = "moreblocks:slab_steelblock_1"}, {["x"] = 7, ["meta"] = {["fields"] = {}, ["inventory"] = {}}, ["param2"] = 9, ["y"] = 5, ["param1"] = 94, ["z"] = 5, ["name"] = "moreblocks:slab_steelblock_1"}, {["x"] = 7, ["meta"] = {["fields"] = {}, ["inventory"] = {}}, ["param2"] = 7, ["y"] = 5, ["param1"] = 94, ["z"] = 9, ["name"] = "moreblocks:slab_steelblock_1"}, {["x"] = 7, ["meta"] = {["fields"] = {}, ["inventory"] = {}}, ["param2"] = 9, ["y"] = 6, ["param1"] = 94, ["z"] = 5, ["name"] = "moreblocks:slab_steelblock_1"}, {["x"] = 7, ["meta"] = {["fields"] = {}, ["inventory"] = {}}, ["param2"] = 7, ["y"] = 6, ["param1"] = 94, ["z"] = 9, ["name"] = "moreblocks:slab_steelblock_1"}, {["x"] = 7, ["meta"] = {["fields"] = {}, ["inventory"] = {}}, ["param2"] = 9, ["y"] = 7, ["param1"] = 94, ["z"] = 5, ["name"] = "moreblocks:slab_steelblock_1"}, {["x"] = 7, ["meta"] = {["fields"] = {}, ["inventory"] = {}}, ["param2"] = 7, ["y"] = 7, ["param1"] = 94, ["z"] = 9, ["name"] = "moreblocks:slab_steelblock_1"}, {["x"] = 7, ["meta"] = {["fields"] = {}, ["inventory"] = {}}, ["param2"] = 9, ["y"] = 8, ["param1"] = 94, ["z"] = 5, ["name"] = "moreblocks:slab_steelblock_1"}, {["x"] = 7, ["meta"] = {["fields"] = {}, ["inventory"] = {}}, ["param2"] = 7, ["y"] = 8, ["param1"] = 94, ["z"] = 9, ["name"] = "moreblocks:slab_steelblock_1"}, {["x"] = 7, ["meta"] = {["fields"] = {}, ["inventory"] = {}}, ["param2"] = 9, ["y"] = 9, ["param1"] = 94, ["z"] = 5, ["name"] = "moreblocks:slab_steelblock_1"}, {["x"] = 7, ["meta"] = {["fields"] = {}, ["inventory"] = {}}, ["param2"] = 7, ["y"] = 9, ["param1"] = 94, ["z"] = 9, ["name"] = "moreblocks:slab_steelblock_1"}, {["x"] = 7, ["meta"] = {["fields"] = {}, ["inventory"] = {}}, ["param2"] = 9, ["y"] = 10, ["param1"] = 110, ["z"] = 5, ["name"] = "moreblocks:slab_steelblock_1"}, {["x"] = 7, ["meta"] = {["fields"] = {}, ["inventory"] = {}}, ["param2"] = 7, ["y"] = 10, ["param1"] = 110, ["z"] = 9, ["name"] = "moreblocks:slab_steelblock_1"}, {["x"] = 7, ["meta"] = {["fields"] = {}, ["inventory"] = {}}, ["param2"] = 20, ["y"] = 11, ["param1"] = 94, ["z"] = 2, ["name"] = "moreblocks:slope_steelblock_half"}, {["x"] = 7, ["meta"] = {["fields"] = {}, ["inventory"] = {}}, ["param2"] = 20, ["y"] = 11, ["param1"] = 94, ["z"] = 3, ["name"] = "moreblocks:slope_steelblock_half_raised"}, {["x"] = 7, ["meta"] = {["fields"] = {}, ["inventory"] = {}}, ["y"] = 11, ["z"] = 4, ["name"] = "default:steelblock"}, {["x"] = 7, ["meta"] = {["fields"] = {}, ["inventory"] = {}}, ["y"] = 11, ["z"] = 5, ["name"] = "default:steelblock"}, {["x"] = 7, ["meta"] = {["fields"] = {}, ["inventory"] = {}}, ["y"] = 11, ["z"] = 6, ["name"] = "default:steelblock"}, {["x"] = 7, ["meta"] = {["fields"] = {}, ["inventory"] = {}}, ["y"] = 11, ["z"] = 8, ["name"] = "default:steelblock"}, {["x"] = 7, ["meta"] = {["fields"] = {}, ["inventory"] = {}}, ["y"] = 11, ["z"] = 9, ["name"] = "default:steelblock"}, {["x"] = 7, ["meta"] = {["fields"] = {}, ["inventory"] = {}}, ["y"] = 11, ["z"] = 10, ["name"] = "default:steelblock"}, {["x"] = 7, ["meta"] = {["fields"] = {}, ["inventory"] = {}}, ["param2"] = 22, ["y"] = 11, ["param1"] = 93, ["z"] = 11, ["name"] = "moreblocks:slope_steelblock_half_raised"}, {["x"] = 7, ["meta"] = {["fields"] = {}, ["inventory"] = {}}, ["param2"] = 22, ["y"] = 11, ["param1"] = 94, ["z"] = 12, ["name"] = "moreblocks:slope_steelblock_half"}, {["x"] = 7, ["meta"] = {["fields"] = {}, ["inventory"] = {}}, ["param2"] = 8, ["y"] = 12, ["param1"] = 109, ["z"] = 1, ["name"] = "moreblocks:slope_steelblock"}, {["x"] = 7, ["meta"] = {["fields"] = {}, ["inventory"] = {}}, ["param2"] = 2, ["y"] = 12, ["param1"] = 93, ["z"] = 2, ["name"] = "moreblocks:slope_steelblock_half_raised"}, {["x"] = 7, ["meta"] = {["fields"] = {}, ["inventory"] = {}}, ["param2"] = 2, ["y"] = 12, ["param1"] = 109, ["z"] = 3, ["name"] = "moreblocks:slope_steelblock_half"}, {["x"] = 7, ["meta"] = {["fields"] = {}, ["inventory"] = {}}, ["param2"] = 8, ["y"] = 12, ["param1"] = 142, ["z"] = 5, ["name"] = "moreblocks:slope_steelblock_half"}, {["x"] = 7, ["meta"] = {["fields"] = {}, ["inventory"] = {}}, ["y"] = 12, ["z"] = 6, ["name"] = "default:steelblock"}, {["x"] = 7, ["meta"] = {["fields"] = {}, ["inventory"] = {}}, ["y"] = 12, ["z"] = 8, ["name"] = "default:steelblock"}, {["x"] = 7, ["meta"] = {["fields"] = {}, ["inventory"] = {}}, ["param2"] = 6, ["y"] = 12, ["param1"] = 142, ["z"] = 9, ["name"] = "moreblocks:slope_steelblock_half"}, {["x"] = 7, ["meta"] = {["fields"] = {}, ["inventory"] = {}}, ["y"] = 12, ["param1"] = 108, ["z"] = 11, ["name"] = "moreblocks:slope_steelblock_half"}, {["x"] = 7, ["meta"] = {["fields"] = {}, ["inventory"] = {}}, ["y"] = 12, ["param1"] = 93, ["z"] = 12, ["name"] = "moreblocks:slope_steelblock_half_raised"}, {["x"] = 7, ["meta"] = {["fields"] = {}, ["inventory"] = {}}, ["param2"] = 6, ["y"] = 12, ["param1"] = 93, ["z"] = 13, ["name"] = "moreblocks:slope_steelblock"}, {["x"] = 7, ["meta"] = {["fields"] = {}, ["inventory"] = {}}, ["param2"] = 8, ["y"] = 13, ["param1"] = 125, ["z"] = 0, ["name"] = "moreblocks:slope_steelblock_half"}, {["x"] = 7, ["meta"] = {["fields"] = {}, ["inventory"] = {}}, ["param2"] = 4, ["y"] = 13, ["param1"] = 109, ["z"] = 1, ["name"] = "moreblocks:slope_steelblock_half_raised"}, {["x"] = 7, ["meta"] = {["fields"] = {}, ["inventory"] = {}}, ["param2"] = 8, ["y"] = 13, ["param1"] = 158, ["z"] = 5, ["name"] = "moreblocks:slope_steelblock_half_raised"}, {["x"] = 7, ["meta"] = {["fields"] = {}, ["inventory"] = {}}, ["param2"] = 2, ["y"] = 13, ["param1"] = 174, ["z"] = 6, ["name"] = "moreblocks:slope_steelblock"}, {["x"] = 7, ["meta"] = {["fields"] = {}, ["inventory"] = {}}, ["y"] = 13, ["param1"] = 174, ["z"] = 8, ["name"] = "moreblocks:slope_steelblock"}, {["x"] = 7, ["meta"] = {["fields"] = {}, ["inventory"] = {}}, ["param2"] = 6, ["y"] = 13, ["param1"] = 158, ["z"] = 9, ["name"] = "moreblocks:slope_steelblock_half_raised"}, {["x"] = 7, ["meta"] = {["fields"] = {}, ["inventory"] = {}}, ["param2"] = 10, ["y"] = 13, ["param1"] = 94, ["z"] = 13, ["name"] = "moreblocks:slope_steelblock_half_raised"}, {["x"] = 7, ["meta"] = {["fields"] = {}, ["inventory"] = {}}, ["param2"] = 6, ["y"] = 13, ["param1"] = 93, ["z"] = 14, ["name"] = "moreblocks:slope_steelblock_half"}, {["x"] = 7, ["meta"] = {["fields"] = {}, ["inventory"] = {}}, ["param2"] = 8, ["y"] = 14, ["param1"] = 125, ["z"] = 0, ["name"] = "moreblocks:slope_steelblock_half_raised"}, {["x"] = 7, ["meta"] = {["fields"] = {}, ["inventory"] = {}}, ["param2"] = 4, ["y"] = 14, ["param1"] = 110, ["z"] = 1, ["name"] = "moreblocks:slope_steelblock_half"}, {["x"] = 7, ["meta"] = {["fields"] = {}, ["inventory"] = {}}, ["param2"] = 8, ["y"] = 14, ["param1"] = 157, ["z"] = 4, ["name"] = "moreblocks:slope_steelblock"}, {["x"] = 7, ["meta"] = {["fields"] = {}, ["inventory"] = {}}, ["param2"] = 2, ["y"] = 14, ["param1"] = 174, ["z"] = 5, ["name"] = "moreblocks:slope_steelblock"}, {["x"] = 7, ["meta"] = {["fields"] = {}, ["inventory"] = {}}, ["y"] = 14, ["param1"] = 174, ["z"] = 9, ["name"] = "moreblocks:slope_steelblock"}, {["x"] = 7, ["meta"] = {["fields"] = {}, ["inventory"] = {}}, ["param2"] = 22, ["y"] = 14, ["param1"] = 158, ["z"] = 10, ["name"] = "moreblocks:slope_steelblock"}, {["x"] = 7, ["meta"] = {["fields"] = {}, ["inventory"] = {}}, ["param2"] = 10, ["y"] = 14, ["param1"] = 110, ["z"] = 13, ["name"] = "moreblocks:slope_steelblock_half"}, {["x"] = 7, ["meta"] = {["fields"] = {}, ["inventory"] = {}}, ["param2"] = 6, ["y"] = 14, ["param1"] = 93, ["z"] = 14, ["name"] = "moreblocks:slope_steelblock_half_raised"}, {["x"] = 7, ["meta"] = {["fields"] = {}, ["inventory"] = {}}, ["y"] = 15, ["z"] = 0, ["name"] = "default:steelblock"}, {["x"] = 7, ["meta"] = {["fields"] = {}, ["inventory"] = {}}, ["param2"] = 20, ["y"] = 15, ["param1"] = 141, ["z"] = 2, ["name"] = "moreblocks:slope_steelblock_half"}, {["x"] = 7, ["meta"] = {["fields"] = {}, ["inventory"] = {}}, ["param2"] = 20, ["y"] = 15, ["param1"] = 156, ["z"] = 3, ["name"] = "moreblocks:slope_steelblock_half_raised"}, {["x"] = 7, ["meta"] = {["fields"] = {}, ["inventory"] = {}}, ["param2"] = 2, ["y"] = 15, ["param1"] = 173, ["z"] = 4, ["name"] = "moreblocks:slope_steelblock"}, {["x"] = 7, ["meta"] = {["fields"] = {}, ["inventory"] = {}}, ["y"] = 15, ["param1"] = 174, ["z"] = 10, ["name"] = "moreblocks:slope_steelblock"}, {["x"] = 7, ["meta"] = {["fields"] = {}, ["inventory"] = {}}, ["param2"] = 22, ["y"] = 15, ["param1"] = 157, ["z"] = 11, ["name"] = "moreblocks:slope_steelblock_half_raised"}, {["x"] = 7, ["meta"] = {["fields"] = {}, ["inventory"] = {}}, ["param2"] = 22, ["y"] = 15, ["param1"] = 141, ["z"] = 12, ["name"] = "moreblocks:slope_steelblock_half"}, {["x"] = 7, ["meta"] = {["fields"] = {}, ["inventory"] = {}}, ["y"] = 15, ["z"] = 14, ["name"] = "default:steelblock"}, {["x"] = 7, ["meta"] = {["fields"] = {}, ["inventory"] = {}}, ["y"] = 16, ["z"] = 0, ["name"] = "default:steelblock"}, {["x"] = 7, ["meta"] = {["fields"] = {}, ["inventory"] = {}}, ["y"] = 16, ["z"] = 2, ["name"] = "default:steelblock"}, {["x"] = 7, ["meta"] = {["fields"] = {}, ["inventory"] = {}}, ["y"] = 16, ["z"] = 3, ["name"] = "default:steelblock"}, {["x"] = 7, ["meta"] = {["fields"] = {}, ["inventory"] = {}}, ["param2"] = 23, ["y"] = 16, ["param1"] = 238, ["z"] = 7, ["name"] = "rainbow:slab_lightblock_cyan_1"}, {["x"] = 7, ["meta"] = {["fields"] = {}, ["inventory"] = {}}, ["y"] = 16, ["z"] = 11, ["name"] = "default:steelblock"}, {["x"] = 7, ["meta"] = {["fields"] = {}, ["inventory"] = {}}, ["y"] = 16, ["z"] = 12, ["name"] = "default:steelblock"}, {["x"] = 7, ["meta"] = {["fields"] = {}, ["inventory"] = {}}, ["y"] = 16, ["z"] = 14, ["name"] = "default:steelblock"}, {["x"] = 7, ["meta"] = {["fields"] = {}, ["inventory"] = {}}, ["y"] = 17, ["z"] = 0, ["name"] = "default:steelblock"}, {["x"] = 7, ["meta"] = {["fields"] = {}, ["inventory"] = {}}, ["param2"] = 22, ["y"] = 17, ["param1"] = 238, ["z"] = 7, ["name"] = "rainbow:slab_lightblock_cyan_1"}, {["x"] = 7, ["meta"] = {["fields"] = {}, ["inventory"] = {}}, ["y"] = 17, ["z"] = 14, ["name"] = "default:steelblock"}, {["x"] = 7, ["meta"] = {["fields"] = {}, ["inventory"] = {}}, ["y"] = 18, ["z"] = 0, ["name"] = "default:steelblock"}, {["x"] = 7, ["meta"] = {["fields"] = {}, ["inventory"] = {}}, ["param2"] = 22, ["y"] = 18, ["param1"] = 238, ["z"] = 7, ["name"] = "rainbow:slab_lightblock_cyan_1"}, {["x"] = 7, ["meta"] = {["fields"] = {}, ["inventory"] = {}}, ["y"] = 18, ["z"] = 14, ["name"] = "default:steelblock"}, {["x"] = 7, ["meta"] = {["fields"] = {}, ["inventory"] = {}}, ["y"] = 19, ["z"] = 0, ["name"] = "default:steelblock"}, {["x"] = 7, ["meta"] = {["fields"] = {}, ["inventory"] = {}}, ["param2"] = 9, ["y"] = 19, ["param1"] = 238, ["z"] = 4, ["name"] = "rainbow:slab_lightblock_cyan_1"}, {["x"] = 7, ["meta"] = {["fields"] = {}, ["inventory"] = {}}, ["param2"] = 9, ["y"] = 19, ["param1"] = 238, ["z"] = 5, ["name"] = "rainbow:slab_lightblock_cyan_1"}, {["x"] = 7, ["meta"] = {["fields"] = {}, ["inventory"] = {}}, ["param2"] = 9, ["y"] = 19, ["param1"] = 238, ["z"] = 6, ["name"] = "rainbow:slab_lightblock_cyan_1"}, {["x"] = 7, ["meta"] = {["fields"] = {}, ["inventory"] = {}}, ["param2"] = 2, ["y"] = 19, ["param1"] = 238, ["z"] = 7, ["name"] = "rainbow:slab_lightblock_cyan_1"}, {["x"] = 7, ["meta"] = {["fields"] = {}, ["inventory"] = {}}, ["param2"] = 7, ["y"] = 19, ["param1"] = 238, ["z"] = 8, ["name"] = "rainbow:slab_lightblock_cyan_1"}, {["x"] = 7, ["meta"] = {["fields"] = {}, ["inventory"] = {}}, ["param2"] = 7, ["y"] = 19, ["param1"] = 238, ["z"] = 9, ["name"] = "rainbow:slab_lightblock_cyan_1"}, {["x"] = 7, ["meta"] = {["fields"] = {}, ["inventory"] = {}}, ["param2"] = 7, ["y"] = 19, ["param1"] = 238, ["z"] = 10, ["name"] = "rainbow:slab_lightblock_cyan_1"}, {["x"] = 7, ["meta"] = {["fields"] = {}, ["inventory"] = {}}, ["y"] = 19, ["z"] = 14, ["name"] = "default:steelblock"}, {["x"] = 7, ["meta"] = {["fields"] = {}, ["inventory"] = {}}, ["y"] = 20, ["z"] = 0, ["name"] = "default:steelblock"}, {["x"] = 7, ["meta"] = {["fields"] = {}, ["inventory"] = {}}, ["param2"] = 2, ["y"] = 20, ["param1"] = 238, ["z"] = 7, ["name"] = "rainbow:slab_lightblock_cyan_1"}, {["x"] = 7, ["meta"] = {["fields"] = {}, ["inventory"] = {}}, ["y"] = 20, ["z"] = 14, ["name"] = "default:steelblock"}, {["x"] = 7, ["meta"] = {["fields"] = {}, ["inventory"] = {}}, ["y"] = 21, ["z"] = 0, ["name"] = "default:steelblock"}, {["x"] = 7, ["meta"] = {["fields"] = {}, ["inventory"] = {}}, ["param2"] = 2, ["y"] = 21, ["param1"] = 238, ["z"] = 7, ["name"] = "rainbow:slab_lightblock_cyan_1"}, {["x"] = 7, ["meta"] = {["fields"] = {}, ["inventory"] = {}}, ["y"] = 21, ["z"] = 14, ["name"] = "default:steelblock"}, {["x"] = 7, ["meta"] = {["fields"] = {}, ["inventory"] = {}}, ["y"] = 22, ["z"] = 0, ["name"] = "default:steelblock"}, {["x"] = 7, ["meta"] = {["fields"] = {}, ["inventory"] = {}}, ["y"] = 22, ["z"] = 2, ["name"] = "default:steelblock"}, {["x"] = 7, ["meta"] = {["fields"] = {}, ["inventory"] = {}}, ["y"] = 22, ["z"] = 3, ["name"] = "default:steelblock"}, {["x"] = 7, ["meta"] = {["fields"] = {}, ["inventory"] = {}}, ["y"] = 22, ["param1"] = 238, ["z"] = 7, ["name"] = "rainbow:slab_lightblock_cyan_1"}, {["x"] = 7, ["meta"] = {["fields"] = {}, ["inventory"] = {}}, ["y"] = 22, ["z"] = 11, ["name"] = "default:steelblock"}, {["x"] = 7, ["meta"] = {["fields"] = {}, ["inventory"] = {}}, ["y"] = 22, ["z"] = 12, ["name"] = "default:steelblock"}, {["x"] = 7, ["meta"] = {["fields"] = {}, ["inventory"] = {}}, ["y"] = 22, ["z"] = 14, ["name"] = "default:steelblock"}, {["x"] = 7, ["meta"] = {["fields"] = {}, ["inventory"] = {}}, ["y"] = 23, ["z"] = 0, ["name"] = "default:steelblock"}, {["x"] = 7, ["meta"] = {["fields"] = {}, ["inventory"] = {}}, ["y"] = 23, ["param1"] = 142, ["z"] = 2, ["name"] = "moreblocks:slope_steelblock_half"}, {["x"] = 7, ["meta"] = {["fields"] = {}, ["inventory"] = {}}, ["y"] = 23, ["param1"] = 158, ["z"] = 3, ["name"] = "moreblocks:slope_steelblock_half_raised"}, {["x"] = 7, ["meta"] = {["fields"] = {}, ["inventory"] = {}}, ["param2"] = 22, ["y"] = 23, ["param1"] = 173, ["z"] = 4, ["name"] = "moreblocks:slope_steelblock"}, {["x"] = 7, ["meta"] = {["fields"] = {}, ["inventory"] = {}}, ["param2"] = 20, ["y"] = 23, ["param1"] = 174, ["z"] = 10, ["name"] = "moreblocks:slope_steelblock"}, {["x"] = 7, ["meta"] = {["fields"] = {}, ["inventory"] = {}}, ["param2"] = 2, ["y"] = 23, ["param1"] = 158, ["z"] = 11, ["name"] = "moreblocks:slope_steelblock_half_raised"}, {["x"] = 7, ["meta"] = {["fields"] = {}, ["inventory"] = {}}, ["param2"] = 2, ["y"] = 23, ["param1"] = 142, ["z"] = 12, ["name"] = "moreblocks:slope_steelblock_half"}, {["x"] = 7, ["meta"] = {["fields"] = {}, ["inventory"] = {}}, ["y"] = 23, ["z"] = 14, ["name"] = "default:steelblock"}, {["x"] = 7, ["meta"] = {["fields"] = {}, ["inventory"] = {}}, ["param2"] = 10, ["y"] = 24, ["param1"] = 126, ["z"] = 0, ["name"] = "moreblocks:slope_steelblock_half_raised"}, {["x"] = 7, ["meta"] = {["fields"] = {}, ["inventory"] = {}}, ["param2"] = 6, ["y"] = 24, ["param1"] = 110, ["z"] = 1, ["name"] = "moreblocks:slope_steelblock_half"}, {["x"] = 7, ["meta"] = {["fields"] = {}, ["inventory"] = {}}, ["param2"] = 10, ["y"] = 24, ["param1"] = 157, ["z"] = 4, ["name"] = "moreblocks:slope_steelblock"}, {["x"] = 7, ["meta"] = {["fields"] = {}, ["inventory"] = {}}, ["param2"] = 22, ["y"] = 24, ["param1"] = 174, ["z"] = 5, ["name"] = "moreblocks:slope_steelblock"}, {["x"] = 7, ["meta"] = {["fields"] = {}, ["inventory"] = {}}, ["param2"] = 20, ["y"] = 24, ["param1"] = 174, ["z"] = 9, ["name"] = "moreblocks:slope_steelblock"}, {["x"] = 7, ["meta"] = {["fields"] = {}, ["inventory"] = {}}, ["param2"] = 4, ["y"] = 24, ["param1"] = 158, ["z"] = 10, ["name"] = "moreblocks:slope_steelblock"}, {["x"] = 7, ["meta"] = {["fields"] = {}, ["inventory"] = {}}, ["param2"] = 8, ["y"] = 24, ["param1"] = 110, ["z"] = 13, ["name"] = "moreblocks:slope_steelblock_half"}, {["x"] = 7, ["meta"] = {["fields"] = {}, ["inventory"] = {}}, ["param2"] = 4, ["y"] = 24, ["param1"] = 94, ["z"] = 14, ["name"] = "moreblocks:slope_steelblock_half_raised"}, {["x"] = 7, ["meta"] = {["fields"] = {}, ["inventory"] = {}}, ["param2"] = 10, ["y"] = 25, ["param1"] = 126, ["z"] = 0, ["name"] = "moreblocks:slope_steelblock_half"}, {["x"] = 7, ["meta"] = {["fields"] = {}, ["inventory"] = {}}, ["param2"] = 6, ["y"] = 25, ["param1"] = 110, ["z"] = 1, ["name"] = "moreblocks:slope_steelblock_half_raised"}, {["x"] = 7, ["meta"] = {["fields"] = {}, ["inventory"] = {}}, ["param2"] = 10, ["y"] = 25, ["param1"] = 158, ["z"] = 5, ["name"] = "moreblocks:slope_steelblock_half_raised"}, {["x"] = 7, ["meta"] = {["fields"] = {}, ["inventory"] = {}}, ["param2"] = 22, ["y"] = 25, ["param1"] = 174, ["z"] = 6, ["name"] = "moreblocks:slope_steelblock"}, {["x"] = 7, ["meta"] = {["fields"] = {}, ["inventory"] = {}}, ["param2"] = 20, ["y"] = 25, ["param1"] = 174, ["z"] = 8, ["name"] = "moreblocks:slope_steelblock"}, {["x"] = 7, ["meta"] = {["fields"] = {}, ["inventory"] = {}}, ["param2"] = 4, ["y"] = 25, ["param1"] = 158, ["z"] = 9, ["name"] = "moreblocks:slope_steelblock_half_raised"}, {["x"] = 7, ["meta"] = {["fields"] = {}, ["inventory"] = {}}, ["param2"] = 8, ["y"] = 25, ["param1"] = 94, ["z"] = 13, ["name"] = "moreblocks:slope_steelblock_half_raised"}, {["x"] = 7, ["meta"] = {["fields"] = {}, ["inventory"] = {}}, ["param2"] = 4, ["y"] = 25, ["param1"] = 94, ["z"] = 14, ["name"] = "moreblocks:slope_steelblock_half"}, {["x"] = 7, ["meta"] = {["fields"] = {}, ["inventory"] = {}}, ["y"] = 26, ["param1"] = 110, ["z"] = 1, ["name"] = "moreblocks:slope_steelblock"}, {["x"] = 7, ["meta"] = {["fields"] = {}, ["inventory"] = {}}, ["param2"] = 22, ["y"] = 26, ["param1"] = 94, ["z"] = 2, ["name"] = "moreblocks:slope_steelblock_half_raised"}, {["x"] = 7, ["meta"] = {["fields"] = {}, ["inventory"] = {}}, ["param2"] = 22, ["y"] = 26, ["param1"] = 110, ["z"] = 3, ["name"] = "moreblocks:slope_steelblock_half"}, {["x"] = 7, ["meta"] = {["fields"] = {}, ["inventory"] = {}}, ["param2"] = 10, ["y"] = 26, ["param1"] = 142, ["z"] = 5, ["name"] = "moreblocks:slope_steelblock_half"}, {["x"] = 7, ["meta"] = {["fields"] = {}, ["inventory"] = {}}, ["y"] = 26, ["z"] = 6, ["name"] = "default:steelblock"}, {["x"] = 7, ["meta"] = {["fields"] = {}, ["inventory"] = {}}, ["y"] = 26, ["z"] = 8, ["name"] = "default:steelblock"}, {["x"] = 7, ["meta"] = {["fields"] = {}, ["inventory"] = {}}, ["param2"] = 4, ["y"] = 26, ["param1"] = 142, ["z"] = 9, ["name"] = "moreblocks:slope_steelblock_half"}, {["x"] = 7, ["meta"] = {["fields"] = {}, ["inventory"] = {}}, ["param2"] = 20, ["y"] = 26, ["param1"] = 110, ["z"] = 11, ["name"] = "moreblocks:slope_steelblock_half"}, {["x"] = 7, ["meta"] = {["fields"] = {}, ["inventory"] = {}}, ["param2"] = 20, ["y"] = 26, ["param1"] = 94, ["z"] = 12, ["name"] = "moreblocks:slope_steelblock_half_raised"}, {["x"] = 7, ["meta"] = {["fields"] = {}, ["inventory"] = {}}, ["param2"] = 2, ["y"] = 26, ["param1"] = 94, ["z"] = 13, ["name"] = "moreblocks:slope_steelblock"}, {["x"] = 7, ["meta"] = {["fields"] = {}, ["inventory"] = {}}, ["y"] = 27, ["param1"] = 94, ["z"] = 2, ["name"] = "moreblocks:slope_steelblock_half"}, {["x"] = 7, ["meta"] = {["fields"] = {}, ["inventory"] = {}}, ["y"] = 27, ["param1"] = 94, ["z"] = 3, ["name"] = "moreblocks:slope_steelblock_half_raised"}, {["x"] = 7, ["meta"] = {["fields"] = {}, ["inventory"] = {}}, ["y"] = 27, ["z"] = 4, ["name"] = "default:steelblock"}, {["x"] = 7, ["meta"] = {["fields"] = {}, ["inventory"] = {}}, ["y"] = 27, ["z"] = 5, ["name"] = "default:steelblock"}, {["x"] = 7, ["meta"] = {["fields"] = {}, ["inventory"] = {}}, ["y"] = 27, ["z"] = 9, ["name"] = "default:steelblock"}, {["x"] = 7, ["meta"] = {["fields"] = {}, ["inventory"] = {}}, ["y"] = 27, ["z"] = 10, ["name"] = "default:steelblock"}, {["x"] = 7, ["meta"] = {["fields"] = {}, ["inventory"] = {}}, ["param2"] = 2, ["y"] = 27, ["param1"] = 94, ["z"] = 11, ["name"] = "moreblocks:slope_steelblock_half_raised"}, {["x"] = 7, ["meta"] = {["fields"] = {}, ["inventory"] = {}}, ["param2"] = 2, ["y"] = 27, ["param1"] = 94, ["z"] = 12, ["name"] = "moreblocks:slope_steelblock_half"}, {["x"] = 8, ["meta"] = {["fields"] = {}, ["inventory"] = {}}, ["param2"] = 12, ["y"] = 0, ["param1"] = 110, ["z"] = 6, ["name"] = "moreblocks:slope_steelblock"}, {["x"] = 8, ["meta"] = {["fields"] = {}, ["inventory"] = {}}, ["param2"] = 7, ["y"] = 0, ["param1"] = 110, ["z"] = 8, ["name"] = "moreblocks:slope_steelblock"}, {["x"] = 8, ["meta"] = {["fields"] = {}, ["inventory"] = {}}, ["param2"] = 12, ["y"] = 1, ["param1"] = 110, ["z"] = 6, ["name"] = "moreblocks:slope_steelblock"}, {["x"] = 8, ["meta"] = {["fields"] = {}, ["inventory"] = {}}, ["param2"] = 7, ["y"] = 1, ["param1"] = 110, ["z"] = 8, ["name"] = "moreblocks:slope_steelblock"}, {["x"] = 8, ["meta"] = {["fields"] = {}, ["inventory"] = {}}, ["param2"] = 12, ["y"] = 2, ["param1"] = 110, ["z"] = 6, ["name"] = "moreblocks:slope_steelblock"}, {["x"] = 8, ["meta"] = {["fields"] = {}, ["inventory"] = {}}, ["param2"] = 7, ["y"] = 2, ["param1"] = 110, ["z"] = 8, ["name"] = "moreblocks:slope_steelblock"}, {["x"] = 8, ["meta"] = {["fields"] = {}, ["inventory"] = {}}, ["param2"] = 12, ["y"] = 3, ["param1"] = 110, ["z"] = 6, ["name"] = "moreblocks:slope_steelblock"}, {["x"] = 8, ["meta"] = {["fields"] = {}, ["inventory"] = {}}, ["param2"] = 7, ["y"] = 3, ["param1"] = 110, ["z"] = 8, ["name"] = "moreblocks:slope_steelblock"}, {["x"] = 8, ["meta"] = {["fields"] = {}, ["inventory"] = {}}, ["param2"] = 12, ["y"] = 4, ["param1"] = 110, ["z"] = 6, ["name"] = "moreblocks:slope_steelblock"}, {["x"] = 8, ["meta"] = {["fields"] = {}, ["inventory"] = {}}, ["param2"] = 7, ["y"] = 4, ["param1"] = 110, ["z"] = 8, ["name"] = "moreblocks:slope_steelblock"}, {["x"] = 8, ["meta"] = {["fields"] = {}, ["inventory"] = {}}, ["param2"] = 12, ["y"] = 5, ["param1"] = 110, ["z"] = 6, ["name"] = "moreblocks:slope_steelblock"}, {["x"] = 8, ["meta"] = {["fields"] = {}, ["inventory"] = {}}, ["param2"] = 7, ["y"] = 5, ["param1"] = 110, ["z"] = 8, ["name"] = "moreblocks:slope_steelblock"}, {["x"] = 8, ["meta"] = {["fields"] = {}, ["inventory"] = {}}, ["param2"] = 12, ["y"] = 6, ["param1"] = 110, ["z"] = 6, ["name"] = "moreblocks:slope_steelblock"}, {["x"] = 8, ["meta"] = {["fields"] = {}, ["inventory"] = {}}, ["param2"] = 7, ["y"] = 6, ["param1"] = 110, ["z"] = 8, ["name"] = "moreblocks:slope_steelblock"}, {["x"] = 8, ["meta"] = {["fields"] = {}, ["inventory"] = {}}, ["param2"] = 12, ["y"] = 7, ["param1"] = 110, ["z"] = 6, ["name"] = "moreblocks:slope_steelblock"}, {["x"] = 8, ["meta"] = {["fields"] = {}, ["inventory"] = {}}, ["param2"] = 7, ["y"] = 7, ["param1"] = 110, ["z"] = 8, ["name"] = "moreblocks:slope_steelblock"}, {["x"] = 8, ["meta"] = {["fields"] = {}, ["inventory"] = {}}, ["param2"] = 12, ["y"] = 8, ["param1"] = 110, ["z"] = 6, ["name"] = "moreblocks:slope_steelblock"}, {["x"] = 8, ["meta"] = {["fields"] = {}, ["inventory"] = {}}, ["param2"] = 7, ["y"] = 8, ["param1"] = 110, ["z"] = 8, ["name"] = "moreblocks:slope_steelblock"}, {["x"] = 8, ["meta"] = {["fields"] = {}, ["inventory"] = {}}, ["param2"] = 12, ["y"] = 9, ["param1"] = 110, ["z"] = 6, ["name"] = "moreblocks:slope_steelblock"}, {["x"] = 8, ["meta"] = {["fields"] = {}, ["inventory"] = {}}, ["param2"] = 7, ["y"] = 9, ["param1"] = 110, ["z"] = 8, ["name"] = "moreblocks:slope_steelblock"}, {["x"] = 8, ["meta"] = {["fields"] = {}, ["inventory"] = {}}, ["param2"] = 12, ["y"] = 10, ["param1"] = 110, ["z"] = 6, ["name"] = "moreblocks:slope_steelblock"}, {["x"] = 8, ["meta"] = {["fields"] = {}, ["inventory"] = {}}, ["param2"] = 7, ["y"] = 10, ["param1"] = 110, ["z"] = 8, ["name"] = "moreblocks:slope_steelblock"}, {["x"] = 8, ["meta"] = {["fields"] = {}, ["inventory"] = {}}, ["param2"] = 12, ["y"] = 11, ["param1"] = 126, ["z"] = 6, ["name"] = "moreblocks:slope_steelblock"}, {["x"] = 8, ["meta"] = {["fields"] = {}, ["inventory"] = {}}, ["y"] = 11, ["z"] = 7, ["name"] = "default:steelblock"}, {["x"] = 8, ["meta"] = {["fields"] = {}, ["inventory"] = {}}, ["param2"] = 7, ["y"] = 11, ["param1"] = 126, ["z"] = 8, ["name"] = "moreblocks:slope_steelblock"}, {["x"] = 8, ["meta"] = {["fields"] = {}, ["inventory"] = {}}, ["y"] = 12, ["z"] = 7, ["name"] = "default:steelblock"}, {["x"] = 8, ["meta"] = {["fields"] = {}, ["inventory"] = {}}, ["param2"] = 1, ["y"] = 13, ["param1"] = 172, ["z"] = 7, ["name"] = "moreblocks:slope_steelblock"}, {["x"] = 8, ["meta"] = {["fields"] = {}, ["inventory"] = {}}, ["y"] = 16, ["z"] = 2, ["name"] = "default:steelblock"}, {["x"] = 8, ["meta"] = {["fields"] = {}, ["inventory"] = {}}, ["y"] = 16, ["z"] = 3, ["name"] = "default:steelblock"}, {["x"] = 8, ["meta"] = {["fields"] = {}, ["inventory"] = {}}, ["param2"] = 5, ["y"] = 16, ["param1"] = 172, ["z"] = 4, ["name"] = "moreblocks:slope_steelblock_half"}, {["x"] = 8, ["meta"] = {["fields"] = {}, ["inventory"] = {}}, ["param2"] = 9, ["y"] = 16, ["param1"] = 175, ["z"] = 10, ["name"] = "moreblocks:slope_steelblock_half"}, {["x"] = 8, ["meta"] = {["fields"] = {}, ["inventory"] = {}}, ["y"] = 16, ["z"] = 11, ["name"] = "default:steelblock"}, {["x"] = 8, ["meta"] = {["fields"] = {}, ["inventory"] = {}}, ["y"] = 16, ["z"] = 12, ["name"] = "default:steelblock"}, {["x"] = 8, ["meta"] = {["fields"] = {}, ["inventory"] = {}}, ["y"] = 19, ["z"] = 0, ["name"] = "default:steelblock"}, {["x"] = 8, ["meta"] = {["fields"] = {}, ["inventory"] = {}}, ["param2"] = 12, ["y"] = 19, ["param1"] = 238, ["z"] = 7, ["name"] = "rainbow:slab_lightblock_cyan_1"}, {["x"] = 8, ["meta"] = {["fields"] = {}, ["inventory"] = {}}, ["y"] = 19, ["z"] = 14, ["name"] = "default:steelblock"}, {["x"] = 8, ["meta"] = {["fields"] = {}, ["inventory"] = {}}, ["y"] = 22, ["z"] = 2, ["name"] = "default:steelblock"}, {["x"] = 8, ["meta"] = {["fields"] = {}, ["inventory"] = {}}, ["y"] = 22, ["z"] = 3, ["name"] = "default:steelblock"}, {["x"] = 8, ["meta"] = {["fields"] = {}, ["inventory"] = {}}, ["param2"] = 5, ["y"] = 22, ["param1"] = 173, ["z"] = 4, ["name"] = "moreblocks:slope_steelblock_half"}, {["x"] = 8, ["meta"] = {["fields"] = {}, ["inventory"] = {}}, ["param2"] = 9, ["y"] = 22, ["param1"] = 175, ["z"] = 10, ["name"] = "moreblocks:slope_steelblock_half"}, {["x"] = 8, ["meta"] = {["fields"] = {}, ["inventory"] = {}}, ["y"] = 22, ["z"] = 11, ["name"] = "default:steelblock"}, {["x"] = 8, ["meta"] = {["fields"] = {}, ["inventory"] = {}}, ["y"] = 22, ["z"] = 12, ["name"] = "default:steelblock"}, {["x"] = 8, ["meta"] = {["fields"] = {}, ["inventory"] = {}}, ["param2"] = 23, ["y"] = 25, ["param1"] = 173, ["z"] = 7, ["name"] = "moreblocks:slope_steelblock"}, {["x"] = 8, ["meta"] = {["fields"] = {}, ["inventory"] = {}}, ["y"] = 26, ["z"] = 7, ["name"] = "default:steelblock"}, {["x"] = 8, ["meta"] = {["fields"] = {}, ["inventory"] = {}}, ["param2"] = 12, ["y"] = 27, ["param1"] = 126, ["z"] = 6, ["name"] = "moreblocks:slope_steelblock"}, {["x"] = 8, ["meta"] = {["fields"] = {}, ["inventory"] = {}}, ["param2"] = 7, ["y"] = 27, ["param1"] = 126, ["z"] = 8, ["name"] = "moreblocks:slope_steelblock"}, {["x"] = 9, ["meta"] = {["fields"] = {}, ["inventory"] = {}}, ["param2"] = 12, ["y"] = 0, ["param1"] = 126, ["z"] = 7, ["name"] = "moreblocks:slab_steelblock_1"}, {["x"] = 9, ["meta"] = {["fields"] = {}, ["inventory"] = {}}, ["param2"] = 12, ["y"] = 1, ["param1"] = 126, ["z"] = 7, ["name"] = "moreblocks:slab_steelblock_1"}, {["x"] = 9, ["meta"] = {["fields"] = {}, ["inventory"] = {}}, ["param2"] = 12, ["y"] = 2, ["param1"] = 126, ["z"] = 7, ["name"] = "moreblocks:slab_steelblock_1"}, {["x"] = 9, ["meta"] = {["fields"] = {}, ["inventory"] = {}}, ["param2"] = 12, ["y"] = 3, ["param1"] = 126, ["z"] = 7, ["name"] = "moreblocks:slab_steelblock_1"}, {["x"] = 9, ["meta"] = {["fields"] = {}, ["inventory"] = {}}, ["param2"] = 12, ["y"] = 4, ["param1"] = 126, ["z"] = 7, ["name"] = "moreblocks:slab_steelblock_1"}, {["x"] = 9, ["meta"] = {["fields"] = {}, ["inventory"] = {}}, ["param2"] = 12, ["y"] = 5, ["param1"] = 126, ["z"] = 7, ["name"] = "moreblocks:slab_steelblock_1"}, {["x"] = 9, ["meta"] = {["fields"] = {}, ["inventory"] = {}}, ["param2"] = 12, ["y"] = 6, ["param1"] = 126, ["z"] = 7, ["name"] = "moreblocks:slab_steelblock_1"}, {["x"] = 9, ["meta"] = {["fields"] = {}, ["inventory"] = {}}, ["param2"] = 12, ["y"] = 7, ["param1"] = 126, ["z"] = 7, ["name"] = "moreblocks:slab_steelblock_1"}, {["x"] = 9, ["meta"] = {["fields"] = {}, ["inventory"] = {}}, ["param2"] = 12, ["y"] = 8, ["param1"] = 126, ["z"] = 7, ["name"] = "moreblocks:slab_steelblock_1"}, {["x"] = 9, ["meta"] = {["fields"] = {}, ["inventory"] = {}}, ["param2"] = 12, ["y"] = 9, ["param1"] = 126, ["z"] = 7, ["name"] = "moreblocks:slab_steelblock_1"}, {["x"] = 9, ["meta"] = {["fields"] = {}, ["inventory"] = {}}, ["param2"] = 12, ["y"] = 10, ["param1"] = 126, ["z"] = 7, ["name"] = "moreblocks:slab_steelblock_1"}, {["x"] = 9, ["meta"] = {["fields"] = {}, ["inventory"] = {}}, ["y"] = 11, ["z"] = 7, ["name"] = "default:steelblock"}, {["x"] = 9, ["meta"] = {["fields"] = {}, ["inventory"] = {}}, ["param2"] = 15, ["y"] = 12, ["param1"] = 141, ["z"] = 7, ["name"] = "moreblocks:slope_steelblock_half"}, {["x"] = 9, ["meta"] = {["fields"] = {}, ["inventory"] = {}}, ["param2"] = 15, ["y"] = 13, ["param1"] = 157, ["z"] = 7, ["name"] = "moreblocks:slope_steelblock_half_raised"}, {["x"] = 9, ["meta"] = {["fields"] = {}, ["inventory"] = {}}, ["param2"] = 1, ["y"] = 14, ["param1"] = 174, ["z"] = 7, ["name"] = "moreblocks:slope_steelblock"}, {["x"] = 9, ["meta"] = {["fields"] = {}, ["inventory"] = {}}, ["param2"] = 11, ["y"] = 16, ["param1"] = 127, ["z"] = 2, ["name"] = "moreblocks:slope_steelblock_half_raised"}, {["x"] = 9, ["meta"] = {["fields"] = {}, ["inventory"] = {}}, ["y"] = 16, ["z"] = 3, ["name"] = "default:steelblock"}, {["x"] = 9, ["meta"] = {["fields"] = {}, ["inventory"] = {}}, ["param2"] = 5, ["y"] = 16, ["param1"] = 157, ["z"] = 4, ["name"] = "moreblocks:slope_steelblock_half_raised"}, {["x"] = 9, ["meta"] = {["fields"] = {}, ["inventory"] = {}}, ["param2"] = 9, ["y"] = 16, ["param1"] = 159, ["z"] = 10, ["name"] = "moreblocks:slope_steelblock_half_raised"}, {["x"] = 9, ["meta"] = {["fields"] = {}, ["inventory"] = {}}, ["y"] = 16, ["z"] = 11, ["name"] = "default:steelblock"}, {["x"] = 9, ["meta"] = {["fields"] = {}, ["inventory"] = {}}, ["param2"] = 7, ["y"] = 16, ["param1"] = 127, ["z"] = 12, ["name"] = "moreblocks:slope_steelblock_half_raised"}, {["x"] = 9, ["meta"] = {["fields"] = {}, ["inventory"] = {}}, ["param2"] = 11, ["y"] = 19, ["param1"] = 143, ["z"] = 0, ["name"] = "moreblocks:slope_steelblock_half_raised"}, {["x"] = 9, ["meta"] = {["fields"] = {}, ["inventory"] = {}}, ["param2"] = 5, ["y"] = 19, ["param1"] = 159, ["z"] = 1, ["name"] = "moreblocks:slope_steelblock_half"}, {["x"] = 9, ["meta"] = {["fields"] = {}, ["inventory"] = {}}, ["param2"] = 12, ["y"] = 19, ["param1"] = 238, ["z"] = 7, ["name"] = "rainbow:slab_lightblock_cyan_1"}, {["x"] = 9, ["meta"] = {["fields"] = {}, ["inventory"] = {}}, ["param2"] = 9, ["y"] = 19, ["param1"] = 159, ["z"] = 13, ["name"] = "moreblocks:slope_steelblock_half"}, {["x"] = 9, ["meta"] = {["fields"] = {}, ["inventory"] = {}}, ["param2"] = 7, ["y"] = 19, ["param1"] = 143, ["z"] = 14, ["name"] = "moreblocks:slope_steelblock_half_raised"}, {["x"] = 9, ["meta"] = {["fields"] = {}, ["inventory"] = {}}, ["param2"] = 11, ["y"] = 22, ["param1"] = 127, ["z"] = 2, ["name"] = "moreblocks:slope_steelblock_half_raised"}, {["x"] = 9, ["meta"] = {["fields"] = {}, ["inventory"] = {}}, ["y"] = 22, ["z"] = 3, ["name"] = "default:steelblock"}, {["x"] = 9, ["meta"] = {["fields"] = {}, ["inventory"] = {}}, ["param2"] = 5, ["y"] = 22, ["param1"] = 157, ["z"] = 4, ["name"] = "moreblocks:slope_steelblock_half_raised"}, {["x"] = 9, ["meta"] = {["fields"] = {}, ["inventory"] = {}}, ["param2"] = 9, ["y"] = 22, ["param1"] = 159, ["z"] = 10, ["name"] = "moreblocks:slope_steelblock_half_raised"}, {["x"] = 9, ["meta"] = {["fields"] = {}, ["inventory"] = {}}, ["y"] = 22, ["z"] = 11, ["name"] = "default:steelblock"}, {["x"] = 9, ["meta"] = {["fields"] = {}, ["inventory"] = {}}, ["param2"] = 7, ["y"] = 22, ["param1"] = 127, ["z"] = 12, ["name"] = "moreblocks:slope_steelblock_half_raised"}, {["x"] = 9, ["meta"] = {["fields"] = {}, ["inventory"] = {}}, ["param2"] = 23, ["y"] = 24, ["param1"] = 174, ["z"] = 7, ["name"] = "moreblocks:slope_steelblock"}, {["x"] = 9, ["meta"] = {["fields"] = {}, ["inventory"] = {}}, ["param2"] = 13, ["y"] = 25, ["param1"] = 158, ["z"] = 7, ["name"] = "moreblocks:slope_steelblock_half_raised"}, {["x"] = 9, ["meta"] = {["fields"] = {}, ["inventory"] = {}}, ["param2"] = 13, ["y"] = 26, ["param1"] = 142, ["z"] = 7, ["name"] = "moreblocks:slope_steelblock_half"}, {["x"] = 9, ["meta"] = {["fields"] = {}, ["inventory"] = {}}, ["y"] = 27, ["z"] = 7, ["name"] = "default:steelblock"}, {["x"] = 10, ["meta"] = {["fields"] = {}, ["inventory"] = {}}, ["y"] = 11, ["z"] = 7, ["name"] = "default:steelblock"}, {["x"] = 10, ["meta"] = {["fields"] = {}, ["inventory"] = {}}, ["param2"] = 15, ["y"] = 14, ["param1"] = 158, ["z"] = 7, ["name"] = "moreblocks:slope_steelblock"}, {["x"] = 10, ["meta"] = {["fields"] = {}, ["inventory"] = {}}, ["param2"] = 1, ["y"] = 15, ["param1"] = 174, ["z"] = 7, ["name"] = "moreblocks:slope_steelblock"}, {["x"] = 10, ["meta"] = {["fields"] = {}, ["inventory"] = {}}, ["param2"] = 11, ["y"] = 16, ["param1"] = 143, ["z"] = 2, ["name"] = "moreblocks:slope_steelblock_half"}, {["x"] = 10, ["meta"] = {["fields"] = {}, ["inventory"] = {}}, ["y"] = 16, ["z"] = 3, ["name"] = "default:steelblock"}, {["x"] = 10, ["meta"] = {["fields"] = {}, ["inventory"] = {}}, ["y"] = 16, ["z"] = 4, ["name"] = "default:steelblock"}, {["x"] = 10, ["meta"] = {["fields"] = {}, ["inventory"] = {}}, ["param2"] = 18, ["y"] = 16, ["param1"] = 158, ["z"] = 5, ["name"] = "moreblocks:slope_steelblock_half_raised"}, {["x"] = 10, ["meta"] = {["fields"] = {}, ["inventory"] = {}}, ["param2"] = 18, ["y"] = 16, ["param1"] = 175, ["z"] = 6, ["name"] = "moreblocks:slope_steelblock_half"}, {["x"] = 10, ["meta"] = {["fields"] = {}, ["inventory"] = {}}, ["param2"] = 16, ["y"] = 16, ["param1"] = 175, ["z"] = 8, ["name"] = "moreblocks:slope_steelblock_half"}, {["x"] = 10, ["meta"] = {["fields"] = {}, ["inventory"] = {}}, ["param2"] = 16, ["y"] = 16, ["param1"] = 159, ["z"] = 9, ["name"] = "moreblocks:slope_steelblock_half_raised"}, {["x"] = 10, ["meta"] = {["fields"] = {}, ["inventory"] = {}}, ["y"] = 16, ["z"] = 10, ["name"] = "default:steelblock"}, {["x"] = 10, ["meta"] = {["fields"] = {}, ["inventory"] = {}}, ["y"] = 16, ["z"] = 11, ["name"] = "default:steelblock"}, {["x"] = 10, ["meta"] = {["fields"] = {}, ["inventory"] = {}}, ["param2"] = 7, ["y"] = 16, ["param1"] = 143, ["z"] = 12, ["name"] = "moreblocks:slope_steelblock_half"}, {["x"] = 10, ["meta"] = {["fields"] = {}, ["inventory"] = {}}, ["param2"] = 11, ["y"] = 19, ["param1"] = 143, ["z"] = 0, ["name"] = "moreblocks:slope_steelblock_half"}, {["x"] = 10, ["meta"] = {["fields"] = {}, ["inventory"] = {}}, ["param2"] = 5, ["y"] = 19, ["param1"] = 143, ["z"] = 1, ["name"] = "moreblocks:slope_steelblock_half_raised"}, {["x"] = 10, ["meta"] = {["fields"] = {}, ["inventory"] = {}}, ["param2"] = 12, ["y"] = 19, ["param1"] = 238, ["z"] = 7, ["name"] = "rainbow:slab_lightblock_cyan_1"}, {["x"] = 10, ["meta"] = {["fields"] = {}, ["inventory"] = {}}, ["param2"] = 9, ["y"] = 19, ["param1"] = 143, ["z"] = 13, ["name"] = "moreblocks:slope_steelblock_half_raised"}, {["x"] = 10, ["meta"] = {["fields"] = {}, ["inventory"] = {}}, ["param2"] = 7, ["y"] = 19, ["param1"] = 143, ["z"] = 14, ["name"] = "moreblocks:slope_steelblock_half"}, {["x"] = 10, ["meta"] = {["fields"] = {}, ["inventory"] = {}}, ["param2"] = 11, ["y"] = 22, ["param1"] = 143, ["z"] = 2, ["name"] = "moreblocks:slope_steelblock_half"}, {["x"] = 10, ["meta"] = {["fields"] = {}, ["inventory"] = {}}, ["y"] = 22, ["z"] = 3, ["name"] = "default:steelblock"}, {["x"] = 10, ["meta"] = {["fields"] = {}, ["inventory"] = {}}, ["y"] = 22, ["z"] = 4, ["name"] = "default:steelblock"}, {["x"] = 10, ["meta"] = {["fields"] = {}, ["inventory"] = {}}, ["param2"] = 18, ["y"] = 22, ["param1"] = 158, ["z"] = 5, ["name"] = "moreblocks:slope_steelblock_half_raised"}, {["x"] = 10, ["meta"] = {["fields"] = {}, ["inventory"] = {}}, ["param2"] = 18, ["y"] = 22, ["param1"] = 175, ["z"] = 6, ["name"] = "moreblocks:slope_steelblock_half"}, {["x"] = 10, ["meta"] = {["fields"] = {}, ["inventory"] = {}}, ["param2"] = 16, ["y"] = 22, ["param1"] = 175, ["z"] = 8, ["name"] = "moreblocks:slope_steelblock_half"}, {["x"] = 10, ["meta"] = {["fields"] = {}, ["inventory"] = {}}, ["param2"] = 16, ["y"] = 22, ["param1"] = 159, ["z"] = 9, ["name"] = "moreblocks:slope_steelblock_half_raised"}, {["x"] = 10, ["meta"] = {["fields"] = {}, ["inventory"] = {}}, ["y"] = 22, ["z"] = 10, ["name"] = "default:steelblock"}, {["x"] = 10, ["meta"] = {["fields"] = {}, ["inventory"] = {}}, ["y"] = 22, ["z"] = 11, ["name"] = "default:steelblock"}, {["x"] = 10, ["meta"] = {["fields"] = {}, ["inventory"] = {}}, ["param2"] = 7, ["y"] = 22, ["param1"] = 143, ["z"] = 12, ["name"] = "moreblocks:slope_steelblock_half"}, {["x"] = 10, ["meta"] = {["fields"] = {}, ["inventory"] = {}}, ["param2"] = 23, ["y"] = 23, ["param1"] = 174, ["z"] = 7, ["name"] = "moreblocks:slope_steelblock"}, {["x"] = 10, ["meta"] = {["fields"] = {}, ["inventory"] = {}}, ["param2"] = 13, ["y"] = 24, ["param1"] = 158, ["z"] = 7, ["name"] = "moreblocks:slope_steelblock"}, {["x"] = 10, ["meta"] = {["fields"] = {}, ["inventory"] = {}}, ["y"] = 27, ["z"] = 7, ["name"] = "default:steelblock"}, {["x"] = 11, ["meta"] = {["fields"] = {}, ["inventory"] = {}}, ["param2"] = 21, ["y"] = 11, ["param1"] = 158, ["z"] = 7, ["name"] = "moreblocks:slope_steelblock_half_raised"}, {["x"] = 11, ["meta"] = {["fields"] = {}, ["inventory"] = {}}, ["param2"] = 1, ["y"] = 12, ["param1"] = 157, ["z"] = 7, ["name"] = "moreblocks:slope_steelblock_half"}, {["x"] = 11, ["meta"] = {["fields"] = {}, ["inventory"] = {}}, ["param2"] = 21, ["y"] = 15, ["param1"] = 157, ["z"] = 7, ["name"] = "moreblocks:slope_steelblock_half_raised"}, {["x"] = 11, ["meta"] = {["fields"] = {}, ["inventory"] = {}}, ["param2"] = 12, ["y"] = 16, ["param1"] = 159, ["z"] = 3, ["name"] = "moreblocks:slope_steelblock"}, {["x"] = 11, ["meta"] = {["fields"] = {}, ["inventory"] = {}}, ["y"] = 16, ["z"] = 4, ["name"] = "default:steelblock"}, {["x"] = 11, ["meta"] = {["fields"] = {}, ["inventory"] = {}}, ["y"] = 16, ["z"] = 5, ["name"] = "default:steelblock"}, {["x"] = 11, ["meta"] = {["fields"] = {}, ["inventory"] = {}}, ["y"] = 16, ["z"] = 6, ["name"] = "default:steelblock"}, {["x"] = 11, ["meta"] = {["fields"] = {}, ["inventory"] = {}}, ["y"] = 16, ["z"] = 7, ["name"] = "default:steelblock"}, {["x"] = 11, ["meta"] = {["fields"] = {}, ["inventory"] = {}}, ["y"] = 16, ["z"] = 8, ["name"] = "default:steelblock"}, {["x"] = 11, ["meta"] = {["fields"] = {}, ["inventory"] = {}}, ["y"] = 16, ["z"] = 9, ["name"] = "default:steelblock"}, {["x"] = 11, ["meta"] = {["fields"] = {}, ["inventory"] = {}}, ["y"] = 16, ["z"] = 10, ["name"] = "default:steelblock"}, {["x"] = 11, ["meta"] = {["fields"] = {}, ["inventory"] = {}}, ["param2"] = 7, ["y"] = 16, ["param1"] = 159, ["z"] = 11, ["name"] = "moreblocks:slope_steelblock"}, {["x"] = 11, ["meta"] = {["fields"] = {}, ["inventory"] = {}}, ["param2"] = 12, ["y"] = 19, ["param1"] = 159, ["z"] = 1, ["name"] = "moreblocks:slope_steelblock"}, {["x"] = 11, ["meta"] = {["fields"] = {}, ["inventory"] = {}}, ["param2"] = 18, ["y"] = 19, ["param1"] = 159, ["z"] = 2, ["name"] = "moreblocks:slope_steelblock"}, {["x"] = 11, ["meta"] = {["fields"] = {}, ["inventory"] = {}}, ["param2"] = 9, ["y"] = 19, ["param1"] = 159, ["z"] = 12, ["name"] = "moreblocks:slope_steelblock"}, {["x"] = 11, ["meta"] = {["fields"] = {}, ["inventory"] = {}}, ["param2"] = 7, ["y"] = 19, ["param1"] = 159, ["z"] = 13, ["name"] = "moreblocks:slope_steelblock"}, {["x"] = 11, ["meta"] = {["fields"] = {}, ["inventory"] = {}}, ["param2"] = 12, ["y"] = 22, ["param1"] = 159, ["z"] = 3, ["name"] = "moreblocks:slope_steelblock"}, {["x"] = 11, ["meta"] = {["fields"] = {}, ["inventory"] = {}}, ["y"] = 22, ["z"] = 4, ["name"] = "default:steelblock"}, {["x"] = 11, ["meta"] = {["fields"] = {}, ["inventory"] = {}}, ["y"] = 22, ["z"] = 5, ["name"] = "default:steelblock"}, {["x"] = 11, ["meta"] = {["fields"] = {}, ["inventory"] = {}}, ["y"] = 22, ["z"] = 6, ["name"] = "default:steelblock"}, {["x"] = 11, ["meta"] = {["fields"] = {}, ["inventory"] = {}}, ["y"] = 22, ["z"] = 7, ["name"] = "default:steelblock"}, {["x"] = 11, ["meta"] = {["fields"] = {}, ["inventory"] = {}}, ["y"] = 22, ["z"] = 8, ["name"] = "default:steelblock"}, {["x"] = 11, ["meta"] = {["fields"] = {}, ["inventory"] = {}}, ["y"] = 22, ["z"] = 9, ["name"] = "default:steelblock"}, {["x"] = 11, ["meta"] = {["fields"] = {}, ["inventory"] = {}}, ["y"] = 22, ["z"] = 10, ["name"] = "default:steelblock"}, {["x"] = 11, ["meta"] = {["fields"] = {}, ["inventory"] = {}}, ["param2"] = 7, ["y"] = 22, ["param1"] = 159, ["z"] = 11, ["name"] = "moreblocks:slope_steelblock"}, {["x"] = 11, ["meta"] = {["fields"] = {}, ["inventory"] = {}}, ["param2"] = 3, ["y"] = 23, ["param1"] = 158, ["z"] = 7, ["name"] = "moreblocks:slope_steelblock_half_raised"}, {["x"] = 11, ["meta"] = {["fields"] = {}, ["inventory"] = {}}, ["param2"] = 23, ["y"] = 26, ["param1"] = 158, ["z"] = 7, ["name"] = "moreblocks:slope_steelblock_half"}, {["x"] = 11, ["meta"] = {["fields"] = {}, ["inventory"] = {}}, ["param2"] = 3, ["y"] = 27, ["param1"] = 158, ["z"] = 7, ["name"] = "moreblocks:slope_steelblock_half_raised"}, {["x"] = 12, ["meta"] = {["fields"] = {}, ["inventory"] = {}}, ["param2"] = 21, ["y"] = 11, ["param1"] = 174, ["z"] = 7, ["name"] = "moreblocks:slope_steelblock_half"}, {["x"] = 12, ["meta"] = {["fields"] = {}, ["inventory"] = {}}, ["param2"] = 1, ["y"] = 12, ["param1"] = 173, ["z"] = 7, ["name"] = "moreblocks:slope_steelblock_half_raised"}, {["x"] = 12, ["meta"] = {["fields"] = {}, ["inventory"] = {}}, ["param2"] = 21, ["y"] = 15, ["param1"] = 157, ["z"] = 7, ["name"] = "moreblocks:slope_steelblock_half"}, {["x"] = 12, ["meta"] = {["fields"] = {}, ["inventory"] = {}}, ["param2"] = 12, ["y"] = 16, ["param1"] = 174, ["z"] = 4, ["name"] = "moreblocks:slope_steelblock_half"}, {["x"] = 12, ["meta"] = {["fields"] = {}, ["inventory"] = {}}, ["param2"] = 12, ["y"] = 16, ["param1"] = 173, ["z"] = 5, ["name"] = "moreblocks:slope_steelblock_half_raised"}, {["x"] = 12, ["meta"] = {["fields"] = {}, ["inventory"] = {}}, ["y"] = 16, ["z"] = 6, ["name"] = "default:steelblock"}, {["x"] = 12, ["meta"] = {["fields"] = {}, ["inventory"] = {}}, ["y"] = 16, ["z"] = 7, ["name"] = "default:steelblock"}, {["x"] = 12, ["meta"] = {["fields"] = {}, ["inventory"] = {}}, ["y"] = 16, ["z"] = 8, ["name"] = "default:steelblock"}, {["x"] = 12, ["meta"] = {["fields"] = {}, ["inventory"] = {}}, ["param2"] = 14, ["y"] = 16, ["param1"] = 175, ["z"] = 9, ["name"] = "moreblocks:slope_steelblock_half_raised"}, {["x"] = 12, ["meta"] = {["fields"] = {}, ["inventory"] = {}}, ["param2"] = 14, ["y"] = 16, ["param1"] = 175, ["z"] = 10, ["name"] = "moreblocks:slope_steelblock_half"}, {["x"] = 12, ["meta"] = {["fields"] = {}, ["inventory"] = {}}, ["param2"] = 12, ["y"] = 19, ["param1"] = 175, ["z"] = 2, ["name"] = "moreblocks:slope_steelblock"}, {["x"] = 12, ["meta"] = {["fields"] = {}, ["inventory"] = {}}, ["param2"] = 18, ["y"] = 19, ["param1"] = 175, ["z"] = 3, ["name"] = "moreblocks:slope_steelblock"}, {["x"] = 12, ["meta"] = {["fields"] = {}, ["inventory"] = {}}, ["param2"] = 16, ["y"] = 19, ["param1"] = 175, ["z"] = 11, ["name"] = "moreblocks:slope_steelblock"}, {["x"] = 12, ["meta"] = {["fields"] = {}, ["inventory"] = {}}, ["param2"] = 7, ["y"] = 19, ["param1"] = 175, ["z"] = 12, ["name"] = "moreblocks:slope_steelblock"}, {["x"] = 12, ["meta"] = {["fields"] = {}, ["inventory"] = {}}, ["param2"] = 12, ["y"] = 22, ["param1"] = 174, ["z"] = 4, ["name"] = "moreblocks:slope_steelblock_half"}, {["x"] = 12, ["meta"] = {["fields"] = {}, ["inventory"] = {}}, ["param2"] = 12, ["y"] = 22, ["param1"] = 173, ["z"] = 5, ["name"] = "moreblocks:slope_steelblock_half_raised"}, {["x"] = 12, ["meta"] = {["fields"] = {}, ["inventory"] = {}}, ["y"] = 22, ["z"] = 6, ["name"] = "default:steelblock"}, {["x"] = 12, ["meta"] = {["fields"] = {}, ["inventory"] = {}}, ["y"] = 22, ["z"] = 7, ["name"] = "default:steelblock"}, {["x"] = 12, ["meta"] = {["fields"] = {}, ["inventory"] = {}}, ["y"] = 22, ["z"] = 8, ["name"] = "default:steelblock"}, {["x"] = 12, ["meta"] = {["fields"] = {}, ["inventory"] = {}}, ["param2"] = 14, ["y"] = 22, ["param1"] = 175, ["z"] = 9, ["name"] = "moreblocks:slope_steelblock_half_raised"}, {["x"] = 12, ["meta"] = {["fields"] = {}, ["inventory"] = {}}, ["param2"] = 14, ["y"] = 22, ["param1"] = 175, ["z"] = 10, ["name"] = "moreblocks:slope_steelblock_half"}, {["x"] = 12, ["meta"] = {["fields"] = {}, ["inventory"] = {}}, ["param2"] = 3, ["y"] = 23, ["param1"] = 158, ["z"] = 7, ["name"] = "moreblocks:slope_steelblock_half"}, {["x"] = 12, ["meta"] = {["fields"] = {}, ["inventory"] = {}}, ["param2"] = 23, ["y"] = 26, ["param1"] = 174, ["z"] = 7, ["name"] = "moreblocks:slope_steelblock_half_raised"}, {["x"] = 12, ["meta"] = {["fields"] = {}, ["inventory"] = {}}, ["param2"] = 3, ["y"] = 27, ["param1"] = 174, ["z"] = 7, ["name"] = "moreblocks:slope_steelblock_half"}, {["x"] = 13, ["meta"] = {["fields"] = {}, ["inventory"] = {}}, ["param2"] = 15, ["y"] = 12, ["param1"] = 189, ["z"] = 7, ["name"] = "moreblocks:slope_steelblock"}, {["x"] = 13, ["meta"] = {["fields"] = {}, ["inventory"] = {}}, ["param2"] = 19, ["y"] = 13, ["param1"] = 189, ["z"] = 7, ["name"] = "moreblocks:slope_steelblock_half_raised"}, {["x"] = 13, ["meta"] = {["fields"] = {}, ["inventory"] = {}}, ["param2"] = 19, ["y"] = 14, ["param1"] = 190, ["z"] = 7, ["name"] = "moreblocks:slope_steelblock_half"}, {["x"] = 13, ["meta"] = {["fields"] = {}, ["inventory"] = {}}, ["param2"] = 12, ["y"] = 19, ["param1"] = 191, ["z"] = 3, ["name"] = "moreblocks:slope_steelblock"}, {["x"] = 13, ["meta"] = {["fields"] = {}, ["inventory"] = {}}, ["param2"] = 18, ["y"] = 19, ["param1"] = 190, ["z"] = 4, ["name"] = "moreblocks:slope_steelblock_half_raised"}, {["x"] = 13, ["meta"] = {["fields"] = {}, ["inventory"] = {}}, ["param2"] = 18, ["y"] = 19, ["param1"] = 190, ["z"] = 5, ["name"] = "moreblocks:slope_steelblock_half"}, {["x"] = 13, ["meta"] = {["fields"] = {}, ["inventory"] = {}}, ["param2"] = 16, ["y"] = 19, ["param1"] = 191, ["z"] = 9, ["name"] = "moreblocks:slope_steelblock_half"}, {["x"] = 13, ["meta"] = {["fields"] = {}, ["inventory"] = {}}, ["param2"] = 16, ["y"] = 19, ["param1"] = 191, ["z"] = 10, ["name"] = "moreblocks:slope_steelblock_half_raised"}, {["x"] = 13, ["meta"] = {["fields"] = {}, ["inventory"] = {}}, ["param2"] = 7, ["y"] = 19, ["param1"] = 191, ["z"] = 11, ["name"] = "moreblocks:slope_steelblock"}, {["x"] = 13, ["meta"] = {["fields"] = {}, ["inventory"] = {}}, ["param2"] = 17, ["y"] = 24, ["param1"] = 190, ["z"] = 7, ["name"] = "moreblocks:slope_steelblock_half"}, {["x"] = 13, ["meta"] = {["fields"] = {}, ["inventory"] = {}}, ["param2"] = 17, ["y"] = 25, ["param1"] = 190, ["z"] = 7, ["name"] = "moreblocks:slope_steelblock_half_raised"}, {["x"] = 13, ["meta"] = {["fields"] = {}, ["inventory"] = {}}, ["param2"] = 3, ["y"] = 26, ["param1"] = 190, ["z"] = 7, ["name"] = "moreblocks:slope_steelblock"}, {["x"] = 14, ["meta"] = {["fields"] = {}, ["inventory"] = {}}, ["param2"] = 15, ["y"] = 13, ["param1"] = 205, ["z"] = 7, ["name"] = "moreblocks:slope_steelblock_half"}, {["x"] = 14, ["meta"] = {["fields"] = {}, ["inventory"] = {}}, ["param2"] = 15, ["y"] = 14, ["param1"] = 206, ["z"] = 7, ["name"] = "moreblocks:slope_steelblock_half_raised"}, {["x"] = 14, ["meta"] = {["fields"] = {}, ["inventory"] = {}}, ["y"] = 15, ["z"] = 7, ["name"] = "default:steelblock"}, {["x"] = 14, ["meta"] = {["fields"] = {}, ["inventory"] = {}}, ["y"] = 16, ["z"] = 7, ["name"] = "default:steelblock"}, {["x"] = 14, ["meta"] = {["fields"] = {}, ["inventory"] = {}}, ["y"] = 17, ["z"] = 7, ["name"] = "default:steelblock"}, {["x"] = 14, ["meta"] = {["fields"] = {}, ["inventory"] = {}}, ["y"] = 18, ["z"] = 7, ["name"] = "default:steelblock"}, {["x"] = 14, ["meta"] = {["fields"] = {}, ["inventory"] = {}}, ["param2"] = 12, ["y"] = 19, ["param1"] = 206, ["z"] = 4, ["name"] = "moreblocks:slope_steelblock_half"}, {["x"] = 14, ["meta"] = {["fields"] = {}, ["inventory"] = {}}, ["param2"] = 12, ["y"] = 19, ["param1"] = 205, ["z"] = 5, ["name"] = "moreblocks:slope_steelblock_half_raised"}, {["x"] = 14, ["meta"] = {["fields"] = {}, ["inventory"] = {}}, ["y"] = 19, ["z"] = 6, ["name"] = "default:steelblock"}, {["x"] = 14, ["meta"] = {["fields"] = {}, ["inventory"] = {}}, ["y"] = 19, ["z"] = 7, ["name"] = "default:steelblock"}, {["x"] = 14, ["meta"] = {["fields"] = {}, ["inventory"] = {}}, ["y"] = 19, ["z"] = 8, ["name"] = "default:steelblock"}, {["x"] = 14, ["meta"] = {["fields"] = {}, ["inventory"] = {}}, ["param2"] = 14, ["y"] = 19, ["param1"] = 207, ["z"] = 9, ["name"] = "moreblocks:slope_steelblock_half_raised"}, {["x"] = 14, ["meta"] = {["fields"] = {}, ["inventory"] = {}}, ["param2"] = 14, ["y"] = 19, ["param1"] = 207, ["z"] = 10, ["name"] = "moreblocks:slope_steelblock_half"}, {["x"] = 14, ["meta"] = {["fields"] = {}, ["inventory"] = {}}, ["y"] = 20, ["z"] = 7, ["name"] = "default:steelblock"}, {["x"] = 14, ["meta"] = {["fields"] = {}, ["inventory"] = {}}, ["y"] = 21, ["z"] = 7, ["name"] = "default:steelblock"}, {["x"] = 14, ["meta"] = {["fields"] = {}, ["inventory"] = {}}, ["y"] = 22, ["z"] = 7, ["name"] = "default:steelblock"}, {["x"] = 14, ["meta"] = {["fields"] = {}, ["inventory"] = {}}, ["y"] = 23, ["z"] = 7, ["name"] = "default:steelblock"}, {["x"] = 14, ["meta"] = {["fields"] = {}, ["inventory"] = {}}, ["param2"] = 13, ["y"] = 24, ["param1"] = 207, ["z"] = 7, ["name"] = "moreblocks:slope_steelblock_half_raised"}, {["x"] = 14, ["meta"] = {["fields"] = {}, ["inventory"] = {}}, ["param2"] = 13, ["y"] = 25, ["param1"] = 207, ["z"] = 7, ["name"] = "moreblocks:slope_steelblock_half"}}