5:return {{["x"] = 0, ["meta"] = {["fields"] = {}, ["inventory"] = {}}, ["y"] = 0, ["param1"] = 143, ["z"] = 0, ["name"] = "maptools:grass"}, {["x"] = 0, ["meta"] = {["fields"] = {}, ["inventory"] = {}}, ["y"] = 0, ["param1"] = 159, ["z"] = 1, ["name"] = "maptools:grass"}, {["x"] = 0, ["meta"] = {["fields"] = {}, ["inventory"] = {}}, ["y"] = 0, ["z"] = 2, ["name"] = "wool:green"}, {["x"] = 0, ["meta"] = {["fields"] = {}, ["inventory"] = {}}, ["y"] = 0, ["param1"] = 92, ["z"] = 3, ["name"] = "maptools:grass"}, {["x"] = 0, ["meta"] = {["fields"] = {}, ["inventory"] = {}}, ["y"] = 0, ["param1"] = 109, ["z"] = 4, ["name"] = "maptools:grass"}, {["x"] = 0, ["meta"] = {["fields"] = {["cart_acceleration"] = "0"}, ["inventory"] = {}}, ["y"] = 1, ["param1"] = 159, ["z"] = 0, ["name"] = "carts:powerrail"}, {["x"] = 0, ["meta"] = {["fields"] = {["cart_acceleration"] = "0"}, ["inventory"] = {}}, ["y"] = 1, ["param1"] = 175, ["z"] = 1, ["name"] = "carts:powerrail"}, {["x"] = 0, ["meta"] = {["fields"] = {}, ["inventory"] = {}}, ["y"] = 1, ["z"] = 2, ["name"] = "wool:green"}, {["x"] = 0, ["meta"] = {["fields"] = {}, ["inventory"] = {}}, ["y"] = 1, ["z"] = 3, ["name"] = "wool:green"}, {["x"] = 0, ["meta"] = {["fields"] = {}, ["inventory"] = {}}, ["y"] = 1, ["z"] = 4, ["name"] = "wool:green"}, {["x"] = 0, ["meta"] = {["fields"] = {["cart_acceleration"] = "0"}, ["inventory"] = {}}, ["y"] = 2, ["param1"] = 175, ["z"] = 2, ["name"] = "carts:powerrail"}, {["x"] = 0, ["meta"] = {["fields"] = {}, ["inventory"] = {}}, ["y"] = 2, ["z"] = 3, ["name"] = "wool:green"}, {["x"] = 0, ["meta"] = {["fields"] = {}, ["inventory"] = {}}, ["y"] = 2, ["z"] = 4, ["name"] = "wool:green"}, {["x"] = 0, ["meta"] = {["fields"] = {["cart_acceleration"] = "0"}, ["inventory"] = {}}, ["y"] = 3, ["param1"] = 143, ["z"] = 3, ["name"] = "carts:powerrail"}, {["x"] = 0, ["meta"] = {["fields"] = {["cart_acceleration"] = "0"}, ["inventory"] = {}}, ["y"] = 3, ["param1"] = 127, ["z"] = 4, ["name"] = "carts:powerrail"}, {["x"] = 1, ["meta"] = {["fields"] = {}, ["inventory"] = {}}, ["y"] = 0, ["param1"] = 159, ["z"] = 0, ["name"] = "maptools:grass"}, {["x"] = 1, ["meta"] = {["fields"] = {}, ["inventory"] = {}}, ["y"] = 0, ["z"] = 1, ["name"] = "building_blocks:Marble"}, {["x"] = 1, ["meta"] = {["fields"] = {["infotext"] = "Command Block\
(owned by Nigel)\
Commands: teleport @nearest 220,5,-93", ["owner"] = "Nigel", ["commands"] = "teleport @nearest 220,5,-93", ["formspec"] = "invsize[9,5;]textarea[0.5,0.5;8.5,4;commands;Commands;teleport @nearest 220,5,-93]label[1,3.8;@nearest, @farthest, and @random are replaced by the respective player names]button_exit[3.3,4.5;2,1;submit;Submit]"}, ["inventory"] = {}}, ["y"] = 0, ["z"] = 2, ["name"] = "mesecons_commandblock:commandblock_off"}, {["x"] = 1, ["meta"] = {["fields"] = {}, ["inventory"] = {}}, ["y"] = 0, ["z"] = 3, ["name"] = "building_blocks:Marble"}, {["x"] = 1, ["meta"] = {["fields"] = {}, ["inventory"] = {}}, ["y"] = 0, ["param1"] = 125, ["z"] = 4, ["name"] = "maptools:grass"}, {["x"] = 1, ["meta"] = {["fields"] = {["cart_acceleration"] = "0"}, ["inventory"] = {}}, ["y"] = 1, ["param1"] = 175, ["z"] = 0, ["name"] = "carts:powerrail"}, {["x"] = 1, ["meta"] = {["fields"] = {}, ["inventory"] = {}}, ["param2"] = 1, ["y"] = 1, ["param1"] = 189, ["z"] = 1, ["name"] = "homedecor:curtain_white"}, {["x"] = 1, ["meta"] = {["fields"] = {}, ["inventory"] = {}}, ["param2"] = 1, ["y"] = 1, ["param1"] = 205, ["z"] = 2, ["name"] = "homedecor:curtain_white"}, {["x"] = 1, ["meta"] = {["fields"] = {}, ["inventory"] = {}}, ["param2"] = 1, ["y"] = 1, ["param1"] = 189, ["z"] = 3, ["name"] = "homedecor:curtain_white"}, {["x"] = 1, ["meta"] = {["fields"] = {}, ["inventory"] = {}}, ["y"] = 1, ["z"] = 4, ["name"] = "wool:green"}, {["x"] = 1, ["meta"] = {["fields"] = {["infotext"] = "PlayLand ", ["text"] = "PlayLand", ["__signslib_new_format"] = "1", ["formspec"] = "size[6,4]textarea[0,-0.3;6.5,3;text;;${text}]button_exit[2,3.4;2,1;ok;Write]background[-0.5,-0.5;7,5;bg_signs_lib.jpg]"}, ["inventory"] = {}}, ["param2"] = 3, ["y"] = 2, ["param1"] = 175, ["z"] = 3, ["name"] = "signs:sign_wall_white_black"}, {["x"] = 1, ["meta"] = {["fields"] = {}, ["inventory"] = {}}, ["y"] = 2, ["z"] = 4, ["name"] = "wool:green"}, {["x"] = 1, ["meta"] = {["fields"] = {["cart_acceleration"] = "0"}, ["inventory"] = {}}, ["y"] = 3, ["param1"] = 143, ["z"] = 4, ["name"] = "carts:powerrail"}, {["x"] = 2, ["meta"] = {["fields"] = {}, ["inventory"] = {}}, ["y"] = 0, ["param1"] = 175, ["z"] = 0, ["name"] = "maptools:grass"}, {["x"] = 2, ["meta"] = {["fields"] = {}, ["inventory"] = {}}, ["y"] = 0, ["z"] = 1, ["name"] = "building_blocks:Marble"}, {["x"] = 2, ["meta"] = {["fields"] = {}, ["inventory"] = {}}, ["y"] = 0, ["z"] = 2, ["name"] = "default:meselamp"}, {["x"] = 2, ["meta"] = {["fields"] = {}, ["inventory"] = {}}, ["y"] = 0, ["z"] = 3, ["name"] = "building_blocks:Marble"}, {["x"] = 2, ["meta"] = {["fields"] = {}, ["inventory"] = {}}, ["y"] = 0, ["param1"] = 141, ["z"] = 4, ["name"] = "maptools:grass"}, {["x"] = 2, ["meta"] = {["fields"] = {["cart_acceleration"] = "0"}, ["inventory"] = {}}, ["y"] = 1, ["param1"] = 191, ["z"] = 0, ["name"] = "carts:powerrail"}, {["x"] = 2, ["meta"] = {["fields"] = {}, ["inventory"] = {}}, ["param2"] = 1, ["y"] = 1, ["param1"] = 205, ["z"] = 1, ["name"] = "homedecor:curtain_white"}, {["x"] = 2, ["meta"] = {["fields"] = {}, ["inventory"] = {}}, ["y"] = 1, ["param1"] = 221, ["z"] = 2, ["name"] = "mesecons_pressureplates:pressure_plate_stone_off"}, {["x"] = 2, ["meta"] = {["fields"] = {}, ["inventory"] = {}}, ["param2"] = 1, ["y"] = 1, ["param1"] = 205, ["z"] = 3, ["name"] = "homedecor:curtain_white"}, {["x"] = 2, ["meta"] = {["fields"] = {}, ["inventory"] = {}}, ["y"] = 1, ["z"] = 4, ["name"] = "wool:green"}, {["x"] = 2, ["meta"] = {["fields"] = {["cart_acceleration"] = "0"}, ["inventory"] = {}}, ["y"] = 2, ["param1"] = 175, ["z"] = 4, ["name"] = "carts:powerrail"}, {["x"] = 3, ["meta"] = {["fields"] = {}, ["inventory"] = {}}, ["y"] = 0, ["param1"] = 159, ["z"] = 0, ["name"] = "maptools:grass"}, {["x"] = 3, ["meta"] = {["fields"] = {}, ["inventory"] = {}}, ["y"] = 0, ["z"] = 1, ["name"] = "building_blocks:Marble"}, {["x"] = 3, ["meta"] = {["fields"] = {}, ["inventory"] = {}}, ["y"] = 0, ["z"] = 2, ["name"] = "building_blocks:Marble"}, {["x"] = 3, ["meta"] = {["fields"] = {}, ["inventory"] = {}}, ["y"] = 0, ["z"] = 3, ["name"] = "building_blocks:Marble"}, {["x"] = 3, ["meta"] = {["fields"] = {}, ["inventory"] = {}}, ["y"] = 0, ["param1"] = 159, ["z"] = 4, ["name"] = "maptools:grass"}, {["x"] = 3, ["meta"] = {["fields"] = {["cart_acceleration"] = "0"}, ["inventory"] = {}}, ["y"] = 1, ["param1"] = 175, ["z"] = 0, ["name"] = "carts:powerrail"}, {["x"] = 3, ["meta"] = {["fields"] = {}, ["inventory"] = {}}, ["param2"] = 1, ["y"] = 1, ["param1"] = 189, ["z"] = 1, ["name"] = "homedecor:curtain_white"}, {["x"] = 3, ["meta"] = {["fields"] = {}, ["inventory"] = {}}, ["param2"] = 1, ["y"] = 1, ["param1"] = 205, ["z"] = 2, ["name"] = "homedecor:curtain_white"}, {["x"] = 3, ["meta"] = {["fields"] = {}, ["inventory"] = {}}, ["param2"] = 1, ["y"] = 1, ["param1"] = 189, ["z"] = 3, ["name"] = "homedecor:curtain_white"}, {["x"] = 3, ["meta"] = {["fields"] = {["cart_acceleration"] = "0"}, ["inventory"] = {}}, ["y"] = 1, ["param1"] = 175, ["z"] = 4, ["name"] = "carts:powerrail"}, {["x"] = 4, ["meta"] = {["fields"] = {}, ["inventory"] = {}}, ["y"] = 0, ["param1"] = 143, ["z"] = 0, ["name"] = "maptools:grass"}, {["x"] = 4, ["meta"] = {["fields"] = {}, ["inventory"] = {}}, ["y"] = 0, ["param1"] = 159, ["z"] = 1, ["name"] = "maptools:grass"}, {["x"] = 4, ["meta"] = {["fields"] = {}, ["inventory"] = {}}, ["y"] = 0, ["param1"] = 175, ["z"] = 2, ["name"] = "maptools:grass"}, {["x"] = 4, ["meta"] = {["fields"] = {}, ["inventory"] = {}}, ["y"] = 0, ["param1"] = 159, ["z"] = 3, ["name"] = "maptools:grass"}, {["x"] = 4, ["meta"] = {["fields"] = {}, ["inventory"] = {}}, ["y"] = 0, ["param1"] = 143, ["z"] = 4, ["name"] = "maptools:grass"}, {["x"] = 4, ["meta"] = {["fields"] = {["cart_acceleration"] = "0"}, ["inventory"] = {}}, ["y"] = 1, ["param1"] = 159, ["z"] = 0, ["name"] = "carts:powerrail"}, {["x"] = 4, ["meta"] = {["fields"] = {["cart_acceleration"] = "0"}, ["inventory"] = {}}, ["y"] = 1, ["param1"] = 175, ["z"] = 1, ["name"] = "carts:powerrail"}, {["x"] = 4, ["meta"] = {["fields"] = {["cart_acceleration"] = "0"}, ["inventory"] = {}}, ["y"] = 1, ["param1"] = 191, ["z"] = 2, ["name"] = "carts:powerrail"}, {["x"] = 4, ["meta"] = {["fields"] = {["cart_acceleration"] = "0"}, ["inventory"] = {}}, ["y"] = 1, ["param1"] = 175, ["z"] = 3, ["name"] = "carts:powerrail"}, {["x"] = 4, ["meta"] = {["fields"] = {["cart_acceleration"] = "0"}, ["inventory"] = {}}, ["y"] = 1, ["param1"] = 159, ["z"] = 4, ["name"] = "carts:powerrail"}}